Workbook
Name Select_Bank: DashBoard!#REF!

Sheet Company Profile
A1: Company Profile
A2: Logo | B2: #VALUE! | C2: #VALUE! | D2: #VALUE! | E2: #VALUE! | F2: #VALUE! | G2: #VALUE! | H2: #VALUE!
A3: Company Name | B3: HDFC Bank | C3: ICICI Bank | D3: Axis Bank | E3: SBI | F3: Bajaj Finance | G3: Bajaj Housing Finance | H3: Muthoot Finance
A4: Company name as per Exchange | B4: #VALUE! | C4: #VALUE! | D4: #VALUE! | E4: #VALUE! | F4: #VALUE! | G4: #VALUE! | H4: #VALUE!
A5: Industry | B5: {=_FV(B4,"Industry")} -> Banking Services | C5: {=_FV(C4,"Industry")} -> Banking Services | D5: {=_FV(D4,"Industry")} -> Banking Services | E5: {=_FV(E4,"Industry")} -> Banking Services | F5: {=_FV(F4,"Industry")} -> Banking Services | G5: {=_FV(G4,"Industry")} -> Banking Services | H5: {=_FV(H4,"Industry")} -> Banking Services
A6: Current Market Price | B6: {=_FV(B4,"Price")} -> 982.3 | C6: {=_FV(C4,"Price")} -> 1343 | D6: {=_FV(D4,"Price")} -> 1222.8 | E6: {=_FV(E4,"Price")} -> 925 | F6: {=_FV(F4,"Price")} -> 1066.6 | G6: {=_FV(G4,"Price")} -> 109.5 | H6: {=_FV(H4,"Price")} -> 3230
A7: Beta | B7: {=_FV(B4,"Beta")} -> 0.8793 | C7: {=_FV(C4,"Beta")} -> 0.9991 | D7: {=_FV(D4,"Beta")} -> 1.0905 | E7: {=_FV(E4,"Beta")} -> 1.2655 | F7: {=_FV(F4,"Beta")} -> 1.1683 | G7: {=_FV(G4,"Beta")} -> 1.422 | H7: {=_FV(H4,"Beta")} -> 0.9721
A8: P/E (Current) | B8: {=_FV(B4,"P/E",TRUE)} -> 20.83 | C8: {=_FV(C4,"P/E",TRUE)} -> 17.58 | D8: {=_FV(D4,"P/E",TRUE)} -> 14.64 | E8: {=_FV(E4,"P/E",TRUE)} -> 10.38 | F8: {=_FV(F4,"P/E",TRUE)} -> 48.19 | G8: {=_FV(G4,"P/E",TRUE)} -> 38.63 | H8: {=_FV(H4,"P/E",TRUE)} -> 20.67
A9: INR/USD | B9: #VALUE! | C9: #VALUE! | D9: #VALUE! | E9: #VALUE! | F9: #VALUE! | G9: #VALUE! | H9: #VALUE!
A10: Conversion | B10: {=_FV(B9,"Price")} -> 0.01128 | C10: {=_FV(C9,"Price")} -> 0.01128 | D10: {=_FV(D9,"Price")} -> 0.01128 | E10: {=_FV(E9,"Price")} -> 0.01128 | F10: {=_FV(F9,"Price")} -> 0.01128 | G10: {=_FV(G9,"Price")} -> 0.01128 | H10: {=_FV(H9,"Price")} -> 0.01128
A11: Market Cap | B11: {=_FV(B4,"Market cap",TRUE)} -> 15104490000000 | C11: {=_FV(C4,"Market cap",TRUE)} -> 9592768000000 | D11: {=_FV(D4,"Market cap",TRUE)} -> 3794774000000 | E11: {=_FV(E4,"Market cap",TRUE)} -> 8517552000000 | F11: {=_FV(F4,"Market cap",TRUE)} -> 6629063000000 | G11: {=_FV(G4,"Market cap",TRUE)} -> 911982700000 | H11: {=_FV(H4,"Market cap",TRUE)} -> 1296743000000
B12: =B11/10000000 -> 1510449 | C12: =C11/10000000 -> 959276.8 | D12: =D11/10000000 -> 379477.4 | E12: =E11/10000000 -> 851755.2 | F12: =F11/10000000 -> 662906.3 | G12: =G11/10000000 -> 91198.27 | H12: =H11/10000000 -> 129674.3
A13: Shares Outstanding | B13: {=_FV(B4,"Shares outstanding",TRUE)} -> 15376650000 | C13: {=_FV(C4,"Shares outstanding",TRUE)} -> 7142791000 | D13: {=_FV(D4,"Shares outstanding",TRUE)} -> 3103348000 | E13: {=_FV(E4,"Shares outstanding",TRUE)} -> 9230617000 | F13: {=_FV(F4,"Shares outstanding",TRUE)} -> 6215135000 | G13: {=_FV(G4,"Shares outstanding",TRUE)} -> 8328608000 | H13: {=_FV(H4,"Shares outstanding",TRUE)} -> 401468500
A14: In Crores | B14: =B13/10000000 -> 1537.665 | C14: =C13/10000000 -> 714.2791 | D14: =D13/10000000 -> 310.3348 | E14: =E13/10000000 -> 923.0617 | F14: =F13/10000000 -> 621.5135 | G14: =G13/10000000 -> 832.8608 | H14: =H13/10000000 -> 40.14685
A15: Change (%) | B15: {=_FV(B4,"Change (%)",TRUE)} -> -0.002387 | C15: {=_FV(C4,"Change (%)",TRUE)} -> 0.017116 | D15: {=_FV(D4,"Change (%)",TRUE)} -> -0.00464 | E15: {=_FV(E4,"Change (%)",TRUE)} -> 0.042959 | F15: {=_FV(F4,"Change (%)",TRUE)} -> 0.023707 | G15: {=_FV(G4,"Change (%)",TRUE)} -> 0.001097 | H15: {=_FV(H4,"Change (%)",TRUE)} -> 0.014511
A16: Change (Rs) | B16: {=_FV(B4,"Change")} -> -2.35 | C16: {=_FV(C4,"Change")} -> 22.6 | D16: {=_FV(D4,"Change")} -> -5.7 | E16: {=_FV(E4,"Change")} -> 38.1 | F16: {=_FV(F4,"Change")} -> 24.7 | G16: {=_FV(G4,"Change")} -> 0.12 | H16: {=_FV(H4,"Change")} -> 46.2
A18: Mcap ($) | B18: =B11*B10 -> 170378647200 | C18: =C11*C10 -> 108206423040 | D18: =D11*D10 -> 42805050720 | E18: =E11*E10 -> 96077986560 | F18: =F11*F10 -> 74775830640 | G18: =G11*G10 -> 10287164856 | H18: =H11*H10 -> 14627261040
A19: In Millions | B19: =B18/1000000 -> 170378.65 | C19: =C18/1000000 -> 108206.42 | D19: =D18/1000000 -> 42805.051 | E19: =E18/1000000 -> 96077.987 | F19: =F18/1000000 -> 74775.831 | G19: =G18/1000000 -> 10287.165 | H19: =H18/1000000 -> 14627.261

Sheet Balance Sheet-Banks
A1: Balance Sheet
A2: Particulars | B2: #VALUE! | G2: #VALUE! | L2: #VALUE! | Q2: #VALUE!
B3: 2020 | C3: 2021 | D3: 2022 | E3: 2023 | F3: 2024 | G3: 2020 | H3: 2021 | I3: 2022 | J3: 2023 | K3: 2024 | L3: 2020 | M3: 2021 | N3: 2022 | O3: 2023 | P3: 2024 | Q3: 2020 | R3: 2021 | S3: 2022 | T3: 2023 | U3: 2024
A4: Shareholder's Equity
A5: Equity Share Capital | B5: 564.33 | C5: =612.75 -> 612.75 | D5: 613.95 | E5: 615.37 | F5: 617.31 | G5: 548.32 | H5: 551.27 | I5: 554.55 | J5: 557.97 | K5: 759.69 | L5: 1294.76 | M5: 1383.41 | N5: 1389.96 | O5: 1396.77 | P5: 1404.67 | Q5: 892.46 | R5: 892.46 | S5: 892.46 | T5: 892.46 | U5: 892.46
A6: Reserves and Surplus | B6: 85776.09 | C6: 102980.95 | D6: 117495.94 | E6: 128740.25 | F6: 155511.72 | G6: 175810.37 | H6: 209258.91 | I6: 246771.62 | J6: 288879.53 | K6: 452982.84 | L6: 121661.8 | M6: 146122.67 | N6: 168855.59 | O6: 212340.12 | P6: 253333.83 | Q6: 250167.66 | R6: 274669.09 | S6: 304695.58 | T6: 358038.85 | U6: 414046.71
A7: Minority Interest | B7: 113.55 | C7: 173.75 | D7: 261.35 | E7: 393.39 | F7: 499.44 | G7: 576.64 | H7: 632.76 | I7: 720.41 | J7: 860.26 | K7: 13383.4 | L7: 6794.76 | M7: 0 | N7: 0 | O7: 6686.75 | P7: 13888.41 | Q7: 7943.82 | R7: 9625.91 | S7: 11207.42 | T7: 12836.61 | U7: 15617.96
A8: Employees Stock options outstanding | B8: 0 | C8: 0 | D8: 150.77 | E8: 426.09 | F8: 894.49 | G8: 0 | H8: 0 | I8: 0 | J8: 0 | K8: 2652.72 | L8: 3.48 | M8: 3.1 | N8: 266.41 | O8: 760.88 | P8: 1405.31 | Q8: 0 | R8: 0 | S8: 0 | T8: 0 | U8: 0
A9: Total Equity | B9: =B5+B6+B7 -> 86453.97 | C9: =C5+C6+C7 -> 103767.45 | D9: =D5+D6+D7+D8 -> 118522.01 | E9: =E5+E6+E7+E8 -> 130175.1 | F9: =F5+F6+F7+F8 -> 157522.96 | G9: =G5+G6+G7+G8 -> 176935.33 | H9: =H5+H6+H7+H8 -> 210442.94 | I9: =I5+I6+I7+I8 -> 248046.58 | J9: =J5+J6+J7+J8 -> 290297.76 | K9: =K5+K6+K7+K8 -> 469778.65 | ... U9: =U5+U6+U7+U8 -> 430557.13
A10: Liabilities
A11: Deposits of branches in India | B11: 635203.77 | C11: 695234.99 | D11: 818308.24 | E11: 931486.13 | F11: 1052137.3 | G11: 1141364.1 | H11: 1327832.4 | I11: 1547880.7 | J11: 1865420.2 | K11: 2354694.8 | L11: 762401.07 | M11: 924888.06 | N11: 1054760.9 | O11: 1163807.9 | P11: 1395478.5 | Q11: 3122567.4 | R11: 3567926.8 | S11: 3917357.6 | T11: 4248617.5 | U11: 4718596.7
A12: Deposits of branches outside India | B12: 6953.43 | C12: 3067.64 | D12: 2605.92 | E12: 14338.59 | F12: 14965.08 | G12: 4843.05 | H12: 5888.44 | I12: 10122.3 | J12: 17243 | K12: 22192.53 | L12: 38383.38 | M12: 7634.09 | N12: 9810.71 | O12: 47024.22 | P12: 48101.42 | Q12: 151593.2 | R12: 147404.39 | S12: 170053.01 | T12: 219918.02 | U12: 247940.75
A13: Total Deposits | B13: =B11+B12 -> 642157.2 | C13: =C11+C12 -> 698302.63 | D13: =D11+D12 -> 820914.16 | E13: =E11+E12 -> 945824.72 | F13: =F11+F12 -> 1067102.4 | G13: =G11+G12 -> 1146207.1 | H13: =H11+H12 -> 1333720.9 | I13: =I11+I12 -> 1558003 | ... U13: =U11+U12 -> 4966537.5
A14: Borrowings in India
A15: RBI | B15: 11619 | C15: 18102 | D15: 18102 | E15: 7769 | F15: 0 | G15: 1726 | H15: 9020 | I15: 9020 | J15: 9020 | K15: 4556 | L15: 11832.85 | M15: 100 | N15: 0 | O15: 1889.92 | P15: 2618.69 | Q15: 34981.75 | R15: 24956 | S15: 24956 | T15: 26467.44 | U15: 98806.56
A16: Other Banks | B16: 2358.29 | C16: 3284.48 | D16: 8518.11 | E16: 13696.28 | F16: 15891.26 | G16: 13804.08 | H16: 11504.26 | I16: 9975.09 | J16: 17538.29 | K16: 138414.6 | L16: 7719.61 | M16: 69.99 | N16: 0 | O16: 7191.11 | P16: 10471.4 | Q16: 10041.13 | R16: 10678.34 | S16: 12601.43 | T16: 12929.14 | U16: 18549.19
A17: Other institutions & agencies | B17: 84526.52 | C17: 90548.85 | D17: 118770.87 | E17: 147235.52 | F17: 176230.7 | G17: 74982.43 | H17: 69351.56 | I17: 88651.96 | J17: 95782.45 | K17: 148410.04 | L17: 58397.15 | M17: 21606.9 | N17: 18716.87 | O17: 60894.23 | P17: 66184.05 | Q17: 11419.94 | R17: 159271.91 | S17: 152877.62 | T17: 98387.56 | U17: 74966.15
A18: Upper and lower capital debts | B18: 0 | C18: 0 | D18: 0 | E18: 0 | F18: 0 | G18: 21875.5 | H18: 21127 | I18: 17627 | J18: 28550 | K18: 30583.32 | L18: 22342.49 | M18: =10120+7125.8998 -> 17245.9 | N18: =6695+7155.6981 -> 13850.698 | O18: =5140+5320.66 -> 10460.66 | P18: 4859.41 | Q18: 56464.75 | R18: 67465.6 | S18: 73239.6 | T18: 90522.6 | U18: 96310.4
A19: Bonds and debentures | B19: 0 | C19: 0 | D19: 0 | E19: 0 | F19: 0 | G19: 39242.41 | H19: 38975.21 | I19: 43986.21 | J19: 46619.58 | K19: 299626.91 | L19: 28115.02 | M19: 19786.78 | N19: 39149.5 | O19: =50678.2+9802.28+3662.44 -> 64142.92 | P19: =52530.38+17296.08+3810.6 -> 73637.06 | Q19: 2927.08 | R19: 2382.91 | S19: 164.61 | T19: 23073 | U19: 42703
A20: Borrowings outside India | B20: 56676.34 | C20: 40313.39 | D20: 54387.18 | E20: 37512.77 | F20: 36077.59 | G20: 35203.89 | H20: 27718.7 | I20: 57706.24 | J20: 59038.34 | K20: 109024.59 | L20: 85444.62 | M20: 32890.66 | N20: 35514.28 | O20: 44482.93 | P20: 49657.37 | Q20: 217066 | R20: 169041.42 | S20: 185320.49 | T20: 269772.2 | U20: 308274.2
A21: Total Borrowings | B21: =B20+B15+B16+B17 -> 155180.15 | C21: =C20+C15+C16+C17 -> 152248.72 | D21: =D20+D15+D16+D17 -> 199778.16 | E21: =E20+E15+E16+E17 -> 206213.57 | F21: =F20+F15+F16+F17 -> 228199.55 | G21: =G20+G15+G16+G17+G18+G19 -> 186834.31 | H21: =H20+H15+H16+H17+H18+H19 -> 177696.73 | I21: =I20+I15+I16+I17+I18+I19 -> 226966.5 | J21: =J20+J15+J16+J17+J18+J19 -> 256548.66 | K21: =K20+K15+K16+K17+K18+K19 -> 730615.46 | L21: =L20+L15+L16+L17+L18+L19 -> 213851.74 | M21: =M20+M15+M16+M17+M18+M19 -> 91700.23 | N21: =N20+N15+N16+N17+N18+N19 -> 107231.35 | ... U21: =U20+U15+U16+U17+U18+U19 -> 639609.5
A22: Bills Payable | B22: 3689.78 | C22: 7032.65 | D22: 8499.36 | E22: 9543.81 | F22: 6713.89 | G22: 7583.72 | H22: 12424.19 | I22: 13093.74 | J22: 11790.76 | K22: 13932.56 | L22: 5714.22 | M22: 12387.06 | N22: 12949.57 | O22: 13603.7 | P22: 12819.31 | Q22: 26889.76 | R22: 17728.51 | S22: 33485.82 | T22: 27408.121 | U22: 15700.292
A23: Inter office adjustments (net) | B23: 0 | C23: 0 | D23: 0 | E23: 0 | F23: 0 | G23: 0 | H23: 0 | I23: 0 | J23: 0 | K23: 0 | L23: 743.95 | M23: 326.26 | N23: 441.81 | O23: 322.8 | P23: 42.09 | Q23: =85.41+10.35 -> 95.76 | R23: =49.69+1.23 -> 50.92 | S23: =37.86+2344.61 -> 2382.47 | T23: =235.5+4346.6 -> 4582.1 | U23: =491.12+1126.5956 -> 1617.7156
A24: Interest accrued | B24: 3412.28 | C24: 3898.24 | D24: 4662.33 | E24: 4097.95 | F24: 3658.22 | G24: 8582.55 | H24: 8123.58 | I24: 8241.11 | J24: 11393.84 | K24: 23853.43 | L24: 3071.04 | M24: 2138.91 | N24: 2463.28 | O24: 3339.01 | P24: 3898.55 | Q24: 15477.09 | R24: 15309.15 | S24: 17990.61 | T24: 27495.02 | U24: 32861.615
A25: Proposed Dividend | B25: 0 | C25: 0 | D25: 0 | E25: 0 | F25: 0 | G25: 0 | H25: 0 | I25: 0 | J25: 0 | K25: 0 | L25: 0 | M25: 0 | N25: 0 | O25: 0 | P25: 0 | Q25: 0 | R25: 0 | S25: 0 | T25: 0 | U25: 0
A26: Sundry Creditors | B26: 0 | C26: 0 | D26: 0 | E26: 0 | F26: 0 | G26: 0 | H26: 0 | I26: 0 | J26: 0 | K26: 0 | L26: 35049.34 | M26: 12184.83 | N26: 14473.12 | O26: 24283.06 | P26: 63912.06 | Q26: 0 | R26: 0 | S26: 0 | T26: 0 | U26: 0
A27: Other Liabilities | B27: 4635.31 | C27: 7113.04 | D27: 7346.31 | E27: 7988.94 | F27: 5113.43 | G27: 4651.76 | H27: 5525.85 | I27: 6791.27 | J27: 7252.06 | K27: 11005.15 | L27: 6623.58 | M27: 3634.28 | N27: 4094.28 | O27: =4994.67+18376.47 -> 23371.14 | P27: =6160.2+17651.91 -> 23812.11 | Q27: =6.6 -> 6.6 | R27: 3.7 | S27: 5.68 | T27: 3.8018 | U27: 23.2084
A28: Liabilities on policies in force | B28: 0 | C28: 0 | D28: 0 | E28: 0 | F28: 0 | G28: 0 | H28: 0 | I28: 0 | J28: 0 | K28: 0 | L28: 0 | M28: 0 | N28: 0 | O28: 238867.36 | P28: 281318.33 | Q28: 159661.49 | R28: 219027.87 | S28: 264548.27 | T28: 308442.72 | U28: 392280.43
A29: Provisions | B29: 32343.05 | C29: 28641.81 | D29: 35806.18 | E29: 40573.87 | F29: 49928.08 | G29: 50035.59 | H29: 51572.43 | I29: 61792.07 | J29: 70486.11 | K29: 126040.93 | L29: 36212.75 | M29: 28099.01 | N29: 34560.7 | O29: 33624.89 | P29: 57220.35 | Q29: =12444.21+116852.16 -> 129296.37 | R29: =16005.37+143178.05 -> 159183.42 | S29: =20592.09+168512.69 -> 189104.78 | T29: =26332.69+198698.4492 -> 225031.14 | U29: =24851.7215+229739.6833 -> 254591.4
A30: Total Liabilities | B30: =B22+B23+B24+B25+B27+B29+B13+B9+B21 -> 927871.74 | C30: =C22+C23+C24+C25+C27+C29+C13+C9+C21 -> 1001004.5 | D30: =D22+D23+D24+D25+D27+D29+D13+D9+D21 -> 1195528.5 | E30: =E22+E23+E24+E25+E27+E29+E13+E9+E21 -> 1344418 | F30: =F22+F23+F24+F25+F27+F29+F13+F9+F21 -> 1518238.5 | G30: =G22+G23+G24+G25+G27+G29+G13+G9+G21 -> 1580830.4 | H30: =H22+H23+H24+H25+H27+H29+H13+H9+H21 -> 1799506.6 | I30: =I22+I23+I24+I25+I27+I29+I13+I9+I21 -> 2122934.3 | ... K30: =K22+K23+K24+K25+K27+K29+K13+K9+K21 -> 3752113.5 | L30: =L22+L23+L24+L25+L27+L29+L13+L9+L21+L26 -> 1231805.9 | M30: =M22+M23+M24+M25+M27+M29+M13+M9+M21+M26 -> 1230501.9 | N30: =N22+N23+N24+N25+N27+N29+N13+N9+N21+N26 -> 1411297.7 | O30: =O22+O23+O24+O25+O27+O29+O13+O9+O21+O26+O28 -> 1958490.4 | P30: =P22+P23+P24+P25+P27+P29+P13+P9+P21+P26+P28 -> 2364062.9 | Q30: =Q22+Q23+Q24+Q25+Q27+Q29+Q13+Q9+Q21+Q26+Q28 -> 4197492.3 | R30: =R22+R23+R24+R25+R27+R29+R13+R9+R21+R26+R28 -> 4845618.4 | S30: =S22+S23+S24+S25+S27+S29+S13+S9+S21+S26+S28 -> 5360883.4 | T30: =T22+T23+T24+T25+T27+T29+T13+T9+T21 -> 5645975.5 | U30: =U22+U23+U24+U25+U27+U29+U13+U9+U21 -> 6341498.3
A31: ASSETS
A32: Cash and Cash Equivalents | B32: 7987.92 | C32: 12673.16 | D32: 9840.1 | E32: 9665.88 | F32: 9634.81 | G32: 9213.58 | H32: 10722.18 | I32: 11239.51 | J32: 13271.35 | K32: 13060.08 | L32: 9969.82 | M32: 7030.96 | N32: 7120.83 | O32: 8681.29 | P32: 8955.84 | Q32: 20334.94 | R32: 23691.32 | S32: 21967.22 | T32: 21628.41 | U32: 18589.64
A33: Balance in Current Accounts | B33: 20971.34 | C33: 23435.41 | D33: 36993.41 | E33: 43003.88 | F33: 48193.68 | G33: 37797.42 | H33: 59442.17 | I33: 81777.2 | J33: 94391.93 | K33: 131892.59 | L33: 25342.11 | M33: 39000.22 | N33: 52999.98 | O33: 48025.64 | P33: 62503.17 | Q33: 146633.51 | R33: 189807.29 | S33: 236119.2 | T33: 225692.63 | U33: 206747.68
A34: Balance in other accounts | B34: 56000 | C34: 15700 | D34: 47201 | E34: 13448 | F34: 28249 | G34: 25200 | H34: 27206 | I34: 37014 | J34: 9526 | K34: 33766 | L34: 0 | M34: 0 | N34: 0 | O34: 11942 | P34: 18484 | Q34: 0 | R34: 0 | S34: 0 | T34: 0 | U34: 19
A35: Total Balances | B35: =B33+B34+B32 -> 84959.26 | C35: =C33+C34+C32 -> 51808.57 | D35: =D33+D34+D32 -> 94034.51 | E35: =E33+E34+E32 -> 66117.76 | F35: =F33+F34+F32 -> 86077.49 | G35: =G33+G34+G32 -> 72211 | H35: =H33+H34+H32 -> 97370.35 | I35: =I33+I34+I32 -> 130030.71 | ... U35: =U33+U34+U32 -> 225356.32
A36: Balance with Banks in India
A37: In current Accounts | B37: 64.55 | C37: 286.85 | D37: 1240.04 | E37: 1517.1 | F37: 721.23 | G37: 415.54 | H37: 989.78 | I37: 627.61 | J37: 933.34 | K37: 1036.55 | L37: 364.19 | M37: 52.64 | N37: 32.41 | O37: 310.32 | P37: 355.37 | Q37: 638.49 | R37: 1067.9 | S37: 1064.57 | T37: 1262.19 | U37: 2510.86
A38: In other deposit accounts | B38: 2890.3 | C38: 1142.08 | D38: 886.98 | E38: 4061.4 | F38: 2931.78 | G38: 1247.68 | H38: 1617.09 | I38: 2730.83 | J38: 4100.75 | K38: 5247.91 | L38: 3335.0096 | M38: 1.52 | N38: 532.14 | O38: 10728.76 | P38: 12580.21 | Q38: 1429.61 | R38: 3160.05 | S38: 3727.11 | T38: 4395.41 | U38: 5211.2181
A39: Money at call and short notice
A40: With banks | B40: 0 | C40: 0 | D40: 0 | E40: 200 | F40: 100 | G40: 0 | H40: 0 | I40: 0 | J40: 0 | K40: 200 | L40: 59421.28 | M40: 35219 | N40: 49402 | O40: 821.7 | P40: 417.02 | Q40: 44747.71 | R40: 47369.93 | S40: 60938.22 | T40: 7770.44 | U40: 2550
...

Sheet Balance Sheet-NBFCs
A2: Particulars | B2: #VALUE! | G2: #VALUE! | L2: #VALUE!
B3: 2020 | C3: 2021 | D3: 2022 | E3: 2023 | F3: 2024 | G3: 2020 | H3: 2021 | I3: 2022 | J3: 2023 | K3: 2024 | L3: 2020 | M3: 2021 | N3: 2022 | O3: 2023 | P3: 2024
A4: Equity
A5: Equity share capital | B5: 4883.33 | C5: 4883.33 | D5: 4883.33 | E5: 6712.16 | F5: 6712.16 | G5: 119.99 | H5: 120.32 | I5: 120.66 | J5: 120.89 | K5: 123.6 | L5: 4010.37 | M5: 4011.96 | N5: 4013.45 | O5: 4014.48 | P5: 4014.62
A6: Other Equity | B6: 701.8 | C6: 1148.89 | D6: 1858.03 | E6: 3791.03 | F6: 5521.34 | G6: 32207.64 | H6: 36798.09 | I6: 43592.03 | J6: 54251.09 | K6: 76571.75 | L6: 114281.73 | M6: 151738.29 | N6: 183843.79 | O6: 212643.04 | P6: 247057.45
A7: Non-controlling interest | L7: 1721.42 | M7: 1845.75 | N7: 3521.72 | O7: 4870.52 | P7: 6468.33
A9: Total Equity | B9: =B5+B6+B7+B8 -> 5585.13 | C9: =C5+C6+C7+C8 -> 6032.22 | D9: =D5+D6+D7+D8 -> 6741.36 | E9: =E5+E6+E7+E8 -> 10503.19 | F9: =F5+F6+F7+F8 -> 12233.5 | G9: =G5+G6+G7+G8 -> 32327.63 | H9: =H5+H6+H7+H8 -> 36918.41 | I9: =I5+I6+I7+I8 -> 43712.69 | ... P9: =P5+P6+P7+P8 -> 257540.4
A10: Liabilities
A11: Payables | B11: =0.24+30.35+17.83 -> 48.42 | C11: =20.9+21.28 -> 42.18 | D11: =0.18+36.23+38.17 -> 74.58 | E11: =73.04+45.93 -> 118.97 | F11: =0.83+57.61+82.75 -> 141.19 | G11: =0.54+761.43+197.84 -> 959.81 | H11: =213.82+884.01+0.27 -> 1098.1 | I11: =0.24+1169.08+341.78 -> 1511.1 | J11: =1.86+1450.26+0.65+638.67 -> 2091.44 | K11: =0.73+2063.31+764.58 -> 2828.62 | L11: 2220.28 | M11: =2111.53+2.31 -> 2113.84 | N11: =1570.2+3.46 -> 1573.66 | O11: =7.2+871.23+1119.71 -> 1998.14 | P11: =7.68+1381.23+1280.77 -> 2669.68
A12: Debt securities | B12: 7823.59 | C12: 11332.08 | D12: 16489.15 | E12: 19914.92 | F12: 26645.33 | G12: 49537.36 | H12: 54502.14 | I12: 76223.07 | J12: 86845.24 | K12: 117999.54 | L12: 102826.55 | M12: 146669.9 | N12: 131740.35 | O12: 146045.79 | P12: 174762.2
A13: Borrowings | B13: 17776.85 | C13: 20268.52 | D13: 24493.17 | E13: 33654.7 | F13: 42299.73 | G13: 54700.17 | H13: 47429.36 | I13: 54363.56 | J13: 81549.4 | K13: 111617.47 | L13: 300115.44 | M13: 351009.78 | N13: 408553.24 | O13: 405974.58 | P13: 500519.53
A14: Deposits | B14: 0 | C14: 0 | D14: 510 | E14: 175.77 | F14: 184.26 | G14: 21427.1 | H14: 25803.43 | I14: 30799.52 | J14: 44665.56 | K14: 60150.92 | L14: 2560.06 | M14: 2579.53 | N14: 2235.26 | O14: 3314.76 | P14: 4018.26
A15: Other financial liabilities | B15: 73.59 | C15: 151.14 | D15: 174.42 | E15: 211.62 | F15: 234.14 | G15: =4141.75+745.05 -> 4886.8 | H15: =945.12+3898.61+137.87 -> 4981.6 | I15: =1110.43+3845.77+140.02 -> 5096.22 | J15: =3630.29+1309.29+4.01 -> 4943.59 | K15: =3577.9+1844.39+2.12 -> 5424.41 | L15: =11884.77+167.72+3849.85 -> 15902.34 | M15: =13598.4+3706.89+177.57+3305.19 -> 20788.05 | N15: =2997.33+159.8+13323.48+4797.97 -> 21278.58 | O15: =2546.55+155.57+12638.76+1921.73 -> 17262.61 | P15: =138.86+3309.73+125.91+16014.9 -> 19589.4
A16: Current tax liabilities (net) | B16: 7.07 | C16: 7.39 | D16: 20.06 | E16: 16.17 | F16: 25.93 | G16: 59.17 | H16: 180.17 | I16: 100.06 | J16: 139.21 | K16: 108.64 | L16: 808.33 | M16: 1302.75 | N16: 1418.15 | O16: 811.92 | P16: 551.68
A17: Provisions | B17: 2.28 | C17: 2.29 | D17: 4.05 | E17: 15.63 | F17: 35.64 | G17: 81.24 | H17: 137.69 | I17: 166.9 | J17: 268.08 | K17: 421.89 | L17: 3712.33 | M17: 3695.29 | N17: 3679.83 | O17: 3618.92 | P17: 3733.27
A18: Deferred tax liabilities (net) | B18: 11.43 | C18: 0 | D18: 0 | E18: 28.27 | F18: 0 | G18: 0 | H18: 0 | I18: 0 | J18: 0 | K18: 0 | L18: 151.03 | M18: 142.21 | N18: 166.36 | O18: 152.86 | P18: 167.62
A19: Other non financial liabilities | B19: 44.06 | C19: 0 | D19: 0 | E19: 14.9 | F19: 27.37 | G19: 412.09 | H19: 419.5 | I19: 532.24 | J19: 351.81 | K19: 494.78 | L19: 507.04 | M19: 517 | N19: 1140.36 | O19: 781.58 | P19: 1142.16
A20: Total Liabilities | B20: =SUM(B11:B19) -> 25787.29 | C20: =SUM(C11:C19) -> 31803.6 | D20: =SUM(D11:D19) -> 41765.43 | E20: =SUM(E11:E19) -> 54150.95 | F20: =SUM(F11:F19) -> 69593.59 | G20: =SUM(G11:G19) -> 132063.74 | H20: =SUM(H11:H19) -> 134551.99 | I20: =SUM(I11:I19) -> 168792.67 | ... P20: =SUM(P11:P19) -> 707153.8
A21: Total Equity and liabilities | B21: =B9+B20 -> 31372.42 | C21: =C9+C20 -> 37835.82 | D21: =D9+D20 -> 48506.79 | E21: =E9+E20 -> 64654.14 | F21: =F9+F20 -> 81827.09 | G21: =G9+G20 -> 164391.37 | H21: =H9+H20 -> 171470.4 | I21: =I9+I20 -> 212505.36 | ... P21: =P9+P20 -> 964694.2
A22: ASSETS
A23: Cash and Cash equivalents | B23: 658.72 | C23: 461.78 | D23: 407.03 | E23: 93.88 | F23: 63.86 | G23: 1344.52 | H23: 1849.33 | I23: 3407.17 | J23: 1550.75 | K23: 4034.51 | L23: 58347.65 | M23: 77775.2 | N23: 100358.14 | O23: 77701.83 | P23: 60373.45
A24: Bank Balances other than cash | B24: 0 | C24: 255 | D24: 0.14 | E24: 14.99 | F24: 0.15 | G24: 38.2 | H24: 314.99 | I24: 273.13 | J24: 2753.77 | K24: 6589.5 | L24: 2958.88 | M24: 2434.87 | N24: 2791.47 | O24: 2654.76 | P24: 2346.57
A25: Derivative Financial Instruments | B25: 0 | C25: 0 | D25: 0 | E25: 1.37 | F25: 11.66 | G25: 171.76 | H25: 0 | I25: 121.9 | J25: 148.88 | K25: 27.84 | L25: 3448.94 | M25: 153.64 | N25: 605.01 | O25: 0 | P25: 0
A26: Receivables | B26: 118.4 | C26: 310.66 | D26: 237.33 | E26: =1.59+0.36 -> 1.95 | F26: 13.36 | G26: 952.49 | H26: 1096.86 | I26: 1265.89 | J26: 1299.72 | K26: 1733.49 | L26: 89.82 | M26: 98.02 | N26: 70.09 | O26: 98.95 | P26: 178.36
A27: Loans | B27: 27975.41 | C27: 33418.9 | D27: 46482.07 | E27: 62113.89 | F27: 79300.75 | G27: 141376.05 | H27: 146686.87 | I27: 191423.25 | J27: 242268.93 | K27: 326293.32 | L27: 470677.41 | M27: 588085.17 | N27: 645276.41 | O27: 705543.84 | P27: 881871.71
A28: Investments | B28: 2508.02 | C28: 3266.06 | D28: 1248.27 | E28: 2000.91 | F28: 1938.57 | G28: 17543.9 | H28: 18396.91 | I28: 12245.54 | J28: 22751.84 | K28: 30880.65 | L28: =6302.16+156.48 -> 6458.64 | M28: =8085.05+139.45 -> 8224.5 | N28: =5233.06+93.41 -> 5326.47 | O28: 5457.12 | P28: 7124.72
A29: Other Financial assets | B29: 8.44 | C29: 33.99 | D29: 18.48 | E29: 301.94 | F29: 284.07 | G29: 470.39 | H29: 536.98 | I29: 721.49 | J29: 817.28 | K29: 1431.88 | L29: 2448.75 | M29: 4383.41 | N29: 2807.28 | O29: 3453 | P29: 4136.12
A30: Current tax assets (net) | B30: 11.1 | C30: 4.46 | D30: 9.08 | E30: 3.97 | F30: 31.09 | G30: 216.72 | H30: 159.77 | I30: 168.3 | J30: 181.43 | K30: 290.92 | L30: 94.25 | M30: 93.96 | N30: 110.21 | O30: 474.57 | P30: 724.86
A31: Deferred tax assets (net) | B31: 0 | C31: 15.26 | D31: 15.58 | E31: 0 | F31: 50.94 | G31: 850.13 | H31: 945.9 | I31: 951.11 | J31: 937.09 | K31: 1017.43 | L31: 171.04 | M31: 592.75 | N31: 1089.74 | O31: 640.98 | P31: 975.78
A32: Property, Plant and Equipments | B32: 77.8 | C32: 63.32 | D32: 78.09 | E32: 84.92 | F32: 87.5 | G32: 1097.26 | H32: 1041.69 | I32: 1282.58 | J32: 1676.57 | K32: 2358.32 | L32: 2426.87 | M32: 2575.11 | N32: 2816.92 | O32: 3272.37 | P32: 4255.24
A33: Intangible assets | B33: 7.98 | C33: =14.57 -> 14.57 | D33: =1.46+19.11 -> 20.57 | E33: =0.31+28.07 -> 28.38 | F33: =0.87+35.36 -> 36.23 | G33: 220.46 | H33: =43.99+270.74 -> 314.73 | I33: =20.87+430.45 -> 451.32 | J33: =65.24+627.78 -> 693.02 | K33: =18.11+888.31 -> 906.42 | L33: =167.56+85.37 -> 252.93 | M33: =170.01+86.31+0.55 -> 256.87 | N33: =147.8+58.74+0.49 -> 207.03 | O33: =82.02+142.23+58.85+0.44 -> 283.54 | P33: =91.07+111.11+58.35+3.65 -> 264.18
A34: Capital work in progress | B34: 0 | C34: 0 | D34: 0 | E34: 0 | F34: 0 | G34: 0 | H34: 7.07 | I34: 13.27 | J34: 14.6 | K34: 25.35 | L34: 287.36 | M34: 384.77 | N34: 523.44 | O34: 674.27 | P34: 883.16
A35: Goodwill | B35: 0 | C35: 0 | D35: 0 | E35: 0 | F35: 0 | G35: 0 | H35: 3.27 | I35: 3.27 | J35: 3.27 | K35: 3.27 | L35: 299.96 | M35: 299.96 | N35: 299.96 | O35: 299.96 | P35: 299.96
A36: Other non financial assets | B36: 6.55 | C36: 13.4 | D36: 10.44 | E36: 7.94 | F36: 8.91 | G36: =3.27+106.22 -> 109.49 | H36: 116.03 | I36: 177.14 | J36: 129.16 | K36: 148.72 | L36: 854.42 | M36: 1056.12 | N36: 882.57 | O36: 934.01 | P36: 1260.09
A37: Total Assets | B37: =SUM(B23:B36) -> 31372.42 | C37: =SUM(C23:C36) -> 37857.4 | D37: =SUM(D23:D36) -> 48527.08 | E37: =SUM(E23:E36) -> 64654.14 | F37: =SUM(F23:F36) -> 81827.09 | G37: =SUM(G23:G36) -> 164391.37 | H37: =SUM(H23:H36) -> 171470.4 | I37: =SUM(I23:I36) -> 212505.36 | ... P37: =SUM(P23:P36) -> 964694.2
A39: Particulars | B39: 2020 | C39: 2021 | D39: 2022 | E39: 2023 | F39: 2024 | G39: 2020 | H39: 2021 | I39: 2022 | J39: 2023 | K39: 2024 | L39: 2020 | M39: 2021 | N39: 2022 | O39: 2023 | P39: 2024
A40: Demand Deposits | B40: 0
A41: Savings Account deposits | B41: 0
A42: Risk weighted assets | B42: 22450.99 | C42: 28119.67 | D42: 34126.15 | E42: 45901.75 | F42: 57351.83 | G42: 134916.74 | H42: 130767.5 | I42: 155832.47 | J42: 198890.13 | K42: 315149.85 | L42: 465414.95 | M42: 577179.12 | N42: 628762.36 | O42: 673758.71 | P42: 815900.47
A43: Tier 1 Capital | B43: 5495.58 | C43: 5820.36 | D43: 6469.01 | E43: 10184.74 | F43: 11857.24 | G43: 28697.72 | H43: 32838.5 | I43: 38570.88 | J43: 46152.01 | K43: 67796.11
...

Sheet Income Statement-Banks
A1: INCOME STATEMENT
A2: Particulars | B2: #VALUE! | G2: #VALUE! | L2: #VALUE! | Q2: #VALUE!
B3: 2020 | C3: 2021 | D3: 2022 | E3: 2023 | F3: 2024 | G3: 2020 | H3: 2021 | I3: 2022 | J3: 2023 | K3: 2024 | L3: 2020 | M3: 2021 | N3: 2022 | O3: 2023 | P3: 2024 | Q3: 2020 | R3: 2021 | S3: 2022 | T3: 2023 | U3: 2024
A4: INCOME
A5: Interest earned | B5: 63715.68 | C5: 64397.36 | D5: 68846.06 | E5: 87448.37 | F5: 112759.05 | G5: 122189.29 | H5: 128552.39 | I5: 135936.41 | J5: 170754.05 | K5: 283649.02 | L5: 84835.773 | M5: 79118.271 | N5: 86374.545 | O5: 121066.81 | P5: 159515.93 | Q5: 269851.65 | R5: 278115.48 | S5: 289972.69 | T5: 350844.58 | U5: 439188.51 | V5: =U5-U9 -> 179452.46
A6: Other income | B6: 16341.99 | C6: 13576.92 | D6: 17268.13 | E6: 18348.93 | F6: 25230.31 | G6: 24878.975 | H6: 27332.88 | I6: 31758.99 | J6: 33912.05 | K6: 124345.75 | L6: 64950.33 | M6: 18968.527 | N6: 18517.53 | O6: 65111.991 | P6: 76521.802 | Q6: 98158.99 | R6: 107222.41 | S6: 117000.4 | T6: 122533.56 | U6: 155386.39
A7: Total Income | B7: =B5+B6 -> 80057.67 | C7: =C5+C6 -> 77974.28 | D7: =D5+D6 -> 86114.19 | E7: =E5+E6 -> 105797.3 | F7: =F5+F6 -> 137989.36 | G7: =G5+G6 -> 147068.27 | H7: =H5+H6 -> 155885.27 | I7: =I5+I6 -> 167695.4 | ... U7: =U5+U6 -> 594574.9
A8: EXPENDITURE
A9: Interest expended | B9: 37995.94 | C9: 34627.38 | D9: 34922.66 | E9: 43389.15 | F9: 61390.74 | G9: 62137.422 | H9: 59247.58 | I9: 58584.33 | J9: 77779.94 | K9: 154138.55 | L9: 44665.522 | M9: 40128.837 | N9: 38908.451 | O9: 50543.388 | P9: 74108.163 | Q9: 161123.8 | R9: 156010.17 | S9: 156194.34 | T9: 189980.82 | U9: 259736.05
A10: Operating expenses | B10: 18065.758 | C10: 19174.88 | D10: 24824.23 | E10: 40869.62 | F10: 37242.55 | G10: 33036.056 | H10: 35001.257 | I10: 40312.43 | J10: 51533.69 | K10: 152269.34 | L10: 71517.899 | M10: 21560.834 | N10: 26733.316 | O10: 82439.023 | P10: 97782.792 | Q10: 131781.56 | R10: 150429.6 | S10: 174363.43 | T10: 189814.49 | U10: 235893.84
A11: Provisions and contingencies | B11: 22117.22 | C11: 16919.63 | D11: 12202.95 | E11: 10685.87 | F11: 12932.53 | G11: 24598.524 | H11: 29779.669 | I11: 30647.74 | J11: 29203.77 | K11: 36140.38 | L11: 22377.214 | M11: 20204.443 | N11: 15910.818 | O11: 18733.363 | P11: 19140.028 | Q11: 56928.459 | R11: 54618.409 | S11: 40059.148 | T11: 37024.409 | U11: 30806.757
A12: Total Expenses | B12: =B9+B10+B11 -> 78178.919 | C12: =C9+C10+C11 -> 70721.89 | D12: =D9+D10+D11 -> 71949.84 | E12: =E9+E10+E11 -> 94944.64 | F12: =F9+F10+F11 -> 111565.82 | G12: =G9+G10+G11 -> 119772 | H12: =H9+H10+H11 -> 124028.51 | I12: =I9+I10+I11 -> 129544.5 | ... U12: =U9+U10+U11 -> 526436.64
A13: Net Profit for the year | B13: =B7-B12 -> 1878.7514 | C13: =C7-C12 -> 7252.39 | D13: =D7-D12 -> 14164.35 | E13: =E7-E12 -> 10852.66 | F13: =F7-F12 -> 26423.54 | G13: =G7-G12 -> 27296.265 | H13: =H7-H12 -> 31856.768 | I13: =I7-I12 -> 38150.9 | ... U13: =U7-U12 -> 68138.261
A14: Minority Interest | B14: -25.6409 | C14: -56.89 | D14: =-87.6+42.54 -> -45.06 | E14: =-100.06+65.85 -> -34.21 | F14: =-106.05+68.71 -> -37.34 | G14: -42.3147 | H14: =-23.559 -> -23.559 | I14: -98.15 | J14: -151.59 | K14: -1384.46 | L14: -1659.1602 | M14: 0 | N14: 0 | O14: =-1424.6738+998.2876 -> -426.3862 | P14: =-1824.1392+1073.768 -> -750.3712 | Q14: =-1372.1667+2963.1404 -> 1590.9737 | R14: =-1482.3573-391.9045 -> -1874.2618 | S14: =-1809.3049+827.0133 -> -982.2916 | T14: =1191.4521-2101.7092 -> -910.2571 | U14: =1405.1543-2458.7491 -> -1053.5948
A15: Consolidated Net Profit | B15: =B13+B14 -> 1853.1105 | C15: =C13+C14 -> 7195.5 | D15: =D13+D14 -> 14119.29 | E15: =E13+E14 -> 10818.45 | F15: =F13+F14 -> 26386.2 | G15: =G13+G14 -> 27253.951 | H15: =H13+H14 -> 31833.209 | I15: =I13+I14 -> 38052.75 | ... U15: =U13+U14 -> 67084.666
A16: Balance in P&L b/d from Previous year | B16: 25117.523 | C16: 27125.82 | D16: 31466.92 | E16: 40604.49 | F16: 47769.25 | G16: 52849.607 | H16: 61817.688 | I16: 78594.2 | J16: 99062.77 | K16: =120369.35+3570.1 -> 123939.45 | L16: 22020.109 | M16: 21327.468 | N16: 31009.066 | O16: 50898.851 | P16: 65638.677 | Q16: -8328.3999 | R16: -1361.7425 | S16: 8096.5412 | T16: 20394.351 | U16: 41923.303
A17: Amount available for appropriation | B17: =B15+B16 -> 26970.633 | C17: =C15+C16 -> 34321.32 | D17: =D15+D16 -> 45586.21 | E17: =E15+E16 -> 51422.94 | F17: =F15+F16 -> 74155.45 | G17: =G15+G16 -> 80103.558 | H17: =H15+H16 -> 93650.897 | I17: =I15+I16 -> 116646.95 | ... U17: =U15+U16 -> 109007.97
A18: Appropriations:
A19: Tranfer to statutory reserve | B19: 406.8 | C19: 1647.13 | D19: 3256.37 | E19: 2394.92 | F19: 6215.36 | G19: 6771.7167 | H19: 7879.6978 | I19: 9444.38 | J19: 11445.96 | K19: 15684.72 | L19: 1982.8 | M19: 4048.2 | N19: 5834.9 | O19: 7974.2 | P19: 10222.1 | Q19: 4538.1761 | R19: 6287.8379 | S19: 9769.0269 | T19: 15370.4 | U19: 18716.883
A20: Transfer to reserve fund | B20: 38.65 | C20: 0 | D20: 609.19 | E20: 841 | F20: 968.13 | G20: 90.2672 | H20: 0 | I20: 0 | J20: 500 | K20: 3000 | L20: 0.367 | M20: 1090 | N20: 1500 | O20: 0 | P20: 0 | Q20: 8254.9135 | R20: 0 | S20: 0
A21: Transfer to Investment reserve | B21: 0 | C21: 0 | D21: 148.5 | E21: -148.5 | F21: 242.29 | G21: 4893.3585 | H21: 0 | I21: 233.13 | J21: -294.79 | K21: 529.42 | L21: 0 | M21: 0 | N21: 0 | O21: 0 | P21: 0 | Q21: 0 | R21: 0 | S21: 0
A22: Transfer to capital reserve | B22: 340.5245 | C22: 848.24 | D22: 441.04 | E22: 67.84 | F22: 139.55 | G22: 1646.9504 | H22: 0 | I22: 666.47 | J22: 4.62 | K22: 4166.41 | L22: 395.44 | M22: 130.23 | N22: 1574.2037 | O22: 87.82 | P22: 33.25 | Q22: 0 | R22: 1465.1242 | S22: 538.1524 | T22: 232.8084 | U22: 326.2104
A23: Transfer to general reserve | B23: 3.4138 | C23: 18.49 | D23: 2.32 | E23: 2.46 | F23: 2.47 | G23: 2625.7315 | H23: 3111.6525 | I23: 3696.14 | J23: 4410.87 | K23: 6081.23 | L23: 796.63 | M23: 1500 | N23: 0 | O23: 2625.4 | P23: 3135.3 | Q23: 0 | R23: -307.4807 | S23: 1783.6804 | T23: 3854.2653 | U23: 6456.9182
A24: Transfer to Investment fluctuation reserve | B24: 328 | C24: 326 | D24: 455 | E24: 73 | F24: 879 | G24: 1123.846 | H24: 2219.6842 | I24: 0 | J24: 82 | K24: 378 | L24: 669 | M24: -249.5799 | N24: 382.8798 | O24: 104.381 | P24: 992.79 | Q24: 0 | R24: 1928.1963 | S24: 4647.8702 | T24: 4575.4343 | U24: -749.0805
A25: Transfer to/from reserve fund | B25: 0.8502 | C25: 42.23 | D25: 69.3 | E25: 115.83 | F25: 119.5 | G25: 0 | H25: 61.6645 | I25: -48.34 | J25: -62.65 | K25: -288.28 | L25: 68.6312 | M25: -7.7638 | N25: 0 | O25: 5025.568 | P25: 87.234 | Q25: 0 | R25: 0 | S25: 0 | T25: 0 | U25: 0
A26: Dividend paid | B26: 331.8569 | C26: 0 | D26: 0 | E26: 307.14 | F26: 307.98 | G26: 1134 | H26: 1712 | I26: 3592.4 | J26: 8604.52 | K26: 8404.42 | L26: 645.3078 | M26: 0 | N26: 1385.2335 | O26: 3479.4463 | P26: 5598.5964 | Q26: 8.0552 | R26: 3559.8446 | S26: 6336.4742 | T26: 10084.811 | U26: 12226.718
A27: Balance in P&L c/d | B27: 25520.538 | C27: 31439.23 | D27: 40604.49 | E27: 47769.25 | F27: 65281.17 | G27: 61817.688 | H27: 78594.198 | I27: 99062.77 | J27: 120369.35 | K27: 150045.57 | L27: 26799.996 | M27: 31009.066 | N27: 43671.339 | O27: 65638.677 | P27: 89825.78 | Q27: -1361.7425 | R27: 8096.5412 | S27: 20394.351 | T27: 41923.303 | U27: 72019.179
A28: Corporate dividend tax paid | L28: 228.2446 | M28: 0 | N28: 0 | O28: 0 | P28: 0 | Q28: 0 | R28: 3.6516 | S28: 0.8664 | T28: 1.5013 | U28: 11.1401
A29: Total of Appropriations | B29: =SUM(B19:B27) -> 26970.633 | C29: =SUM(C19:C27) -> 34321.32 | D29: =SUM(D19:D27) -> 45586.21 | E29: =SUM(E19:E27) -> 51422.94 | F29: =SUM(F19:F27) -> 74155.45 | G29: =SUM(G19:G27) -> 80103.558 | H29: =SUM(H19:H27) -> 93578.897 | I29: =SUM(I19:I27) -> 116646.95 | ... K29: =SUM(K19:K27) -> 188001.49 | L29: =SUM(L19:L28) -> 31586.416 | M29: =SUM(M19:M28) -> 37520.152 | N29: =SUM(N19:N28) -> 54348.556 | O29: =SUM(O19:O28) -> 84935.492 | P29: =SUM(P19:P28) -> 109895.05 | Q29: =SUM(Q19:Q28) -> 11439.402 | R29: =SUM(R19:R28) -> 21033.715 | S29: =SUM(S19:S28) -> 43470.421 | ... U29: =SUM(U19:U28) -> 109007.97
A30: Earnings Per equity share
A31: Basic | B31: 6.83 | C31: 24.19 | D31: 46.04 | E31: 35.2 | F31: 85.62 | G31: 49.84 | H31: 57.88 | I31: 68.77 | J31: 82.64 | K31: 90.42 | L31: 14.81 | M31: 24.01 | N31: 33.66 | O31: 48.86 | P31: 63.19 | Q31: 22.15 | R31: 25.11 | S31: 39.64 | T31: 62.35 | U31: 75.17
A32: Market prices | B32: 495.05 | C32: 706.3 | D32: =760 -> 760 | E32: =864 -> 864 | F32: =1052.35 -> 1052.35 | G32: 1128 | H32: 1499.4 | I32: 1476.4 | J32: 1607.55 | K32: =1458 -> 1458 | L32: 394.15 | M32: 587.7 | N32: 726.4 | O32: 877.6 | P32: 1097 | Q32: 213.1 | R32: 367.7 | S32: 491 | T32: 524.75 | U32: 759.05
B33: =B5-B9 -> 25719.74 | C33: =C5-C9 -> 29769.98 | D33: =D5-D9 -> 33923.4 | E33: =E5-E9 -> 44059.22 | F33: =F5-F9 -> 51368.31 | G33: =G5-G9 -> 60051.87 | H33: =H5-H9 -> 69304.813 | I33: =I5-I9 -> 77352.08 | ... U33: =U5-U9 -> 179452.46
A34: P/E | B34: =B32/'Income Statement-Banks'!B31 -> 72.481698 | C34: =C32/'Income Statement-Banks'!C31 -> 29.198016 | D34: =D32/'Income Statement-Banks'!D31 -> 16.507385 | E34: =E32/'Income Statement-Banks'!E31 -> 24.545455 | F34: =F32/'Income Statement-Banks'!F31 -> 12.290937 | G34: =G32/'Income Statement-Banks'!G31 -> 22.632424 | H34: =H32/'Income Statement-Banks'!H31 -> 25.905321 | I34: =I32/'Income Statement-Banks'!I31 -> 21.468664 | ... U34: =U32/'Income Statement-Banks'!U31 -> 10.097778
A35: P/B | B35: =B32/('Balance Sheet-Banks'!B9/'Company Profile'!$D$14) -> 1.7770294 | C35: =C32/('Balance Sheet-Banks'!C9/'Company Profile'!$D$14) -> 2.1123143 | D35: =D32/('Balance Sheet-Banks'!D9/'Company Profile'!$D$14) -> 1.9899633 | E35: =E32/('Balance Sheet-Banks'!E9/'Company Profile'!$D$14) -> 2.0597585 | F35: =F32/('Balance Sheet-Banks'!F9/'Company Profile'!$D$14) -> 2.0732268 | G35: =G32/('Balance Sheet-Banks'!G9/'Company Profile'!$D$14) -> 1.9784497 | H35: =H32/('Balance Sheet-Banks'!H9/'Company Profile'!$D$14) -> 2.2111267 | I35: =I32/('Balance Sheet-Banks'!I9/'Company Profile'!$D$14) -> 1.8471462 | ... U35: =U32/('Balance Sheet-Banks'!U9/'Company Profile'!$D$14) -> 0.54710424
A36: Market Cap | B36: =B32*'Company Profile'!$D$14 -> 153631.24 | C36: =C32*'Company Profile'!$D$14 -> 219189.47 | D36: =D32*'Company Profile'!$D$14 -> 235854.45 | E36: =E32*'Company Profile'!$D$14 -> 268129.27 | F36: =F32*'Company Profile'!$D$14 -> 326580.83 | G36: =G32*'Company Profile'!$B$14 -> 1734486.1 | H36: =H32*'Company Profile'!$B$14 -> 2305574.9 | I36: =I32*'Company Profile'!$B$14 -> 2270208.6 | J36: =J32*'Company Profile'!$B$14 -> 2471873.4 | K36: =K32*'Company Profile'!$B$14 -> 2241915.6 | L36: =L32*'Company Profile'!$C$14 -> 281533.11 | M36: =M32*'Company Profile'!$C$14 -> 419781.83 | N36: =N32*'Company Profile'!$C$14 -> 518852.34 | O36: =O32*'Company Profile'!$C$14 -> 626851.34 | P36: =P32*'Company Profile'!$C$14 -> 783564.17 | Q36: =Q32*'Company Profile'!$E$14 -> 196704.45 | R36: =R32*'Company Profile'!$E$14 -> 339409.79 | S36: =S32*'Company Profile'!$E$14 -> 453223.29 | T36: =T32*'Company Profile'!$E$14 -> 484376.63 | U36: =U32*'Company Profile'!$E$14 -> 700649.98

Sheet Income Statement-NBFCs
A1: INCOME STATEMENT
A2: Particulars | B2: #VALUE! | G2: #VALUE! | L2: #VALUE!
B3: 2020 | C3: 2021 | D3: 2022 | E3: 2023 | F3: 2024 | G3: 2020 | H3: 2021 | I3: 2022 | J3: 2023 | K3: 2024 | L3: 2020 | M3: 2021 | N3: 2022 | O3: 2023 | P3: 2024
A4: INCOME
A5: Revenue from Operations
A6: Interest Income | B6: 2303.08 | C6: 2877.43 | D6: 3481.75 | E6: 5269.24 | F6: 7202.36 | G6: 22970.39 | H6: 23303.38 | I6: 27269.76 | J6: 35548.57 | K6: 48306.6 | L6: 94177.36 | M6: 112102.79 | N6: 119251.52 | O6: 115555.35 | P6: 145457.01
A7: Fees and commission income | B7: 100.08 | C7: 74.62 | D7: 81.85 | E7: 86.22 | F7: 138.23 | G7: 2590.95 | H7: 2452.39 | I7: 3066.69 | J7: 4355.63 | K7: 5267.17 | L7: 9.19 | M7: 0.13 | N7: 0.09 | O7: 9.41 | P7: 48.1
A8: Net gain on fair value changes | B8: 73.71 | C8: 59.85 | D8: 58.97 | E8: 112.04 | F8: 133.2 | G8: 537.49 | H8: 591.22 | I8: 327.74 | J8: 334.32 | K8: 308.29 | L8: 739.79 | M8: 1648.37 | N8: 488.74 | O8: 524.14 | P8: 640.06
A9: Sale of services | B9: 169.15 | C9: 142.15 | D9: 142.02 | E9: 50.29 | F9: 52.48 | G9: 124.27 | H9: 157.53 | I9: 74.96 | J9: 38.18 | K9: 49.97 | L9: 191.14 | M9: 120.33 | N9: 139.69 | O9: 90.7 | P9: 88.87
A10: Income on assigned. Derecongnised loans | B10: 0 | C10: 0 | D10: 0 | E10: 134.8 | F10: 53.08 | G10: 0 | H10: 0 | I10: 0 | J10: 23.17 | K10: 13.33 | L10: 779.3 | M10: 487.93 | N10: 847.74 | O10: 1403.12 | P10: 1723.34
A11: Other operating income | B11: 0 | C11: 0.65 | D11: 2.07 | E11: 12.14 | F11: 37.96 | G11: 150.7 | H11: 163.58 | I11: 893.27 | J11: 1110.29 | K11: 1024.13 | L11: 943.02 | M11: 986.08 | N11: 1121.31 | O11: 1393.91 | P11: 2659.19
A12: Total revenue from operations | B12: =SUM(B6:B11) -> 2646.02 | C12: =SUM(C5:C11) -> 3154.7 | D12: =SUM(D5:D11) -> 3766.66 | E12: =SUM(E5:E11) -> 5664.73 | F12: =SUM(F5:F11) -> 7617.31 | G12: =SUM(G5:G11) -> 26373.8 | H12: =SUM(H5:H11) -> 26668.1 | I12: =SUM(I5:I11) -> 31632.42 | J12: =SUM(J5:J11) -> 41410.16 | ... P12: =SUM(P5:P11) -> 150616.57
A13: Other Income | B13: 0.21 | C13: 0.58 | D13: 0.47 | E13: 0.71 | F13: 0.4 | G13: 11.83 | H13: 14.95 | I13: 7.99 | J13: 8.1 | K13: 13.02 | L13: 232.87 | M13: 356.33 | N13: 525.54 | O13: 773.42 | P13: 1010.85
A14: Total income | B14: =B12+B13 -> 2646.23 | C14: =C12+C13 -> 3155.28 | D14: =D12+D13 -> 3767.13 | E14: =E12+E13 -> 5665.44 | F14: =F12+F13 -> 7617.71 | G14: =G12+G13 -> 26385.63 | H14: =H12+H13 -> 26683.05 | I14: =I12+I13 -> 31640.41 | ... P14: =P12+P13 -> 151627.42
A16: EXPENSES
A17: Finance costs | B17: 1616.03 | C17: 1965.87 | D17: 2155.31 | E17: 3211.32 | F17: 4692.61 | G17: 9473.21 | H17: 9414 | I17: 9748.24 | J17: 12559.89 | K17: 18724.69 | L17: 31728.4 | M17: 40999.29 | N17: 42558.52 | O17: 42091.78 | P17: 54300.78
A18: Fees and commission expense | B18: 1.3 | C18: 1.33 | D18: 4.68 | E18: 14.03 | F18: 11.71 | G18: 1056.37 | H18: 1246.48 | I18: 1745.55 | J18: 1891.47 | K18: 1931.5 | L18: 0 | M18: 32.48 | N18: 35.19
A19: Impairment on financial instruments | B19: 124.33 | C19: 247.21 | D19: 181.07 | E19: 123.5 | F19: 60.88 | G19: 3929.48 | H19: 5968.58 | I19: 4803.4 | J19: 3189.65 | K19: 4630.7 | L19: 1870.8 | M19: 2552.15 | N19: 3835.21 | O19: 2432.22 | P19: 5538.21
A20: Employee benefit expense | B20: 248.51 | C20: 245.76 | D20: 348.8 | E20: 435.14 | F20: 465.63 | G20: 2549.08 | H20: 2498.67 | I20: 3589.66 | J20: 5100.19 | K20: 6396.01 | L20: 12084.9 | M20: 11892.72 | N20: 12394.8 | O20: 14882.68 | P20: 18282.06
A21: Depreciation and ammortization expense | B21: 23.14 | C21: 21.77 | D21: 25.76 | E21: 33.4 | F21: 39.6 | G21: 294.63 | H21: 325.27 | I21: 384.57 | J21: 485.38 | K21: 683.32 | L21: 592.42 | M21: 673.6 | N21: 700.03 | O21: 781.61 | P21: 921.06
A22: Other expenses | B22: 65.47 | C22: 60.16 | D22: 91.65 | E22: 147.99 | F22: 185.96 | G22: 1760.74 | H22: 1237.79 | I22: 1865.21 | J22: 2665.49 | K22: 3314.36 | L22: 8192.24 | M22: 8236.92 | N22: 8749 | O22: 10333.96 | P22: 12620.27
A23: Total expenses | B23: =SUM(B17:B22) -> 2078.78 | C23: =SUM(C17:C22) -> 2542.1 | D23: =SUM(D17:D22) -> 2807.27 | E23: =SUM(E17:E22) -> 3965.38 | F23: =SUM(F17:F22) -> 5456.39 | G23: =SUM(G17:G22) -> 19063.51 | H23: =SUM(H17:H22) -> 20690.79 | I23: =SUM(I17:I22) -> 22136.63 | ... P23: =SUM(P17:P22) -> 91662.38
A24: Share of profit/loss from associates | B24: 0 | C24: 0 | D24: 0 | E24: 0 | F24: 0 | G24: 0 | H24: 0 | I24: 0 | J24: 1.67 | K24: 7.64 | L24: 0 | M24: 0 | N24: 0 | O24: 0 | P24: 0
A25: Profit before tax and exceptional items | B25: =B14-B23+B24 -> 567.45 | C25: =C14-C23+C24 -> 613.18 | D25: =D14-D23+D24 -> 959.86 | E25: =E14-E23+E24 -> 1700.06 | F25: =F14-F23+F24 -> 2161.32 | G25: =G14-G23+G24 -> 7322.12 | H25: =H14-H23+H24 -> 5992.26 | I25: =I14-I23+I24 -> 9503.78 | ... P25: =P14-P23+P24 -> 59965.04
A26: Exceptional items | B26: 0 | G26: 0 | H26: 0 | I26: 0 | J26: 0 | K26: 0 | L26: 0 | M26: 0 | N26: 0 | O26: 0 | P26: 0
A27: Tax expense
A28: Current tax | B28: 126.1 | C28: 187 | D28: 250.4 | E28: 399.8 | F28: 509 | G28: 2205.25 | H28: 1660.26 | I28: 2497.45 | J28: 3998.18 | K28: 4957.72 | L28: 10779.28 | M28: 13359.62 | N28: 14110.96 | O28: 12341.19 | P28: 15807.24
A29: Deferred tax | B29: 20.02 | C29: -27.01 | D29: -0.16 | E29: 42.46 | F29: -78.9 | G29: -146.88 | H29: -87.82 | I29: -21.9 | J29: 21.99 | K29: -99.32 | L29: 137.32 | M29: -225.02 | N29: -315.12 | O29: 294.47 | P29: -512.3
A30: Tax relating to prior years | L30: 0.5 | M30: -8.5 | N30: -7.2 | O30: -105.52 | P30: -5.84
A31: Total tax expense | B31: =B28+B29 -> 146.12 | C31: =C28+C29 -> 159.99 | D31: =D28+D29 -> 250.24 | E31: =E28+E29 -> 442.26 | F31: =F28+F29 -> 430.1 | G31: =G28+G29 -> 2058.37 | H31: =H28+H29 -> 1572.44 | I31: =I28+I29 -> 2475.55 | ... K31: =K28+K29 -> 4858.4 | L31: =L28+L29+L30 -> 10917.1 | M31: =M28+M29+M30 -> 13126.1 | N31: =N28+N29+N30 -> 13788.64 | O31: =O28+O29+O30 -> 12530.14 | P31: =P28+P29+P30 -> 15289.1
A33: Profit after tax | B33: =B25-B31 -> 421.33 | C33: =C25-C31 -> 453.19 | D33: =D25-D31 -> 709.62 | E33: =E25-E31 -> 1257.8 | F33: =F25-F31 -> 1731.22 | G33: =G25+G26-G31 -> 5263.75 | H33: =H25+H26-H31 -> 4419.82 | I33: =I25+I26-I31 -> 7028.23 | J33: =J25+J26-J31 -> 11507.69 | K33: =K25+K26-K31 -> 14451.17 | L33: =L25+L26-L31 -> 31686.81 | M33: =M25+M26-M31 -> 38188.7 | N33: =N25+N26-N31 -> 40313.24 | ... P33: =P25+P26-P31 -> 44675.94
A34: Earnings Per Share
A35: Basic | B35: 1.12 | C35: 0.93 | D35: 1.45 | E35: 1.88 | F35: 2.58 | G35: 89.77 | H35: 73.58 | I35: 116.64 | J35: 190.53 | K35: 236.89 | L35: 78.3 | M35: 94.84 | N35: 100.1 | O35: 89.99 | P35: 107.72
A36: Market price | B36: 0 | C36: 0 | D36: 0 | E36: 0 | F36: 150 | G36: 364.39 | H36: 461.36 | I36: 724.05 | J36: 628.01 | K36: 689.32 | L36: 0 | M36: 0 | N36: 0 | O36: 275.3 | P36: 200.5
A38: Operating expenses | B38: =B18+B20+B21+B22+B19 -> 462.75 | C38: =C18+C20+C21+C22+C19 -> 576.23 | D38: =D18+D20+D21+D22+D19 -> 651.96 | E38: =E18+E20+E21+E22+E19 -> 754.06 | F38: =F18+F20+F21+F22+F19 -> 763.78 | G38: =G18+G20+G21+G22+G19 -> 9590.3 | H38: =H18+H20+H21+H22+H19 -> 11276.79 | I38: =I18+I20+I21+I22+I19 -> 12388.39 | ... P38: =P18+P20+P21+P22+P19 -> 37361.6
A39: Operating Income | B39: =B7+B8+B9+B10+B11+B13 -> 343.15 | C39: =C7+C8+C9+C10+C11+C13 -> 277.85 | D39: =D7+D8+D9+D10+D11+D13 -> 285.38 | E39: =E7+E8+E9+E10+E11+E13 -> 396.2 | F39: =F7+F8+F9+F10+F11+F13 -> 415.35 | G39: =G7+G8+G9+G10+G11+G13 -> 3415.24 | H39: =H7+H8+H9+H10+H11+H13 -> 3379.67 | I39: =I7+I8+I9+I10+I11+I13 -> 4370.65 | ... P39: =P7+P8+P9+P10+P11+P13 -> 6170.41
A40: P/E | B40: =B36/B35 -> 0 | C40: =C36/C35 -> 0 | D40: =D36/D35 -> 0 | E40: =E36/E35 -> 0 | F40: =F36/F35 -> 58.139535 | G40: =G36/G35 -> 4.0591512 | H40: =H36/H35 -> 6.2701821 | I40: =I36/I35 -> 6.2075617 | ... P40: =P36/P35 -> 1.8613071
A41: P/B | B41: =B36/('Balance Sheet-NBFCs'!B9/'Company Profile'!$G$14) -> 0 | C41: =C36/('Balance Sheet-NBFCs'!C9/'Company Profile'!$G$14) -> 0 | D41: =D36/('Balance Sheet-NBFCs'!D9/'Company Profile'!$G$14) -> 0 | E41: =E36/('Balance Sheet-NBFCs'!E9/'Company Profile'!$G$14) -> 0 | F41: =F36/('Balance Sheet-NBFCs'!F9/'Company Profile'!$G$14) -> 10.212051 | G41: =G36/('Balance Sheet-NBFCs'!G9/'Company Profile'!$F$14) -> 7.0055647 | H41: =H36/('Balance Sheet-NBFCs'!H9/'Company Profile'!$F$14) -> 7.7668965 | I41: =I36/('Balance Sheet-NBFCs'!I9/'Company Profile'!$F$14) -> 10.29465 | J41: =J36/('Balance Sheet-NBFCs'!J9/'Company Profile'!$F$14) -> 7.1786367 | K41: =K36/('Balance Sheet-NBFCs'!K9/'Company Profile'!$F$14) -> 5.586019 | L41: =L36/('Balance Sheet-NBFCs'!L9/'Company Profile'!$H$14) -> 0 | M41: =M36/('Balance Sheet-NBFCs'!M9/'Company Profile'!$H$14) -> 0 | N41: =N36/('Balance Sheet-NBFCs'!N9/'Company Profile'!$H$14) -> 0 | O41: =O36/('Balance Sheet-NBFCs'!O9/'Company Profile'!$H$14) -> 0.049891778 | P41: =P36/('Balance Sheet-NBFCs'!P9/'Company Profile'!$H$14) -> 0.031255071
A42: Market cap | B42: =B36*'Company Profile'!$G$14 -> 0 | C42: =C36*'Company Profile'!$G$14 -> 0 | D42: =D36*'Company Profile'!$G$14 -> 0 | E42: =E36*'Company Profile'!$G$14 -> 0 | F42: =F36*'Company Profile'!$G$14 -> 124929.12 | G42: =G36*'Company Profile'!$F$14 -> 226473.3 | H42: =H36*'Company Profile'!$F$14 -> 286741.47 | I42: =I36*'Company Profile'!$F$14 -> 450006.85 | J42: =J36*'Company Profile'!$F$14 -> 390316.69 | K42: =K36*'Company Profile'!$F$14 -> 428421.69 | L42: =L36*'Company Profile'!$H$14 -> 0 | M42: =M36*'Company Profile'!$H$14 -> 0 | N42: =N36*'Company Profile'!$H$14 -> 0 | O42: =O36*'Company Profile'!$H$14 -> 11052.428 | P42: =P36*'Company Profile'!$H$14 -> 8049.4434

Sheet Cash Flow Statement-Banks
A1: CASH FLOW STATEMENT
A2: Particulars | B2: #VALUE! | G2: #VALUE! | L2: #VALUE! | Q2: #VALUE!
B3: 2020 | C3: 2021 | D3: 2022 | E3: 2023 | F3: 2024 | G3: 2020 | H3: 2021 | I3: 2022 | J3: 2023 | K3: 2024 | L3: 2020 | M3: 2021 | N3: 2022 | O3: 2023 | P3: 2024 | Q3: 2020 | R3: 2021 | S3: 2022 | T3: 2023 | U3: 2024
A4: Cash flow from Operating activities
A5: Net profit before taxes | B5: 5254.4043 | C5: 9693.19 | D5: 18841.86 | E5: 18521.12 | F5: 35071.95 | G5: 38152.537 | H5: 42772.584 | I5: 50775.24 | J5: 61346.8 | K5: 75184.14 | L5: 16929.447 | M5: 20182.718 | N5: 30608.885 | O5: 45830.078 | P5: 59683.996 | Q5: 31907.559 | R5: 30921.708 | S5: 48756.343 | T5: 74488.304 | U5: 90186.447
A6: Adjustments for:
A7: Depreciation on fixed assets | B7: 806.0735 | C7: 979.39 | D7: 1048.99 | E7: 13145.65 | F7: 1388.46 | G7: 1276.7714 | H7: 1385.0062 | I7: 1680.73 | J7: 2345.47 | K7: 3092.08 | L7: 1369.6381 | M7: 1201.3384 | N7: 1316.2116 | O7: 1635.1038 | P7: 1995.8856 | Q7: 3661.5585 | R7: 3711.0636 | S7: 3691.27 | T7: 3695.5986 | U7: 3849.1245
A8: Depreciation on investments | B8: 135.9912 | C8: 1329.08 | D8: -264.48 | E8: 595.57 | F8: -431.32 | G8: 702.1095 | H8: 1485.3243 | I8: -1546.4 | J8: 545.82 | K8: -6957.14 | L8: 2180.9159 | M8: -2214.3504 | N8: 1908.9256 | O8: 2705.3455 | P8: 1617.2037 | Q8: 626.5221 | R8: 5.1548 | S8: 445.7369 | T8: 0 | U8: 0
A9: Ammortisation of premium on held to maturity | B9: 354.6142 | C9: 592.12 | D9: 823.78 | E9: 889.11 | F9: 894.18 | G9: 501.4137 | H9: 765.4693 | I9: 821.32 | J9: 851.2 | K9: 966.09 | L9: 0 | M9: 0 | N9: 0 | O9: 0 | P9: 0 | Q9: 0 | R9: 0 | S9: 0 | T9: 0 | U9: 0
A10: Provision for Non performing assets | B10: 12835.295 | C10: 12344.85 | D10: 7580.8 | E10: 6225.9 | F10: 6533.43 | G10: 11065.713 | H10: 13927.011 | I10: 13286.95 | J10: 13561.19 | K10: 12540.05 | L10: 8962.7398 | M10: 10749.126 | N10: 6164.0412 | O10: -365.3501 | P10: 963.5716 | Q10: 43848.89 | R10: =29732.6529+2820.9883 -> 32553.641 | S10: =15845.8997+3471.788 -> 19317.688 | T10: =10826.8816+1483.8759 -> 12310.757 | U10: =12241.867-604.1107 -> 11637.756
A11: Provision on standard assets | B11: 1534.1633 | C11: 3322.61 | D11: 2224.17 | E11: -421.94 | F11: 424.15 | G11: 3057.4317 | H11: 5283.0711 | I11: 5418.21 | J11: 292.89 | K11: 1578.23 | L11: 3443.9929 | M11: 278.8318 | N11: 449.2475 | O11: 489.8941 | P11: 1165.8491 | Q11: -291.3652 | R11: 3601.3226 | S11: 4581.8142 | T11: 5641.5051 | U11: -1264.4725
A12: Profit/Loss on sale of land, buildings and other assets | B12: 5.0818 | C12: 8.77 | D12: 6.11 | E12: 7.69 | F12: 4.42 | G12: 8.1865 | H12: 0.2859 | I12: 3.25 | J12: -8.05 | K12: -75.36 | L12: -0.145 | M12: 2.7974 | N12: -4.04 | O12: -54.2579 | P12: -14.4093 | Q12: 28.3375 | R12: 28.3364 | S12: 16.4047 | T12: 29.0316 | U12: 25.2054
A13: Profit/Loss on revaluation of investments | T13: 4922.6098 | U13: -4892.7872
A14: Income from subsidiaries, joint ventures and entities | B14: 12.1721 | C14: 0 | D14: 0 | E14: 0 | F14: 0 | G14: 0 | H14: 0 | I14: 0 | J14: 0 | K14: 0 | L14: 0 | M14: -1233.995 | N14: -1828.7906 | O14: 0 | P14: 0 | Q14: -5573.6296 | R14: =-1577.8431+254.4131 -> -1323.43 | S14: =-9.7432 -> -9.7432 | T14: 0 | U14: 0
A15: Provision for restructured assets/ strategic debt restructuring | B15: -15.498 | C15: 0 | D15: 0 | E15: 0 | F15: 0 | G15: 0 | H15: 0 | I15: 0 | J15: 0 | K15: -7341.42 | L15: 0 | M15: 0 | N15: 0 | O15: 0 | P15: 0 | Q15: 4908.0907 | R15: 5900.3121 | S15: 5587.8874 | T15: 6543.7306 | U15: 9661.5237
A16: Provision on unhedged foreign currency exposure | B16: -10.68 | C16: 0 | D16: 0 | E16: 0 | G16: 0 | H16: 0 | I16: 0 | J16: 0 | K16: 0 | L16: 0 | M16: 0 | N16: 0 | O16: 0 | P16: 0
A17: Provision for other contingencies | B17: 4224.4858 | C17: 0 | D17: 0 | F17: 0 | G17: 0 | H17: 0 | I17: 0 | J17: 0 | K17: 10900 | L17: 793.6906 | M17: 5344.2673 | N17: 1651.0217 | O17: 5423.6861 | P17: 878.0202 | Q17: 604.6549 | R17: 9947.1949 | S17: 2777.1833 | T17: 232.0148 | U17: -2668.3083
A18: Employee stock exchange expense | B18: 0 | C18: 0 | D18: 150.77 | E18: 286.02 | F18: 519.57 | G18: 0 | H18: 0 | I18: 341.24 | J18: 787.06 | K18: 1731.73 | L18: 11.413 | M18: 0 | N18: 264.219 | O18: 518.0508 | P18: 702.9081 | Q18: =-2963.1404-14.6677 -> -2977.8081 | R18: =391.9045-3.195 -> 388.7095 | S18: =-827.0133-3.195 -> -830.2083 | T18: =-1191.4521-2.6625 -> -1194.1146 | U18: =-1405.1543-5.5719 -> -1410.7262
A19: Adjustments for:
A20: Increase/Decrease in investments | B20: 24432.47 | C20: -19644 | D20: -24189.72 | E20: 4622.29 | F20: -38129.02 | G20: -101070.1 | H20: -50156.636 | I20: -10849.22 | J20: -64182.03 | K20: -88411.63 | L20: -31531.315 | M20: 24066.691 | N20: 4431.1642 | O20: -15828.629 | P20: 16735.535 | Q20: -100670.42 | R20: -368800.15 | S20: -183899.64 | T20: -141597.38 | U20: -190457.11
A21: Increase/decrease in advances | B21: -86703.113 | C21: -63518.12 | D21: -106571.94 | E21: -149553.15 | F21: -137622.1 | G21: -185500.36 | H21: -155681.07 | I21: -248946.13 | J21: -254569.45 | K21: -309210.7 | L21: -69243.415 | M21: -99494.736 | N21: -131475.82 | O21: -163893.16 | P21: -178264.48 | Q21: -191306.4 | R21: -156020.46 | S21: -309322.91 | T21: -484653.01 | U21: -528612.41
A22: increase/decrease in deposits | B22: 91411.273 | C22: 65466.21 | D22: 122611.53 | E22: 125161.2 | F22: 121277.69 | G22: 223704.46 | H22: 187513.74 | I22: 224282.15 | J22: 324660.22 | K22: 336964.81 | L22: 119467.52 | M22: 161553.17 | N22: 132049.45 | O22: 119466.36 | P22: 232993.01 | Q22: 333619.56 | R22: 441170.62 | S22: 372079.36 | T22: 381124.91 | U22: 498001.98
A23: Increase/decrease in other assets | B23: -26522.351 | C23: 4801.71 | D23: 2920.04 | E23: 2968.61 | F23: 9145.17 | G23: -7249.7457 | H23: 8307.684 | I23: -40044.7 | J23: -58909.79 | K23: -31197.26 | L23: 2456.0834 | M23: 1077.3799 | N23: 5072.7916 | O23: -16597.135 | P23: 1881.8794 | Q23: -21857.443 | R23: -66249.946 | S23: 5255.8279 | T23: -60531.723 | U23: -46236.906
A24: Increase/Decrease in borrowings other than capital instruments | Q24: -89342.809 | R24: 90438.852 | S24: 11807.876 | T24: 54584.073 | U24: 112581.11
A25: Increase/decrease in other liabilities & provisions | B25: 5698.2825 | C25: -715.93 | D25: 7401.45 | E25: 6313.23 | F25: 2599.86 | G25: 9359.8719 | H25: -104.56 | I25: 7655.94 | J25: 10459.86 | K25: 6420.4 | L25: 27116.069 | M25: 5082.0785 | N25: 8133.4402 | O25: 27774.253 | P25: 30289.317 | Q25: 31602.728 | R25: 67465.501 | S25: 86464.266 | T25: 75713.74 | U25: 102500.28
A26: Direct taxes paid | B26: -3037.0292 | C26: -2027 | D26: -4446.06 | E26: -6686.52 | F26: -7231.11 | G26: -10877.375 | H26: -13021.453 | I26: -14838.16 | J26: -16367.49 | K26: -22842.84 | L26: -2391.8931 | M26: -2501.9557 | N26: -3693.8225 | O26: -10875.426 | P26: -13343.605 | Q26: -14859.491 | R26: -3819.4934 | S26: -9024.303 | T26: -17323.722 | U26: -31268.268
A27: Increase in policy holder's funds | K27: 35728.16 | L27: 0 | M27: 0 | N27: 0 | O27: 0 | P27: 0 | Q27: 0 | R27: 0 | S27: 0 | T27: 0 | U27: 0
A28: Net cash flow from operating activities | B28: =SUM(B5,B7:B17,B20:B26) -> 30415.636 | C28: =SUM(C5,C7:C17,C20:C26) -> 12632.88 | D28: =SUM(D5,D7:D18,D20:D26) -> 28137.3 | E28: =SUM(E5,E7:E18,E20:E26) -> 22074.78 | F28: =SUM(F5,F7:F18,F20:F26) -> -5554.67 | G28: =SUM(G5,G7:G18,G20:G26) -> -16869.092 | H28: =SUM(H5,H7:H18,H20:H26) -> 42476.456 | I28: =SUM(I5,I7:I18,I20:I26) -> -11959.58 | J28: =SUM(J5,J7:J18,J20:J26) -> 20813.7 | K28: =SUM(K5,K7:K18,K20:K27) -> 19069.34 | L28: =SUM(L5,L7:L18,L20:L26) -> 79564.747 | M28: =SUM(M5,M7:M18,M20:M26) -> 124093.36 | N28: =SUM(N5,N7:N18,N20:N26) -> 55046.925 | O28: =SUM(O5,O7:O18,O20:O26) -> -3771.1921 | P28: =SUM(P5,P7:P18,P20:P26) -> 157284.68 | Q28: =SUM(Q5,Q7:Q18,Q20:Q26) -> 23928.532 | R28: =SUM(R5,R7:R18,R20:R26) -> 89918.93 | S28: =SUM(S5,S7:S18,S20:S26) -> 57694.846 | ... U28: =SUM(U5,U7:U18,U20:U26) -> 21632.431
A30: Cash flow from Investing activities
A31: Purchase of fixed assets | B31: -1104.2694 | C31: -938.44 | D31: -1408.97 | E31: -1389.42 | F31: -2385.41 | G31: -1635.8706 | H31: -1696.146 | I31: -2236.24 | J31: -3466.57 | K31: -4286.72 | L31: -1873.4522 | M31: -1430.1487 | N31: -1610.9856 | O31: -2467.6808 | P31: -3678.5464 | Q31: -3065.0113 | R31: =-3909.825+81.8047 -> -3828.0203 | S31: =-3305.2601+254.3431 -> -3050.917 | T31: -4043.6315 | U31: -4175.1262
A32: Increase/decrease in held to maturity investments | B32: -8581.9362 | C32: -53269.93 | D32: -25830.38 | E32: -19714.15 | F32: -6381.97 | G32: 0 | H32: 0 | I32: 0 | J32: 0 | K32: 0 | L32: -40460.513 | M32: -57037.844 | N32: -38089.5 | O32: -65825.059 | P32: -142322.44 | Q32: -6031.0606 | R32: 0 | S32: 0 | T32: 0 | U32: 0
A33: Proceeds from sale of fixed assets | B33: 27.3426 | C33: 13.55 | D33: 7.25 | E33: 11.73 | F33: 9.07 | G33: 18.9462 | H33: 15.2809 | I33: 19.91 | J33: 42.68 | K33: 99.82 | L33: 25.5374 | M33: 5.6622 | N33: 20.8665 | O33: 287.4176 | P33: 69.8893 | Q33: 0 | R33: 0 | S33: 0 | T33: 0 | U33: 0
A34: Purchase consideration for acquisition | B34: 0 | C34: 0 | D34: 0 | E34: -11602.54 | F34: -329.85 | G34: 0 | H34: 0 | I34: 0 | J34: 0 | L34: 0 | M34: 0 | N34: 0 | O34: 0 | P34: 0 | Q34: 184.0819 | R34: -3176.9416 | S34: -582.764 | T34: 0 | U34: -82.161
A35: Dividend from associates | Q35: 0 | R35: 3.195 | S35: 3.195 | T35: 2.6625 | U35: 5.5719
A36: Income from subsidiaries, joint ventures and entities | L36: 0 | M36: 1233.995 | N36: 1828.7906 | O36: 0 | P36: 0 | Q36: 14.6677 | R36: =1577.8431-254.4131 -> 1323.43 | S36: 9.7432 | T36: 0 | U36: 0
A37: Proceeds from sale of investment in subsidiaries | K37: 9500.67 | L37: 0 | M37: 3736.9338 | N37: 2815.38 | O37: 0 | P37: 0 | Q37: 5573.6296 | R37: 1942.1097 | S37: 2.2296 | T37: 0 | U37: 0
A38: Net cash generated from/to investing activities | B38: =SUM(B31:B34) -> -9658.863 | C38: =SUM(C31:C34) -> -54194.82 | D38: =SUM(D31:D34) -> -27232.1 | E38: =SUM(E31:E34) -> -32694.38 | F38: =SUM(F31:F34) -> -9088.16 | G38: =SUM(G31:G34) -> -1616.9244 | H38: =SUM(H31:H34) -> -1680.8651 | I38: =SUM(I31:I34) -> -2216.33 | J38: =SUM(J31:J34) -> -3423.89 | K38: =SUM(K31:K37) -> 5313.77 | L38: =SUM(L31:L37) -> -42308.428 | M38: =SUM(M31:M37) -> -53491.402 | N38: =SUM(N31:N37) -> -35035.448 | O38: =SUM(O31:O37) -> -68005.322 | P38: =SUM(P31:P37) -> -145931.09 | Q38: =SUM(Q31:Q37) -> -3323.6927 | R38: =SUM(R31:R37) -> -3736.2272 | ... U38: =SUM(U31:U37) -> -4251.7153
A40: Cash flow from Financing activities
A41: Proceeds/repayment from issue of subordinated debt, perpetual debt & upper tier II instruments | B41: -2000 | C41: 0 | D41: -2377.45 | E41: =12382.65-6000 -> 6382.65 | F41: 0 | G41: 743.5 | H41: =356.5-1105 -> -748.5 | I41: =8312.75-3650 -> 4662.75 | J41: =23000-12077 -> 10923 | K41: =2350-230 -> 2120 | L41: 0 | M41: 0 | N41: 0 | O41: 0 | P41: 0 | Q41: =8495.818-4908.0907 -> 3587.7273 | R41: =27431-16897.664-5069.1088 -> 5464.2272 | S41: =14074-10518.3-5411.0089 -> -1855.3089 | T41: =19533.0925-2125-6324.6256 -> 11083.467 | U41: =20164.6479-14288.2-8589.2532 -> -2712.8053
A42: Increase/decrease in borrowings (net) | B42: -4069.6631 | C42: -2931.44 | D42: 49906.9 | E42: 52.76 | F42: 21985.98 | G42: 28358.044 | H42: -8389.0744 | I42: 44308.08 | J42: 18007.29 | K42: -7342.84 | L42: =36611.4451-52000.6249+18718.421 -> 3329.2412 | M42: =15208.9846-37729.0832-48875.2518 -> -71395.35 | N42: =25260.1665-23314.4678+13509.5945 -> 15455.293 | O42: =41736.1966-26891.7978+12483.696 -> 27328.095 | P42: =39196.8191-39146.8771+18142.3005 -> 18192.243 | Q42: 0 | R42: 0 | S42: 0
...

Sheet Cash Flow Statement-NBFCs
A1: CASH FLOW STATEMENT
A2: Particulars | B2: #VALUE! | G2: #VALUE! | L2: #VALUE!
B3: 2020 | C3: 2021 | D3: 2022 | E3: 2023 | F3: 2024 | G3: 2020 | H3: 2021 | I3: 2022 | J3: 2023 | K3: 2024 | L3: 2020 | M3: 2021 | N3: 2022 | O3: 2023 | P3: 2024
A4: CASH FLOW FROM OPERATING ACTIVITIES
A5: Profit before tax | B5: 567.45 | C5: 613.18 | D5: 959.86 | E5: 1700.06 | F5: 2161.32 | G5: 7322.12 | H5: 5992.26 | I5: 9503.78 | J5: 15527.86 | K5: 19309.57 | L5: 42603.91 | M5: 51314.8 | N5: 54101.87 | O5: 49227.8 | P5: 59965.04
A6: Adjustments for:
A7: Interest income | B7: -2303.08 | C7: -2877.43 | D7: -3481.75 | E7: -5269.24 | F7: -7202.36 | G7: -22970.39 | H7: -23303.38 | I7: -27269.76 | J7: -35548.57 | K7: -48306.6 | L7: -474.33 | M7: -1154.55 | N7: -1799.91 | O7: -2665.79 | P7: -3369.08
A8: Depreciation and ammortization | B8: 23.14 | C8: 21.77 | D8: 25.76 | E8: 33.4 | F8: 39.6 | G8: 294.63 | H8: 325.27 | I8: 384.57 | J8: 485.38 | K8: 683.32 | L8: 592.42 | M8: 673.6 | N8: 700.03 | O8: 781.61 | P8: 921.06
A9: Impairment on financial instruments | B9: 124.33 | C9: 247.21 | D9: 181.07 | E9: 123.5 | F9: 60.88 | G9: 3929.48 | H9: 5968.58 | I9: 4803.4 | J9: 3189.65 | K9: 4630.7 | L9: 1870.8 | M9: 2552.15 | N9: 3835.21 | O9: 2420.07 | P9: 5538.21
A10: Finance costs | B10: 1616.03 | C10: 1965.87 | D10: 2155.31 | E10: 3211.32 | F10: 4692.61 | G10: 9473.21 | H10: 9414 | I10: 9748.24 | J10: 12559.89 | K10: 18724.69 | L10: 31728.4 | M10: 40999.29 | N10: 42558.52 | O10: 42091.78 | P10: 54300.78
A11: Dividend income | B11: 0 | C11: 0 | D11: 0 | E11: 0 | F11: 0 | G11: -0.64 | H11: 0 | I11: 0 | J11: -1.67 | K11: -7.64 | L11: -9.19 | M11: -0.13 | N11: -0.09 | O11: -9.41 | P11: -48.1
A12: Profit/loss on disposal of PPE (Fixed assets) | B12: 0.49 | C12: 0.44 | D12: 0.48 | E12: 0.7 | F12: 0.77 | G12: 2.29 | H12: 6.85 | I12: 24.84 | J12: 13.33 | K12: 12.54 | L12: -0.11 | M12: -7.19 | N12: -7.9 | O12: -2.39 | P12: -6.39
A13: Service fees for management of assigned portfolio of loans | B13: -129.81 | C13: -103.74 | D13: -112.53 | E13: -22.49 | F13: -37.11 | G13: -124.27 | H13: -157.53 | I13: -74.96 | J13: -38.18 | K13: -49.97 | L13: 0 | M13: 0 | N13: 0 | O13: 0 | P13: 0
A14: Share based payments to employees | B14: 7.05 | C14: 13.36 | D14: 19.23 | E14: 0 | F14: 0 | G14: 100.76 | H14: 124.75 | I14: 161.03 | J14: 224.41 | K14: 268.23 | L14: 31.03 | M14: 14.04 | N14: -1.98 | O14: 0 | P14: 0
A15: Provision for gratuity | L15: 176.21 | M15: 159.52 | N15: 172.74 | O15: 145.71 | P15: 161.02
A16: Provision for compensated absences | L16: 137.78 | M16: 17.52 | N16: -32.34 | O16: 31.16 | P16: -13.55
A17: Provision for refund of interest | L17: 0 | M17: 19 | N17: 4.55 | O17: 0 | P17: 0
A18: Profit/Loss on sale of mutual funds | L18: -707.46 | M18: -1618.18 | N18: -492.84 | O18: -716.5 | P18: -1022.58
