Workbook

Sheet Company Profile
A1: COMPANY PROFILE
A2: Logo | B2: #VALUE! | C2: #VALUE! | D2: #VALUE! | E2: #VALUE! | F2: #VALUE!
A3: Company name | B3: Tata Consultancy Services | C3: Infosys | D3: HCL Technologies | E3: Wipro | F3: LT Mindtree
A4: Listed Name | B4: #VALUE! | C4: #VALUE! | D4: #VALUE! | E4: #VALUE! | F4: #VALUE!
A5: Ticker symbol | B5: {=_FV(B4,"Ticker symbol",TRUE)} -> TCS | C5: {=_FV(C4,"Ticker symbol",TRUE)} -> INFY | D5: {=_FV(D4,"Ticker symbol",TRUE)} -> HCLTECH | E5: {=_FV(E4,"Ticker symbol",TRUE)} -> WIPRO | F5: {=_FV(F4,"Ticker symbol",TRUE)} -> LTIM
A6: Industry | B6: {=_FV(B4,"Industry")} -> Software & IT Services | C6: {=_FV(C4,"Industry")} -> Software & IT Services | D6: {=_FV(D4,"Industry")} -> Software & IT Services | E6: {=_FV(E4,"Industry")} -> Software & IT Services | F6: {=_FV(F4,"Industry")} -> Software & IT Services
A7: Employees | B7: {=_FV(B4,"Employees")} -> 613069 | C7: {=_FV(C4,"Employees")} -> 331991 | D7: {=_FV(D4,"Employees")} -> 226640 | E7: {=_FV(E4,"Employees")} -> 235492 | F7: {=_FV(F4,"Employees")} -> 86447
A8: In crores | B8: 0.0613 | C8: 0.0323578 | D8: 0.0218621 | E8: 0.023 | F8: 0.0083889
A9: Share Price | B9: {=_FV(B4,"Price")} -> 3025.2 | C9: {=_FV(C4,"Price")} -> 1513.5 | D9: {=_FV(D4,"Price")} -> 1540.5 | E9: {=_FV(E4,"Price")} -> 239.84 | F9: {=_FV(F4,"Price")} -> 5650
A10: Outstanding shares | B10: {=_FV(B4,"Shares outstanding",TRUE)} -> 3618087000 | C10: {=_FV(C4,"Shares outstanding",TRUE)} -> 4145310000 | D10: {=_FV(D4,"Shares outstanding",TRUE)} -> 2705510000 | E10: {=_FV(E4,"Shares outstanding",TRUE)} -> 10472250000 | F10: {=_FV(F4,"Shares outstanding",TRUE)} -> 296468400
A11: In Crores | B11: 361.81 | C11: 414.46 | D11: 270.89 | E11: 1047.087 | F11: 29.633
A12: Market cap (INR) | B12: {=_FV(B4,"Market cap",TRUE)} -> 10824590000000 | C12: {=_FV(C4,"Market cap",TRUE)} -> 6121794000000 | D12: {=_FV(D4,"Market cap",TRUE)} -> 4091814000000 | E12: {=_FV(E4,"Market cap",TRUE)} -> 2476583000000 | F12: {=_FV(F4,"Market cap",TRUE)} -> 1650588000000
A13: In crores | B13: =B12/10000000 -> 1082459 | C13: =C12/10000000 -> 612179.4 | D13: =D12/10000000 -> 409181.4 | E13: =E12/10000000 -> 247658.3 | F13: =F12/10000000 -> 165058.8
A14: Conversion | B14: #VALUE! | C14: #VALUE! | D14: #VALUE! | E14: #VALUE! | F14: #VALUE!
B15: {=_FV(B14,"Price")} -> 0.01127 | C15: {=_FV(C14,"Price")} -> 0.01127 | D15: {=_FV(D14,"Price")} -> 0.01127 | E15: {=_FV(E14,"Price")} -> 0.01127 | F15: {=_FV(F14,"Price")} -> 0.01127
A16: In USD | B16: =B12*B15 -> 121993129300 | C16: =C12*C15 -> 68992618380 | D16: =D12*D15 -> 46114743780 | E16: =E12*E15 -> 27911090410 | F16: =F12*F15 -> 18602126760
A17: Beta | B17: {=_FV(B4,"Beta")} -> 0.9429 | C17: {=_FV(C4,"Beta")} -> 0.8999 | D17: {=_FV(D4,"Beta")} -> 1.0408 | E17: {=_FV(E4,"Beta")} -> 0.8684 | F17: {=_FV(F4,"Beta")} -> 1.3531
A18: Change (%) | B18: {=_FV(B4,"Change (%)",TRUE)} -> 0.011164 | C18: {=_FV(C4,"Change (%)",TRUE)} -> 0.024851 | D18: {=_FV(D4,"Change (%)",TRUE)} -> 0.01858 | E18: {=_FV(E4,"Change (%)",TRUE)} -> 0.014166 | F18: {=_FV(F4,"Change (%)",TRUE)} -> 0.014818

Sheet Balance Sheet
A1: Consolidated Balance Sheet | E1: #VALUE! | H1: Consolidated Balance Sheet | L1: #VALUE! | O1: Consolidated Balance Sheet | S1: #VALUE! | V1: Consolidated Balance Sheet | Z1: #VALUE! | AC1: Consolidated Balance Sheet | AG1: #VALUE!
A2: Particulars | B2: 2020 | C2: 2021 | D2: 2022 | E2: 2023 | F2: 2024 | H2: Particulars | I2: 2020 | J2: 2021 | K2: 2022 | L2: 2023 | M2: 2024 | O2: Particulars | P2: 2020 | Q2: 2021 | R2: 2022 | S2: 2023 | T2: 2024 | V2: Particulars | W2: 2020 | X2: 2021 | Y2: 2022 | Z2: 2023 | AA2: 2024 | AC2: Particulars | AD2: 2020 | AE2: 2021 | AF2: 2022 | AG2: 2023 | AH2: 2024
A3: ASSETS | H3: ASSETS | O3: ASSETS | V3: ASSETS | AC3: ASSETS
A4: Non-Current Assets | H4: Non current assets | O4: Non current assets | V4: Non current assets | AC4: Non current assets
A5: Property, plant and equipment | B5: 10941 | C5: 11110 | D5: 10774 | E5: 10230 | F5: 9376 | H5: Property, plant and equipment | I5: 12435 | J5: 12560 | K5: 13075 | L5: 13346 | M5: 12370 | O5: Property, plant and equipment | P5: 5494 | Q5: 5642 | R5: 5612 | S5: 5371 | T5: 4891 | V5: Property, plant and equipment | W5: 6061.7 | X5: 6575.1 | Y5: 7461 | Z5: 8233.6 | AA5: 7412.8 | AC5: Property, plant and equipment | AD5: 403.1 | AE5: 385.7 | AF5: 918.3 | AG5: 969.7 | AH5: 1655.5
A6: Capital work-in-progress | B6: 906 | C6: 926 | D6: 1205 | E6: 1234 | F6: 1564 | H6: Right-of-use assets | I6: 4168 | J6: 4794 | K6: 4823 | L6: 6882 | M6: 6552 | O6: Capital work in progress | P6: 400 | Q6: 312 | R6: 129 | S6: 40 | T6: 108 | V6: Right-of-use assets | W6: 1674.8 | X6: 1642 | Y6: 1887 | Z6: 1870.2 | AA6: 1795.5 | AC6: Right of use asset | AD6: 769.2 | AE6: 622.1 | AF6: 1112.4 | AG6: 1253.9 | AH6: 1901.3
A7: Right-of-use assets | B7: 7994 | C7: 7633 | D7: 7636 | E7: 7560 | F7: 7886 | H7: Capital work in progress | I7: 954 | J7: 922 | K7: 416 | L7: 288 | M7: 293 | O7: Right of use assets | P7: 2648 | Q7: 2410 | R7: 2305 | S7: 2337 | T7: 2910 | V7: Capital work in progress | W7: 1881.1 | X7: 1853.2 | Y7: 1601.5 | Z7: 617.1 | AA7: 723.4 | AC7: Capital work in progress | AD7: 38.2 | AE7: 40.3 | AF7: 458.9 | AG7: 812.6 | AH7: 466.9
A8: Goodwill | B8: 1710 | C8: 1798 | D8: 1787 | E8: 1858 | F8: 1832 | H8: Goodwill | I8: 5286 | J8: 6079 | K8: 6195 | L8: 7248 | M8: 7303 | O8: Goodwill | P8: 16154 | Q8: 17192 | R8: 17417 | S8: 18567 | T8: 20132 | V8: Goodwill | W8: 12689.4 | X8: 13514.7 | Y8: 24286.1 | Z8: 30348.5 | AA8: 31144.9 | AC8: Goodwill | AD8: 636.8 | AE8: 657.4 | AF8: 1163.2 | AG8: 1189.2 | AH8: 1192.7
A9: Other Tangible assets | B9: 283 | C9: 480 | D9: 1101 | E9: 867 | F9: 510 | H9: Other intangible assets | I9: 1900 | J9: 2072 | K9: 1707 | L9: 1749 | M9: 1397 | O9: Other intangible assets | P9: 13194 | Q9: 11901 | R9: 9743 | S9: 8344 | T9: 7130 | V9: Other intangible assets | W9: 1636.2 | X9: 1308.5 | Y9: 4355.5 | Z9: 4304.5 | AA9: 3274.8 | AC9: Other tangible assets | AD9: 110.6 | AE9: 240.8 | AF9: 279 | AG9: 266.3 | AH9: 231.3
A10: Financial Assets | H10: Financial assets | O10: Financial Assets | V10: Investments accounted for using the equity method | W10: 138.3 | X10: 146.4 | Y10: 77.4 | Z10: 78 | AA10: 104.4 | AC10: Intangible assets under development | AD10: 21 | AE10: 25.9 | AF10: 43.9 | AG10: 89.7 | AH10: 83.8
A11: Investments | B11: 216 | C11: 213 | D11: 223 | E11: 266 | F11: 281 | H11: Investments | I11: 4137 | J11: 11863 | K11: 13651 | L11: 12569 | M11: 11708 | O11: Investments | P11: 77 | Q11: 89 | R11: =9+103 -> 112 | S11: 110 | T11: 94 | V11: Financial assets | AC11: Financial Assets
A12: Trade receivables | B12: 74 | C12: 55 | D12: 145 | E12: 149 | F12: 127 | H12: Loans | I12: 21 | J12: 32 | K12: 34 | L12: 39 | M12: 34 | O12: Others | P12: 2373 | Q12: 2569 | R12: 1220 | S12: 1279 | T12: 1346 | V12: Investments | W12: 930.2 | X12: 1057.6 | Y12: 1910.9 | Z12: 2072 | AA12: 2162.9 | AC12: Investments | AD12: 0.2 | AE12: 101.3 | AF12: 651.3 | AG12: 716.5 | AH12: 1990.2
A13: Unbilled receivables | B13: 324 | C13: 273 | D13: 55 | E13: 199 | F13: 16 | H13: Other financial assets | I13: 737 | J13: 1141 | K13: 1460 | L13: 2798 | M13: 3105 | O13: Deferred tax assets (net) | P13: 2317 | Q13: 1181 | R13: 1176 | S13: 1252 | T13: 1031 | V13: Derivative assets | W13: 0 | X13: 1.6 | Y13: 0.6 | Z13: 2.9 | AA13: 2.5 | AC13: Loans | AD13: 56 | AE13: 45.7 | AF13: 0 | AG13: 3.9 | AH13: 6.6
A14: Loans | B14: 29 | C14: 29 | D14: 311 | E14: 173 | F14: 2 | H14: Deferred tax assets (net) | I14: 1744 | J14: 1098 | K14: 1212 | L14: 1245 | M14: 454 | O14: Other non current assets | P14: 1829 | Q14: 1847 | R14: =2006+1072+200 -> 3278 | S14: =1853+681 -> 2534 | T14: =1894+624 -> 2518 | V14: Trade receivables | W14: 604.9 | X14: 435.8 | Y14: 476.5 | Z14: 86.3 | AA14: 404.5 | AC14: Other financial assets | AD14: 11.8 | AE14: 159.5 | AF14: 550.5 | AG14: 192.4 | AH14: 471.5
A15: Other financial assets | B15: 1184 | C15: 1573 | D15: 2253 | E15: 2149 | F15: 3272 | H15: Income tax assets (net) | I15: 5384 | J15: 5811 | K15: 6098 | L15: 6453 | M15: 3045 | O15: Total non current assets | P15: =SUM(P5:P9,P11:P14) -> 44486 | Q15: =SUM(Q5:Q9,Q11:Q14) -> 43143 | R15: =SUM(R5:R9,R11:R14) -> 40992 | S15: =SUM(S5:S9,S11:S14) -> 39834 | T15: =SUM(T5:T9,T11:T14) -> 40160 | V15: Other financial assets | W15: 588.1 | X15: 608.8 | Y15: 608.4 | Z15: 633 | AA15: 555 | AC15: Deferred tax assets (net) | AD15: 222.2 | AE15: 54.6 | AF15: 38.7 | AG15: 380.9 | AH15: 225
A16: Income tax assets (net) | B16: 2462 | C16: 1845 | D16: 1983 | E16: 3307 | F16: 3403 | H16: Other non current assets | I16: 1426 | J16: 1281 | K16: 2029 | L16: 2318 | M16: 2121 | O16: Current assets | V16: Deferred tax assets (net) | W16: 600.5 | X16: 166.4 | Y16: 229.8 | Z16: 210 | AA16: 181.7 | AC16: Income tax assets (net) | AD16: 81.7 | AE16: 93 | AF16: 221.8 | AG16: 233.4 | AH16: 297
A17: Deferred tax assets (net) | B17: 2828 | C17: 3931 | D17: 3708 | E17: 2583 | F17: 1600 | H17: Total non current assets | I17: =SUM(I5:I9,I11:I16) -> 38192 | J17: =SUM(J5:J9,J11:J16) -> 47653 | K17: =SUM(K5:K9,K11:K16) -> 50700 | L17: =SUM(L5:L9,L11:L16) -> 54935 | M17: =SUM(M5:M9,M11:M16) -> 48382 | O17: Inventories | P17: 91 | Q17: 94 | R17: 161 | S17: 228 | T17: 185 | V17: Non current tax assets (net) | W17: 1141.4 | X17: 1432.3 | Y17: 1025.6 | Z17: 1192.2 | AA17: 904.3 | AC17: Other non current assets | AD17: 145.1 | AE17: 151.5 | AF17: 205.8 | AG17: 201.8 | AH17: 194.8
A18: Other assets | B18: 1711 | C18: 1613 | D18: 2023 | E18: 2806 | F18: 3596 | H18: Current assets | O18: Financial Assets | V18: Other non current assets | W18: 1347.2 | X18: 1671.2 | Y18: 1509.9 | Z18: 1375.8 | AA18: 1057.7 | AC18: Total non current assets | AD18: =SUM(AD5:AD10,AD12:AD17) -> 2495.9 | AE18: =SUM(AE5:AE10,AE12:AE17) -> 2577.8 | AF18: =SUM(AF5:AF10,AF12:AF17) -> 5643.8 | AG18: =SUM(AG5:AG10,AG12:AG17) -> 6310.3 | AH18: =SUM(AH5:AH10,AH12:AH17) -> 8716.6
A19: Total non-current assets | B19: =SUM(B3:B9,B11:B18) -> 30662 | C19: =SUM(C3:C9,C11:C18) -> 31479 | D19: =SUM(D3:D9,D11:D18) -> 33204 | E19: =SUM(E3:E9,E11:E18) -> 33381 | F19: =SUM(F3:F9,F11:F18) -> 33465 | H19: Financial assets | O19: Investments | P19: 6989 | Q19: 6773 | R19: 6239 | S19: 5385 | T19: 7043 | V19: Total non current assets | W19: =SUM(W5:W10,W12:W18) -> 29293.8 | X19: =SUM(X5:X10,X12:X18) -> 30413.6 | Y19: =SUM(Y5:Y10,Y12:Y18) -> 45430.2 | Z19: =SUM(Z5:Z10,Z12:Z18) -> 51024.1 | AA19: =SUM(AA5:AA10,AA12:AA18) -> 49724.4 | AC19: Current Assets
A20: Current Assets | H20: Investments | I20: 4655 | J20: 2342 | K20: 6673 | L20: 6909 | M20: 12915 | O20: Trade receivables | P20: 14131 | Q20: 13663 | R20: =15476+5195 -> 20671 | S20: =19572+5934 -> 25506 | T20: =19483+6038 -> 25521 | V20: Current Assets | AC20: Inventories | AD20: 0 | AE20: 0 | AF20: 4.1 | AG20: 3.3 | AH20: 3
A21: Inventories | B21: 5 | C21: 8 | D21: 20 | E21: 28 | F21: 28 | H21: Trade receivables | I21: 18487 | J21: 19294 | K21: 22698 | L21: 25424 | M21: 30193 | O21: Cash and cash equivalents | P21: 4848 | Q21: 6521 | R21: 10510 | S21: 9065 | T21: 9456 | V21: Inventories | W21: 186.5 | X21: 106.4 | Y21: 133.4 | Z21: 118.8 | AA21: 90.7 | AC21: Financial Assets
A22: Financial Assets | H22: Cash and cash equivalents | I22: 18649 | J22: 24714 | K22: 17472 | L22: 12173 | M22: 14786 | O22: Other bank balances | P22: 128 | Q22: 2367 | R22: 2126 | S22: 5659 | T22: 10694 | V22: Financial assets | AC22: Investments | AD22: 2218.6 | AE22: 3628.2 | AF22: 5397.1 | AG22: 4741.8 | AH22: 6753.4
A23: Investments | B23: 26140 | C23: 29160 | D23: 30262 | E23: 36897 | F23: 31481 | H23: Loans | I23: 239 | J23: 159 | K23: 248 | L23: 289 | M23: 248 | O23: Loans | P23: 3422 | Q23: 4841 | R23: 3008 | S23: 2603 | T23: 795 | V23: Investments | W23: 18963.5 | X23: 17570.7 | Y23: 24165.5 | Z23: 30923.2 | AA23: 31117.1 | AC23: Trade receivables | AD23: 2312.1 | AE23: 2083.5 | AF23: 4557.4 | AG23: 5623.4 | AH23: 5706
A24: Trade receivables | B24: 30532 | C24: 30079 | D24: 34074 | E24: 41049 | F24: 44434 | H24: Other financial assets | I24: 5457 | J24: 6410 | K24: 8727 | L24: 11604 | M24: 12085 | O24: Others | P24: 5937 | Q24: 5889 | R24: 1520 | S24: 1120 | T24: 1235 | V24: Trade receivables | W24: 10447.4 | X24: 9429.8 | Y24: 11521.9 | Z24: 12635 | AA24: 11547.7 | AC24: Unbilled revenue | AD24: 442 | AE24: 607.1 | AF24: 1069.7 | AG24: 1601.1 | AH24: 1326.1
A25: Unbilled receivables | B25: 5732 | C25: 6583 | D25: 7736 | E25: 8905 | F25: 9143 | H25: Income tax assets (net) | I25: 7 | J25: 0 | K25: 54 | L25: 6 | M25: 6397 | O25: Current tax assets (net) | P25: 157 | Q25: 131 | R25: 234 | S25: 195 | T25: 161 | V25: Cash and cash equivalents | W25: 14449.9 | X25: 16979.3 | Y25: 10383.6 | Z25: 9188 | AA25: 9695.3 | AC25: Cash and cash equivalents | AD25: 485.3 | AE25: 675.9 | AF25: 1446.2 | AG25: 2338.9 | AH25: 1820
A26: Cash and Cash Equivalents | B26: 8646 | C26: 6858 | D26: 12488 | E26: 7123 | F26: 9016 | H26: Other current assets | I26: 7082 | J26: 7814 | K26: 11313 | L26: 14476 | M26: 12808 | O26: Other current assets | P26: 2717 | Q26: 2772 | R26: 3572 | S26: 3816 | T26: 4241 | V26: Derivative assets | W26: 302.5 | X26: 406.4 | Y26: 303.2 | Z26: 184.4 | AA26: 133.3 | AC26: Other bank balances | AD26: 39.9 | AE26: 83.5 | AF26: 391.1 | AG26: 593.1 | AH26: 996
A27: Other balances with banks | B27: 1020 | C27: 2471 | D27: 5733 | E27: 3909 | F27: 4270 | H27: Total current assets | I27: =SUM(I20:I26) -> 54576 | J27: =SUM(J20:J26) -> 60733 | K27: =SUM(K20:K26) -> 67185 | L27: =SUM(L20:L26) -> 70881 | M27: =SUM(M20:M26) -> 89432 | O27: Total current assets | P27: =SUM(P17,P19:P26) -> 38420 | Q27: =SUM(Q17,Q19:Q26) -> 43051 | R27: =SUM(R17,R19:R26) -> 48041 | S27: =SUM(S17,S19:S26) -> 53577 | T27: =SUM(T17,T19:T26) -> 59331 | V27: Unbilled receivables | W27: 2520.9 | X27: 2712.4 | Y27: 6080.9 | Z27: 6051.5 | AA27: 5834.5 | AC27: Loans | AD27: 12.9 | AE27: 30 | AF27: 0 | AG27: 0 | AH27: 0
A28: Loans | B28: 8475 | C28: 11472 | D28: 6445 | E28: 1325 | F28: 491 | H28: Total assets | I28: =I17+I27 -> 92768 | J28: =J17+J27 -> 108386 | K28: =K17+K27 -> 117885 | L28: =L17+L27 -> 125816 | M28: =M17+M27 -> 137814 | O28: Total assets | P28: =P15+P27 -> 82906 | Q28: =Q15+Q27 -> 86194 | R28: =R15+R27 -> 89033 | S28: =S15+S27 -> 93411 | T28: =T15+T27 -> 99491 | V28: Other financial assets | W28: 861.4 | X28: 724.5 | Y28: 4291.4 | Z28: 909.6 | AA28: 1053.6 | AC28: Other financial assets | AD28: 161.3 | AE28: 185.8 | AF28: 480.7 | AG28: 183 | AH28: 263.5
A29: Other financial assets | B29: 1473 | C29: 1394 | D29: 1390 | E29: 1319 | F29: 1703 | H29: EQUITY AND LIABILITIES | O29: EQUITY | V29: Current tax assets (net) | W29: 288.2 | X29: 246.1 | Y29: 237.3 | Z29: 509.1 | AA29: 648.4 | AC29: Income tax assets (net) | AD29: 0.7 | AE29: 0 | AF29: 0 | AG29: 0 | AH29: 25.1
A30: Income tax assets (net) | B30: 8 | C30: 19 | D30: 11 | E30: 8 | F30: 151 | H30: Equity | O30: Equity share capital | P30: 543 | Q30: 543 | R30: 543 | S30: 543 | T30: 543 | V30: Contract assets | W30: 1714.3 | X30: 1650.7 | Y30: 2064.7 | Z30: 2300.1 | AA30: 1985.4 | AC30: Other current assets | AD30: 656.2 | AE30: 837.3 | AF30: 1592.3 | AG30: 2101.2 | AH30: 1953.3
A31: Other assets | B31: 8206 | C31: 11236 | D31: 10151 | E31: 9707 | F31: 12267 | H31: Equity share capital | I31: 2122 | J31: 2124 | K31: 2098 | L31: 2069 | M31: 2071 | O31: Other equity | P31: 50724 | Q31: 59370 | R31: 61371 | S31: 64862 | T31: 67720 | V31: Other current assets | W31: 2250.5 | X31: 2492.3 | Y31: 2893.3 | Z31: 3289.9 | AA31: 2960.2 | AC31: Total current assets | AD31: =SUM(AD22:AD30,AD20) -> 6329 | AE31: =SUM(AE22:AE30,AE20) -> 8131.3 | AF31: =SUM(AF22:AF30,AF20) -> 14938.6 | AG31: =SUM(AG22:AG30,AG20) -> 17185.8 | AH31: =SUM(AH22:AH30,AH20) -> 18846.4
A32: Total current assets | B32: =SUM(B21,B23:B31) -> 90237 | C32: =SUM(C21,C23:C31) -> 99280 | D32: =SUM(D21,D23:D31) -> 108310 | E32: =SUM(E21,E23:E31) -> 110270 | F32: =SUM(F21,F23:F31) -> 112984 | H32: Other equity | I32: 63328 | J32: 74227 | K32: 73252 | L32: 73338 | M32: 86045 | O32: Equity distributable to shareholders of the company | P32: =P30+P31 -> 51267 | Q32: =Q30+Q31 -> 59913 | R32: =R30+R31 -> 61914 | S32: =S30+S31 -> 65405 | T32: =T30+T31 -> 68263 | V32: Assets held for sale | W32: 0 | X32: 0 | Y32: 0 | Z32: 0 | AA32: 0 | AC32: Total assets | AD32: =AD18+AD31 -> 8824.9 | AE32: =AE18+AE31 -> 10709.1 | AF32: =AF18+AF31 -> 20582.4 | AG32: =AG18+AG31 -> 23496.1 | AH32: =AH18+AH31 -> 27563
A33: Total Assets | B33: =B19+B32 -> 120899 | C33: =C19+C32 -> 130759 | D33: =D19+D32 -> 141514 | E33: =E19+E32 -> 143651 | F33: =F19+F32 -> 146449 | H33: Total equity distributable to equity holders of the company | I33: =I31+I32 -> 65450 | J33: =J31+J32 -> 76351 | K33: =K31+K32 -> 75350 | L33: =L31+L32 -> 75407 | M33: =M31+M32 -> 88116 | O33: Non controlling interest | P33: 154 | Q33: 169 | R33: 92 | S33: -7 | T33: 8 | V33: Total current assets | W33: =SUM(W21,W23:W32) -> 51985.1 | X33: =SUM(X21,X23:X32) -> 52318.6 | Y33: =SUM(Y21,Y23:Y32) -> 62075.2 | Z33: =SUM(Z21,Z23:Z32) -> 66109.6 | AA33: =SUM(AA21,AA23:AA32) -> 65066.2 | AC33: EQUITY AND LIABILITIES
A34: EQUITY AND LIABILITIES | H34: Non controlling interest | I34: 394 | J34: 431 | K34: 386 | L34: 388 | M34: 345 | O34: Total equity | P34: =P32+P33 -> 51421 | Q34: =Q32+Q33 -> 60082 | R34: =R32+R33 -> 62006 | S34: =S32+S33 -> 65398 | T34: =T32+T33 -> 68271 | V34: Total assets | W34: =W19+W33 -> 81278.9 | X34: =X19+X33 -> 82732.2 | Y34: =Y19+Y33 -> 107505.4 | Z34: =Z19+Z33 -> 117133.7 | AA34: =AA19+AA33 -> 114790.6 | AC34: Equity
A35: Equity | H35: Total equity | I35: =I33+I34 -> 65844 | J35: =J33+J34 -> 76782 | K35: =K33+K34 -> 75736 | L35: =L33+L34 -> 75795 | M35: =M33+M34 -> 88461 | O35: LIABILITIES | V35: EQUITY AND LIABILITIES | AC35: Equity share capital | AD35: 17.4 | AE35: 17.5 | AF35: 29.6 | AG35: 29.6 | AH35: 29.6
A36: Share capital | B36: 375 | C36: 370 | D36: 366 | E36: 366 | F36: 362 | H36: Liabilities | O36: Non current liabilities | V36: EQUITY | AC36: Other equity
A37: Other equity | B37: 83751 | C37: 86063 | D37: 88773 | E37: 90058 | F37: 90127 | H37: Non current liabilities | O37: Financial Liabilities | V37: Equity share capital | W37: 1142.7 | X37: 1095.8 | Y37: 1096.4 | Z37: 1097.6 | AA37: 1045 | AC37: Other reserves | AD37: 633.6 | AE37: 1129.4 | AF37: 1880.3 | AG37: 1112.4 | AH37: 1695.6
A38: Equity distributable to shareholders of the company | B38: =SUM(B36:B37) -> 84126 | C38: =SUM(C36:C37) -> 86433 | D38: =SUM(D36:D37) -> 89139 | E38: =SUM(E36:E37) -> 90424 | F38: =SUM(F36:F37) -> 90489 | H38: Financial liabilities | O38: Borrowings | P38: 2848 | Q38: 3828 | R38: 3923 | S38: 2111 | T38: 2223 | V38: Other equity | W38: 54179 | X38: 53805.2 | Y38: 64306.6 | Z38: 76570.3 | AA38: 73488 | AC38: Retained earnings | AD38: 4753 | AE38: 6156.5 | AF38: 12377.3 | AG38: 15450.1 | AH38: 18291.9
A39: Non controlling interests | B39: 623 | C39: 675 | D39: 707 | E39: 782 | F39: 830 | H39: Lease liabilities | I39: 4014 | J39: 4587 | K39: 4602 | L39: 7057 | M39: 6400 | O39: Lease liabilities | P39: 2179 | Q39: 1903 | R39: 1659 | S39: 1664 | T39: 2339 | V39: Equity attributable to the shareholders of the company | W39: =W37+W38 -> 55321.7 | X39: =X37+X38 -> 54901 | Y39: =Y37+Y38 -> 65403 | Z39: =Z37+Z38 -> 77667.9 | AA39: =AA37+AA38 -> 74533 | AC39: Non controlling interest | AD39: 1.1 | AE39: 3.7 | AF39: 5.7 | AG39: 7.1 | AH39: =0.1+9.2 -> 9.3
A40: Total Equity | B40: =B38+B39 -> 84749 | C40: =C38+C39 -> 87108 | D40: =D38+D39 -> 89846 | E40: =E38+E39 -> 91206 | F40: =F38+F39 -> 91319 | H40: Other financial liabilities | I40: 807 | J40: 1514 | K40: 2337 | L40: 2058 | M40: 2130 | O40: Others | P40: 1194 | Q40: 973 | R40: 452 | S40: 506 | T40: 730 | V40: Non controlling interest | W40: 187.5 | X40: 149.8 | Y40: 51.5 | Z40: 58.9 | AA40: 134 | AC40: Total equity | AD40: =SUM(AD35:AD39) -> 5405.1 | AE40: =SUM(AE35:AE39) -> 7307.1 | AF40: =SUM(AF35:AF39) -> 14292.9 | AG40: =SUM(AG35:AG39) -> 16599.2 | AH40: =SUM(AH35:AH39) -> 20026.4
...

Sheet Income Statement
A1: Consolidated Income Statement | E1: #VALUE! | H1: Consolidated Income Statement | L1: #VALUE! | O1: Consolidated Income Statement | S1: #VALUE! | V1: Consolidated Income Statement | Z1: #VALUE! | AC1: Consolidated Income Statement | AG1: #VALUE!
A2: Particulars | B2: 2020 | C2: 2021 | D2: 2022 | E2: 2023 | F2: 2024 | H2: Particulars | I2: 2020 | J2: 2021 | K2: 2022 | L2: 2023 | M2: 2024 | O2: Particulars | P2: 2020 | Q2: 2021 | R2: 2022 | S2: 2023 | T2: 2024 | V2: Particulars | W2: 2020 | X2: 2021 | Y2: 2022 | Z2: 2023 | AA2: 2024 | AC2: Particulars | AD2: 2020 | AE2: 2021 | AF2: 2022 | AG2: 2023 | AH2: 2024
A3: Revenue from Operations | B3: 156949 | C3: 164177 | D3: 191754 | E3: 225458 | F3: 240893 | H3: Revenue from Operations | I3: 90791 | J3: 100472 | K3: 121641 | L3: 146767 | M3: 162990 | O3: Revenue from operations | P3: 70676 | Q3: 75379 | R3: 85651 | S3: 101456 | T3: 109913 | V3: Revenue from operations | W3: 61023.2 | X3: 61943 | Y3: 79093.4 | Z3: 90487.6 | AA3: 89760.3 | AC3: Revenue from operations | AD3: 10878.6 | AE3: 12369.8 | AF3: 26108.7 | AG3: 33183 | AH3: 35517
A4: Other Income | B4: 4592 | C4: 3134 | D4: 4018 | E4: 3449 | F4: 4422 | H4: Other income | I4: 2803 | J4: 2201 | K4: 2295 | L4: 2701 | M4: 3600 | O4: Other income | P4: 589 | Q4: 927 | R4: 1067 | S4: 1358 | T4: 1495 | V4: Other operating income | W4: 114.4 | X4: -8.1 | Y4: 218.6 | Z4: 0 | AA4: 0 | AC4: Other income | AD4: 329.2 | AE4: 274.4 | AF4: 765.8 | AG4: 556.9 | AH4: 701.9
A5: Total Income | B5: =B3+B4 -> 161541 | C5: =C3+C4 -> 167311 | D5: =D3+D4 -> 195772 | E5: =E3+E4 -> 228907 | F5: =F3+F4 -> 245315 | H5: Total income | I5: =I3+I4 -> 93594 | J5: =J3+J4 -> 102673 | K5: =K3+K4 -> 123936 | L5: =L3+L4 -> 149468 | M5: =M3+M4 -> 166590 | O5: Total Income | P5: =P3+P4 -> 71265 | Q5: =Q3+Q4 -> 76306 | R5: =R3+R4 -> 86718 | S5: =S3+S4 -> 102814 | T5: =T3+T4 -> 111408 | V5: Other income | W5: 2725 | X5: 2390.7 | Y5: 2061.2 | Z5: 2274.6 | AA5: 2630.8 | AC5: Total income | AD5: =AD3+AD4 -> 11207.8 | AE5: =AE3+AE4 -> 12644.2 | AF5: =AF3+AF4 -> 26874.5 | AG5: =AG3+AG4 -> 33739.9 | AH5: =AH3+AH4 -> 36218.9
A6: Expenses | H6: Expenses | O6: Expenses | V6: Total income | W6: =SUM(W3:W5) -> 63862.6 | X6: =SUM(X3:X5) -> 64325.6 | Y6: =SUM(Y3:Y5) -> 81373.2 | Z6: =SUM(Z3:Z5) -> 92762.2 | AA6: =SUM(AA3:AA5) -> 92391.1 | AC6: Expenses
A7: Employee benefit expenses | B7: 85952 | C7: 91814 | D7: 107554 | E7: 127522 | F7: 140131 | H7: Employee benefit expenses | I7: 50887 | J7: 55541 | K7: 63986 | L7: 78359 | M7: 85950 | O7: Purchase of stock-in-trade | P7: 1536 | Q7: 1698 | R7: 1473 | S7: 2072 | T7: 1754 | V7: Expenses | AC7: Employee benefit expenses | AD7: 6516.6 | AE7: 7428.9 | AF7: 15989.2 | AG7: 20879.9 | AH7: 22732.3
A8: Cost of equipments and software licenses | B8: 1905 | C8: 1462 | D8: 1163 | E8: 1881 | F8: 3702 | H8: Cost of technical sub contractors | I8: 6714 | J8: 7084 | K8: 12606 | L8: 14062 | M8: 12937 | O8: Changes in inventories of stock in trade | P8: 0 | Q8: -3 | R8: -67 | S8: -67 | T8: 43 | V8: Purchase of stock in trade | W8: 936 | X8: 695.7 | Y8: 673.5 | Z8: 649.4 | AA8: 383.2 | AC8: Operating expenses | AD8: 2150.6 | AE8: 2019.4 | AF8: 2359.1 | AG8: 2828.6 | AH8: 2559.9
A9: Finance costs | B9: 924 | C9: 637 | D9: 784 | E9: 779 | F9: 778 | H9: Travel expenses | I9: 2710 | J9: 554 | K9: 827 | L9: 1525 | M9: 1894 | O9: Employee benefit expenses | P9: 34928 | Q9: 38853 | R9: 46130 | S9: 55280 | T9: 62480 | V9: Changes in inventories of finished goods and stock in trade | W9: 202.2 | X9: 31.5 | Y9: -36.9 | Z9: 15 | AA9: 27.8 | AC9: Finance costs | AD9: 82.6 | AE9: 78.8 | AF9: 123.4 | AG9: 150.4 | AH9: 221.7
A10: Depreciation and ammortisation expenses | B10: 3529 | C10: 4065 | D10: 4604 | E10: 5022 | F10: 4985 | H10: Cost of software package and others | I10: 2703 | J10: 4223 | K10: 6811 | L10: 10902 | M10: 15911 | O10: Finance cost | P10: 505 | Q10: 511 | R10: 12515 | S10: 14950 | T10: 14578 | V10: Employee benefit expenses | W10: 32657.1 | X10: 33237.1 | Y10: 45007.5 | Z10: 53764.4 | AA10: 54930.1 | AC10: Depreciation and ammortization expenses | AD10: 273 | AE10: 332.5 | AF10: 597.1 | AG10: 722.7 | AH10: 818.9
A11: Other expenses | B11: 26983 | C11: 24355 | D11: 29980 | E11: 36796 | F11: 32764 | H11: Communication expenses | I11: 528 | J11: 634 | K11: 611 | L11: 713 | M11: 620 | O11: Depreciation, ammortization and impairment expenses | P11: 3420 | Q11: 4611 | R11: 319 | S11: 353 | T11: 553 | V11: Finance cost | W11: 732.8 | X11: 508.8 | Y11: 532.5 | Z11: 1007.7 | AA11: 1255.2 | AC11: Other expenses | AD11: 182.1 | AE11: 196.4 | AF11: 2511.8 | AG11: 3366.8 | AH11: 3837.4
A12: Total Expenses | B12: =SUM(B7:B11) -> 119293 | C12: =SUM(C7:C11) -> 122333 | D12: =SUM(D7:D11) -> 144085 | E12: =SUM(E7:E11) -> 172000 | F12: =SUM(F7:F11) -> 182360 | H12: Consultancy and professional charges | I12: 1326 | J12: 1261 | K12: 1885 | L12: 1684 | M12: 1655 | O12: Outsourcing costs | P12: 10700 | Q12: 10158 | R12: 4326 | S12: 4145 | T12: 4173 | V12: Depreciation, ammortization and impairment expenses | W12: 2085.5 | X12: 2763.4 | Y12: 3077.8 | Z12: 3340.2 | AA12: 3407.1 | AC12: Total expenses | AD12: =SUM(AD7:AD11) -> 9204.9 | AE12: =SUM(AE7:AE11) -> 10056 | AF12: =SUM(AF7:AF11) -> 21580.6 | AG12: =SUM(AG7:AG11) -> 27948.4 | AH12: =SUM(AH7:AH11) -> 30170.2
A13: Profit before exceptional items and tax | B13: =B5-B12 -> 42248 | C13: =C5-C12 -> 44978 | D13: =D5-D12 -> 51687 | E13: =E5-E12 -> 56907 | F13: =F5-F12 -> 62955 | H13: Depreciation and ammortization expenses | I13: 2893 | J13: 3267 | K13: 3476 | L13: 4225 | M13: 4812 | O13: Other expenses | P13: 6196 | Q13: 4625 | R13: =5070-(-1) -> 5071 | S13: =6593 -> 6593 | T13: 6860 | V13: Sub-contracting/technical fees/third party application | W13: 9052.1 | X13: 8360.9 | Y13: 10858.9 | Z13: 11524.7 | AA13: 10303 | AC13: Profit before tax | AD13: =AD5-AD12 -> 2002.9 | AE13: =AE5-AE12 -> 2588.2 | AF13: =AF5-AF12 -> 5293.9 | AG13: =AG5-AG12 -> 5791.5 | AH13: =AH5-AH12 -> 6048.7
A14: Exceptional items | H14: Finance cost | I14: 170 | J14: 195 | K14: 200 | L14: 284 | M14: 416 | O14: Total expenses | P14: =SUM(P7:P13) -> 57285 | Q14: =SUM(Q7:Q13) -> 60453 | R14: =SUM(R7:R13) -> 69767 | S14: =SUM(S7:S13) -> 83326 | T14: =SUM(T7:T13) -> 90441 | V14: Facility expenses | W14: 1973.3 | X14: 2025.5 | Y14: 2526.9 | Z14: 1349.2 | AA14: 1455.6 | AC14: Tax expense
A15: Provision towards legal claim | B15: 0 | C15: 1218 | D15: 0 | E15: 0 | F15: 958 | H15: Other expenses | I15: 3656 | J15: 3286 | K15: 3424 | L15: 4392 | M15: 4787 | O15: Profit before tax | P15: =P5-P14 -> 13980 | Q15: =Q5-Q14 -> 15853 | R15: =R5-R14 -> 16951 | S15: =S5-S14 -> 19488 | T15: =T5-T14 -> 20967 | V15: Travel | W15: 1816.9 | X15: 525.8 | Y15: 732 | Z15: 1444.5 | AA15: 1510.2 | AC15: Current tax | AD15: 391.3 | AE15: 631.4 | AF15: 1359.8 | AG15: 1439.1 | AH15: 1460
A16: Profit before tax | B16: =B13-B15 -> 42248 | C16: =C13-C15 -> 43760 | D16: =D13-D15 -> 51687 | E16: =E13-E15 -> 56907 | F16: =F13-F15 -> 61997 | H16: Total expenses | I16: =SUM(I7:I15) -> 71587 | J16: =SUM(J7:J15) -> 76045 | K16: =SUM(K7:K15) -> 93826 | L16: =SUM(L7:L15) -> 116146 | M16: =SUM(M7:M15) -> 128982 | O16: Tax expenses | V16: Communication | W16: 481.2 | X16: 606.9 | Y16: 576 | Z16: 591.1 | AA16: 487.8 | AC16: Deferred tax | AD16: 91.1 | AE16: 18.6 | AF16: -15.9 | AG16: -57.9 | AH16: 4.1
A17: Tax expenses | H17: Profit before tax | I17: =I5-I16 -> 22007 | J17: =J5-J16 -> 26628 | K17: =K5-K16 -> 30110 | L17: =L5-L16 -> 33322 | M17: =M5-M16 -> 37608 | O17: Current tax | P17: 2821 | Q17: 3719 | R17: 3442 | S17: 4665 | T17: 4626 | V17: Marketing and brand building | W17: 253.2 | X17: 556.1 | Y17: 756.1 | Z17: 295.1 | AA17: 355.5 | AC17: Total tax expenses | AD17: =SUM(AD15:AD16) -> 482.4 | AE17: =SUM(AE15:AE16) -> 650 | AF17: =SUM(AF15:AF16) -> 1343.9 | AG17: =SUM(AG15:AG16) -> 1381.2 | AH17: =SUM(AH15:AH16) -> 1464.1
A18: Current tax | B18: 10378 | C18: 11635 | D18: 13654 | E18: 14757 | F18: 15864 | H18: Tax expense | O18: Deferred tax | P18: 102 | Q18: 965 | R18: -14 | S18: -22 | T18: 631 | V18: Legal and professional charges | W18: 473.3 | X18: 101.1 | Y18: 201 | Z18: 1328.8 | AA18: 955.9 | AC18: Profit/Loss for the year | AD18: =AD13-AD17 -> 1520.5 | AE18: =AE13-AE17 -> 1938.2 | AF18: =AF13-AF17 -> 3950 | AG18: =AG13-AG17 -> 4410.3 | AH18: =AH13-AH17 -> 4584.6
A19: Deferred tax | B19: -577 | C19: -437 | D19: -416 | E19: -153 | F19: 34 | H19: Current tax | I19: 5775 | J19: 6672 | K19: 7811 | L19: 9287 | M19: 12130 | O19: Total tax expense | P19: =P17+P18 -> 2923 | Q19: =Q17+Q18 -> 4684 | R19: =R17+R18 -> 3428 | S19: =S17+S18 -> 4643 | T19: =T17+T18 -> 5257 | V19: Allowance for lifetime expected credit loss | W19: 104.3 | X19: 150.6 | Y19: -79.7 | Z19: -60.4 | AA19: 64
A20: Total tax expense | B20: =B18+B19 -> 9801 | C20: =C18+C19 -> 11198 | D20: =D18+D19 -> 13238 | E20: =E18+E19 -> 14604 | F20: =F18+F19 -> 15898 | H20: Deferred tax | I20: -407 | J20: 533 | K20: 153 | L20: -73 | M20: -1272 | O20: Profit for the year | P20: =P15-P19 -> 11057 | Q20: =Q15-Q19 -> 11169 | R20: =R15-R19 -> 13523 | S20: =S15-S19 -> 14845 | T20: =T15-T19 -> 15710 | V20: Other expenses | W20: 845.7 | X20: 872.3 | Y20: 1412.5 | Z20: =869.4+1871.7 -> 2741.1 | AA20: =673.6+1837.8 -> 2511.4 | AD20: =AD13+AD9 -> 2085.5 | AH20: =AH13+AH9 -> 6270.4
A21: Profit for the year | B21: =B16-B20 -> 32447 | C21: =C16-C20 -> 32562 | D21: =D16-D20 -> 38449 | E21: =E16-E20 -> 42303 | F21: =F16-F20 -> 46099 | H21: Total tax expense | I21: =I19+I20 -> 5368 | J21: =J19+J20 -> 7205 | K21: =K19+K20 -> 7964 | L21: =L19+L20 -> 9214 | M21: =M19+M20 -> 10858 | V21: Total expenses | W21: =SUM(W8:W20) -> 51613.6 | X21: =SUM(X8:X20) -> 50435.7 | Y21: =SUM(Y8:Y20) -> 66238.1 | Z21: =SUM(Z8:Z20) -> 77990.8 | AA21: =SUM(AA8:AA20) -> 77646.8
H22: Profit for the period | I22: =I17-I21 -> 16639 | J22: =J17-J21 -> 19423 | K22: =K17-K21 -> 22146 | L22: =L17-L21 -> 24108 | M22: =M17-M21 -> 26750 | V22: Share of net profit/loss of associates | W22: 2.9 | X22: 13 | Y22: 5.7 | Z22: -5.7 | AA22: -23.3
V23: Profit before tax | W23: =W6-W21+W22 -> 12251.9 | X23: =(X6-X21)+X22 -> 13902.9 | Y23: =(Y6-Y21)+Y22 -> 15140.8 | Z23: =(Z6-Z21)+Z22 -> 14765.7 | AA23: =(AA6-AA21)+AA22 -> 14721
P24: =P15+P10 -> 14485 | T24: =T15+T10 -> 35545 | V24: Tax expense
A25: EBIT | B25: =B13+B9 -> 43172 | F25: =F13+F9 -> 63733 | I25: =I17+I14 -> 22177 | M25: =M17+M14 -> 38024 | V25: Current tax | W25: 2432.4 | X25: 2606.5 | Y25: 3241.5 | Z25: 3219.8 | AA25: 3497.3
V26: Deferred tax | W26: 47.7 | X26: 428.4 | Y26: -344.1 | Z26: 179.4 | AA26: 111.6
V27: Total tax expense | W27: =W25+W26 -> 2480.1 | X27: =X25+X26 -> 3034.9 | Y27: =Y25+Y26 -> 2897.4 | Z27: =Z25+Z26 -> 3399.2 | AA27: =AA25+AA26 -> 3608.9
V28: Profit for the year | W28: =W23-W27 -> 9771.8 | X28: =X23-X27 -> 10868 | Y28: =Y23-Y27 -> 12243.4 | Z28: =Z23-Z27 -> 11366.5 | AA28: =AA23-AA27 -> 11112.1
W31: =W23+W11 -> 12984.7 | AA31: =AA23+AA11 -> 15976.2

Sheet Cash flow statement
A1: Consolidated Cash flow Statement | E1: #VALUE! | H1: Consolidated Cash flow Statement | L1: #VALUE! | O1: Consolidated Cash flow Statement | S1: #VALUE! | V1: Consolidated Cash flow Statement | Z1: #VALUE! | AC1: Consolidated Cash flow Statement | AG1: #VALUE!
A2: Particulars | B2: 2020 | C2: 2021 | D2: 2022 | E2: 2023 | F2: 2024 | H2: Particulars | I2: 2020 | J2: 2021 | K2: 2022 | L2: 2023 | M2: 2024 | O2: Particulars | P2: 2020 | Q2: 2021 | R2: 2022 | S2: 2023 | T2: 2024 | V2: Particulars | W2: 2020 | X2: 2021 | Y2: 2022 | Z2: 2023 | AA2: 2024 | AC2: Particulars | AD2: 2020 | AE2: 2021 | AF2: 2022 | AG2: 2023 | AH2: 2024
A3: Profit for the year | B3: 32447 | C3: 32562 | D3: 38449 | E3: 42303 | F3: 46099 | H3: Profit for the period | I3: 16639 | J3: 19423 | K3: 22146 | L3: 24108 | M3: 26248 | O3: Profits before tax | P3: 13980 | Q3: 15853 | R3: 16951 | S3: 19488 | T3: 20967 | V3: Profit/Loss for the year | W3: 9771.8 | X3: 10868 | Y3: 12243.4 | Z3: 11366.5 | AA3: 11112.1 | AC3: Net profit after tax | AD3: 1520.5 | AE3: 1938.2 | AF3: 3950 | AG3: 4410.3 | AH3: 4584.6
A4: Adjustments: | H4: Adjustments: | O4: Adjustments for: | V4: Adjustments: | AC4: Adjustments:
A5: Depreciation and ammortization | B5: 3529 | C5: 4065 | D5: 4604 | E5: 5022 | F5: 4985 | H5: Income tax expense | I5: 5368 | J5: 7205 | K5: 7964 | L5: 9214 | M5: 9740 | O5: Depreciation, ammortization and impairment expense | P5: 3420 | Q5: 4611 | R5: 4326 | S5: 4145 | T5: 4173 | V5: Gain on sale of PPE and intangibles assets,net | W5: -1.1 | X5: -51.6 | Y5: -31.3 | Z5: -8.9 | AA5: -207.2 | AC5: Depreciation and ammortization expense | AD5: 273 | AE5: 332.5 | AF5: 597.1 | AG5: 722.7 | AH5: 818.9
A6: Bad debts and advances written off | B6: 144 | C6: 201 | D6: 135 | E6: 140 | F6: 114 | H6: Depreciation and ammortization | I6: 2893 | J6: 3267 | K6: 3476 | L6: 4225 | M6: 4678 | O6: Interest income | P6: -441 | Q6: -645 | R6: -583 | S6: -769 | T6: -1273 | V6: Depreciation, ammortization and impairment | W6: 2085.5 | X6: 2763.4 | Y6: 3077.8 | Z6: 3340.2 | AA6: 3407.1 | AC6: Income tax expense | AD6: 482.4 | AE6: 650 | AF6: 1343.9 | AG6: 1381.2 | AH6: 1464.1
A7: Provision towards legal claim | B7: 0 | C7: 1218 | D7: 0 | E7: 0 | F7: 0 | H7: Interest and dividend income | I7: -1613 | J7: -1615 | K7: -1645 | L7: -1817 | M7: -2067 | O7: Provision for doubtful debts | P7: 200 | Q7: 19 | R7: 21 | S7: 25 | T7: 117 | V7: Unrealized exchange gain/loss, net and exchange gain/loss on borrowings | W7: 637.6 | X7: -225.1 | Y7: -102.1 | Z7: 15.2 | AA7: 65.5 | AC7: Expense recognised in respect of equity settled stock option | AD7: 31.9 | AE7: 16.8 | AF7: 53.8 | AG7: 113.6 | AH7: 124.4
A8: Tax expense | B8: 9801 | C8: 11198 | D8: 13238 | E8: 14604 | F8: 15898 | H8: Finance cost | I8: 170 | J8: 195 | K8: 200 | L8: 284 | M8: 470 | O8: Income on investments carried at fair value | P8: -94 | Q8: -97 | R8: -104 | S8: -106 | T8: -165 | V8: Share based compensation expenses | W8: 126.2 | X8: 231 | Y8: 411 | Z8: 396.9 | AA8: 558.4 | AC8: Income from investments | AD8: -103.7 | AE8: -98.2 | AF8: -204 | AG8: -167 | AH8: -314
A9: Net gain on lease | B9: -14 | C9: -100 | D9: =-7+9 -> 2 | E9: 2 | F9: -7 | H9: Impairment loss recognised/reversed | I9: 161 | J9: 190 | K9: 170 | L9: 283 | M9: 121 | O9: Profits on sale of investments | P9: -16 | Q9: -3 | R9: -10 | S9: 0 | T9: 0 | V9: Share of net profit/loss of associates accounted for using equity method | W9: -2.9 | X9: -13 | Y9: -5.7 | Z9: 5.7 | AA9: 23.3 | AC9: Interest income | AD9: -17.9 | AE9: -56 | AF9: -86.8 | AG9: -173.6 | AH9: -301.4
A10: Unrealised foreign exchange gain | B10: -117 | C10: -21 | D10: -120 | E10: -189 | F10: -17 | H10: Exchange differences on translation | I10: 184 | J10: -62 | K10: 119 | L10: 161 | M10: 76 | O10: Interest expense | P10: 251 | Q10: 298 | R10: 225 | S10: 238 | T10: 269 | V10: Income tax expense | W10: 2480.1 | X10: 3034.9 | Y10: 2897.4 | Z10: 3399.2 | AA10: 3608.9 | AC10: Finance costs | AD10: -6.4 | AE10: -16.2 | AF10: 123.4 | AG10: 150.4 | AH10: 221.7
A11: Net gain on disposal of PPE | B11: -46 | C11: -13 | D11: -23 | E11: -26 | F11: -7 | H11: Stock compensation expense | I11: 249 | J11: 333 | K11: 415 | L11: 519 | M11: 652 | O11: Profit on sale of PPE (net) | P11: 0 | Q11: -102 | R11: -15 | S11: -162 | T11: -4 | V11: Dividend and interest income/expenses, net | W11: -1894.5 | X11: -1661.4 | Y11: =-944.7-30.1 -> -974.8 | Z11: -810.8 | AA11: -1134.4 | AC11: Allowance for expected credit loss | AD11: 82.6 | AE11: 78.8 | AF11: -9.4 | AG11: -60.6 | AH11: 76.5
A12: Net gain on investments | B12: -214 | C12: -204 | D12: -198 | E12: -224 | F12: -312 | H12: Other adjustments | I12: -131 | J12: -91 | K12: 76 | L12: 628 | M12: =-1934+75+1464 -> -395 | O12: Other non-cash charges (net) | P12: 177 | Q12: 88 | R12: =81+1-1 -> 81 | S12: =308-170+15 -> 153 | T12: =-41+312 -> 271 | V12: Gain on sale of business and loss control in subsidiary, net | W12: -114.4 | X12: 8.1 | Y12: -218.6 | Z12: =-167.1+6 -> -161.1 | AA12: =-130+488 -> 358 | AC12: Unrealised foreign exchange loss/gain, net | AD12: -0.3 | AE12: -17.6 | AF12: 47 | AG12: 69.5 | AH12: 26.3
A13: Interest income | B13: -3562 | C13: -2504 | D13: -2663 | E13: -3248 | F13: -3781 | H13: Changes in assets and liabilities | O13: Net change in | V13: Changes in operating assets and liabilities | AC13: Change in fair value of contingent consideration | AD13: 23.6 | AE13: 23.2 | AF13: 7.1 | AG13: -55.6 | AH13: 0
A14: Dividend income | B14: -10 | C14: -8 | D14: -4 | E14: -15 | F14: -41 | H14: Trade receivables and unbilled revenue | I14: -3861 | J14: -1835 | K14: -7937 | L14: -7076 | M14: -2667 | O14: Trade receivables | P14: -1957 | Q14: 633 | R14: -2809 | S14: -3240 | T14: 248 | V14: Trade receivables | W14: -332.7 | X14: 1284.8 | Y14: -1183.3 | Z14: -98.5 | AA14: 846.4 | AC14: Gain from modification in leases | AD14: 0 | AE14: =-59.2-8.3-14.5 -> -82 | AF14: -2.1 | AG14: -8.3 | AH14: -51.3
A15: Finance costs | B15: 924 | C15: 637 | D15: 784 | E15: 779 | F15: 778 | H15: Loans, other financial assets and other assets | I15: 76 | J15: -534 | K15: -1914 | L15: -3108 | M15: -1172 | O15: Inventories | P15: 24 | Q15: 72 | R15: 207 | S15: -37 | T15: 60 | V15: Unbilled receivables and contract assets | W15: -356.1 | X15: -106.2 | Y15: -3139.6 | Z15: 155.8 | AA15: 591.9 | AC15: Net gain on sale of PPE | AD15: 0.9 | AE15: -0.3 | AF15: -2.7 | AG15: -1.8 | AH15: -7.1
A16: Operating profit before working capital changes | B16: =SUM(B3,B5:B15) -> 42882 | C16: =SUM(C3,C5:C15) -> 47031 | D16: =SUM(D3,D5:D15) -> 54204 | E16: =SUM(E3,E5:E15) -> 59148 | F16: =SUM(F3,F5:F15) -> 63709 | H16: Trade payables | I16: -373 | J16: -245 | K16: 1489 | L16: -279 | M16: 91 | O16: Other financial assets and other assets | P16: -1229 | Q16: 344 | R16: 219 | S16: 917 | T16: 164 | V16: Inventories | W16: 208.5 | X16: 80.3 | Y16: -25.6 | Z16: 16.2 | AA16: 28.7 | AC16: Operating profit before working capital changes | AD16: =SUM(AD3,AD5:AD15) -> 2286.6 | AE16: =SUM(AE3,AE5:AE15) -> 2769.2 | AF16: =SUM(AF3,AF5:AF15) -> 5817.3 | AG16: =SUM(AG3,AG5:AG15) -> 6380.8 | AH16: =SUM(AH3,AH5:AH15) -> 6642.7
A17: Net change in | H17: Other financial liabilities, other liabilities and provisions | I17: 1791 | J17: 3382 | K17: 6938 | L17: 4119 | M17: -1334 | O17: Trade payables | P17: -208 | Q17: 538 | R17: 718 | S17: -175 | T17: -681 | V17: Other assets | W17: -8 | X17: 93.1 | Y17: -653 | Z17: 105.5 | AA17: 886.9 | AC17: Change in working capital
A18: Inventories | B18: 5 | C18: -3 | D18: -12 | E18: -8 | F18: 0 | H18: Cash generated from operations | I18: =SUM(I3,I5:I12,I14:I17) -> 21553 | J18: =SUM(J3,J5:J12,J14:J17) -> 29613 | K18: =SUM(K3,K5:K12,K14:K17) -> 31497 | L18: =SUM(L3,L5:L12,L14:L17) -> 31261 | M18: =SUM(M3,M5:M12,M14:M17) -> 34441 | O18: Provisions, other financial liabilities and other liabilities | P18: 1810 | Q18: 1454 | R18: 1116 | S18: 1230 | T18: 2514 | V18: Trade payables, other liabilities and provisions | W18: -1240.1 | X18: 569.8 | Y18: 969.5 | Z18: -982.4 | AA18: -43.5 | AC18: Decrease in inventories | AD18: -313.1 | AE18: -20.3 | AF18: 0.5 | AG18: 0.8 | AH18: 0.3
A19: Trade receivables | B19: -3295 | C19: 1260 | D19: -4210 | E19: -6501 | F19: -3327 | H19: Income tax paid | I19: -4550 | J19: -6389 | K19: -7612 | L19: -8794 | M19: -9231 | O19: Cash generated from operations | P19: =SUM(P3,P5:P12,P14:P18) -> 15917 | Q19: =SUM(Q3,Q5:Q12,Q14:Q18) -> 23063 | R19: =SUM(R3,R5:R12,R14:R18) -> 20343 | S19: =SUM(S3,S5:S12,S14:S18) -> 21707 | T19: =SUM(T3,T5:T12,T14:T18) -> 26660 | V19: Contract liabilities | W19: -657.2 | X19: 370.4 | Y19: 383.2 | Z19: -652.2 | AA19: -505.3 | AC19: Decrease/Increase in trade receivables and unbilled revenue | AD19: -278.6 | AE19: -196.8 | AF19: -1823.8 | AG19: -1969 | AH19: 504.6
A20: Unbilled receivables | B20: -508 | C20: -201 | D20: -934 | E20: -1182 | F20: -5 | H20: Net cash generated by operating activities | I20: =I18+I19 -> 17003 | J20: =J18+J19 -> 23224 | K20: =K18+K19 -> 23885 | L20: =L18+L19 -> 22467 | M20: =M18+M19 -> 25210 | O20: Income tax paid | P20: -2558 | Q20: -3445 | R20: -3443 | S20: -3698 | T20: -4212 | V20: Cash generated from operations | W20: =SUM(W3,W5:W19) -> 10702.7 | X20: =SUM(X3,X5:X19) -> 17246.5 | Y20: =SUM(Y3,Y5:Y19) -> 13648.3 | Z20: =SUM(Z3,Z5:Z19) -> 16087.3 | AA20: =SUM(AA3,AA5:AA19) -> 19596.8 | AC20: Increase in other assets | AD20: 0 | AE20: 0 | AF20: -186.4 | AG20: -208.5 | AH20: -329.7
A21: Loans and other financial assets | B21: -2 | C21: -17 | D21: -116 | E21: 261 | F21: -301 | H21: CASH FLOW FROM INVESTING ACTIVITIES | O21: Net cash flow from operating activities | P21: =P19+P20 -> 13359 | Q21: =Q19+Q20 -> 19618 | R21: =R19+R20 -> 16900 | S21: =S19+S20 -> 18009 | T21: =T19+T20 -> 22448 | V21: Income tax paid | W21: -638.4 | X21: -2491.5 | Y21: -2568.6 | Z21: -3021.8 | AA21: -1536 | AC21: Increase in trade and other liabilities | AD21: 360.4 | AE21: 487.5 | AF21: 790.9 | AG21: 412.2 | AH21: 422.3
A22: Other assets | B22: -3492 | C22: -2805 | D22: 807 | E22: -25 | F22: -3160 | H22: Expenditure on PPE and intangibles | I22: -3307 | J22: -2107 | K22: -2161 | L22: -2579 | M22: -2201 | O22: CASH FLOW FROM INVESTING ACTIVITIES | V22: Net cash flow from operating activties | W22: =W20+W21 -> 10064.3 | X22: =X20+X21 -> 14755 | Y22: =Y20+Y21 -> 11079.7 | Z22: =Z20+Z21 -> 13065.5 | AA22: =AA20+AA21 -> 18060.8 | AC22: Decrease/Increase in working capital | AD22: =SUM(AD18:AD21) -> -231.3 | AE22: =SUM(AE18:AE21) -> 270.4 | AF22: =SUM(AF18:AF21) -> -1218.8 | AG22: =SUM(AG18:AG21) -> -1764.5 | AH22: =SUM(AH18:AH21) -> 597.5
A23: Trade payables | B23: 446 | C23: -93 | D23: 186 | E23: 2036 | F23: -632 | H23: Deposits placed with corporation | I23: -108 | J23: -207 | K23: =-906+753 -> -153 | L23: =-996+762 -> -234 | M23: -847 | O23: Investments in bank deposits | P23: -265 | Q23: -2427 | R23: -2625 | S23: -8346 | T23: -13924 | V23: CASH FLOW FROM INVESTING ACTIVITIES | AC23: Cash generated from operations | AD23: =SUM(AD16,AD22) -> 2055.3 | AE23: =SUM(AE16,AE22) -> 3039.6 | AF23: =SUM(AF16,AF22) -> 4598.5 | AG23: =SUM(AG16,AG22) -> 4616.3 | AH23: =SUM(AH16,AH22) -> 7240.2
A24: Unearned and deferred revenue | B24: 375 | C24: 1091 | D24: -103 | E24: 39 | F24: -740 | H24: Interest and dividend received | I24: 1929 | J24: 1418 | K24: 1898 | L24: 1525 | M24: 710 | O24: Proceeds from bank deposits on maturity | P24: 2074 | Q24: 188 | R24: 2866 | S24: 4484 | T24: 10315 | V24: Purchase of PPE | W24: -2349.7 | X24: -1957.7 | Y24: -2015.3 | Z24: -1483.4 | AA24: -1051 | AC24: Income tax paid | AD24: -411.8 | AE24: -640 | AF24: -1347.8 | AG24: -1521.7 | AH24: -1570.7
A25: Other financial liabilities | B25: 1208 | C25: 122 | D25: 1153 | E25: 1417 | F25: -695 | H25: Payments towards acquisition of business, net cash acq | I25: -1860 | J25: -1221 | K25: 0 | L25: -910 | M25: 1768 | O25: Purchase of investments in securities | P25: -35420 | Q25: -20792 | R25: -32574 | S25: -34620 | T25: -41674 | V25: Proceeds from sale of PPE | W25: 127 | X25: 75.3 | Y25: 73.6 | Z25: 54.6 | AA25: 402.2 | AC25: Net cash generated from operating activities | AD25: =AD23+AD24 -> 1643.5 | AE25: =AE23+AE24 -> 2399.6 | AF25: =AF23+AF24 -> 3250.7 | AG25: =AG23+AG24 -> 3094.6 | AH25: =AH23+AH24 -> 5669.5
A26: Other liabilties and provisions | B26: 596 | C26: 1509 | D26: 460 | E26: -254 | F26: 1978 | H26: Payments of contingent consideration pertaining of acq | I26: -6 | J26: -158 | K26: -53 | L26: -60 | M26: 0 | O26: Proceeds from sale/maturity of investments in securities | P26: 30785 | Q26: 21109 | R26: 33215 | S26: 35626 | T26: 40329 | V26: Purchase of investments | W26: -117824.7 | X26: -117225.1 | Y26: -101548.6 | Z26: -80663.2 | AA26: -97506.9 | AC26: CASH FLOW FROM INVESTING ACTIVITIES
A27: Cash generated from operations | B27: =SUM(B18:B26,B16) -> 38215 | C27: =SUM(C18:C26,C16) -> 47894 | D27: =SUM(D18:D26,D16) -> 51435 | E27: =SUM(E18:E26,E16) -> 54931 | F27: =SUM(F18:F26,F16) -> 56827 | H27: Redemption of escrow pertaining to buyback | I27: 257 | J27: 0 | K27: =-420+420 -> 0 | L27: =-483+483 -> 0 | M27: -101 | O27: Investments in equity instruments | P27: -15 | Q27: -3 | R27: -1 | S27: 0 | T27: -8 | V27: Proceeds from sale of investments | W27: 121282.6 | X27: 118905.9 | Y27: 95373.5 | Z27: 74088.5 | AA27: 97859.8 | AC27: Purchase of PPE | AD27: -246.5 | AE27: -271.9 | AF27: -1057.3 | AG27: -939.3 | AH27: -843.2
A28: Taxes paid | B28: -5846 | C28: -9092 | D28: -11486 | E28: -12966 | F28: -12489 | H28: Other receipts | I28: 46 | J28: 49 | K28: 67 | L28: 71 | M28: 128 | O28: Deposits placed with body corporates | P28: -5015 | Q28: -6641 | R28: =-5478+40-9 -> -5447 | S28: =-2602+9 -> -2593 | T28: -1079 | V28: Proceeds from sale of hosted data centre services business and loss of control in subsidiary, net of related expenses and cash | W28: 0 | X28: 0 | Y28: 165.2 | Z28: 2741 | AA28: 0 | AC28: Sale of PPE | AD28: 3.9 | AE28: 5.4 | AF28: 4.4 | AG28: 4.7 | AH28: 10.2
A29: Net cash generated from Operating activities | B29: =B27+B28 -> 32369 | C29: =C27+C28 -> 38802 | D29: =D27+D28 -> 39949 | E29: =E27+E28 -> 41965 | F29: =F27+F28 -> 44338 | H29: Other payments | I29: 0 | J29: -45 | K29: -22 | L29: 0 | M29: 0 | O29: Proceeds from maturity of deposits placed with body corp | P29: 3261 | Q29: 5219 | R29: 7111 | S29: 3208 | T29: 1605 | V29: Payment for business acquisitions including deposits and escrow, net | W29: -1000.3 | X29: -987.3 | Y29: -12984.6 | Z29: -4556.6 | AA29: -529.1 | AC29: Purchase of Investments | AD29: -460.4 | AE29: -1461.1 | AF29: 14390.4 | AG29: 20638.5 | AH29: 28666.5
A30: CASH FLOW FROM INVESTING ACTIVITIES | H30: Payments to acquire investments | O30: Payments for business acquisitions, net of cash acquired | P30: -6091 | Q30: -1211 | R30: 0 | S30: -706 | T30: -2043 | V30: Proceeds from sale of business | W30: 745.9 | X30: 0 | Y30: -2741 | Z30: 1.1 | AA30: =-48.4+30 -> -18.4 | AC30: Sale of Investments | AD30: -10.3 | AE30: -40.8 | AF30: -14854.7 | AG30: -20012.8 | AH30: -31997
A31: Bank deposits placed | B31: -7663 | C31: -6605 | D31: -15947 | E31: -4548 | F31: -9471 | H31: Preference, equity securities and others | I31: -41 | J31: 0 | K31: 0 | L31: 0 | M31: 0 | O31: Purchase of non-controlling interest | P31: 0 | Q31: -12 | R31: 0 | S31: 0 | T31: 0 | V31: Interest received | W31: 2383.7 | X31: 1962.4 | Y31: 1227.5 | Z31: 1411.2 | AA31: 2011.1 | AC31: Payment towards contingent consideration | AD31: -48.8 | AE31: -1.8 | AF31: -42.7 | AG31: -49.6 | AH31: -5.9
A32: Inter-corporate deposits placed | B32: -14905 | C32: -21076 | D32: -14619 | E32: -8293 | F32: 0 | H32: Tax free bonds and government bonds | I32: -19 | J32: -318 | K32: 0 | L32: -27 | M32: 0 | O32: Investment in limited liability partnership | P32: -3 | Q32: -4 | R32: -2 | S32: -3 | T32: 0 | V32: Dividend received | W32: 36.7 | X32: 0.4 | Y32: 0.2 | Z32: 0.3 | AA32: 0.3 | AC32: Payment towards transfer of business under common control | AD32: 6.4 | AE32: 16 | AF32: -142.8 | AG32: -99 | AH32: 0
A33: Purchase of investments | B33: -80002 | C33: -54462 | D33: -75374 | E33: -129745 | F33: -141011 | H33: Liquid mutual funds and fixed maturity plan securities | I33: -34839 | J33: -35196 | K33: -54064 | L33: -70631 | M33: -66191 | O33: Distribution from LLP | P33: 1 | Q33: 0 | R33: 0 | S33: 1 | T33: 13 | V33: Cash generated from investing activities | W33: =SUM(W24:W32) -> 3401.2 | X33: =SUM(X24:X32) -> 773.9 | Y33: =SUM(Y24:Y32) -> -22449.5 | Z33: =SUM(Z24:Z32) -> -8406.5 | AA33: =SUM(AA24:AA32) -> 1168 | AC33: Interest received | AD33: 103.7 | AE33: 98.2 | AF33: 57.4 | AG33: 126.6 | AH33: 257.3
A34: Payment of purchase of PPE | B34: -2538 | C34: -2719 | D34: -2483 | E34: -2532 | F34: -2202 | H34: Non-convertible debentures | I34: -993 | J34: -3689 | K34: -1609 | L34: -249 | M34: -1526 | O34: Purchase of PPE and intangibles | P34: -1866 | Q34: -1904 | R34: -1645 | S34: -1661 | T34: -1048 | V34: CASH FLOW FROM FINANCING ACTIVITIES | AC34: Net cash used in Investing activities | AD34: =SUM(AD27:AD33) -> -652 | AE34: =SUM(AE27:AE33) -> -1656 | AF34: =SUM(AF27:AF33) -> -1645.3 | AG34: =SUM(AG27:AG33) -> -330.9 | AH34: =SUM(AH27:AH33) -> -3912.1
A35: Payment including advances for acquiring right of use assests | B35: -519 | C35: -101 | D35: -15 | E35: -213 | F35: -30 | H35: Certificates of deposits | I35: -1114 | J35: 0 | K35: -4184 | L35: -10348 | M35: -8509 | O35: Proceeds from sale of PPE | P35: 37 | Q35: 151 | R35: 90 | S35: 217 | T35: 32 | V35: Proceeds from issuance of equity shares and shares pending allotment | W35: 1.4 | X35: 0.6 | Y35: 0.6 | Z35: 1.2 | AA35: 1.3 | AC35: CASH FLOW FROM FINANCING ACTIVTIES
A36: Payments for purchase of intangible assets | B36: -192 | C36: -356 | D36: -497 | E36: -355 | F36: -442 | H36: Government securities | I36: -1561 | J36: -7510 | K36: -4254 | L36: -1569 | M36: -10387 | O36: Interest received | P36: 282 | Q36: 676 | R36: 590 | S36: 636 | T36: 1041 | V36: Repayment of borrowings | W36: -13238 | X36: -9720.6 | Y36: -19181 | Z36: -16891 | AA36: -13055.7 | AC36: Proceeds from issue of share capital | AD36: 0 | AE36: 0.1 | AF36: 0.2 | AG36: 1.2 | AH36: 1.2
A37: Proceeds from bank deposits | B37: 11965 | C37: 4767 | D37: 11950 | E37: 6252 | F37: 8089 | H37: Others | I37: -29 | J37: -25 | K37: =-24 -> -24 | L37: =-20-400-3003 -> -3423 | M37: -14 | O37: Income taxes paid | P37: -139 | Q37: -91 | R37: -101 | S37: -174 | T37: -282 | V37: Proceeds from borrowings | W37: 10634.2 | X37: 10341.8 | Y37: 26012 | Z37: 16103.4 | AA37: 12050 | AC37: Share issue expenses paid | AD37: 32 | AE37: 9.4 | AF37: 0 | AG37: -1 | AH37: 0
A38: Proceeds from inter-corporate deposits | B38: 14432 | C38: 18018 | D38: 19498 | E38: 13654 | F38: 846 | H38: Proceeds on sale of investments | O38: Net cash flow generated/used in investing activities | P38: =SUM(P23:P37) -> -12374 | Q38: =SUM(Q23:Q37) -> -5742 | R38: =SUM(R23:R37) -> 1477 | S38: =SUM(S23:S37) -> -3931 | T38: =SUM(T23:T37) -> -6723 | V38: Repayment of lease liabilities | W38: -678.4 | X38: -866 | Y38: -973 | Z38: -971.1 | AA38: -1006 | AC38: Net repayment of/proceeds from short term borrowings | AD38: -210.4 | AE38: 175.9 | AF38: 10.5 | AG38: 66.5 | AH38: -86.6
A39: Proceeds from disposal/redemption of investments | B39: 84089 | C39: 51630 | D39: =73852+3 -> 73855 | E39: =122687+2 -> 122689 | F39: =147204+3 -> 147207 | H39: Tax free bonds and government bonds | I39: 87 | J39: 0 | K39: 20 | L39: 221 | M39: 150 | O39: CASH FLOW FROM FINANCING ACTIVITIES | V39: Payment for deferred contingent consideration in respect of business combination | W39: 0 | X39: -9519.9 | Y39: -30.9 | Z39: -178.4 | AA39: -129.4 | AC39: Deposit under credit support agreement received/paid | AD39: -139.7 | AE39: -160.2 | AF39: -47.5 | AG39: -59.4 | AH39: 58.6
A40: Proceeds from disposal of PPE | B40: 161 | C40: 37 | D40: 31 | E40: =37+0 -> 37 | F40: =17+7 -> 24 | H40: Non-convertible debentures | I40: 1888 | J40: 1251 | K40: 2201 | L40: 470 | M40: 1230 | O40: Proceeds from long term borrowings | P40: 152 | Q40: 3752 | R40: 25 | S40: 36 | T40: 6 | V40: Payment for buy back of shares, including transaction cost | W40: -10531.1 | X40: -2144.5 | Y40: 0 | Z40: -870.8 | AA40: -1045.6 | AC40: Payment towards lease liabilities (net) | AD40: -4 | AE40: -2.1 | AF40: -200.4 | AG40: -227.1 | AH40: -247.8
...

Sheet Financial Ratios
A1: FINANCIAL RATIO | F1: #VALUE! | I1: FINANCIAL RATIO | N1: #VALUE! | Q1: FINANCIAL RATIO | V1: #VALUE! | Y1: FINANCIAL RATIO | AD1: #VALUE! | AG1: FINANCIAL RATIO | AL1: #VALUE!
A2: Category | B2: Ratio name | C2: 2020 | D2: 2021 | E2: 2022 | F2: 2023 | G2: 2024 | I2: Category | J2: Ratio name | K2: 2020 | L2: 2021 | M2: 2022 | N2: 2023 | O2: 2024 | Q2: Category | R2: Ratio name | S2: 2020 | T2: 2021 | U2: 2022 | V2: 2023 | W2: 2024 | Y2: Category | Z2: Ratio name | AA2: 2020 | AB2: 2021 | AC2: 2022 | AD2: 2023 | AE2: 2024 | AG2: Category | AH2: Ratio name | AI2: 2020 | AJ2: 2021 | AK2: 2022 | AL2: 2023 | AM2: 2024
A3: Profitability | B3: Gross Profit Margin | C3: =('Income Statement'!B3-'Income Statement'!B8)/'Income Statement'!B3 -> 0.9878623 | D3: =('Income Statement'!C3-'Income Statement'!C8)/'Income Statement'!C3 -> 0.99109498 | E3: =('Income Statement'!D3-'Income Statement'!D8)/'Income Statement'!D3 -> 0.99393494 | F3: =('Income Statement'!E3-'Income Statement'!E8)/'Income Statement'!E3 -> 0.99165698 | G3: =('Income Statement'!F3-'Income Statement'!F8)/'Income Statement'!F3 -> 0.98463218 | I3: Profitability | J3: Gross Profit Margin | K3: =('Income Statement'!I3-'Income Statement'!I8-'Income Statement'!I10)/'Income Statement'!I3 -> 0.89627827 | L3: =('Income Statement'!J3-'Income Statement'!J8-'Income Statement'!J10)/'Income Statement'!J3 -> 0.88746118 | M3: =('Income Statement'!K3-'Income Statement'!K8-'Income Statement'!K10)/'Income Statement'!K3 -> 0.84037454 | N3: =('Income Statement'!L3-'Income Statement'!L8-'Income Statement'!L10)/'Income Statement'!L3 -> 0.82990727 | O3: =('Income Statement'!M3-'Income Statement'!M8-'Income Statement'!M10)/'Income Statement'!M3 -> 0.82300755 | Q3: Profitability | R3: Gross Profit Margin | S3: =('Income Statement'!P3-('Income Statement'!P7+'Income Statement'!P8))/'Income Statement'!P3 -> 0.97826702 | T3: =('Income Statement'!Q3-('Income Statement'!Q7+'Income Statement'!Q8))/'Income Statement'!Q3 -> 0.97751363 | U3: =('Income Statement'!R3-('Income Statement'!R7+'Income Statement'!R8))/'Income Statement'!R3 -> 0.98358455 | V3: =('Income Statement'!S3-('Income Statement'!S7+'Income Statement'!S8))/'Income Statement'!S3 -> 0.98023774 | W3: =('Income Statement'!T3-('Income Statement'!T7+'Income Statement'!T8))/'Income Statement'!T3 -> 0.98365071 | Y3: Profitability | Z3: Gross Profit Margin | AA3: =('Income Statement'!W3-('Income Statement'!W8+'Income Statement'!W9))/'Income Statement'!W3 -> 0.98134808 | AB3: =('Income Statement'!X3-('Income Statement'!X8+'Income Statement'!X9))/'Income Statement'!X3 -> 0.98826017 | AC3: =('Income Statement'!Y3-('Income Statement'!Y8+'Income Statement'!Y9))/'Income Statement'!Y3 -> 0.99195129 | AD3: =('Income Statement'!Z3-('Income Statement'!Z8+'Income Statement'!Z9))/'Income Statement'!Z3 -> 0.99265756 | AE3: =('Income Statement'!AA3-('Income Statement'!AA8+'Income Statement'!AA9))/'Income Statement'!AA3 -> 0.99542114 | AG3: Profitability | AH3: Gross Profit Margin
B4: EBITDA Margin | C4: =('Income Statement'!B16+'Income Statement'!B9+'Income Statement'!B10+'Income Statement'!B15)/'Income Statement'!B3 -> 0.29755526 | D4: =('Income Statement'!C16+'Income Statement'!C9+'Income Statement'!C10+'Income Statement'!C15)/'Income Statement'!C3 -> 0.30260024 | E4: =('Income Statement'!D16+'Income Statement'!D9+'Income Statement'!D10+'Income Statement'!D15)/'Income Statement'!D3 -> 0.29764699 | F4: =('Income Statement'!E16+'Income Statement'!E9+'Income Statement'!E10+'Income Statement'!E15)/'Income Statement'!E3 -> 0.27813606 | G4: =('Income Statement'!F16+'Income Statement'!F9+'Income Statement'!F10+'Income Statement'!F15)/'Income Statement'!F3 -> 0.28526358 | J4: EBITDA Margin | K4: =('Income Statement'!I17+'Income Statement'!I14+'Income Statement'!I13)/'Income Statement'!I3 -> 0.27612869 | L4: =('Income Statement'!J17+'Income Statement'!J14+'Income Statement'!J13)/'Income Statement'!J3 -> 0.29948642 | M4: =('Income Statement'!K17+'Income Statement'!K14+'Income Statement'!K13)/'Income Statement'!K3 -> 0.27775174 | N4: =('Income Statement'!L17+'Income Statement'!L14+'Income Statement'!L13)/'Income Statement'!L3 -> 0.2577623 | O4: =('Income Statement'!M17+'Income Statement'!M14+'Income Statement'!M13)/'Income Statement'!M3 -> 0.26281367 | R4: EBITDA Margin | S4: =('Income Statement'!P15+'Income Statement'!P10+'Income Statement'!P11)/'Income Statement'!P3 -> 0.25333918 | T4: =('Income Statement'!Q15+'Income Statement'!Q10+'Income Statement'!Q11)/'Income Statement'!Q3 -> 0.27826052 | U4: =('Income Statement'!R15+'Income Statement'!R10+'Income Statement'!R11)/'Income Statement'!R3 -> 0.34774842 | V4: =('Income Statement'!S15+'Income Statement'!S10+'Income Statement'!S11)/'Income Statement'!S3 -> 0.34291713 | W4: =('Income Statement'!T15+'Income Statement'!T10+'Income Statement'!T11)/'Income Statement'!T3 -> 0.32842339 | Z4: EBITDA Margin | AA4: =('Income Statement'!W23+'Income Statement'!W11+'Income Statement'!W12)/'Income Statement'!W3 -> 0.24695853 | AB4: =('Income Statement'!X23+'Income Statement'!X11+'Income Statement'!X12)/'Income Statement'!X3 -> 0.27727265 | AC4: =('Income Statement'!Y23+'Income Statement'!Y11+'Income Statement'!Y12)/'Income Statement'!Y3 -> 0.23707541 | AD4: =('Income Statement'!Z23+'Income Statement'!Z11+'Income Statement'!Z12)/'Income Statement'!Z3 -> 0.21122894 | AE4: =('Income Statement'!AA23+'Income Statement'!AA11+'Income Statement'!AA12)/'Income Statement'!AA3 -> 0.21594513 | AH4: EBITDA Margin | AI4: =('Income Statement'!AD13+'Income Statement'!AD9+'Income Statement'!AD10)/'Income Statement'!AD3 -> 0.21680179 | AJ4: =('Income Statement'!AE13+'Income Statement'!AE9+'Income Statement'!AE10)/'Income Statement'!AE3 -> 0.24248573 | AK4: =('Income Statement'!AF13+'Income Statement'!AF9+'Income Statement'!AF10)/'Income Statement'!AF3 -> 0.23035999 | AL4: =('Income Statement'!AG13+'Income Statement'!AG9+'Income Statement'!AG10)/'Income Statement'!AG3 -> 0.20084381 | AM4: =('Income Statement'!AH13+'Income Statement'!AH9+'Income Statement'!AH10)/'Income Statement'!AH3 -> 0.19960301
B5: EBIT Margin | C5: =('Income Statement'!B13+'Income Statement'!B9)/'Income Statement'!B3 -> 0.27507025 | D5: =('Income Statement'!C13+'Income Statement'!C9)/'Income Statement'!C3 -> 0.27784038 | E5: =('Income Statement'!D13+'Income Statement'!D9)/'Income Statement'!D3 -> 0.27363706 | F5: =('Income Statement'!E13+'Income Statement'!E9)/'Income Statement'!E3 -> 0.2558614 | G5: =('Income Statement'!F13+'Income Statement'!F9)/'Income Statement'!F3 -> 0.26456975 | J5: EBIT Margin | K5: =('Income Statement'!I17+'Income Statement'!I14)/'Income Statement'!I3 -> 0.2442643 | L5: =('Income Statement'!J17+'Income Statement'!J14)/'Income Statement'!J3 -> 0.2669699 | M5: =('Income Statement'!K17+'Income Statement'!K14)/'Income Statement'!K3 -> 0.24917585 | N5: =('Income Statement'!L17+'Income Statement'!L14)/'Income Statement'!L3 -> 0.22897518 | O5: =('Income Statement'!M17+'Income Statement'!M14)/'Income Statement'!M3 -> 0.23329039 | R5: EBIT Margin | S5: =('Income Statement'!P15+'Income Statement'!P10)/'Income Statement'!P3 -> 0.20494935 | T5: =('Income Statement'!Q15+'Income Statement'!Q10)/'Income Statement'!Q3 -> 0.21708964 | U5: =('Income Statement'!R15+'Income Statement'!R10)/'Income Statement'!R3 -> 0.344024 | V5: =('Income Statement'!S15+'Income Statement'!S10)/'Income Statement'!S3 -> 0.33943779 | W5: =('Income Statement'!T15+'Income Statement'!T10)/'Income Statement'!T3 -> 0.32339214 | Z5: EBIT Margin | AA5: =('Income Statement'!W23+'Income Statement'!W11)/'Income Statement'!W3 -> 0.21278301 | AB5: =('Income Statement'!X23+'Income Statement'!X11)/'Income Statement'!X3 -> 0.23266067 | AC5: =('Income Statement'!Y23+'Income Statement'!Y11)/'Income Statement'!Y3 -> 0.19816192 | AD5: =('Income Statement'!Z23+'Income Statement'!Z11)/'Income Statement'!Z3 -> 0.1743156 | AE5: =('Income Statement'!AA23+'Income Statement'!AA11)/'Income Statement'!AA3 -> 0.17798737 | AH5: EBIT Margin | AI5: =('Income Statement'!AD13+'Income Statement'!AD9)/'Income Statement'!AD3 -> 0.19170665 | AJ5: =('Income Statement'!AE13+'Income Statement'!AE9)/'Income Statement'!AE3 -> 0.21560575 | AK5: =('Income Statement'!AF13+'Income Statement'!AF9)/'Income Statement'!AF3 -> 0.20749022 | AL5: =('Income Statement'!AG13+'Income Statement'!AG9)/'Income Statement'!AG3 -> 0.17906458 | AM5: =('Income Statement'!AH13+'Income Statement'!AH9)/'Income Statement'!AH3 -> 0.17654644
