Workbook

Sheet Company Info
A1: COMPANY PROFILE
A3: Company | B3: #VALUE! | C3: #VALUE! | D3: #VALUE! | E3: #VALUE! | F3: #VALUE!
A4: Name | B4: #VALUE! | C4: #VALUE! | D4: #VALUE! | E4: #VALUE! | F4: #VALUE!
A5: Industry | B5: {=_FV(B4,"Industry")} -> Transport Infrastructure | C5: {=_FV(C4,"Industry")} -> Construction & Engineering | D5: {=_FV(D4,"Industry")} -> Construction & Engineering | E5: {=_FV(E4,"Industry")} -> Construction & Engineering | F5: {=_FV(F4,"Industry")} -> Construction & Engineering
A6: Ticker Symbol | B6: {=_FV(B4,"Ticker symbol",TRUE)} -> ADANIPORTS | C6: {=_FV(C4,"Ticker symbol",TRUE)} -> KPIL | D6: {=_FV(D4,"Ticker symbol",TRUE)} -> KEC | E6: {=_FV(E4,"Ticker symbol",TRUE)} -> LT | F6: {=_FV(F4,"Ticker symbol",TRUE)} -> RVNL
A7: Year of establishment | B7: {=_FV(B4,"Year incorporated",TRUE)} -> 1998 | C7: {=_FV(C4,"Year incorporated",TRUE)} -> 1981 | D7: {=_FV(D4,"Year incorporated",TRUE)} -> 2005 | E7: {=_FV(E4,"Year incorporated",TRUE)} -> 1946 | F7: {=_FV(F4,"Year incorporated",TRUE)} -> 2003
A8: Employees | B8: {=_FV(B4,"Employees")} -> 3118 | C8: {=_FV(C4,"Employees")} -> 9870 | D8: {=_FV(D4,"Employees")} -> 7692 | E8: {=_FV(E4,"Employees")} -> 58244 | F8: {=_FV(F4,"Employees")} -> 213
A9: Beta | B9: {=_FV(B4,"Beta")} -> 1.4608 | C9: {=_FV(C4,"Beta")} -> 0.5909 | D9: {=_FV(D4,"Beta")} -> 0.6763 | E9: {=_FV(E4,"Beta")} -> 1.0837 | F9: {=_FV(F4,"Beta")} -> 1.4107
A10: Shares Outstanding | B10: {=_FV(B4,"Shares outstanding",TRUE)} -> 2160139000 | C10: {=_FV(C4,"Shares outstanding",TRUE)} -> 170772600 | D10: {=_FV(D4,"Shares outstanding",TRUE)} -> 266200000 | E10: {=_FV(E4,"Shares outstanding",TRUE)} -> 1375581000 | F10: {=_FV(F4,"Shares outstanding",TRUE)} -> 2085020000
B11: =B10/10000000 -> 216.0139 | C11: =C10/10000000 -> 17.07726 | D11: =D10/10000000 -> 26.62 | E11: =E10/10000000 -> 137.5581 | F11: =F10/10000000 -> 208.502
A12: Current Market Price | B12: {=_FV(B4,"Price")} -> 1444.9 | C12: {=_FV(C4,"Price")} -> 1276 | D12: {=_FV(D4,"Price")} -> 722.25 | E12: {=_FV(E4,"Price")} -> 3918.5 | F12: {=_FV(F4,"Price")} -> 315.9
A13: Market cap | B13: {=_FV(B4,"Market cap",TRUE)} -> 3128529000000 | C13: {=_FV(C4,"Market cap",TRUE)} -> 221304100000 | D13: {=_FV(D4,"Market cap",TRUE)} -> 202139000000 | E13: {=_FV(E4,"Market cap",TRUE)} -> 5340693000000 | F13: {=_FV(F4,"Market cap",TRUE)} -> 663036400000
B14: =B13/10000000 -> 312852.9 | C14: =C13/10000000 -> 22130.41 | D14: =D13/10000000 -> 20213.9 | E14: =E13/10000000 -> 534069.3 | F14: =F13/10000000 -> 66303.64
A15: Change (%) | B15: {=_FV(B4,"Change (%)",TRUE)} -> -0.002348 | C15: {=_FV(C4,"Change (%)",TRUE)} -> -0.015356 | D15: {=_FV(D4,"Change (%)",TRUE)} -> -0.048858 | E15: {=_FV(E4,"Change (%)",TRUE)} -> 0.009272 | F15: {=_FV(F4,"Change (%)",TRUE)} -> -0.006604
A16: Change (Rs) | B16: {=_FV(B4,"Change")} -> -3.4 | C16: {=_FV(C4,"Change")} -> -19.9 | D16: {=_FV(D4,"Change")} -> -37.1 | E16: {=_FV(E4,"Change")} -> 36 | F16: {=_FV(F4,"Change")} -> -2.1

Sheet Balance Sheet
A1: Consolidated Balance Sheet
E2: #VALUE! | M2: #VALUE! | U2: #VALUE! | AC2: #VALUE! | AK2: #VALUE!
A3: Particulars | B3: 2020 | C3: 2021 | D3: 2022 | E3: 2023 | F3: 2024 | G3: 2025 | I3: Particulars | J3: 2020 | K3: 2021 | L3: 2022 | M3: 2023 | N3: 2024 | O3: 2025 | Q3: Particulars | R3: 2020 | S3: 2021 | T3: 2022 | U3: 2023 | V3: 2024 | W3: 2025 | Y3: Particulars | Z3: 2020 | AA3: 2021 | AB3: 2022 | AC3: 2023 | AD3: 2024 | AE3: 2025 | AG3: Particulars | AH3: 2020 | AI3: 2021 | AJ3: 2022 | AK3: 2023 | AL3: 2024 | AM3: 2025
A4: ASSETS | I4: ASSETS | Q4: ASSETS | Y4: ASSETS | AG4: ASSETS
A5: Non-current assets | I5: Non-current assets | Q5: Non-current Assets | Y5: Non-current assets | AG5: Non-current assets
A6: PPE | B6: 25744.92 | C6: 36791.51 | D6: 41488.7 | E6: 48414 | F6: 51803.83 | G6: 62394.43 | I6: PPE | J6: 1571.09 | K6: 1622.03 | L6: 1626.61 | M6: 1980.78 | N6: 1996.33 | O6: 2181.29 | Q6: PPE | R6: 894.23 | S6: 979.45 | T6: 1011.95 | U6: 1067.23 | V6: 1141.22 | W6: 1073.99 | Y6: PPE | Z6: 6853.43 | AA6: 7462.21 | AB6: 10577.98 | AC6: 11336.28 | AD6: 13297.64 | AE6: 14128.56 | AG6: PPE | AH6: 16.5636 | AI6: 19.22 | AJ6: 23.09 | AK6: 26.63 | AL6: 28.86 | AM6: 537.21
A7: Right-of-use assets | B7: 1742.96 | C7: 1775.95 | D7: 2772.25 | E7: 3541.9 | F7: 3809.11 | G7: 6177.54 | I7: Capital work in progress | J7: 50.06 | K7: 29.49 | L7: 19.91 | M7: 52.28 | N7: 33.32 | O7: 28.58 | Q7: Right of use assets | R7: 147 | S7: 136.32 | T7: 231.32 | U7: 214.57 | V7: 195.24 | W7: 289.57 | Y7: Capital work in progress | Z7: 796.55 | AA7: 236.12 | AB7: 1170.32 | AC7: 2949.09 | AD7: 2897.04 | AE7: 2390.86 | AG7: Right of use assets | AH7: 265.0926 | AI7: 253.05 | AJ7: 335.5 | AK7: 313.39 | AL7: 328.88 | AM7: 346.13
A8: Capital work-in-progress | B8: 3216.33 | C8: 3697.13 | D8: 4022.9 | E8: 6814.03 | F8: 10936.09 | G8: 11592.19 | I8: Right of use assets | J8: 100.15 | K8: 109.79 | L8: 133.7 | M8: 106.16 | N8: 102.93 | O8: 161.78 | Q8: Capital work in progress | R8: 83.96 | S8: 17.9 | T8: 2.46 | U8: 11.45 | V8: 13.92 | W8: 38.52 | Y8: Investment Property | Z8: 490.4 | AA8: 421.61 | AB8: 3962.98 | AC8: 3360.22 | AD8: =1936.44+254.93 -> 2191.37 | AE8: =1157.33+501.3 -> 1658.63 | AG8: Capital work in progress | AH8: 18.3638 | AI8: 47.07 | AJ8: 1.2 | AK8: 1.27 | AL8: 93.79 | AM8: 0.32
A9: Investment Properties | B9: 0 | C9: 0 | D9: 0 | E9: 2473.38 | F9: 1345.3 | G9: 1459.16 | I9: Investment property | J9: 0.82 | K9: 0.82 | L9: 0.82 | M9: 0 | N9: 0 | O9: 0 | Q9: Goodwill | R9: 222.56 | S9: 215.36 | T9: 249.7 | U9: 268.49 | V9: 272.13 | W9: 278.22 | Y9: Goodwill | Z9: 0 | AA9: 0 | AB9: 7685.17 | AC9: 7798.65 | AD9: 7800.88 | AE9: 8348.48 | AG9: Intangible assets | AH9: 23.6478 | AI9: 19.88 | AJ9: 20.9 | AK9: 14.73 | AL9: 8.86 | AM9: 3.32
A10: Goodwill | B10: 3286.25 | C10: 4036.43 | D10: 6711.43 | E10: 6963.4 | F10: 6906.93 | G10: 7093.59 | I10: Goodwill | J10: 105.88 | K10: 114.76 | L10: 184.21 | M10: 183.61 | N10: 184.3 | O10: 184.73 | Q10: Intangible assets | R10: 87.99 | S10: 66.37 | T10: 44.68 | U10: 32.52 | V10: 19.68 | W10: 4.83 | Y10: Intangible assets | Z10: 83.72 | AA10: 55.39 | AB10: 18729.37 | AC10: 18007.98 | AD10: 17384.52 | AE10: 17050.76 | AG10: Intangible assets under development | AH10: 6.3706 | AI10: 6.37 | AJ10: 0 | AK10: 0 | AL10: 0 | AM10: 140.14
A11: Other intangible assets | B11: 1940.38 | C11: 5533.03 | D11: 11580.54 | E11: 11445.51 | F11: 11282.64 | G11: 12491.6 | I11: Other Intangible assets | J11: 1666.52 | K11: 1624.94 | L11: 1613.23 | M11: 853.88 | N11: 789.48 | O11: 723.84 | Q11: Investments | R11: 0 | S11: 0 | T11: 0 | U11: 0 | V11: 0 | W11: 0 | Y11: Intangible assets under development | Z11: 0.66 | AA11: 48.01 | AB11: 79.23 | AC11: 116.48 | AD11: 147.97 | AE11: 197.82 | AG11: Investments in Joint ventures | AH11: 1574.9679 | AI11: 1720.15 | AJ11: 1872.31 | AK11: 1893.76 | AL11: 2395.17 | AM11: 1764.13
A12: Intangible assets under development | B12: 0 | C12: 0 | D12: 0 | E12: 0 | F12: 0 | G12: 113.91 | I12: Intangible assets under development | J12: 4.2 | K12: 4.54 | L12: 4.72 | M12: 0 | N12: 0 | O12: 0 | Q12: Trade receivables | R12: 18.9 | S12: 182.13 | T12: 467.69 | U12: 359.3 | V12: 288.34 | W12: 214.93 | Y12: Right of use assets | Z12: 412.82 | AA12: 417.37 | AB12: 1989.51 | AC12: 2137.87 | AD12: 2289.41 | AE12: 2869.02 | AG12: Investments | AH12: 9.97 | AI12: 10 | AJ12: 10 | AK12: 10 | AL12: 10 | AM12: 0
A13: Investments accounted using equity method | B13: 826.01 | C13: 649.53 | D13: 1189.85 | E13: 2498.38 | F13: 2707.26 | G13: 3082.64 | I13: Investments | J13: 1.36 | K13: 1.13 | L13: 1.49 | M13: 1.55 | N13: 0 | O13: 0 | Q13: Loans | R13: 10.95 | S13: 13.24 | T13: 0 | U13: 0 | V13: 0 | Y13: Investments | Z13: 27975.28 | AA13: 28569.12 | AB13: =2521.16+7074.44 -> 9595.6 | AC13: =1304.86+7920.03 -> 9224.89 | AD13: =1264.25+9425.94 -> 10690.19 | AE13: =2318.42+9126.23 -> 11444.65 | AG13: Lease receivables | AH13: 1386.1361 | AI13: 1262.95 | AJ13: 1826.88 | AK13: 4964.36 | AL13: 4492.36 | AM13: 3992.85
A14: Investments | B14: 340.1 | C14: 447.86 | D14: 1923.1 | E14: 1059.47 | F14: 919.61 | G14: 824.93 | I14: Trade receivables | J14: 186.7 | K14: 187.85 | L14: 213.82 | M14: 188.79 | N14: 131.05 | O14: 80.5 | Q14: Other financial assets | R14: 0 | S14: 0 | T14: 41.03 | U14: 76.2 | V14: 61.94 | W14: 66.07 | Y14: Loans | Z14: 3507 | AA14: 2567.05 | AB14: =46736.84+284.54 -> 47021.38 | AC14: =40920.92+356 -> 41276.92 | AD14: =52154.76+475.46 -> 52630.22 | AE14: =62847.35+348.96 -> 63196.31 | AG14: Loans | AH14: 9.117 | AI14: 8.17 | AJ14: 6.06 | AK14: 4.87 | AL14: 4.07 | AM14: 4.72
A15: Loans | B15: 0 | C15: 235 | D15: 87 | E15: 1582.15 | F15: 55 | G15: 24 | I15: Loans | J15: 76.53 | K15: 88.88 | L15: 0 | M15: 0 | N15: 0 | O15: 0 | Q15: Deferred tax assets (net) | R15: 22.37 | S15: 61.93 | T15: 214.13 | U15: 327.31 | V15: 353.66 | W15: 452.7 | Y15: Other financial assets | Z15: 304.48 | AA15: 403.84 | AB15: 2134.9 | AC15: 1965.78 | AD15: 1952.08 | AE15: 1863.04 | AG15: Others | AH15: 519.4188 | AI15: 744.32 | AJ15: 1086.56 | AK15: 1799.66 | AL15: 2010.59 | AM15: 1177.53
A16: Loans to Joint venture entities | B16: 1264.37 | C16: 751.26 | D16: 484.41 | E16: 6.7 | F16: 4.52 | G16: 704.15 | I16: Others | J16: 36.55 | K16: 43.18 | L16: 160.5 | M16: 156.34 | N16: 194.73 | O16: 292.36 | Q16: Non-current tax assets (net) | R16: 155.81 | S16: 168.51 | T16: 179.43 | U16: 268.03 | V16: 294.06 | W16: 138.92 | Y16: Deferred tax assets (net) | Z16: 1428.2 | AA16: 494 | AB16: 2840.1 | AC16: 3984.79 | AD16: 3863.72 | AE16: 3792.88 | AG16: Deferred tax assets (net) | AH16: 42.7848 | AI16: 43.13 | AJ16: 13.15 | AK16: 13.81 | AL16: 13.99 | AM16: 45.29
A17: Other financial assets | I17: Deferred tax assets (net) | J17: 118.63 | K17: 129.94 | L17: 198.02 | M17: 178.43 | N17: 187.66 | O17: 270.52 | Q17: Other non-current assets | R17: 212.04 | S17: 323.25 | T17: 209.6 | U17: 217.88 | V17: 233.43 | W17: 235.53 | Y17: Current tax assets (net) | Z17: 0 | AA17: 0 | AB17: 0 | AC17: 0 | AD17: 4245.78 | AE17: 4581.6 | AG17: Other non-current assets | AH17: 0.4429 | AI17: 102.32 | AJ17: 204.68 | AK17: 255.99 | AL17: 479.63 | AM17: 0.38
A18: Bank deposits having maturity over 12 months | B18: 6.9 | C18: 89.42 | D18: 3072.08 | E18: 1552.97 | F18: 1523.53 | G18: 1633.51 | I18: Non-current tax assets (net) | J18: 7.13 | K18: 3.17 | L18: 7.18 | M18: 0.59 | N18: 1.17 | O18: 2 | Q18: Total non-current assets | R18: =SUM(R6:R17) -> 1855.81 | S18: =SUM(S6:S17) -> 2164.46 | T18: =SUM(T6:T17) -> 2651.99 | U18: =SUM(U6:U17) -> 2842.98 | V18: =SUM(V6:V17) -> 2873.62 | W18: =SUM(W6:W17) -> 2793.28 | Y18: Other non-current assets | Z18: 4068.94 | AA18: 3646.05 | AB18: 6077.62 | AC18: 5989.04 | AD18: 2156.55 | AE18: 2659.78 | AG18: Total non-current assets | AH18: =SUM(AH6:AH17) -> 3872.8759 | AI18: =SUM(AI6:AI17) -> 4236.63 | AJ18: =SUM(AJ6:AJ17) -> 5400.33 | AK18: =SUM(AK6:AK17) -> 9298.47 | AL18: =SUM(AL6:AL17) -> 9866.2 | AM18: =SUM(AM6:AM17) -> 8012.02
A19: Other financial assets | B19: 5052.26 | C19: 5010.85 | D19: 4607.95 | E19: 4567.78 | F19: 3167.65 | G19: 3323.67 | I19: Other non-current assets | J19: 55.34 | K19: 72.39 | L19: 133.54 | M19: 127.19 | N19: 137.81 | O19: 148.11 | Q19: Current Assets | Y19: Total non-current assets | Z19: =SUM(Z6:Z18) -> 45921.48 | AA19: =SUM(AA6:AA18) -> 44320.77 | AB19: =SUM(AB6:AB18) -> 111864.16 | AC19: =SUM(AC6:AC18) -> 108147.99 | AD19: =SUM(AD6:AD18) -> 121547.37 | AE19: =SUM(AE6:AE18) -> 134182.39 | AG19: Current assets
A20: Deferred tax assets (net) | B20: 1209.62 | C20: 881.73 | D20: 1357.83 | E20: 2199.9 | F20: 1918.67 | G20: 1889.58 | I20: Total non-current assets | J20: =SUM(J6:J19) -> 3980.96 | K20: =SUM(K6:K19) -> 4032.91 | L20: =SUM(L6:L19) -> 4297.75 | M20: =SUM(M6:M19) -> 3829.6 | N20: =SUM(N6:N19) -> 3758.78 | O20: =SUM(O6:O19) -> 4073.71 | Q20: Inventories | R20: 775.82 | S20: 842.2 | T20: 1066.48 | U20: 1137.16 | V20: 1213.31 | W20: 1140.46 | Y20: Current Assets | AG20: Project work in progress | AH20: 9.1819 | AI20: 23.49 | AJ20: 49.91 | AK20: 58.93 | AL20: 64.72 | AM20: 0
A21: Other non-current assets | B21: 2753.66 | C21: 2593.44 | D21: 2299.36 | E21: 4338.04 | F21: 5065.37 | G21: 3583.21 | I21: Current Assets | Q21: Investments | R21: 22.5 | S21: 1.06 | T21: 12.64 | U21: 0 | V21: 0 | W21: 0 | Y21: Inventories | Z21: 2769.9 | AA21: 2858.56 | AB21: 5943.32 | AC21: 6828.78 | AD21: 6620.19 | AE21: 7670.55 | AG21: Investments | AH21: 0 | AI21: 0 | AJ21: 0 | AK21: 0 | AL21: 0 | AM21: 0
A22: Total non-current assets | B22: =SUM(B6:B21) -> 47383.76 | C22: =SUM(C6:C21) -> 62493.14 | D22: =SUM(D6:D21) -> 81597.4 | E22: =SUM(E6:E21) -> 97457.61 | F22: =SUM(F6:F21) -> 101445.51 | G22: =SUM(G6:G21) -> 116388.11 | I22: Inventories | J22: 1208.55 | K22: 1071.08 | L22: 1096.03 | M22: 1228.47 | N22: 1353.36 | O22: 1428.76 | Q22: Trade receivables | R22: 5425.88 | S22: 5384.69 | T22: 5106.1 | U22: 6896.06 | V22: 4136.62 | W22: 5051.1 | Y22: Investments | Z22: 6059.15 | AA22: 18454.4 | AB22: 29799.58 | AC22: 35573.42 | AD22: 34957.63 | AE22: 43360.62 | AG22: Trade receivables | AH22: 834.7555 | AI22: 979.83 | AJ22: 938.17 | AK22: 969.3 | AL22: 1077.38 | AM22: 1489.51
A23: Current Assets | I23: Investments | J23: 0 | K23: 0 | L23: 3.2 | M23: 3.08 | N23: 0 | O23: 150.11 | Q23: Cash and cash equivalents | R23: 152.68 | S23: 199.79 | T23: 207.63 | U23: 281.16 | V23: 205.1 | W23: 545.69 | Y23: Trade receivables | Z23: 27912.96 | AA23: 29948.24 | AB23: 46139.32 | AC23: 44731.53 | AD23: 48770.95 | AE23: 53713.68 | AG23: Lease receivables | AH23: 265.7442 | AI23: 230.29 | AJ23: 279.95 | AK23: 377.28 | AL23: 472 | AM23: 499.51
A24: Inventories | B24: 288.28 | C24: 991.85 | D24: 395.64 | E24: 451.97 | F24: 437.51 | G24: 521.8 | I24: Trade receivables | J24: 4616.01 | K24: 5016.82 | L24: 4578.77 | M24: 5251.25 | N24: 5805.29 | O24: 7816.87 | Q24: Bank balances | R24: 10.99 | S24: 49.38 | T24: 54.31 | U24: 63 | V24: 68.18 | W24: 110.24 | Y24: Cash and cash equivalents | Z24: 3262.83 | AA24: 3112.69 | AB24: 13770.24 | AC24: 16926.69 | AD24: 11958.5 | AE24: 12187 | AG24: Cash and cash equivalents | AH24: 273.8076 | AI24: 1421 | AJ24: 4607.98 | AK24: 836.67 | AL24: 1104.05 | AM24: 3044.8
A25: Investments | B25: 11.89 | C25: 1138.76 | D25: 47.79 | E25: 4028.69 | F25: 661.79 | G25: 751.88 | I25: Cash and cash equivalents | J25: 499.48 | K25: 537.53 | L25: 1061.76 | M25: 956.43 | N25: 1009.33 | O25: 1601.69 | Q25: Loans | R25: 102.01 | S25: 99.67 | T25: 0 | U25: 0 | V25: 0 | W25: 0 | Y25: Other bank balances | Z25: 675.56 | AA25: 650.59 | AB25: 5182.93 | AC25: 5592.91 | AD25: 3399.89 | AE25: 10778.34 | AG25: Bank Balances | AH25: 709.4773 | AI25: 625.97 | AJ25: 2215.52 | AK25: 1016.64 | AL25: 2008.59 | AM25: 718.44
A26: Trade receivables | B26: 2589.09 | C26: 2385.9 | D26: 2221.9 | E26: 3241.67 | F26: 3666.94 | G26: 4432.36 | I26: Bank balances | J26: 46.62 | K26: 54.33 | L26: 132.26 | M26: 103.44 | N26: 22.66 | O26: 157.58 | Q26: Other financial assets | R26: 6.07 | S26: 18.99 | T26: 113.74 | U26: 164.61 | V26: 148.51 | W26: 144.42 | Y26: Loans | Z26: 515.14 | AA26: 434.91 | AB26: =42269.2+280.34 -> 42549.54 | AC26: =40460.55+251.15 -> 40711.7 | AD26: =34814.59+106.54 -> 34921.13 | AE26: =36077.51+416.85 -> 36494.36 | AG26: Loans | AH26: 9.748 | AI26: 4.99 | AJ26: 4.51 | AK26: 4.13 | AL26: 4.15 | AM26: 2.28
A27: Customers bills discounted | B27: 613.05 | C27: 539.81 | D27: 299.24 | E27: 699.12 | F27: 0 | G27: 0 | I27: Loans | J27: 300.67 | K27: 460.26 | L27: 151.34 | M27: 57.52 | N27: 62.82 | O27: 68.68 | Q27: Contract assets | R27: 3664.77 | S27: 4582.93 | T27: 6092.09 | U27: 6241.18 | V27: 9088.37 | W27: 11043.51 | Y27: Other financial assets | Z27: 1997.59 | AA27: 1693.05 | AB27: 3655.82 | AC27: 4930.1 | AD27: 5563.92 | AE27: 5419.89 | AG27: Others | AH27: 2558.3492 | AI27: 655.89 | AJ27: 923.74 | AK27: 2597.07 | AL27: 1960.92 | AM27: 2584.18
A28: Cash and cash equivalents | B28: 7195.46 | C28: 4198.04 | D28: 8653.02 | E28: 931.99 | F28: 1575.73 | G28: 3406.32 | I28: Others | J28: 119.14 | K28: 122.68 | L28: 271.75 | M28: 422.87 | N28: 465.63 | O28: 403.02 | Q28: Current tax assets (net) | R28: 23.01 | S28: 14.21 | T28: 28.42 | U28: 53.16 | V28: 179.89 | W28: 16.7 | Y28: Other current assets | Z28: 49661.61 | AA28: 46479.35 | AB28: 60331.55 | AC28: 65920.39 | AD28: 71391.03 | AE28: 75559.83 | AG28: Current tax assets (net) | AH28: 24.6419 | AI28: 0 | AJ28: 2.22 | AK28: 12.03 | AL28: 0 | AM28: 58.65
A29: Bank balances other than above | B29: 118.4 | C29: 502.74 | D29: 2014.39 | E29: 3316.79 | F29: 6056.15 | G29: 3199.65 | I29: Current tax assets (net) | J29: 66.02 | K29: 67.06 | L29: 122.2 | M29: 185.78 | N29: 161.49 | O29: 191.85 | Q29: Other current assets | R29: 837.41 | S29: 690.57 | T29: 1008.37 | U29: 989.24 | V29: 1117.87 | W29: 1334.52 | Y29: Assets classified as held for sale | Z29: 2780.37 | AA29: 0 | AB29: 830.78 | AC29: 988.8 | AD29: 1005.36 | AE29: 157.44 | AG29: Other current assets | AH29: 3832.6669 | AI29: 6043.04 | AJ29: 5458.7 | AK29: 3173.27 | AL29: 3053.98 | AM29: 3075.13
A30: Loans | B30: 1784.88 | C30: 1014.81 | D30: 1240.65 | E30: 107.77 | F30: 64 | G30: 70.6 | I30: Other current assets | J30: 3636.18 | K30: 3615.53 | L30: 4979.58 | M30: 6519.77 | N30: 8379.78 | O30: 8667.99 | Q30: Total current assets | R30: =SUM(R20:R29) -> 11021.14 | S30: =SUM(S20:S29) -> 11883.49 | T30: =SUM(T20:T29) -> 13689.78 | U30: =SUM(U20:U29) -> 15825.57 | V30: =SUM(V20:V29) -> 16157.85 | W30: =SUM(W20:W29) -> 19386.64 | Y30: Total Current assets | Z30: =SUM(Z21:Z29) -> 95635.11 | AA30: =SUM(AA21:AA29) -> 103631.79 | AB30: =SUM(AB21:AB29) -> 208203.08 | AC30: =SUM(AC21:AC29) -> 222204.32 | AD30: =SUM(AD21:AD29) -> 218588.6 | AE30: =SUM(AE21:AE29) -> 245341.71 | AG30: Total current assets | AH30: =SUM(AH20:AH29) -> 8518.3725 | AI30: =SUM(AI20:AI29) -> 9984.5 | AJ30: =SUM(AJ20:AJ29) -> 14480.7 | AK30: =SUM(AK20:AK29) -> 9045.32 | AL30: =SUM(AL20:AL29) -> 9745.79 | AM30: =SUM(AM20:AM29) -> 11472.5
A31: Loans to Joint venture entities | B31: 68 | C31: 68 | D31: 61.77 | E31: 300.33 | F31: 205.01 | G31: 102.57 | I31: Total current assets | J31: =SUM(J22:J30) -> 10492.67 | K31: =SUM(K22:K30) -> 10945.29 | L31: =SUM(L22:L30) -> 12396.89 | M31: =SUM(M22:M30) -> 14728.61 | N31: =SUM(N22:N30) -> 17260.36 | O31: =SUM(O22:O30) -> 20486.55 | Q31: Total assets | R31: =R18+R30 -> 12876.95 | S31: =S18+S30 -> 14047.95 | T31: =T18+T30 -> 16341.77 | U31: =U18+U30 -> 18668.55 | V31: =V18+V30 -> 19031.47 | W31: =W18+W30 -> 22179.92 | Y31: Total Assets | Z31: =Z19+Z30 -> 141556.59 | AA31: =AA19+AA30 -> 147952.56 | AB31: =AB19+AB30 -> 320067.24 | AC31: =AC19+AC30 -> 330352.31 | AD31: =AD19+AD30 -> 340135.97 | AE31: =AE19+AE30 -> 379524.1 | AG31: Total assets | AH31: =AH18+AH30 -> 12391.248 | AI31: =AI18+AI30 -> 14221.13 | AJ31: =AJ18+AJ30 -> 19881.03 | AK31: =AK18+AK30 -> 18343.79 | AL31: =AL18+AL30 -> 19611.99 | AM31: =AM18+AM30 -> 19484.52
A32: Other financial assets | B32: 986.69 | C32: 622.67 | D32: 525.45 | E32: 1263.85 | F32: 3441.08 | G32: 4471.8 | I32: Assets classified as held for sale | J32: 1305.52 | K32: 375.33 | L32: 516.87 | M32: 1022.64 | N32: 1018.57 | O32: 1023.83 | Q32: EQUITY AND LIABILITIES | Y32: Equity and Liabilities | AG32: EQUITY AND LIABILITIES
A33: Other current assets | B33: 1164.17 | C33: 1013.2 | D33: 730.09 | E33: 1164.08 | F33: 1177.4 | G33: 1800.39 | I33: Total Assets | J33: =J31+J32+J20 -> 15779.15 | K33: =K31+K32+K20 -> 15353.53 | L33: =L31+L32+L20 -> 17211.51 | M33: =M31+M32+M20 -> 19580.85 | N33: =N31+N32+N20 -> 22037.71 | O33: =O31+O32+O20 -> 25584.09 | Q33: Equity | Y33: Equity | AG33: Equity
A34: Total current assets | B34: =SUM(B24:B33) -> 14819.91 | C34: =SUM(C24:C33) -> 12475.78 | D34: =SUM(D24:D33) -> 16189.94 | E34: =SUM(E24:E33) -> 15506.26 | F34: =SUM(F24:F33) -> 17285.61 | G34: =SUM(G24:G33) -> 18757.37 | I34: EQUITY AND LIABILITIES | Q34: Equity share capital | R34: 51.42 | S34: 51.42 | T34: 51.42 | U34: 51.42 | V34: 51.42 | W34: 53.24 | Y34: Equity share capital | Z34: 280.78 | AA34: 280.91 | AB34: 281.01 | AC34: 281.1 | AD34: 274.93 | AE34: 275.04 | AG34: Equity share capital | AH34: 2085.0201 | AI34: 2085.02 | AJ34: 2085.02 | AK34: 2085.02 | AL34: 2085.02 | AM34: 2085.02
A35: Assets held for sale | B35: 0 | C35: 354.86 | D35: 1898.48 | E35: 1941.26 | F35: 186.75 | G35: 186.75 | I35: Equity | Q35: Other equity | R35: 2746.16 | S35: 3308.27 | T35: 3568.51 | U35: 3720 | V35: 4044.28 | W35: 5294.21 | Y35: Other equity | Z35: 51894.57 | AA35: 60132.63 | AB35: 82126.65 | AC35: 89044.85 | AD35: 86084.31 | AE35: 97380.56 | AG35: Other equity | AH35: 3030.8791 | AI35: 3551.06 | AJ35: 4312.38 | AK35: 5161.18 | AL35: =6660.66+0.17 -> 6660.83 | AM35: 6538.7
A36: Total Assets | B36: =B22+B34+B35 -> 62203.67 | C36: =C22+C34+C35 -> 75323.78 | D36: =D22+D34+D35 -> 99685.82 | E36: =E22+E34+E35 -> 114905.13 | F36: =F22+F34+F35 -> 118917.87 | G36: =G22+G34+G35 -> 135332.23 | I36: Equity share capital | J36: 30.94 | K36: 29.78 | L36: 29.78 | M36: 32.49 | N36: 32.49 | O36: 34.16 | Q36: Total equity | R36: =R34+R35 -> 2797.58 | S36: =S34+S35 -> 3359.69 | T36: =T34+T35 -> 3619.93 | U36: =U34+U35 -> 3771.42 | V36: =V34+V35 -> 4095.7 | W36: =W34+W35 -> 5347.45 | Y36: Non-controlling interests | Z36: 0 | AA36: 0 | AB36: 12966.07 | AC36: 14241.27 | AD36: 16190.42 | AE36: 17748.08 | AG36: Total equity | AH36: =AH34+AH35 -> 5115.8992 | AI36: =AI34+AI35 -> 5636.08 | AJ36: =AJ34+AJ35 -> 6397.4 | AK36: =AK34+AK35 -> 7246.2 | AL36: =AL34+AL35 -> 8745.85 | AM36: =AM34+AM35 -> 8623.72
A37: EQUITY AND LIABILITIES | I37: Other equity | J37: 3327.48 | K37: 3708.72 | L37: 4248.79 | M37: 4688.13 | N37: 5105.5 | O37: 6479.17 | Q37: Liabilities | Y37: Total equity | Z37: =Z34+Z35+Z36 -> 52175.35 | AA37: =AA34+AA35+AA36 -> 60413.54 | AB37: =AB34+AB35+AB36 -> 95373.73 | AC37: =AC34+AC35+AC36 -> 103567.22 | AD37: =AD34+AD35+AD36 -> 102549.66 | AE37: =AE34+AE35+AE36 -> 115403.68 | AG37: Liabilities
A38: Equity | I38: Equity attributable to owners of the company | J38: =J36+J37 -> 3358.42 | K38: =K36+K37 -> 3738.5 | L38: =L36+L37 -> 4278.57 | M38: =M36+M37 -> 4720.62 | N38: =N36+N37 -> 5137.99 | O38: =O36+O37 -> 6513.33 | Q38: Non-current liabilities | Y38: Liabilities | AG38: Non-current liabilities
A39: Equity share capital | B39: 406.35 | C39: 406.35 | D39: 422.47 | E39: 432.03 | F39: 432.03 | G39: 432.03 | I39: Non-controlling interests | J39: 136.75 | K39: 120.44 | L39: 138.9 | M39: -26.76 | N39: -25.18 | O39: -44.47 | Q39: Borrowings | R39: 152.66 | S39: 218.71 | T39: 393.26 | U39: 493.16 | V39: 236.01 | W39: 358.46 | Y39: Non-current liabilities | AG39: Borrowings | AH39: 4256.654 | AI39: 5671.51 | AJ39: 6315.43 | AK39: 6030.59 | AL39: 5515.77 | AM39: 4889.51
A40: Other Equity | B40: 25217.14 | C40: 30221.91 | D40: 41565.75 | E40: 45151.55 | F40: 52512.74 | G40: 62003.36 | I40: Total equity | J40: =J38+J39 -> 3495.17 | K40: =K38+K39 -> 3858.94 | L40: =L38+L39 -> 4417.47 | M40: =M38+M39 -> 4693.86 | N40: =N38+N39 -> 5112.81 | O40: =O38+O39 -> 6468.86 | Q40: Lease Liabilities | R40: 111.08 | S40: 113.06 | T40: 167.44 | U40: 163.17 | V40: 148.14 | W40: 211.48 | Y40: Borrowings | Z40: 7185.71 | AA40: 15868.21 | AB40: 61618.31 | AC40: 61217.68 | AD40: 56506.97 | AE40: 57503.34 | AG40: Lease liabilities | AH40: 0 | AI40: 11.2 | AJ40: 27.91 | AK40: 11.15 | AL40: 27.85 | AM40: 12.03
...

Sheet Income Statement
A1: Consolidated Income Statements
E2: #VALUE! | M2: #VALUE! | U2: #VALUE! | AC2: #VALUE! | AK2: #VALUE!
A3: Particulars | B3: 2020 | C3: 2021 | D3: 2022 | E3: 2023 | F3: 2024 | G3: 2025 | I3: Particulars | J3: 2020 | K3: 2021 | L3: 2022 | M3: 2023 | N3: 2024 | O3: 2025 | Q3: Particulars | R3: 2020 | S3: 2021 | T3: 2022 | U3: 2023 | V3: 2024 | W3: 2025 | Y3: Particulars | Z3: 2020 | AA3: 2021 | AB3: 2022 | AC3: 2023 | AD3: 2024 | AE3: 2025 | AG3: Particulars | AH3: 2020 | AI3: 2021 | AJ3: 2022 | AK3: 2023 | AL3: 2024 | AM3: 2025
A4: Income | I4: INCOME | Q4: INCOME | Y4: Continuing operations | AG4: Revenue
A5: Revenue from Operations | B5: 11438.77 | C5: 12549.6 | D5: 17118.79 | E5: 20851.91 | F5: 26710.56 | G5: 30475.33 | I5: Revenue from operations | J5: 12675.84 | K5: 12949.44 | L5: 14777.38 | M5: 16361.44 | N5: 19626.43 | O5: 22315.78 | Q5: Revenue from Operations | R5: 11965.37 | S5: 13114.2 | T5: 13742.26 | U5: 17281.71 | V5: 19914.17 | W5: 21846.7 | Y5: Income | AG5: Revenue from operations | AH5: 10068.681 | AI5: 14530.58 | AJ5: 15403.76 | AK5: 19381.71 | AL5: 20281.57 | AM5: 21889.23
A6: Gain arising from Infrastructure development | B6: 434.3 | C6: 0 | D6: 0 | E6: 0 | F6: 0 | G6: 603.27 | I6: Other income | J6: 44.04 | K6: 67.02 | L6: 88.92 | M6: 39.7 | N6: 63.99 | O6: 62.48 | Q6: Other income | R6: 11.1 | S6: 29.92 | T6: 13.43 | U6: 31.32 | V6: 52.41 | W6: 70.86 | Y6: Revenue from operations | Z6: 145452.36 | AA6: 135979.03 | AB6: 156521.23 | AC6: 183340.7 | AD6: 221112.91 | AE6: 255734.45 | AG6: Other income | AH6: 255.2419 | AI6: 245.6845 | AJ6: 739.19 | AK6: 800.23 | AL6: 996.44 | AM6: 1185.57
A7: Other income | B7: 1861.35 | C7: 1970.23 | D7: 2223.72 | E7: 1553.48 | F7: 1499.42 | G7: 1304.48 | I7: Total Income | J7: =J5+J6 -> 12719.88 | K7: =K5+K6 -> 13016.46 | L7: =L5+L6 -> 14866.3 | M7: =M5+M6 -> 16401.14 | N7: =N5+N6 -> 19690.42 | O7: =O5+O6 -> 22378.26 | Q7: Total income | R7: =R5+R6 -> 11976.47 | S7: =S5+S6 -> 13144.12 | T7: =T5+T6 -> 13755.69 | U7: =U5+U6 -> 17313.03 | V7: =V5+V6 -> 19966.58 | W7: =W5+W6 -> 21917.56 | Y7: Other income | Z7: 2360.9 | AA7: 3429.35 | AB7: 2267.08 | AC7: 2929.17 | AD7: 4158.03 | AE7: 4124.82 | AG7: Total income | AH7: =AH5+AH6 -> 10323.923 | AI7: =AI5+AI6 -> 14776.264 | AJ7: =AJ5+AJ6 -> 16142.95 | AK7: =AK5+AK6 -> 20181.94 | AL7: =AL5+AL6 -> 21278.01 | AM7: =AM5+AM6 -> 23074.8
A8: Total income | B8: =SUM(B5:B7) -> 13734.42 | C8: =SUM(C5:C7) -> 14519.83 | D8: =SUM(D5:D7) -> 19342.51 | E8: =SUM(E5:E7) -> 22405.39 | F8: =SUM(F5:F7) -> 28209.98 | G8: =SUM(G5:G7) -> 32383.08 | I8: EXPENSES | Q8: Expenses | Y8: Total income | Z8: =SUM(Z6:Z7) -> 147813.26 | AA8: =SUM(AA6:AA7) -> 139408.38 | AB8: =SUM(AB6:AB7) -> 158788.31 | AC8: =SUM(AC6:AC7) -> 186269.87 | AD8: =SUM(AD6:AD7) -> 225270.94 | AE8: =SUM(AE6:AE7) -> 259859.27 | AG8: Expenses
A9: Expenses | I9: Cost of materials consumed | J9: 5329.84 | K9: 4745.01 | L9: 6421.34 | M9: 6983.77 | N9: 8187.39 | O9: 8584.51 | Q9: Cost of materials consumed | R9: 5669.62 | S9: 5696.99 | T9: 6090.81 | U9: 6969.83 | V9: 8413.69 | W9: 9912.15 | Y9: Expenses | AG9: Expenses on operations | AH9: 9307.6557 | AI9: 13415.819 | AJ9: 14229.41 | AK9: 17903.33 | AL9: 18720.07 | AM9: 20181.86
A10: Operating expenses | B10: 3097.26 | C10: 3259.49 | D10: 4865.11 | E10: 5654.56 | F10: 7116.34 | G10: 8069.75 | I10: Changes in Inventories of finished goods and WIP | J10: -62.15 | K10: 13.9 | L10: 24.66 | M10: -13.46 | N10: 17.71 | O10: -3.72 | Q10: Changes in inventories of finished goods and WIP | R10: -78.03 | S10: 3.61 | T10: -141.79 | U10: 98.77 | V10: -5.7 | W10: 166.52 | Y10: Manufacturing, construction and operating expenses: | AG10: Employee benefit expenses | AH10: 161.1064 | AI10: 189.9382 | AJ10: 207.78 | AK10: 204.36 | AL10: 190.98 | AM10: 188.91
A11: Employee benefit expenses | B11: 546.52 | C11: 615.05 | D11: 779.43 | E11: 1178.17 | F11: 1896.4 | G11: 2008.66 | I11: Erection, sub-contracting and other project expenses | J11: 3978.06 | K11: 4553.35 | L11: 4693.16 | M11: 5413.5 | N11: 6595.43 | O11: 8357.68 | Q11: Erection and sub-contracting expenses | R11: 2826.65 | S11: 3907.01 | T11: 4509.15 | U11: 6552.24 | V11: 7176.82 | W11: 6831.64 | Y11: Cost of raw materials, components consumed | Z11: 15548.66 | AA11: 15571.4 | AB11: 17100.84 | AC11: 18995.11 | AD11: 19442.25 | AE11: 27655.02 | AG11: Finance costs | AH11: 51.9798 | AI11: 40.9855 | AJ11: 458.14 | AK11: 563.71 | AL11: 581.37 | AM11: 568.49
A12: Finance costs | I12: Employee benefit expenses | J12: 996.54 | K12: 1041.36 | L12: 1299.08 | M12: 1446.88 | N12: 1717.63 | O12: 2113.47 | Q12: Finance costs | R12: 307.98 | S12: 262.69 | T12: 316 | U12: 538.59 | V12: 655.13 | W12: 663.59 | Y12: Construction materials consumed | Z12: 30316.12 | AA12: 24558.23 | AB12: 33506.21 | AC12: 43237.35 | AD12: 54813.97 | AE12: 63526.44 | AG12: Depreciation, amortisation and impairment | AH12: 5.7372 | AI12: 20.2856 | AJ12: 22.92 | AK12: 20.91 | AL12: 22.32 | AM12: 20.94
A13: Interest and bank charges | B13: 1950.64 | C13: 2129.16 | D13: 2559.61 | E13: 2593.62 | F13: 2784.41 | G13: 2778 | I13: Finance costs | J13: 520.89 | K13: 435.73 | L13: 396.33 | M13: 466.75 | N13: 518.08 | O13: 576.53 | Q13: Employee benefit expense | R13: 1104.36 | S13: 1115.09 | T13: 1258.66 | U13: 1356.24 | V13: 1440.63 | W13: 1540.2 | Y13: Purchase of stock in trade | Z13: 841.09 | AA13: 1213.58 | AB13: 1069.5 | AC13: 1052.86 | AD13: 1063.77 | AE13: 1402.14 | AG13: Other expenses | AH13: 57.5203 | AI13: 119.2857 | AJ13: 86.71 | AK13: 90.98 | AL13: 124.1 | AM13: 165.63
A14: Derivative Loss/Gain (net) | B14: -137.5 | C14: 126.13 | D14: -15.69 | E14: -230.98 | F14: -51.47 | G14: -246.18 | I14: Depreciation and amortisation expense | J14: 339.64 | K14: 373.45 | L14: 350.78 | M14: 391.75 | N14: 473.29 | O14: 497.27 | Q14: Depreciation and amortisation | R14: 147.2 | S14: 152.53 | T14: 157.86 | U14: 161.48 | V14: 185.36 | W14: 183.68 | Y14: Stores, spares and tools consumed | Z14: 2184.46 | AA14: 2023.54 | AB14: 3091.07 | AC14: 4814.89 | AD14: 4432.02 | AE14: 4393.39 | AG14: CSR expenses | AH14: 11.4846 | AI14: 19.052 | AJ14: 0 | AK14: 0 | AL14: 0 | AM14: 0
A15: Total Finance costs | B15: =B13+B14 -> 1813.14 | C15: =C13+C14 -> 2255.29 | D15: =D13+D14 -> 2543.92 | E15: =E13+E14 -> 2362.64 | F15: =F13+F14 -> 2732.94 | G15: =G13+G14 -> 2531.82 | I15: Expected credit losses provision for loans and advances | J15: 79.47 | K15: 0 | L15: 95.26 | M15: 2.81 | N15: 0 | O15: 0 | Q15: Other expenses | R15: 1208.42 | S15: 1250.29 | T15: 1121.93 | U15: 1474.9 | V15: 1674.16 | W15: 1892.29 | Y15: Sub-contracting charges | Z15: 26454.05 | AA15: 22316.18 | AB15: 24772.33 | AC15: 25624.45 | AD15: 35054.35 | AE15: 40570.92 | AG15: Total expenses | AH15: =SUM(AH9:AH14) -> 9595.484 | AI15: =SUM(AI9:AI14) -> 13805.366 | AJ15: =SUM(AJ9:AJ14) -> 15004.96 | AK15: =SUM(AK9:AK14) -> 18783.29 | AL15: =SUM(AL9:AL14) -> 19638.84 | AM15: =SUM(AM9:AM14) -> 21125.83
A16: Depreciation and amortisation | B16: 1680.28 | C16: 2107.34 | D16: 3099.3 | E16: 3423.24 | F16: 3888.46 | G16: 4378.93 | I16: Other expenses | J16: 870.58 | K16: 1085.84 | L16: 1054.32 | M16: 1158.4 | N16: 1479.7 | O16: 1429.72 | Q16: Total expenses | R16: =SUM(R9:R15) -> 11186.2 | S16: =SUM(S9:S15) -> 12388.21 | T16: =SUM(T9:T15) -> 13312.62 | U16: =SUM(U9:U15) -> 17152.05 | V16: =SUM(V9:V15) -> 19540.09 | W16: =SUM(W9:W15) -> 21190.07 | Y16: Changes in inventories of finished goods, WIP | Z16: 647.7 | AA16: 343.37 | AB16: -2076.6 | AC16: -3156.64 | AD16: 1021.07 | AE16: -410.79 | AG16: Profit/loss before exceptional items and tax | AH16: =AH7-AH15 -> 728.4392 | AI16: =AI7-AI15 -> 970.898 | AJ16: =AJ7-AJ15 -> 1137.99 | AK16: =AK7-AK15 -> 1398.65 | AL16: =AL7-AL15 -> 1639.17 | AM16: =AM7-AM15 -> 1948.97
A17: Foreign exchange Gain/Loss (net) | B17: 1626.38 | C17: -715.24 | D17: 872.07 | E17: 1886.32 | F17: 112.82 | G17: 280.85 | I17: Total Expenses | J17: =SUM(J9:J16) -> 12052.87 | K17: =SUM(K9:K16) -> 12248.64 | L17: =SUM(L9:L16) -> 14334.93 | M17: =SUM(M9:M16) -> 15850.4 | N17: =SUM(N9:N16) -> 18989.23 | O17: =SUM(O9:O16) -> 21555.46 | Q17: Profit before exceptional items and tax | R17: =R7-R16 -> 790.27 | S17: =S7-S16 -> 755.91 | T17: =T7-T16 -> 443.07 | U17: =U7-U16 -> 160.98 | V17: =V7-V16 -> 426.49 | W17: =W7-W16 -> 727.49 | Y17: Other manufacturing, construction and operating expenses | Z17: 13328.71 | AA17: 12983.56 | AB17: 16471.05 | AC17: 20020.81 | AD17: 24486.49 | AE17: 27533.55 | AG17: Exceptional items | AH17: 12.4235 | AI17: 0 | AJ17: 0 | AK17: 0 | AL17: 0 | AM17: 0
A18: Other expenses | B18: 663.9 | C18: 691.62 | D18: 1077.74 | E18: 1185.73 | F18: 1833.9 | G18: 1975.55 | I18: Profit before share of profit/loss of JV and exceptional items | J18: =J7-J17 -> 667.01 | K18: =K7-K17 -> 767.82 | L18: =L7-L17 -> 531.37 | M18: =M7-M17 -> 550.74 | N18: =N7-N17 -> 701.19 | O18: =O7-O17 -> 822.8 | Q18: Exceptional items | R18: 0 | S18: 0 | T18: 43.64 | U18: 0 | V18: 0 | W18: 0 | Y18: Finance cost of financial services | Z18: 8041.88 | AA18: 7691.04 | AB18: 5952.54 | AC18: 6026.44 | AD18: 5714.9 | AE18: 6302.23 | AG18: Share in profit/loss of JV | AH18: 98.6199 | AI18: -16.5814 | AJ18: 68.72 | AK18: 103.52 | AL18: 80.11 | AM18: 104.94
A19: Total expenses | B19: =SUM(B10:B11,B15,B16:B18) -> 9427.48 | C19: =SUM(C10:C11,C15,C16:C18) -> 8213.55 | D19: =SUM(D10:D11,D15,D16:D18) -> 13237.57 | E19: =SUM(E10:E11,E15,E16:E18) -> 15690.66 | F19: =SUM(F10:F11,F15,F16:F18) -> 17580.86 | G19: =SUM(G10:G11,G15,G16:G18) -> 19245.56 | I19: Share of profit/loss from JV | J19: -23.38 | K19: -32.21 | L19: -19.89 | M19: 0 | N19: 0 | O19: 0 | Q19: Profit after exceptional items and tax | R19: =R17-R18 -> 790.27 | S19: =S17-S18 -> 755.91 | T19: =T17-T18 -> 399.43 | U19: =U17-U18 -> 160.98 | V19: =V17-V18 -> 426.49 | W19: =W17-W18 -> 727.49 | Y19: Employee benefits expense | Z19: 23114 | AA19: 24762.03 | AB19: 29695.79 | AC19: 37214.11 | AD19: 41171.02 | AE19: 46768.68 | AG19: Profit/Loss before tax | AH19: =AH16+AH17+AH18 -> 839.4826 | AI19: =AI16+AI17+AI18 -> 954.3166 | AJ19: =AJ16+AJ17+AJ18 -> 1206.71 | AK19: =AK16+AK17+AK18 -> 1502.17 | AL19: =AL16+AL17+AL18 -> 1719.28 | AM19: =AM16+AM17+AM18 -> 2053.91
A20: Profit before share of loss from JV, exceptional items and tax | B20: =B8-B19 -> 4306.94 | C20: =C8-C19 -> 6306.28 | D20: =D8-D19 -> 6104.94 | E20: =E8-E19 -> 6714.73 | F20: =F8-F19 -> 10629.12 | G20: =G8-G19 -> 13137.52 | I20: Profit before exceptiona items and tax | J20: =J18+J19 -> 643.63 | K20: =K18+K19 -> 735.61 | L20: =L18+L19 -> 511.48 | M20: =M18+M19 -> 550.74 | N20: =N18+N19 -> 701.19 | O20: =O18+O19 -> 822.8 | Q20: Tax expense | Y20: Sales, administration and other expense | Z20: 8646.71 | AA20: 8892 | AB20: 8733.89 | AC20: 8758.04 | AD20: 10419.42 | AE20: 11558.13 | AG20: Tax expense
A21: Share of loss from Joint ventures entities | B21: -4.39 | C21: -14.27 | D21: 17.39 | E21: 47.78 | F21: -161.69 | G21: 141.56 | I21: Exceptional items | J21: 4.06 | K21: 209.64 | L21: 184.93 | M21: 90.78 | N21: 0 | O21: 0 | Q21: Current tax | R21: 285.43 | S21: 280 | T21: 198.58 | U21: 121.74 | V21: 114.1 | W21: 269.96 | Y21: Finance cost | Z21: 2796.66 | AA21: 3913.44 | AB21: 3125.7 | AC21: 3207.16 | AD21: 3545.85 | AE21: 3334.37 | AG21: Current tax | AH21: 159.9869 | AI21: 206.0474 | AJ21: 226.31 | AK21: 324.72 | AL21: 382.62 | AM21: 485.05
A22: Profit before exceptional items and tax | B22: =B20+B21 -> 4302.55 | C22: =C20+C21 -> 6292.01 | D22: =D20+D21 -> 6122.33 | E22: =E20+E21 -> 6762.51 | F22: =F20+F21 -> 10467.43 | G22: =G20+G21 -> 13279.08 | I22: Profit before tax | J22: =J20+J21 -> 647.69 | K22: =K20+K21 -> 945.25 | L22: =L20+L21 -> 696.41 | M22: =M20+M21 -> 641.52 | N22: =N20+N21 -> 701.19 | O22: =O20+O21 -> 822.8 | Q22: Deferred tax | R22: -60.68 | S22: -76.81 | T22: -131.23 | U22: -136.79 | V22: -34.39 | W22: -113.21 | Y22: Depreciation, amortisation, impairment and obsolescnese | Z22: 2462.27 | AA22: 2904.21 | AB22: 2947.95 | AC22: 3502.25 | AD22: 3682.33 | AE22: 4121.18 | AG22: Earlier year tax | AH22: 0 | AI22: 0 | AJ22: -6.44 | AK22: -11.52 | AL22: -4.23 | AM22: -5.35
A23: Exceptional items | B23: -58.63 | C23: 0 | D23: -405.19 | E23: -1273.38 | F23: -373.7 | G23: -249.46 | I23: Tax expenses | Q23: Total tax expense | R23: =R21+R22 -> 224.75 | S23: =S21+S22 -> 203.19 | T23: =T21+T22 -> 67.35 | U23: =U21+U22 -> -15.05 | V23: =V21+V22 -> 79.71 | W23: =W21+W22 -> 156.75 | Y23: Total expenses | Z23: =SUM(Z11:Z22) -> 134382.31 | AA23: =SUM(AA11:AA22) -> 127172.58 | AB23: =SUM(AB11:AB22) -> 144390.27 | AC23: =SUM(AC11:AC22) -> 169296.83 | AD23: =SUM(AD11:AD22) -> 204847.44 | AE23: =SUM(AE11:AE22) -> 236755.26 | AG23: Deferred tax | AH23: -8.2478 | AI23: -5.0535 | AJ23: -4.73 | AK23: 6.28 | AL23: -0.86 | AM23: -0.26
A24: Profit before tax | B24: =B22+B23 -> 4243.92 | C24: =C22+C23 -> 6292.01 | D24: =D22+D23 -> 5717.14 | E24: =E22+E23 -> 5489.13 | F24: =F22+F23 -> 10093.73 | G24: =G22+G23 -> 13029.62 | I24: Current tax | J24: 226.14 | K24: 303.24 | L24: 191.59 | M24: 265.64 | N24: 223.4 | O24: 312.25 | Q24: Profit for the year | R24: =R19-R23 -> 565.52 | S24: =S17-S23 -> 552.72 | T24: =T17-T23 -> 375.72 | U24: =U17-U23 -> 176.03 | V24: =V17-V23 -> 346.78 | W24: =W17-W23 -> 570.74 | Y24: Profit before exceptional items and tax | Z24: =Z8-Z23 -> 13430.95 | AA24: =AA8-AA23 -> 12235.8 | AB24: =AB8-AB23 -> 14398.04 | AC24: =AC8-AC23 -> 16973.04 | AD24: =AD8-AD23 -> 20423.5 | AE24: =AE8-AE23 -> 23104.01 | AG24: Total tax expense | AH24: =AH21+AH23 -> 151.7391 | AI24: =AI21+AI23 -> 200.9939 | AJ24: =AJ21+AJ23+AJ22 -> 215.14 | AK24: =AK21+AK23+AK22 -> 319.48 | AL24: =AL21+AL23+AL22 -> 377.53 | AM24: =AM21+AM23+AM22 -> 479.44
A25: Tax expense | I25: Deferred tax | J25: 31.96 | K25: -20.03 | L25: -30.24 | M25: -59.14 | N25: -38.11 | O25: -56.72 | Y25: Exceptional items before tax (net) | Z25: 0 | AA25: 0 | AB25: 119.7 | AC25: -91.97 | AD25: 114.44 | AE25: 474.78 | AG25: Profit/loss for the year from continuing operations | AH25: =AH19-AH24 -> 687.7435 | AI25: =AI19-AI24 -> 753.3227 | AJ25: =AJ19-AJ24 -> 991.57 | AK25: =AK19-AK24 -> 1182.69 | AL25: =AL19-AL24 -> 1341.75 | AM25: =AM19-AM24 -> 1574.47
A26: Current tax | B26: 707.49 | C26: 1271.51 | D26: 888.2 | E26: 977.9 | F26: 1134.73 | G26: 2221.87 | I26: Total tax expenses | J26: =J24+J25 -> 258.1 | K26: =K24+K25 -> 283.21 | L26: =L24+L25 -> 161.35 | M26: =M24+M25 -> 206.5 | N26: =N24+N25 -> 185.29 | O26: =O24+O25 -> 255.53 | Q26: EPS | R26: =R24/'Company Info'!$D$11 -> 21.244177 | S26: =S24/'Company Info'!$D$11 -> 20.763336 | T26: =T24/'Company Info'!$D$11 -> 14.1142 | U26: =U24/'Company Info'!$D$11 -> 6.6126972 | V26: =V24/'Company Info'!$D$11 -> 13.027047 | W26: =W24/'Company Info'!$D$11 -> 21.44027 | Y26: Tax expense
A27: Deferred tax | B27: -144.6 | C27: 102.39 | D27: -124.24 | E27: -881.52 | F27: 399.85 | G27: -253.51 | I27: Profit for the year | J27: =J22-J26 -> 389.59 | K27: =K22-K26 -> 662.04 | L27: =L22-L26 -> 535.06 | M27: =M22-M26 -> 435.02 | N27: =N22-N26 -> 515.9 | O27: =O22-O26 -> 567.27 | Y27: Current tax | Z27: 3564.58 | AA27: 3923.39 | AB27: 22.77 | AC27: 448.35 | AD27: 20.83 | AE27: 0 | AG27: EPS | AH27: =AH25/'Company Info'!$F$11 -> 3.2984983 | AI27: =AI25/'Company Info'!$F$11 -> 3.6130239 | AJ27: =AJ25/'Company Info'!$F$11 -> 4.7556858 | AK27: =AK25/'Company Info'!$F$11 -> 5.6723197 | AL27: =AL25/'Company Info'!$F$11 -> 6.4351901 | AM27: =AM25/'Company Info'!$F$11 -> 7.5513424
A28: Less: Tax credit under Minimum alternate tax | B28: -103.5 | C28: -130.63 | D28: 0 | E28: 0 | F28: 455.16 | G28: 0 | Y28: Deferred tax | Z28: -301.38 | AA28: 87.43 | AB28: 0 | AC28: -676.31 | AD28: 0 | AE28: 0
A29: Total tax expense | B29: =SUM(B26:B28) -> 459.39 | C29: =SUM(C26:C28) -> 1243.27 | D29: =SUM(D26:D28) -> 763.96 | E29: =SUM(E26:E28) -> 96.38 | F29: =SUM(F26:F28) -> 1989.74 | G29: =SUM(G26:G28) -> 1968.36 | I29: EPS | J29: =J27/'Company Info'!$C$11 -> 22.813379 | K29: =K27/'Company Info'!$C$11 -> 38.767343 | L29: =L27/'Company Info'!$C$11 -> 31.331724 | M29: =M27/'Company Info'!$C$11 -> 25.473642 | N29: =N27/'Company Info'!$C$11 -> 30.209764 | O29: =O27/'Company Info'!$C$11 -> 33.217858 | Y29: Net Profit after tax from continuing operations | Z29: =Z24-(Z27+Z28) -> 10167.75 | AA29: =AA24-(AA27+AA28) -> 8224.98 | AB29: =AB24-(AB27+AB28)+AB25 -> 14494.97 | AC29: =AC24-(AC27+AC28)+AC25 -> 17109.03 | AD29: =AD24-(AD27+AD28)+AD25 -> 20517.11 | AE29: =AE24-(AE27+AE28)+AE25 -> 23578.79
A30: Profit for the year | B30: =B24-B29 -> 3784.53 | C30: =C24-C29 -> 5048.74 | D30: =D24-D29 -> 4953.18 | E30: =E24-E29 -> 5392.75 | F30: =F24-F29 -> 8103.99 | G30: =G24-G29 -> 11061.26 | Y30: Exceptional items before tax | Z30: 0 | AA30: -3693.78 | AB30: 0 | AC30: 0 | AD30: 0 | AE30: 0
Y31: Tax expense on exceptional items
A32: EPS | B32: =B30/'Company Info'!$B$11 -> 17.519845 | C32: =C30/'Company Info'!$B$11 -> 23.372292 | D32: =D30/'Company Info'!$B$11 -> 22.929913 | E32: =E30/'Company Info'!$B$11 -> 24.964829 | F32: =F30/'Company Info'!$B$11 -> 37.516058 | G32: =G30/'Company Info'!$B$11 -> 51.206242 | Y32: Current tax | Z32: 0 | AA32: 48.44 | AB32: 4499.4 | AC32: 5055.17 | AD32: 5127.7 | AE32: 6100.82
Y33: Deferred tax | Z33: 0 | AA33: -186.2 | AB33: -295.48 | AC33: -571.01 | AD33: -180.31 | AE33: -209.42
Y34: Exceptional items (net of tax) | Z34: =Z30-(Z32+Z33) -> 0 | AA34: =AA30-(AA32+AA33) -> -3556.02 | AB34: =AB30-(AB32+AB33) -> -4203.92 | AC34: =AC30-(AC32+AC33) -> -4484.16 | AD34: =AD30-(AD32+AD33) -> -4947.39 | AE34: =AE30-(AE32+AE33) -> -5891.4
Y35: Net Profit after tax from continuing operations | Z35: =Z29+Z34 -> 10167.75 | AA35: =AA29+AA34 -> 4668.96 | AB35: =AB29+AB34 -> 10291.05 | AC35: =AC29+AC34 -> 12624.87 | AD35: =AD29+AD34 -> 15569.72 | AE35: =AE29+AE34 -> 17687.39
Y36: Share in profit/loss after tax of joint ventures (net) | Z36: 71.96 | AA36: 14.4 | AB36: 128.19 | AC36: -94.25 | AD36: -22.62 | AE36: -14.06
Y37: Profit for the year from continuing operations | Z37: =Z35+Z36 -> 10239.71 | AA37: =AA35+AA36 -> 4683.36 | AB37: =AB35+AB36 -> 10419.24 | AC37: =AC35+AC36 -> 12530.62 | AD37: =AD35+AD36 -> 15547.1 | AE37: =AE35+AE36 -> 17673.33
Y38: Discontinued operations
Y39: Profit before tax from discontinued operations | Z39: 883.25 | AA39: 10790.5 | AB39: 0 | AC39: 0 | AD39: 0 | AE39: 0
Y40: Tax expense of discontinued operations | Z40: 228.68 | AA40: 2552.58 | AB40: 0 | AC40: 0 | AD40: 0 | AE40: 0
...

Sheet Cash Flow Statement
A1: Consolidated Statement of Cash Flows
E2: #VALUE! | M2: #VALUE! | U2: #VALUE! | AC2: #VALUE! | AK2: #VALUE!
A3: Particulars | B3: 2020 | C3: 2021 | D3: 2022 | E3: 2023 | F3: 2024 | G3: 2025 | I3: Particulars | J3: 2020 | K3: 2021 | L3: 2022 | M3: 2023 | N3: 2024 | O3: 2025 | Q3: Particulars | R3: 2020 | S3: 2021 | T3: 2022 | U3: 2023 | V3: 2024 | W3: 2025 | Y3: Particulars | Z3: 2020 | AA3: 2021 | AB3: 2022 | AC3: 2023 | AD3: 2024 | AE3: 2025 | AG3: Particulars | AH3: 2020 | AI3: 2021 | AJ3: 2022 | AK3: 2023 | AL3: 2024 | AM3: 2025
A4: Cash Flows from Operating Activities | I4: Cash flow from Operating activities | Q4: CASH FLOW FROM OPERATING ACTIVITIES | Y4: CASH FLOW FROM OPERATING ACTIVITIES | AG4: CASH FLOW FROM OPERATING ACTIVITIES
A5: Net profit before tax | B5: 4243.92 | C5: 6292.01 | D5: 5717.14 | E5: 5489.13 | F5: 10093.73 | G5: 13029.62 | I5: Profit for the year | J5: 389.59 | K5: 662.04 | L5: 535.06 | M5: 435.02 | N5: 515.9 | O5: 567.27 | Q5: Profit for the year after tax | R5: 565.52 | S5: 552.72 | T5: 332.08 | U5: 176.03 | V5: 346.78 | W5: 570.74 | Y5: Profit before tax | AG5: Net profit before taxation | AH5: 954.3166 | AI5: 1206.71 | AJ5: 1502.17 | AK5: 1719.28 | AL5: 2053.91 | AM5: 1550.17
A6: Adjustments for | I6: Adjustments for | Q6: Adjustments for | Y6: Continuing operations | Z6: 13430.95 | AA6: 12235.8 | AB6: 14398.04 | AC6: 16973.04 | AD6: 20423.5 | AE6: 23104.01 | AG6: Adjustments for
A7: Share of profit/loss of joint ventures entities | B7: 4.39 | C7: 14.27 | D7: -17.39 | E7: -47.78 | F7: 161.69 | G7: -141.56 | I7: Tax expenses | J7: 258.1 | K7: 283.21 | L7: 161.35 | M7: 206.5 | N7: 185.29 | O7: 255.53 | Q7: Income tax expense | R7: 224.75 | S7: 203.19 | T7: 67.35 | U7: -15.05 | V7: 79.71 | W7: 156.75 | Y7: Discontinued operations | Z7: 883.25 | AA7: 10790.5 | AB7: 0 | AC7: 0 | AD7: 0 | AE7: 0 | AG7: Depreciation, amortization and impairment | AH7: 34.8849 | AI7: 0.74 | AJ7: -0.21 | AK7: 0 | AL7: 0 | AM7: 0
A8: Depreciation and amortisation expense | B8: 1680.28 | C8: 2107.34 | D8: 3099.3 | E8: 3423.24 | F8: 3888.46 | G8: 4378.93 | I8: Share of loss of Joint venture | J8: 23.38 | K8: 32.21 | L8: 19.89 | M8: 0 | N8: 473.29 | O8: 497.27 | Q8: Depreciation and amortisation expense | R8: 147.2 | S8: 152.53 | T8: 157.86 | U8: 161.48 | V8: 185.36 | W8: 183.68 | Y8: Profit before tax including discontinued operations | Z8: =Z6+Z7 -> 14314.2 | AA8: =AA6+AA7 -> 23026.3 | AB8: =AB6+AB7 -> 14398.04 | AC8: =AC6+AC7 -> 16973.04 | AD8: =AD6+AD7 -> 20423.5 | AE8: =AE6+AE7 -> 23104.01 | AG8: Share in (Profit)/Losses of Joint Ventures | AH8: 16.5814 | AI8: 36.67 | AJ8: 37.07 | AK8: 42.32 | AL8: 37.78 | AM8: 47.09
A9: Unclaimed Liabilities/excess provision written back | B9: -1.84 | C9: -5.38 | D9: -20.47 | E9: -20.85 | F9: -99.12 | G9: -43.52 | I9: Depreciation and amortization expenses | J9: 339.64 | K9: 373.45 | L9: 350.78 | M9: 391.75 | N9: 518.08 | O9: 576.53 | Q9: Profit on sale of PPE | R9: -0.06 | S9: -8.34 | T9: -0.98 | U9: -4.46 | V9: -3.26 | W9: -8.56 | Y9: Adjustments for | AG9: Unwinding of Interest Cost on Lease obligation | AH9: 3.9101 | AI9: -68.72 | AJ9: -103.52 | AK9: -80.11 | AL9: -104.94 | AM9: =0.05+0.57-0.27+24.75-25.05+0.68+0.04 -> 0.77
A10: Cost of assets transferred under finance lease | B10: 19.8 | C10: 4.2 | D10: 8.62 | E10: 8.38 | F10: 5.27 | G10: 7.12 | I10: Finance costs | J10: 520.89 | K10: 435.73 | L10: 396.33 | M10: 466.75 | N10: -57.8 | O10: -43.34 | Q10: Loss on PPE discarded & intangible assets derecognised | R10: 0.5 | S10: 0.86 | T10: 0.67 | U10: 0.95 | V10: 2.64 | W10: 3.32 | Y10: Dividend received | Z10: -101.6 | AA10: -28.47 | AB10: -4.12 | AC10: -6.28 | AD10: -208.49 | AE10: -117.05 | AG10: Unwinding of Interest Cost Retention Money | AH10: 1.5859 | AI10: 3.01 | AJ10: 3.16 | AK10: 3.1 | AL10: 4.02 | AM10: 4.25
A11: Recognition of deferred income under long term land lease | B11: -71.8 | C11: -65.62 | D11: -65.63 | E11: -69.57 | F11: -75.37 | G11: -82.61 | I11: Impairment loss on PPE | J11: 6.89 | K11: 0 | L11: 37.71 | M11: 18.22 | N11: 2.13 | O11: -8.92 | Q11: Finance costs | R11: 307.98 | S11: 262.69 | T11: 316 | U11: 538.59 | V11: 655.13 | W11: 663.59 | Y11: Depreciation, amortisation, impairment and obsolescene | Z11: 2462.27 | AA11: 2904.21 | AB11: 2947.95 | AC11: 3502.25 | AD11: 3682.33 | AE11: 4121.18 | AG11: Unwinding of Interest Cost on Performance and Security Deposit | AH11: 8.3178 | AI11: 1.14 | AJ11: 0.3 | AK11: 0.09 | AL11: -2.03 | AM11: 0.02
A12: Financial guarantees income | B12: -1.52 | C12: -2.71 | D12: -4.38 | E12: -6.53 | F12: -8.54 | G12: 0 | I12: Gain on sale of subsidiary and Joint ventures (net) | J12: -12.3 | K12: -209.64 | L12: -262.41 | M12: 0 | N12: -0.93 | O12: -0.23 | Q12: Interest income | R12: -3.27 | S12: -4.74 | T12: -10.56 | U12: -23.2 | V12: -45.32 | W12: -55.24 | Y12: Exchange difference rate changes on cash and cash equivalents | Z12: 5.69 | AA12: -75.47 | AB12: -108.09 | AC12: -1.83 | AD12: -20.53 | AE12: -5.91 | AG12: Profit on sale of assets (net) | AH12: -0.0004 | AI12: -50 | AJ12: 0 | AK12: 18.22 | AL12: -14.5 | AM12: 1.12
A13: Amortisation of government grant | B13: -12.48 | C13: -12.95 | D13: -14.23 | E13: -16.34 | F13: -20.61 | G13: -23.82 | I13: Dividend income | J13: -0.07 | K13: -16.32 | L13: -0.1 | M13: -0.08 | N13: 81.7 | O13: 32.84 | Q13: Bad debts, loans and advances written off | R13: 27.6 | S13: 42.43 | T13: -10.68 | U13: 17.66 | V13: 2.17 | W13: 46.97 | Y13: Unrealised gain/loss on finance leases | Z13: -88.14 | AA13: 74.98 | AB13: -41.25 | AC13: -66.92 | AD13: -2.37 | AE13: -2.17 | AG13: Interest Income | AH13: -214.5683 | AI13: 429.87 | AJ13: 529.72 | AK13: =0.78+0.13+529.48 -> 530.39 | AL13: =-0.23-9.24-25.81+503.95 -> 468.67 | AM13: 457.82
A14: Finance cost | B14: 1950.64 | C14: 2129.16 | D14: 2559.61 | E14: 2593.62 | F14: 2784.41 | G14: 2778 | I14: Interest income | J14: -36.22 | K14: -30.13 | L14: -35.28 | M14: -34.05 | N14: 0.03 | O14: 0 | Q14: Exceptional items | R14: 26.8 | S14: 41.38 | T14: 43.64 | U14: 0 | V14: 90.91 | W14: 216.7 | Y14: Finance costs | Z14: 0 | AA14: -14.55 | AB14: 0 | AC14: 0 | AD14: 0 | AE14: 0 | AG14: Dividend Income | AH14: -0.7084 | AI14: -652.33 | AJ14: -763.47 | AK14: -956.39 | AL14: -1066.75 | AM14: -874.53
A15: Effect of exchange rate change | B15: 1709.73 | C15: -729.14 | D15: 917.91 | E15: 2527.76 | F15: 328.79 | G15: 719.33 | I15: Gain on disposal of PPE | J15: -0.56 | K15: -8.5 | L15: -18.61 | M15: 6.65 | N15: 42.35 | O15: -13.62 | Q15: Allowances for bad and doubtful debts, loans and advances | R15: 92.11 | S15: 2.74 | T15: 28.24 | U15: 32.8 | V15: -7.69 | W15: 9.71 | Y15: Interest income | Z15: 2796.66 | AA15: 3913.44 | AB15: 3125.7 | AC15: 3207.16 | AD15: 3545.85 | AE15: 3334.37 | AG15: Other Comprehensive Income | AH15: 2.4141 | AI15: =-7.83+0.04 -> -7.79 | AJ15: =0.03-3.04 -> -3.01 | AK15: 0 | AL15: =-0.19+1.4 -> 1.21 | AM15: 0
A16: Gain on account of dilution of stake in subsidiary | B16: -480.57 | C16: 0 | D16: -15.69 | E16: -230.98 | F16: -51.47 | G16: -246.18 | I16: Bad debts written off | J16: 7.68 | K16: 8.74 | L16: 0.25 | M16: 0 | N16: -0.23 | O16: -0.17 | Q16: Mark to market loss/gain on forward and commodity contracts | R16: -85.39 | S16: 32.72 | T16: -12.36 | U16: 15.38 | V16: 47.02 | W16: -2.09 | Y16: Profit/loss on sale of fixed assets | Z16: -829.78 | AA16: -1377.66 | AB16: -1053.65 | AC16: -1817.47 | AD16: -2447.07 | AE16: -2449.87 | AG16: Operating Profit Before Working Capital Changes | AH16: =SUM(AH5,AH7:AH15) -> 806.7337 | AI16: =SUM(AI5,AI7:AI15) -> 899.3 | AJ16: =SUM(AJ5,AJ7:AJ15) -> 1202.21 | AK16: =SUM(AK5,AK7:AK15) -> 1276.9 | AL16: =SUM(AL5,AL7:AL15) -> 1377.37 | AM16: =SUM(AM5,AM7:AM15) -> 1186.71
A17: Derivative Loss/gain (net) | B17: -137.5 | C17: 126.13 | D17: 12.53 | E17: -7.49 | F17: -5.31 | G17: -2.27 | I17: Liabilities written off | J17: -1.51 | K17: -4.4 | L17: -21.67 | M17: -0.57 | N17: 0 | O17: 0 | Q17: Net unrealised exchange gain/loss | R17: 0 | S17: 0 | T17: 16.59 | U17: -46.44 | V17: 0 | W17: 0 | Y17: Profit/loss on sale/fair valuation of investments | Z17: 33.28 | AA17: -528.81 | AB17: -17.6 | AC17: -167.65 | AD17: -95.44 | AE17: -187.64 | AG17: Adjustments for
A18: Provision of doubtful debts | B18: 19.47 | C18: 25 | D18: 41.25 | E18: 1 | F18: -860.19 | G18: -687.98 | I18: Allowance for expected credit loss | J18: 76.89 | K18: 26.77 | L18: 39.26 | M18: -10.27 | N18: 0 | O18: 0 | Q18: Operating profit before working capital changes | R18: =SUM(R5,R7:R17) -> 1303.74 | S18: =SUM(S5,S7:S17) -> 1278.18 | T18: =SUM(T5,T7:T17) -> 927.85 | U18: =SUM(U5,U7:U17) -> 853.74 | V18: =SUM(V5,V7:V17) -> 1353.45 | W18: =SUM(W5,W7:W17) -> 1785.57 | Y18: Gain/loss on disposal of discontinued operations | Z18: -733.84 | AA18: -1118.77 | AB18: -440.14 | AC18: -52.87 | AD18: -734.2 | AE18: -1133.12 | AG18: Trade Receivables (Current) | AH18: -196.7422 | AI18: -145.08 | AJ18: 41.66 | AK18: -31.91 | AL18: -108.08 | AM18: -383.03
A19: Interest income | B19: -1669.74 | C19: -1758.17 | D19: -1940.71 | E19: -1246.28 | F19: -209.51 | G19: -251.87 | I19: Impairment loss on asset held for sale | J19: 0.27 | K19: 0.86 | L19: 95.26 | M19: 2.81 | N19: 0 | O19: 0 | Q19: Adjustments for | Y19: Gain/loss on derivatives at fair value through profit or loss | Z19: 0 | AA19: -10707.92 | AB19: 0 | AC19: 0 | AD19: 0 | AE19: 0 | AG19: Lease receivables | AH19: 155.8103 | AI19: 123.19 | AJ19: -563.93 | AK19: -3137.49 | AL19: 472.01 | AM19: 499.51
A20: Dividend income | B20: -8 | C20: -7.01 | D20: -4.01 | E20: -0.35 | F20: -19.41 | G20: -20.52 | I20: Unrealised foreign exchange gain/loss (net) | J20: -95.14 | K20: 50.78 | L20: =0.68-29.27 -> -28.59 | M20: =0.05-9.76 -> -9.71 | N20: 0 | O20: 0 | Q20: Inventories | R20: -134.81 | S20: -66.38 | T20: -213.09 | U20: -46.8 | V20: -71.9 | W20: 72.85 | Y20: Employee stock option | Z20: -13.19 | AA20: 0 | AB20: 0 | AC20: 0 | AD20: 0 | AE20: 0 | AG20: Lease receivables (current) | AH20: -3.0986 | AI20: 35.46 | AJ20: -49.67 | AK20: -97.33 | AL20: -94.71 | AM20: -27.51
A21: Net gain on sale of current investments | B21: -48.7 | C21: -12.39 | D21: -5.41 | E21: -20.71 | F21: 373.7 | G21: 249.46 | I21: Net gain/loss arising on financial assets | J21: 0.19 | K21: -0.27 | L21: -0.3 | M21: -0.14 | N21: 0 | O21: 0 | Q21: Trade receivables | R21: -475.64 | S21: -324.1 | T21: 8.3 | U21: -1602.52 | V21: 144.68 | W21: -992.62 | Y21: Non cash items related to discontinued operations | Z21: 190.84 | AA21: 137.67 | AB21: 135.31 | AC21: 249.51 | AD21: 297.63 | AE21: 222.6 | AG21: Project work in progress | AH21: -4.7017 | AI21: -14.31 | AJ21: -44.44 | AK21: -9.02 | AL21: -5.79 | AM21: 64.72
A22: Gain on disposal of associate | B22: 0 | C22: -92.28 | D22: 405.19 | E22: 1273.38 | F22: 0 | G22: -603.27 | I22: Operating profit before working capital changes | J22: =SUM(J5,J7:J21) -> 1477.72 | K22: =SUM(K5,K7:K21) -> 1604.53 | L22: =SUM(L5,L7:L21) -> 1268.93 | M22: =SUM(M5,M7:M21) -> 1472.88 | N22: =SUM(N5,N7:N21) -> 1759.81 | O22: =SUM(O5,O7:O21) -> 1863.16 | Q22: Other financial assets | R22: -71.18 | S22: 0.36 | T22: 39.22 | U22: -86.09 | V22: 60.14 | W22: -23.42 | Y22: Business combination expenses | Z22: 49.44 | AA22: 3.13 | AB22: -1.65 | AC22: 0 | AD22: -2.65 | AE22: 0 | AG22: Other non current financial assets | AH22: 261.1774 | AI22: -216.16 | AJ22: -344.03 | AK22: -711.49 | AL22: -214.54 | AM22: 838.75
A23: Provision for royalty on storage | B23: 58.63 | C23: 0 | D23: -59.23 | E23: 0 | F23: 19.7 | G23: 8.61 | I23: Adjustments for | Q23: Contract assets | R23: -286.14 | S23: -994.49 | T23: -1580.48 | U23: -132.38 | V23: -1645.8 | W23: -2017.72 | Y23: Impairment of debt instruments | Z23: 84.28 | AA23: 0 | AB23: 12 | AC23: 716.2 | AD23: 1055.47 | AE23: 148.52 | AG23: Other financial assets | AH23: -2083.8398 | AI23: 1907.07 | AJ23: -252.53 | AK23: 1258.09 | AL23: 1425.98 | AM23: -532.75
A24: Diminution in value of inventories | B24: 0.16 | C24: 2.49 | D24: 1.83 | E24: 30.77 | F24: 0 | G24: 0 | I24: Trade and other receivables | J24: -695.49 | K24: -615.85 | L24: -950.18 | M24: -2321.71 | N24: -2486.27 | O24: -2338.81 | Q24: Other current assets | R24: 21.74 | S24: 147.02 | T24: -311.59 | U24: 27.65 | V24: -132.73 | W24: -221.95 | Y24: Impairment recognised on non-current assets held for sale | Z24: 350.59 | AA24: 151.26 | AB24: -6.11 | AC24: -10.16 | AD24: -511.73 | AE24: -187.44 | AG24: Other non current assets | AH24: -0.2068 | AI24: 1.25 | AJ24: -0.26 | AK24: 0.01 | AL24: -0.07 | AM24: 299.33
A25: Amortisation of fair valuation adjustment on security deposit | B25: 1.72 | C25: 1.72 | D25: 1.72 | E25: 1.72 | F25: 1.72 | G25: 2.67 | I25: Inventories | J25: -95.31 | K25: 137.47 | L25: 13.5 | M25: -132.44 | N25: -124.87 | O25: -75.4 | Q25: Other non-current assets | R25: -24.99 | S25: -110.35 | T25: 113.91 | U25: -18.86 | V25: -9.3 | W25: -6.56 | Y25: Gain/loss on de-recognition of lease liability | Z25: =3.93-1.85 -> 2.08 | AA25: =0.23-15.78 -> -15.55 | AB25: 0 | AC25: 0 | AD25: -52.27 | AE25: -33.29 | AG25: Other current assets | AH25: 1916.0358 | AI25: -2231.18 | AJ25: 568.87 | AK25: 351.03 | AL25: 121.65 | AM25: -38.07
A26: Loss on sale/discard of PPE (net) | B26: 3.86 | C26: 3.55 | D26: 3.52 | E26: -60.32 | F26: -8.89 | G26: -8.36 | I26: Trade, other payables and provisions | J26: 512.19 | K26: 51.1 | L26: 644.87 | M26: 1864.6 | N26: 1976.58 | O26: 1736.91 | Q26: Trade payables | R26: 156.71 | S26: 1183.86 | T26: 692.48 | U26: 1515.27 | V26: 1384.32 | W26: 1244.06 | Y26: Interest expenses | Z26: 1.33 | AA26: 1.16 | AB26: 0 | AC26: 0 | AD26: 1.38 | AE26: 11.57 | AG26: Trade payables | AH26: 522.0482 | AI26: -427.51 | AJ26: -47.77 | AK26: 397.21 | AL26: -370.37 | AM26: 91.78
A27: Operating profit before working capital changes | B27: =SUM(B5,B7:B26) -> 7260.45 | C27: =SUM(C5,C7:C26) -> 8020.22 | D27: =SUM(D5,D7:D26) -> 10621.47 | E27: =SUM(E5,E7:E26) -> 13621.8 | F27: =SUM(F5,F7:F26) -> 16299.05 | G27: =SUM(G5,G7:G26) -> 19061.78 | I27: Cash generated from Operations | J27: =SUM(J22,J24:J26) -> 1199.11 | K27: =SUM(K22,K24:K26) -> 1177.25 | L27: =SUM(L22,L24:L26) -> 977.12 | M27: =SUM(M22,M24:M26) -> 883.33 | N27: =SUM(N22,N24:N26) -> 1125.25 | O27: =SUM(O22,O24:O26) -> 1185.86 | Q27: Other current liabilities | R27: -56.46 | S27: -122.82 | T27: 0.58 | U27: 88.14 | V27: -576.31 | W27: -53.52 | Y27: Operating profit before working capital changes | Z27: =SUM(Z8,Z10:Z26) -> 18524.11 | AA27: =SUM(AA8,AA10:AA26) -> 16344.95 | AB27: =SUM(AB8,AB10:AB26) -> 18946.39 | AC27: =SUM(AC8,AC10:AC26) -> 22524.98 | AD27: =SUM(AD8,AD10:AD26) -> 24931.41 | AE27: =SUM(AE8,AE10:AE26) -> 26825.76 | AG27: Other current financial liabilities | AH27: 234.765 | AI27: 300.34 | AJ27: 840.19 | AK27: 181.21 | AL27: -13.69 | AM27: 284.08
A28: Adjustments for: | I28: Income tax paid | J28: -261.87 | K28: -246.25 | L28: -263.46 | M28: -226.94 | N28: -282.29 | O28: -271.91 | Q28: Contract liabilities | R28: -10.11 | S28: 55.13 | T28: 308.94 | U28: 220.87 | V28: 83.88 | W28: 27.17 | Y28: Adjustments for | AG28: Other non current liabilities | AH28: 20.7787 | AI28: -11.08 | AJ28: -14.23 | AK28: 0 | AL28: 0 | AM28: -81.33
A29: Decrease/Increase in trade receivables | B29: -175.66 | C29: 295.2 | D29: 230.18 | E29: -787.07 | F29: -329.79 | G29: -450.99 | I29: Net cash generated from/used in operating activities | J29: =J27+J28 -> 937.24 | K29: =K27+K28 -> 931 | L29: =L27+L28 -> 713.66 | M29: =M27+M28 -> 656.39 | N29: =N27+N28 -> 842.96 | O29: =O27+O28 -> 913.95 | Q29: Other financial liabilities | R29: 13.9 | S29: 6.91 | T29: -4.9 | U29: -4.76 | V29: -25.79 | W29: 444.81 | Y29: Increase/decrease in trade and other receivables | Z29: -11278.12 | AA29: 2783.81 | AB29: -9851.72 | AC29: -4495.26 | AD29: -10642.89 | AE29: -9252.32 | AG29: Other non current fnancial liabilities | AH29: 50.9097 | AI29: 102.08 | AJ29: -85.35 | AK29: 217.5 | AL29: -8.09 | AM29: 14.15
A30: Increase in inventories | B30: -44.65 | C30: -23.58 | D30: 605.43 | E30: -66.66 | F30: 8.09 | G30: -37.35 | I30: CASH FLOW FROM INVESTING ACTIVITIES | Q30: Provisions | R30: 0 | S30: 0 | T30: 21.37 | U30: 14.01 | V30: =-4.19+2.83 -> -1.36 | W30: =3.9-0.68 -> 3.22 | Y30: increase/decrease in inventories | Z30: 353.19 | AA30: 348.9 | AB30: -74.33 | AC30: -475.75 | AD30: 244.68 | AE30: -539.52 | AG30: Other current liabilities | AH30: -2522.6487 | AI30: 239.62 | AJ30: 3841.67 | AK30: -3372.81 | AL30: 838.4 | AM30: 167.62
A31: Decrease in Financial assets | B31: 512.56 | C31: 219.36 | D31: -89.15 | E31: -325.52 | F31: 436.12 | G31: -94.19 | I31: CapEx on PPE | J31: -469.77 | K31: -261.15 | L31: -308.1 | M31: -771.48 | N31: -351.58 | O31: -574.62 | Q31: Cash generated from operations | R31: =SUM(R18,R20:R30) -> 436.76 | S31: =SUM(S18,S20:S30) -> 1053.32 | T31: =SUM(T18,T20:T30) -> 2.59 | U31: =SUM(U18,U20:U30) -> 828.27 | V31: =SUM(V18,V20:V30) -> 563.28 | W31: =SUM(W18,W20:W30) -> 261.89 | Y31: increase/decrease in trade payables and customer advances | Z31: 3134.23 | AA31: 2219.78 | AB31: 9678.03 | AC31: 5412.71 | AD31: 14601.02 | AE31: 9683.41 | AG31: Short term provisions | AH31: 21.7558 | AI31: 1.55 | AJ31: 3.89 | AK31: 0.79 | AL31: 10.68 | AM31: -14.86
A32: Decrease/Increase in other assets | B32: -612.94 | C32: 56.57 | D32: 215.77 | E32: -205.51 | F32: -138.64 | G32: -759.97 | I32: Proceeds from disposal of PPE | J32: 6.03 | K32: 26.41 | L32: 46.68 | M32: 52.13 | N32: 32.92 | O32: 62.73 | Q32: Income tax paid | R32: -349.31 | S32: -208.78 | T32: -286.3 | U32: -221.54 | V32: -252.13 | W32: 157.19 | Y32: Cash generated from operations before financing activities | Z32: =SUM(Z27:Z31) -> 10733.41 | AA32: =SUM(AA27:AA31) -> 21697.44 | AB32: =SUM(AB27:AB31) -> 18698.37 | AC32: =SUM(AC27:AC31) -> 22966.68 | AD32: =SUM(AD27:AD31) -> 29134.22 | AE32: =SUM(AE27:AE31) -> 26717.33 | AG32: Long term provisions | AH32: 7.7635 | AI32: 5.41 | AJ32: 3.19 | AK32: 1.52 | AL32: -16.03 | AM32: 13.46
