Workbook

Sheet Company Profile
A1: COMPANY PROFILE
A2: Parameters | B2: #VALUE! | C2: #VALUE! | D2: #VALUE! | E2: #VALUE! | F2: #VALUE! | G2: #VALUE!
A3: Company | B3: #VALUE! | C3: #VALUE! | D3: #VALUE! | E3: #VALUE! | F3: #VALUE! | G3: #VALUE!
A4: Industry | B4: {=_FV(B3,"Industry")} -> Pharmaceuticals | C4: {=_FV(C3,"Industry")} -> Pharmaceuticals | D4: {=_FV(D3,"Industry")} -> Pharmaceuticals | E4: {=_FV(E3,"Industry")} -> Pharmaceuticals | F4: {=_FV(F3,"Industry")} -> Pharmaceuticals | G4: {=_FV(G3,"Industry")} -> Pharmaceuticals
A5: Beta | B5: {=_FV(B3,"Beta")} -> 0.6846 | C5: {=_FV(C3,"Beta")} -> 0.4776 | D5: {=_FV(D3,"Beta")} -> 0.4693 | E5: {=_FV(E3,"Beta")} -> 0.7232 | F5: {=_FV(F3,"Beta")} -> 0.615 | G5: {=_FV(G3,"Beta")} -> 0.8713
A6: Share Price | B6: {=_FV(B3,"Price")} -> 3817.5 | C6: {=_FV(C3,"Price")} -> 1511.5 | D6: {=_FV(D3,"Price")} -> 1198.7 | E6: {=_FV(E3,"Price")} -> 6691.5 | F6: {=_FV(F3,"Price")} -> 2234.4 | G6: {=_FV(G3,"Price")} -> 1697.8
A7: Shares Outstanding | B7: {=_FV(B3,"Shares outstanding",TRUE)} -> 338445400 | C7: {=_FV(C3,"Shares outstanding",TRUE)} -> 807771200 | D7: {=_FV(D3,"Shares outstanding",TRUE)} -> 832515300 | E7: {=_FV(E3,"Shares outstanding",TRUE)} -> 265468600 | F7: {=_FV(F3,"Shares outstanding",TRUE)} -> 412758500 | G7: {=_FV(G3,"Shares outstanding",TRUE)} -> 2399335000
A8: In crores | B8: =B7/10000000 -> 33.84454 | C8: =C7/10000000 -> 80.77712 | D8: =D7/10000000 -> 83.25153 | E8: =E7/10000000 -> 26.54686 | F8: =F7/10000000 -> 41.27585 | G8: =G7/10000000 -> 239.9335
A9: Market Cap | B9: {=_FV(B3,"Market cap",TRUE)} -> 1211635000000 | C9: {=_FV(C3,"Market cap",TRUE)} -> 1216261000000 | D9: {=_FV(D3,"Market cap",TRUE)} -> 1003514000000 | E9: {=_FV(E3,"Market cap",TRUE)} -> 1767092000000 | F9: {=_FV(F3,"Market cap",TRUE)} -> 933577100000 | G9: {=_FV(G3,"Market cap",TRUE)} -> 4058235000000
A10: Year Incorporated | B10: {=_FV(B3,"Year incorporated",TRUE)} -> 1972 | C10: {=_FV(C3,"Year incorporated",TRUE)} -> 1935 | D10: {=_FV(D3,"Year incorporated",TRUE)} -> 1984 | E10: {=_FV(E3,"Year incorporated",TRUE)} -> 1990 | F10: {=_FV(F3,"Year incorporated",TRUE)} -> 1991 | G10: {=_FV(G3,"Year incorporated",TRUE)} -> 1993
A11: Change | B11: {=_FV(B3,"Change")} -> 237.5 | C11: {=_FV(C3,"Change")} -> 5.8 | D11: {=_FV(D3,"Change")} -> -6.7 | E11: {=_FV(E3,"Change")} -> 35 | F11: {=_FV(F3,"Change")} -> -28.9 | G11: {=_FV(G3,"Change")} -> 6.4
A12: Change (%) | B12: {=_FV(B3,"Change (%)",TRUE)} -> 0.066341 | C12: {=_FV(C3,"Change (%)",TRUE)} -> 0.003852 | D12: {=_FV(D3,"Change (%)",TRUE)} -> -0.005558 | E12: {=_FV(E3,"Change (%)",TRUE)} -> 0.005258 | F12: {=_FV(F3,"Change (%)",TRUE)} -> -0.012769 | G12: {=_FV(G3,"Change (%)",TRUE)} -> 0.003784
A13: P/E | B13: {=_FV(B3,"P/E",TRUE)} -> 60.374 | C13: {=_FV(C3,"P/E",TRUE)} -> 22.4324 | D13: {=_FV(D3,"P/E",TRUE)} -> 17.2931 | E13: {=_FV(E3,"P/E",TRUE)} -> 71.4383 | F13: {=_FV(F3,"P/E",TRUE)} -> 53.19 | G13: {=_FV(G3,"P/E",TRUE)} -> 39.3612

Sheet Balance Sheet
A1: BALANCE SHEET
A2: #VALUE! | I2: #VALUE! | Q2: #VALUE! | Y2: #VALUE! | AG2: #VALUE! | AO2: #VALUE!
A3: Particulars | B3: 2020 | C3: 2021 | D3: 2022 | E3: 2023 | F3: 2024 | G3: 2025 | I3: Particulars | J3: 2020 | K3: 2021 | L3: 2022 | M3: 2023 | N3: 2024 | O3: 2025 | Q3: Particulars | R3: 2020 | S3: 2021 | T3: 2022 | U3: 2023 | V3: 2024 | W3: 2025 | Y3: Particulars | Z3: 2020 | AA3: 2021 | AB3: 2022 | AC3: 2023 | AD3: 2024 | AE3: 2025 | AG3: Particulars | AH3: 2020 | AI3: 2021 | AJ3: 2022 | AK3: 2023 | AL3: 2024 | AM3: 2025 | AO3: Particulars | AP3: 2020 | AQ3: 2021 | AR3: 2022 | AS3: 2023 | AT3: 2024 | AU3: 2025
A4: ASSETS | I4: ASSETS | Q4: ASSETS | Y4: ASSETS | AG4: ASSETS | AO4: ASSETS
A5: Non-Current Assets | I5: Non-Current Assets | Q5: Non-Current Assets | Y5: Non-Current Assets | AG5: Non-Current Assets | AO5: Non-Current Assets
A6: Property, plant and equipment | B6: 2773.16 | C6: 3694.66 | D6: 4314.12 | E6: 4714.17 | F6: 4733 | G6: 5437 | I6: Property, plant and equipment | J6: 10567.43 | K6: 10234.99 | L6: 4969.57 | M6: 4733.25 | N6: 10192.32 | O6: 10035.94 | Q6: Property, plant and equipment | R6: 1551.3441 | S6: 1620.0707 | T6: 1652.363 | U6: 2409.4343 | V6: 2812.53 | W6: 2740.57 | Y6: PPE | Z6: 4912.7 | AA6: 4777.9 | AB6: 4732.2 | AC6: 4886.9 | AD6: 6248.7 | AE6: 7298.4 | AG6: PPE | AH6: 2817.89 | AI6: 2757.79 | AJ6: 2575.08 | AK6: 2626.67 | AL6: 3139.4 | AM6: 3209.24 | AO6: PPE | AP6: 4805.32 | AQ6: 4618.14 | AR6: 4838.79 | AS6: 4583.6 | AT6: 4641.94 | AU6: 4813.88
A7: Right-of-use assets | B7: 5.09 | C7: 4.26 | D7: 3.44 | E7: 3.15 | F7: 2 | G7: 1 | I7: Capital work-in-progress | J7: 658.91 | K7: 936.52 | L7: 358.94 | M7: 328.87 | N7: 1107.73 | O7: 1234.34 | Q7: Capital work-in-progress | R7: 313.2586 | S7: 371.6162 | T7: 669.8734 | U7: 493.182 | V7: 207.1 | W7: 306.13 | Y7: Capital work-in-progress | Z7: 472.5 | AA7: 436.4 | AB7: 953.9 | AC7: 1279.6 | AD7: 1351 | AE7: 2399.4 | AG7: Capital WIP | AH7: 576.61 | AI7: 745.41 | AJ7: 544.34 | AK7: 688.24 | AL7: 280.8 | AM7: 367.26 | AO7: RoU assets | AP7: 322.73 | AQ7: 338.13 | AR7: 325.61 | AS7: 407.18 | AT7: 427.03 | AU7: 448.38
A8: Capital work-in-progress | B8: 919.69 | C8: 710.62 | D8: 469.93 | E8: 211.88 | F8: 778 | G8: 1022 | I8: Goodwill (net) | J8: 6481.46 | K8: 6287.64 | L8: 120.8 | M8: 120.8 | N8: 8568.99 | O8: 8939.42 | Q8: Investment properties | R8: 5.5582 | S8: 5.5035 | T8: 5.4243 | U8: 5.3696 | V8: 5.32 | W8: 0.05 | Y8: Goodwill | Z8: 465.9 | AA8: 491.3 | AB8: 559.9 | AC8: 547.3 | AD8: 550.1 | AE8: 1313.9 | AG8: ROU Assets | AH8: 135.42 | AI8: 125.55 | AJ8: 127.51 | AK8: 144.93 | AL8: 157.57 | AM8: 246.41 | AO8: Capital WIP | AP8: 421 | AQ8: 570.84 | AR8: 382.9 | AS8: 689.17 | AT8: 864.32 | AU8: 1212.76
A9: Intangible assets | B9: 3.6 | C9: 4.95 | D9: 7.49 | E9: 5.28 | F9: 4 | G9: 4 | I9: Other intangible assets | J9: 5798.02 | K9: 5030.35 | L9: 4622.41 | M9: 3857.62 | N9: 4486.84 | O9: 3610.92 | Q9: Goodwill | R9: 20.4422 | S9: 20.4422 | T9: 20.4422 | U9: 20.0225 | V9: 20.02 | W9: 6492.63 | Y9: Other tangible assets | Z9: 1812.4 | AA9: 1581.1 | AB9: 2913.6 | AC9: 2687.3 | AD9: 3626.8 | AE9: 9614.1 | AG9: Goodwill | AH9: 342.09 | AI9: 341.23 | AJ9: 259.48 | AK9: 337.5 | AL9: 338.03 | AM9: 338.88 | AO9: Investment properties | AP9: 124.3 | AQ9: 121.75 | AR9: 61.42 | AS9: 59.83 | AT9: 113.61 | AU9: 111.25
A10: Investments | B10: 0.01 | C10: 0.01 | D10: 72.01 | E10: 77.05 | F10: 82 | G10: 65 | I10: Intangible assets under development | J10: 561.43 | K10: 630.31 | L10: 469.7 | M10: 524.04 | N10: 4246.15 | O10: 5409.62 | Q10: Other intangible assets | R10: 22.2521 | S10: 18.4286 | T10: 1842.6052 | U10: 1701.4633 | V10: 1588.34 | W10: 9604.03 | Y10: Intangible assets under development | Z10: 2461 | AA10: 1098.7 | AB10: 611.2 | AC10: 13.8 | AD10: 68.3 | AE10: 66.2 | AG10: Other tangible assets | AH10: 4237.72 | AI10: 3840.06 | AJ10: 3460.58 | AK10: 5012.35 | AL10: 4503.11 | AM10: 4152.37 | AO10: Goodwill | AP10: 2934 | AQ10: 3007.29 | AR10: 3137.93 | AS10: 2983.86 | AT10: 3112.04 | AU10: 3270.27
A11: Loans | B11: 35.32 | C11: 55.33 | D11: 0 | E11: 0 | F11: 0 | G11: 0 | I11: Investments in associates | J11: 215.39 | K11: 232.73 | L11: 0 | M11: 0 | N11: 0 | O11: 0 | Q11: Intangible assets under development | R11: 3.6946 | S11: 0.3336 | T11: 31.5979 | U11: 56.9536 | V11: 74.7 | W11: 519.54 | Y11: Investment in equity accounted investees | Z11: 252.9 | AA11: 276.3 | AB11: 337.5 | AC11: 431.8 | AD11: 419.6 | AE11: 481.1 | AG11: Intangible assets under development | AH11: 135.32 | AI11: 143.97 | AJ11: 85.48 | AK11: 77.16 | AL11: 79.71 | AM11: 110.88 | AO11: Intangible assets | AP11: 1496.54 | AQ11: 1430.21 | AR11: 1319.58 | AS11: 1126.01 | AT11: 1312.6 | AU11: 1362.61
A12: Other financial assets | B12: 0 | C12: 1.45 | D12: 57.75 | E12: 51.09 | F12: 56 | G12: 62 | I12: Investments in joint venture | J12: 27.57 | K12: 27.83 | L12: 15340.41 | M12: 12401.74 | N12: 0 | O12: 0 | Q12: RoU Assets | R12: 0 | S12: 0 | T12: 67.3571 | U12: 114.3647 | V12: 119.06 | W12: 167.25 | Y12: Investments | Z12: 81.3 | AA12: 32.8 | AB12: 495.8 | AC12: 166.8 | AD12: 105.9 | AE12: 239.3 | AG12: Investments | AH12: 2.09 | AI12: 42.09 | AJ12: 42.33 | AK12: 42.7 | AL12: 31.8 | AM12: 43.57 | AO12: Intangible assets under development | AP12: 403.53 | AQ12: 398.05 | AR12: 383.28 | AS12: 404.13 | AT12: 288.4 | AU12: 353.51
A13: Income tax assets | B13: 0 | C13: 68.6 | D13: 29.17 | E13: 29.17 | F13: 1 | G13: 1 | I13: Investments | J13: 5002.79 | K13: 6221.83 | L13: 15.42 | M13: 14.4 | N13: 6441.23 | O13: 4697.7 | Q13: Investment in associates and joint ventures | R13: 164.3798 | S13: 165.7868 | T13: 167.7428 | U13: 181.4112 | V13: 189.28 | W13: 190.9 | Y13: Trade receivables | Z13: 11.3 | AA13: 173.7 | AB13: 11.8 | AC13: 5.4 | AD13: 0 | AE13: 0 | AG13: Loans | AH13: 2.29 | AI13: 214 | AJ13: 1.75 | AK13: 2.5 | AL13: 2.5 | AM13: 3.37 | AO13: Investment in associates | AP13: 234.97 | AQ13: 228.38 | AR13: 45.81 | AS13: 90.9 | AT13: 130.05 | AU13: 140.47
A14: Deferred tax assets | B14: 4.38 | C14: 3.23 | D14: 14.47 | E14: 14.24 | F14: 10 | G14: 11 | I14: Loans | J14: 0.79 | K14: 0.71 | L14: 3656.63 | M14: 632.7 | N14: 0.85 | O14: 2.79 | Q14: Investments | R14: 0.0125 | S14: 40.0125 | T14: 67.265 | U14: 89.5373 | V14: 120.53 | W14: 160.19 | Y14: Other financial assets | Z14: 73.1 | AA14: 79.3 | AB14: 76.8 | AC14: 277.3 | AD14: 121.2 | AE14: 887.5 | AG14: Other financial assets | AH14: 126.28 | AI14: 52.11 | AJ14: 66.85 | AK14: 48.68 | AL14: 36.87 | AM14: 32.86 | AO14: Investments | AP14: 219.53 | AQ14: 195.3 | AR14: 309.82 | AS14: 481.62 | AT14: 512.16 | AU14: 499.07
A15: Other non-current assets | B15: 114.62 | C15: 56.25 | D15: 54.83 | E15: 21 | F15: 129 | G15: 248 | I15: Other financial assets | J15: 104.88 | K15: 95.78 | L15: 65.13 | M15: 53.89 | N15: 117.95 | O15: 177.04 | Q15: Loans | R15: 0.0993 | S15: 0.0743 | T15: 0.0288 | U15: 0 | V15: 0 | W15: 0 | Y15: Deferred tax assets | Z15: 431.7 | AA15: 1219.9 | AB15: 1068.6 | AC15: 1277 | AD15: 1057.8 | AE15: 1832.5 | AG15: Income tax assets | AH15: 188.88 | AI15: 55.89 | AJ15: 122.21 | AK15: 135.8 | AL15: 308.79 | AM15: 226.35 | AO15: Loans | AP15: 52.39 | AQ15: 52.99 | AR15: 0.04 | AS15: 0 | AT15: 16.98 | AU15: 32.54
A16: Total Non-current assets | B16: =SUM(B6:B15) -> 3855.87 | C16: =SUM(C6:C15) -> 4599.36 | D16: =SUM(D6:D15) -> 5023.21 | E16: =SUM(E6:E15) -> 5127.03 | F16: =SUM(F6:F15) -> 5795 | G16: =SUM(G6:G15) -> 6851 | I16: Deferred tax assets (net) | J16: 3175.29 | K16: 3556.44 | L16: 324.04 | M16: 1032.39 | N16: 4103.65 | O16: 4407.55 | Q16: Other financial assets | R16: 30.9299 | S16: 22.4287 | T16: 22.9265 | U16: 110.1814 | V16: 29.5 | W16: 200.33 | Y16: Tax assets | Z16: 340 | AA16: 437.9 | AB16: 274.5 | AC16: 328.5 | AD16: 371.8 | AE16: 182.1 | AG16: Deferred tax assets | AH16: 433.21 | AI16: 421.66 | AJ16: 493.65 | AK16: 543.67 | AL16: 555.13 | AM16: 594.15 | AO16: Other financial assets | AP16: 42.04 | AQ16: 42.88 | AR16: 417.04 | AS16: 99.32 | AT16: 508.56 | AU16: 283.46
A17: Current Assets | I17: Income tax assets (net) | J17: 3384.25 | K17: 3432.78 | L17: 883.67 | M17: 586.13 | N17: 2285.03 | O17: 420.67 | Q17: Income tax assets | R17: 54.5116 | S17: 55.6056 | T17: 79.8242 | U17: 102.5153 | V17: 81.98 | W17: 189.49 | Y17: Other non-current assets | Z17: 40.7 | AA17: 20.9 | AB17: 30.7 | AC17: 62.9 | AD17: 137.3 | AE17: 94 | AG17: Other non current assets | AH17: 31.02 | AI17: 23.65 | AJ17: 25.93 | AK17: 22.47 | AL17: 15.38 | AM17: 41.83 | AO17: Income tax assets | AP17: 468.62 | AQ17: 468.16 | AR17: 483.62 | AS17: 548 | AT17: 463.67 | AU17: 487.86
A18: Inventories | B18: 1863.86 | C18: 2145.23 | D18: 2828.62 | E18: 3000.41 | F18: 3184 | G18: 3236 | I18: Other non-current assets | J18: 620.09 | K18: 636.74 | L18: 235.01 | M18: 236.51 | N18: 473.93 | O18: 540.12 | Q18: Deferred tax assets | R18: 47.9389 | S18: 49.011 | T18: 39.2862 | U18: 29.7769 | V18: 80.39 | W18: 107.89 | Y18: Total non current assets | Z18: =SUM(Z6:Z17) -> 11355.5 | AA18: =SUM(AA6:AA17) -> 10626.2 | AB18: =SUM(AB6:AB17) -> 12066.5 | AC18: =SUM(AC6:AC17) -> 11964.6 | AD18: =SUM(AD6:AD17) -> 14058.5 | AE18: =SUM(AE6:AE17) -> 24408.5 | AG18: Total non-current assets | AH18: =SUM(AH6:AH17) -> 9028.82 | AI18: =SUM(AI6:AI17) -> 8763.41 | AJ18: =SUM(AJ6:AJ17) -> 7805.19 | AK18: =SUM(AK6:AK17) -> 9682.67 | AL18: =SUM(AL6:AL17) -> 9449.09 | AM18: =SUM(AM6:AM17) -> 9367.17 | AO18: Deferred tax assets | AP18: 239.77 | AQ18: 314.69 | AR18: 448.83 | AS18: 456.54 | AT18: 587.8 | AU18: 644.87
A19: Investments | B19: 971.35 | C19: 0 | D19: 0 | E19: 0 | F19: 0 | G19: 0 | I19: Total non-current assets | J19: =SUM(J6:J18) -> 36598.3 | K19: =SUM(K6:K18) -> 37324.65 | L19: =SUM(L6:L18) -> 31061.73 | M19: =SUM(M6:M18) -> 24522.34 | N19: =SUM(N6:N18) -> 42024.67 | O19: =SUM(O6:O18) -> 39476.11 | Q19: Other non-current assets | R19: 36.6462 | S19: 96.6766 | T19: 74.1843 | U19: 73.355 | V19: 66.28 | W19: 92.26 | Y19: Current Assets | AG19: Current assets | AO19: Other non current assets | AP19: 191.64 | AQ19: 155.57 | AR19: 218.91 | AS19: 258.17 | AT19: 297.25 | AU19: 437.59
A20: Trade Receivables | B20: 1413.35 | C20: 1676.52 | D20: 2423.88 | E20: 1792.53 | F20: 2156 | G20: 2731 | I20: Current Assets | Q20: Total non-current assets | R20: =SUM(R6:R19) -> 2251.068 | S20: =SUM(S6:S19) -> 2465.9903 | T20: =SUM(T6:T19) -> 4740.9209 | U20: =SUM(U6:U19) -> 5387.5671 | V20: =SUM(V6:V19) -> 5395.03 | W20: =SUM(W6:W19) -> 20771.26 | Y20: Inventories | Z20: 3557.9 | AA20: 3506.7 | AB20: 4541.2 | AC20: 5088.4 | AD20: 6355.2 | AE20: 7108.5 | AG20: Inventories | AH20: 2148.22 | AI20: 2681.2 | AJ20: 2462.32 | AK20: 2229.64 | AL20: 2279.07 | AM20: 2541.25 | AO20: Total non current assets | AP20: =SUM(AP6:AP19) -> 11956.38 | AQ20: =SUM(AQ6:AQ19) -> 11942.38 | AR20: =SUM(AR6:AR19) -> 12373.58 | AS20: =SUM(AS6:AS19) -> 12188.33 | AT20: =SUM(AT6:AT19) -> 13276.41 | AU20: =SUM(AU6:AU19) -> 14098.52
A21: Cash and cash Equivalents | B21: 43.15 | C21: 2030.32 | D21: 1214.76 | E21: 169.7 | F21: 363 | G21: 415 | I21: Inventories | J21: 7874.99 | K21: 8997.02 | L21: 3403.74 | M21: 3989.19 | N21: 9868.29 | O21: 10243.33 | Q21: Current assets | Y21: Investments | Z21: 2252.9 | AA21: 2368.7 | AB21: 1378.5 | AC21: 2017.3 | AD21: 4405 | AE21: 3330.7 | AG21: Investments | AH21: 0.02 | AI21: 139.05 | AJ21: 183.98 | AK21: 156.09 | AL21: 141.04 | AM21: 112.21 | AO21: Current Assets
A22: Bank Balance | B22: 79.48 | C22: 125.71 | D22: 1604.12 | E22: 4043.39 | F22: 3617 | G22: 3300 | I22: Investments | J22: 4897.36 | K22: 3130.06 | L22: 193.04 | M22: 200.26 | N22: 8584.54 | O22: 13656.1 | Q22: Inventories | R22: 899.1345 | S22: 1183.5377 | T22: 1760.2381 | U22: 1498.4582 | V22: 1553.46 | W22: 2093.71 | Y22: Trade receivables | Z22: 3986.9 | AA22: 5027.8 | AB22: 4964.1 | AC22: 6676.4 | AD22: 8029.8 | AE22: 9042 | AG22: Trade receivables | AH22: 1649.34 | AI22: 1523.37 | AJ22: 1632.48 | AK22: 1943.82 | AL22: 1844.3 | AM22: 1866.45 | AO22: Inventories | AP22: 4377.6 | AQ22: 4669.18 | AR22: 5350.24 | AS22: 5156.43 | AT22: 5237.95 | AU22: 5642.11
A23: Loans | B23: 0.09 | C23: 0 | D23: 0 | E23: 0 | F23: 0 | G23: 0 | I23: Trade receivables | J23: 9421.24 | K23: 9061.4 | L23: 4245.16 | M23: 7125.02 | N23: 11249.37 | O23: 13046.11 | Q23: Investments | R23: 665.0325 | S23: 1306.1741 | T23: 874.4618 | U23: 1075.4741 | V23: 2258.11 | W23: 1690.84 | Y23: Derivative Instruments | Z23: 36 | AA23: 110.5 | AB23: 121.8 | AC23: 190.6 | AD23: 16.9 | AE23: 55.7 | AG23: Cash and cash equivalents | AH23: 661.82 | AI23: 572.56 | AJ23: 398.4 | AK23: 508.53 | AL23: 835.14 | AM23: 573.48 | AO23: Investments | AP23: 1016.52 | AQ23: 2286.37 | AR23: 2194.97 | AS23: 3089.86 | AT23: 4807.01 | AU23: 7293.23
A24: Other financial assets | B24: 3.89 | C24: 9.47 | D24: 4.89 | E24: 6.07 | F24: 7 | G24: 16 | I24: Cash and cash equivalents | J24: 5676.61 | K24: 6273.03 | L24: 419.53 | M24: 410.28 | N24: 9285.65 | O24: 10268.77 | Q24: Trade Receivables | R24: 531.092 | S24: 330.6113 | T24: 388.166 | U24: 576.4214 | V24: 848.28 | W24: 1538.34 | Y24: Cash and cash equivalents | Z24: 222.8 | AA24: 205.3 | AB24: 1482.9 | AC24: 1485.2 | AD24: 710.7 | AE24: 1465.4 | AG24: Bank balances | AH24: 4.83 | AI24: 30.94 | AJ24: 5.01 | AK24: 62.93 | AL24: 3.9 | AM24: 5.98 | AO24: Trade receivables | AP24: 3891.31 | AQ24: 3445.68 | AR24: 3424.44 | AS24: 4057 | AT24: 4770.66 | AU24: 5506.37
A25: Income tax assets | B25: 79.05 | C25: 34.27 | D25: 57.68 | E25: 97.87 | F25: 28 | G25: 13 | I25: Bank balances | J25: 810.94 | K25: 172.48 | L25: 115.43 | M25: 11 | N25: 1235.03 | O25: 1062.85 | Q25: Cash and cash equivalents | R25: 226.0753 | S25: 167.182 | T25: 302.5347 | U25: 304.8207 | V25: 382.01 | W25: 407.36 | Y25: Bank Balances | Z25: 0 | AA25: 0 | AB25: 595.9 | AC25: 934 | AD25: 1017 | AE25: 994.8 | AG25: Loans | AH25: 3.64 | AI25: 3.08 | AJ25: 2.61 | AK25: 1.71 | AL25: 3.05 | AM25: 4.22 | AO25: Cash and cash equivalents | AP25: 742.38 | AQ25: 793.29 | AR25: 677.74 | AS25: 627.63 | AT25: 640.07 | AU25: 588.69
A26: Other current assets | B26: 225.61 | C26: 153.19 | D26: 217.55 | E26: 201.77 | F26: 320 | G26: 370 | I26: Loans | J26: 148.38 | K26: 56.01 | L26: 9.1 | M26: 3347.03 | N26: 65.02 | O26: 48.38 | Q26: Bank Balances | R26: 193.802 | S26: 533.5598 | T26: 103.4068 | U26: 148.3779 | V26: 326.09 | W26: 147.14 | Y26: Other financial assets | Z26: 211.2 | AA26: 337.7 | AB26: 185.8 | AC26: 157.4 | AD26: 2252.7 | AE26: 314.2 | AG26: Other financial assets | AH26: 81.69 | AI26: 120.79 | AJ26: 167.98 | AK26: 108.41 | AL26: 200.68 | AM26: 182.85 | AO26: Bank Balances | AP26: 261.53 | AQ26: 607.94 | AR26: 1250.74 | AS26: 936.99 | AT26: 234.9 | AU26: 211.15
A27: Total Current assets | B27: =SUM(B18:B26) -> 4679.83 | C27: =SUM(C18:C26) -> 6174.71 | D27: =SUM(D18:D26) -> 8351.5 | E27: =SUM(E18:E26) -> 9311.74 | F27: =SUM(F18:F26) -> 9675 | G27: =SUM(G18:G26) -> 10081 | I27: Other financial assets | J27: 929.34 | K27: 875.93 | L27: 402.18 | M27: 582.4 | N27: 917.2 | O27: 1740.66 | Q27: Loans | R27: 34.4979 | S27: 18.4114 | T27: 1.1944 | U27: 1.6326 | V27: 2.86 | W27: 3.95 | Y27: Other current assets | Z27: 1042.4 | AA27: 1042.4 | AB27: 1265 | AC27: 1233 | AD27: 2018 | AE27: 2706.8 | AG27: Other current assets | AH27: 429.5 | AI27: 450.51 | AJ27: 312.21 | AK27: 302.59 | AL27: 304.3 | AM27: 336.13 | AO27: Loans | AP27: 5.6 | AQ27: 2.58 | AR27: 3.57 | AS27: 7.59 | AT27: 0.24 | AU27: 15.64
A28: Total Assets | B28: =B16+B27 -> 8535.7 | C28: =C16+C27 -> 10774.07 | D28: =D16+D27 -> 13374.71 | E28: =E16+E27 -> 14438.77 | F28: =F16+F27 -> 15470 | G28: =G16+G27 -> 16932 | I28: Other current assets | J28: 1895.3 | K28: 1876.15 | L28: =915.57+21.4 -> 936.97 | M28: =778.57+21.4 -> 799.97 | N28: 2228.01 | O28: 2527.86 | Q28: Others | R28: 4.4869 | S28: 9.9912 | T28: 13.9371 | U28: 55.9797 | V28: 503.03 | W28: 301.41 | Y28: Total current assets | Z28: =SUM(Z20:Z27) -> 11310.1 | AA28: =SUM(AA20:AA27) -> 12599.1 | AB28: =SUM(AB20:AB27) -> 14535.2 | AC28: =SUM(AC20:AC27) -> 17782.3 | AD28: =SUM(AD20:AD27) -> 24805.3 | AE28: =SUM(AE20:AE27) -> 25018.1 | AG28: Total current assets | AH28: =SUM(AH20:AH27) -> 4979.06 | AI28: =SUM(AI20:AI27) -> 5521.5 | AJ28: =SUM(AJ20:AJ27) -> 5164.99 | AK28: =SUM(AK20:AK27) -> 5313.72 | AL28: =SUM(AL20:AL27) -> 5611.48 | AM28: =SUM(AM20:AM27) -> 5622.57 | AO28: Other financial assets | AP28: 522.28 | AQ28: 481.66 | AR28: 898.39 | AS28: 2080.57 | AT28: 2801.52 | AU28: 2936.9
A29: EQUITY AND LIABILITIES | I29: Total current assets | J29: =SUM(J21:J28) -> 31654.16 | K29: =SUM(K21:K28) -> 30442.08 | L29: =SUM(L21:L28) -> 9725.15 | M29: =SUM(M21:M28) -> 16465.15 | N29: =SUM(N21:N28) -> 43433.11 | O29: =SUM(O21:O28) -> 52594.06 | Q29: Other current assets | R29: 265.381 | S29: 354.4653 | T29: 959.8978 | U29: 663.3918 | V29: 691.68 | W29: 802.82 | Y29: Total assets | Z29: =Z18+Z28 -> 22665.6 | AA29: =AA18+AA28 -> 23225.3 | AB29: =AB18+AB28 -> 26601.7 | AC29: =AC18+AC28 -> 29746.9 | AD29: =AD18+AD28 -> 38863.8 | AE29: =AE18+AE28 -> 49426.6 | AG29: Non-current assets held for sale | AH29: 1.86 | AI29: 1.72 | AJ29: 129.66 | AK29: 15.46 | AL29: 0 | AM29: 0 | AO29: Other current assets | AP29: 886.62 | AQ29: 894.33 | AR29: 910.74 | AS29: 848.99 | AT29: 900.1 | AU29: 1054.88
A30: Equity | I30: Total Assets | J30: =J19+J29 -> 68252.46 | K30: =K19+K29 -> 67766.73 | L30: =L19+L29 -> 40786.88 | M30: =M19+M29 -> 40987.49 | N30: =N19+N29 -> 85457.78 | O30: =O19+O29 -> 92070.17 | Q30: Assets held for sale | R30: 2.7105 | S30: 2.702 | T30: 2.9816 | U30: 3.3156 | V30: 2.7 | W30: 2.7 | Y30: EQUITY AND LIABILITIES | AG30: Total assets | AH30: =AH28+AH29+AH18 -> 14009.74 | AI30: =AI28+AI29+AI18 -> 14286.63 | AJ30: =AJ28+AJ29+AJ18 -> 13099.84 | AK30: =AK28+AK29+AK18 -> 15011.85 | AL30: =AL28+AL29+AL18 -> 15060.57 | AM30: =AM28+AM29+AM18 -> 14989.74 | AO30: Total current assets | AP30: =SUM(AP22:AP29) -> 11703.84 | AQ30: =SUM(AQ22:AQ29) -> 13181.03 | AR30: =SUM(AR22:AR29) -> 14710.83 | AS30: =SUM(AS22:AS29) -> 16805.06 | AT30: =SUM(AT22:AT29) -> 19392.45 | AU30: =SUM(AU22:AU29) -> 23248.97
A31: Equity share capital | B31: 53.09 | C31: 53.09 | D31: 53.09 | E31: 53.09 | F31: 53 | G31: 53 | I31: EQUITY AND LIABILITIES | Q31: Total current assets | R31: =SUM(R22:R30) -> 2822.2126 | S31: =SUM(S22:S30) -> 3906.6348 | T31: =SUM(T22:T30) -> 4406.8183 | U31: =SUM(U22:U30) -> 4327.872 | V31: =SUM(V22:V30) -> 6568.22 | W31: =SUM(W22:W30) -> 6988.27 | Y31: Equity | AG31: EQUITY AND LIABILITIES | AO31: Assets classified for sale | AP31: 2.34 | AQ31: 28.48 | AR31: 16.71 | AS31: 469.89 | AT31: 48.96 | AU31: 39.55
A32: Other Equity | B32: 7256.83 | C32: 9241.52 | D32: 11675.09 | E32: 12714 | F32: 13518 | G32: 14916 | I32: Equity | Q32: Total assets | R32: =R20+R31 -> 5073.2806 | S32: =S20+S31 -> 6372.6251 | T32: =T20+T31 -> 9147.7392 | U32: =U20+U31 -> 9715.4391 | V32: =V20+V31 -> 11963.25 | W32: =W20+W31 -> 27759.53 | Y32: Equity share capital | Z32: 83 | AA32: 83.1 | AB32: 83.2 | AC32: 83.2 | AD32: 83.4 | AE32: 83.4 | AG32: Equity | AO32: Total assets | AP32: =AP30+AP20+AP31 -> 23662.56 | AQ32: =AQ30+AQ20+AQ31 -> 25151.89 | AR32: =AR30+AR20+AR31 -> 27101.12 | AS32: =AS30+AS20+AS31 -> 29463.28 | AT32: =AT30+AT20+AT31 -> 32717.82 | AU32: =AU30+AU20+AU31 -> 37387.04
A33: Total Equity | B33: =SUM(B31:B32) -> 7309.92 | C33: =SUM(C31:C32) -> 9294.61 | D33: =SUM(D31:D32) -> 11728.18 | E33: =SUM(E31:E32) -> 12767.09 | F33: =SUM(F31:F32) -> 13571 | G33: =SUM(G31:G32) -> 14969 | I33: Equity share capital | J33: 239.93 | K33: 239.93 | L33: 239.93 | M33: 239.93 | N33: 239.93 | O33: 239.93 | Q33: EQUITY AND LIABILITIES | Y33: Other equity | Z33: 13940.6 | AA33: 15515.7 | AB33: 17558.5 | AC33: 19129.2 | AD33: 28171.4 | AE33: 33466.2 | AG33: Equity share capital | AH33: 84.62 | AI33: 84.62 | AJ33: 84.62 | AK33: 169.23 | AL33: 169.23 | AM33: 169.23 | AO33: Equity and Liabilities
A34: LIABILITIES | I34: Other equity | J34: 45024.52 | K34: 46222.85 | L34: 24348.02 | M34: 23508.43 | N34: 63426.82 | O34: 71978.09 | Q34: Equity | Y34: Non-controlling interests | Z34: 0 | AA34: 0 | AB34: 0 | AC34: 0 | AD34: 0 | AE34: 377.8 | AG34: Other equity | AH34: 4738.6 | AI34: 5752.55 | AJ34: 5868.33 | AK34: 6028.84 | AL34: 6686.92 | AM34: 7421.46 | AO34: Equity
A35: Non-current liabilities | I35: Non-controlling interests | J35: 3860.24 | K35: 3017.05 | L35: 0 | M35: 0 | N35: 3459.19 | O35: 267.93 | Q35: Equity share capital | R35: 40.0588 | S35: 40.0588 | T35: 40.0588 | U35: 40.0588 | V35: 40.06 | W35: 41.26 | Y35: Total equity | Z35: =SUM(Z32:Z34) -> 14023.6 | AA35: =SUM(AA32:AA34) -> 15598.8 | AB35: =SUM(AB32:AB34) -> 17641.7 | AC35: =SUM(AC32:AC34) -> 19212.4 | AD35: =SUM(AD32:AD34) -> 28254.8 | AE35: =SUM(AE32:AE34) -> 33927.4 | AG35: Non-controlling interests | AH35: 0 | AI35: 0 | AJ35: 0 | AK35: 0 | AL35: 0 | AM35: 0 | AO35: Equity share capital | AP35: 161.25 | AQ35: 161.29 | AR35: 161.36 | AS35: 161.43 | AT35: 161.47 | AU35: 161.52
A36: Lease Liabilities | B36: 4.47 | C36: 3.69 | D36: 2.87 | E36: 2.77 | F36: 2 | G36: 2 | I36: Total equity | J36: =SUM(J33:J35) -> 49124.69 | K36: =SUM(K33:K35) -> 49479.83 | L36: =SUM(L33:L35) -> 24587.95 | M36: =SUM(M33:M35) -> 23748.36 | N36: =SUM(N33:N35) -> 67125.94 | O36: =SUM(O33:O35) -> 72485.95 | Q36: Other equity | R36: 3445.2514 | S36: 4681.945 | T36: 6115.1733 | U36: 7395.164 | V36: 9323.03 | W36: 14291.13 | Y36: LIABILITIES | AG36: Total equity | AH36: =SUM(AH33:AH35) -> 4823.22 | AI36: =SUM(AI33:AI35) -> 5837.17 | AJ36: =SUM(AJ33:AJ35) -> 5952.95 | AK36: =SUM(AK33:AK35) -> 6198.07 | AL36: =SUM(AL33:AL35) -> 6856.15 | AM36: =SUM(AM33:AM35) -> 7590.69 | AO36: Other equity | AP36: 15601.75 | AQ36: 18165.24 | AR36: 20680.33 | AS36: 23246.35 | AT36: 26544.96 | AU36: 31031.93
A37: Other financial liabilities | B37: 0 | C37: 0 | D37: 0 | E37: 0 | F37: 0 | G37: 0 | I37: LIABILITIES | Q37: Non-controlling interests | R37: 186.2611 | S37: 140.8874 | T37: 161.0799 | U37: 188.0701 | V37: 212.7 | W37: 235.79 | Y37: Non-current liabilities | AG37: Non-current liabilities | AO37: Non-controlling interest | AP37: 294.28 | AQ37: 259.06 | AR37: 275.69 | AS37: 305.76 | AT37: 95.9 | AU37: 95.8
A38: Borrowings | B38: 0 | C38: 0 | D38: 0 | E38: 0 | F38: 0 | G38: 0 | I38: Non-current liabilities | Q38: Total Equity | R38: =SUM(R35:R37) -> 3671.5713 | S38: =SUM(S35:S37) -> 4862.8912 | T38: =SUM(T35:T37) -> 6316.312 | U38: =SUM(U35:U37) -> 7623.2929 | V38: =SUM(V35:V37) -> 9575.79 | W38: =SUM(W35:W37) -> 14568.18 | Y38: Borrowings | Z38: 2200 | AA38: 130.4 | AB38: 380 | AC38: 380 | AD38: 380 | AE38: 380 | AG38: Borrowings | AH38: 3275.22 | AI38: 2941.07 | AJ38: 2123.22 | AK38: 2496.22 | AL38: 1603.78 | AM38: 1191.75 | AO38: Total equity | AP38: =SUM(AP35:AP37) -> 16057.28 | AQ38: =SUM(AQ35:AQ37) -> 18585.59 | AR38: =SUM(AR35:AR37) -> 21117.38 | AS38: =SUM(AS35:AS37) -> 23713.54 | AT38: =SUM(AT35:AT37) -> 26802.33 | AU38: =SUM(AU35:AU37) -> 31289.25
A39: Provisions | B39: 20.52 | C39: 25.25 | D39: 26.71 | E39: 30.62 | F39: 37 | G39: 0 | I39: Borrowings | J39: 2028.92 | K39: 898.13 | L39: 4865.64 | M39: 7586.73 | N39: 1.33 | O39: 2.52 | Q39: LIABILITIES | Y39: Lease Liabilities | Z39: 10.2 | AA39: 0 | AB39: 249.9 | AC39: 194.6 | AD39: 219 | AE39: 406.4 | AG39: Other financial liabilities | AH39: 110.62 | AI39: 29.71 | AJ39: 5.04 | AK39: 20.87 | AL39: 9.24 | AM39: 13.8 | AO39: Share application money pending allotment | AP39: 0 | AQ39: 0 | AR39: 0 | AS39: 0 | AT39: 0 | AU39: 0
A40: Deferred tax liabilities (net) | B40: 273.96 | C40: 338.06 | D40: 421.4 | E40: 537.21 | F40: 582 | G40: 509 | I40: Other financial liabilities | J40: 42.41 | K40: 19.58 | L40: 0 | M40: 391.22 | N40: 302.29 | O40: 355.74 | Q40: Non-current Liabilities | Y40: Other financial liabilities | Z40: 0 | AA40: 0 | AB40: 0 | AC40: 0 | AD40: 0 | AE40: 19.8 | AG40: Provisions | AH40: 338.34 | AI40: 369.62 | AJ40: 368.74 | AK40: 393.06 | AL40: 444.69 | AM40: 501.27 | AO40: Liabilities
...

Sheet Balance Sheet Forecast
A2: #VALUE! | H2: #VALUE! | O2: #VALUE! | V2: #VALUE! | AC2: #VALUE! | AJ2: #VALUE!
A3: Particulars | B3: 2026 | C3: 2027 | D3: 2028 | E3: 2029 | F3: 2030 | H3: Particulars | I3: 2026 | J3: 2027 | K3: 2028 | L3: 2029 | M3: 2030 | O3: Particulars | P3: 2026 | Q3: 2027 | R3: 2028 | S3: 2029 | T3: 2030 | V3: Particulars | W3: 2026 | X3: 2027 | Y3: 2028 | Z3: 2029 | AA3: 2030 | AC3: Particulars | AD3: 2026 | AE3: 2027 | AF3: 2028 | AG3: 2029 | AH3: 2030 | AJ3: Particulars | AK3: 2026 | AL3: 2027 | AM3: 2028 | AN3: 2029 | AO3: 2030
A4: ASSETS | H4: ASSETS | O4: ASSETS | V4: ASSETS | AC4: ASSETS | AJ4: ASSETS
A5: Non-current Assets | H5: Non-current Assets | O5: Non-current Assets | V5: Non-current Assets | AC5: Non-current Assets | AJ5: Non-current Assets
A6: Property, Plant and Equipment | B6: =Table1[[#This Row],[2025]]+'Income Statement'!B58-'Income Statement'!B59 -> 6372.4947 | C6: =Table25[[#This Row],[2026]]+'Income Statement'!C58-'Income Statement'!C59 -> 7369.225 | D6: =Table25[[#This Row],[2027]]+'Income Statement'!D58-'Income Statement'!D59 -> 8435.286 | E6: =Table25[[#This Row],[2028]]+'Income Statement'!E58-'Income Statement'!E59 -> 9579.4043 | F6: =Table25[[#This Row],[2029]]+'Income Statement'!F58-'Income Statement'!F59 -> 10811.01 | H6: Property, Plant and Equipment | I6: =Table2[[#This Row],[2025]]+'Income Statement'!J69-'Income Statement'!J70 -> 10721.884 | J6: =Table26[[#This Row],[2026]]+'Income Statement'!K69-'Income Statement'!K70 -> 11494.881 | K6: =Table26[[#This Row],[2027]]+'Income Statement'!L69-'Income Statement'!L70 -> 12357.245 | L6: =Table26[[#This Row],[2028]]+'Income Statement'!M69-'Income Statement'!M70 -> 13312.374 | M6: =Table26[[#This Row],[2029]]+'Income Statement'!N69-'Income Statement'!N70 -> 14364.687 | O6: Property, Plant and Equipment | P6: =Table3[[#This Row],[2025]]+'Income Statement'!R69-'Income Statement'!R70 -> 3279.2546 | Q6: =Table27[[#This Row],[2026]]+'Income Statement'!S69-'Income Statement'!S70 -> 3881.9688 | R6: =Table27[[#This Row],[2027]]+'Income Statement'!T69-'Income Statement'!T70 -> 4559.474 | S6: =Table27[[#This Row],[2028]]+'Income Statement'!U69-'Income Statement'!U70 -> 5324.4099 | T6: =Table27[[#This Row],[2029]]+'Income Statement'!V69-'Income Statement'!V70 -> 6191.7102 | V6: Property, Plant and Equipment | W6: =Table4[[#This Row],[2025]]+'Income Statement'!Z71-'Income Statement'!Z72 -> 8362.2111 | X6: =Table28[[#This Row],[2026]]+'Income Statement'!AA71-'Income Statement'!AA72 -> 9502.1226 | Y6: =Table28[[#This Row],[2027]]+'Income Statement'!AB71-'Income Statement'!AB72 -> 10732.529 | Z6: =Table28[[#This Row],[2028]]+'Income Statement'!AC71-'Income Statement'!AC72 -> 12068.481 | AA6: =Table28[[#This Row],[2029]]+'Income Statement'!AD71-'Income Statement'!AD72 -> 13525.894 | AC6: Property, Plant and Equipment | AD6: =Table5[[#This Row],[2025]]+'Income Statement'!AH71-'Income Statement'!AH72 -> 3453.6832 | AE6: =Table29[[#This Row],[2026]]+'Income Statement'!AI71-'Income Statement'!AI72 -> 3708.4442 | AF6: =Table29[[#This Row],[2027]]+'Income Statement'!AJ71-'Income Statement'!AJ72 -> 3974.6411 | AG6: =Table29[[#This Row],[2028]]+'Income Statement'!AK71-'Income Statement'!AK72 -> 4253.4115 | AH6: =Table29[[#This Row],[2029]]+'Income Statement'!AL71-'Income Statement'!AL72 -> 4545.9195 | AJ6: Property, Plant and Equipment | AK6: =Table6[[#This Row],[2025]]+'Income Statement'!AP71-'Income Statement'!AP72 -> 5005.9468 | AL6: =Table30[[#This Row],[2026]]+'Income Statement'!AQ71-'Income Statement'!AQ72 -> 5253.1906 | AM6: =Table30[[#This Row],[2027]]+'Income Statement'!AR71-'Income Statement'!AR72 -> 5553.1553 | AN6: =Table30[[#This Row],[2028]]+'Income Statement'!AS71-'Income Statement'!AS72 -> 5904.474 | AO6: =Table30[[#This Row],[2029]]+'Income Statement'!AT71-'Income Statement'!AT72 -> 6306.7239
A7: Intangible assets (Patents, R&D) | B7: ='Balance Sheet'!G8+'Balance Sheet'!G9+'Income Statement Forecast'!B11 -> 1368.012 | C7: =Table25[[#This Row],[2026]]+'Income Statement Forecast'!C11 -> 1743.2223 | D7: =Table25[[#This Row],[2027]]+'Income Statement Forecast'!D11 -> 2154.8551 | E7: =Table25[[#This Row],[2028]]+'Income Statement Forecast'!E11 -> 2606.4479 | F7: =Table25[[#This Row],[2029]]+'Income Statement Forecast'!F11 -> 3101.8821 | H7: Intangible assets (Patents, R&D) | I7: ='Balance Sheet'!O9+'Income Statement'!J78-'Income Statement'!J77 -> 6548.0895 | J7: =Table26[[#This Row],[2026]]+'Income Statement'!K78-'Income Statement'!K77 -> 9249.9841 | K7: =Table26[[#This Row],[2027]]+'Income Statement'!L78-'Income Statement'!L77 -> 11785.796 | L7: =Table26[[#This Row],[2028]]+'Income Statement'!M78-'Income Statement'!M77 -> 14214.175 | M7: =Table26[[#This Row],[2029]]+'Income Statement'!N78-'Income Statement'!N77 -> 16585.358 | O7: Intangible assets (Patents, R&D) | P7: ='Balance Sheet'!W10+'Income Statement'!R78-'Income Statement'!R77 -> 9554.8562 | Q7: =Table27[[#This Row],[2026]]+'Income Statement'!S78-'Income Statement'!S77 -> 9573.3567 | R7: =Table27[[#This Row],[2027]]+'Income Statement'!T78-'Income Statement'!T77 -> 9664.0764 | S7: =Table27[[#This Row],[2028]]+'Income Statement'!U78-'Income Statement'!U77 -> 9832.3922 | T7: =Table27[[#This Row],[2029]]+'Income Statement'!V78-'Income Statement'!V77 -> 10084.607 | V7: Intangible assets (Patents, R&D) | W7: ='Balance Sheet'!AE9+'Income Statement'!Z80-'Income Statement'!Z79 -> 11240.508 | X7: ='Income Statement'!AA80-'Income Statement'!AA79+Table28[[#This Row],[2026]] -> 12966.697 | Y7: ='Income Statement'!AB80-'Income Statement'!AB79+Table28[[#This Row],[2027]] -> 14814.155 | Z7: ='Income Statement'!AC80-'Income Statement'!AC79+Table28[[#This Row],[2028]] -> 16805.283 | AA7: ='Income Statement'!AD80-'Income Statement'!AD79+Table28[[#This Row],[2029]] -> 18963.691 | AC7: Intangible assets (Patents, R&D) | AD7: ='Balance Sheet'!AM10+'Income Statement'!AH80-'Income Statement'!AH79 -> 4381.9349 | AE7: =Table29[[#This Row],[2026]]+'Income Statement'!AI80-'Income Statement'!AI79 -> 4628.3001 | AF7: =Table29[[#This Row],[2027]]+'Income Statement'!AJ80-'Income Statement'!AJ79 -> 4892.2327 | AG7: =Table29[[#This Row],[2028]]+'Income Statement'!AK80-'Income Statement'!AK79 -> 5174.5746 | AH7: =Table29[[#This Row],[2029]]+'Income Statement'!AL80-'Income Statement'!AL79 -> 5476.2434 | AJ7: Intangible assets (Patents, R&D) | AK7: ='Balance Sheet'!AU11+'Income Statement'!AP80-'Income Statement'!AP79 -> 3951.3488 | AL7: =Table30[[#This Row],[2026]]+'Income Statement'!AQ80-'Income Statement'!AQ79 -> 6298.1986 | AM7: =Table30[[#This Row],[2027]]+'Income Statement'!AR80-'Income Statement'!AR79 -> 8468.3555 | AN7: =Table30[[#This Row],[2028]]+'Income Statement'!AS80-'Income Statement'!AS79 -> 10516.592 | AO7: =Table30[[#This Row],[2029]]+'Income Statement'!AT80-'Income Statement'!AT79 -> 12489.341
A8: Other non-current assets | B8: ='Income Statement'!B62 -> 288.45634 | C8: ='Income Statement'!C62 -> 316.45611 | D8: ='Income Statement'!D62 -> 347.17521 | E8: ='Income Statement'!E62 -> 380.8779 | F8: ='Income Statement'!F62 -> 417.85414 | H8: Other non-current assets | I8: ='Income Statement'!J73 -> 18411.023 | J8: ='Income Statement'!K73 -> 19971.848 | K8: ='Income Statement'!L73 -> 21664.994 | L8: ='Income Statement'!M73 -> 23501.68 | M8: ='Income Statement'!N73 -> 25494.074 | O8: Other non-current assets | P8: ='Income Statement'!R73 -> 2872.3565 | Q8: ='Income Statement'!S73 -> 3244.9877 | R8: ='Income Statement'!T73 -> 3665.9604 | S8: ='Income Statement'!U73 -> 4141.546 | T8: ='Income Statement'!V73 -> 4678.8293 | V8: Other non-current assets | W8: ='Income Statement'!Z75 -> 5692.189 | X8: ='Income Statement'!AA75 -> 6314.4622 | Y8: ='Income Statement'!AB75 -> 7004.7625 | Z8: ='Income Statement'!AC75 -> 7770.5269 | AA8: ='Income Statement'!AD75 -> 8620.005 | AC8: Other non-current assets | AD8: ='Income Statement'!AH75 -> 2393.3055 | AE8: ='Income Statement'!AI75 -> 2540.7802 | AF8: ='Income Statement'!AJ75 -> 2697.3423 | AG8: ='Income Statement'!AK75 -> 2863.5518 | AH8: ='Income Statement'!AL75 -> 3040.003 | AJ8: Other non-current assets | AK8: ='Income Statement'!AP75 -> 8079.7437 | AL8: ='Income Statement'!AQ75 -> 8760.9587 | AM8: ='Income Statement'!AR75 -> 9499.6082 | AN8: ='Income Statement'!AS75 -> 10300.535 | AO8: ='Income Statement'!AT75 -> 11168.989
A9: Total non-current assets | B9: =SUM(B6:B8) -> 8028.9631 | C9: =SUM(C6:C8) -> 9428.9034 | D9: =SUM(D6:D8) -> 10937.316 | E9: =SUM(E6:E8) -> 12566.73 | F9: =SUM(F6:F8) -> 14330.746 | H9: Total non-current assets | I9: =SUM(I6:I8) -> 35680.996 | J9: =SUM(J6:J8) -> 40716.713 | K9: =SUM(K6:K8) -> 45808.035 | L9: =SUM(L6:L8) -> 51028.229 | M9: =SUM(M6:M8) -> 56444.119 | O9: Total non-current assets | P9: =P6+P7+P8 -> 15706.467 | Q9: =Q6+Q7+Q8 -> 16700.313 | R9: =R6+R7+R8 -> 17889.511 | S9: =S6+S7+S8 -> 19298.348 | T9: =T6+T7+T8 -> 20955.146 | V9: Total non-current assets | W9: =SUM(W6:W8) -> 25294.908 | X9: =SUM(X6:X8) -> 28783.282 | Y9: =SUM(Y6:Y8) -> 32551.447 | Z9: =SUM(Z6:Z8) -> 36644.291 | AA9: =SUM(AA6:AA8) -> 41109.59 | AC9: Total non-current assets | AD9: =SUM(AD6:AD8) -> 10228.924 | AE9: =SUM(AE6:AE8) -> 10877.525 | AF9: =SUM(AF6:AF8) -> 11564.216 | AG9: =SUM(AG6:AG8) -> 12291.538 | AH9: =SUM(AH6:AH8) -> 13062.166 | AJ9: Total non-current assets | AK9: =SUM(AK6:AK8) -> 17037.039 | AL9: =SUM(AL6:AL8) -> 20312.348 | AM9: =SUM(AM6:AM8) -> 23521.119 | AN9: =SUM(AN6:AN8) -> 26721.601 | AO9: =SUM(AO6:AO8) -> 29965.053
A10: Current Assets | H10: Current Assets | O10: Current Assets | V10: Current Assets | AC10: Current Assets | AJ10: Current Assets
A11: Cash and Cash equivalents (B&L) | B11: =B32-(SUM(B6:B8,B12:B14)) -> 1370.4179 | C11: =C32-(SUM(C6:C8,C12:C14)) -> 767.85449 | D11: =D32-(SUM(D6:D8,D12:D14)) -> 122.61044 | E11: 0 | F11: 0 | H11: Cash and Cash equivalents | I11: =I32-(SUM(I6:I8,I12:I14)) -> 35848.081 | J11: =J32-(SUM(J6:J8,J12:J14)) -> 36498.269 | K11: =K32-(SUM(K6:K8,K12:K14)) -> 37587.012 | L11: =L32-(SUM(L6:L8,L12:L14)) -> 39155.793 | M11: =M32-(SUM(M6:M8,M12:M14)) -> 41263.453 | O11: Cash and Cash equivalents (B&L) | P11: =P32-(SUM(P6:P8,P12:P14)) -> 7729.9371 | Q11: =Q32-(SUM(Q6:Q8,Q12:Q14)) -> 9046.172 | R11: =R32-(SUM(R6:R8,R12:R14)) -> 10680.094 | S11: =S32-(SUM(S6:S8,S12:S14)) -> 12711.655 | T11: =T32-(SUM(T6:T8,T12:T14)) -> 15243.078 | V11: Cash and Cash equivalents (B&L) | W11: =W32-(SUM(W6:W8,W12:W14)) -> 9586.6307 | X11: =X32-(SUM(X6:X8,X12:X14)) -> 9502.8242 | Y11: =Y32-(SUM(Y6:Y8,Y12:Y14)) -> 9440.8186 | Z11: =Z32-(SUM(Z6:Z8,Z12:Z14)) -> 9396.9292 | AA11: =AA32-(SUM(AA6:AA8,AA12:AA14)) -> 9367.7309 | AC11: Cash and Cash equivalents | AD11: =AD32-(SUM(AD6:AD8,AD12:AD14)) -> 922.19755 | AE11: =AE32-(SUM(AE6:AE8,AE12:AE14)) -> 930.24221 | AF11: =AF32-(SUM(AF6:AF8,AF12:AF14)) -> 938.77052 | AG11: =AG32-(SUM(AG6:AG8,AG12:AG14)) -> 948.00117 | AH11: =AH32-(SUM(AH6:AH8,AH12:AH14)) -> 958.10184 | AJ11: Cash and Cash equivalents | AK11: =AK32-(SUM(AK6:AK8,AK12:AK14)) -> 1210.9451 | AL11: 0 | AM11: 0 | AN11: 0 | AO11: 0
A12: Trade receivables | B12: ='Income Statement Forecast'!B7/'Income Statement'!$B$44 -> 2567.7851 | C12: ='Income Statement Forecast'!C7/'Income Statement'!$B$44 -> 2817.0339 | D12: ='Income Statement Forecast'!D7/'Income Statement'!$B$44 -> 3090.4897 | E12: ='Income Statement Forecast'!E7/'Income Statement'!$B$44 -> 3390.5048 | F12: ='Income Statement Forecast'!F7/'Income Statement'!$B$44 -> 3719.6604 | H12: Trade receivables | I12: ='Income Statement'!J76/'Income Statement'!$J$53 -> 11465.177 | J12: ='Income Statement'!K76/'Income Statement'!$J$53 -> 12437.156 | K12: ='Income Statement'!L76/'Income Statement'!$J$53 -> 13491.537 | L12: ='Income Statement'!M76/'Income Statement'!$J$53 -> 14635.304 | M12: ='Income Statement'!N76/'Income Statement'!$J$53 -> 15876.036 | O12: Trade receivables | P12: ='Income Statement'!R76/'Income Statement'!$R$48 -> 897.91476 | Q12: ='Income Statement'!S76/'Income Statement'!$R$48 -> 1014.4014 | R12: ='Income Statement'!T76/'Income Statement'!$R$48 -> 1145.9998 | S12: ='Income Statement'!U76/'Income Statement'!$R$48 -> 1294.6705 | T12: ='Income Statement'!V76/'Income Statement'!$R$48 -> 1462.6283 | V12: Trade receivables | W12: ='Income Statement'!Z78/'Income Statement'!$Z$49 -> 6518.2335 | X12: ='Income Statement'!AA78/'Income Statement'!$Z$49 -> 7230.8102 | Y12: ='Income Statement'!AB78/'Income Statement'!$Z$49 -> 8021.2862 | Z12: ='Income Statement'!AC78/'Income Statement'!$Z$49 -> 8898.1775 | AA12: ='Income Statement'!AD78/'Income Statement'!$Z$49 -> 9870.931 | AC12: Trade receivables | AD12: ='Income Statement Forecast'!AD7/'Income Statement'!$AH$48 -> 2066.3727 | AE12: ='Income Statement Forecast'!AE7/'Income Statement'!$AH$48 -> 2192.8025 | AF12: ='Income Statement Forecast'!AF7/'Income Statement'!$AH$48 -> 2327.2392 | AG12: ='Income Statement Forecast'!AG7/'Income Statement'!$AH$48 -> 2470.1243 | AH12: ='Income Statement Forecast'!AH7/'Income Statement'!$AH$48 -> 2621.9386 | AJ12: Trade receivables | AK12: ='Income Statement Forecast'!AK7/'Income Statement'!$AP$49 -> 5444.0269 | AL12: ='Income Statement Forecast'!AL7/'Income Statement'!$AP$49 -> 5903.0208 | AM12: ='Income Statement Forecast'!AM7/'Income Statement'!$AP$49 -> 6400.7133 | AN12: ='Income Statement Forecast'!AN7/'Income Statement'!$AP$49 -> 6940.3671 | AO12: ='Income Statement Forecast'!AO7/'Income Statement'!$AP$49 -> 7525.5202
A13: Inventory | B13: ='Income Statement Forecast'!B9/'Income Statement'!$B$45 -> 3460.6439 | C13: ='Income Statement Forecast'!C9/'Income Statement'!$B$45 -> 3796.5604 | D13: ='Income Statement Forecast'!D9/'Income Statement'!$B$45 -> 4165.101 | E13: ='Income Statement Forecast'!E9/'Income Statement'!$B$45 -> 4569.4361 | F13: ='Income Statement Forecast'!F9/'Income Statement'!$B$45 -> 5013.0442 | H13: Inventory | I13: ='Income Statement'!J71/'Income Statement'!$J$54 -> 11789.473 | J13: ='Income Statement'!K71/'Income Statement'!$J$54 -> 12788.945 | K13: ='Income Statement'!L71/'Income Statement'!$J$54 -> 13873.149 | L13: ='Income Statement'!M71/'Income Statement'!$J$54 -> 15049.268 | M13: ='Income Statement'!N71/'Income Statement'!$J$54 -> 16325.095 | O13: Inventory | P13: ='Income Statement'!R71/'Income Statement'!$R$49 -> 2210.8281 | Q13: ='Income Statement'!S71/'Income Statement'!$R$49 -> 2497.6391 | R13: ='Income Statement'!T71/'Income Statement'!$R$49 -> 2821.6582 | S13: ='Income Statement'!U71/'Income Statement'!$R$49 -> 3187.7123 | T13: ='Income Statement'!V71/'Income Statement'!$R$49 -> 3601.2546 | V13: Inventory | W13: ='Income Statement'!Z73/'Income Statement'!$Z$50 -> 6896.9062 | X13: ='Income Statement'!AA73/'Income Statement'!$Z$50 -> 7650.8797 | Y13: ='Income Statement'!AB73/'Income Statement'!$Z$50 -> 8487.2779 | Z13: ='Income Statement'!AC73/'Income Statement'!$Z$50 -> 9415.1117 | AA13: ='Income Statement'!AD73/'Income Statement'!$Z$50 -> 10444.377 | AC13: Inventory | AD13: ='Income Statement'!AH73/'Income Statement'!$AH$49 -> 3060.9411 | AE13: ='Income Statement'!AI73/'Income Statement'!$AH$49 -> 3249.5553 | AF13: ='Income Statement'!AJ73/'Income Statement'!$AH$49 -> 3449.792 | AG13: ='Income Statement'!AK73/'Income Statement'!$AH$49 -> 3662.3671 | AH13: ='Income Statement'!AL73/'Income Statement'!$AH$49 -> 3888.0411 | AJ13: Inventory | AK13: ='Income Statement Forecast'!AK9/'Income Statement'!$AP$50 -> 6767.4899 | AL13: ='Income Statement Forecast'!AL9/'Income Statement'!$AP$50 -> 7338.0669 | AM13: ='Income Statement Forecast'!AM9/'Income Statement'!$AP$50 -> 7956.7502 | AN13: ='Income Statement Forecast'!AN9/'Income Statement'!$AP$50 -> 8627.596 | AO13: ='Income Statement Forecast'!AO9/'Income Statement'!$AP$50 -> 9355.0019
A14: Other current assets | B14: ='Income Statement Forecast'!B7*'Income Statement'!$B$47 -> 3063.8537 | C14: ='Income Statement Forecast'!C7*'Income Statement'!$B$47 -> 3361.2547 | D14: ='Income Statement Forecast'!D7*'Income Statement'!$B$47 -> 3687.5393 | E14: ='Income Statement Forecast'!E7*'Income Statement'!$B$47 -> 4045.5141 | F14: ='Income Statement Forecast'!F7*'Income Statement'!$B$47 -> 4438.259 | H14: Other current assets | I14: ='Income Statement'!J76*'Income Statement'!$J$56 -> 5803.9502 | J14: ='Income Statement'!K76*'Income Statement'!$J$56 -> 6295.9897 | K14: ='Income Statement'!L76*'Income Statement'!$J$56 -> 6829.7427 | L14: ='Income Statement'!M76*'Income Statement'!$J$56 -> 7408.7454 | M14: ='Income Statement'!N76*'Income Statement'!$J$56 -> 8036.834 | O14: Other current assets | P14: ='Income Statement'!R80 -> 1593.9655 | Q14: ='Income Statement'!S80 -> 1800.7509 | R14: ='Income Statement'!T80 -> 2034.3625 | S14: ='Income Statement'!U80 -> 2298.2807 | T14: ='Income Statement'!V80 -> 2596.4369 | V14: Other current assets | W14: ='Income Statement'!Z82 -> 3914.3526 | X14: ='Income Statement'!AA82 -> 4342.2717 | Y14: ='Income Statement'!AB82 -> 4816.9712 | Z14: ='Income Statement'!AC82 -> 5343.5651 | AA14: ='Income Statement'!AD82 -> 5927.7264 | AC14: Other current assets | AD14: ='Income Statement'!AH82 -> 848.27606 | AE14: ='Income Statement'!AI82 -> 900.54658 | AF14: ='Income Statement'!AJ82 -> 956.03799 | AG14: ='Income Statement'!AK82 -> 1014.9488 | AH14: ='Income Statement'!AL82 -> 1077.4896 | AJ14: Other current assets | AK14: ='Income Statement'!AP82 -> 10624.65 | AL14: ='Income Statement'!AQ82 -> 11520.43 | AM14: ='Income Statement'!AR82 -> 12491.734 | AN14: ='Income Statement'!AS82 -> 13544.931 | AO14: ='Income Statement'!AT82 -> 14686.925
A15: Total current assets | B15: =SUM(B11:B14) -> 10462.701 | C15: =SUM(C11:C14) -> 10742.704 | D15: =SUM(D11:D14) -> 11065.74 | E15: =SUM(E11:E14) -> 12005.455 | F15: =SUM(F11:F14) -> 13170.964 | H15: Total current assets | I15: =SUM(I11:I14) -> 64906.681 | J15: =SUM(J11:J14) -> 68020.361 | K15: =SUM(K11:K14) -> 71781.441 | L15: =SUM(L11:L14) -> 76249.11 | M15: =SUM(M11:M14) -> 81501.419 | O15: Total current assets | P15: =SUM(P11:P14) -> 12432.646 | Q15: =SUM(Q11:Q14) -> 14358.963 | R15: =SUM(R11:R14) -> 16682.114 | S15: =SUM(S11:S14) -> 19492.318 | T15: =SUM(T11:T14) -> 22903.398 | V15: Total current assets | W15: =SUM(W11:W14) -> 26916.123 | X15: =SUM(X11:X14) -> 28726.786 | Y15: =SUM(Y11:Y14) -> 30766.354 | Z15: =SUM(Z11:Z14) -> 33053.783 | AA15: =SUM(AA11:AA14) -> 35610.765 | AC15: Total current assets | AD15: =SUM(AD11:AD14) -> 6897.7874 | AE15: =SUM(AE11:AE14) -> 7273.1466 | AF15: =SUM(AF11:AF14) -> 7671.8397 | AG15: =SUM(AG11:AG14) -> 8095.4413 | AH15: =SUM(AH11:AH14) -> 8545.5711 | AJ15: Total current assets | AK15: =SUM(AK11:AK14) -> 24047.112 | AL15: =SUM(AL11:AL14) -> 24761.517 | AM15: =SUM(AM11:AM14) -> 26849.198 | AN15: =SUM(AN11:AN14) -> 29112.894 | AO15: =SUM(AO11:AO14) -> 31567.448
A16: Total Assets | B16: =B9+B15 -> 18491.664 | C16: =C9+C15 -> 20171.607 | D16: =D9+D15 -> 22003.057 | E16: =E9+E15 -> 24572.185 | F16: =F9+F15 -> 27501.71 | H16: Total Assets | I16: =I9+I15 -> 100587.68 | J16: =J9+J15 -> 108737.07 | K16: =K9+K15 -> 117589.48 | L16: =L9+L15 -> 127277.34 | M16: =M9+M15 -> 137945.54 | O16: Total Assets | P16: =P9+P15 -> 28139.113 | Q16: =Q9+Q15 -> 31059.277 | R16: =R9+R15 -> 34571.625 | S16: =S9+S15 -> 38790.666 | T16: =T9+T15 -> 43858.544 | V16: Total Assets | W16: =W9+W15 -> 52211.031 | X16: =X9+X15 -> 57510.067 | Y16: =Y9+Y15 -> 63317.8 | Z16: =Z9+Z15 -> 69698.074 | AA16: =AA9+AA15 -> 76720.355 | AC16: Total Assets | AD16: =AD9+AD15 -> 17126.711 | AE16: =AE9+AE15 -> 18150.671 | AF16: =AF9+AF15 -> 19236.056 | AG16: =AG9+AG15 -> 20386.979 | AH16: =AH9+AH15 -> 21607.737 | AJ16: Total Assets | AK16: =AK9+AK15 -> 41084.151 | AL16: =AL9+AL15 -> 45073.865 | AM16: =AM9+AM15 -> 50370.317 | AN16: =AN9+AN15 -> 55834.495 | AO16: =AO9+AO15 -> 61532.501
A17: EQUITY & LIABILITIES | H17: EQUITY & LIABILITIES | O17: EQUITY & LIABILITIES | V17: EQUITY & LIABILITIES | AC17: EQUITY & LIABILITIES | AJ17: EQUITY & LIABILITIES
A18: Equity | H18: Equity | O18: Equity | V18: Equity | AC18: Equity | AJ18: Equity
A19: Equity Share capital | B19: ='Balance Sheet'!$G$31 -> 53 | C19: ='Balance Sheet'!$G$31 -> 53 | D19: ='Balance Sheet'!$G$31 -> 53 | E19: ='Balance Sheet'!$G$31 -> 53 | F19: ='Balance Sheet'!$G$31 -> 53 | H19: Equity Share capital | I19: ='Balance Sheet'!$O$33 -> 239.93 | J19: ='Balance Sheet'!$O$33 -> 239.93 | K19: ='Balance Sheet'!$O$33 -> 239.93 | L19: ='Balance Sheet'!$O$33 -> 239.93 | M19: ='Balance Sheet'!$O$33 -> 239.93 | O19: Equity Share capital | P19: ='Balance Sheet'!$W$35 -> 41.26 | Q19: ='Balance Sheet'!$W$35 -> 41.26 | R19: ='Balance Sheet'!$W$35 -> 41.26 | S19: ='Balance Sheet'!$W$35 -> 41.26 | T19: ='Balance Sheet'!$W$35 -> 41.26 | V19: Equity Share capital | W19: ='Balance Sheet'!$AE$32 -> 83.4 | X19: ='Balance Sheet'!$AE$32 -> 83.4 | Y19: ='Balance Sheet'!$AE$32 -> 83.4 | Z19: ='Balance Sheet'!$AE$32 -> 83.4 | AA19: ='Balance Sheet'!$AE$32 -> 83.4 | AC19: Equity Share capital | AD19: ='Balance Sheet'!$AM$33 -> 169.23 | AE19: ='Balance Sheet'!$AM$33 -> 169.23 | AF19: ='Balance Sheet'!$AM$33 -> 169.23 | AG19: ='Balance Sheet'!$AM$33 -> 169.23 | AH19: ='Balance Sheet'!$AM$33 -> 169.23 | AJ19: Equity Share capital | AK19: ='Balance Sheet'!$AU$35 -> 161.52 | AL19: ='Balance Sheet'!$AU$35 -> 161.52 | AM19: ='Balance Sheet'!$AU$35 -> 161.52 | AN19: ='Balance Sheet'!$AU$35 -> 161.52 | AO19: ='Balance Sheet'!$AU$35 -> 161.52
A20: Other equity | B20: ='Balance Sheet'!G32+Table31[[#This Row],[2026]]-'Income Statement'!B64 -> 16266.888 | C20: =Table25[[#This Row],[2026]]+Table31[[#This Row],[2027]]-'Income Statement'!C64 -> 17736.41 | D20: =Table25[[#This Row],[2027]]+Table31[[#This Row],[2028]]-'Income Statement'!D64 -> 19337.003 | E20: =Table25[[#This Row],[2028]]+Table31[[#This Row],[2029]]-'Income Statement'!E64 -> 21082.245 | F20: =Table25[[#This Row],[2029]]+Table31[[#This Row],[2030]]-'Income Statement'!F64 -> 22986.972 | H20: Other equity | I20: ='Balance Sheet'!O34+Table32[[#This Row],[2026]]-'Income Statement'!J75 -> 78276.81 | J20: =Table26[[#This Row],[2026]]+Table32[[#This Row],[2027]]-'Income Statement'!K75 -> 85047.165 | K20: =Table26[[#This Row],[2027]]+Table32[[#This Row],[2028]]-'Income Statement'!L75 -> 92403.615 | L20: =Table26[[#This Row],[2028]]+Table32[[#This Row],[2029]]-'Income Statement'!M75 -> 100468.7 | M20: =Table26[[#This Row],[2029]]+Table32[[#This Row],[2030]]-'Income Statement'!N75 -> 109376.56 | O20: Other equity | P20: ='Balance Sheet'!W36+Table33[[#This Row],[2026]]-'Income Statement'!R75 -> 16337.045 | Q20: =Table27[[#This Row],[2026]]+Table33[[#This Row],[2027]]-'Income Statement'!S75 -> 18833.802 | R20: =Table27[[#This Row],[2027]]+Table33[[#This Row],[2028]]-'Income Statement'!T75 -> 21867.816 | S20: =Table27[[#This Row],[2028]]+Table33[[#This Row],[2029]]-'Income Statement'!U75 -> 25546.467 | T20: =Table27[[#This Row],[2029]]+Table33[[#This Row],[2030]]-'Income Statement'!V75 -> 30003.851 | V20: Other equity | W20: ='Balance Sheet'!AE33+Table34[[#This Row],[2026]]-'Income Statement'!Z77 -> 36891.521 | X20: =Table28[[#This Row],[2026]]+Table34[[#This Row],[2027]]-'Income Statement'!AA77 -> 40610.908 | Y20: =Table28[[#This Row],[2027]]+Table34[[#This Row],[2028]]-'Income Statement'!AB77 -> 44666.302 | Z20: =Table28[[#This Row],[2028]]+Table34[[#This Row],[2029]]-'Income Statement'!AC77 -> 49102.671 | AA20: =Table28[[#This Row],[2029]]+Table34[[#This Row],[2030]]-'Income Statement'!AD77 -> 53968.539 | AC20: Other equity | AD20: ='Balance Sheet'!AM34+Table35[[#This Row],[2026]]-'Income Statement'!AH77 -> 7870.7667 | AE20: =Table29[[#This Row],[2026]]+Table35[[#This Row],[2027]]-'Income Statement'!AI77 -> 8345.6655 | AF20: =Table29[[#This Row],[2027]]+Table35[[#This Row],[2028]]-'Income Statement'!AJ77 -> 8848.1558 | AG20: =Table29[[#This Row],[2028]]+Table35[[#This Row],[2029]]-'Income Statement'!AK77 -> 9380.267 | AH20: =Table29[[#This Row],[2029]]+Table35[[#This Row],[2030]]-'Income Statement'!AL77 -> 9944.0817 | AJ20: Other equity | AK20: ='Balance Sheet'!AU36+Table36[[#This Row],[2026]]-'Income Statement'!AP77 -> 33095.765 | AL20: =Table30[[#This Row],[2026]]+Table36[[#This Row],[2027]]-'Income Statement'!AQ77 -> 35121.682 | AM20: =Table30[[#This Row],[2027]]+Table36[[#This Row],[2028]]-'Income Statement'!AR77 -> 37070.557 | AN20: =Table30[[#This Row],[2028]]+Table36[[#This Row],[2029]]-'Income Statement'!AS77 -> 38892.559 | AO20: =Table30[[#This Row],[2029]]+Table36[[#This Row],[2030]]-'Income Statement'!AT77 -> 40868.102
A21: Total equity | B21: =SUM(B19:B20) -> 16319.888 | C21: =SUM(C19:C20) -> 17789.41 | D21: =SUM(D19:D20) -> 19390.003 | E21: =SUM(E19:E20) -> 21135.245 | F21: =SUM(F19:F20) -> 23039.972 | H21: Total equity | I21: =I19+I20 -> 78516.74 | J21: =J19+J20 -> 85287.095 | K21: =K19+K20 -> 92643.545 | L21: =L19+L20 -> 100708.63 | M21: =M19+M20 -> 109616.49 | O21: Total equity | P21: =P19+P20 -> 16378.305 | Q21: =Q19+Q20 -> 18875.062 | R21: =R19+R20 -> 21909.076 | S21: =S19+S20 -> 25587.727 | T21: =T19+T20 -> 30045.111 | V21: Total equity | W21: =W19+W20 -> 36974.921 | X21: =X19+X20 -> 40694.308 | Y21: =Y19+Y20 -> 44749.702 | Z21: =Z19+Z20 -> 49186.071 | AA21: =AA19+AA20 -> 54051.939 | AC21: Total equity | AD21: =AD19+AD20 -> 8039.9967 | AE21: =AE19+AE20 -> 8514.8955 | AF21: =AF19+AF20 -> 9017.3858 | AG21: =AG19+AG20 -> 9549.497 | AH21: =AH19+AH20 -> 10113.312 | AJ21: Total equity | AK21: =AK19+AK20 -> 33257.285 | AL21: =AL19+AL20 -> 35283.202 | AM21: =AM19+AM20 -> 37232.077 | AN21: =AN19+AN20 -> 39054.079 | AO21: =AO19+AO20 -> 41029.622
A22: Non-current liabilities | H22: Non-current liabilities | O22: Non-current liabilities | V22: Non-current liabilities | AC22: Non-current liabilities | AJ22: Non-current liabilities
A23: Long-term borrowings (B&L) | B23: 0 | C23: 0 | D23: 0 | E23: =E16-(SUM(E19:E20,E24:E25,E28:E30)) -> 570.60775 | F23: =F16-(SUM(F19:F20,F24:F25,F28:F30)) -> 1317.5256 | H23: Long-term borrowings | I23: ='Income Statement'!$J$66 -> 5364.71 | J23: ='Income Statement'!$J$66 -> 5364.71 | K23: ='Income Statement'!$J$66 -> 5364.71 | L23: ='Income Statement'!$J$66 -> 5364.71 | M23: ='Income Statement'!$J$66 -> 5364.71 | O23: Long-term borrowings | P23: ='Balance Sheet'!$W$41 -> 5526.19 | Q23: ='Balance Sheet'!$W$41 -> 5526.19 | R23: ='Balance Sheet'!$W$41 -> 5526.19 | S23: ='Balance Sheet'!$W$41 -> 5526.19 | T23: ='Balance Sheet'!$W$41 -> 5526.19 | V23: Long-term borrowings | W23: ='Balance Sheet'!$AE$38 -> 380 | X23: ='Balance Sheet'!$AE$38 -> 380 | Y23: ='Balance Sheet'!$AE$38 -> 380 | Z23: ='Balance Sheet'!$AE$38 -> 380 | AA23: ='Balance Sheet'!$AE$38 -> 380 | AC23: Long-term borrowings | AD23: ='Income Statement'!AH85 -> 1543.3761 | AE23: ='Income Statement'!AI85 -> 1638.4785 | AF23: ='Income Statement'!AJ85 -> 1739.441 | AG23: ='Income Statement'!AK85 -> 1846.6249 | AH23: ='Income Statement'!AL85 -> 1960.4133 | AJ23: Long-term borrowings | AK23: 0 | AL23: =AL16-(SUM(AL19:AL20,AL24:AL25,AL28:AL30)) -> 1333.0819 | AM23: =AM16-(SUM(AM19:AM20,AM24:AM25,AM28:AM30)) -> 3996.7659 | AN23: =AN16-(SUM(AN19:AN20,AN24:AN25,AN28:AN30)) -> 6897.3907 | AO23: =AO16-(SUM(AO19:AO20,AO24:AO25,AO28:AO30)) -> 9815.7798
A24: Lease liabilities | B24: 2 | C24: 2 | D24: 2 | E24: 2 | F24: 2 | H24: Lease liabilities | I24: =AVERAGE('Balance Sheet'!N42:O42) -> 439.465 | J24: =$I$24 -> 439.465 | K24: =$I$24 -> 439.465 | L24: =$I$24 -> 439.465 | M24: =$I$24 -> 439.465 | O24: Lease liabilities | P24: ='Balance Sheet'!$W$42 -> 14.03 | Q24: ='Balance Sheet'!$W$42 -> 14.03 | R24: ='Balance Sheet'!$W$42 -> 14.03 | S24: ='Balance Sheet'!$W$42 -> 14.03 | T24: ='Balance Sheet'!$W$42 -> 14.03 | V24: Lease liabilities | W24: ='Balance Sheet'!$AE$39 -> 406.4 | X24: ='Balance Sheet'!$AE$39 -> 406.4 | Y24: ='Balance Sheet'!$AE$39 -> 406.4 | Z24: ='Balance Sheet'!$AE$39 -> 406.4 | AA24: ='Balance Sheet'!$AE$39 -> 406.4 | AC24: Lease liabilities | AD24: ='Balance Sheet'!AM42+'Balance Sheet'!AM50 -> 176.23 | AE24: =$AD$24 -> 176.23 | AF24: =$AD$24 -> 176.23 | AG24: =$AD$24 -> 176.23 | AH24: =$AD$24 -> 176.23 | AJ24: Lease liabilities | AK24: ='Balance Sheet'!AU54+'Balance Sheet'!AU43 -> 346.09 | AL24: =$AK$24 -> 346.09 | AM24: =$AK$24 -> 346.09 | AN24: =$AK$24 -> 346.09 | AO24: =$AK$24 -> 346.09
A25: Other non-current liabilities | B25: ='Income Statement Forecast'!B7*'Income Statement'!$B$51 -> 624.77092 | C25: ='Income Statement Forecast'!C7*'Income Statement'!$B$51 -> 685.41595 | D25: ='Income Statement Forecast'!D7*'Income Statement'!$B$51 -> 751.95081 | E25: ='Income Statement Forecast'!E7*'Income Statement'!$B$51 -> 824.94786 | F25: ='Income Statement Forecast'!F7*'Income Statement'!$B$51 -> 905.0351 | H25: Other non-current liabilities | I25: ='Income Statement'!J76*'Income Statement'!$J$59 -> 1210.3038 | J25: ='Income Statement'!K76*'Income Statement'!$J$59 -> 1312.9093 | K25: ='Income Statement'!L76*'Income Statement'!$J$59 -> 1424.2134 | L25: ='Income Statement'!M76*'Income Statement'!$J$59 -> 1544.9534 | M25: ='Income Statement'!N76*'Income Statement'!$J$59 -> 1675.9294 | O25: Other non-current liabilities | P25: ='Income Statement'!R82 -> 574.34751 | Q25: ='Income Statement'!S82 -> 648.85769 | R25: ='Income Statement'!T82 -> 733.03409 | S25: ='Income Statement'!U82 -> 828.1307 | T25: ='Income Statement'!V82 -> 935.5642 | V25: Other non-current liabilities | W25: ='Income Statement'!Z84 -> 699.43298 | X25: ='Income Statement'!AA84 -> 775.89536 | Y25: ='Income Statement'!AB84 -> 860.71666 | Z25: ='Income Statement'!AC84 -> 954.81066 | AA25: ='Income Statement'!AD84 -> 1059.1911 | AC25: Other non-current liabilities | AD25: ='Income Statement'!AH84 -> 1031.0561 | AE25: ='Income Statement'!AI84 -> 1094.5895 | AF25: ='Income Statement'!AJ84 -> 1162.0378 | AG25: ='Income Statement'!AK84 -> 1233.6422 | AH25: ='Income Statement'!AL84 -> 1309.6589 | AJ25: Other non-current liabilities | AK25: ='Income Statement'!AP84 -> 798.4097 | AL25: ='Income Statement'!AQ84 -> 865.72479 | AM25: ='Income Statement'!AR84 -> 938.71534 | AN25: ='Income Statement'!AS84 -> 1017.8599 | AO25: ='Income Statement'!AT84 -> 1103.6772
A26: Total non-current liabilities | B26: =SUM(B23:B25) -> 626.77092 | C26: =SUM(C23:C25) -> 687.41595 | D26: =SUM(D23:D25) -> 753.95081 | E26: =SUM(E23:E25) -> 1397.5556 | F26: =SUM(F23:F25) -> 2224.5607 | H26: Total non-current liabilities | I26: =SUM(I23:I25) -> 7014.4788 | J26: =SUM(J23:J25) -> 7117.0843 | K26: =SUM(K23:K25) -> 7228.3884 | L26: =SUM(L23:L25) -> 7349.1284 | M26: =SUM(M23:M25) -> 7480.1044 | O26: Total non-current liabilities | P26: =SUM(P23:P25) -> 6114.5675 | Q26: =SUM(Q23:Q25) -> 6189.0777 | R26: =SUM(R23:R25) -> 6273.2541 | S26: =SUM(S23:S25) -> 6368.3507 | T26: =SUM(T23:T25) -> 6475.7842 | V26: Total non-current liabilities | W26: =SUM(W23:W25) -> 1485.833 | X26: =SUM(X23:X25) -> 1562.2954 | Y26: =SUM(Y23:Y25) -> 1647.1167 | Z26: =SUM(Z23:Z25) -> 1741.2107 | AA26: =SUM(AA23:AA25) -> 1845.5911 | AC26: Total non-current liabilities | AD26: =SUM(AD23:AD25) -> 2750.6622 | AE26: =SUM(AE23:AE25) -> 2909.298 | AF26: =SUM(AF23:AF25) -> 3077.7088 | AG26: =SUM(AG23:AG25) -> 3256.4971 | AH26: =SUM(AH23:AH25) -> 3446.3022 | AJ26: Total non-current liabilities | AK26: =SUM(AK23:AK25) -> 1144.4997 | AL26: =SUM(AL23:AL25) -> 2544.8967 | AM26: =SUM(AM23:AM25) -> 5281.5712 | AN26: =SUM(AN23:AN25) -> 8261.3406 | AO26: =SUM(AO23:AO25) -> 11265.547
A27: Current Liabilities | H27: Current Liabilities | O27: Current Liabilities | V27: Current Liabilities | AC27: Current Liabilities | AJ27: Current Liabilities
A28: Short term borrowings | B28: 2 | C28: 2 | D28: 2 | E28: 2 | F28: 2 | H28: Short term borrowings | I28: 0 | J28: 0 | K28: 0 | L28: 0 | M28: 0 | O28: Short term borrowings | P28: ='Balance Sheet'!$W$48 -> 2956.84 | Q28: ='Balance Sheet'!$W$48 -> 2956.84 | R28: ='Balance Sheet'!$W$48 -> 2956.84 | S28: ='Balance Sheet'!$W$48 -> 2956.84 | T28: ='Balance Sheet'!$W$48 -> 2956.84 | V28: Short term borrowings | W28: ='Income Statement'!Z86 -> 4083.1577 | X28: ='Income Statement'!AA86 -> 4529.5307 | Y28: ='Income Statement'!AB86 -> 5024.7014 | Z28: ='Income Statement'!AC86 -> 5574.0044 | AA28: ='Income Statement'!AD86 -> 6183.3576 | AC28: Short term borrowings | AD28: ='Income Statement'!AH86 -> 2703.7345 | AE28: ='Income Statement'!AI86 -> 2870.3378 | AF28: ='Income Statement'!AJ86 -> 3047.2071 | AG28: ='Income Statement'!AK86 -> 3234.9751 | AH28: ='Income Statement'!AL86 -> 3434.3133 | AJ28: Short term borrowings | AK28: ='Income Statement'!AP86 -> 492.1441 | AL28: ='Income Statement'!AQ86 -> 533.63748 | AM28: ='Income Statement'!AR86 -> 578.62926 | AN28: ='Income Statement'!AS86 -> 627.41437 | AO28: ='Income Statement'!AT86 -> 680.31265
