Workbook

Sheet Company Profile
A1: COMPANY PROFILE
A3: Logo | B3: #VALUE! | C3: #VALUE! | D3: #VALUE! | E3: #VALUE! | F3: #VALUE! | G3: #VALUE!
A4: Name | B4: #VALUE! | C4: #VALUE! | D4: #VALUE! | E4: #VALUE! | F4: #VALUE! | G4: #VALUE!
A5: Official Name | B5: {=_FV(B4,"Official name",TRUE)} -> COAL INDIA LTD | C5: {=_FV(C4,"Official name",TRUE)} -> HINDUSTAN ZINC LIMITED | D5: {=_FV(D4,"Official name",TRUE)} -> JSW Steel Limited | E5: {=_FV(E4,"Official name",TRUE)} -> TATA STEEL LIMITED | F5: {=_FV(F4,"Official name",TRUE)} -> STEEL AUTHORITY OF INDIA LIMITED | G5: {=_FV(G4,"Official name",TRUE)} -> NMDC LIMITED
A6: Industry | B6: {=_FV(B4,"Industry")} -> Coal | C6: {=_FV(C4,"Industry")} -> Metals & Mining | D6: {=_FV(D4,"Industry")} -> Metals & Mining | E6: {=_FV(E4,"Industry")} -> Metals & Mining | F6: {=_FV(F4,"Industry")} -> Metals & Mining | G6: {=_FV(G4,"Industry")} -> Metals & Mining
A7: Share Price | B7: {=_FV(B4,"Price")} -> 381.3 | C7: {=_FV(C4,"Price")} -> 484.65 | D7: {=_FV(D4,"Price")} -> 1179.3 | E7: {=_FV(E4,"Price")} -> 181.48 | F7: {=_FV(F4,"Price")} -> 144.34 | G7: {=_FV(G4,"Price")} -> 75.08
A8: Change (%) | B8: {=_FV(B4,"Change (%)",TRUE)} -> 0.013691 | C8: {=_FV(C4,"Change (%)",TRUE)} -> 0.021283 | D8: {=_FV(D4,"Change (%)",TRUE)} -> 0.006486 | E8: {=_FV(E4,"Change (%)",TRUE)} -> 0.0006065 | F8: {=_FV(F4,"Change (%)",TRUE)} -> 0.023688 | G8: {=_FV(G4,"Change (%)",TRUE)} -> 0.011315
A9: Shares Outstanding | B9: {=_FV(B4,"Shares outstanding",TRUE)} -> 6162729000 | C9: {=_FV(C4,"Shares outstanding",TRUE)} -> 4225319000 | D9: {=_FV(D4,"Shares outstanding",TRUE)} -> 2442547000 | E9: {=_FV(E4,"Shares outstanding",TRUE)} -> 12485450000 | F9: {=_FV(F4,"Shares outstanding",TRUE)} -> 4130525000 | G9: {=_FV(G4,"Shares outstanding",TRUE)} -> 8791817000
A10: In Crores | B10: =B9/10000000 -> 616.2729 | C10: =C9/10000000 -> 422.5319 | D10: =D9/10000000 -> 244.2547 | E10: =E9/10000000 -> 1248.545 | F10: =F9/10000000 -> 413.0525 | G10: =G9/10000000 -> 879.1817
A11: Market Cap | B11: {=_FV(B4,"Market cap",TRUE)} -> 2317186000000 | C11: {=_FV(C4,"Market cap",TRUE)} -> 2004914000000 | D11: {=_FV(D4,"Market cap",TRUE)} -> 2861933000000 | E11: {=_FV(E4,"Market cap",TRUE)} -> 2264138000000 | F11: {=_FV(F4,"Market cap",TRUE)} -> 582404100000 | G11: {=_FV(G4,"Market cap",TRUE)} -> 652704600000
A12: In crores | B12: =B11/10000000 -> 231718.6 | C12: =C11/10000000 -> 200491.4 | D12: =D11/10000000 -> 286193.3 | E12: =E11/10000000 -> 226413.8 | F12: =F11/10000000 -> 58240.41 | G12: =G11/10000000 -> 65270.46
A13: Beta | B13: {=_FV(B4,"Beta")} -> 1.0568 | C13: {=_FV(C4,"Beta")} -> 0.4783 | D13: {=_FV(D4,"Beta")} -> 0.8371 | E13: {=_FV(E4,"Beta")} -> 1.2322 | F13: {=_FV(F4,"Beta")} -> 1.7377 | G13: {=_FV(G4,"Beta")} -> 1.0063
A14: Year of Corporation | B14: {=_FV(B4,"Year incorporated",TRUE)} -> 1973 | C14: {=_FV(C4,"Year incorporated",TRUE)} -> 1966 | D14: {=_FV(D4,"Year incorporated",TRUE)} -> 1994 | E14: {=_FV(E4,"Year incorporated",TRUE)} -> 1907 | F14: {=_FV(F4,"Year incorporated",TRUE)} -> 1973 | G14: {=_FV(G4,"Year incorporated",TRUE)} -> 1958

Sheet Balance Sheet
A1: BALANCE SHEET
A3: #VALUE! | I3: #VALUE! | Q3: #VALUE! | Y3: #VALUE! | AG3: #VALUE! | AO3: #VALUE!
A4: Particulars | B4: 2020 | C4: 2021 | D4: 2022 | E4: 2023 | F4: 2024 | G4: 2025 | I4: Particulars | J4: 2020 | K4: 2021 | L4: 2022 | M4: 2023 | N4: 2024 | O4: 2025 | Q4: Particulars | R4: 2020 | S4: 2021 | T4: 2022 | U4: 2023 | V4: 2024 | W4: 2025 | Y4: Particulars | Z4: 2020 | AA4: 2021 | AB4: 2022 | AC4: 2023 | AD4: 2024 | AE4: 2025 | AG4: Particulars | AH4: 2020 | AI4: 2021 | AJ4: 2022 | AK4: 2023 | AL4: 2024 | AM4: 2025 | AO4: Particulars | AP4: 2020 | AQ4: 2021 | AR4: 2022 | AS4: 2023 | AT4: 2024 | AU4: 2025
A5: Non current assets | I5: Non current assets | Q5: Non Current assets | Y5: Non current assets | AG5: Non current assets | AO5: Non current assets
A6: PPE | B6: 32302.35 | C6: 37753.65 | D6: 42697.79 | E6: 44447.97 | F6: 67900.41 | G6: 76639.85 | I6: PPE | J6: 16217 | K6: 16447 | L6: 17165 | M6: 17530 | N6: 17971 | O6: 18485 | Q6: PPE | R6: 57625 | S6: 58857 | T6: 92952 | U6: 97699 | V6: 105123 | W6: 116814 | Y6: PPE | Z6: 119503 | AA6: 119003.5 | AB6: 116166.46 | AC6: 118696.74 | AD6: 123538.14 | AE6: 125215.17 | AG6: PPE | AH6: 65384.47 | AI6: 64133.48 | AJ6: 68382.92 | AK6: 67110.71 | AL6: 65415.07 | AM6: 65061.37 | AO6: PPE | AP6: 3253.87 | AQ6: 3313.92 | AR6: 3024.61 | AS6: 2381.31 | AT6: 2477.88 | AU6: 2634.35
A7: Capital work in progress | B7: 8271.09 | C7: 10403.66 | D7: 12713.73 | E7: 15262.62 | F7: 14738.66 | G7: 15888.64 | I7: Capital work in progress | J7: 2489 | K7: 1922 | L7: 2075 | M7: 2237 | N7: 1696 | O7: 2606 | Q7: Capital work in progress | R7: 26857 | S7: 32433 | T7: 16756 | U7: 21921 | V7: 29216 | W7: 20478 | Y7: Capital work in progress | Z7: 18862.06 | AA7: 18128.74 | AB7: 21227.62 | AC7: 30307.9 | AD7: 33370.19 | AE7: 40601.88 | AG7: Capital work in progress | AH7: 8753.33 | AI7: 8880.63 | AJ7: 4709.95 | AK7: 4891.36 | AL7: 6140.57 | AM7: 7206.21 | AO7: Right of use assets | AP7: 7.08 | AQ7: 7.02 | AR7: 8.27 | AS7: 7.44 | AT7: 42.61 | AU7: 1542.95
A8: Exploration and Evaluation assets | B8: 4443.12 | C8: 4605.81 | D8: 3873.55 | E8: 4924.85 | F8: 5049.58 | G8: 3645.3 | I8: Intangible assets | J8: 252 | K8: 361 | L8: 231 | M8: 92 | N8: 109 | O8: 65 | Q8: Investment property | R8: 224 | S8: 259 | T8: 180 | U8: 86 | V8: 140 | W8: 163 | Y8: Right of use assets | Z8: 8549.78 | AA8: 9450.95 | AB8: 8337.7 | AC8: 9222.52 | AD8: 7585.89 | AE8: 8087.95 | AG8: Right of use assets | AH8: 2205.08 | AI8: 2054.21 | AJ8: 3834.1 | AK8: 4910.28 | AL8: 5521.19 | AM8: 6838.6 | AO8: Capital work in progress | AP8: 15500.22 | AQ8: 17106.51 | AR8: 1328.31 | AS8: 1991.55 | AT8: 3230.51 | AU8: 4737.48
A9: Intangible assets | B9: 38.14 | C9: 45.76 | D9: 105.62 | E9: 2588.11 | F9: 2718.21 | G9: 2579.89 | I9: Loans | J9: 13 | K9: 12 | L9: 0 | M9: 257 | N9: 71 | O9: 58 | Q9: Right of use assets | R9: 3471 | S9: 3816 | T9: 4715 | U9: 4699 | V9: 4477 | W9: 4837 | Y9: Goodwill on consolidation | Z9: 4054.53 | AA9: 4344.69 | AB9: 4311.2 | AC9: 5601.65 | AD9: 5745.3 | AE9: 5958.53 | AG9: Investment property | AH9: 1.12 | AI9: 1.09 | AJ9: 1.06 | AK9: 1.03 | AL9: 0.99 | AM9: 0.96 | AO9: Goodwill | AP9: 93.89 | AQ9: 93.89 | AR9: 93.89 | AS9: 93.89 | AT9: 93.89 | AU9: 93.89
A10: Intangible assets under development | B10: 57.16 | C10: 86.17 | D10: 183.41 | E10: 2359.35 | F10: 4221.64 | G10: 6496.27 | I10: Others | J10: 40 | K10: 43 | L10: 2 | M10: 0 | N10: 578 | O10: 823 | Q10: Goodwill | R10: 415 | S10: 336 | T10: 119 | U10: 128 | V10: 639 | W10: 643 | Y10: Other intangible assets | Z10: 2442.37 | AA10: 2976.04 | AB10: 4472.47 | AC10: 13100.55 | AD10: 11945.05 | AE10: 11652.41 | AG10: Intangible assets | AH10: 1443.61 | AI10: 1429.38 | AJ10: 1459.41 | AK10: 1521.04 | AL10: 1488.86 | AM10: 1425.71 | AO10: Other intangible assets | AP10: 454.66 | AQ10: 518.57 | AR10: 535.72 | AS10: 715.93 | AT10: 762.24 | AU10: 767.27
A11: Investments | B11: 1873.17 | C11: 2317.64 | D11: 2426.97 | E11: 3085.4 | F11: 3859.31 | G11: 4416.07 | I11: Deferred tax assets | J11: 1822 | K11: 1058 | L11: 56 | M11: 112 | N11: 131 | O11: 96 | Q11: Other intangible assets | R11: 350 | S11: 1649 | T11: 1914 | U11: 1840 | V11: 2082 | W11: 2009 | Y11: Intangible assets under development | Z11: 634.77 | AA11: 878.66 | AB11: 817.93 | AC11: 905.12 | AD11: 985.34 | AE11: 1020.47 | AG11: Investments accounted for using the equity method | AH11: 3107.27 | AI11: 3297.56 | AJ11: 3587.35 | AK11: 3967.5 | AL11: 4278.55 | AM11: 4603.25 | AO11: Intangible assets under development | AP11: 29.64 | AQ11: 51.42 | AR11: 5 | AS11: 6.49 | AT11: 4.14 | AU11: 0
A12: Loans | B12: 638.59 | C12: 136.27 | D12: 355.47 | E12: 372.21 | F12: 358.71 | G12: 389.86 | I12: Other non current assets | J12: 480 | K12: 431 | L12: 275 | M12: 290 | N12: 145 | O12: 140 | Q12: Intangible assets under development | R12: 334 | S12: 133 | T12: 149 | U12: 245 | V12: 460 | W12: 529 | Y12: Equity accounted investments | Z12: 2168.54 | AA12: 2475.66 | AB12: =1210+2961.65 -> 4171.65 | AC12: 3233.33 | AD12: 2947.15 | AE12: 2970.86 | AG12: Inventories | AH12: 0 | AI12: 4236.26 | AJ12: 4598.45 | AK12: 4635.29 | AL12: 4625.29 | AM12: 4591.88 | AO12: Investments | AP12: 910.1 | AQ12: 874.9 | AR12: 894.95 | AS12: 934.68 | AT12: 951.17 | AU12: 974.53
A13: Other financial assets | B13: 12293.05 | C13: 13020.45 | D13: 14498.79 | E13: 16300.29 | F13: 18010.69 | G13: 19668.15 | I13: Income tax assets | J13: 849 | K13: 885 | L13: 884 | M13: 145 | N13: 569 | O13: 591 | Q13: Investments in joint ventures | R13: 283 | S13: 2969 | T13: 367 | U13: 700 | V13: 1709 | W13: 3689 | Y13: Investments | Z13: 684.77 | AA13: 987.38 | AB13: 1653.78 | AC13: 1546.92 | AD13: 2579.19 | AE13: 2780.6 | AG13: Investments | AH13: 133.12 | AI13: 144.7 | AJ13: 169.57 | AK13: 217.75 | AL13: 310.47 | AM13: 372.33 | AO13: Loans | AP13: 224.38 | AQ13: 259.17 | AR13: =40.77+589.75 -> 630.52 | AS13: =62.62+2646.17 -> 2708.79 | AT13: 81.74 | AU13: 126.72
A14: Deferred tax assets | B14: 3618.01 | C14: 4059.43 | D14: 4128.42 | E14: 4177 | F14: 3141.29 | G14: 2694.71 | I14: Total non current assets | J14: =SUM(J6:J13) -> 22162 | K14: =SUM(K6:K13) -> 21159 | L14: =SUM(L6:L13) -> 20688 | M14: =SUM(M6:M13) -> 20663 | N14: =SUM(N6:N13) -> 21270 | O14: =SUM(O6:O13) -> 22864 | Q14: Investments | R14: 974 | S14: 5604 | T14: 4565 | U14: 4101 | V14: 5534 | W14: 5709 | Y14: Loans | Z14: 488.71 | AA14: 336.57 | AB14: 72.44 | AC14: 64.74 | AD14: 73.14 | AE14: 114.66 | AG14: Trade receivables | AH14: 0.92 | AI14: 0.9 | AJ14: 0 | AK14: 0 | AL14: 0 | AM14: 0 | AO14: Deferred tax assets | AP14: 397.07 | AQ14: 408.28 | AR14: 568.94 | AS14: 297.5 | AT14: 265.89 | AU14: 296.25
A15: Other non current assets | B15: 3105.25 | C15: 4625.99 | D15: 6407.94 | E15: 9606.15 | F15: =71.14+13719.26 -> 13790.4 | G15: 31586.21 | I15: Current assets | Q15: Loans | R15: 772 | S15: 1022 | T15: 125 | U15: 130 | V15: 120 | W15: 70 | Y15: Derivative assets | Z15: 279.64 | AA15: 162.66 | AB15: 318.15 | AC15: 403.4 | AD15: 265.86 | AE15: 0.05 | AG15: Loans | AH15: 665.28 | AI15: 756.99 | AJ15: 559.61 | AK15: 655.26 | AL15: 877.37 | AM15: 950.93 | AO15: Other non current assets | AP15: 3502.9 | AQ15: 3695.91 | AR15: 2103.89 | AS15: 3302.92 | AT15: =2609.89+3860.79 -> 6470.68 | AU15: =2269.38+4187.38 -> 6456.76
A16: Total non current assets | B16: =SUM(B6:B15) -> 66639.93 | C16: =SUM(C6:C15) -> 77054.83 | D16: =SUM(D6:D15) -> 87391.69 | E16: =SUM(E6:E15) -> 103123.95 | F16: =SUM(F6:F15) -> 133788.9 | G16: =SUM(G6:G15) -> 164004.95 | I16: Inventories | J16: 1835 | K16: 1425 | L16: 1953 | M16: 1862 | N16: 1926 | O16: 1889 | Q16: Derivative assets | R16: 0 | S16: 110 | T16: 24 | U16: 18 | V16: 88 | W16: 116 | Y16: Other financial assets | Z16: 588.93 | AA16: 214.93 | AB16: 442.64 | AC16: 510.88 | AD16: 1608.32 | AE16: 1662.34 | AG16: Other financial assets | AH16: 448.58 | AI16: 336.25 | AJ16: 237.57 | AK16: 370.73 | AL16: 444.96 | AM16: 623.13 | AO16: Total non current assets | AP16: =SUM(AP6:AP15) -> 24373.81 | AQ16: =SUM(AQ6:AQ15) -> 26329.59 | AR16: =SUM(AR6:AR15) -> 9194.1 | AS16: =SUM(AS6:AS15) -> 12440.5 | AT16: =SUM(AT6:AT15) -> 14380.75 | AU16: =SUM(AU6:AU15) -> 17630.2
A17: Current Assets | I17: Investments | J17: 20329 | K17: 12957 | L17: 15052 | M17: 9850 | N17: 9874 | O17: 9149 | Q17: Other financial assets | R17: 696 | S17: 2154 | T17: 4084 | U17: 4799 | V17: 6135 | W17: 6899 | Y17: Retirement benefit assets | Z17: 27278.45 | AA17: 20019.47 | AB17: 20397.96 | AC17: 6990.83 | AD17: 23.26 | AE17: 12.67 | AG17: Deferred tax assets | AH17: 2022.17 | AI17: 0 | AJ17: 0 | AK17: 0 | AL17: 0 | AM17: 0 | AO17: Current assets
A18: Inventories | B18: 6617.98 | C18: 8947.47 | D18: 7075.68 | E18: 8154.68 | F18: 10177.23 | G18: 12613.7 | I18: Trade receivables | J18: 379 | K18: 406 | L18: 716 | M18: 380 | N18: 155 | O18: 117 | Q18: Current tax assets | R18: 385 | S18: 275 | T18: 528 | U18: =631+539 -> 1170 | V18: 1338 | W18: =829+297 -> 1126 | Y18: Non current tax assets | Z18: 1725.67 | AA18: 1845.34 | AB18: 3785.01 | AC18: 4369.03 | AD18: 4754.11 | AE18: 3824.52 | AG18: Current tax assets | AH18: 153.31 | AI18: 217.56 | AJ18: 296.34 | AK18: 595.49 | AL18: 374.78 | AM18: 452.14 | AO18: Inventories | AP18: 723.51 | AQ18: 921.72 | AR18: 2125.21 | AS18: 2660.58 | AT18: 2766.95 | AU18: 2637.72
A19: Investments | B19: 99.7 | C19: 3632.59 | D19: 6493.63 | E19: 4054.01 | F19: 3251.1 | G19: 3175.26 | I19: Cash and cash equivalents | J19: 1878 | K19: 313 | L19: 1592 | M19: 59 | N19: 53 | O19: 96 | Q19: Other non current assets | R19: 2956 | S19: 2848 | T19: 4633 | U19: 5392 | V19: 6603 | W19: 6924 | Y19: Deferred tax assets | Z19: 1270.33 | AA19: 1578.02 | AB19: 3023.93 | AC19: 2625.96 | AD19: 4111.08 | AE19: 3936.22 | AG19: Other non current assets | AH19: 1483.92 | AI19: 1572.65 | AJ19: 3433.13 | AK19: 3610.03 | AL19: 3092.79 | AM19: 2355.95 | AO19: Trade receivables | AP19: 2223.71 | AQ19: 2139.89 | AR19: 2954.3 | AS19: 2656.02 | AT19: 3508.93 | AU19: 7744.61
A20: Trade receivables | B20: 14408.22 | C20: 19623.12 | D20: 11367.68 | E20: 13060.48 | F20: 13255.75 | G20: 12727.72 | I20: Bank balances | J20: 40 | K20: 9063 | L20: 4171 | M20: 1353 | N20: 122 | O20: 81 | Q20: Total non current assets | R20: =SUM(R6:R19) -> 95342 | S20: =SUM(S6:S19) -> 112465 | T20: =SUM(T6:T19) -> 131111 | U20: =SUM(U6:U19) -> 142928 | V20: =SUM(V6:V19) -> 163664 | W20: =SUM(W6:W19) -> 170006 | Y20: Other assets | Z20: 3154.2 | AA20: 2872.7 | AB20: 3690.05 | AC20: 3776.63 | AD20: 3343.23 | AE20: 3164.93 | AG20: Total non current assets | AH20: =SUM(AH6:AH19) -> 85802.18 | AI20: =SUM(AI6:AI19) -> 87061.66 | AJ20: =SUM(AJ6:AJ19) -> 91269.46 | AK20: =SUM(AK6:AK19) -> 92486.47 | AL20: =SUM(AL6:AL19) -> 92570.89 | AM20: =SUM(AM6:AM19) -> 94482.46 | AO20: Cash and cash equivalents | AP20: 105.57 | AQ20: 464.1 | AR20: 120.6 | AS20: 93 | AT20: 109.39 | AU20: 84.82
A21: Cash and cash equivalents | B21: 2791.1 | C21: 5234.54 | D21: 7063.48 | E21: 5665.38 | F21: 6008.71 | G21: 11160.68 | I21: Loans | J21: 2 | K21: 2 | L21: 2 | M21: 3 | N21: 1 | O21: 1 | Q21: Current Assets | Y21: Total non current assets | Z21: =SUM(Z6:Z20) -> 191685.75 | AA21: =SUM(AA6:AA20) -> 185275.31 | AB21: =SUM(AB6:AB20) -> 192888.99 | AC21: =SUM(AC6:AC20) -> 201356.2 | AD21: =SUM(AD6:AD20) -> 202875.25 | AE21: =SUM(AE6:AE20) -> 211003.26 | AG21: Current assets | AO21: Bank balances | AP21: 2331.89 | AQ21: 5397.72 | AR21: 7856.87 | AS21: 7004.75 | AT21: 12254.26 | AU21: 10003.73
A22: Bank Balances | B22: 25657.86 | C22: 12075.76 | D22: 22901.75 | E22: 34256.48 | F22: 24226.46 | G22: 23054.63 | I22: Others | J22: 21 | K22: 53 | L22: 33 | M22: 89 | N22: 59 | O22: 42 | Q22: Inventories | R22: 13773 | S22: 14249 | T22: 33787 | U22: 33135 | V22: 37815 | W22: 34956 | Y22: Current assets | AG22: Inventories | AH22: 23836.27 | AI22: 15334.17 | AJ22: 19568.28 | AK22: 27764.9 | AL22: 32721.45 | AM22: 29151.45 | AO22: Other financial assets | AP22: 365.4 | AQ22: 292.61 | AR22: 583.86 | AS22: 490.79 | AT22: =40.29+295.51 -> 335.8 | AU22: =53.91+292.19 -> 346.1
A23: Loans | B23: 502.65 | C23: 501.28 | D23: 0.32 | E23: 20.79 | F23: 21.59 | G23: 18.9 | I23: Other current assets | J23: 329 | K23: 349 | L23: 463 | M23: 336 | N23: 435 | O23: 251 | Q23: Investments | R23: 2 | S23: 8 | T23: 8 | U23: 5 | V23: 3 | W23: 5819 | Y23: Inventories | Z23: 31068.72 | AA23: 33276.38 | AB23: 48824.39 | AC23: 54415.33 | AD23: 49157.51 | AE23: 44589.94 | AG23: Investments | AH23: 0 | AI23: 0 | AJ23: 0 | AK23: 0 | AL23: 15.11 | AM23: 3.9 | AO23: Current tax assets | AP23: 429.24 | AQ23: 257.05 | AR23: 899.86 | AS23: 1121.82 | AT23: 830.69 | AU23: 682.37
A24: Other financial assets | B24: 2779.28 | C24: 2344.77 | D24: 2620.91 | E24: 2716.96 | F24: 2698.51 | G24: 2475.77 | I24: Total current assets | J24: =SUM(J16:J23) -> 24813 | K24: =SUM(K16:K23) -> 24568 | L24: =SUM(L16:L23) -> 23982 | M24: =SUM(M16:M23) -> 13932 | N24: =SUM(N16:N23) -> 12625 | O24: =SUM(O16:O23) -> 11626 | Q24: Trade receivables | R24: 4505 | S24: 4486 | T24: 7457 | U24: 7134 | V24: 7548 | W24: 8415 | Y24: Investments | Z24: 3431.87 | AA24: 7218.89 | AB24: 8524.42 | AC24: 3630.06 | AD24: 731.23 | AE24: 442.65 | AG24: Trade receivables | AH24: 8844.73 | AI24: 7153.7 | AJ24: 4770.85 | AK24: 5389.97 | AL24: 8355.37 | AM24: 7609.94 | AO24: Other current assets | AP24: 740.64 | AQ24: 1126.48 | AR24: 1176.73 | AS24: 1779.59 | AT24: =1468.39+4.89 -> 1473.28 | AU24: =1872.79+3.6 -> 1876.39
A25: Current tax assets | B25: 8950.27 | C25: 9398.38 | D25: 8423.19 | E25: 8719 | F25: 9064.13 | G25: 9822.62 | I25: Total Assets | J25: =J14+J24 -> 46975 | K25: =K14+K24 -> 45727 | L25: =L14+L24 -> 44670 | M25: =M14+M24 -> 34595 | N25: =N14+N24 -> 33895 | O25: =O14+O24 -> 34490 | Q25: Cash and cash equivalents | R25: 3966 | S25: 11943 | T25: 8808 | U25: 15424 | V25: 8030 | W25: 11655 | Y25: Trade receivables | Z25: 7884.91 | AA25: 9539.84 | AB25: 12246.43 | AC25: 8257.24 | AD25: 6263.53 | AE25: 5260.06 | AG25: Cash and cash equivalents | AH25: 190.54 | AI25: 518.28 | AJ25: 131.54 | AK25: 57.09 | AL25: 69.38 | AM25: 291.58 | AO25: Assets held for sale | AP25: 0.66 | AQ25: 0.63 | AR25: 0.81 | AS25: 0.66 | AT25: 0.98 | AU25: 0.94
A26: Other current assets | B26: 21880.49 | C26: 22966.95 | D26: 26899.35 | E26: 31434.93 | F26: 35179.88 | G26: 21144.14 | I26: EQUITY AND LIABILITIES | Q26: Bank balances | R26: 8037 | S26: 870 | T26: 8575 | U26: 5290 | V26: 4318 | W26: 1630 | Y26: Cash and cash equivalents | Z26: 7541.96 | AA26: 5532.08 | AB26: 15604.68 | AC26: 12129.9 | AD26: 7080.84 | AE26: 9604.96 | AG26: Bank balances | AH26: 254.48 | AI26: 278.07 | AJ26: 654.52 | AK26: 493.55 | AL26: 603.57 | AM26: 675.3 | AO26: Total current assets | AP26: =SUM(AP18:AP25) -> 6920.62 | AQ26: =SUM(AQ18:AQ25) -> 10600.2 | AR26: =SUM(AR18:AR25) -> 15718.24 | AS26: =SUM(AS18:AS25) -> 15807.21 | AT26: =SUM(AT18:AT25) -> 21280.28 | AU26: =SUM(AU18:AU25) -> 23376.68
A27: Total current assets | B27: =SUM(B18:B26) -> 83687.55 | C27: =SUM(C18:C26) -> 84724.86 | D27: =SUM(D18:D26) -> 92845.99 | E27: =SUM(E18:E26) -> 108082.71 | F27: =SUM(F18:F26) -> 103883.36 | G27: =SUM(G18:G26) -> 96193.42 | I27: Equity | Q27: Loans | R27: 742 | S27: 622 | T27: 759 | U27: 717 | V27: 4 | W27: 2 | Y27: Bank balances | Z27: 512.76 | AA27: 250.1 | AB27: 294.25 | AC27: 1227.36 | AD27: 1596.88 | AE27: 2042.02 | AG27: Loans | AH27: 49.67 | AI27: 50.47 | AJ27: 43.1 | AK27: 35.29 | AL27: 28.31 | AM27: 22.6 | AO27: Total assets | AP27: =AP16+AP26 -> 31294.43 | AQ27: =AQ16+AQ26 -> 36929.79 | AR27: =AR16+AR26 -> 24912.34 | AS27: =AS16+AS26 -> 28247.71 | AT27: =AT16+AT26 -> 35661.03 | AU27: =AU16+AU26 -> 41006.88
A28: Total Assets | B28: =B16+B27 -> 150327.48 | C28: =C16+C27 -> 161779.69 | D28: =D16+D27 -> 180237.68 | E28: =E16+E27 -> 211206.66 | F28: =F16+F27 -> 237672.26 | G28: =G16+G27 -> 260198.37 | I28: Equity share capital | J28: 845 | K28: 845 | L28: 845 | M28: 845 | N28: 845 | O28: 845 | Q28: Derivative assets | R28: 294 | S28: 102 | T28: 426 | U28: 460 | V28: 173 | W28: 284 | Y28: Loans | Z28: 215.68 | AA28: 64.72 | AB28: 5.84 | AC28: 1.84 | AD28: 1.6 | AE28: 4.98 | AG28: Other financial assets | AH28: 2189.25 | AI28: 2478.32 | AJ28: 1338.45 | AK28: 1262.61 | AL28: 1369.07 | AM28: 1221.76 | AO28: EQUITY AND LIABILITIES
A29: EQUITY AND LIABILITIES | I29: Other equity | J29: 39465 | K29: 31468 | L29: 33436 | M29: 12087 | N29: 14350 | O29: 12481 | Q29: Other financial assets | R29: 2858 | S29: 1467 | T29: 1289 | U29: 1701 | V29: 1752 | W29: 1247 | Y29: Derivative assets | Z29: 1486.06 | AA29: 498.79 | AB29: 1172.74 | AC29: 561.46 | AD29: 201.33 | AE29: 370.5 | AG29: Other current assets | AH29: 5733.32 | AI29: 6354.19 | AJ29: 2318.92 | AK29: 2961.93 | AL29: 433.11 | AM29: 0 | AO29: Equity
A30: Equity | I30: Total Equity | J30: =J28+J29 -> 40310 | K30: =K28+K29 -> 32313 | L30: =L28+L29 -> 34281 | M30: =M28+M29 -> 12932 | N30: =N28+N29 -> 15195 | O30: =O28+O29 -> 13326 | Q30: Current tax assets | R30: 6 | S30: 6 | T30: 7 | U30: 3 | V30: 5 | W30: 15 | Y30: Other financial assets | Z30: 446.42 | AA30: 1420.97 | AB30: 2011.62 | AC30: 1435.51 | AD30: 1172.58 | AE30: 1456.14 | AG30: Assets classified for sale | AH30: 27.2 | AI30: 17.01 | AJ30: 14 | AK30: 29.28 | AL30: 4542.32 | AM30: 2911.95 | AO30: Equity share capital | AP30: 306.19 | AQ30: 293.07 | AR30: 293.07 | AS30: 293.07 | AT30: 293.07 | AU30: 879.18
A31: Equity share capital | B31: 6162.73 | C31: 6162.73 | D31: 6162.73 | E31: 6162.73 | F31: 6162.73 | G31: 6162.73 | I31: Non current liabilities | Q31: Other current assets | R31: 2286 | S31: 2091 | T31: 4250 | U31: 4277 | V31: 4885 | W31: 6684 | Y31: Retirement benefit assets | Z31: 0 | AA31: 0.42 | AB31: 1.25 | AC31: 0 | AD31: 0 | AE31: 2.33 | AG31: Total current assets | AH31: =SUM(AH22:AH30) -> 41125.46 | AI31: =SUM(AI22:AI30) -> 32184.21 | AJ31: =SUM(AJ22:AJ30) -> 28839.66 | AK31: =SUM(AK22:AK30) -> 37994.62 | AL31: =SUM(AL22:AL30) -> 48137.69 | AM31: =SUM(AM22:AM30) -> 41888.48 | AO31: Other equity | AP31: 27366.88 | AQ31: 29590.98 | AR31: 17725.18 | AS31: 22327.76 | AT31: 25362.83 | AU31: 28816.59
A32: Other equity | B32: 25994.19 | C32: 30354.63 | D32: 36980.31 | E32: 51082.16 | F32: 76567.05 | G32: 92942.19 | I32: Borrowings | J32: 0 | K32: 4312 | L32: 2111 | M32: 1500 | N32: 4246 | O32: 5990 | Q32: Assets classified as held for sale | R32: 9 | S32: 8 | T32: 8 | U32: 4 | V32: 1 | W32: 29 | Y32: Current tax assets | Z32: 143.2 | AA32: 156.74 | AB32: 61.63 | AC32: 117.69 | AD32: 79.68 | AE32: 79.52 | AG32: Total assets | AH32: =AH20+AH31 -> 126927.64 | AI32: =AI20+AI31 -> 119245.87 | AJ32: =AJ20+AJ31 -> 120109.12 | AK32: =AK20+AK31 -> 130481.09 | AL32: =AL20+AL31 -> 140708.58 | AM32: =AM20+AM31 -> 136370.94 | AO32: Non controlling interest | AP32: 8.05 | AQ32: 13.54 | AR32: 13.45 | AS32: 14.23 | AT32: 17.01 | AU32: 11.41
A33: Non controlling interest | B33: 394.08 | C33: 441.08 | D33: 673.79 | E33: 770.68 | F33: 852.12 | G33: 845.77 | I33: Lease Liabilities | J33: 0 | K33: 0 | L33: 6 | M33: 19 | N33: 178 | O33: 178 | Q33: Total current assets | R33: =SUM(R22:R32) -> 36478 | S33: =SUM(S22:S32) -> 35852 | T33: =SUM(T22:T32) -> 65374 | U33: =SUM(U22:U32) -> 68150 | V33: =SUM(V22:V32) -> 64534 | W33: =SUM(W22:W32) -> 70736 | Y33: Other assets | Z33: 3177.69 | AA33: 2153.44 | AB33: 3508.82 | AC33: 4829.75 | AD33: 4218.41 | AE33: 4538.44 | AG33: EQUITY AND LIABILITES | AO33: Total equity | AP33: =SUM(AP30:AP32) -> 27681.12 | AQ33: =SUM(AQ30:AQ32) -> 29897.59 | AR33: =SUM(AR30:AR32) -> 18031.7 | AS33: =SUM(AS30:AS32) -> 22635.06 | AT33: =SUM(AT30:AT32) -> 25672.91 | AU33: =SUM(AU30:AU32) -> 29707.18
A34: Total Equity | B34: =SUM(B31:B33) -> 32551 | C34: =SUM(C31:C33) -> 36958.44 | D34: =SUM(D31:D33) -> 43816.83 | E34: =SUM(E31:E33) -> 58015.57 | F34: =SUM(F31:F33) -> 83581.9 | G34: =SUM(G31:G33) -> 99950.69 | I34: Other financial liabilities | J34: 22 | K34: 8 | L34: 1024 | M34: 1060 | N34: =925 -> 925 | O34: =342+963 -> 1305 | Q34: Total assets | R34: =R20+R33 -> 131820 | S34: =S20+S33 -> 148317 | T34: =T20+T33 -> 196485 | U34: =U20+U33 -> 211078 | V34: =V20+V33 -> 228198 | W34: =W20+W33 -> 240742 | Y34: Total current assets | Z34: =SUM(Z23:Z33) -> 55909.27 | AA34: =SUM(AA23:AA33) -> 60112.37 | AB34: =SUM(AB23:AB33) -> 92256.07 | AC34: =SUM(AC23:AC33) -> 86606.14 | AD34: =SUM(AD23:AD33) -> 70503.59 | AE34: =SUM(AE23:AE33) -> 68391.54 | AG34: Equity | AO34: Non current liabilities
A35: Non current liabilities | I35: Other non current liabilities | J35: 1068 | K35: 1036 | L35: 212 | M35: 189 | N35: 199 | O35: 200 | Q35: EQUITY AND LIABILITIES | Y35: Assets held for sale | Z35: 2823.45 | AA35: 99.53 | AB35: 300.54 | AC35: 59.4 | AD35: 44.66 | AE35: 0 | AG35: Equity share capital | AH35: 4130.53 | AI35: 4130.53 | AJ35: 4130.53 | AK35: 4130.53 | AL35: 4130.53 | AM35: 4130.53 | AO35: Borrowings | AP35: 0 | AQ35: 546.43 | AR35: 0 | AS35: 0 | AT35: 0 | AU35: 0
A36: Borrowings | B36: 1993.38 | C36: 2688.1 | D36: 3301.78 | E36: 4106.25 | F36: 5617.2 | G36: 7385.75 | I36: Provisions | J36: 162 | K36: 182 | L36: 942 | M36: 2314 | N36: 2311 | O36: 2292 | Q36: Equity | Y36: Total assets | Z36: =Z21+Z34+Z35 -> 250418.47 | AA36: =AA21+AA34+AA35 -> 245487.21 | AB36: =AB21+AB34+AB35 -> 285445.6 | AC36: =AC21+AC34+AC35 -> 288021.74 | AD36: =AD21+AD34+AD35 -> 273423.5 | AE36: =AE21+AE34+AE35 -> 279394.8 | AG36: Other equity | AH36: 37379.7 | AI36: 41275.69 | AJ36: 50081.15 | AK36: 50616.14 | AL36: 52970.69 | AM36: 54775.08 | AO36: Lease liabilities | AP36: 0 | AQ36: 0 | AR36: 5.85 | AS36: 5.02 | AT36: 1.76 | AU36: 1.97
A37: Lease liabilities | B37: 0 | C37: 0 | D37: 159.66 | E37: 157 | F37: 156.29 | G37: 146.46 | I37: Total non current liabilities | J37: =SUM(J32:J36) -> 1252 | K37: =SUM(K32:K36) -> 5538 | L37: =SUM(L32:L36) -> 4295 | M37: =SUM(M32:M36) -> 5082 | N37: =SUM(N32:N36) -> 7859 | O37: =SUM(O32:O36) -> 9965 | Q37: Equity share capital | R37: 301 | S37: 302 | T37: 301 | U37: 301 | V37: 305 | W37: 305 | Y37: EQUITY AND LIABILITES | AG37: Non controlling interest | AH37: 0.01 | AI37: 0.01 | AJ37: 0.01 | AK37: 0.01 | AL37: 0.01 | AM37: -0.01 | AO37: Other financial liabilities | AP37: 5.83 | AQ37: 4.7 | AR37: 150.28 | AS37: 150.28 | AT37: 150.28 | AU37: 150.28
A38: Other financial liabilities | B38: 802.51 | C38: 942.3 | D38: 2477.84 | E38: 3207.57 | F38: 3469.26 | G38: 3427.31 | I38: Current Liabilities | Q38: Other equity | R38: 36298 | S38: 46462 | T38: 66996 | U38: 65394 | V38: 77364 | W38: 79191 | Y38: Equity | AG38: Total equity | AH38: =SUM(AH35:AH37) -> 41510.24 | AI38: =SUM(AI35:AI37) -> 45406.23 | AJ38: =SUM(AJ35:AJ37) -> 54211.69 | AK38: =SUM(AK35:AK37) -> 54746.68 | AL38: =SUM(AL35:AL37) -> 57101.23 | AM38: =SUM(AM35:AM37) -> 58905.6 | AO38: Provisions | AP38: 827.96 | AQ38: 945.41 | AR38: 1092.46 | AS38: 1255.99 | AT38: 1431.26 | AU38: 1479.09
A39: Provisions | B39: 60223.45 | C39: 63178.61 | D39: 65944 | E39: 68827.95 | F39: 74311.01 | G39: 74531.52 | I39: Borrowings | J39: 611 | K39: 2161 | L39: 712 | M39: 10341 | N39: 4210 | O39: 4661 | Q39: Non controlling interests | R39: -575 | S39: -619 | T39: 1238 | U39: 1344 | V39: 2107 | W39: 2170 | Y39: Equity share capital | Z39: 1144.95 | AA39: 1197.61 | AB39: 1221.21 | AC39: 1221.24 | AD39: 1247.44 | AE39: 1247.44 | AG39: Non current liabilities | AO39: Total non current liabilities | AP39: =SUM(AP35:AP38) -> 833.79 | AQ39: =SUM(AQ35:AQ38) -> 1496.54 | AR39: =SUM(AR35:AR38) -> 1248.59 | AS39: =SUM(AS35:AS38) -> 1411.29 | AT39: =SUM(AT35:AT38) -> 1583.3 | AU39: =SUM(AU35:AU38) -> 1631.34
A40: Deferred tax liabilities | B40: 307.04 | C40: 722.07 | D40: 801.35 | E40: 1330.68 | F40: 1822.16 | G40: 1831.9 | I40: Lease Liabilities | J40: 0 | K40: 0 | L40: 15 | M40: 21 | N40: 88 | O40: 138 | Q40: Total equity | R40: =SUM(R37:R39) -> 36024 | S40: =SUM(S37:S39) -> 46145 | T40: =SUM(T37:T39) -> 68535 | U40: =SUM(U37:U39) -> 67039 | V40: =SUM(V37:V39) -> 79776 | W40: =SUM(W37:W39) -> 81666 | Y40: Hybrid perpetual securities | Z40: 2275 | AA40: 775 | AB40: 0 | AC40: 0 | AD40: 0 | AE40: 0 | AG40: Borrowings | AH40: 34560.03 | AI40: 19726.03 | AJ40: 8135.81 | AK40: 6112.58 | AL40: 9568.21 | AM40: 10100.95 | AO40: Current liabilities
A41: Other non current liabilities | B41: 5381.81 | C41: 5647.3 | D41: 6527.71 | E41: 6826.99 | F41: 7441.9 | G41: 8183.09 | I41: Operational buyers credit | J41: 76 | K41: 0 | L41: 280 | M41: 307 | N41: 399 | O41: 569 | Q41: Non current liabilities | Y41: Other equity | Z41: 70156.35 | AA41: 72266.16 | AB41: 113221.83 | AC41: 101860.86 | AD41: 90788.32 | AE41: 89922.19 | AG41: Total outstanding dues of micro and small enterprises | AH41: 0 | AI41: 0 | AJ41: 0 | AK41: 0 | AL41: 0 | AM41: 0 | AO41: Borrowings | AP41: 565.57 | AQ41: 1448.04 | AR41: 1792.5 | AS41: 415.98 | AT41: 3356.54 | AU41: 3770.45
...

Sheet Income Statement
A1: INCOME STATEMENT
B3: #VALUE! | J3: #VALUE! | R3: #VALUE! | Z3: #VALUE! | AH3: #VALUE! | AP3: #VALUE!
A4: Particulars | B4: 2020 | C4: 2021 | D4: 2022 | E4: 2023 | F4: 2024 | G4: 2025 | I4: Particulars | J4: 2020 | K4: 2021 | L4: 2022 | M4: 2023 | N4: 2024 | O4: 2025 | Q4: Particulars | R4: 2020 | S4: 2021 | T4: 2022 | U4: 2023 | V4: 2024 | W4: 2025 | Y4: Particulars | Z4: 2020 | AA4: 2021 | AB4: 2022 | AC4: 2023 | AD4: 2024 | AE4: 2025 | AG4: Particulars | AH4: 2020 | AI4: 2021 | AJ4: 2022 | AK4: 2023 | AL4: 2024 | AM4: 2025 | AO4: Particulars | AP4: 2020 | AQ4: 2021 | AR4: 2022 | AS4: 2023 | AT4: 2024 | AU4: 2025
A5: INCOME | I5: INCOME | Q5: INCOME | Y5: INCOME | AG5: INCOME | AO5: INCOME
A6: Revenue from Operations | B6: 89373.34 | C6: 82710.32 | D6: 100562.57 | E6: 127627.47 | F6: 130325.65 | G6: 126956.76 | I6: Revenue from operations | J6: 18332 | K6: 22071 | L6: 28790 | M6: 33272 | N6: 28082 | O6: 33041 | Q6: Revenue from operations | R6: 72610 | S6: 79839 | T6: 146371 | U6: 165960 | V6: 175006 | W6: 168824 | Y6: Revenue from operations | Z6: 148971 | AA6: 156294.18 | AB6: 243959.17 | AC6: 243352.69 | AD6: 229170.78 | AE6: 218542.51 | AG6: Revenue from operations | AH6: 61664.16 | AI6: 69113.61 | AJ6: 103476.84 | AK6: 104447.72 | AL6: 105378.33 | AM6: 102479.06 | AO6: Revenue from operations | AP6: 11699.22 | AQ6: 15370.06 | AR6: 25964.79 | AS6: 17666.88 | AT6: 21307.85 | AU6: 23905.52
A7: Other operating income | B7: 6707 | C7: 7315.69 | D7: 9152.85 | E7: 10624.44 | F7: 14436.77 | G7: 16412.16 | I7: Other operating income | J7: 229 | K7: 558 | L7: 650 | M7: 826 | N7: 850 | O7: 1042 | Q7: Fees for assignment of contract | R7: 250 | S7: 0 | T7: 0 | U7: 0 | V7: 0 | W7: 0 | Y7: Other income | Z7: 1821.99 | AA7: 895.6 | AB7: 784.89 | AC7: 1037.48 | AD7: 1808.85 | AE7: 1540.53 | AG7: Other income | AH7: 905.79 | AI7: 860.67 | AJ7: 858.55 | AK7: 950.36 | AL7: 1066.96 | AM7: 875.03 | AO7: Other income | AP7: 514.36 | AQ7: 351.6 | AR7: 718.52 | AS7: 768.22 | AT7: 1370.68 | AU7: 1593.32
A8: Other income | B8: 6444.96 | C8: 3792.38 | D8: 3881.41 | E8: 6550.66 | F8: 7969.08 | G8: 9470.06 | I8: Other income | J8: 1934 | K8: 1819 | L8: 1216 | M8: 1379 | N8: 1074 | O8: 983 | Q8: Government grant income | R8: 466 | S8: 0 | T8: 0 | U8: 0 | V8: 0 | W8: 0 | Y8: Total income | Z8: =SUM(Z6:Z7) -> 150792.99 | AA8: =SUM(AA6:AA7) -> 157189.78 | AB8: =SUM(AB6:AB7) -> 244744.06 | AC8: =SUM(AC6:AC7) -> 244390.17 | AD8: =SUM(AD6:AD7) -> 230979.63 | AE8: =SUM(AE6:AE7) -> 220083.04 | AG8: Total income | AH8: =SUM(AH6:AH7) -> 62569.95 | AI8: =SUM(AI6:AI7) -> 69974.28 | AJ8: =SUM(AJ6:AJ7) -> 104335.39 | AK8: =SUM(AK6:AK7) -> 105398.08 | AL8: =SUM(AL6:AL7) -> 106445.29 | AM8: =SUM(AM6:AM7) -> 103354.09 | AO8: Total income | AP8: =SUM(AP6:AP7) -> 12213.58 | AQ8: =SUM(AQ6:AQ7) -> 15721.66 | AR8: =SUM(AR6:AR7) -> 26683.31 | AS8: =SUM(AS6:AS7) -> 18435.1 | AT8: =SUM(AT6:AT7) -> 22678.53 | AU8: =SUM(AU6:AU7) -> 25498.84
A9: Total income | B9: =SUM(B6:B8) -> 102525.3 | C9: =SUM(C6:C8) -> 93818.39 | D9: =SUM(D6:D8) -> 113596.83 | E9: =SUM(E6:E8) -> 144802.57 | F9: =SUM(F6:F8) -> 152731.5 | G9: =SUM(G6:G8) -> 152838.98 | I9: Total income | J9: =SUM(J6:J8) -> 20495 | K9: =SUM(K6:K8) -> 24448 | L9: =SUM(L6:L8) -> 30656 | M9: =SUM(M6:M8) -> 35477 | N9: =SUM(N6:N8) -> 30006 | O9: =SUM(O6:O8) -> 35066 | Q9: Total revenue from operations | R9: =SUM(R6:R8) -> 73326 | S9: =SUM(S6:S8) -> 79839 | T9: =SUM(T6:T8) -> 146371 | U9: =SUM(U6:U8) -> 165960 | V9: =SUM(V6:V8) -> 175006 | W9: =SUM(W6:W8) -> 168824 | Y9: EXPENSES | AG9: EXPENSES | AO9: EXPENSES
A10: EXPENSES | I10: EXPENSES | Q10: Other income | R10: 546 | S10: 592 | T10: 1531 | U10: 1030 | V10: 1004 | W10: 694 | Y10: Cost of materials consumed | Z10: 53592.83 | AA10: 46187.96 | AB10: 75763.7 | AC10: 101483.08 | AD10: 82533.6 | AE10: 77079.62 | AG10: Cost of materials consumed | AH10: 29371.73 | AI10: 23213.59 | AJ10: 42890.12 | AK10: 62179.91 | AL10: 57709.26 | AM10: 49051.46 | AO10: Cosumption of raw materials | AP10: 36.48 | AQ10: 42.01 | AR10: 106.95 | AS10: 70.59 | AT10: 20.97 | AU10: 12.42
A11: Cost of materials consumed | B11: 7065.46 | C11: 7585.35 | D11: 9443.51 | E11: 13557 | F11: 11580.04 | G11: 11246.95 | I11: Change in inventories of finished goods | J11: -291 | K11: 239 | L11: -278 | M11: -143 | N11: -157 | O11: -64 | Q11: Total income | R11: =R9+R10 -> 73872 | S11: =S9+S10 -> 80431 | T11: =T9+T10 -> 147902 | U11: =U9+U10 -> 166990 | V11: =V9+V10 -> 176010 | W11: =W9+W10 -> 169518 | Y11: Purchase of stock in trade | Z11: 10504.2 | AA11: 9235.42 | AB11: 15312.91 | AC11: 15114.11 | AD11: 14972.79 | AE11: 18017.68 | AG11: Purchase of stock in trade | AH11: 0 | AI11: 0 | AJ11: 0 | AK11: 0 | AL11: 0 | AM11: 1856.98 | AO11: Consumption of stores and spares | AP11: 243.15 | AQ11: 257.41 | AR11: 396.53 | AS11: 556.34 | AT11: 652.72 | AU11: 720.84
A12: Purchase of stock in trade | B12: 60.8 | C12: 282.34 | D12: 103.56 | E12: 469.74 | F12: 0 | G12: 0 | I12: Employee benefit expenses | J12: 689 | K12: 760 | L12: 718 | M12: 845 | N12: 828 | O12: 886 | Q12: EXPENSES | Y12: Changes in inventories of finished goods | Z12: -490.05 | AA12: 1516.77 | AB12: -7597.87 | AC12: -3358.89 | AD12: 4409.35 | AE12: -96.65 | AG12: Changes in inventories of finished goods | AH12: -5577.63 | AI12: 4276.64 | AJ12: -279.54 | AK12: -5154.71 | AL12: -3354.77 | AM12: 88.75 | AO12: Purchase of stock in trade | AP12: 0 | AQ12: 0 | AR12: 0 | AS12: 0 | AT12: 0 | AU12: 197.09
A13: Changes in inventories of finished goods | B13: -1042.5 | C13: -2351.26 | D13: 2308.49 | E13: -678.12 | F13: -1521.5 | G13: -2303.35 | I13: Depreciation/Amortisation | J13: 2279 | K13: 2531 | L13: 2917 | M13: 3264 | N13: 3468 | O13: 3640 | Q13: Cost of materials consumed | R13: 38865 | S13: 32623 | T13: 62337 | U13: 94456 | V13: 93590 | W13: 88324 | Y13: Employee benefit expense | Z13: 19152.23 | AA13: 19908.81 | AB13: 23264.1 | AC13: 22419.32 | AD13: 24509.58 | AE13: 24888.99 | AG13: Employee benefit expenses | AH13: 8797.32 | AI13: 10461.05 | AJ13: 12861.99 | AK13: 12071.53 | AL13: 11765.72 | AM13: 11674.95 | AO13: Changes in inventories of finished goods, WIP | AP13: -53.83 | AQ13: -161.81 | AR13: -1159.39 | AS13: -496.6 | AT13: -93.36 | AU13: 99.31
A14: Employee benefit expense | B14: 39404.18 | C14: 38697.72 | D14: 40473.21 | E14: 49409.16 | F14: 48782.58 | G14: 46249.13 | I14: Power and fuel | J14: 1704 | K14: 1732 | L14: 2452 | M14: 3711 | N14: 2843 | O14: 2702 | Q14: Purchase of stock in trade | R14: 135 | S14: 233 | T14: 534 | U14: 1514 | V14: 1164 | W14: 845 | Y14: Finance costs | Z14: 7580.72 | AA14: 7606.71 | AB14: 5462.2 | AC14: 6298.7 | AD14: 7507.57 | AE14: 7340.95 | AG14: Finance costs | AH14: 3486.76 | AI14: 2817.15 | AJ14: 1697.89 | AK14: 2037.47 | AL14: 2473.86 | AM14: 2793.17 | AO14: Employee benefit expenses | AP14: 1049.36 | AQ14: 1085.24 | AR14: 1337.07 | AS14: 1530.57 | AT14: 1625.54 | AU14: 1795.04
A15: Power expense | B15: 2467.22 | C15: 2538.19 | D15: 2638.46 | E15: 2759.89 | F15: 0 | G15: 0 | I15: Minority royalty | J15: 2353 | K15: 2759 | L15: 3667 | M15: 4068 | N15: 3517 | O15: 4103 | Q15: Changes in inventories of SIT, WIP | R15: -270 | S15: -348 | T15: -3601 | U15: -2636 | V15: -3087 | W15: 829 | Y15: Depreciation/Amortisation | Z15: 8707.67 | AA15: 9233.64 | AB15: 9100.87 | AC15: 9335.2 | AD15: 9882.16 | AE15: 10421.33 | AG15: Depreciation/Amortisation | AH15: 3755.73 | AI15: 4102.78 | AJ15: 4275.02 | AK15: 4963.54 | AL15: 5278.37 | AM15: 5650.68 | AO15: Power and electricity | AP15: 114.73 | AQ15: 110.82 | AR15: 122.54 | AS15: 144.1 | AT15: 168.1 | AU15: 163.13
A16: CSR Expense | B16: 587.84 | C16: 449.31 | D16: 548.98 | E16: 586.5 | F16: 0 | G16: 0 | I16: Finance costs | J16: 112 | K16: 386 | L16: 290 | M16: 333 | N16: 955 | O16: 1095 | Q16: Mining premium and royalties | R16: 651 | S16: 6972 | T16: 13894 | U16: 7457 | V16: 10011 | W16: 9144 | Y16: Other expenses | Z16: 50702.93 | AA16: 50706.65 | AB16: 76616.28 | AC16: 80518.87 | AD16: 82354.89 | AE16: 74699.99 | AG16: Other expenses | AH16: 18857.02 | AI16: 18423.59 | AJ16: 26662.75 | AK16: 27311.56 | AL16: 28108.81 | AM16: 29160.71 | AO16: Repairs and maintenance | AP16: 156.95 | AQ16: 136.02 | AR16: 192.23 | AS16: 210.01 | AT16: 246.34 | AU16: 254.8
A17: Repairs | B17: 1410.93 | C17: 1418.8 | D17: 1632.33 | E17: 1772.28 | F17: 0 | G17: 0 | I17: Other expenses | J17: 5259 | K17: 5467 | L17: 6656 | M17: 8111 | N17: 8245 | O17: 9068 | Q17: Employee benefit expenses | R17: 2839 | S17: 2506 | T17: 3493 | U17: 3915 | V17: 4591 | W17: 4798 | Y17: Less: Expenditure | Z17: -2318 | AA17: -1765.69 | AB17: -2889.9 | AC17: -5123.96 | AD17: -1915.33 | AE17: -1345.57 | AG17: Total expenses | AH17: =SUM(AH10:AH16) -> 58690.93 | AI17: =SUM(AI10:AI16) -> 63294.8 | AJ17: =SUM(AJ10:AJ16) -> 88108.23 | AK17: =SUM(AK10:AK16) -> 103409.3 | AL17: =SUM(AL10:AL16) -> 101981.25 | AM17: =SUM(AM10:AM16) -> 100276.7 | AO17: Royalty & other levies | AP17: 2096.29 | AQ17: 2969.38 | AR17: 9986.76 | AS17: 7725.04 | AT17: 9214.13 | AU17: 9709.17
A18: Contractual expense | B18: 13911.55 | C18: 16023.08 | D18: 18875.16 | E18: 23289.21 | F18: 27439.88 | G18: 31811.5 | I18: Total expenses | J18: =SUM(J11:J17) -> 12105 | K18: =SUM(K11:K17) -> 13874 | L18: =SUM(L11:L17) -> 16422 | M18: =SUM(M11:M17) -> 20189 | N18: =SUM(N11:N17) -> 19699 | O18: =SUM(O11:O17) -> 21430 | Q18: Finance costs | R18: 4265 | S18: 3957 | T18: 4968 | U18: 6902 | V18: 8105 | W18: 8412 | Y18: Total expenses | Z18: =SUM(Z10:Z17) -> 147432.53 | AA18: =SUM(AA10:AA17) -> 142630.27 | AB18: =SUM(AB10:AB17) -> 195032.29 | AC18: =SUM(AC10:AC17) -> 226686.43 | AD18: =SUM(AD10:AD17) -> 224254.61 | AE18: =SUM(AE10:AE17) -> 211006.34 | AG18: Profit before exceptional items, share of profits | AH18: =AH8-AH17 -> 3879.02 | AI18: =AI8-AI17 -> 6679.48 | AJ18: =AJ8-AJ17 -> 16227.16 | AK18: =AK8-AK17 -> 1988.78 | AL18: =AL8-AL17 -> 4464.04 | AM18: =AM8-AM17 -> 3077.39 | AO18: Selling expenses | AP18: 702.43 | AQ18: 695.27 | AR18: 227.74 | AS18: 263 | AT18: 338.47 | AU18: 538.94
A19: Finance costs | B19: 502.92 | C19: 644.69 | D19: 541.49 | E19: 684.31 | F19: 819.37 | G19: 883.65 | I19: Exceptional items | J19: 0 | K19: 0 | L19: -134 | M19: 0 | N19: 0 | O19: -83 | Q19: Depreciation/Amortisation | R19: 4246 | S19: 4679 | T19: 6001 | U19: 7474 | V19: 8172 | W19: 9309 | Y19: Share of profit/loss | Z19: 187.97 | AA19: 327.34 | AB19: 649.16 | AC19: 418.12 | AD19: -57.98 | AE19: 190.81 | AG19: Share of profit | AH19: 194.32 | AI19: 467.74 | AJ19: 418.12 | AK19: 645.67 | AL19: 438.61 | AM19: 486.78 | AO19: Finance costs | AP19: 9.88 | AQ19: 16.81 | AR19: 39.06 | AS19: 75.23 | AT19: 78.24 | AU19: 177.68
A20: Depreciation/Amortisation/Impairment | B20: 3450.83 | C20: 3708.92 | D20: 4428.67 | E20: 4675.27 | F20: 6735.42 | G20: 9145.49 | I20: Profit before tax | J20: =J9-J18+J19 -> 8390 | K20: =K9-K18+K19 -> 10574 | L20: =L9-L18+L19 -> 14100 | M20: =M9-M18+M19 -> 15288 | N20: =N9-N18+N19 -> 10307 | O20: =O9-O18+O19 -> 13553 | Q20: Other expenses | R20: 19233 | S20: 17712 | T20: 30707 | U20: 42707 | V20: 40501 | W20: 41980 | Y20: Profit/Loss before exceptional items and tax | Z20: =Z8-Z18+Z19 -> 3548.43 | AA20: =AA8-AA18+AA19 -> 14886.85 | AB20: =AB8-AB18+AB19 -> 50360.93 | AC20: =AC8-AC18+AC19 -> 18121.86 | AD20: =AD8-AD18+AD19 -> 6667.04 | AE20: =AE8-AE18+AE19 -> 9267.51 | AG20: Profit before exceptional items and tax | AH20: =AH18+AH19 -> 4073.34 | AI20: =AI18+AI19 -> 7147.22 | AJ20: =AJ18+AJ19 -> 16645.28 | AK20: =AK18+AK19 -> 2634.45 | AL20: =AL18+AL19 -> 4902.65 | AM20: =AM18+AM19 -> 3564.17 | AO20: Depreciation/Amortisation | AP20: 294.93 | AQ20: 228.54 | AR20: 287.74 | AS20: 336.18 | AT20: 350.66 | AU20: 420.42
A21: Provisions | B21: 457.04 | C21: 1036.32 | D21: 172.77 | E21: 374.93 | F21: 0 | G21: 0 | I21: Current tax | J21: 1428 | K21: 1827 | L21: 2445 | M21: 3431 | N21: 2549 | O21: 3226 | Q21: Total expenses | R21: =SUM(R13:R20) -> 69964 | S21: =SUM(S13:S20) -> 68334 | T21: =SUM(T13:T20) -> 118333 | U21: =SUM(U13:U20) -> 161789 | V21: =SUM(V13:V20) -> 163047 | W21: =SUM(W13:W20) -> 163641 | Y21: Exceptional items: | AG21: Exceptional items | AH21: 771.76 | AI21: -58.43 | AJ21: -353.41 | AK21: 257.99 | AL21: -840.84 | AM21: -312.64 | AO21: Other expenses | AP21: 1351.74 | AQ21: 1446.45 | AR21: 2129.89 | AS21: 1611.3 | AT21: 1841.91 | AU21: 2266.11
A22: Write off | B22: 29.37 | C22: 5.81 | D22: 11.56 | E22: 192.6 | F22: 0 | G22: 0 | I22: Deferred tax charge | J22: 157 | K22: 767 | L22: 2026 | M22: 1346 | N22: -1 | O22: -26 | Q22: Profit before share of profit/loss from joint ventures | R22: =R11-R21 -> 3908 | S22: =S11-S21 -> 12097 | T22: =T11-T21 -> 29569 | U22: =U11-U21 -> 5201 | V22: =V11-V21 -> 12963 | W22: =W11-W21 -> 5877 | Y22: Profit on sale of subsidiaries | Z22: 202.99 | AA22: 15.81 | AB22: 724.84 | AC22: 66.86 | AD22: 4.68 | AE22: -7.05 | AG22: Profit before tax | AH22: =AH20-AH21 -> 3301.58 | AI22: =AI20-AI21 -> 7205.65 | AJ22: =AJ20+AJ21 -> 16291.87 | AK22: =AK20+AK21 -> 2892.44 | AL22: =AL20+AL21 -> 4061.81 | AM22: =AM20+AM21 -> 3251.53 | AO22: Total expenses | AP22: =SUM(AP10:AP21) -> 6002.11 | AQ22: =SUM(AQ10:AQ21) -> 6826.14 | AR22: =SUM(AR10:AR21) -> 13667.12 | AS22: =SUM(AS10:AS21) -> 12025.76 | AT22: =SUM(AT10:AT21) -> 14443.72 | AU22: =SUM(AU10:AU21) -> 16354.95
A23: Stripping activity adjustment | B23: 5541.87 | C23: 1450.37 | D23: 3760.86 | E23: 3809.11 | F23: -3699.73 | G23: -4105.52 | I23: Total tax expenses | J23: =J21+J22 -> 1585 | K23: =K21+K22 -> 2594 | L23: =L21+L22 -> 4471 | M23: =M21+M22 -> 4777 | N23: =N21+N22 -> 2548 | O23: =O21+O22 -> 3200 | Q23: Share of profit/loss | R23: -90 | S23: 1 | T23: 917 | U23: -137 | V23: -172 | W23: -311 | Y23: Provision for impairement of investments | Z23: -40.95 | AA23: 70.23 | AB23: 30.83 | AC23: 0 | AD23: 51.77 | AE23: 61.89 | AG23: Current tax | AH23: 229.79 | AI23: 16.35 | AJ23: 7.25 | AK23: 125.47 | AL23: 612.79 | AM23: 821.32 | AO23: Profit before exceptional items and tax | AP23: =AP8-AP22 -> 6211.47 | AQ23: =AQ8-AQ22 -> 8895.52 | AR23: =AR8-AR22 -> 13016.19 | AS23: =AS8-AS22 -> 6409.34 | AT23: =AT8-AT22 -> 8234.81 | AU23: =AU8-AU22 -> 9143.89
A24: Other expenses | B24: 4605.3 | C24: 4316.54 | D24: 5032.91 | E24: 5891.74 | F24: 14209.66 | G24: 13407.2 | I24: Profit for the year | J24: =J20-J23 -> 6805 | K24: =K20-K23 -> 7980 | L24: =L20-L23 -> 9629 | M24: =M20-M23 -> 10511 | N24: =N20-N23 -> 7759 | O24: =O20-O23 -> 10353 | Q24: Profit before exceptional items and tax | R24: =R22+R23 -> 3818 | S24: =S22+S23 -> 12098 | T24: =T22+T23 -> 30486 | U24: =U22+U23 -> 5064 | V24: =V22+V23 -> 12791 | W24: =W22+W23 -> 5566 | Y24: Provision for impairment of non current assets | Z24: -4372.44 | AA24: -723.41 | AB24: -99.74 | AC24: 83.68 | AD24: 19.98 | AE24: 0 | AG24: Deferred tax | AH24: 951.08 | AI24: 3041.17 | AJ24: 4041.15 | AK24: 590.44 | AL24: 382.35 | AM24: 58.41 | AO24: Exceptional items | AP24: 96.44 | AQ24: 0 | AR24: 0 | AS24: 1237.27 | AT24: -282.15 | AU24: 0
A25: Total expenses | B25: =SUM(B11:B24) -> 78452.81 | C25: =SUM(C11:C24) -> 75806.18 | D25: =SUM(D11:D24) -> 89971.96 | E25: =SUM(E11:E24) -> 106793.62 | F25: =SUM(F11:F24) -> 104345.72 | G25: =SUM(G11:G24) -> 106335.05 | Q25: Exceptional items | R25: 805 | S25: 83 | T25: 741 | U25: -591 | V25: -589 | W25: 489 | Y25: Provision for demands and claims | Z25: -196.41 | AA25: 0 | AB25: -252.68 | AC25: 25.37 | AD25: -3515.99 | AE25: -119.18 | AG25: Total tax expense | AH25: =SUM(AH23:AH24) -> 1180.87 | AI25: =SUM(AI23:AI24) -> 3057.52 | AJ25: =SUM(AJ23:AJ24) -> 4048.4 | AK25: =SUM(AK23:AK24) -> 715.91 | AL25: =SUM(AL23:AL24) -> 995.14 | AM25: =SUM(AM23:AM24) -> 879.73 | AO25: Profit before tax | AP25: =AP23-AP24 -> 6115.03 | AQ25: =AQ23-AQ24 -> 8895.52 | AR25: =AR23-AR24 -> 13016.19 | AS25: =AS23+AS24 -> 7646.61 | AT25: =AT23+AT24 -> 7952.66 | AU25: =AU23+AU24 -> 9143.89
A26: Profit before share of joint venture | B26: =B9-B25 -> 24072.49 | C26: =C9-C25 -> 18012.21 | D26: =D9-D25 -> 23624.87 | E26: =E9-E25 -> 38008.95 | F26: =F9-F25 -> 48385.78 | G26: =G9-G25 -> 46503.93 | Q26: Profit before tax | R26: =R24-R25 -> 3013 | S26: =S24-S25 -> 12015 | T26: =T24-T25 -> 29745 | U26: =U24-U25 -> 5655 | V26: =V24-V25 -> 13380 | W26: =W24-W25 -> 5077 | Y26: Employee seperation compensation | Z26: -107.37 | AA26: -443.55 | AB26: -330.81 | AC26: -91.94 | AD26: -129.86 | AE26: -691.65 | AG26: Profit for the year | AH26: =AH22-AH25 -> 2120.71 | AI26: =AI22-AI25 -> 4148.13 | AJ26: =AJ22-AJ25 -> 12243.47 | AK26: =AK22-AK25 -> 2176.53 | AL26: =AL22-AL25 -> 3066.67 | AM26: =AM22-AM25 -> 2371.8 | AO26: Current tax | AP26: 1555.59 | AQ26: 2316.46 | AR26: 3444.39 | AS26: 1664.65 | AT26: 2117.62 | AU26: 2410.81
A27: Share of Joint venture | B27: -1.17 | C27: -2.97 | D27: -8.59 | E27: -8.14 | F27: 426.83 | G27: 462.26 | Q27: Current tax | R27: 943 | S27: 2467 | T27: 4974 | U27: 1499 | V27: 2643 | W27: 1986 | Y27: Restructuring and other provisions | Z27: -165.4 | AA27: 87.5 | AB27: -256.24 | AC27: -1.7 | AD27: -4262.75 | AE27: 57.7 | AO27: Earlier years | AP27: 771.47 | AQ27: 343.2 | AR27: 260.53 | AS27: 172.13 | AT27: 231.18 | AU27: 223.69
A28: Profit before tax | B28: =B26+B27 -> 24071.32 | C28: =C26+C27 -> 18009.24 | D28: =D26+D27 -> 23616.28 | E28: =E26+E27 -> 38000.81 | F28: =F26+F27 -> 48812.61 | G28: =G26+G27 -> 46966.19 | Q28: Deferred tax | R28: -1849 | S28: 1675 | T28: 3833 | U28: 17 | V28: 733 | W28: -182 | Y28: Gain/loss on non current investments | Z28: -250 | AA28: -49.74 | AB28: 49.74 | AC28: 30.99 | AD28: 18.09 | AE28: =16.76-173.11 -> -156.35 | AO28: Deferred tax | AP28: 185.66 | AQ28: -11.21 | AR28: -129.83 | AS28: 271.43 | AT28: 31.62 | AU28: -30.36
A29: Tax expense | Q29: Tax impact of earlier years | R29: 0 | S29: 0 | T29: 0 | U29: 0 | V29: 1031 | W29: -218 | Y29: Total exceptional items | Z29: =SUM(Z22:Z28) -> -4929.58 | AA29: =SUM(AA22:AA28) -> -1043.16 | AB29: =SUM(AB22:AB28) -> -134.06 | AC29: =SUM(AC22:AC28) -> 113.26 | AD29: =SUM(AD22:AD28) -> -7814.08 | AE29: =SUM(AE22:AE28) -> -854.64 | AO29: Total tax expenses | AP29: =SUM(AP26:AP28) -> 2512.72 | AQ29: =SUM(AQ26:AQ28) -> 2648.45 | AR29: =SUM(AR26:AR28) -> 3575.09 | AS29: =SUM(AS26:AS28) -> 2108.21 | AT29: =SUM(AT26:AT28) -> 2380.42 | AU29: =SUM(AU26:AU28) -> 2604.14
A30: Current tax | B30: 6272.4 | C30: 5379.53 | D30: 6257.12 | E30: 9389.75 | F30: 11576.35 | G30: 11148.08 | Q30: Total tax expense | R30: =SUM(R27:R28) -> -906 | S30: =SUM(S27:S28) -> 4142 | T30: =SUM(T27:T28) -> 8807 | U30: =SUM(U27:U28) -> 1516 | V30: =SUM(V27:V29) -> 4407 | W30: =SUM(W27:W29) -> 1586 | Y30: Profit/loss before tax | Z30: =Z20+Z29 -> -1381.15 | AA30: =AA20+AA29 -> 13843.69 | AB30: =AB20+AB29 -> 50226.87 | AC30: =AC20+AC29 -> 18235.12 | AD30: =AD20+AD29 -> -1147.04 | AE30: =AE20+AE29 -> 8412.87 | AO30: Profit/loss for the year from continuing operations | AP30: =AP25-AP29 -> 3602.31 | AQ30: =AQ25-AQ29 -> 6247.07 | AR30: =AR25-AR29 -> 9441.1 | AS30: =AS25-AS29 -> 5538.4 | AT30: =AT25-AT29 -> 5572.24 | AU30: =AU25-AU29 -> 6539.75
A31: Deferred tax | B31: 1098.58 | C31: -72.46 | D31: -19.26 | E31: 486.12 | F31: -132.87 | G31: 516.01 | Q31: Profit for the year | R31: =R26-R30 -> 3919 | S31: =S26-S30 -> 7873 | T31: =T26-T30 -> 20938 | U31: =U26-U30 -> 4139 | V31: =V26-V30 -> 8973 | W31: =W26-W30 -> 3491 | Y31: Current tax | Z31: 2113.63 | AA31: 4288.27 | AB31: 7049.88 | AC31: 5361.33 | AD31: 5368.91 | AE31: 3563.77 | AO31: Profit/loss from discontinued operations | AP31: -1.05 | AQ31: 0.53 | AR31: -0.91 | AS31: -0.91 | AT31: -1.32 | AU31: -1.24
A32: Total tax expense | B32: =SUM(B30:B31) -> 7370.98 | C32: =SUM(C30:C31) -> 5307.07 | D32: =SUM(D30:D31) -> 6237.86 | E32: =SUM(E30:E31) -> 9875.87 | F32: =SUM(F30:F31) -> 11443.48 | G32: =SUM(G30:G31) -> 11664.09 | Y32: Deferred tax | Z32: -4666.53 | AA32: 1365.63 | AB32: 1427.67 | AC32: 4798.44 | AD32: -1527.57 | AE32: 1683.11 | AO32: Tax expense of discontinued operations | AP32: -0.26 | AQ32: 0.13 | AR32: -0.23 | AS32: -0.23 | AT32: -0.33 | AU32: -0.31
A33: Profit for the year from continuing operations | B33: =B28-B32 -> 16700.34 | C33: =C28-C32 -> 12702.17 | D33: =D28-D32 -> 17378.42 | E33: =E28-E32 -> 28124.94 | F33: =F28-F32 -> 37369.13 | G33: =G28-G32 -> 35302.1 | Y33: Current tax for earlier years | Z33: 0 | AA33: 0 | AB33: 0 | AC33: 0 | AD33: -78.77 | AE33: -7.79 | AO33: Profit/loss from discontinued operations (after tax) | AP33: =AP31-AP32 -> -0.79 | AQ33: =AQ31-AQ32 -> 0.4 | AR33: =AR31-AR32 -> -0.68 | AS33: =AS31-AS32 -> -0.68 | AT33: =AT31-AT32 -> -0.99 | AU33: =AU31-AU32 -> -0.93
A34: Profit/loss from discontinued operations | B34: 0 | C34: 0 | D34: 0 | E34: 0 | F34: 0 | G34: 0 | Y34: Total tax expense | Z34: =SUM(Z31:Z33) -> -2552.9 | AA34: =SUM(AA31:AA33) -> 5653.9 | AB34: =SUM(AB31:AB33) -> 8477.55 | AC34: =SUM(AC31:AC33) -> 10159.77 | AD34: =SUM(AD31:AD33) -> 3762.57 | AE34: =SUM(AE31:AE33) -> 5239.09 | AO34: Profit/Loss for the year | AP34: =AP30+AP33 -> 3601.52 | AQ34: =AQ30+AQ33 -> 6247.47 | AR34: =AR30+AR33 -> 9440.42 | AS34: =AS30+AS33 -> 5537.72 | AT34: =AT30+AT33 -> 5571.25 | AU34: =AU30+AU33 -> 6538.82
A35: Tax expense of discontinued operations | B35: 0 | C35: 0 | D35: 0 | E35: 0 | F35: 0 | G35: 0 | Y35: Profit/Loss for the year | Z35: =Z30-Z34 -> 1171.75 | AA35: =AA30-AA34 -> 8189.79 | AB35: =AB30-AB34 -> 41749.32 | AC35: =AC30-AC34 -> 8075.35 | AD35: =AD30-AD34 -> -4909.61 | AE35: =AE30-AE34 -> 3173.78
A36: Profit/loss from discontinued operations (after tax) | B36: =SUM(B34:B35) -> 0 | C36: =SUM(C34:C35) -> 0 | D36: =SUM(D34:D35) -> 0 | E36: =SUM(E34:E35) -> 0 | F36: =SUM(F34:F35) -> 0 | G36: =SUM(G34:G35) -> 0
A37: Profit/Loss for the year | B37: =B33+B36 -> 16700.34 | C37: =C33+C36 -> 12702.17 | D37: =D33+D36 -> 17378.42 | E37: =E33+E36 -> 28124.94 | F37: =F33+F36 -> 37369.13 | G37: =G33+G36 -> 35302.1

Sheet Cash Flow Statement
A1: CASH FLOW STATEMENT
B3: #VALUE! | J3: #VALUE! | R3: #VALUE! | Z3: #VALUE! | AH3: #VALUE! | AP3: #VALUE!
A4: Particulars | B4: 2020 | C4: 2021 | D4: 2022 | E4: 2023 | F4: 2024 | G4: 2025 | I4: Particulars | J4: 2020 | K4: 2021 | L4: 2022 | M4: 2023 | N4: 2024 | O4: 2025 | Q4: Particulars | R4: 2020 | S4: 2021 | T4: 2022 | U4: 2023 | V4: 2024 | W4: 2025 | Y4: Particulars | Z4: 2020 | AA4: 2021 | AB4: 2022 | AC4: 2023 | AD4: 2024 | AE4: 2025 | AG4: Particulars | AH4: 2020 | AI4: 2021 | AJ4: 2022 | AK4: 2023 | AL4: 2024 | AM4: 2025 | AO4: Particulars | AP4: 2020 | AQ4: 2021 | AR4: 2022 | AS4: 2023 | AT4: 2024 | AU4: 2025
A5: Net cash flow from/used in Operating Activities | B5: 4977.24 | C5: 10559.85 | D5: 41106.77 | E5: 35686.21 | F5: 18103.1 | G5: 29199.66 | I5: Net cash flow from/used in Operating Activities | J5: 6621 | K5: 10567 | L5: 12691 | M5: 15129 | N5: 13346 | O5: 14160 | Q5: Net cash flow from/used in Operating Activities | R5: 12785 | S5: 18789 | T5: 26270 | U5: 23323 | V5: 12078 | W5: 20899 | Y5: Net cash flow from/used in Operating Activities | Z5: 20168.72 | AA5: 44326.68 | AB5: 44380.99 | AC5: 21683.08 | AD5: 20300.67 | AE5: 23511.81 | AG5: Net cash flow from/used in Operating Activities | AH5: -617.67 | AI5: 23430.37 | AJ5: 30986.65 | AK5: -5290.15 | AL5: 2910.88 | AM5: 9914.3 | AO5: Net cash flow from/used in Operating Activities | AP5: 2125.97 | AQ5: 7266.11 | AR5: 6941.8 | AS5: 2465.61 | AT5: 7393.94 | AU5: 1894.28
A6: Net cash flow from/used in Investing activities | B6: 1032.84 | C6: 338.87 | D6: -25714.51 | E6: -23422.99 | F6: -4485.8 | G6: -10076.36 | I6: CapEx | J6: -3637 | K6: -2481 | L6: -2998 | M6: -3561 | N6: -3866 | O6: -4006 | Q6: CapEx | R6: -12810 | S6: -9258 | T6: -10091 | U6: -14784 | V6: -15801 | W6: -12694 | Y6: CapEx | Z6: -10398 | AA6: -6978.59 | AB6: -10522.2 | AC6: -14142.49 | AD6: -18206.6 | AE6: -15670.52 | AG6: CapEx | AH6: -4754.36 | AI6: -3672.7 | AJ6: -3665.49 | AK6: -3921.64 | AL6: -4710.69 | AM6: -6221.15 | AO6: CapEx | AP6: -2403.49 | AQ6: -1622.11 | AR6: -1198.34 | AS6: -1401.28 | AT6: -1847.09 | AU6: -3230.34
A7: CapEX | B7: -5213.86 | C7: -10852.51 | D7: -11679.27 | E7: -14209.48 | F7: -16379.95 | G7: -12803.58 | I7: Net cash flow from/used in Investing activities | J7: -2648 | K7: -2435 | L7: 846 | M7: 6562 | N7: -3406 | O7: -2706 | Q7: Net cash flow from/used in Investing activities | R7: -19586 | S7: -8119 | T7: -15987 | U7: -10711 | V7: -14638 | W7: -16997 | Y7: Net cash flow from/used in Investing activities | Z7: -14530.35 | AA7: -9322.88 | AB7: -10881.23 | AC7: -18679.84 | AD7: -14251.44 | AE7: -14172.73 | AG7: Net cash flow from/used in Investing activities | AH7: -4260.52 | AI7: -3412.69 | AJ7: -3975.78 | AK7: -3370.98 | AL7: -4260.54 | AM7: -5268.5 | AO7: Net cash flow from/used in Investing activities | AP7: -312.76 | AQ7: -4316.28 | AR7: -3213.89 | AS7: 43.29 | AT7: -6075.57 | AU7: 305.7
A8: Net cash flow from/used in Financing activities | B8: -4790.87 | C8: -8455.4 | D8: -13441.24 | E8: -13661.14 | F8: -13899.27 | G8: -13308.5 | I8: Net cash flow from/used in Financing activities | J8: -2098 | K8: -9697 | L8: -12258 | M8: -23224 | N8: -9946 | O8: -11411 | Q8: Net cash flow from/used in Financing activities | R8: 5189 | S8: -3110 | T8: -14657 | U8: -5977 | V8: -5005 | W8: -262 | Y8: Net cash flow from/used in Financing activities | Z8: -1694.62 | AA8: -37089.67 | AB8: -23401.09 | AC8: -6980.69 | AD8: -11096.99 | AE8: -7002.44 | AG8: Net cash flow from/used in Financing activities | AH8: 5003.15 | AI8: -19689.94 | AJ8: -27397.61 | AK8: 8586.68 | AL8: 1361.95 | AM8: -4423.6 | AO8: Net cash flow from/used in Financing activities | AP8: -1753.31 | AQ8: -2591.3 | AR8: -4066.85 | AS8: -2536.5 | AT8: -1301.98 | AU8: -2224.55
A9: Net change in cash and cash equivalents | B9: =SUM(B5:B6,B8) -> 1219.21 | C9: =SUM(C5:C6,C8) -> 2443.32 | D9: =SUM(D5:D6,D8) -> 1951.02 | E9: =SUM(E5:E6,E8) -> -1397.92 | F9: =SUM(F5:F6,F8) -> -281.97 | G9: =SUM(G5:G6,G8) -> 5814.8 | I9: Net change in cash and cash equivalents | J9: =SUM(J5,J7:J8) -> 1875 | K9: =SUM(K5,K7:K8) -> -1565 | L9: =SUM(L5,L7:L8) -> 1279 | M9: =SUM(M5,M7:M8) -> -1533 | N9: =SUM(N5,N7:N8) -> -6 | O9: =SUM(O5,O7:O8) -> 43 | Q9: Net change in cash and cash equivalents | R9: =SUM(R5,R7:R8) -> -1612 | S9: =SUM(S5,S7:S8) -> 7560 | T9: =SUM(T5,T7:T8) -> -4374 | U9: =SUM(U5,U7:U8) -> 6635 | V9: =SUM(V5,V7:V8) -> -7565 | W9: =SUM(W5,W7:W8) -> 3640 | Y9: Net change in cash and cash equivalents | Z9: =SUM(Z5,Z7:Z8) -> 3943.75 | AA9: =SUM(AA5,AA7:AA8) -> -2085.87 | AB9: =SUM(AB5,AB7:AB8) -> 10098.67 | AC9: =SUM(AC5,AC7:AC8) -> -3977.45 | AD9: =SUM(AD5,AD7:AD8) -> -5047.76 | AE9: =SUM(AE5,AE7:AE8) -> 2336.64 | AG9: Net change in cash and cash equivalents | AH9: =SUM(AH5,AH7:AH8) -> 124.96 | AI9: =SUM(AI5,AI7:AI8) -> 327.74 | AJ9: =SUM(AJ5,AJ7:AJ8) -> -386.74 | AK9: =SUM(AK5,AK7:AK8) -> -74.45 | AL9: =SUM(AL5,AL7:AL8) -> 12.29 | AM9: =SUM(AM5,AM7:AM8) -> 222.2 | AO9: Net change in cash and cash equivalents | AP9: =SUM(AP5,AP7:AP8) -> 59.9 | AQ9: =SUM(AQ5,AQ7:AQ8) -> 358.53 | AR9: =SUM(AR5,AR7:AR8) -> -338.94 | AS9: =SUM(AS5,AS7:AS8) -> -27.6 | AT9: =SUM(AT5,AT7:AT8) -> 16.39 | AU9: =SUM(AU5,AU7:AU8) -> -24.57

Sheet Financial Ratios
A1: FINANCIAL RATIOS
B3: #VALUE! | J3: #VALUE! | S3: #VALUE! | AA3: #VALUE! | AI3: #VALUE! | AQ3: #VALUE!
A4: Particulars | B4: 2020 | C4: 2021 | D4: 2022 | E4: 2023 | F4: 2024 | G4: 2025 | I4: Particulars | J4: 2020 | K4: 2021 | L4: 2022 | M4: 2023 | N4: 2024 | O4: 2025 | Q4: Particulars | R4: 2020 | S4: 2021 | T4: 2022 | U4: 2023 | V4: 2024 | W4: 2025 | Y4: Particulars | Z4: 2020 | AA4: 2021 | AB4: 2022 | AC4: 2023 | AD4: 2024 | AE4: 2025 | AG4: Particulars | AH4: 2020 | AI4: 2021 | AJ4: 2022 | AK4: 2023 | AL4: 2024 | AM4: 2025 | AO4: Particulars | AP4: 2020 | AQ4: 2021 | AR4: 2022 | AS4: 2023 | AT4: 2024 | AU4: 2025
A5: Liquidity | I5: Liquidity | Q5: Liquidity | Y5: Liquidity | AG5: Liquidity | AO5: Liquidity
A6: Current Ratio | B6: ='Balance Sheet'!B27/'Balance Sheet'!B52 -> 1.7055322 | C6: ='Balance Sheet'!C27/'Balance Sheet'!C52 -> 1.6405916 | D6: ='Balance Sheet'!D27/'Balance Sheet'!D52 -> 1.6229402 | E6: ='Balance Sheet'!E27/'Balance Sheet'!E52 -> 1.5724635 | F6: ='Balance Sheet'!F27/'Balance Sheet'!F52 -> 1.6954309 | G6: ='Balance Sheet'!G27/'Balance Sheet'!G52 -> 1.4858043 | I6: Current Ratio | J6: ='Balance Sheet'!J24/'Balance Sheet'!J49 -> 4.5839645 | K6: ='Balance Sheet'!K24/'Balance Sheet'!K49 -> 3.1193499 | L6: ='Balance Sheet'!L24/'Balance Sheet'!L49 -> 3.9353462 | M6: ='Balance Sheet'!M24/'Balance Sheet'!M49 -> 0.79825818 | N6: ='Balance Sheet'!N24/'Balance Sheet'!N49 -> 1.1645605 | O6: ='Balance Sheet'!O24/'Balance Sheet'!O49 -> 1.0381284 | Q6: Current Ratio | R6: ='Balance Sheet'!R33/'Balance Sheet'!R61 -> 0.83496612 | S6: ='Balance Sheet'!S33/'Balance Sheet'!S61 -> 0.82800988 | T6: ='Balance Sheet'!T33/'Balance Sheet'!T61 -> 1.1359316 | U6: ='Balance Sheet'!U33/'Balance Sheet'!U61 -> 0.9740863 | V6: ='Balance Sheet'!V33/'Balance Sheet'!V61 -> 0.97682585 | W6: ='Balance Sheet'!W33/'Balance Sheet'!W61 -> 1.1667601 | Y6: Current Ratio | Z6: ='Balance Sheet'!Z34/'Balance Sheet'!Z68 -> 0.92699185 | AA6: ='Balance Sheet'!AA34/'Balance Sheet'!AA68 -> 0.8482405 | AB6: ='Balance Sheet'!AB34/'Balance Sheet'!AB68 -> 1.0205669 | AC6: ='Balance Sheet'!AC34/'Balance Sheet'!AC68 -> 0.89013849 | AD6: ='Balance Sheet'!AD34/'Balance Sheet'!AD68 -> 0.71647456 | AE6: ='Balance Sheet'!AE34/'Balance Sheet'!AE68 -> 0.79438634 | AG6: Current Ratio | AH6: ='Balance Sheet'!AH31/'Balance Sheet'!AH60 -> 0.91461373 | AI6: ='Balance Sheet'!AI31/'Balance Sheet'!AI60 -> 0.69216883 | AJ6: ='Balance Sheet'!AJ31/'Balance Sheet'!AJ60 -> 0.73303303 | AK6: ='Balance Sheet'!AK31/'Balance Sheet'!AK60 -> 0.77014644 | AL6: ='Balance Sheet'!AL31/'Balance Sheet'!AL60 -> 0.90036869 | AM6: ='Balance Sheet'!AM31/'Balance Sheet'!AM60 -> 0.90687158 | AO6: Current Ratio | AP6: ='Balance Sheet'!AP26/'Balance Sheet'!AP49 -> 2.4898616 | AQ6: ='Balance Sheet'!AQ26/'Balance Sheet'!AQ49 -> 1.9148936 | AR6: ='Balance Sheet'!AR26/'Balance Sheet'!AR49 -> 2.7908559 | AS6: ='Balance Sheet'!AS26/'Balance Sheet'!AS49 -> 3.7624031 | AT6: ='Balance Sheet'!AT26/'Balance Sheet'!AT49 -> 2.5319138 | AU6: ='Balance Sheet'!AU26/'Balance Sheet'!AU49 -> 2.4178537
