Workbook

Sheet Company Profile
A1: COMPANY PROFILE
A2: Particulars | B2: #VALUE! | C2: #VALUE! | D2: #VALUE! | E2: #VALUE! | F2: #VALUE! | G2: #VALUE!
A3: Company | B3: #VALUE! | C3: #VALUE! | D3: #VALUE! | E3: #VALUE! | F3: #VALUE! | G3: #VALUE!
A4: Official Name | B4: {=_FV(B3,"Official name",TRUE)} -> MARUTI SUZUKI INDIA LIMITED | C4: {=_FV(C3,"Official name",TRUE)} -> MAHINDRA AND MAHINDRA LIMITED | D4: {=_FV(D3,"Official name",TRUE)} -> TATA MOTORS PASSENGER VEHICLES LIMITED | E4: {=_FV(E3,"Official name",TRUE)} -> TVS MOTOR COMPANY LIMITED | F4: {=_FV(F3,"Official name",TRUE)} -> EXIDE INDUSTRIES LIMITED | G4: {=_FV(G3,"Official name",TRUE)} -> SAMVARDHANA MOTHERSON INTERNATIONAL LIMITED
A5: Ticker Symbol | B5: {=_FV(B3,"Ticker symbol",TRUE)} -> MARUTI | C5: {=_FV(C3,"Ticker symbol",TRUE)} -> M&M | D5: {=_FV(D3,"Ticker symbol",TRUE)} -> 500570 | E5: {=_FV(E3,"Ticker symbol",TRUE)} -> TVSMOTOR | F5: {=_FV(F3,"Ticker symbol",TRUE)} -> 500086 | G5: {=_FV(G3,"Ticker symbol",TRUE)} -> MOTHERSON
A6: Industry | B6: {=_FV(B3,"Industry")} -> Automobiles & Auto Parts | C6: {=_FV(C3,"Industry")} -> Automobiles & Auto Parts | D6: {=_FV(D3,"Industry")} -> Automobiles & Auto Parts | E6: {=_FV(E3,"Industry")} -> Automobiles & Auto Parts | F6: {=_FV(F3,"Industry")} -> Automobiles & Auto Parts | G6: {=_FV(G3,"Industry")} -> Automobiles & Auto Parts
A7: Headquarters | B7: {=_FV(B3,"Headquarters")} -> 1, Nelson Mandela Road,, Vasant Kunj,, NEW DELHI, DELHI, 110070 IN | C7: {=_FV(C3,"Headquarters")} -> Gateway Building, Apollo Bunder, MUMBAI, MAHARASHTRA, 400001 IN | D7: {=_FV(D3,"Headquarters")} -> A Block, Shivasagar Estate, Dr. Annie Besant Road, Worli, MUMBAI, MAHARASHTRA, 400018 IN | E7: {=_FV(E3,"Headquarters")} -> "Chaitanya", No.12, Khader Nawaz Khan Road, Nungambakkam, KRISHNAGIRI, TAMIL NADU, 600006 IN | F7: {=_FV(F3,"Headquarters")} -> Exide House, 59E, Chowringhee Road, KOLKATA, WEST BENGAL, 700020 IN | G7: {=_FV(G3,"Headquarters")} -> C-14 A & B, Sector 1,, Distt. Gautam Budh Nagar, NOIDA, UTTAR PRADESH, 201301 IN
A8: Established year | B8: {=_FV(B3,"Year incorporated",TRUE)} -> 1981 | C8: {=_FV(C3,"Year incorporated",TRUE)} -> 1945 | D8: {=_FV(D3,"Year incorporated",TRUE)} -> 1945 | E8: {=_FV(E3,"Year incorporated",TRUE)} -> 1992 | F8: {=_FV(F3,"Year incorporated",TRUE)} -> 1947 | G8: {=_FV(G3,"Year incorporated",TRUE)} -> 1986
A9: Employees | B9: {=_FV(B3,"Employees")} -> 20171 | C9: {=_FV(C3,"Employees")} -> 25222 | D9: {=_FV(D3,"Employees")} -> 86259 | E9: {=_FV(E3,"Employees")} -> 6522 | F9: {=_FV(F3,"Employees")} -> 5135 | G9: {=_FV(G3,"Employees")} -> 91481
B10: =B9/10000000 -> 0.0020171 | C10: =C9/10000000 -> 0.0025222 | D10: =D9/10000000 -> 0.0086259 | E10: =E9/10000000 -> 0.0006522 | F10: =F9/10000000 -> 0.0005135 | G10: =G9/10000000 -> 0.0091481
A11: Share Price | B11: {=_FV(B3,"Price")} -> 15583 | C11: {=_FV(C3,"Price")} -> 3663.9 | D11: {=_FV(D3,"Price")} -> 410.5 | E11: {=_FV(E3,"Price")} -> 3490.8 | F11: {=_FV(F3,"Price")} -> 379.55 | G11: {=_FV(G3,"Price")} -> 102.55
A12: Change (%) | B12: {=_FV(B3,"Change (%)",TRUE)} -> 0.006719 | C12: {=_FV(C3,"Change (%)",TRUE)} -> -0.007127 | D12: {=_FV(D3,"Change (%)",TRUE)} -> 0.011956 | E12: {=_FV(E3,"Change (%)",TRUE)} -> 0.009836 | F12: {=_FV(F3,"Change (%)",TRUE)} -> 0.00623 | G12: {=_FV(G3,"Change (%)",TRUE)} -> -0.012042
A13: Currency conversion | B13: #VALUE! | C13: #VALUE! | D13: #VALUE! | E13: #VALUE! | F13: #VALUE! | G13: #VALUE!
B14: {=_FV(B13,"Price")} -> 0.01127 | C14: {=_FV(C13,"Price")} -> 0.01127 | D14: {=_FV(D13,"Price")} -> 0.01127 | E14: {=_FV(E13,"Price")} -> 0.01127 | F14: {=_FV(F13,"Price")} -> 0.01127 | G14: {=_FV(G13,"Price")} -> 0.01127
A15: Share Outstanding | B15: {=_FV(B3,"Shares outstanding",TRUE)} -> 314402600 | C15: {=_FV(C3,"Shares outstanding",TRUE)} -> 1200046000 | D15: {=_FV(D3,"Shares outstanding",TRUE)} -> 3682331000 | E15: {=_FV(E3,"Shares outstanding",TRUE)} -> 474919100 | F15: {=_FV(F3,"Shares outstanding",TRUE)} -> 850000000 | G15: {=_FV(G3,"Shares outstanding",TRUE)} -> 10554440000
B16: =B15/10000000 -> 31.44026 | C16: =C15/10000000 -> 120.0046 | D16: =D15/10000000 -> 368.2331 | E16: =E15/10000000 -> 47.49191 | F16: =F15/10000000 -> 85 | G16: =G15/10000000 -> 1055.444
A17: Market Cap | B17: {=_FV(B3,"Market cap",TRUE)} -> 4866638000000 | C17: {=_FV(C3,"Market cap",TRUE)} -> 4428411000000 | D17: {=_FV(D3,"Market cap",TRUE)} -> 1493922000000 | E17: {=_FV(E3,"Market cap",TRUE)} -> 1641700000000 | F17: {=_FV(F3,"Market cap",TRUE)} -> 320747500000 | G17: {=_FV(G3,"Market cap",TRUE)} -> 1095551000000
B18: =B17/10000000 -> 486663.8 | C18: =C17/10000000 -> 442841.1 | D18: =D17/10000000 -> 149392.2 | E18: =E17/10000000 -> 164170 | F18: =F17/10000000 -> 32074.75 | G18: =G17/10000000 -> 109555.1
A19: Beta | B19: {=_FV(B3,"Beta")} -> 0.3464 | C19: {=_FV(C3,"Beta")} -> 0.7572 | D19: {=_FV(D3,"Beta")} -> 1.0253 | E19: {=_FV(E3,"Beta")} -> 0.1588 | F19: {=_FV(F3,"Beta")} -> 0.9844 | G19: {=_FV(G3,"Beta")} -> 1.5879

Sheet Balance Sheet
A1: Balance Sheet | F1: #VALUE! | I1: Balance Sheet | N1: #VALUE! | Q1: Balance Sheet | V1: #VALUE! | Y1: Balance Sheet | AD1: #VALUE! | AG1: Balance Sheet | AL1: #VALUE! | AO1: Balance Sheet | AT1: #VALUE!
A2: Particulars | B2: 2020 | C2: 2021 | D2: 2022 | E2: 2023 | F2: 2024 | G2: 2025 | I2: Particulars | J2: 2020 | K2: 2021 | L2: 2022 | M2: 2023 | N2: 2024 | O2: 2025 | Q2: Particulars | R2: 2020 | S2: 2021 | T2: 2022 | U2: 2023 | V2: 2024 | W2: 2025 | Y2: Particulars | Z2: 2020 | AA2: 2021 | AB2: 2022 | AC2: 2023 | AD2: 2024 | AE2: NA | AG2: Particulars | AH2: 2020 | AI2: 2021 | AJ2: 2022 | AK2: 2023 | AL2: 2024 | AM2: 2025 | AO2: Particulars | AP2: 2020 | AQ2: 2021 | AR2: 2022 | AS2: 2023 | AT2: 2024 | AU2: NA
A3: ASSETS | I3: ASSETS | Q3: ASSETS | Y3: ASSETS | AG3: ASSETS | AO3: ASSETS
A4: Non-Current Assets | I4: Non-Current Assets | Q4: Non-Current Assets | Y4: Non-Current Assets | AG4: Non-Current Assets | AO4: Non-Current Assets
A5: PPE | B5: 14790.5 | C5: 14178.5 | D5: 12826.1 | E5: 16692.1 | F5: 17431.4 | G5: 23638.2 | I5: PPE | J5: 24417.18 | K5: 17611.65 | L5: 21902.26 | M5: 20351.33 | N5: 21408.6 | O5: 25834.82 | Q5: PPE | R5: 77882.83 | S5: 79640.05 | T5: 80900.13 | U5: 76641.43 | V5: 73125 | W5: 72536 | Y5: PPE | Z5: 3066.54 | AA5: 3123.85 | AB5: 4377.8 | AC5: 4177.4 | AD5: 4294.12 | AG5: PPE | AH5: 2620 | AI5: 2970.19 | AJ5: 3240.18 | AK5: 3582.06 | AL5: 3760.47 | AM5: 3853.53 | AO5: PPE | AP5: 14713.8 | AQ5: 14373.8 | AR5: 14525.2 | AS5: 15644.5 | AT5: 18773
A6: Capital work-in-progress | B6: 1344.3 | C6: 1199.3 | D6: 2646.2 | E6: 2815.2 | F6: 6303.4 | G6: 5357.5 | I6: Capital work-in-progress | J6: 2551.75 | K6: 4477.64 | L6: 3036.1 | M6: 1222.66 | N6: 3461.33 | O6: 3652.56 | Q6: Capital work-in-progress | R6: 8599.56 | S6: 8377.14 | T6: 3529.04 | U6: 5219.87 | V6: 10937 | W6: 17624 | Y6: Capital work-in-progress | Z6: 847.14 | AA6: 873.89 | AB6: 320.18 | AC6: 315.81 | AD6: 338.01 | AG6: Capital work-in-progress | AH6: 360.72 | AI6: 379.47 | AJ6: 322.42 | AK6: 335.38 | AL6: 1164.54 | AM6: 3426.05 | AO6: Right-to-use assets | AP6: 1559.6 | AQ6: 1438.3 | AR6: 1603.1 | AS6: 1918.1 | AT6: 2880.6
A7: Intangible assets | B7: 335.8 | C7: 224.2 | D7: 349.9 | E7: 547.9 | F7: 451 | G7: 482.8 | I7: Intangible assets | J7: 1512.31 | K7: 1304.9 | L7: 2775.83 | M7: 4239.75 | N7: 4272.44 | O7: 6427.64 | Q7: Right of use assets | R7: 6275.34 | S7: 6490.66 | T7: 6686.02 | U7: 7801.04 | V7: 8059 | W7: 8476 | Y7: Investment properties | Z7: 137.7 | AA7: 137.7 | AB7: 137.7 | AC7: 137.7 | AD7: 137.7 | AG7: Goodwill | AH7: 581.9 | AI7: 581.9 | AJ7: 46.77 | AK7: 45.82 | AL7: 45.82 | AM7: 45.82 | AO7: Capital work-in-progress | AP7: 815.4 | AQ7: 838.3 | AR7: 1248.8 | AS7: 1422.2 | AT7: 2430.6
A8: Intangible assets under development | B8: 70.9 | C8: 297.5 | D8: 290.3 | E8: 88.9 | F8: 230.5 | G8: 401.8 | I8: Intangible assets under development | J8: 3759.78 | K8: 2463.13 | L8: 3666.71 | M8: 2745.92 | N8: 4577.97 | O8: 4645.08 | Q8: Goodwill | R8: 777.06 | S8: 803.72 | T8: 807.17 | U8: 840.6 | V8: 860 | W8: 895 | Y8: Goodwill | Z8: 2.2 | AA8: 2.2 | AB8: 0 | AC8: 0 | AD8: 0 | AG8: Other tangible assets | AH8: 46.6 | AI8: 46.66 | AJ8: 74.28 | AK8: 56.94 | AL8: 46.55 | AM8: 35.89 | AO8: Investment property | AP8: 119.7 | AQ8: 128.1 | AR8: 524.1 | AS8: 499.3 | AT8: 583.7
A9: Right-of-use assets | B9: 618.1 | C9: 586 | D9: 571.2 | E9: 590.4 | F9: 612.9 | G9: 585.8 | I9: Goodwill | J9: 4304.73 | K9: 3394.97 | L9: 1340.4 | M9: 2548.9 | N9: 2448.37 | O9: 2373.9 | Q9: Other intangible assets | R9: 42171.91 | S9: 51773.18 | T9: 50462.13 | U9: 46796.69 | V9: 39241 | W9: 33790 | Y9: Goodwill on consolidation | Z9: 186.11 | AA9: 186.11 | AB9: 569.47 | AC9: 597.05 | AD9: 597.05 | AG9: Intangible assets under development | AH9: 44.15 | AI9: 51.48 | AJ9: 18.52 | AK9: 189.67 | AL9: 187.44 | AM9: 217.36 | AO9: Goodwill | AP9: 2406 | AQ9: 2471.8 | AR9: 3374.3 | AS9: 3772.6 | AT9: 5750.1
A10: Financial assets | I10: Investments accounted using equity method | J10: 11229.4 | K10: 12256.22 | L10: 13149.7 | M10: 14380.57 | N10: 13800.71 | O10: 14176.68 | Q10: Intangible assets under development | R10: 27022.73 | S10: 12586.79 | T10: 6722.05 | U10: 9054.63 | V10: 24761 | W10: 48182 | Y10: Other tangible assets | Z10: 183 | AA10: 528.44 | AB10: 889.49 | AC10: 835.88 | AD10: 861.95 | AG10: Reinsurance asset | AH10: 138.96 | AI10: 271.2 | AJ10: 24.56 | AK10: 24.84 | AL10: 25.66 | AM10: 27.66 | AO10: Other Intangible assets | AP10: 1951 | AQ10: 1687.1 | AR10: 1384.5 | AS10: 1312.4 | AT10: 2134.1
A11: Investments | B11: 36269.2 | C11: 34529.1 | D11: 37934.6 | E11: 49184.3 | F11: 64601.5 | G11: 68945.9 | I11: Financial assets | Q11: Investment in equity accounted investees | R11: 4418.89 | S11: 4200.79 | T11: 4349.39 | U11: 4675.66 | V11: 5340 | W11: 5534 | Y11: Intangible assets under development | Z11: 158.87 | AA11: 166.88 | AB11: 231.35 | AC11: 427.64 | AD11: 694.94 | AG11: Financial assets | AO11: Intangible assets under development | AP11: 36.4 | AQ11: 38.6 | AR11: 60.9 | AS11: 55.7 | AT11: 67.2
A12: Loans | B12: 0.2 | C12: 0.2 | D12: 0.2 | E12: 0.2 | F12: 0.1 | G12: 0.1 | I12: Investments | J12: 1685.38 | K12: 6489.62 | L12: 6060.85 | M12: 6625.93 | N12: 7772.75 | O12: 5184.42 | Q12: Financial assets | Y12: Right of use assets | Z12: 235.14 | AA12: 242.75 | AB12: 0 | AC12: 0 | AD12: 0 | AG12: Investments | AO12: Investments accounted for using the equity method | AP12: 634.1 | AQ12: 716.6 | AR12: 6264.7 | AS12: 6105.9 | AT12: 6207.5
A13: Other Financial assets | B13: 36.5 | C13: 36.9 | D13: 37.5 | E13: 59.5 | F13: 82.2 | G13: 87.1 | I13: Loans | J13: 45945.23 | K13: 38525.68 | L13: 38849.4 | M13: 52772.75 | N13: 67783.65 | O13: 79607.31 | Q13: Other investments | R13: 1028.05 | S13: 1368.3 | T13: 2320.92 | U13: 2865.19 | V13: 3378 | W13: 2923 | Y13: Financial assets | AG13: Investments on life insurance business | AH13: 14736.78 | AI13: 17702.22 | AJ13: 4822.34 | AK13: 4477.82 | AL13: 5655.45 | AM13: 6122.03 | AO13: Financial assets
A14: Other non-current assets | B14: 1721.6 | C14: 1686.7 | D14: =544.6+141.1+2520.4 -> 3206.1 | E14: =574.9+279.4+2148.5 -> 3002.8 | F14: =543.9+112.4+2153.1 -> 2809.4 | G14: =474.3+2394.5 -> 2868.8 | I14: Other Financial assets | J14: 1187.72 | K14: 1497.38 | L14: 2206.65 | M14: 3353.97 | N14: 4297.97 | O14: 2282.79 | Q14: Financial receivables | R14: 16833.77 | S14: 16846.82 | T14: 11135.85 | U14: 7416.41 | V14: 6095 | W14: 0 | Y14: Investments | Z14: 195.71 | AA14: 180.39 | AB14: 109.51 | AC14: 364.1 | AD14: 482.75 | AG14: Other investments | AH14: 83.72 | AI14: 100.82 | AJ14: 25.59 | AK14: 23.19 | AL14: 40.39 | AM14: 43.44 | AO14: Investments | AP14: 161.4 | AQ14: 128.7 | AR14: 195.8 | AS14: 181.1 | AT14: 215.3
A15: Total non-current assets | B15: =SUM(B5:B9,B11:B14) -> 55187.1 | C15: =SUM(C5:C9,C11:C14) -> 52738.4 | D15: =SUM(D5:D9,D11:D14) -> 57862.1 | E15: =SUM(E5:E9,E11:E14) -> 72981.3 | F15: =SUM(F5:F9,F11:F14) -> 92522.4 | G15: =SUM(G5:G9,G11:G14) -> 102368 | I15: Trade receivables | J15: 556.19 | K15: 366.16 | L15: 309.43 | M15: 282.6 | N15: 270.66 | O15: 256.54 | Q15: Loans and advances | R15: 782.78 | S15: 1204.59 | T15: 843.35 | U15: 870.65 | V15: 442 | W15: 99 | Y15: Loans | Z15: 4148.49 | AA15: 5361.97 | AB15: 6716.45 | AC15: 10321.42 | AD15: 12054.55 | AG15: Trade receivables | AH15: 0.11 | AI15: 0.08 | AJ15: 0.05 | AK15: 0.32 | AL15: 0.6 | AM15: 0.59 | AO15: Loans | AP15: 17.7 | AQ15: 44.5 | AR15: 3.6 | AS15: 9 | AT15: 12.2
A16: Current Assets | I16: Deferred tax assets (net) | J16: 1290.53 | K16: 1717.32 | L16: 1724.31 | M16: 1615.46 | N16: 1578.99 | O16: 1573.11 | Q16: Other financial assets | R16: 4749.57 | S16: 5813.98 | T16: 5179.49 | U16: 7027.66 | V16: 9085 | W16: 12185 | Y16: Other financial assets | Z16: 36.64 | AA16: 14.92 | AB16: 124.14 | AC16: 192.93 | AD16: 195.52 | AG16: Loans | AH16: 38.08 | AI16: 51.17 | AJ16: 0.09 | AK16: 0.07 | AL16: 0.25 | AM16: 0.19 | AO16: Trade receivables | AP16: 1399.8 | AQ16: 1494.6 | AR16: 1451.6 | AS16: 1324.4 | AT16: 1557.2
A17: Inventories | B17: 3213.9 | C17: 3049 | D17: 3532.3 | E17: 4283.5 | F17: 4119.6 | G17: 5123 | I17: Income tax assets (net) | J17: 1897.98 | K17: 1887.47 | L17: 1604.24 | M17: 1802.88 | N17: 2129.91 | O17: 2270.77 | Q17: Deferred tax assets (net) | R17: 5457.9 | S17: 4520.35 | T17: 3870.85 | U17: 5184.67 | V17: 13099 | W17: 7176 | Y17: Investments accounted using equity method | Z17: 175.2 | AA17: 287.62 | AB17: 364.82 | AC17: 411.23 | AD17: 477.25 | AG17: Current tax assets (net) | AH17: 69.01 | AI17: 54.97 | AJ17: 37.9 | AK17: 41.2 | AL17: 39.54 | AM17: 26.69 | AO17: Other financial assets | AP17: 122.8 | AQ17: 106.9 | AR17: 241.3 | AS17: 115.5 | AT17: 155
A18: Financial assets | I18: Other non-current assets | J18: 2623.05 | K18: 2332.44 | L18: 2338.92 | M18: 2623.61 | N18: 4231.74 | O18: 2727.38 | Q18: Non-current tax assets (net) | R18: 1152.05 | S18: 1003.3 | T18: 1196.79 | U18: 1556.36 | V18: 2130 | W18: 2045 | Y18: Non-current tax assets (net) | Z18: 28.34 | AA18: 39.72 | AB18: 49.6 | AC18: 27.6 | AD18: 23.55 | AG18: Deferred tax assets (net) | AH18: 16.1 | AI18: 9.94 | AJ18: 65.38 | AK18: 115.98 | AL18: 23.04 | AM18: 6.65 | AO18: Deferred tax assets (net) | AP18: 503 | AQ18: 1022.4 | AR18: 1148.6 | AS18: 1364.4 | AT18: 2074.6
A19: Investments | B19: 1218.8 | C19: 8415.7 | D19: 4100.1 | E19: 0 | F19: 3912.2 | G19: 5560.4 | I19: Total non-current assets | J19: =SUM(J5:J10,J12:J18) -> 102961.23 | K19: =SUM(K5:K10,K12:K18) -> 94324.58 | L19: =SUM(L5:L10,L12:L18) -> 98964.8 | M19: =SUM(M5:M10,M12:M18) -> 114566.33 | N19: =SUM(N5:N10,N12:N18) -> 138035.09 | O19: =SUM(O5:O10,O12:O18) -> 151013 | Q19: Other non-current assets | R19: 5381.57 | S19: 1608.49 | T19: 5639.21 | U19: 8602.05 | V19: 5720 | W19: 6852 | Y19: Deferred tax assets | Z19: 86.65 | AA19: 127.62 | AB19: 217.88 | AC19: 305.73 | AD19: 394.28 | AG19: Other non-current assets | AH19: 221.51 | AI19: 211.08 | AJ19: 111.28 | AK19: 183.4 | AL19: 908.75 | AM19: 386.28 | AO19: Other non-current assets | AP19: 1216.5 | AQ19: 1383.5 | AR19: 1376.7 | AS19: 1226.5 | AT19: 1566.8
A20: Trade Receivables | B20: 1977.7 | C20: 1279.9 | D20: 2034.5 | E20: 3301.4 | F20: 4601.3 | G20: 6537.7 | I20: Current Assets | Q20: Total non-current assets | R20: =SUM(R5:R11,R13:R19) -> 202534.01 | S20: =SUM(S5:S11,S13:S19) -> 196238.16 | T20: =SUM(T5:T11,T13:T19) -> 183642.39 | U20: =SUM(U5:U11,U13:U19) -> 184552.91 | V20: =SUM(V5:V11,V13:V19) -> 202272 | W20: =SUM(W5:W11,W13:W19) -> 218317 | Y20: Other non-current assets | Z20: 132.09 | AA20: 181.79 | AB20: 115.43 | AC20: 94.14 | AD20: 148.78 | AG20: Total non-current assets | AH20: =SUM(AH5:AH10,AH13:AH19) -> 18957.64 | AI20: =SUM(AI5:AI10,AI13:AI19) -> 22431.18 | AJ20: =SUM(AJ5:AJ10,AJ13:AJ19) -> 8789.36 | AK20: =SUM(AK5:AK10,AK13:AK19) -> 9076.69 | AL20: =SUM(AL5:AL10,AL13:AL19) -> 11898.5 | AM20: =SUM(AM5:AM10,AM13:AM19) -> 14192.18 | AO20: Non-current tax assets (net) | AP20: 373.2 | AQ20: 184.3 | AR20: 250.7 | AS20: 120.9 | AT20: 341.6
A21: Cash and Cash Equivalents | B21: 20.8 | C21: 40.8 | D21: 35.1 | E21: 37.3 | F21: 455.7 | G21: 78 | I21: Inventories | J21: 11111.86 | K21: 9615.41 | L21: 11595.82 | M21: 16854.97 | N21: 18590.47 | O21: 20330.93 | Q21: Current Assets | Y21: Total Non-current assets | Z21: =SUM(Z5:Z12,Z14:Z20) -> 9619.82 | AA21: =SUM(AA5:AA12,AA14:AA20) -> 11455.85 | AB21: =SUM(AB5:AB12,AB14:AB20) -> 14223.82 | AC21: =SUM(AC5:AC12,AC14:AC20) -> 18208.63 | AD21: =SUM(AD5:AD12,AD14:AD20) -> 20700.45 | AE21: =SUM(AE5:AE12,AE14:AE20) -> 0 | AG21: Current Assets | AO21: Total Non-current assets | AP21: =SUM(AP5:AP12,AP14:AP20) -> 26030.4 | AQ21: =SUM(AQ5:AQ12,AQ14:AQ20) -> 26057.5 | AR21: =SUM(AR5:AR12,AR14:AR20) -> 33653.9 | AS21: =SUM(AS5:AS12,AS14:AS20) -> 35072.5 | AT21: =SUM(AT5:AT12,AT14:AT20) -> 44749.5 | AU21: =SUM(AU5:AU12,AU14:AU20) -> 0
A22: Other bank balances | B22: 8.2 | C22: 3006.3 | D22: 3007.1 | E22: 4.3 | F22: 4.3 | G22: 368.4 | I22: Financial assets | Q22: Inventories | R22: 37456.88 | S22: 36088.59 | T22: 35240.34 | U22: 40755.39 | V22: 47788 | W22: 47269 | Y22: Current Assets | AG22: Inventories | AH22: 2414.56 | AI22: 2636.86 | AJ22: 2855.29 | AK22: 3436.4 | AL22: 3868.53 | AM22: 4564.9 | AO22: Current Assets
A23: Loans | B23: 17 | C23: 23 | D23: 30.5 | E23: 29.7 | F23: 32.7 | G23: 43.2 | I23: Investments | J23: 6295.56 | K23: 10031.82 | L23: 10849.88 | M23: 14265.92 | N23: 13634.64 | O23: 21947.47 | Q23: Financial assets | Y23: Inventories | Z23: 1188.47 | AA23: 1367.43 | AB23: 1642.36 | AC23: 1921.51 | AD23: 2248.4 | AG23: Financial assets | AO23: Inventories | AP23: 5156.6 | AQ23: 4995.6 | AR23: 6441.7 | AS23: 7822.8 | AT23: 9138.6
A24: Other Financial assets | B24: 659.6 | C24: 642.7 | D24: 2593 | E24: 2193.4 | F24: 1980.1 | G24: 1731.2 | I24: Trade Receivables | J24: 6928.28 | K24: 6007.76 | L24: 6373.95 | M24: 7028.02 | N24: 7459.4 | O24: 8279.7 | Q24: Other investments | R24: 10861.54 | S24: 19051.19 | T24: 22709.22 | U24: 18838.31 | V24: 14253 | W24: 27199 | Y24: Financial assets | AG24: Investments | AO24: Financial assets
A25: Current tax assets (net) | B25: 527.2 | C25: 540.7 | D25: 0 | E25: 0 | F25: 0 | G25: 0 | I25: Cash and Cash Equivalents | J25: 4745.03 | K25: 3374.59 | L25: 3487.59 | M25: 3493.41 | N25: 4530.1 | O25: 4923.89 | Q25: Trade receivables | R25: 11172.69 | S25: 12679.08 | T25: 12442.12 | U25: 15737.97 | V25: 16952 | W25: 13248 | Y25: Trade receivables | Z25: 1454.36 | AA25: 1035.97 | AB25: 1155.24 | AC25: 1256.42 | AD25: 1839.42 | AG25: Investments of life insurance business | AH25: 918.21 | AI25: 633.58 | AJ25: 711.54 | AK25: 603.25 | AL25: 258.9 | AM25: 318.27 | AO25: Investments | AP25: 0.6 | AQ25: 1.2 | AR25: 1.2 | AS25: 2.9 | AT25: 98.6
A26: Other current assets | B26: 797.4 | C26: 1546.2 | D26: 1460.8 | E26: 1766 | F26: 2656.5 | G26: 3810.3 | I26: Other bank balances | J26: 3165.87 | K26: 9477.4 | L26: 7630.02 | M26: 7780.02 | N26: 7482.65 | O26: 15690.95 | Q26: Cash and cash equivalents | R26: 18467.8 | S26: 31700.01 | T26: 38159.01 | U26: 31886.95 | V26: 40015 | W26: 34349 | Y26: Loans | Z26: 5306.84 | AA26: 5794.23 | AB26: 7299.24 | AC26: 10225.16 | AD26: 13417.26 | AG26: Other investments | AH26: 76.79 | AI26: 903.04 | AJ26: 0 | AK26: 0 | AL26: 0 | AM26: 0 | AO26: Trade receivables | AP26: 5178.4 | AQ26: 5693.1 | AR26: 6573.1 | AS26: 8513.5 | AT26: 15637.1
A27: Total current Assets | B27: =SUM(B17,B19:B26) -> 8440.6 | C27: =SUM(C17,C19:C26) -> 18544.3 | D27: =SUM(D17,D19:D26) -> 16793.4 | E27: =SUM(E17,E19:E26) -> 11615.6 | F27: =SUM(F17,F19:F26) -> 17762.4 | G27: =SUM(G17,G19:G26) -> 23252.2 | I27: Loans | J27: 27963.68 | K27: 29119.55 | L27: 29242.26 | M27: 34684.81 | N27: 39060.13 | O27: 44644.77 | Q27: Bank Balances | R27: 15259.17 | S27: 15092.45 | T27: 2510.18 | U27: 5128.61 | V27: 5792 | W27: 6485 | Y27: Cash and cash equivalents | Z27: 1079.69 | AA27: 1573.76 | AB27: 1445.68 | AC27: 1851.19 | AD27: 2355.8 | AG27: Trade receivables | AH27: 1060.83 | AI27: 1076.2 | AJ27: 1097.85 | AK27: 1229.55 | AL27: 1382.27 | AM27: 1686.39 | AO27: Cash and cash equivalents | AP27: 4868.8 | AQ27: 5899.4 | AR27: 4877.5 | AS27: 4538.1 | AT27: 6743.2
A28: Total Assets | B28: =B15+B27 -> 63627.7 | C28: =C15+C27 -> 71282.7 | D28: =D15+D27 -> 74655.5 | E28: =E15+E27 -> 84596.9 | F28: =F15+F27 -> 110284.8 | G28: =G15+G27 -> 125620.2 | I28: Other Financial assets | J28: 1177.36 | K28: 1431.4 | L28: 1998.95 | M28: 1951.7 | N28: 2102.43 | O28: 3552.48 | Q28: Financial receivables | R28: 14245.3 | S28: 17868.09 | T28: 22095.35 | U28: 23417.31 | V28: 24070 | W28: 0 | Y28: Bank Balances | Z28: 27.88 | AA28: 83.09 | AB28: 89.93 | AC28: 27.92 | AD28: 69.93 | AG28: Cash and cash equivalents | AH28: 331.47 | AI28: 342.43 | AJ28: 189.11 | AK28: 131.78 | AL28: 322.99 | AM28: 180.82 | AO28: Bank Balances | AP28: 10.1 | AQ28: 6.8 | AR28: 121.9 | AS28: 160.6 | AT28: 242.5
A29: EQUITY AND LIABILITIES | I29: Current tax assets (net) | J29: 2561.29 | K29: 3079.98 | L29: 0 | M29: 56.6 | N29: 25.47 | O29: 0 | Q29: Loans and advances | R29: 935.25 | S29: 1749.4 | T29: 1671.93 | U29: 2302.84 | V29: 197 | W29: 72 | Y29: Other financial assets | Z29: 93.19 | AA29: 85.64 | AB29: 131.62 | AC29: 241.26 | AD29: 202.66 | AG29: Bank balances | AH29: 10.13 | AI29: 11.14 | AJ29: 9.88 | AK29: 8.53 | AL29: 7.52 | AM29: 7.2 | AO29: Loans | AP29: 31.3 | AQ29: 27.2 | AR29: 28.9 | AS29: 28.9 | AT29: 27.6
A30: Equity | I30: Other current assets | J30: 96.5 | K30: 0 | L30: 3969.53 | M30: 5209.99 | N30: 5380.35 | O30: 7203.08 | Q30: Other financial assets | R30: 4586.48 | S30: 5274.32 | T30: 3799.82 | U30: 2786.72 | V30: 8121 | W30: 18984 | Y30: Current tax assets (net) | Z30: 2.43 | AA30: 4.83 | AB30: 1.42 | AC30: 4.56 | AD30: 23.89 | AG30: Loans | AH30: 22.87 | AI30: 20.76 | AJ30: 0.28 | AK30: 0.26 | AL30: 0.36 | AM30: 0.34 | AO30: Other financial assets | AP30: 3088.2 | AQ30: 2420 | AR30: 3127.8 | AS30: 4021.3 | AT30: 5142.3
A31: Equity share capital | B31: 151 | C31: 151 | D31: 151 | E31: 151 | F31: 157.2 | G31: 157.2 | I31: Total current Assets | J31: =SUM(J21,J23:J30) -> 64045.43 | K31: =SUM(K21,K23:K30) -> 72137.91 | L31: =SUM(L21,L23:L30) -> 75148 | M31: =SUM(M21,M23:M30) -> 91325.44 | N31: =SUM(N21,N23:N30) -> 98265.64 | O31: =SUM(O21,O23:O30) -> 126573.27 | Q31: Current tax assets (net) | R31: 142.28 | S31: 865.31 | T31: 259.84 | U31: 259.26 | V31: 101 | W31: 411 | Y31: Other current assets | Z31: 586.14 | AA31: 591.89 | AB31: =952.35+130.23 -> 1082.58 | AC31: =1304.34+191.92 -> 1496.26 | AD31: =1199.46+163.19 -> 1362.65 | AG31: Other financial assets | AH31: 376.26 | AI31: 418.95 | AJ31: 53.14 | AK31: 58.07 | AL31: 46.46 | AM31: 76.72 | AO31: Other current assets | AP31: 1131.4 | AQ31: 1205.2 | AR31: 1444.1 | AS31: 1691.1 | AT31: 3242.3
A32: Other equity | B32: 49262 | C32: 52349.6 | D32: 55182.5 | E32: 61640.3 | F32: 83824.8 | G32: 93889.5 | I32: Total Assets | J32: =J19+J31 -> 167006.66 | K32: =K19+K31 -> 166462.49 | L32: =L19+L31 -> 174112.8 | M32: =M19+M31 -> 205891.77 | N32: =N19+N31 -> 236300.73 | O32: =O19+O31 -> 277586.27 | Q32: Assets classified as held-for-sale | R32: 194.43 | S32: 220.8 | T32: 523.85 | U32: 827.78 | V32: 674 | W32: 514 | Y32: Total current assets | Z32: =SUM(Z23,Z25:Z31) -> 9739 | AA32: =SUM(AA23,AA25:AA31) -> 10536.84 | AB32: =SUM(AB23,AB25:AB31) -> 12848.07 | AC32: =SUM(AC23,AC25:AC31) -> 17024.28 | AD32: =SUM(AD23,AD25:AD31) -> 21520.01 | AE32: =SUM(AE23,AE25:AE31) -> 0 | AG32: Other current assets | AH32: 198.83 | AI32: 212.97 | AJ32: 204.16 | AK32: 223.15 | AL32: =347.93+16.56 -> 364.49 | AM32: =352.29+17.12 -> 369.41 | AO32: Total current assets | AP32: =SUM(AP25:AP31,AP23) -> 19465.4 | AQ32: =SUM(AQ25:AQ31,AQ23) -> 20248.5 | AR32: =SUM(AR25:AR31,AR23) -> 22616.2 | AS32: =SUM(AS25:AS31,AS23) -> 26779.2 | AT32: =SUM(AT25:AT31,AT23) -> 40272.2 | AU32: =SUM(AU25:AU31,AU23) -> 0
A33: Equity attributable to owners of the company | B33: =SUM(B31:B32) -> 49413 | C33: =SUM(C31:C32) -> 52500.6 | D33: =SUM(D31:D32) -> 55333.5 | E33: =SUM(E31:E32) -> 61791.3 | F33: =SUM(F31:F32) -> 83982 | G33: =SUM(G31:G32) -> 94046.7 | I33: EQUITY AND LIABILITIES | Q33: Other assets | R33: 6264.91 | S33: 6298.4 | T33: 7565.88 | U33: 9587.33 | V33: 10429 | W33: 11794 | Y33: Total Assets | Z33: =Z21+Z32 -> 19358.82 | AA33: =AA21+AA32 -> 21992.69 | AB33: =AB21+AB32 -> 27071.89 | AC33: =AC21+AC32 -> 35232.91 | AD33: =AD21+AD32 -> 42220.46 | AE33: =AE21+AE32 -> 0 | AG33: Total current assets | AH33: =SUM(AH22,AH25:AH32) -> 5409.95 | AI33: =SUM(AI22,AI25:AI32) -> 6255.93 | AJ33: =SUM(AJ22,AJ25:AJ32) -> 5121.25 | AK33: =SUM(AK22,AK25:AK32) -> 5690.99 | AL33: =SUM(AL22,AL25:AL32) -> 6251.52 | AM33: =SUM(AM22,AM25:AM32) -> 7204.05 | AO33: Assets classified as held for distribution | AP33: 0 | AQ33: 1779 | AR33: 0 | AS33: 0
A34: Non-controlling interest | B34: 19.2 | C34: 0 | D34: 0 | E34: 0 | F34: 0 | G34: 0 | I34: Equity | Q34: Total Current assets | R34: =SUM(R22,R24:R33) -> 119586.73 | S34: =SUM(S22,S24:S33) -> 146887.64 | T34: =SUM(T22,T24:T33) -> 146977.54 | U34: =SUM(U22,U24:U33) -> 151528.47 | V34: =SUM(V22,V24:V33) -> 168392 | W34: =SUM(W22,W24:W33) -> 160325 | Y34: EQUITY AND LIABILITIES | AG34: Total Assets | AH34: =AH20+AH33 -> 24367.59 | AI34: =AI20+AI33 -> 28687.11 | AJ34: =AJ20+AJ33 -> 13910.61 | AK34: =AK20+AK33 -> 14767.68 | AL34: =AL20+AL33 -> 18150.02 | AM34: =AM20+AM33 -> 21396.23 | AO34: Total assets | AP34: =AP21+AP32+AP33 -> 45495.8 | AQ34: =AQ21+AQ32+AQ33 -> 48085 | AR34: =AR21+AR32+AR33 -> 56270.1 | AS34: =AS21+AS32+AS33 -> 61851.7 | AT34: =AT21+AT32+AT33 -> 85021.7 | AU34: =AU21+AU32+AU33 -> 0
A35: Total Equity | B35: =B33+B34 -> 49432.2 | C35: =C33+C34 -> 52500.6 | D35: =D33+D34 -> 55333.5 | E35: =E33+E34 -> 61791.3 | F35: =F33+F34 -> 83982 | G35: =G33+G34 -> 94046.7 | I35: Equity share capital | J35: 554.28 | K35: 555.15 | L35: 556.06 | M35: 556.82 | N35: 557.38 | O35: 558.15 | Q35: Total Assets | R35: =R20+R34 -> 322120.74 | S35: =S20+S34 -> 343125.8 | T35: =T20+T34 -> 330619.93 | U35: =U20+U34 -> 336081.38 | V35: =V20+V34 -> 370664 | W35: =W20+W34 -> 378642 | Y35: Equity | AG35: EQUITY AND LIABILITIES | AO35: EQUITY AND LIABILITIES
A36: Liabilities | I36: Other equity | J36: 39415.03 | K36: 41026.77 | L36: 46566.58 | M36: 55808.97 | N36: 65633.17 | O36: 76480.71 | Q36: EQUITY AND LIABILITIES | Y36: Equity share capital | Z36: 47.51 | AA36: 47.51 | AB36: 47.51 | AC36: 47.51 | AD36: 47.51 | AG36: Equity | AO36: Equity
A37: Non-current liabilities | I37: Equity attributable to owners of the company | J37: =SUM(J35:J36) -> 39969.31 | K37: =SUM(K35:K36) -> 41581.92 | L37: =SUM(L35:L36) -> 47122.64 | M37: =SUM(M35:M36) -> 56365.79 | N37: =SUM(N35:N36) -> 66190.55 | O37: =SUM(O35:O36) -> 77038.86 | Q37: Equity | Y37: Other equity | Z37: 3234.59 | AA37: 3779.1 | AB37: 4351.94 | AC37: 5457.49 | AD37: 6736 | AG37: Equity share capital | AH37: 85 | AI37: 85 | AJ37: 85 | AK37: 85 | AL37: 85 | AM37: 85 | AO37: Equity share capital | AP37: 315.8 | AQ37: 315.8 | AR37: 451.8 | AS37: 677.6 | AT37: 677.6
A38: Financial Liabilities | I38: Non-controlling interest | J38: 7691.74 | K38: 9070.31 | L38: 9702.62 | M38: 10716.32 | N38: 11318.79 | O38: 12059.14 | Q38: Equity share capital | R38: 719.54 | S38: 765.81 | T38: 765.88 | U38: 766.02 | V38: 767 | W38: 736 | Y38: Equity attributable to owners of the company | Z38: =SUM(Z36:Z37) -> 3282.1 | AA38: =SUM(AA36:AA37) -> 3826.61 | AB38: =SUM(AB36:AB37) -> 4399.45 | AC38: =SUM(AC36:AC37) -> 5505 | AD38: =SUM(AD36:AD37) -> 6783.51 | AE38: =SUM(AE36:AE37) -> 0 | AG38: Other equity | AH38: 6382.32 | AI38: 7187.27 | AJ38: 10498.74 | AK38: 11047.28 | AL38: 12801.34 | AM38: 13828.48 | AO38: Other equity
A39: Borrowings | B39: 5.4 | C39: 2.8 | D39: 0 | E39: 0 | F39: 0 | G39: 0 | I39: Total Equity | J39: =J37+J38 -> 47661.05 | K39: =K37+K38 -> 50652.23 | L39: =L37+L38 -> 56825.26 | M39: =M37+M38 -> 67082.11 | N39: =N37+N38 -> 77509.34 | O39: =O37+O38 -> 89098 | Q39: Other equity | R39: 62358.99 | S39: 54480.91 | T39: 43795.36 | U39: 44555.77 | V39: 84151 | W39: 115408 | Y39: Non-controlling interest | Z39: 320.94 | AA39: 387.9 | AB39: 653.56 | AC39: 404.85 | AD39: 727.6 | AG39: Equity attributable to owners of the company | AH39: =SUM(AH37:AH38) -> 6467.32 | AI39: =SUM(AI37:AI38) -> 7272.27 | AJ39: =SUM(AJ37:AJ38) -> 10583.74 | AK39: =SUM(AK37:AK38) -> 11132.28 | AL39: =SUM(AL37:AL38) -> 12886.34 | AM39: =SUM(AM37:AM38) -> 13913.48 | AO39: Reserves and Surplus | AP39: 10395.8 | AQ39: 11441.9 | AR39: 19451.1 | AS39: 20562.8 | AT39: 24778.8
A40: Lease Liabilities | B40: 59.8 | C40: 39.2 | D40: 32.9 | E40: 24.9 | F40: 67.7 | G40: 53.8 | I40: Liabilities | Q40: Equity attributable to owners of the company | R40: =SUM(R38:R39) -> 63078.53 | S40: =SUM(S38:S39) -> 55246.72 | T40: =SUM(T38:T39) -> 44561.24 | U40: =SUM(U38:U39) -> 45321.79 | V40: =SUM(V38:V39) -> 84918 | W40: =SUM(W38:W39) -> 116144 | Y40: Total Equity | Z40: =Z38+Z39 -> 3603.04 | AA40: =AA38+AA39 -> 4214.51 | AB40: =AB38+AB39 -> 5053.01 | AC40: =AC38+AC39 -> 5909.85 | AD40: =AD38+AD39 -> 7511.11 | AE40: =AE38+AE39 -> 0 | AG40: Non-controlling interest | AH40: 46.94 | AI40: 46.22 | AJ40: 40.21 | AK40: 9.02 | AL40: 15.16 | AM40: 20.64 | AO40: Other reserves | AP40: 549.3 | AQ40: 802.9 | AR40: 685.4 | AS40: 1211.1 | AT40: 698.5
...

Sheet Income Statement
A1: INCOME STATEMENT | F1: #VALUE! | I1: INCOME STATEMENT | N1: #VALUE! | Q1: INCOME STATEMENT | V1: #VALUE! | Y1: INCOME STATEMENT | AD1: #VALUE! | AG1: INCOME STATEMENT | AL1: #VALUE! | AO1: INCOME STATEMENT | AT1: #VALUE!
A2: Particulars | B2: 2020 | C2: 2021 | D2: 2022 | E2: 2023 | F2: 2024 | G2: 2025 | I2: Particulars | J2: 2020 | K2: 2021 | L2: 2022 | M2: 2023 | N2: 2024 | O2: 2025 | Q2: Particulars | R2: 2020 | S2: 2021 | T2: 2022 | U2: 2023 | V2: 2024 | W2: 2025 | Y2: Particulars | Z2: 2020 | AA2: 2021 | AB2: 2022 | AC2: 2023 | AD2: 2024 | AE2: NA | AG2: Particulars | AH2: 2020 | AI2: 2021 | AJ2: 2022 | AK2: 2023 | AL2: 2024 | AM2: 2025 | AO2: Particulars | AP2: 2020 | AQ2: 2021 | AR2: 2022 | AS2: 2023 | AT2: 2024 | AU2: NA
A3: INCOME | I3: INCOME | Q3: INCOME | Y3: INCOME | AG3: INCOME | AO3: INCOME
A4: Revenue from operations | B4: 75660 | C4: 70372 | D4: 88329.8 | E4: 117571.3 | F4: 134937.8 | G4: 145115.2 | I4: Revenue from operations | J4: 75381.93 | K4: 74277.78 | L4: 90170.57 | M4: 121268.55 | N4: 138279.3 | O4: 158749.75 | Q4: Revenue from operations | R4: 258594.36 | S4: 246972.17 | T4: 275235.23 | U4: 342874.59 | V4: 431212 | W4: 436821 | Y4: Revenue from operations | Z4: 18849.31 | AA4: 19420.82 | AB4: 24355.31 | AC4: 31973.99 | AD4: 39144.74 | AG4: Revenue from operations | AH4: 14471.01 | AI4: 15296.89 | AJ4: 12789.22 | AK4: 15078.16 | AL4: 16769.73 | AM4: 17237.85 | AO4: Revenue from operations | AP4: 60278.3 | AQ4: 56951.3 | AR4: 62936.7 | AS4: 77870.7 | AT4: 97779.4
A5: Other income | B5: 3334.4 | C5: 2936.3 | D5: 1744.7 | E5: 2140.7 | F5: =5994.8+3854.7 -> 9849.5 | G5: =6784.9+4750.4 -> 11535.3 | I5: Other income | J5: 1028.69 | K5: 1033.11 | L5: 934.51 | M5: 1206.49 | N5: =798.97+2176.42 -> 2975.39 | O5: =461.07+2181.05 -> 2642.12 | Q5: Other Operating revenues | R5: 2473.61 | S5: 2822.58 | T5: 3218.39 | U5: 3092.38 | V5: 2804 | W5: 2874 | Y5: Other income | Z5: 51.83 | AA5: 47.22 | AB5: 32.87 | AC5: 138 | AD5: 105.82 | AG5: Other income | AH5: 61.88 | AI5: 70.45 | AJ5: 62.07 | AK5: 124.74 | AL5: 89.95 | AM5: 112.8 | AO5: Other operating revenue | AP5: 450.6 | AQ5: 418.6 | AR5: 837.3 | AS5: 830 | AT5: 912.3
A6: Total income | B6: =B4+B5 -> 78994.4 | C6: =C4+C5 -> 73308.3 | D6: =D4+D5 -> 90074.5 | E6: =E4+E5 -> 119712 | F6: =F4+F5 -> 144787.3 | G6: =G4+G5 -> 156650.5 | I6: Total income | J6: =SUM(J4:J5) -> 76410.62 | K6: =SUM(K4:K5) -> 75310.89 | L6: =SUM(L4:L5) -> 91105.08 | M6: =SUM(M4:M5) -> 122475.04 | N6: =SUM(N4:N5) -> 141254.69 | O6: =SUM(O4:O5) -> 161391.87 | Q6: Total revenue from operations | R6: =SUM(R4:R5) -> 261067.97 | S6: =SUM(S4:S5) -> 249794.75 | T6: =SUM(T4:T5) -> 278453.62 | U6: =SUM(U4:U5) -> 345966.97 | V6: =SUM(V4:V5) -> 434016 | W6: =SUM(W4:W5) -> 439695 | Y6: Total income | Z6: =Z4+Z5 -> 18901.14 | AA6: =AA4+AA5 -> 19468.04 | AB6: =AB4+AB5 -> 24388.18 | AC6: =AC4+AC5 -> 32111.99 | AD6: =AD4+AD5 -> 39250.56 | AE6: =AE4+AE5 -> 0 | AG6: Total income | AH6: =SUM(AH4:AH5) -> 14532.89 | AI6: =SUM(AI4:AI5) -> 15367.34 | AJ6: =SUM(AJ4:AJ5) -> 12851.29 | AK6: =SUM(AK4:AK5) -> 15202.9 | AL6: =SUM(AL4:AL5) -> 16859.68 | AM6: =SUM(AM4:AM5) -> 17350.65 | AO6: Total revenue from operations | AP6: =SUM(AP4:AP5) -> 60728.9 | AQ6: =SUM(AQ4:AQ5) -> 57369.9 | AR6: =SUM(AR4:AR5) -> 63774 | AS6: =SUM(AS4:AS5) -> 78700.7 | AT6: =SUM(AT4:AT5) -> 98691.7 | AU6: =SUM(AU4:AU5) -> 0
A7: EXPENSES | I7: EXPENSES | Q7: Other income (includes government grants) | R7: 2973.15 | S7: 2643.19 | T7: 3053.63 | U7: 4633.18 | V7: 5692 | W7: 6244 | Y7: EXPENSES | AG7: EXPENSES | AO7: Other income | AP7: 224.6 | AQ7: 229.3 | AR7: 257.7 | AS7: 257 | AT7: 187.6
A8: Cost of material consumed | B8: 34634.8 | C8: 33296.4 | D8: 39739.6 | E8: 46669.6 | F8: 45939.7 | G8: 52927.1 | I8: Cost of materials consumed | J8: 32321.8 | K8: 32797.56 | L8: 46265.48 | M8: 68477.97 | N8: 77848.82 | O8: 88111.05 | Q8: Total income | R8: =R6+R7 -> 264041.12 | S8: =S6+S7 -> 252437.94 | T8: =T6+T7 -> 281507.25 | U8: =U6+U7 -> 350600.15 | V8: =V6+V7 -> 439708 | W8: =W6+W7 -> 445939 | Y8: Cost of materials consumed | Z8: 12050.84 | AA8: 12700.73 | AB8: 15938.65 | AC8: 20096.24 | AD8: 23717.91 | AG8: Cost of materials consumed | AH8: 6567.39 | AI8: 6645.5 | AJ8: 8882.49 | AK8: 10585.52 | AL8: 11481.61 | AM8: 11697.3 | AO8: Total income | AP8: =SUM(AP6:AP7) -> 60953.5 | AQ8: =SUM(AQ6:AQ7) -> 57599.2 | AR8: =SUM(AR6:AR7) -> 64031.7 | AS8: =SUM(AS6:AS7) -> 78957.7 | AT8: =SUM(AT6:AT7) -> 98879.3 | AU8: =SUM(AU6:AU7) -> 0
A9: Purchase of stock-in-trade | B9: 18767.2 | C9: 17254.1 | D9: 26397.5 | E9: 39985.1 | F9: 55109.9 | G9: 56434 | I9: Purchase of stock-in-trade | J9: 5273.5 | K9: 5473.64 | L9: 6399.37 | M9: 7541.9 | N9: 7221.25 | O9: 7643.85 | Q9: EXPENSES | Y9: Purchase of stock in trade | Z9: 259.2 | AA9: 224.92 | AB9: 579.04 | AC9: 890.95 | AD9: 1011.69 | AG9: Purchase of stock-in-trade | AH9: 54.25 | AI9: 41.77 | AJ9: 63.92 | AK9: 77.77 | AL9: 216.31 | AM9: 119.62 | AO9: EXPENSES
A10: Change in inventories of finished good, work-in-progress and SIT | B10: -238.7 | C10: 273.6 | D10: -93.1 | E10: -403.9 | F10: -442.9 | G10: -890.3 | I10: Changes in inventory of finished goods, stock in trade and work in progress | J10: 826.62 | K10: 135.59 | L10: -861.66 | M10: -2032.31 | N10: -1455.32 | O10: -12.18 | Q10: Cost of materials consumed | Y10: Changes in inventories of finished goods, stock-in-trade and work in progress | Z10: 6.73 | AA10: -0.19 | AB10: -260.4 | AC10: -140.93 | AD10: -324.35 | AG10: Changes in inventories of finished goods, work-in-progress and stock-in-trade | AH10: -219.14 | AI10: 0.13 | AJ10: -269.63 | AK10: -310 | AL10: -300.33 | AM10: -219.5 | AO10: Cost of materials consumed | AP10: 34285 | AQ10: 32675.8 | AR10: 36804.9 | AS10: 45175.5 | AT10: 53899.7
A11: Employee benefit expenses | B11: 3416.2 | C11: 3431.6 | D11: 4051.4 | E11: 4634.6 | F11: 5478.4 | G11: 6137 | I11: Employee benefit expense | J11: 8214.82 | K11: 7813.26 | L11: 8386.74 | M11: 9677.95 | N11: 10624.33 | O11: 11126.17 | Q11: Cost of materials consumed | R11: 152968.74 | S11: 141392.43 | T11: 159598.06 | U11: 208218.05 | V11: 249278 | W11: 241148 | Y11: Employee benefit expense | Z11: 1539.35 | AA11: 1689.37 | AB11: 2124.03 | AC11: 2890.25 | AD11: 3385.19 | AG11: Employee benefit expenses | AH11: 1118.93 | AI11: 1122.49 | AJ11: 906.36 | AK11: 1002.62 | AL11: 1166.63 | AM11: 1296.31 | AO11: Purchase of stock-in-trade | AP11: 710 | AQ11: 103.3 | AR11: 182.8 | AS11: 465.4 | AT11: 468.2
A12: Finance costs | B12: 134.2 | C12: 101.8 | D12: 126.6 | E12: 187 | F12: 193.2 | G12: 193.1 | I12: Finance cost | J12: 6021.15 | K12: 6102.22 | L12: 5018.05 | M12: 5829.7 | N12: 7488.21 | O12: 9083.39 | Q12: Basis adjustment on hedge accounted derivatives | R12: -297.27 | S12: -35.16 | T12: 1322.5 | U12: 726.26 | V12: 0 | W12: 0 | Y12: Finance costs | Z12: 854.54 | AA12: 881.49 | AB12: 940.22 | AC12: 1367.89 | AD12: 1927.72 | AG12: Other expenses | AH12: =1622.86+3880.66 -> 5503.52 | AI12: =2346.75+3559.83 -> 5906.58 | AJ12: 1806.15 | AK12: 2133.72 | AL12: 2388.42 | AM12: 2546.09 | AO12: Change in inventories of finished goods, WIP and SIT | AP12: -26.2 | AQ12: -181.2 | AR12: -251.4 | AS12: -323.5 | AT12: 46.8
A13: Depreciation and ammortisation expenses | B13: 3528.4 | C13: 3034.1 | D13: 2789 | E13: 2825.7 | F13: 3022.3 | G13: 3159.3 | I13: Depreciation and amortisation expense | J13: 3366.68 | K13: 3378.11 | L13: 3507.5 | M13: 4356.81 | N13: 4723.78 | O13: 6073.65 | Q13: Purchase of products for sale | R13: 12228.35 | S13: 12250.09 | T13: 18374.77 | U13: 22306.95 | V13: 25043 | W13: 27802 | Y13: Depreciation and ammortisation expense | Z13: 556 | AA13: 564.82 | AB13: 742.86 | AC13: 858.86 | AD13: 975.12 | AG13: Total expenses | AH13: =SUM(AH8:AH12) -> 13024.95 | AI13: =SUM(AI8:AI12) -> 13716.47 | AJ13: =SUM(AJ8:AJ12) -> 11389.29 | AK13: =SUM(AK8:AK12) -> 13489.63 | AL13: =SUM(AL8:AL12) -> 14952.64 | AM13: =SUM(AM8:AM12) -> 15439.82 | AO13: Employee benefit expense | AP13: 14372.6 | AQ13: 14099.6 | AR13: 15374.6 | AS13: 17931.4 | AT13: 23538.5
A14: Other expenses | B14: 11889.6 | C14: 10837.5 | D14: 12672.7 | E14: 15805.5 | F14: 18635.2 | G14: 19824 | I14: Other expenses | J14: 15871.2 | K14: 14541.92 | L14: 15297.79 | M14: 17317.75 | N14: =32.92+19914.34 -> 19947.26 | O14: =30.84+21792.9 -> 21823.74 | Q14: Changes in inventories of finished goods, WIP and products for sale | R14: 2231.19 | S14: 4684.16 | T14: 1590.49 | U14: -4781.62 | V14: -1566 | W14: 2836 | Y14: Other expenses | Z14: 2720.14 | AA14: 2568.16 | AB14: 3219.36 | AC14: 4170.1 | AD14: 5810.89 | AG14: EBITDA | AH14: =AH6-AH13 -> 1507.94 | AI14: =AI6-AI13 -> 1650.87 | AJ14: =AJ6-AJ13 -> 1462 | AK14: =AK6-AK13 -> 1713.27 | AL14: =AL6-AL13 -> 1907.04 | AM14: =AM6-AM13 -> 1910.83 | AO14: Depreciation and amortisation expense | AP14: 2721 | AQ14: 2926 | AR14: 2958.2 | AS14: 3135.8 | AT14: 3810.5
A15: Vehicle/dies for own use | B15: -121.7 | C15: -72.8 | D15: -144.5 | E15: -137.3 | F15: -188.8 | G15: -316.9 | I15: (-) Amounts capitalised | J15: 317.58 | K15: 160.74 | L15: 0 | M15: 0 | N15: 0 | O15: 0 | Q15: Employee benefit expense | R15: 30438.6 | S15: 27648.48 | T15: 30808.52 | U15: 33654.7 | V15: 41990 | W15: 47767 | Y15: Total expenses | Z15: =SUM(Z8:Z14) -> 17986.8 | AA15: =SUM(AA8:AA14) -> 18629.3 | AB15: =SUM(AB8:AB14) -> 23283.76 | AC15: =SUM(AC8:AC14) -> 30133.36 | AD15: =SUM(AD8:AD14) -> 36504.17 | AE15: =SUM(AE8:AE14) -> 0 | AG15: Finance costs | AH15: 96.59 | AI15: 142.19 | AJ15: 60.93 | AK15: 73.84 | AL15: 116 | AM15: 153.03 | AO15: Finance cost | AP15: 592.8 | AQ15: 511.5 | AR15: 542.6 | AS15: 780.9 | AT15: 1811.2
A16: Total expenses | B16: =SUM(B8:B15) -> 72010 | C16: =SUM(C8:C15) -> 68156.3 | D16: =SUM(D8:D15) -> 85539.2 | E16: =SUM(E8:E15) -> 109566.3 | F16: =SUM(F8:F15) -> 127747 | G16: =SUM(G8:G15) -> 137467.3 | I16: Total expenses | J16: =SUM(J8:J14)-J15 -> 71578.19 | K16: =SUM(K8:K14)-K15 -> 70081.56 | L16: =SUM(L8:L14)-L15 -> 84013.27 | M16: =SUM(M8:M14)-M15 -> 111169.77 | N16: =SUM(N8:N14)-N15 -> 126398.33 | O16: =SUM(O8:O14)-O15 -> 143849.67 | Q16: Finance cost | R16: 7243.33 | S16: 8097.17 | T16: 9311.86 | U16: 10225.48 | V16: 7594 | W16: 5083 | Y16: Profit before exceptional items, share of net profit/loss from associates and tax | Z16: =Z6-Z15 -> 914.34 | AA16: =AA6-AA15 -> 838.74 | AB16: =AB6-AB15 -> 1104.42 | AC16: =AC6-AC15 -> 1978.63 | AD16: =AD6-AD15 -> 2746.39 | AE16: =AE6-AE15 -> 0 | AG16: Depreciation and ammortisation expenses | AH16: 417.58 | AI16: 433.65 | AJ16: 439.52 | AK16: 502.12 | AL16: 560.42 | AM16: 582.34 | AO16: Other expenses | AP16: 6733.5 | AQ16: 6313.5 | AR16: 6963.7 | AS16: 9244.2 | AT16: 11451.9
A17: Share of profit of associates | B17: 117.5 | C17: 158.8 | D17: 146.4 | E17: 155.8 | F17: 0 | G17: 0 | I17: Profit before exceptional items, share of profit of associates and joint ventures and tax | J17: =J6-J16 -> 4832.43 | K17: =K6-K16 -> 5229.33 | L17: =L6-L16 -> 7091.81 | M17: =M6-M16 -> 11305.27 | N17: =N6-N16 -> 14856.36 | O17: =O6-O16 -> 17542.2 | Q17: Foreign exchange gain/loss (net) | R17: 1738.74 | S17: -1732.15 | T17: 78.68 | U17: -103.88 | V17: 15 | W17: -922 | Y17: Share of net profit/loss from associates using equity method | Z17: -8.59 | AA17: -7.75 | AB17: 2.49 | AC17: -40.73 | AD17: -43.47 | AG17: Interest, depreciation and ammortisation expenses | AH17: =SUM(AH15:AH16) -> 514.17 | AI17: =SUM(AI15:AI16) -> 575.84 | AJ17: =SUM(AJ15:AJ16) -> 500.45 | AK17: =SUM(AK15:AK16) -> 575.96 | AL17: =SUM(AL15:AL16) -> 676.42 | AM17: =SUM(AM15:AM16) -> 735.37 | AO17: Total expenses | AP17: =SUM(AP10:AP16) -> 59388.7 | AQ17: =SUM(AQ10:AQ16) -> 56448.5 | AR17: =SUM(AR10:AR16) -> 62575.4 | AS17: =SUM(AS10:AS16) -> 76409.7 | AT17: =SUM(AT10:AT16) -> 95026.8 | AU17: =SUM(AU10:AU16) -> 0
A18: Share of profit of joint ventures | B18: 0.9 | C18: 10.2 | D18: 15.5 | E18: 21.6 | F18: 0 | G18: 0 | I18: Exceptional items (net) | J18: -1171.28 | K18: -1158.26 | L18: 414.17 | M18: 1249.52 | N18: 0 | O18: 0 | Q18: Depreciation and ammortisation expense | R18: 21425.43 | S18: 23546.71 | T18: 24835.69 | U18: 24860.36 | V18: 27239 | W18: 23256 | Y18: Profit before exceptional items and tax | Z18: =Z16+Z17 -> 905.75 | AA18: =AA16+AA17 -> 830.99 | AB18: =AB16+AB17 -> 1106.91 | AC18: =AC16+AC17 -> 1937.9 | AD18: =AD16+AD17 -> 2702.92 | AE18: =AE16+AE17 -> 0 | AG18: Share of loss of equity accounted investees, net of tax | AH18: -0.19 | AI18: -0.64 | AJ18: -0.94 | AK18: 0.28 | AL18: 0.55 | AM18: 0.5 | AO18: Profit before exceptional items, share of profit of investments accounted for using equity method and tax | AP18: =AP8-AP17 -> 1564.8 | AQ18: =AQ8-AQ17 -> 1150.7 | AR18: =AR8-AR17 -> 1456.3 | AS18: =AS8-AS17 -> 2548 | AT18: =AT8-AT17 -> 3852.5 | AU18: =AU8-AU17 -> 0
A19: Profit/Loss before tax | B19: =(B6-B16)+B17+B18 -> 7102.8 | C19: =(C6-C16)+C17+C18 -> 5321 | D19: =(D6-D16)+D17+D18 -> 4697.2 | E19: =(E6-E16)+E17+E18 -> 10323.1 | F19: =(F6-F16)+F17+F18 -> 17040.3 | G19: =(G6-G16)+G17+G18 -> 19183.2 | I19: Share of profit associates and joint ventures, (net) | J19: 1027.28 | K19: 1276.66 | L19: 1855.79 | M19: 1505.44 | N19: 1121.43 | O19: 1537.42 | Q19: Product development/engineering expenses | R19: 4188.49 | S19: 5226.63 | T19: 9209.5 | U19: 10661.96 | V19: 10959 | W19: 10716 | Y19: Exceptional items | Z19: -40.33 | AA19: -9.36 | AB19: -40.12 | AC19: -1.87 | AD19: 0 | AG19: Profit before exceptional items and tax | AH19: =AH14-AH17+AH18 -> 993.58 | AI19: =AI14-AI17+AI18 -> 1074.39 | AJ19: =AJ14-AJ17+AJ18 -> 960.61 | AK19: =AK14-AK17+AK18 -> 1137.59 | AL19: =AL14-AL17+AL18 -> 1231.17 | AM19: =AM14-AM17+AM18 -> 1175.96 | AO19: Exceptional income/expenses | AP19: 0 | AQ19: -62.3 | AR19: 48.1 | AS19: 99.5 | AT19: -249.9
A20: Tax expense | I20: Profit before tax | J20: =SUM(J17:J19) -> 4688.43 | K20: =SUM(K17:K19) -> 5347.73 | L20: =SUM(L17:L19) -> 9361.77 | M20: =SUM(M17:M19) -> 14060.23 | N20: =SUM(N17:N19) -> 15977.79 | O20: =SUM(O17:O19) -> 19079.62 | Q20: Other expenses | R20: 57087.46 | S20: 40921.97 | T20: =47133.85+14.45 -> 47148.3 | U20: =61785.96+13.75 -> 61799.71 | V20: =77198+48 -> 77246 | W20: =85399-84 -> 85315 | Y20: Profit before tax | Z20: =SUM(Z18:Z19) -> 865.42 | AA20: =SUM(AA18:AA19) -> 821.63 | AB20: =SUM(AB18:AB19) -> 1066.79 | AC20: =SUM(AC18:AC19) -> 1936.03 | AD20: =SUM(AD18:AD19) -> 2702.92 | AE20: =SUM(AE18:AE19) -> 0 | AG20: Exceptional items | AH20: -21.7 | AI20: 0 | AJ20: 0 | AK20: 0 | AL20: 0 | AM20: 0 | AO20: Group's share in net profit/loss of associates and Joint ventures | AP20: 57.5 | AQ20: 84.9 | AR20: 16 | AS20: -43.7 | AT20: 237.6
A21: Current tax | B21: 1376.5 | C21: 1156.2 | D21: 1431 | E21: 2249.6 | F21: 3631.1 | G21: 3841.8 | I21: Tax expense | Q21: Amount transferred to capital and other account | R21: -17503.4 | S21: -12849.13 | T21: -14397.29 | U21: -18434.84 | V21: -26758 | W21: -31105 | Y21: Tax expense | AG21: Profit before tax | AH21: =AH19+AH20 -> 971.88 | AI21: =AI19+AI20 -> 1074.39 | AJ21: =AJ19+AJ20 -> 960.61 | AK21: =AK19+AK20 -> 1137.59 | AL21: =AL19+AL20 -> 1231.17 | AM21: =AM19+AM20 -> 1175.96 | AO21: Profit/Loss before tax from continuing operations | AP21: =AP18+AP19+AP20 -> 1622.3 | AQ21: =AQ18+AQ19+AQ20 -> 1173.3 | AR21: =AR18-AR19+AR20 -> 1424.2 | AS21: =AS18-AS19+AS20 -> 2404.8 | AT21: =AT18+AT19+AT20 -> 3840.2 | AU21: =AU18-AU19+AU20 -> 0
A22: Deferred tax | B22: 48.7 | C22: -224.3 | D22: -613.3 | E22: -137.5 | F22: 199.9 | G22: 1386.2 | I22: Current tax | J22: 2314.16 | K22: 2014.89 | L22: -1868.1 | M22: -2742.04 | N22: -3597.39 | O22: -4851.93 | Q22: Total expenses | R22: =SUM(R11:R21) -> 271749.66 | S22: =SUM(S11:S21) -> 249151.2 | T22: =SUM(T11:T21) -> 287881.08 | U22: =SUM(U11:U21) -> 349133.13 | V22: =SUM(V11:V21) -> 411040 | W22: =SUM(W11:W21) -> 411896 | Y22: Current tax | Z22: 294.65 | AA22: 249.76 | AB22: 364.55 | AC22: 703.46 | AD22: 1012.63 | AG22: Tax expense | AO22: Tax expenses
A23: Total tax expense | B23: =SUM(B21:B22) -> 1425.2 | C23: =SUM(C21:C22) -> 931.9 | D23: =SUM(D21:D22) -> 817.7 | E23: =SUM(E21:E22) -> 2112.1 | F23: =SUM(F21:F22) -> 3831 | G23: =SUM(G21:G22) -> 5228 | I23: Deferred tax | J23: -338.55 | K23: -369.08 | L23: -240.66 | M23: 56.29 | N23: -110.58 | O23: -154.52 | Q23: Profit/loss before exceptional items and tax | R23: =R8-R22 -> -7708.54 | S23: =S8-S22 -> 3286.74 | T23: =T8-T22 -> -6373.83 | U23: =U8-U22 -> 1467.02 | V23: =V8-V22 -> 28668 | W23: =W8-W22 -> 34043 | Y23: Deferred tax | Z23: -76.03 | AA23: -35.63 | AB23: -28.64 | AC23: -76.89 | AD23: -88.25 | AG23: Current tax | AH23: 288.02 | AI23: 291.24 | AJ23: 265.86 | AK23: 327.99 | AL23: 393.98 | AM23: 394.41 | AO23: Current tax | AP23: 775.5 | AQ23: 606.6 | AR23: 731.5 | AS23: 940.2 | AT23: 1262.7
A24: Profit/Loss for the year | B24: =B19-B23 -> 5677.6 | C24: =C19-C23 -> 4389.1 | D24: =D19-D23 -> 3879.5 | E24: =E19-E23 -> 8211 | F24: =F19-F23 -> 13209.3 | G24: =G19-G23 -> 13955.2 | I24: Total tax expense | J24: =SUM(J22:J23) -> 1975.61 | K24: =SUM(K22:K23) -> 1645.81 | L24: =SUM(L22:L23) -> -2108.76 | M24: =SUM(M22:M23) -> -2685.75 | N24: =SUM(N22:N23) -> -3707.97 | O24: =SUM(O22:O23) -> -5006.45 | Q24: Exceptional items | Y24: Total tax expense | Z24: =SUM(Z22:Z23) -> 218.62 | AA24: =SUM(AA22:AA23) -> 214.13 | AB24: =SUM(AB22:AB23) -> 335.91 | AC24: =SUM(AC22:AC23) -> 626.57 | AD24: =SUM(AD22:AD23) -> 924.38 | AE24: =SUM(AE22:AE23) -> 0 | AG24: Deferred tax | AH24: -78.62 | AI24: -19.95 | AJ24: 0.44 | AK24: -13.17 | AL24: -45.63 | AM24: -18.95 | AO24: Deferred tax expense | AP24: -87.4 | AQ24: -676 | AR24: -124.6 | AS24: -205 | AT24: -442.1
I25: Profit/loss for the year from continuing operations | J25: =J20-J24 -> 2712.82 | K25: =K20-K24 -> 3701.92 | L25: =L20+L24 -> 7253.01 | M25: =M20+M24 -> 11374.48 | N25: =N20+N24 -> 12269.82 | O25: =O20+O24 -> 14073.17 | Q25: Defined benefit pension plan amendment past service cost | R25: 0 | S25: 84.81 | T25: 0 | U25: -1495.07 | V25: -700 | W25: -287 | Y25: Profit for the year | Z25: =Z20-Z24 -> 646.8 | AA25: =AA20-AA24 -> 607.5 | AB25: =AB20-AB24 -> 730.88 | AC25: =AC20-AC24 -> 1309.46 | AD25: =AD20-AD24 -> 1778.54 | AE25: =AE20-AE24 -> 0 | AG25: Total tax expense | AH25: =SUM(AH23:AH24) -> 209.4 | AI25: =SUM(AI23:AI24) -> 271.29 | AJ25: =SUM(AJ23:AJ24) -> 266.3 | AK25: =SUM(AK23:AK24) -> 314.82 | AL25: =SUM(AL23:AL24) -> 348.35 | AM25: =SUM(AM23:AM24) -> 375.46 | AO25: Total tax expense | AP25: =SUM(AP23:AP24) -> 688.1 | AQ25: =SUM(AQ23:AQ24) -> -69.4 | AR25: =SUM(AR23:AR24) -> 606.9 | AS25: =SUM(AS23:AS24) -> 735.2 | AT25: =SUM(AT23:AT24) -> 820.6 | AU25: =SUM(AU23:AU24) -> 0
B26: =B19+B12 -> 7237 | G26: =G19+G12 -> 19376.3 | I26: Profit/loss before tax from discontinued operations | J26: -3033.82 | K26: -2189.53 | L26: 0 | M26: 0 | N26: 0 | O26: 0 | Q26: Employee seperation cost | R26: 436.14 | S26: 459.9 | T26: 9.83 | U26: 1.45 | V26: 0 | W26: 0 | Y26: Profit/Loss attributable to non-controlling interest | Z26: -22.18 | AA26: -13.24 | AB26: 25.94 | AC26: 19.21 | AD26: -92.17 | AG26: Profit after tax | AH26: =AH21-AH25 -> 762.48 | AI26: =AI21-AI25 -> 803.1 | AJ26: =AJ21-AJ25 -> 694.31 | AK26: =AK21-AK25 -> 822.77 | AL26: =AL21-AL25 -> 882.82 | AM26: =AM21-AM25 -> 800.5 | AO26: Profit for the year from continuing operations | AP26: =AP21-AP25 -> 934.2 | AQ26: =AQ21-AQ25 -> 1242.7 | AR26: =AR21-AR25 -> 817.3 | AS26: =AS21-AS25 -> 1669.6 | AT26: =AT21-AT25 -> 3019.6 | AU26: =AU21-AU25 -> 0
I27: Tax expense of discontinued operations | J27: 0 | K27: 0 | L27: 0 | M27: 0 | N27: 0 | O27: 0 | Q27: Charge associated with change in JLR strategy | R27: 0 | S27: 14994.3 | T27: 0 | U27: 0 | V27: 0 | W27: 0 | Y27: Profit for the year attributable to owners | Z27: =SUM(Z25:Z26) -> 624.62 | AA27: =SUM(AA25:AA26) -> 594.26 | AB27: =SUM(AB25:AB26) -> 756.82 | AC27: =SUM(AC25:AC26) -> 1328.67 | AD27: =SUM(AD25:AD26) -> 1686.37 | AE27: =SUM(AE25:AE26) -> 0 | AO27: Discontinued operations:
I28: Profit/Loss after tax from discontinued operations | J28: =SUM(J26:J27) -> -3033.82 | K28: =SUM(K26:K27) -> -2189.53 | L28: =SUM(L26:L27) -> 0 | M28: =SUM(M26:M27) -> 0 | N28: =SUM(N26:N27) -> 0 | O28: =SUM(O26:O27) -> 0 | Q28: Write off/provision (reversal) for tangible/intangible assets | R28: -73.04 | S28: 114 | T28: 0 | U28: 229.96 | V28: 0 | W28: 0 | AG28: COGS | AH28: =IF(AH10>=0,AH8+AH9-AH10,AH8+AH9+AH10) -> 6402.5 | AI28: =IF(AI10>=0,AI8+AI9-AI10,AI8+AI9+AI10) -> 6687.14 | AJ28: =IF(AJ10>=0,AJ8+AJ9-AJ10,AJ8+AJ9+AJ10) -> 8676.78 | AK28: =IF(AK10>=0,AK8+AK9-AK10,AK8+AK9+AK10) -> 10353.29 | AL28: =IF(AL10>=0,AL8+AL9-AL10,AL8+AL9+AL10) -> 11397.59 | AM28: =IF(AM10>=0,AM8+AM9-AM10,AM8+AM9+AM10) -> 11597.42 | AO28: Revenue from operations | AP28: 3943.9 | AQ28: 4138.2 | AR28: 3973.5 | AS28: 0 | AT28: 0
I29: Profit/loss after tax from continuing and discontinued operations | J29: =J25+J28 -> -321 | K29: =K25+K28 -> 1512.39 | L29: =L25+L28 -> 7253.01 | M29: =M25+M28 -> 11374.48 | N29: =N25+N28 -> 12269.82 | O29: =O25+O28 -> 14073.17 | Q29: Impairment losses/reversal in passenger vehicle business | R29: 1418.64 | S29: -1182.41 | T29: 0 | U29: 0 | V29: 939 | W29: 550 | Y29: COGS | Z29: =IF(Z10>=0,Z8+Z9-Z10,Z8+Z9+Z10) -> 12303.31 | AA29: =IF(AA10>=0,AA8+AA9-AA10,AA8+AA9+AA10) -> 12925.46 | AB29: =IF(AB10>=0,AB8+AB9-AB10,AB8+AB9+AB10) -> 16257.29 | AC29: =IF(AC10>=0,AC8+AC9-AC10,AC8+AC9+AC10) -> 20846.26 | AD29: =IF(AD10>=0,AD8+AD9-AD10,AD8+AD9+AD10) -> 24405.25 | AG29: EBIT | AH29: =AH14-AH16 -> 1090.36 | AI29: =AI14-AI16 -> 1217.22 | AJ29: =AJ14-AJ16 -> 1022.48 | AK29: =AK14-AK16 -> 1211.15 | AL29: =AL14-AL16 -> 1346.62 | AM29: =AM14-AM16 -> 1328.49 | AO29: Other income | AP29: 6.4 | AQ29: 27.5 | AR29: 20.7 | AS29: 0 | AT29: 0
Q30: Provision/reversal for onerous contracts and supplier claims | R30: 777 | S30: -663 | T30: 0 | U30: -61.03 | V30: 0 | W30: 0 | Y30: EBIT | Z30: =Z16+Z12 -> 1768.88 | AA30: =AA16+AA12 -> 1720.23 | AB30: =AB16+AB12 -> 2044.64 | AC30: =AC16+AC12 -> 3346.52 | AD30: =AD16+AD12 -> 4674.11 | AO30: Total expenses | AP30: 3459.7 | AQ30: 3726.1 | AR30: 3509.6 | AS30: 0 | AT30: 0
J31: =J17+J12 -> 10853.58 | O31: =O17+O12 -> 26625.59 | Q31: Reversal for cost of closure of operation of a subsidiary | R31: -65.62 | S31: -46.58 | T31: -21.47 | U31: 0 | V31: 0 | W31: 0 | AO31: Profit before tax from discontinued operations | AP31: =(AP28+AP29)-AP30 -> 490.6 | AQ31: =(AQ28+AQ29)-AQ30 -> 439.6 | AR31: =(AR28+AR29)-AR30 -> 484.6 | AS31: =(AS28+AS29)-AS30 -> 0 | AT31: =(AT28+AT29)-AT30 -> 0 | AU31: =(AU28+AU29)-AU30 -> 0
Q32: Impairment in subsidiaries | R32: 353.2 | S32: 0 | T32: -86.26 | U32: -214.39 | V32: 0 | W32: 0 | AO32: Tax expense/credit of discontinued operations | AP32: 130.3 | AQ32: 112.9 | AR32: 120.4 | AS32: 0
Q33: Provision for loan given to a joint venture | R33: 25.12 | S33: 0 | T33: =301.34+428.66-2.52 -> 727.48 | U33: =9-60.45 -> -51.45 | V33: 0 | W33: 0 | AO33: Profit/Loss for the year from discontinued operations | AP33: =AP31-AP32 -> 360.3 | AQ33: =AQ31-AQ32 -> 326.7 | AR33: =AR31-AR32 -> 364.2 | AS33: =AS31-AS32 -> 0 | AT33: =AT31-AT32 -> 0 | AU33: =AU31-AU32 -> 0
Q34: Total exceptional items | R34: =SUM(R25:R33) -> 2871.44 | S34: =SUM(S25:S33) -> 13761.02 | T34: =SUM(T25:T33) -> 629.58 | U34: =SUM(U25:U33) -> -1590.53 | V34: =SUM(V25:V33) -> 239 | W34: =SUM(W25:W33) -> 263 | AO34: Profit/Loss for the year from continuing and discontinued operations | AP34: =AP26+AP33 -> 1294.5 | AQ34: =AQ26+AQ33 -> 1569.4 | AR34: =AR26+AR33 -> 1181.5 | AS34: =AS26+AS33 -> 1669.6 | AT34: =AT26+AT33 -> 3019.6 | AU34: =AU26+AU33 -> 0
Q35: Profit/Loss before tax | R35: =R23-R34 -> -10579.98 | S35: =S23-S34 -> -10474.28 | T35: =T23-T34 -> -7003.41 | U35: =U23-U34 -> 3057.55 | V35: =V23-V34 -> 28429 | W35: =W23-W34 -> 33780
Q36: Tax expense | AO36: COGS | AP36: =IF(AP12>=0,AP10+AP11-AP12,AP10+AP11+AP12) -> 34968.8 | AQ36: =IF(AQ12>=0,AQ10+AQ11-AQ12,AQ10+AQ11+AQ12) -> 32597.9 | AR36: =IF(AR12>=0,AR10+AR11-AR12,AR10+AR11+AR12) -> 36736.3 | AS36: =IF(AS12>=0,AS10+AS11-AS12,AS10+AS11+AS12) -> 45317.4 | AT36: =IF(AT12>=0,AT10+AT11-AT12,AT10+AT11+AT12) -> 54321.1
Q37: Current tax (including minimum alternate tax) | R37: 0 | S37: 0 | T37: 2669.98 | U37: 3258.35 | V37: 4937 | W37: 5023 | AO37: EBIT | AP37: =AP18+AP15 -> 2157.6 | AQ37: =AQ18+AQ15 -> 1662.2 | AR37: =AR18+AR15 -> 1998.9 | AS37: =AS18+AS15 -> 3328.9 | AT37: =AT18+AT15 -> 5663.7
Q38: Deferred tax | R38: 0 | S38: 0 | T38: 1561.31 | U38: -2554.29 | V38: -8961 | W38: 5479
Q39: Total tax expense | R39: =SUM(R37:R38) -> 0 | S39: =SUM(S37:S38) -> 0 | T39: =SUM(T37:T38) -> 4231.29 | U39: =SUM(U37:U38) -> 704.06 | V39: =SUM(V37:V38) -> -4024 | W39: =SUM(W37:W38) -> 10502
Q40: Profit/Loss for the year from continuing operations | R40: =R35-R39 -> -10579.98 | S40: =S35-S39 -> -10474.28 | T40: =T35-T39 -> -11234.7 | U40: =U35-U39 -> 2353.49 | V40: =V35-V39 -> 32453 | W40: =W35-W39 -> 23278
...

Sheet Cash Flow Statement
A1: CASH FLOW STATEMENT | F1: #VALUE! | I1: CASH FLOW STATEMENT | N1: #VALUE! | Q1: CASH FLOW STATEMENT | V1: #VALUE! | Y1: CASH FLOW STATEMENT | AD1: #VALUE! | AG1: CASH FLOW STATEMENT | AL1: #VALUE! | AO1: CASH FLOW STATEMENT | AT1: #VALUE!
A2: Particulars | B2: 2020 | C2: 2021 | D2: 2022 | E2: 2023 | F2: 2024 | G2: 2025 | I2: Particulars | J2: 2020 | K2: 2021 | L2: 2022 | M2: 2023 | N2: 2024 | O2: 2025 | Q2: Particulars | R2: 2020 | S2: 2021 | T2: 2022 | U2: 2023 | V2: 2024 | W2: 2025 | Y2: Particulars | Z2: 2020 | AA2: 2021 | AB2: 2022 | AC2: 2023 | AD2: 2024 | AE2: NA | AG2: Particulars | AH2: 2020 | AI2: 2021 | AJ2: 2022 | AK2: 2023 | AL2: 2024 | AM2: 2025 | AO2: Particulars | AP2: 2020 | AQ2: 2021 | AR2: 2022 | AS2: 2023 | AT2: 2024 | AU2: NA
A3: Cash flow from Operating activities | I3: Cash flow from Operating activities | Q3: Cash flow from operating activities | Y3: Cash Flow from Operating actitivities | AG3: Cash flow from Operating activities | AO3: Cash flow from operating activities
A4: Profit before tax | B4: 7102.8 | C4: 5321 | D4: 4697.2 | E4: 10323.1 | F4: 17040.4 | G4: 19183.2 | I4: Profit/Loss before exceptional items and tax | J4: 4832.43 | K4: 5229.33 | L4: 7091.81 | M4: 11305.27 | N4: 14856.36 | O4: 17542.2 | Q4: Profit/Loss for the year | R4: -11975.23 | S4: -13395.1 | T4: -11308.76 | U4: 2689.87 | V4: 32453 | W4: 23278 | Y4: Net profit before tax | Z4: 865.42 | AA4: 821.63 | AB4: 1066.79 | AC4: 1936.03 | AD4: 2702.92 | AG4: Net profit before tax | AH4: 971.88 | AI4: 1074.39 | AJ4: 960.61 | AK4: 1137.59 | AL4: 1231.17 | AM4: 1175.96 | AO4: Profit before tax from continuing operation | AP4: 1622.3 | AQ4: 1173.3 | AR4: 1424.2 | AS4: 2404.8 | AT4: 3840.2
A5: Adjustments for: | I5: Profit/Loss before tax from discontinued operations | J5: -3033.82 | K5: -2189.53 | L5: 0 | M5: 0 | N5: 0 | O5: 0 | Q5: Adjustments for: | Y5: Add: Depreciation and amortisation for the year | Z5: 556 | AA5: 564.82 | AB5: 742.86 | AC5: 858.86 | AD5: 975.12 | AG5: Adjustments for: | AO5: Profit before tax from discontinued operation | AP5: 490.6 | AQ5: 439.6 | AR5: 484.6 | AS5: 0 | AT5: 0
A6: Share of profit of associates | B6: -117.5 | C6: -158.8 | D6: -146.4 | E6: -155.8 | F6: 0 | G6: 0 | I6: Profit/Loss | J6: =SUM(J4:J5) -> 1798.61 | K6: =SUM(K4:K5) -> 3039.8 | L6: =SUM(L4:L5) -> 7091.81 | M6: =SUM(M4:M5) -> 11305.27 | N6: =SUM(N4:N5) -> 14856.36 | O6: =SUM(O4:O5) -> 17542.2 | Q6: Depreciation and amortisation expense | R6: 21425.43 | S6: 23546.71 | T6: 24835.69 | U6: 24860.36 | V6: -646 | W6: 4871 | Y6: Gain on lease preclosure | Z6: -0.31 | AA6: 0 | AB6: 0 | AC6: -0.01 | AD6: -4.75 | AG6: Depreciation and amortisation | AH6: 417.58 | AI6: 433.65 | AJ6: 439.52 | AK6: 502.12 | AL6: 560.42 | AM6: 582.34 | AO6: Adjustments:
A7: Share of profit of joint ventures | B7: -0.9 | C7: -10.2 | D7: -15.5 | E7: -21.6 | F7: 0 | G7: 0 | I7: Adjustments for: | Q7: Allowances for finance receivables | R7: 660.21 | S7: 957.93 | T7: 1307.59 | U7: 2039.15 | V7: 27270 | W7: 23256 | Y7: Profit/Loss on sale of fixed assets | Z7: -2.28 | AA7: 1.96 | AB7: -2.47 | AC7: -2.65 | AD7: -3.38 | AG7: Gain on disposal of investment | AH7: -214.57 | AI7: -146.86 | AJ7: -23.61 | AK7: -38.2 | AL7: -46.8 | AM7: -27.8 | AO7: Share of profit/loss in associates and joint venture accounted for using the equity method | AP7: -57.5 | AQ7: -84.9 | AR7: -16 | AS7: 43.7 | AT7: -237.6
A8: Share of dividend from joint ventures and associates | B8: 86.7 | C8: 10.4 | D8: 49 | E8: 20.9 | F8: 0 | G8: 0 | I8: Depreciation, amortisation and impairment expense | J8: 4976.29 | K8: 4398.89 | L8: 3507.5 | M8: 4356.81 | N8: 4723.78 | O8: 6073.65 | Q8: Allowances for trade and other receivables | R8: 137.03 | S8: 50.01 | T8: 151.26 | U8: 80.63 | V8: 1153 | W8: 0 | Y8: Profit/Loss on sale of investments | Z8: -0.03 | AA8: -0.04 | AB8: -0.23 | AC8: =-61.84-45.56 -> -107.4 | AD8: =26.93-89.47 -> -62.54 | AG8: Profit/loss on PPE sold/discarded (net) | AH8: -7.32 | AI8: 0.18 | AJ8: 0.02 | AK8: -6.48 | AL8: 2.27 | AM8: -11.17 | AO8: Depreciation and amortisation expense | AP8: 2778 | AQ8: 2976.4 | AR8: 2996.3 | AS8: 3135.8 | AT8: 3810.5
A9: Depreciation and amortisation expense | B9: 3528.4 | C9: 3034.1 | D9: 2789 | E9: 2825.7 | F9: 3022.3 | G9: 3159.3 | I9: Loss/Gain on foreign exchange fluctuation (net) | J9: 202.94 | K9: 63.35 | L9: -65.31 | M9: 59.62 | N9: -74.33 | O9: 44.6 | Q9: Inventory write-down | R9: 351.14 | S9: 129.19 | T9: 125.34 | U9: 723.21 | V9: 197 | W9: 109 | Y9: Unrealised exchange gain/loss | Z9: -29.41 | AA9: 17.7 | AB9: -5.65 | AC9: 0.63 | AD9: 10.82 | AG9: Income from investments including dividend and interest | AH9: -1015.35 | AI9: -1188.95 | AJ9: -8.31 | AK9: -16.37 | AL9: -22.92 | AM9: -20.81 | AO9: Finance cost | AP9: 598.6 | AQ9: 520.2 | AR9: 551.9 | AS9: 780.9 | AT9: 1811.2
A10: Finance costs | B10: 134.2 | C10: 101.8 | D10: 126.6 | E10: 187 | F10: 193.2 | G10: 193.1 | I10: Gain due to change in lease arrangements | J10: 0 | K10: -44.21 | L10: -15.07 | M10: 0 | N10: 43.45 | O10: -18.18 | Q10: Reversal for costs of closure of operations of a subsidiary company | R10: -65.62 | S10: -51.99 | T10: -3.32 | U10: 0 | V10: 1334 | W10: 337 | Y10: Net profit/loss from associates using equity method | Z10: 8.59 | AA10: 7.75 | AB10: -2.49 | AC10: 40.73 | AD10: 43.47 | AG10: Gain on fair valuation of investment | AH10: 291.08 | AI10: -461.22 | AJ10: -7.68 | AK10: -10.47 | AL10: -5.43 | AM10: -21.77 | AO10: Interest income | AP10: -36.1 | AQ10: -65.8 | AR10: -117.3 | AS10: -70.3 | AT10: -148.3
