Workbook

Sheet Company Basic info
A1: Company Basic Info
A2: Logo | C2: #VALUE! | D2: #VALUE! | E2: #VALUE! | F2: #VALUE! | G2: #VALUE!
A3: Attribute | C3: Bharat Electronics Limited | D3: Mazagon Dock Shipbuilders | E3: Bharat Dynamics Limited | F3: Hindustan Aeronautics Limited | G3: GRSE
A4: Company Name | C4: #VALUE! | D4: #VALUE! | E4: #VALUE! | F4: #VALUE! | G4: #VALUE!
A5: Ticker Symbol | C5: {=_FV(C4,"Ticker symbol",TRUE)} -> 500049 | D5: {=_FV(D4,"Ticker symbol",TRUE)} -> 543237 | E5: {=_FV(E4,"Ticker symbol",TRUE)} -> 541143 | F5: {=_FV(F4,"Ticker symbol",TRUE)} -> 541154 | G5: {=_FV(G4,"Ticker symbol",TRUE)} -> GRSE
A6: Industry/Sector | C6: {=_FV(C4,"Industry")} -> Aerospace & Defense | D6: {=_FV(D4,"Industry")} -> Aerospace & Defense | E6: {=_FV(E4,"Industry")} -> Aerospace & Defense | F6: {=_FV(F4,"Industry")} -> Aerospace & Defense | G6: {=_FV(G4,"Industry")} -> Aerospace & Defense
A7: Listed Exchange | C7: {=_FV(C4,"Exchange")} -> Bombay Stock Exchange | D7: {=_FV(D4,"Exchange")} -> Bombay Stock Exchange | E7: {=_FV(E4,"Exchange")} -> Bombay Stock Exchange | F7: {=_FV(F4,"Exchange")} -> Bombay Stock Exchange | G7: {=_FV(G4,"Exchange")} -> National Stock Exchange of India
A8: Year of Corporation | C8: {=_FV(C4,"Year incorporated",TRUE)} -> 1954 | D8: {=_FV(D4,"Year incorporated",TRUE)} -> 1934 | E8: {=_FV(E4,"Year incorporated",TRUE)} -> 1970 | F8: {=_FV(F4,"Year incorporated",TRUE)} -> 1963 | G8: {=_FV(G4,"Year incorporated",TRUE)} -> 1934
A9: Market Capitalization (in ₹) | C9: {=_FV(C4,"Market cap",TRUE)} -> 3028076000000 | D9: {=_FV(D4,"Market cap",TRUE)} -> 1077146000000 | E9: {=_FV(E4,"Market cap",TRUE)} -> 530672500000 | F9: {=_FV(F4,"Market cap",TRUE)} -> 3094155000000 | G9: {=_FV(G4,"Market cap",TRUE)} -> 294868300000
C10: =C9/10000000 -> 302807.6 | D10: =D9/10000000 -> 107714.6 | E10: =E9/10000000 -> 53067.25 | F10: =F9/10000000 -> 309415.5 | G10: =G9/10000000 -> 29486.83
A11: Market Price | C11: {=_FV(C4,"Price")} -> 416.7 | D11: {=_FV(D4,"Price")} -> 2705.35 | E11: {=_FV(E4,"Price")} -> 1514.45 | F11: {=_FV(F4,"Price")} -> 4789.5 | G11: {=_FV(G4,"Price")} -> 2682.5
A12: Daily change (%) | C12: {=_FV(C4,"Change (%)",TRUE)} -> 0.005914 | D12: {=_FV(D4,"Change (%)",TRUE)} -> 0.013031 | E12: {=_FV(E4,"Change (%)",TRUE)} -> 0.046758 | F12: {=_FV(F4,"Change (%)",TRUE)} -> 0.035131 | G12: {=_FV(G4,"Change (%)",TRUE)} -> 0.042112
A13: Change (in Rs) | C13: {=_FV(C4,"Change")} -> 2.45 | D13: {=_FV(D4,"Change")} -> 34.8 | E13: {=_FV(E4,"Change")} -> 67.65 | F13: {=_FV(F4,"Change")} -> 162.55 | G13: {=_FV(G4,"Change")} -> 108.4
A14: No. of Shares Outstanding | C14: {=_FV(C4,"Shares outstanding",TRUE)} -> 7309779000 | D14: {=_FV(D4,"Shares outstanding",TRUE)} -> 403380000 | E14: {=_FV(E4,"Shares outstanding",TRUE)} -> 366562500 | F14: {=_FV(F4,"Shares outstanding",TRUE)} -> 668775000 | G14: {=_FV(G4,"Shares outstanding",TRUE)} -> 114552000
C15: =C14/10000000 -> 730.9779 | D15: =D14/10000000 -> 40.338 | E15: =E14/10000000 -> 36.65625 | F15: =F14/10000000 -> 66.8775 | G15: =G14/10000000 -> 11.4552
A16: Beta | C16: {=_FV(C4,"Beta")} -> 1.096 | D16: {=_FV(D4,"Beta")} -> 1.9085 | E16: {=_FV(E4,"Beta")} -> 1.2893 | F16: {=_FV(F4,"Beta")} -> 1.4937 | G16: {=_FV(G4,"Beta")} -> 1.5609

Sheet Balance Sheet 
A1: BALANCE SHEET | F1: #VALUE! | M1: #VALUE! | T1: #VALUE! | AB1: #VALUE! | AI1: #VALUE!
A2: Particulars | B2: 2020 | C2: 2021 | D2: 2022 | E2: 2023 | F2: 2024 | H2: Particulars | I2: 2020 | J2: 2021 | K2: 2022 | L2: 2023 | M2: 2024 | O2: Particulars | P2: 2020 | Q2: 2021 | R2: 2022 | S2: 2023 | T2: 2024 | V2: Particulars | W2: 2020 | X2: 2021 | Y2: 2022 | Z2: 2023 | AA2: 2024 | AB2: 2025 | AD2: Particulars | AE2: 2020 | AF2: 2021 | AG2: 2022 | AH2: 2023 | AI2: 2024
A3: ASSETS | H3: EQUITIES AND LIABILITIES | O3: Assets | V3: Assets | AD3: Assets
A4: NON-CURRENT ASSETS | H4: SHAREHOLDER'S FUNDS | O4: Non-current assets | V4: Non-current assets | AD4: Non-Current assets
A5: Property, plant and equipment | B5: 2496.63 | C5: 2485.5 | D5: 2509.37 | E5: 2694.31 | F5: 2788.47 | H5: Equity Share Capital | I5: 201.69 | J5: 201.69 | K5: 201.69 | L5: 201.69 | M5: 201.69 | O5: PPE | P5: 753.0516 | Q5: 742.7311 | R5: 704.2644 | S5: 646.2838 | T5: 672.355 | V5: PPE | W5: 6350.59 | X5: 6547.01 | Y5: 5927.58 | Z5: 5798.62 | AA5: 5780.23 | AB5: 5970.26 | AD5: PPE | AE5: 299.2331 | AF5: 334.9742 | AG5: =482.9569+11.6104 -> 494.5673 | AH5: =488.2643+10.9865 -> 499.2508 | AI5: =475.1622+9.8172 -> 484.9794
A6: Capital work-in-progress | B6: 199.44 | C6: 397.47 | D6: 445.93 | E6: 361.23 | F6: 456.42 | H6: Total Share Capital | I6: =I5 -> 201.69 | J6: 201.69 | K6: =K5 -> 201.69 | L6: 201.69 | M6: 201.69 | O6: Capital work-in-progress | P6: 42.0585 | Q6: 21.4986 | R6: 40.7318 | S6: 74.3466 | T6: 72.8748 | V6: Capital work-in-progress | W6: 860 | X6: 791.56 | Y6: 949.1 | Z6: 636.9 | AA6: 936.88 | AB6: 1091.08 | AD6: Capital work-in-progress | AE6: 51.5152 | AF6: 151.2972 | AG6: 9.6598 | AH6: 4.8445 | AI6: 116.186
A7: Investment property | B7: 0.09 | C7: 0.08 | D7: 0.07 | E7: 0.06 | F7: 0.04 | H7: Reserves and Surplus | I7: 2857.69 | J7: 3230.02 | K7: 3655.99 | L7: 3975.87 | M7: 6041.78 | O7: Investment property | P7: 0.0097 | Q7: 0.0097 | R7: 0.0097 | S7: 0.0097 | T7: 0.0097 | V7: Investment Property | W7: 0.03 | X7: 0.03 | Y7: 0.03 | Z7: 0.03 | AA7: 0.02 | AB7: 0.02 | AD7: Intangible assets | AE7: 4.4556 | AF7: 5.2286 | AG7: 6.0869 | AH7: 8.3596 | AI7: 7.5872
A8: Investment in associate | B8: 0 | C8: 189.89 | D8: 232.92 | E8: 200.73 | F8: 151.57 | H8: Total Reserves and Surplus | I8: =I7 -> 2857.69 | J8: =J7 -> 3230.02 | K8: =K7 -> 3655.99 | L8: 3975.87 | M8: =M7 -> 6041.78 | O8: Right of use assets | P8: 41.5145 | Q8: 39.7504 | R8: 56.8232 | S8: 54.5603 | T8: 52.8974 | V8: Goodwill | W8: 0 | X8: 0 | Y8: 0 | Z8: 0 | AA8: 0 | AB8: 0 | AD8: Intangible assets under development | AE8: 0 | AF8: 0 | AG8: 0 | AH8: 1.196 | AI8: 13.1439
A9: Other intangible assets | B9: 22.97 | C9: 166.56 | D9: 165.82 | E9: 268.49 | F9: 246.7 | H9: Total Shareholders Funds | I9: =I6+I8 -> 3059.38 | J9: =J6+J8 -> 3431.71 | K9: =K6+K8 -> 3857.68 | L9: =L6+L8 -> 4177.56 | M9: =M6+M8 -> 6243.47 | O9: Intangible assets | P9: 137.792 | Q9: 132.4979 | R9: 112.749 | S9: 107.383 | T9: 98.3599 | V9: Other intangible assets | W9: 1006.87 | X9: 944.07 | Y9: 838.27 | Z9: 1035.75 | AA9: 956.64 | AB9: 700.52 | AD9: Investments | AE9: 0.0044 | AF9: 0.0044 | AG9: 0.0044 | AH9: 0.0044 | AI9: 0.0044
A10: Intangible assets under development | B10: 483.43 | C10: 485.21 | D10: 560.11 | E10: 493.71 | F10: 437.3 | H10: NON-CURRENT LIABILITIES | O10: Investments | P10: 3.9043 | Q10: 4.5226 | R10: 0 | S10: 0 | T10: 0 | V10: Intangible assets under development | W10: 1182.69 | X10: 1286.27 | Y10: 1523.84 | Z10: 1248.1 | AA10: 1556.55 | AB10: 2006.67 | AD10: Other financial assets | AE10: 76.6042 | AF10: 694.559 | AG10: 1141.2663 | AH10: 90.4406 | AI10: 90.1645
A11: Financial assets | H11: Trade Payables | I11: 15.62 | J11: 15.44 | K11: 17.73 | L11: =18.02 -> 18.02 | M11: 17.65 | O11: Loans | P11: 3.0035 | Q11: 2.5196 | R11: 2.0369 | S11: 1.7386 | T11: 1.7022 | V11: Investments accounted for using the equity method | W11: 157.54 | X11: 160.96 | Y11: 167.79 | Z11: 168.33 | AA11: 201.64 | AB11: 244.72 | AD11: Non-current tax assets | AE11: 120.6002 | AF11: 117.1477 | AG11: 153.9376 | AH11: 205.8435 | AI11: 198.4275
A12: Investments | B12: 1161.67 | C12: 1116.05 | D12: 1339.1 | E12: 449.26 | F12: 530.66 | H12: Other Financial Liabilities | I12: 36 | J12: 30.41 | K12: =0.97+4.74 -> 5.71 | L12: =0.48+0.31 -> 0.79 | M12: =0.81+0.69 -> 1.5 | O12: Other financial assets | P12: 46.7689 | Q12: 44.0411 | R12: 40.8576 | S12: 106.0314 | T12: 108.2881 | V12: Investments | W12: 833.26 | X12: 894.55 | Y12: 1194.91 | Z12: 1289.59 | AA12: 1389.69 | AB12: 1509.48 | AD12: Other non-current assets | AE12: 24.0806 | AF12: 2.543 | AG12: 0.1078 | AH12: 0.1634 | AI12: 0.2016
A13: Trade receivables | B13: 0 | C13: 0 | D13: 0 | E13: 0 | F13: 0 | H13: Other long-term liabilities | I13: 154.84 | J13: 148.02 | K13: 140.37 | L13: 133.5 | M13: 126.63 | O13: Deferred tax assets (net) | P13: 54.2497 | Q13: 47.7325 | R13: 57.1071 | S13: 56.4202 | T13: 70.7281 | V13: Trade receivables | W13: 0 | X13: 0 | Y13: 0 | Z13: 0 | AA13: 0 | AB13: 0 | AD13: Total non-current assets | AE13: =SUM(AE5:AE12) -> 576.4933 | AF13: =SUM(AF5:AF12) -> 1305.7541 | AG13: =SUM(AG5:AG12) -> 1805.6301 | AH13: =SUM(AH5:AH12) -> 810.1028 | AI13: =SUM(AI5:AI12) -> 910.6945
A14: Loans | B14: 33.09 | C14: 7.36 | D14: 7.28 | E14: 6.56 | F14: 7.03 | H14: Long term Provisions | I14: 1215.07 | J14: 730.16 | K14: 564.73 | L14: 410.85 | M14: 425.21 | O14: Other non-current assets | P14: 28.8457 | Q14: 27.4555 | R14: 26.0653 | S14: 25.2152 | T14: 23.825 | V14: Contract assets | W14: 0 | X14: 0 | Y14: 0 | Z14: 0 | AA14: 0 | AB14: 0 | AD14: Current Assets
A15: Other financial assets | B15: 28.45 | C15: 28.71 | D15: 24.17 | E15: 20.45 | F15: 18.83 | H15: Total Non-Current Liabilities | I15: =SUM(I11:I14) -> 1421.53 | J15: =SUM(J11:J14) -> 924.03 | K15: =SUM(K11:K14) -> 728.54 | L15: =L11+L12+L13+L14 -> 563.16 | M15: =SUM(M11:M14) -> 570.99 | O15: Total non-current assets | P15: =SUM(P5:P14) -> 1111.1984 | Q15: =SUM(Q5:Q14) -> 1062.759 | R15: =SUM(R5:R14) -> 1040.645 | S15: =SUM(S5:S14) -> 1071.9888 | T15: =SUM(T5:T14) -> 1101.0402 | V15: Loans | W15: 47.96 | X15: 46.13 | Y15: 6.93 | Z15: 6.21 | AA15: 5.61 | AB15: 5.57 | AD15: Inventories | AE15: 441.0222 | AF15: 787.8745 | AG15: 1172.268 | AH15: 2918.5049 | AI15: 3984.4414
A16: Deferred tax assets (net) | B16: 497.4 | C16: 463.46 | D16: 620.94 | E16: 503.72 | F16: 574.68 | H16: CURRENT LIABILITIES | O16: Current Assets | V16: Other financial assets | W16: 345.13 | X16: 344.76 | Y16: 410.3 | Z16: 412.98 | AA16: 395.47 | AB16: 389.11 | AD16: Current Investments | AE16: 54.0043 | AF16: 825.8196 | AG16: 196.6782 | AH16: 233.664 | AI16: 0
A17: Inventories | B17: 52.55 | C17: 39.38 | D17: 27.34 | E17: 5.87 | F17: 0 | H17: Trade Payables | I17: =20.07+4708.17 -> 4728.24 | J17: =39.36+6232.46 -> 6271.82 | K17: 6165.65 | L17: 4462.79 | M17: 4466.42 | O17: Inventories | P17: 856.5177 | Q17: 1397.01 | R17: 1654.4513 | S17: 1822.4375 | T17: 1982.4731 | V17: Deferred tax assets (net) | W17: 470.11 | X17: 52.35 | Y17: 565.57 | Z17: 1125.71 | AA17: 1454.33 | AB17: 1567.99 | AD17: Trade receivables | AE17: 535.28 | AF17: 178.1374 | AG17: 154.9433 | AH17: 50.845 | AI17: 194.207
A18: Other non-current assets | B18: 340.78 | C18: 396.69 | D18: 683.82 | E18: 439.04 | F18: 252 | H18: Other Current Liabilities | I18: 43.63 | J18: 16.49 | K18: 19.23 | L18: 17.28 | M18: 56.26 | O18: Trade receivables | P18: 338.368 | Q18: 322.6927 | R18: 304.1613 | S18: 184.5727 | T18: 310.4472 | V18: Other non-current assets | W18: 629.4 | X18: 706.86 | Y18: 1814.64 | Z18: 3596.54 | AA18: 2400.63 | AB18: 2686.83 | AD18: Cash and cash equivalents | AE18: 729.2275 | AF18: 9.3205 | AG18: 9.7126 | AH18: 13.9855 | AI18: 5.27
A19: Total Non-current assets | B19: =SUM(B5:B18) -> 5316.5 | C19: =SUM(C5:C18) -> 5776.36 | D19: =SUM(D5:D18) -> 6616.87 | E19: =SUM(E5:E18) -> 5443.43 | F19: =SUM(F5:F18) -> 5463.7 | H19: Other Financial Liabilities | I19: 124.08 | J19: 158.11 | K19: =169.73+6.9 -> 176.63 | L19: =146.58+5.73 -> 152.31 | M19: =196.74+0.12 -> 196.86 | O19: Cash and cash equivalents | P19: 297.4947 | Q19: 456.9167 | R19: 265.0437 | S19: 1052.8837 | T19: 593.842 | V19: Total non-current assets | W19: =SUM(W5:W18) -> 11883.58 | X19: =SUM(X5:X18) -> 11774.55 | Y19: =SUM(Y5:Y18) -> 13398.96 | Z19: =SUM(Z5:Z18) -> 15318.76 | AA19: =SUM(AA5:AA18) -> 15077.69 | AB19: =SUM(AB5:AB18) -> 16172.25 | AD19: Bank Balances other than above | AE19: 1882.0938 | AF19: 2271.8514 | AG19: 2548.0263 | AH19: 4313.8207 | AI19: 3715.0684
A20: CURRENT ASSETS | H20: Contract Liability | I20: 11437.25 | J20: =14176.08+90 -> 14266.08 | K20: =18707.76 -> 18707.76 | L20: =19333.34 -> 19333.34 | M20: 17723.39 | O20: Bank Balances other than cash | P20: 366 | Q20: 1104.038 | R20: 1634.49 | S20: 2805.98 | T20: 3634.64 | V20: Current Assets | AD20: Other financial assets | AE20: 207.3275 | AF20: 143.8003 | AG20: 127.513 | AH20: 234.2292 | AI20: 222.3479
A21: Inventories | B21: 3910.2 | C21: 4967.98 | D21: 5591.9 | E21: 6448.04 | F21: 7446.89 | H21: Short Term Provisions | I21: 126.75 | J21: 70.27 | K21: 114.67 | L21: 174.13 | M21: 191.42 | O21: Loans | P21: 2.3696 | Q21: 1.9687 | R21: 1.8374 | S21: 2.0216 | T21: 1.9985 | V21: Inventories | W21: 19435.9 | X21: 16544.77 | Y21: 14347.28 | Z21: 12148.69 | AA21: 13217.54 | AB21: 21675.7 | AD21: Other current assets | AE21: 958.1844 | AF21: 1260.2192 | AG21: 1620.3632 | AH21: 2200.7017 | AI21: 1324.2874
A22: Financial assets | H22: Total Current Liabilities | I22: =SUM(I17:I21) -> 16459.95 | J22: =SUM(J17:J21) -> 20782.77 | K22: =SUM(K17:K21) -> 25183.94 | L22: =SUM(L17:L21) -> 24139.85 | M22: 22634.35 | O22: Other financial assets | P22: 2425.5043 | Q22: 1215.9431 | R22: 1291.6231 | S22: 1324.1177 | T22: 1061.6302 | V22: Investments | W22: 0 | X22: 0 | Y22: 0 | Z22: 0 | AA22: 0 | AB22: 0 | AD22: Assets classified as held for sale | AE22: 0.528 | AF22: 0.4339 | AG22: 0.4587 | AH22: 0.079 | AI22: 0.1599
A23: Trade receivables | B23: 6732.91 | C23: 6561.99 | D23: 6108.09 | E23: 7033.48 | F23: 7392.38 | H23: Total Capital And Liabilities | I23: =I9+I15+I22 -> 20940.86 | J23: =J9+J15+J22 -> 25138.51 | K23: =K9+K15+K22 -> 29770.16 | L23: =L9+L15+L22 -> 28880.57 | M23: =M9+M15+M22 -> 29448.81 | O23: Current tax assets | P23: 36.4539 | Q23: 42.2326 | R23: 29.1205 | S23: 119.4887 | T23: 46.708 | V23: Trade receivables | W23: 11234.73 | X23: 5637.86 | Y23: 4641.53 | Z23: 4719.07 | AA23: 4616.85 | AB23: 4647.79 | AD23: Total current assets | AE23: =SUM(AE15:AE22) -> 4807.6677 | AF23: =SUM(AF15:AF22) -> 5477.4568 | AG23: =SUM(AG15:AG22) -> 5829.9633 | AH23: =SUM(AH15:AH22) -> 9965.83 | AI23: =SUM(AI15:AI22) -> 9445.782
A24: Cash & Cash equivalents | B24: 1556.22 | C24: 3042.9 | D24: 1300.86 | E24: 3945.69 | F24: 1206.32 | H24: ASSETS | O24: Other Current assets | P24: 251.3545 | Q24: 358.1953 | R24: 342.5079 | S24: 288.6407 | T24: 1607.2715 | V24: Contract assets | W24: 7841.73 | X24: 8346.16 | Y24: 7808.65 | Z24: 9376.4 | AA24: 11893.96 | AB24: 15889.16 | AD24: Total Assets | AE24: =AE13+AE23 -> 5384.161 | AF24: =AF13+AF23 -> 6783.2109 | AG24: =AG13+AG23 -> 7635.5934 | AH24: =AH13+AH23 -> 10775.933 | AI24: =AI13+AI23 -> 10356.477
A25: Bank Balances | B25: 1.48 | C25: 2030.86 | D25: 6262.88 | E25: 4165.89 | F25: 9850.27 | H25: NON-CURRENT ASSETS | O25: Total current assets | P25: =SUM(P17:P24) -> 4574.0627 | Q25: =SUM(Q17:Q24) -> 4898.9971 | R25: =SUM(R17:R24) -> 5523.2352 | S25: =SUM(S17:S24) -> 7600.1426 | T25: =SUM(T17:T24) -> 9239.0105 | V25: Cash and cash equivalents | W25: 279.32 | X25: 7146.15 | Y25: 3070.37 | Z25: 4440.77 | AA25: 4254.69 | AB25: 4548.55 | AD25: Equity and Liabilities
A26: Loans | B26: 32.62 | C26: 1.52 | D26: 1.48 | E26: 1.72 | F26: 1.41 | H26: Property, Plant and equipment | I26: 819.22 | J26: 794.93 | K26: 956.56 | L26: =777.63+229.34 -> 1006.97 | M26: 819.65 | O26: Total assets | P26: =P15+P25 -> 5685.2611 | Q26: =Q15+Q25 -> 5961.7561 | R26: =R15+R25 -> 6563.8802 | S26: =S15+S25 -> 8672.1314 | T26: =T15+T25 -> 10340.051 | V26: Bank balances | W26: 37.24 | X26: 31.2 | Y26: 11277.35 | Z26: 15875.84 | AA26: 22176.92 | AB26: 33633.7 | AD26: Equity
A27: Other finance assets | B27: 29.03 | C27: 60.66 | D27: 102.54 | E27: 203.42 | F27: 294.4 | H27: Other Intangible Assets | I27: 17.13 | J27: 11.92 | K27: 8.06 | L27: 17.36 | M27: 18.29 | O27: Equity and Liabilities | V27: Loans | W27: 19.43 | X27: 14.7 | Y27: 7.51 | Z27: 7.76 | AA27: 10.77 | AB27: 7.43 | AD27: Equity share capital | AE27: 114.552 | AF27: 114.552 | AG27: 114.552 | AH27: 114.552 | AI27: 114.552
A28: Current tax assets (net) | B28: 279.89 | C28: 133.64 | D28: 144.74 | E28: 403.14 | F28: 449.61 | H28: Capital Work-In-Progress | I28: 79.96 | J28: 80.15 | K28: 86.94 | L28: 61.62 | M28: 68.24 | O28: Equity | V28: Other financial assets | W28: 1219.03 | X28: 1055.1 | Y28: 1023.23 | Z28: 1119.27 | AA28: 1514.19 | AB28: 1346.93 | AD28: Oher equity | AE28: 925.679 | AF28: 1022.5656 | AG28: 1143.3387 | AH28: 1299.2655 | AI28: 1558.8869
A29: Other current assets | B29: 6052.24 | C29: 6913.76 | D29: 7781.22 | E29: 7846.36 | F29: 7421.7 | H29: Intangible Assets Under Development | I29: 0 | J29: 0 | K29: 0 | L29: 0 | M29: 3.39 | O29: Equity share capital | P29: 183.2812 | Q29: 183.2812 | R29: 183.2812 | S29: 183.2812 | T29: 183.2812 | V29: Current tax assets (net) | W29: 35.31 | X29: 0 | Y29: 0 | Z29: 0 | AA29: 0 | AB29: 0 | AD29: Total equity | AE29: =AE27+AE28 -> 1040.231 | AF29: =AF27+AF28 -> 1137.1176 | AG29: =AG27+AG28 -> 1257.8907 | AH29: =AH27+AH28 -> 1413.8175 | AI29: =AI27+AI28 -> 1673.4389
A30: Total Current Assets | B30: =B21+SUM(B23:B29) -> 18594.59 | C30: =C21+SUM(C23:C29) -> 23713.31 | D30: =D21+SUM(D23:D29) -> 27293.71 | E30: =E21+SUM(E23:E29) -> 30047.74 | F30: =F21+SUM(F23:F29) -> 34062.98 | H30: Investments | I30: 484.18 | J30: 518.65 | K30: 542.32 | L30: 6 | M30: 678.79 | O30: Other equity | P30: 2423.5485 | Q30: 2501.466 | R30: 2847.2762 | S30: 3028.2165 | T30: 3453.5421 | V30: Other current assets | W30: 1291.11 | X30: 1395.41 | Y30: 2808.99 | Z30: 4189.13 | AA30: 5332.57 | AB30: 8345.34 | AD30: Liabilities
A31: TOTAL ASSETS | B31: =B19+B21+B23+B24+B25+B26+B27+B28+B29 -> 23911.09 | C31: =C19+C21+C23+C24+C25+C26+C27+C28+C29 -> 29489.67 | D31: =D19+D21+D23+D24+D25+D26+D27+D28+D29 -> 33910.58 | E31: =E19+E21+E23+E24+E25+E26+E27+E28+E29 -> 35491.17 | F31: =F19+F21+F23+F24+F25+F26+F27+F28+F29 -> 39526.68 | H31: Trade receivable | I31: 15.62 | J31: 15.44 | K31: 17.73 | L31: 18.02 | M31: 17.65 | O31: Total equity | P31: =SUM(P29:P30) -> 2606.8297 | Q31: =SUM(Q29:Q30) -> 2684.7472 | R31: =SUM(R29:R30) -> 3030.5574 | S31: =SUM(S29:S30) -> 3211.4977 | T31: =SUM(T29:T30) -> 3636.8233 | V31: Total current assets | W31: =SUM(W21:W30) -> 41393.8 | X31: =SUM(X21:X30) -> 40171.35 | Y31: =SUM(Y21:Y30) -> 44984.91 | Z31: =SUM(Z21:Z30) -> 51876.93 | AA31: =SUM(AA21:AA30) -> 63017.49 | AB31: =SUM(AB21:AB30) -> 90094.6 | AD31: Non-current liabilities
A32: EQUITY AND LIABILITIES | H32: Loans | I32: 6.89 | J32: 7.1 | K32: 0 | L32: 0 | M32: 20 | O32: Non-current Liabilities | V32: Assets held for sale | W32: 0 | X32: 0 | Y32: 8.11 | Z32: 8.11 | AA32: 0 | AB32: 0 | AD32: Lease Liabilities | AE32: 0 | AF32: 0 | AG32: 9.7354 | AH32: 9.2316 | AI32: 8.2884
A33: Equity share capital | B33: 243.66 | C33: 243.66 | D33: 243.66 | E33: 730.98 | F33: 730.98 | H33: Other Financial assets | I33: 153.45 | J33: 141.59 | K33: 141.16 | L33: 131.67 | M33: 137.45 | O33: Lease liabilities | P33: 7.7119 | Q33: 6.5271 | R33: 5.2075 | S33: 3.7411 | T33: 2.115 | V33: Total assets | W33: =W19+W31 -> 53277.38 | X33: =X19+X31 -> 51945.9 | Y33: =Y19+Y31+Y32 -> 58391.98 | Z33: =Z19+Z31+Z32 -> 67203.8 | AA33: =AA19+AA31+AA32 -> 78095.18 | AB33: =AB19+AB31+AB32 -> 106266.85 | AD33: Total outstanding dues of micro and small ent | AE33: 0 | AF33: 0 | AG33: 0 | AH33: 0 | AI33: 0
A34: Other equity | B34: 9609.28 | C34: 10815.92 | D34: 12042.27 | E34: 13130.65 | F34: 15595.49 | H34: Deferred Tax Assets [Net] | I34: 414.72 | J34: 423.61 | K34: 446.83 | L34: 450.1 | M34: 599.8 | O34: Other financial liabilities | P34: 45.4038 | Q34: 43.2539 | R34: 41.0616 | S34: 45.5747 | T34: 46.3966 | V34: Equity and Liabilities | AD34: Total outstanding dues other than above | AE34: 10.7505 | AF34: 9.2367 | AG34: 8.1892 | AH34: 8.1736 | AI34: 7.8356
A35: Non controlling interest | B35: 0 | C35: 14.99 | D35: 16.34 | E35: 17.75 | F35: 17.92 | H35: Non-current tax assets [Net] | I35: 225.94 | J35: 218.82 | K35: 313.2 | L35: 265.5 | M35: 178.56 | O35: Provisions | P35: 0.2913 | Q35: 29.0682 | R35: 44.6564 | S35: 0.37 | T35: 0.4007 | V35: Equity | AD35: Total trade payables | AE35: =AE33+AE34 -> 10.7505 | AF35: =AF33+AF34 -> 9.2367 | AG35: =AG33+AG34 -> 8.1892 | AH35: =AH33+AH34 -> 8.1736 | AI35: =AI33+AI34 -> 7.8356
A36: Total shareholder's funds | B36: =B33+B34+B35 -> 9852.94 | C36: =C33+C34+C35 -> 11074.57 | D36: =D33+D34+D35 -> 12302.27 | E36: =E33+E34+E35 -> 13879.38 | F36: =F33+F34+F35 -> 16344.39 | H36: Other Non-Current Assets | I36: 651.75 | J36: 842.06 | K36: 727.92 | L36: 838.14 | M36: 1118.8 | O36: Other non-current liabilities | P36: 710.3609 | Q36: 677.1887 | R36: 861.3395 | S36: 3205.2818 | T36: 3648.5577 | V36: Equity share capital | W36: 334.39 | X36: 334.39 | Y36: 334.39 | Z36: 334.39 | AA36: 334.39 | AB36: 334.39 | AD36: Provisions | AE36: 76.6246 | AF36: 82.8666 | AG36: 89.0743 | AH36: 89.3337 | AI36: 92.0135
A37: LIABILITIES | H37: Total Non-Current Assets | I37: =SUM(I26:I36) -> 2868.86 | J37: =SUM(J26:J36) -> 3054.27 | K37: =SUM(K26:K36) -> 3240.72 | L37: =SUM(L26:L36) -> 2795.38 | M37: =SUM(M26:M36) -> 3660.62 | O37: Total non-current Liabilities | P37: =SUM(P33:P36) -> 763.7679 | Q37: =SUM(Q33:Q36) -> 756.0379 | R37: =SUM(R33:R36) -> 952.265 | S37: =SUM(S33:S36) -> 3254.9676 | T37: =SUM(T33:T36) -> 3697.47 | V37: Other equity | W37: 12914.12 | X37: 15077.88 | Y37: 18978.74 | Z37: 23237.76 | AA37: 28803.78 | AB37: 34647.22 | AD37: Deferred tax liabilities (net) | AE37: 9.5378 | AF37: 5.5087 | AG37: 10.7813 | AH37: 14.519 | AI37: 13.9839
A38: NON-CURRENT LIABILITIES | H38: CURRENT ASSETS | O38: Current Liabilities | V38: Equity attributable to the owners | W38: =W36+W37 -> 13248.51 | X38: =X36+X37 -> 15412.27 | Y38: =Y36+Y37 -> 19313.13 | Z38: =Z36+Z37 -> 23572.15 | AA38: =AA36+AA37 -> 29138.17 | AB38: =AB36+AB37 -> 34981.61 | AD38: Total non-current liabilities | AE38: =SUM(AE35,AE36:AE37,AE32) -> 96.9129 | AF38: =SUM(AF35,AF36:AF37,AF32) -> 97.612 | AG38: =SUM(AG35,AG36:AG37,AG32) -> 117.7802 | AH38: =SUM(AH35,AH36:AH37,AH32) -> 121.2579 | AI38: =SUM(AI35,AI36:AI37,AI32) -> 122.1214
A39: Deferred income | B39: 68.89 | C39: 164.99 | D39: 148.43 | E39: 133.95 | F39: 117.76 | H39: Inventories | I39: 4622.69 | J39: 5888.61 | K39: 7700.1 | L39: 7356.86 | M39: 5713.37 | O39: Borrowings | P39: 2.1663 | Q39: 0 | R39: 0 | S39: 0 | T39: 0 | V39: Non-controlling interests | W39: 4.31 | X39: 3.91 | Y39: 3.75 | Z39: 3.74 | AA39: 3.64 | AB39: 3.56 | AD39: Current Liabilities
A40: Financial liabilities | H40: Trade Receivables | I40: 1432.82 | J40: 965.94 | K40: 1005.41 | L40: 1002.33 | M40: 1846.93 | O40: Total outstanding dues of micro and small enterprises (Trade Payables) | P40: 13.8062 | Q40: 29.3769 | R40: 39.9637 | S40: 42.7606 | T40: 12.0705 | V40: Total equity | W40: =W38+W39 -> 13252.82 | X40: =X38+X39 -> 15416.18 | Y40: =Y38+Y39 -> 19316.88 | Z40: =Z38+Z39 -> 23575.89 | AA40: =AA38+AA39 -> 29141.81 | AB40: =AB38+AB39 -> 34985.17 | AD40: Borrowings | AE40: 0 | AF40: 0 | AG40: 0 | AH40: 301.1718 | AI40: 55.5848
...

Sheet Income Statement
A1: INCOME STATEMENT | F1: #VALUE! | M1: #VALUE! | T1: #VALUE! | AA1: #VALUE! | AI1: #VALUE!
A2: Particulars | B2: Mar 24 | C2: Mar 23 | D2: Mar 22 | E2: Mar 21 | F2: Mar 20 | H2: Particulars | I2: Mar 24 | J2: Mar 23 | K2: Mar 22 | L2: Mar 21 | M2: Mar 20 | O2: Particulars | P2: 2020 | Q2: 2021 | R2: 2022 | S2: 2023 | T2: 2024 | V2: Particulars | W2: 2020 | X2: 2021 | Y2: 2022 | Z2: 2023 | AA2: 2024 | AC2: Particulars | AD2: 2020 | AE2: 2021 | AF2: 2022 | AG2: 2023 | AH2: 2024 | AI2: 2025
A3: INCOME | H3: INCOME | O3: Income | V3: Income | AC3: Income
A4: Revenue From Operations [Gross] | B4: 9068.01 | C4: 7584.03 | D4: 5717.61 | E4: 4041.58 | F4: 4977.65 | H4: Revenue From Operations [Gross] | I4: 19819.93 | J4: 17333.37 | K4: 15043.67 | L4: 13818.16 | M4: 12967.67 | O4: Revenue from Operations | P4: 1433.2953 | Q4: 1140.8353 | R4: 1757.51 | S4: 2561.1451 | T4: 3592.6423 | V4: Revenue from Operations | W4: 3104.872 | X4: 1913.7595 | Y4: 2817.4028 | Z4: 2489.3925 | AA4: 2369.2751 | AC4: Revenue from Operations | AD4: 21445.16 | AE4: 22754.54 | AF4: 24620.02 | AG4: 26927.46 | AH4: 30381.08 | AI4: 30980.95
A5: Revenue From Operations [Net] | B5: 9068.01 | C5: 7584.03 | D5: 5717.61 | E5: 4041.58 | F5: 4977.65 | H5: Revenue From Operations [Net] | I5: 19819.93 | J5: 17333.37 | K5: 15043.67 | L5: 13818.16 | M5: =M4 -> 12967.67 | O5: Other income | P5: 225.4994 | Q5: 187.5956 | R5: 160.65 | S5: 201.8355 | T5: 299.6219 | V5: Other income | W5: 88.0503 | X5: 94.6136 | Y5: 111.2104 | Z5: 155.4022 | AA5: 361.8293 | AC5: Other income | AD5: 296.57 | AE5: 358.23 | AF5: 984.93 | AG5: 1670.12 | AH5: 1896.6 | AI5: 2561.69
A6: Other Operating Revenues | B6: 398.57 | C6: 243.15 | D6: 15.67 | E6: 6.24 | F6: 0 | H6: Other Operating Revenues | I6: 349.46 | J6: 312.83 | K6: 270.09 | L6: 245.67 | M6: 0 | O6: Total income | P6: =P4+P5 -> 1658.7947 | Q6: =Q4+Q5 -> 1328.4309 | R6: =R4+R5 -> 1918.16 | S6: =S4+S5 -> 2762.9806 | T6: =T4+T5 -> 3892.2642 | V6: Total income | W6: =W4+W5 -> 3192.9223 | X6: =X4+X5 -> 2008.3731 | Y6: =Y4+Y5 -> 2928.6132 | Z6: =Z4+Z5 -> 2644.7947 | AA6: =AA4+AA5 -> 2731.1044 | AC6: Total Income | AD6: =AD4+AD5 -> 21741.73 | AE6: =AE4+AE5 -> 23112.77 | AF6: =AF4+AF5 -> 25604.95 | AG6: =AG4+AG5 -> 28597.58 | AH6: =AH4+AH5 -> 32277.68 | AI6: =AI4+AI5 -> 33542.64
A7: Total Operating Revenues | B7: 9466.58 | C7: 7827.18 | D7: 5733.28 | E7: 4047.82 | F7: =F5+F6 -> 4977.65 | H7: Total Operating Revenues | I7: 20169.39 | J7: 17646.2 | K7: 15313.76 | L7: 14063.83 | M7: 0 | O7: Expenses | V7: Expenses | AC7: Expenses
A8: Other Income | B8: 1138.02 | C8: 713.48 | D8: 433.63 | E8: 574.1 | F8: 557.67 | H8: Other Income | I8: 755.84 | J8: 360.02 | K8: 233.59 | L8: 126.1 | M8: 99.4 | O8: Cost of materials consumed | P8: 691.6971 | Q8: 447.2489 | R8: 935.2037 | S8: 1495.2439 | T8: 2060.3678 | V8: Cost of materials consumed | W8: 1014.0885 | X8: 970.0831 | Y8: 1263.3655 | Z8: 1210.3346 | AA8: 1119.959 | AC8: Cost of materials consumed | AD8: 8164.53 | AE8: 7764.72 | AF8: 8752.24 | AG8: 9993.68 | AH8: 12346.33 | AI8: 19234.46
A9: Total Revenue | B9: 10604.6 | C9: 8540.66 | D9: 6166.91 | E9: =E7+E8 -> 4621.92 | F9: =F7+F8 -> 5535.32 | H9: Total Revenue | I9: 20925.23 | J9: 18006.22 | K9: 15547.35 | L9: 14189.93 | M9: =M5+M8 -> 13067.07 | O9: Purchase of products for resale | P9: 54.2626 | Q9: 23.9227 | R9: 8.365 | S9: 112.1006 | T9: 197.0656 | V9: Changes in inventories of finished goods and WIP | W9: 503.6633 | X9: -128.9075 | Y9: -84.3558 | Z9: -19.0372 | AA9: -222.6315 | AC9: Purchases of stock-in-trade | AD9: 587.15 | AE9: 821.16 | AF9: 656.68 | AG9: 799.15 | AH9: 671.4 | AI9: 679.37
A10: EXPENSES | H10: EXPENSES | O10: Changes in inventories of WIP and scrap | P10: -24.1995 | Q10: 11.329 | R10: 0.3871 | S10: 4.7266 | T10: -6.0555 | V10: Employee benefit expenses | W10: 534.0307 | X10: 501.0886 | Y10: 570.6627 | Z10: 532.4643 | AA10: 600.0076 | AC10: Changes in Inventories of Finished goods, SIT, WIP and scrap | AD10: 635.68 | AE10: 2458.14 | AF10: 592.3 | AG10: -690.72 | AH10: -1958.64 | AI10: -7625.79
A11: Cost Of Materials Consumed | B11: 0 | C11: 0 | D11: 0 | E11: 1881.91 | F11: 2503.18 | H11: Cost Of Materials Consumed | I11: 10497.62 | J11: 9378.44 | K11: 8125.98 | L11: 6723.94 | M11: =5869.26+27.74 -> 5897 | O11: Sub-contracting charges | P11: 170.0721 | Q11: 129.926 | R11: 254.5935 | S11: 317.9334 | T11: 524.9324 | V11: Finance costs | W11: 4.6557 | X11: 3.9128 | Y11: 3.4243 | Z11: 4.5364 | AA11: 3.1052 | AC11: Employee benefit expenses | AD11: 4777.62 | AE11: 4305.17 | AF11: 4604.42 | AG11: 4910.37 | AH11: 5290.69 | AI11: 5730.37
A12: Operating And Direct Expenses | B12: 6627.6 | C12: 5155.53 | D12: 4215.14 | E12: 1155.21 | F12: =362.23+744.09+16.52+113.7 -> 1236.54 | H12: Purchase Of Stock-In Trade | I12: 628.86 | J12: 827.85 | K12: 1053.49 | L12: 1233.21 | M12: 950.97 | O12: Employee benefit expenses | P12: 296.9415 | Q12: 269.3804 | R12: 290.286 | S12: 316.9107 | T12: 348.9333 | V12: Depreciation and amortisation expense | W12: 96.4384 | X12: 94.5384 | Y12: 90.3547 | Z12: 77.2579 | AA12: 67.0392 | AC12: Finance costs | AD12: 348.46 | AE12: 259.17 | AF12: 58.2 | AG12: 57.97 | AH12: 32.11 | AI12: 8.68
A13: Employee Benefit Expenses | B13: 896.55 | C13: 792.71 | D13: 798.73 | E13: 652.81 | F13: 792.92 | H13: Changes In Inventories Of FG,WIP And Stock-In Trade | I13: -560.57 | J13: -397.45 | K13: -276.97 | L13: -129.33 | M13: 249.31 | O13: Finance cost | P13: 1.3356 | Q13: 2.701 | R13: 0.7641 | S13: 6.4807 | T13: 11.4892 | V13: Other expenses | W13: 297.5917 | X13: 226.7766 | Y13: 341.6636 | Z13: 357.4352 | AA13: 335.3895 | AC13: Depreciation and amortization expenses | AD13: 998.52 | AE13: 1178.28 | AF13: 1110.53 | AG13: 1784.67 | AH13: 1407.17 | AI13: 1340.37
A14: Finance Costs | B14: 5.12 | C14: 6.37 | D14: 7.16 | E14: 8.36 | F14: 9.26 | H14: Employee Benefit Expenses | I14: 2466.7 | J14: 2297.73 | K14: 2109.39 | L14: 1940.68 | M14: 2074.74 | O14: Depreciation and amortisation expense | P14: 30.0892 | Q14: 29.0876 | R14: 35.7101 | S14: 39.1663 | T14: 41.3266 | V14: Total expenses | W14: =SUM(W8:W13) -> 2450.4683 | X14: =SUM(X8:X13) -> 1667.492 | Y14: =SUM(Y8:Y13) -> 2185.115 | Z14: =SUM(Z8:Z13) -> 2162.9912 | AA14: =SUM(AA8:AA13) -> 1902.869 | AC14: Impairement loss | AD14: 31.79 | AE14: 63.85 | AF14: 176.43 | AG14: 597.43 | AH14: 14.95 | AI14: 24.75
A15: Provsions and Contingencies | B15: 168.5 | C15: 117.39 | D15: 102.55 | E15: 19.82 | F15: 38.64 | H15: Finance Costs | I15: 7.02 | J15: 14.79 | K15: 4.85 | L15: 6.08 | M15: 3.6 | O15: Other expenses-project related | P15: 73.119 | Q15: 75.3111 | R15: 23.488 | S15: 57.0743 | T15: 99.0402 | V15: Profit/loss before exceptional items and tax | W15: =W6-W14 -> 742.454 | X15: =X6-X14 -> 340.8811 | Y15: =Y6-Y14 -> 743.4982 | Z15: =Z6-Z14 -> 481.8035 | AA15: =AA6-AA14 -> 828.2354 | AC15: Other expenses | AD15: 1448.69 | AE15: 1216.03 | AF15: 1210.86 | AG15: 1560.59 | AH15: 1530.53 | AI15: 1784.62
A16: Depreciation And Amortisation Expenses | B16: 83.13 | C16: 75.58 | D16: 74.51 | E16: 59.65 | F16: 68.69 | H16: Depreciation And Amortisation Expenses | I16: 412.43 | J16: 407.87 | K16: 380.18 | L16: 366.33 | M16: 371.86 | O16: Other expenses | P16: 130.9991 | Q16: 111.6574 | R16: 104.443 | S16: 108.1262 | T16: 134.2437 | V16: Exceptional items | W16: 0 | X16: 0 | Y16: -33.5857 | Z16: 0 | AA16: 0 | AC16: Direct input to WIP/Expenses capitalised | AD16: 178.29 | AE16: 259.77 | AF16: 323.15 | AG16: 516.03 | AH16: 425.99 | AI16: 372.33
A17: Other Expenses | B17: 362.32 | C17: 963.75 | D17: 182.16 | E17: 114.2 | F17: 138.4 | H17: Other Expenses | I17: 2138.61 | J17: 1492.11 | K17: 992.63 | L17: 1114.21 | M17: 1041.19 | O17: Total expenses | P17: =SUM(P8:P16) -> 1424.3167 | Q17: =SUM(Q8:Q16) -> 1100.5641 | R17: =SUM(R8:R16) -> 1653.2405 | S17: =SUM(S8:S16) -> 2457.7627 | T17: =SUM(T8:T16) -> 3411.3433 | V17: Profit before tax | W17: =W15+W16 -> 742.454 | X17: =X15+X16 -> 340.8811 | Y17: =Y15+Y16 -> 709.9125 | Z17: =Z15+Z16 -> 481.8035 | AA17: =AA15+AA16 -> 828.2354 | AC17: Provisions | AD17: 1453.27 | AE17: 1450.26 | AF17: 3729.54 | AG17: 3724.8 | AH17: 3303.04 | AI17: 2527.84
A18: Total Expenses | B18: 8143.22 | C18: 7111.33 | D18: 5380.25 | E18: 3891.96 | F18: =SUM(F11:F17) -> 4787.63 | H18: Total Expenses | I18: 15590.67 | J18: 14021.34 | K18: 12389.55 | L18: 11255.12 | M18: =SUM(M11:M17) -> 10588.67 | O18: Profit before exceptional items and tax | P18: =P6-P17 -> 234.478 | Q18: =Q6-Q17 -> 227.8668 | R18: =R6-R17 -> 264.9195 | S18: =S6-S17 -> 305.2179 | T18: =T6-T17 -> 480.9209 | V18: Tax expense | AC18: Total Gross expenses | AD18: =SUM(AD8:AD17) -> 18624 | AE18: =SUM(AE8:AE17) -> 19776.55 | AF18: =SUM(AF8:AF17) -> 21214.35 | AG18: =SUM(AG8:AG17) -> 23253.97 | AH18: =SUM(AH8:AH17) -> 23063.57 | AI18: =SUM(AI8:AI17) -> 24077
O19: Exceptional items | P19: -10.607 | Q19: -20.7494 | R19: -7.6854 | S19: 0 | T19: 0 | V19: Current tax | W19: 190.0293 | X19: 72.0437 | Y19: 216.5356 | Z19: 127.7536 | AA19: 228.7472 | AC19: Less: Expenses relating to capital and other accounts | AD19: 734.97 | AE19: 933.94 | AF19: 834.16 | AG19: 1163.02 | AH19: 984.27 | AI19: 1355.07
A20: Profit/Loss Before Exceptional, Extraordinary Items And Tax | B20: 2461.38 | C20: 1429.33 | D20: 786.66 | E20: =E9-E18 -> 729.96 | F20: =F9-F18 -> 747.69 | H20: Profit/Loss Before Exceptional, Extraordinary Items And Tax | I20: 5334.56 | J20: 3984.88 | K20: 3157.8 | L20: 2934.81 | M20: =M9-M18 -> 2478.4 | O20: Profit before tax | P20: =P18+P19 -> 223.871 | Q20: =Q18+Q19 -> 207.1174 | R20: =R18+R19 -> 257.2341 | S20: =S18+S19 -> 305.2179 | T20: =T18+T19 -> 480.9209 | V20: Deferred tax | W20: 17.5239 | X20: 11.0722 | Y20: -6.5475 | AA20: -13.2326 | AC20: Total expenses | AD20: =AD18-AD19 -> 17889.03 | AE20: =AE18-AE19 -> 18842.61 | AF20: =AF18-AF19 -> 20380.19 | AG20: =AG18-AG19 -> 22090.95 | AH20: =AH18-AH19 -> 22079.3 | AI20: =AI18-AI19 -> 22721.93
A21: Exceptional Items | B21: 0 | C21: 0 | D21: -13.97 | E21: 126.14 | F21: 12.32 | H21: Profit/Loss Before Tax | I21: 5334.56 | J21: 3984.88 | K21: 3157.8 | L21: 2934.81 | M21: =M20 -> 2478.4 | O21: Tax expense | V21: Total tax expense | W21: =W19+W20 -> 207.5532 | X21: =X19+X20 -> 83.1159 | Y21: =Y19+Y20 -> 209.9881 | Z21: =Z19+Z20 -> 127.7536 | AA21: =AA19+AA20 -> 215.5146 | AC21: Profit/loss before share of Profit/Loss of joint ventures, exceptional items and tax | AD21: =AD6-AD20 -> 3852.7 | AE21: =AE6-AE20 -> 4270.16 | AF21: =AF6-AF20 -> 5224.76 | AG21: =AG6-AG20 -> 6506.63 | AH21: =AH6-AH20 -> 10198.38 | AI21: =AI6-AI20 -> 10820.71
A22: Profit/Loss Before Tax | B22: 2461.38 | C22: 1429.33 | D22: 772.69 | E22: =E20-E21 -> 603.82 | F22: =F20-F21 -> 735.37 | H22: Tax Expenses-Continued Operations | O22: Current tax | P22: 58.0878 | Q22: 58.8711 | R22: 62.82 | S22: 73.539 | T22: 124.5575 | V22: Profit/Loss for the year | W22: =W17-W21 -> 534.9008 | X22: =X17-X21 -> 257.7652 | Y22: =Y17-Y21 -> 499.9244 | Z22: =Z17-Z21 -> 354.0499 | AA22: =AA17-AA21 -> 612.7208 | AC22: Share of profit/loss of joint ventures accounted using equity method | AD22: 7.02 | AE22: 4.81 | AF22: -0.23 | AG22: 2.87 | AH22: 26.5 | AI22: 40.65
A23: Tax Expenses-Continued Operations | H23: Current Tax | I23: 1449.59 | J23: 874.46 | K23: 910.52 | L23: 824.93 | M23: 757.67 | O23: Deferred tax | P23: 2.3015 | Q23: -5.2249 | R23: 4.8948 | S23: 3.5549 | T23: -0.9043 | AC23: Profit/loss before exceptional items and tax | AD23: =AD21+AD22 -> 3859.72 | AE23: =AE21+AE22 -> 4274.97 | AF23: =AF21+AF22 -> 5224.53 | AG23: =AG21+AG22 -> 6509.5 | AH23: =AH21+AH22 -> 10224.88 | AI23: =AI21+AI22 -> 10861.36
A24: Current Tax | B24: 763.88 | C24: 358.87 | D24: 209.44 | E24: 148.63 | F24: 180.43 | H24: Deferred Tax | I24: -66.13 | J24: 123.76 | K24: -101.65 | L24: 69.38 | M24: -31.43 | O24: Total tax expense | P24: =SUM(P22:P23) -> 60.3893 | Q24: =SUM(Q22:Q23) -> 53.6462 | R24: =SUM(R22:R23) -> 67.7148 | S24: =SUM(S22:S23) -> 77.0939 | T24: =SUM(T22:T23) -> 123.6532 | W24: =W15+W11 -> 747.1097 | X24: =X15+X11 -> 344.7939 | Y24: =Y15+Y11 -> 746.9225 | Z24: =Z15+Z11 -> 486.3399 | AA24: =AA15+AA11 -> 831.3406 | AC24: Exceptional items | AD24: 118.92 | AE24: 2.02 | AF24: 0 | AG24: 0 | AH24: 0 | AI24: 5.89
A25: Deferred Tax | B25: -149.69 | C25: -3.27 | D25: -23.22 | E25: -8.88 | F25: 170.32 | H25: Tax For Earlier Years | I25: -68.9 | J25: -20.01 | K25: 0 | L25: -24.92 | M25: -40.47 | O25: Profit for the period | P25: =P20-P24 -> 163.4817 | Q25: =Q20-Q24 -> 153.4712 | R25: =R20-R24 -> 189.5193 | S25: =S20-S24 -> 228.124 | T25: =T20-T24 -> 357.2677 | V25: Revenue YoY | X25: =(X6/W6)-1 -> -0.37099218 | Y25: =(Y6/X6)-1 -> 0.45820177 | Z25: =(Z6/Y6)-1 -> -0.096912252 | AA25: =(AA6/Z6)-1 -> 0.0326338 | AC25: Profit/Loss before tax | AD25: =AD23+AD24 -> 3978.64 | AE25: =AE23+AE24 -> 4276.99 | AF25: =AF23+AF24 -> 5224.53 | AG25: =AG23+AG24 -> 6509.5 | AH25: =AH23+AH24 -> 10224.88 | AI25: =AI23+AI24 -> 10867.25
A26: Tax For Earlier Years | B26: 1.76 | C26: 1.01 | D26: 0 | E26: 10.6 | F26: 0.92 | H26: Total Tax Expenses | I26: 1314.56 | J26: 978.21 | K26: 808.87 | L26: 869.39 | M26: =SUM(M23:M25) -> 685.77 | V26: EPS | W26: =W22/'Company Basic info'!$E$15 -> 14.592349 | X26: =X22/'Company Basic info'!$E$15 -> 7.0319577 | Y26: =Y22/'Company Basic info'!$E$15 -> 13.638176 | Z26: =Z22/'Company Basic info'!$E$15 -> 9.6586503 | AA26: =AA22/'Company Basic info'!$E$15 -> 16.715316 | AC26: Tax expense
A27: Total Tax Expenses | B27: 615.95 | C27: 356.61 | D27: 186.22 | E27: =SUM(E24:E26) -> 150.35 | F27: =SUM(F24:F26) -> 351.67 | H27: Profit/Loss After Tax And Before Extraordinary Items | I27: 4020 | J27: 3006.67 | K27: 2348.93 | L27: 2065.42 | M27: =M21-M26 -> 1792.63 | P27: =P18+P13 -> 235.8136 | Q27: =Q18+Q13 -> 230.5678 | R27: =R18+R13 -> 265.6836 | S27: =S18+S13 -> 311.6986 | T27: =T18+T13 -> 492.4101 | AC27: Current tax | AD27: 1180 | AE27: 645 | AF27: 1900 | AG27: 2250 | AH27: 2905 | AI27: 2880
A28: Profit/Loss After Tax And Before Extraordinary Items | B28: 1845.43 | C28: 1072.72 | D28: 586.47 | E28: =E22-E27 -> 453.47 | F28: =F22-F27 -> 383.7 | H28: Profit/Loss From Continuing Operations | I28: 4020 | J28: 3006.67 | K28: 2348.93 | L28: 2065.42 | M28: =M27 -> 1792.63 | O28: EPS | P28: =P25/'Company Basic info'!$G$15 -> 14.271396 | Q28: =Q25/'Company Basic info'!$G$15 -> 13.397514 | R28: =R25/'Company Basic info'!$G$15 -> 16.54439 | S28: =S25/'Company Basic info'!$G$15 -> 19.914449 | T28: =T25/'Company Basic info'!$G$15 -> 31.188255 | AC28: Earlier year tax refund/liability | AD28: 0 | AE28: -49.33 | AF28: -1192.73 | AG28: -973.46 | AH28: 0 | AI28: -256.08
A29: Profit/Loss From Continuing Operations | B29: 1845.43 | C29: 1072.72 | D29: 586.47 | E29: =E28+60.39 -> 513.86 | F29: =F28+93.37 -> 477.07 | H29: Profit/Loss For The Period | I29: 4020 | J29: 3006.67 | K29: 2348.93 | L29: 2065.42 | M29: =M28+32.09 -> 1824.72 | AC29: Deferred tax | AD29: -84.01 | AE29: 442.26 | AF29: -562.62 | AG29: -594.77 | AH29: -301.07 | AI29: -120.71
A30: Profit/Loss For The Period | B30: 1845.43 | C30: 1072.72 | D30: 586.47 | E30: =E29 -> 513.86 | F30: =F29 -> 477.07 | AC30: Total tax expense | AD30: =SUM(AD27:AD29) -> 1095.99 | AE30: =SUM(AE27:AE29) -> 1037.93 | AF30: =SUM(AF27:AF29) -> 144.65 | AG30: =SUM(AG27:AG29) -> 681.77 | AH30: =SUM(AH27:AH29) -> 2603.93 | AI30: =SUM(AI27:AI29) -> 2503.21
H31: OTHER ADDITIONAL INFORMATION | AC31: Profit/loss for the period from Continuing operations | AD31: =AD25-AD30 -> 2882.65 | AE31: =AE25-AE30 -> 3239.06 | AF31: =AF25-AF30 -> 5079.88 | AG31: =AG25-AG30 -> 5827.73 | AH31: =AH25-AH30 -> 7620.95 | AI31: =AI25-AI30 -> 8364.04
A32: OTHER ADDITIONAL INFORMATION | H32: EARNINGS PER SHARE | AC32: Profit/Loss from discontinued operations | AD32: 0 | AE32: 0 | AF32: 0 | AG32: 0 | AH32: 0 | AI32: 0
A33: EARNINGS PER SHARE | H33: Basic EPS (Rs.) | I33: 5.5 | J33: 4.11 | K33: 9.64 | L33: 8.48 | M33: 7.49 | AC33: Tax expense of discontinued operations | AD33: 0 | AE33: 0 | AF33: 0 | AG33: 0 | AH33: 0 | AI33: 0
A34: Basic EPS (Rs.) | B34: 91.5 | C34: 53.19 | D34: 29.08 | E34: 23.78 | F34: 21.36 | H34: Diluted EPS (Rs.) | I34: 5.5 | J34: 4.11 | K34: 9.64 | L34: 8.48 | M34: 7.49 | AC34: Profit/loss from discontinued operations after tax | AD34: =AD32-AD33 -> 0 | AE34: =AE32-AE33 -> 0 | AF34: =AF32-AF33 -> 0 | AG34: =AG32-AG33 -> 0 | AH34: =AH32-AH33 -> 0 | AI34: =AI32-AI33 -> 0
A35: Diluted EPS (Rs.) | B35: 91.5 | C35: 53.19 | D35: 29.08 | E35: 23.78 | F35: 21.36 | AC35: Profit/Loss for the period | AD35: =AD31+AD34 -> 2882.65 | AE35: =AE31+AE34 -> 3239.06 | AF35: =AF31+AF34 -> 5079.88 | AG35: =AG31+AG34 -> 5827.73 | AH35: =AH31+AH34 -> 7620.95 | AI35: =AI31+AI34 -> 8364.04
I36: =I20+I15 -> 5341.58 | J36: =J20+J15 -> 3999.67 | K36: =K20+K15 -> 3162.65 | L36: =L20+L15 -> 2940.89 | M36: =M20+M15 -> 2482
A37: EBIT | B37: =B20+B14 -> 2466.5 | C37: =C20+C14 -> 1435.7 | D37: =D20+D14 -> 793.82 | E37: =E20+E14 -> 738.32 | F37: =F20+F14 -> 756.95 | AD37: =AD21+AD12 -> 4201.16 | AE37: =AE21+AE12 -> 4529.33 | AF37: =AF21+AF12 -> 5282.96 | AG37: =AG21+AG12 -> 6564.6 | AH37: =AH21+AH12 -> 10230.49 | AI37: =AI21+AI12 -> 10829.39
AC38: EPS | AD38: =AD35/'Company Basic info'!$F$15 -> 43.103435 | AE38: =AE35/'Company Basic info'!$F$15 -> 48.432731 | AF38: =AF35/'Company Basic info'!$F$15 -> 75.957983 | AG38: =AG35/'Company Basic info'!$F$15 -> 87.140369 | AH38: =AH35/'Company Basic info'!$F$15 -> 113.95387 | AI38: =AI35/'Company Basic info'!$F$15 -> 125.06508

Sheet Cash Flow Statement
A1: CASH FLOW STATEMENT | F1: #VALUE! | M1: #VALUE! | T1: #VALUE! | AA1: #VALUE! | AI1: #VALUE!
A2: Particulars | B2: 2020 | C2: 2021 | D2: 2022 | E2: 2023 | F2: 2024 | H2: Particulars | I2: Mar 20 | J2: Mar 21 | K2: Mar 22 | L2: Mar 23 | M2: Mar 24 | O2: Particulars | P2: 2020 | Q2: 2021 | R2: 2022 | S2: 2023 | T2: 2024 | V2: Particulars | W2: 2020 | X2: 2021 | Y2: 2022 | Z2: 2023 | AA2: 2024 | AC2: Particulars | AD2: 2020 | AE2: 2021 | AF2: 2022 | AG2: 2023 | AH2: 2024 | AI2: 2025
A3: CASH FLOW FROM OPERATING ACTIVITIES | H3: CASH FLOW FROM OPERATING ACTIVITIES | O3: Cash flow from Operating Activities | V3: Cash flow from Operating activities | AC3: Cash flow from Operating activities
A4: Profit after share of associate but before exceptional items and tax | B4: 2510.49 | C4: 2972.2 | D4: 3212 | E4: 3968.8 | F4: 5308.34 | H4: Profit before tax but after exceptional items | I4: 726.78 | J4: 603.82 | K4: 749.33 | L4: 1402.68 | M4: 2424.83 | O4: Profit before exceptional items and tax | P4: 742.454 | Q4: 340.8811 | R4: 743.4982 | S4: 481.8035 | T4: 828.2352 | V4: Profit before tax | W4: 223.871 | X4: 207.1174 | Y4: 257.2416 | Z4: 305.2179 | AA4: 480.9209 | AC4: Profit after tax | AD4: 2882.65 | AE4: 3239.06 | AF4: 5079.88 | AG4: 5827.73 | AH4: 7620.95 | AI4: 8364.05
A5: Adjustments for | H5: Ajustments for | O5: Adjustments for | V5: Adjustments for | AC5: Adjustments for
A6: Depreciation and ammortization expense | B6: 371.86 | C6: 387.32 | D6: 401.13 | E6: 428.82 | F6: 443.2 | H6: Plus: Non cash expenditure and non operating expenses | O6: Depreciation and amoritsation expense | P6: 96.4384 | Q6: 94.5384 | R6: 90.3547 | S6: 77.2579 | T6: 67.0392 | V6: Interest income | W6: -203.9684 | X6: -152.6823 | Y6: -130.19 | Z6: -178.34 | AA6: -271.3547 | AC6: Income tax expense | AD6: 1095.99 | AE6: 1037.93 | AF6: 144.65 | AG6: 681.77 | AH6: 2603.93 | AI6: 2503.21
A7: Provision for doubtful advances | B7: 0 | C7: 0 | D7: 0 | E7: -2.6 | F7: 19.13 | H7: Depreciation / Ammortization | I7: 71.14 | J7: 71.08 | K7: 74.51 | L7: 75.58 | M7: 83.13 | O7: Finance costs | P7: 4.6557 | Q7: 3.9128 | R7: 3.4243 | S7: 4.5364 | T7: 3.1052 | V7: Unrealised fair value gain (net) | W7: -6.9694 | X7: -3.1796 | Y7: -4.217 | Z7: -2.6817 | AA7: -5.727 | AC7: Gain/loss on sale of PPE | AD7: -0.23 | AE7: -0.12 | AF7: -1.57 | AG7: -3.18 | AH7: -5.9 | AI7: -1.88
A8: Provision for performance warranty | B8: 0 | C8: 0 | D8: 0 | E8: 32.15 | F8: 168.52 | H8: Finance cost | I8: 9.26 | J8: 8.36 | K8: 7.16 | L8: 6.37 | M8: 5.12 | O8: Interest income | P8: -53.934 | Q8: -56.2886 | R8: -63.7516 | S8: -111.7617 | T8: -319.0637 | V8: Actuarial Gain/loss on remeasurements of defined benefit plan | W8: 4.751 | X8: 3.5552 | Y8: 1.123 | Z8: 0.5433 | AA8: 1.0975 | AC8: Finance cost | AD8: 348.46 | AE8: 259.17 | AF8: 55.86 | AG8: 25.82 | AH8: 31.41 | AI8: 8.68
A9: Provision for onerous contract | B9: 0 | C9: 0 | D9: 0 | E9: 18.44 | F9: 31.32 | H9: Ammortization of prepaid rentals | I9: 0.15 | J9: 0.15 | K9: 0.15 | L9: 0.15 | M9: 0.15 | O9: Profit on sale of PPE | P9: 0.0062 | Q9: -0.1029 | R9: 0.009 | S9: -0.1006 | T9: 0.0624 | V9: Depreciation and amortisation expense | W9: 30.0892 | X9: 29.0876 | Y9: 36.296 | Z9: 39.1663 | AA9: 41.3266 | AC9: Interest income | AD9: -66.29 | AE9: -89.23 | AF9: -687.69 | AG9: -1499.13 | AH9: -1634.43 | AI9: -2287.44
H10: Forex variation | I10: 0 | J10: 0 | K10: 0 | L10: -0.1 | M10: 0.02 | O10: Deferred revenue on customer provided assets | P10: -13.0684 | Q10: -13.4462 | R10: -26.5432 | S10: -10.2106 | T10: -8.2889 | V10: Retirement/write off of assets-net | W10: -1.1053 | X10: -1.5397 | Y10: -0.2822 | Z10: -0.2448 | AA10: 3.0643 | AC10: Share of Profit/Loss of Joint venture | AD10: -7.02 | AE10: -4.81 | AF10: 0.23 | AG10: -2.87 | AH10: -26.5 | AI10: -40.65
A11: Provision for obselete / redundant materials | B11: 0 | C11: 0 | D11: 0 | E11: 177.21 | F11: 72.35 | H11: (-) Non Operating income | O11: Provision for expenses | P11: 21.0192 | Q11: 10.95 | R11: 104.8495 | S11: 26.2219 | T11: 25.3708 | V11: Finance cost | W11: 1.3356 | X11: 2.701 | Y11: 0.7641 | Z11: 6.4807 | AA11: 11.4892 | AC11: Other adjustments | AD11: 0.22 | AE11: -0.14 | AF11: 0.19 | AG11: -0.25 | AH11: 0.45 | AI11: 0.34
A12: Provision for doubtful debts, liquidated damages, customer's claims and disallowances | B12: 0 | C12: 0 | D12: 0 | E12: 375.36 | F12: 831.18 | H12: Profit/Loss on sale of fixed assets | I12: 2.03 | J12: 0 | K12: 2.56 | L12: -0.9 | M12: -1.48 | O12: Liabilities/provisions no required written back | P12: -8.4491 | Q12: -8.2125 | R12: -23.6508 | S12: -9.5993 | T12: -0.1058 | V12: Unrealised loss/gain on foreign exchange fluctuation | W12: -0.2459 | X12: -0.8647 | Y12: -0.449 | Z12: 3.5268 | AA12: 2.5971 | AC12: Net gain/loss on fair value adjustments | AD12: 0.37 | AE12: 0.64 | AF12: 3.13 | AG12: -2.91 | AH12: 2.21 | AI12: -1.68
A13: Provision for intangible assets under development | B13: 0 | C13: 72.13 | D13: 0 | E13: 5.44 | F13: 96.66 | H13: Interest income | I13: -527.78 | J13: -368.24 | K13: -347.48 | L13: -601.77 | M13: -994.41 | O13: Fair value adjustment to investment carried at fair value through P&L | P13: -1.6128 | Q13: -2.0062 | R13: 3.1758 | S13: 1.3024 | T13: -1.2544 | V13: Liquidated damages written back | W13: 0 | X13: -3.397 | Y13: 0 | Z13: -8.4707 | AA13: -6.7567 | AC13: Depreciation, amortisation and impairment expense | AD13: 1030.31 | AE13: 1242.13 | AF13: 1286.96 | AG13: 2382.1 | AH13: 1422.12 | AI13: 1362.67
A14: Intangible assets under development charged off | B14: 0 | C14: 0.75 | D14: 0 | E14: 19.5 | F14: 0 | H14: Ammortization gain on deferred depsoits of vendors | I14: -0.14 | J14: -0.09 | K14: -0.07 | L14: -0.05 | M14: -0.04 | O14: Gain on sale of financial assets measured at fair value through P&L | P14: 0 | Q14: 0 | R14: 0 | S14: 0 | T14: 0 | V14: Liabilities no longer required written back | W14: -6.3903 | X14: 8.9493 | Y14: -6.5455 | Z14: 0 | AA14: 0 | AC14: Reversal of provision for impairment in value of investments | AD14: 1.33 | AE14: 0.25 | AF14: 0.86 | AG14: 0.03 | AH14: 0 | AI14: -7.83
A15: Provision for impairement of capital work in progress | B15: 0 | C15: 14.68 | D15: 0 | E15: 0 | F15: 0 | H15: Ammortization of deferred revenue | I15: -8.07 | J15: -8.04 | K15: -7.63 | L15: -6.87 | M15: -6.87 | O15: Operating profit before working capital changes | P15: =SUM(P4,P6:P14) -> 787.5092 | Q15: =SUM(Q4,Q6:Q14) -> 370.2259 | R15: =SUM(R4,R6:R14) -> 831.3659 | S15: =SUM(S4,S6:S14) -> 459.4499 | T15: =SUM(T4,T6:T14) -> 595.1 | V15: Operating profit before working capital changes | W15: =SUM(W4,W6:W14) -> 41.3675 | X15: =SUM(X4,X6:X14) -> 89.7472 | Y15: =SUM(Y4,Y6:Y14) -> 153.741 | Z15: =SUM(Z4,Z6:Z14) -> 165.1978 | AA15: =SUM(AA4,AA6:AA14) -> 256.6572 | AC15: Provision for doubtful debts | AD15: 37.67 | AE15: 14.26 | AF15: 1054.18 | AG15: 104.16 | AH15: 35.34 | AI15: 0.83
A16: Contract costs charged off | B16: 12.47 | C16: 0 | D16: 0 | E16: 41.8 | F16: 0.02 | H16: Interest income on deferred payment liability to foreign supplier | I16: -3.74 | J16: -3.71 | K16: -3.98 | L16: -4.74 | M16: -4.33 | O16: Changes in working capital | V16: Adjustments for: | AC16: Provision for doubtful contract assets | AD16: 33.42 | AE16: 29.55 | AF16: 67.77 | AG16: 26.78 | AH16: 23.86 | AI16: 150.1
A17: Corporate Social responsibility | B17: 31.17 | C17: 47.11 | D17: 53.48 | E17: 0 | F17: 0 | H17: Interest income deferred deposit with MbPT | I17: -0.19 | J17: -0.2 | K17: -0.22 | L17: -0.23 | M17: -0.25 | O17: Adjustments for | V17: Increase/decrease in trade and other receivables | W17: -303.5833 | X17: 360.3222 | Y17: 27.4111 | Z17: 100.8141 | AA17: -140.811 | AC17: Provision for doubtful claims | AD17: 463.28 | AE17: 211.75 | AF17: 787.29 | AG17: 2450.52 | AH17: 38.98 | AI17: 4.09
A18: Transfer from government grants | B18: -19.98 | C18: -17.36 | D18: -17.13 | E18: -16.55 | F18: -16.57 | H18: Operating profit before working capital changes | I18: =SUM(I4:I17) -> 269.44 | J18: =SUM(J4:J17) -> 303.13 | K18: =SUM(K4:K17) -> 474.33 | L18: =SUM(L4:L17) -> 870.12 | M18: =SUM(M4:M17) -> 1505.87 | O18: Trade receivables | P18: 187.5571 | Q18: 15.6753 | R18: 18.5313 | S18: 119.5886 | T18: -125.8745 | V18: Increase/decrease in other financial assets | W18: 334.8856 | X18: -554.4276 | Y18: -430.42 | Z18: 944.1095 | AA18: 12.1574 | AC18: Provision for doubtful advances | AD18: 213.84 | AE18: 325.61 | AF18: 515.44 | AG18: 439.01 | AH18: 10.15 | AI18: 2.4
A19: Interest income | B19: -70.58 | C19: -60.5 | D19: -176.45 | E19: -260.88 | F19: -571.95 | H19: Movement in working capital | O19: Loans | P19: 0.0654 | Q19: 0.8848 | R19: 0.614 | S19: 0.1141 | T19: 0.0595 | V19: Increase/decrease in other non current assets | W19: -15.5191 | X19: 24.9901 | Y19: -34.3547 | Z19: -51.9615 | AA19: 7.3778 | AC19: Provision for replacement and other charges | AD19: 182.13 | AE19: 430.09 | AF19: 0 | AG19: 0 | AH19: 1166.11 | AI19: 1263.73
A20: Interest on lease liability | B20: 0.28 | C20: 0.24 | D20: 3.06 | E20: 3.7 | F20: 4.21 | H20: Decrease / Increase in inventories | I20: -832.4 | J20: -1265.92 | K20: -1811.49 | L20: 343.24 | M20: 1643.49 | O20: Other financial assets | P20: -978.3477 | Q20: 1206.397 | R20: -69.6539 | S20: -95.8605 | T20: 390.8946 | V20: Increase/decrease in other current assets | W20: -396.6191 | X20: -302.0348 | Y20: -360.144 | Z20: -580.3385 | AA20: 876.4143 | AC20: Provision for warranty | AD20: 521.6 | AE20: 438.75 | AF20: 0 | AG20: 0 | AH20: 324.25 | AI20: 370.15
A21: Finance cost | B21: 3.32 | C21: 6.13 | D21: 1.99 | E21: 11.25 | F21: 2.93 | H21: Decrease / Increase in trade receivables and loans and advances | I21: 46.11 | J21: 470.75 | K21: -37.56 | L21: 7.76 | M21: -859.65 | O21: Inventories | P21: 797.7006 | Q21: -544.0886 | R21: -261.412 | S21: -179.51 | T21: -163.1565 | V21: Increase/decrease in assets held for sale | W21: -0.0973 | X21: 0.0943 | Y21: -0.0248 | Z21: 0.3797 | AA21: -0.0809 | AC21: Provision for raw materials and components | AD21: -207.21 | AE21: -321.83 | AF21: 560.05 | AG21: 281.4 | AH21: 1001.64 | AI21: 76.78
A22: Profit on sale of property, plant and equipment | B22: -0.21 | C22: -1.21 | D22: -0.45 | E22: -1.52 | F22: -7.02 | H22: Decrease / Increase Other current and non-current assets | I22: 387.03 | J22: -3136.06 | K22: -2489.61 | L22: 1808.26 | M22: 565.9 | O22: Other assets | P22: 18.7543 | Q22: -106.8408 | R22: 15.6874 | S22: 53.3272 | T22: -1318.6308 | V22: Increase/decrease in Inventories | W22: -91.4531 | X22: -346.8523 | Y22: -384.3935 | Z22: -1746.2369 | AA22: -1065.9365 | AC22: Provision for liquidated damages | AD22: 0 | AE22: 0 | AF22: 743.95 | AG22: 422.9 | AH22: 702.71 | AI22: 658.43
A23: Operating Profit before working capital changes | B23: =SUM(B4:B22) -> 2838.82 | C23: =SUM(C4:C22) -> 3421.49 | D23: =SUM(D4:D22) -> 3477.63 | E23: =SUM(E4:E22) -> 4800.92 | F23: =SUM(F4:F22) -> 6382.32 | H23: Decrease / Increase in trade payables and provisions | I23: 1829.63 | J23: 1106.34 | K23: -528.66 | L23: -1801.94 | M23: 24.44 | O23: Adjustments for increase/decrease in operating liabilities | V23: Increase/decrease in Trade payables | W23: 173.1744 | X23: 235.288 | Y23: -362.1053 | Z23: 761.4678 | AA23: -180.3596 | AC23: Operating profit before working capital changes | AD23: =SUM(AD4,AD6:AD22) -> 6530.52 | AE23: =SUM(AE4,AE6:AE22) -> 6813.06 | AF23: =SUM(AF4,AF6:AF22) -> 9611.18 | AG23: =SUM(AG4,AG6:AG22) -> 11133.88 | AH23: =SUM(AH4,AH6:AH22) -> 13317.28 | AI23: =SUM(AI4,AI6:AI22) -> 12425.98
A24: Increase/ Decrease in | H24: Decrease / Increase in other current and non-current liabilities | I24: -1587.2 | J24: 2746.65 | K24: 4532.81 | L24: 600.31 | M24: -1519.14 | O24: Trade payables | P24: -173.9719 | Q24: 397.1158 | R24: -190.1313 | S24: -88.0915 | T24: 334.0088 | V24: Increase/decrease in provisions | W24: 22.3954 | X24: 10.0196 | Y24: 16.897 | Z24: -124.9321 | AA24: 18.6783 | AC24: Adjustments for
A25: Trade Receivables | B25: -1350.35 | C25: 162.03 | D25: 453.9 | E25: -1300.75 | F25: -1190.08 | H25: Cash flow from operations | I25: =I18+SUM(I20:I24) -> 112.61 | J25: =J18+SUM(J20:J24) -> 224.89 | K25: =K18+SUM(K20:K24) -> 139.82 | L25: =L18+SUM(L20:L24) -> 1827.75 | M25: =M18+SUM(M20:M24) -> 1360.91 | O25: Other financial liabilities | P25: 41.601 | Q25: -22.5313 | R25: 26.8995 | S25: 17.3623 | T25: 123.7122 | V25: Increase/decrease in other financial liabilities | W25: 2.7395 | X25: -0.2519 | Y25: 1.5911 | Z25: 3.8624 | AA25: 4.8229 | AC25: Increase/decrease in trade receivables | AD25: -1883.81 | AE25: 5078.18 | AF25: 611.37 | AG25: -1749.45 | AH25: -2474.43 | AI25: -4177.07
A26: Loans | B26: -5.97 | C26: 40.79 | D26: 0.12 | E26: 0.48 | F26: -0.16 | H26: Direct tax paid | I26: -208.15 | J26: -156.68 | K26: -302.45 | L26: -312.15 | M26: -677.16 | O26: Other liabilities | P26: 51.4426 | Q26: -88.0383 | R26: 364.0412 | S26: 2079.5551 | T26: 748.8828 | V26: Increase/decrease in other current liabilities | W26: 737.6515 | X26: 1058.0822 | Y26: 1078.132 | Z26: 2051.2272 | AA26: -371.625 | AC26: Increase/decrease in Loans, Financial assets and other assets | AD26: -30.02 | AE26: -217.4 | AF26: -1351.44 | AG26: -1624.92 | AH26: -1361.94 | AI26: -2620.31
A27: Other financial assets | B27: 4.21 | C27: -27.13 | D27: -34.56 | E27: -111.37 | F27: 45.65 | H27: Net cash from / used in Operating activities | I27: =I25+I26 -> -95.54 | J27: =J25+J26 -> 68.21 | K27: =K25+K26 -> -162.63 | L27: =L25+L26 -> 1515.6 | M27: =M25+M26 -> 683.75 | O27: Provisions | P27: -54.4451 | Q27: -82.9644 | R27: -2.8596 | S27: -14.9568 | T27: -17.311 | V27: Increase/decrease in other non-current liabilities | W27: -1.6875 | X27: -4.0291 | Y27: 5.2726 | Z27: 3.7377 | AA27: -0.5351 | AC27: Increase/decrease in Inventories | AD27: 46.23 | AE27: 2461.04 | AF27: 1765.67 | AG27: 1917.19 | AH27: -2070.49 | AI27: -8534.94
A28: Other assets | B28: -1365.28 | C28: -902.72 | D28: -1154.59 | E28: 140.44 | F28: 592.55 | H28: CASH FLOW FROM INVESTING ACTIVITIES | O28: Cash generated from operations | P28: =SUM(P15,P18:P22,P24:P27) -> 677.8655 | Q28: =SUM(Q15,Q18:Q22,Q24:Q27) -> 1145.8354 | R28: =SUM(R15,R18:R22,R24:R27) -> 733.0825 | S28: =SUM(S15,S18:S22,S24:S27) -> 2350.9784 | T28: =SUM(T15,T18:T22,T24:T27) -> 567.6851 | V28: Cash generated from/used in operations | W28: =SUM(W17:W27,W15) -> 503.2545 | X28: =SUM(X17:X27,X15) -> 570.9479 | Y28: =SUM(Y17:Y27,Y15) -> -288.3975 | Z28: =SUM(Z17:Z27,Z15) -> 1527.3272 | AA28: =SUM(AA17:AA27,AA15) -> -583.2402 | AC28: Increase/decrease in trade payables | AD28: 1454.5 | AE28: -1842.72 | AF28: 302.01 | AG28: 577.36 | AH28: 277.9 | AI28: 1692.8
A29: Inventories | B29: 473.64 | C29: -996.51 | D29: -611.88 | E29: -1011.88 | F29: -1065.33 | H29: Purchase of property, plant and equipment | I29: -109.5 | J29: -41.9 | K29: -32.01 | L29: -135.57 | M29: 103.03 | O29: Income tax paid | P29: -173.6441 | Q29: -77.8224 | R29: -203.4235 | S29: -218.1218 | T29: -155.9665 | V29: Taxes paid | W29: 124.5821 | X29: -53.6462 | Y29: -67.7148 | Z29: -77.0939 | AA29: -123.6532 | AC29: Increase/decrease in financial liabilities, provisions and other liabilities | AD29: -2770.13 | AE29: 3689.14 | AF29: 261.79 | AG29: 1331.36 | AH29: 2503.83 | AI29: 18395.15
A30: Trade payables | B30: 1016.02 | C30: 848.86 | D30: 70.45 | E30: -38.89 | F30: 375.56 | H30: Capital work in progress | I30: 8.81 | J30: -0.19 | K30: -6.79 | L30: 25.32 | M30: -10.01 | O30: Net cash flow before exceptional items | P30: =P28+P29 -> 504.2214 | Q30: =Q28+Q29 -> 1068.013 | R30: =R28+R29 -> 529.659 | S30: =S28+S29 -> 2132.8566 | T30: =T28+T29 -> 411.7186 | V30: Net cash from/used in operating activities | W30: =W28+W29 -> 627.8366 | X30: =X28+X29 -> 517.3017 | Y30: =Y28+Y29 -> -356.1123 | Z30: =Z28+Z29 -> 1450.2333 | AA30: =AA28+AA29 -> -706.8934 | AC30: Cash generated from Operations | AD30: =SUM(AD25:AD29,AD23) -> 3347.29 | AE30: =SUM(AE25:AE29,AE23) -> 15981.3 | AF30: =SUM(AF25:AF29,AF23) -> 11200.58 | AG30: =SUM(AG25:AG29,AG23) -> 11585.42 | AH30: =SUM(AH25:AH29,AH23) -> 10192.15 | AI30: =SUM(AI25:AI29,AI23) -> 17181.61
A31: Other financial liabilities | B31: -99.25 | C31: 78.91 | D31: 60.93 | E31: 327.16 | F31: 33.51 | H31: Proceeds from sale of property, plant and equipment | I31: 0.17 | J31: 0.16 | K31: 1.27 | L31: 1.31 | M31: 1.66 | O31: Exceptional items | P31: 0 | Q31: 0 | R31: 0 | S31: 0 | T31: 0 | V31: Cash flow from Investing activities | AC31: Income tax paid | AD31: -1819.9 | AE31: -718.58 | AF31: -1027.45 | AG31: -2755.7 | AH31: -1969.33 | AI31: -3538.15
A32: Provisions | B32: 33.04 | C32: 146.5 | D32: 267.55 | E32: -1029.41 | F32: -86.94 | H32: Capital advance | I32: -1.01 | J32: 1.03 | K32: -2.39 | L32: -5.26 | M32: -431.17 | O32: Net cash from/used in operating activities | P32: =P30+P31 -> 504.2214 | Q32: =Q30+Q31 -> 1068.013 | R32: =R30+R31 -> 529.659 | S32: =S30+S31 -> 2132.8566 | T32: =T30+T31 -> 411.7186 | V32: Purchase of PPE | W32: -67.3676 | X32: -163.844 | Y32: -54.8278 | Z32: -42.2584 | AA32: -48.0691 | AC32: Net cash used in/generated from Operating activities | AD32: =AD30+AD31 -> 1527.39 | AE32: =AE30+AE31 -> 15262.72 | AF32: =AF30+AF31 -> 10173.13 | AG32: =AG30+AG31 -> 8829.72 | AH32: =AH30+AH31 -> 8222.82 | AI32: =AI30+AI31 -> 13643.46
A33: Other liabilities | B33: 1758.8 | C33: 2977.06 | D33: 2606.11 | E33: 489.99 | F33: 990.78 | H33: Interest received | I33: 527.78 | J33: 368.24 | K33: 347.48 | L33: 601.77 | M33: 994.41 | O33: Cash Flow from Investing activities | V33: Investments in Mutual fund (net) | W33: -51.8494 | X33: -771.8153 | Y33: 629.1414 | Z33: -36.5728 | AA33: 233.664 | AC33: Cash flow from Investing activities
A34: Current tax asstes | B34: -159.03 | C34: -122.99 | D34: -124.15 | E34: 0 | F34: 0 | H34: Dividend received | I34: 31.33 | J34: 26.1 | K34: 23.36 | L34: 26.65 | M34: 36.55 | O34: Purchase of PPE | P34: -56.8884 | Q34: -56.6091 | R34: -102.0442 | S34: -108.2571 | T34: -80.8897 | V34: Investments in fixed deposits (net) | W34: 249.7652 | X34: -389.7576 | Y34: -276.1749 | Z34: -1765.7944 | AA34: 598.7523 | AC34: Purchase of PPE | AD34: -890.23 | AE34: -762.98 | AF34: -799.29 | AG34: -782.42 | AH34: -916.42 | AI34: -930.09
H35: Fixed deposits / Term deposits | I35: 0 | J35: 0 | K35: 0 | L35: -658 | M35: 731.85 | O35: Bank deposits | P35: -11.654 | Q35: -738.038 | R35: -530.452 | S35: -1171.49 | T35: -828.66 | V35: Interest received | W35: 114.4014 | X35: 152.6823 | Y35: 130.19 | Z35: 178.34 | AA35: 271.3547 | AC35: Purchase of Intangible assets | AD35: -490.49 | AE35: -554.3 | AF35: -701.28 | AG35: -998.8 | AH35: -838.75 | AI35: -826.83
A36: Cash generated from Operations | B36: =B23+SUM(B25:B34) -> 3144.65 | C36: =C23+SUM(C25:C34) -> 5626.29 | D36: =D23+SUM(D25:D34) -> 5011.51 | E36: =E23+SUM(E25:E34) -> 2266.69 | F36: =F23+SUM(F25:F34) -> 6077.86 | H36: Principal portion of lease payments | I36: -3.86 | J36: -5.19 | K36: -4.52 | L36: -5.88 | M36: -6.51 | O36: Proceeds from sale of PPE | P36: 0.0036 | Q36: 0.1121 | R36: 0.0045 | S36: 0.1936 | T36: 0.1747 | V36: Net cash from/used in investing activities | W36: =SUM(W32:W35) -> 244.9496 | X36: =SUM(X32:X35) -> -1172.7346 | Y36: =SUM(Y32:Y35) -> 428.3287 | Z36: =SUM(Z32:Z35) -> -1666.2856 | AA36: =SUM(AA32:AA35) -> 1055.7019 | AC36: Proceeds from sale of PPE | AD36: 1.57 | AE36: 1.23 | AF36: 3.17 | AG36: 5.06 | AH36: 7.97 | AI36: 3.35
