Workbook

Sheet Company Profile
A1: COMPANY PROFILE
A2: Logo | B2: #VALUE! | C2: #VALUE! | D2: #VALUE! | E2: #VALUE! | F2: #VALUE!
A3: Name | B3: Adani Power | C3: Reliance Power | D3: TATA Power | E3: JSW Energy | F3: NTPC
A4: Company Name | B4: #VALUE! | C4: #VALUE! | D4: #VALUE! | E4: #VALUE! | F4: #VALUE!
A5: Ticker Symbol | B5: {=_FV(B4,"Ticker symbol",TRUE)} -> 533096 | C5: {=_FV(C4,"Ticker symbol",TRUE)} -> 532939 | D5: {=_FV(D4,"Ticker symbol",TRUE)} -> 500400 | E5: {=_FV(E4,"Ticker symbol",TRUE)} -> 533148 | F5: {=_FV(F4,"Ticker symbol",TRUE)} -> NTPC
A6: Industry | B6: {=_FV(B4,"Industry")} -> Electrical Utilities & IPPs | C6: {=_FV(C4,"Industry")} -> Electrical Utilities & IPPs | D6: {=_FV(D4,"Industry")} -> Electrical Utilities & IPPs | E6: {=_FV(E4,"Industry")} -> Electrical Utilities & IPPs | F6: {=_FV(F4,"Industry")} -> Electrical Utilities & IPPs
A7: Listed Exchange | B7: {=_FV(B4,"Exchange")} -> Bombay Stock Exchange | C7: {=_FV(C4,"Exchange")} -> Bombay Stock Exchange | D7: {=_FV(D4,"Exchange")} -> Bombay Stock Exchange | E7: {=_FV(E4,"Exchange")} -> Bombay Stock Exchange | F7: {=_FV(F4,"Exchange")} -> National Stock Exchange of India
A8: Year of Corporation | B8: {=_FV(B4,"Year incorporated",TRUE)} -> 1996 | C8: {=_FV(C4,"Year incorporated",TRUE)} -> 1995 | D8: {=_FV(D4,"Year incorporated",TRUE)} -> 1919 | E8: {=_FV(E4,"Year incorporated",TRUE)} -> 1994 | F8: {=_FV(F4,"Year incorporated",TRUE)} -> 1975
A9: Market Capitalization | B9: {=_FV(B4,"Market cap",TRUE)} -> 2921246000000 | C9: {=_FV(C4,"Market cap",TRUE)} -> 162080900000 | D9: {=_FV(D4,"Market cap",TRUE)} -> 1256408000000 | E9: {=_FV(E4,"Market cap",TRUE)} -> 906696900000 | F9: {=_FV(F4,"Market cap",TRUE)} -> 3162083000000
A10: Exchange rate | B10: #VALUE! | C10: #VALUE! | D10: #VALUE! | E10: #VALUE! | F10: #VALUE!
B11: {=_FV(B10,"Price")} -> 0.01127 | C11: {=_FV(C10,"Price")} -> 0.01127 | D11: {=_FV(D10,"Price")} -> 0.01127 | E11: {=_FV(E10,"Price")} -> 0.01127 | F11: {=_FV(F10,"Price")} -> 0.01127
A12: Mcap in USD | B12: =B9*B11 -> 32922442420 | C12: =C9*C11 -> 1826651743 | D12: =D9*D11 -> 14159718160 | E12: =E9*E11 -> 10218474063 | F12: =F9*F11 -> 35636675410
A13: Market Price | B13: {=_FV(B4,"Price")} -> 150.05 | C13: {=_FV(C4,"Price")} -> 41.13 | D13: {=_FV(D4,"Price")} -> 395.95 | E13: {=_FV(E4,"Price")} -> 522.35 | F13: {=_FV(F4,"Price")} -> 325.45
A14: Shares Outstanding | B14: {=_FV(B4,"Shares outstanding",TRUE)} -> 19284700000 | C14: {=_FV(C4,"Shares outstanding",TRUE)} -> 4135771000 | D14: {=_FV(D4,"Shares outstanding",TRUE)} -> 3195340000 | E14: {=_FV(E4,"Shares outstanding",TRUE)} -> 1746503000 | F14: {=_FV(F4,"Shares outstanding",TRUE)} -> 9696666000
B15: =B14/10000000 -> 1928.47 | C15: =C14/10000000 -> 413.5771 | D15: =D14/10000000 -> 319.534 | E15: =E14/10000000 -> 174.6503 | F15: =F14/10000000 -> 969.6666
A16: Daily change | B16: {=_FV(B4,"Change (%)",TRUE)} -> -0.009571 | C16: {=_FV(C4,"Change (%)",TRUE)} -> 0.048165 | D16: {=_FV(D4,"Change (%)",TRUE)} -> 0.006482 | E16: {=_FV(E4,"Change (%)",TRUE)} -> 0.005002 | F16: {=_FV(F4,"Change (%)",TRUE)} -> -0.001993
A17: Beta | B17: {=_FV(B4,"Beta")} -> 1.1437 | C17: {=_FV(C4,"Beta")} -> 2.5566 | D17: {=_FV(D4,"Beta")} -> 1.4704 | E17: {=_FV(E4,"Beta")} -> 1.2627 | F17: {=_FV(F4,"Beta")} -> 1.101
A18: 52 Week Low | B18: {=_FV(B4,"52 week low",TRUE)} -> 86.17 | C18: {=_FV(C4,"52 week low",TRUE)} -> 31.3 | D18: {=_FV(D4,"52 week low",TRUE)} -> 326.25 | E18: {=_FV(E4,"52 week low",TRUE)} -> 419.1 | F18: {=_FV(F4,"52 week low",TRUE)} -> 292.8
A19: 52 Week High | B19: {=_FV(B4,"52 week high",TRUE)} -> 182.75 | C19: {=_FV(C4,"52 week high",TRUE)} -> 76.49 | D19: {=_FV(D4,"52 week high",TRUE)} -> 454.8 | E19: {=_FV(E4,"52 week high",TRUE)} -> 776.35 | F19: {=_FV(F4,"52 week high",TRUE)} -> 414.3

Sheet Balance Sheet
A1: Balance Sheet (ADANI POWER) | F1: #VALUE! | H1: Balance Sheet (Reliance Power) | M1: #VALUE! | O1: Balance Sheet (TATA Power) | T1: #VALUE! | V1: Balance Sheet (JSW Energy) | AA1: #VALUE! | AC1: Balance Sheet (NTPC) | AH1: #VALUE!
A2: Particulars | B2: Mar 20 | C2: Mar 21 | D2: Mar 22 | E2: Mar 23 | F2: Mar 24 | H2: Particulars | I2: Mar 20 | J2: Mar 21 | K2: Mar 22 | L2: Mar 23 | M2: Mar 24 | O2: Particulars | P2: Mar 20 | Q2: Mar 21 | R2: Mar 22 | S2: Mar 23 | T2: Mar 24 | V2: Particulars | W2: Mar 20 | X2: Mar 21 | Y2: Mar 22 | Z2: Mar 23 | AA2: Mar 24 | AC2: Particulars | AD2: Mar 20 | AE2: Mar 21 | AF2: Mar 22 | AG2: Mar 23 | AH2: Mar 24
A3: ASSETS | H3: ASSETS | O3: ASSETS | V3: Property, Plant and equipment | W3: 15217.11 | X3: 14166.26 | Y3: 13422.82 | Z3: 23065.01 | AA3: 26088.16 | AC3: ASSETS
A4: Non-Current Assets | H4: Non current assets | O4: Non current assets | V4: Capital work in progress | W4: 391.32 | X4: 472.77 | Y4: 2090.6 | Z4: 4779.5 | AA4: 10282.3 | AC4: Non-current assets
A5: Property, Plant and Equipment | B5: 55571.1 | C5: 52575.24 | D5: 53071.62 | E5: 50543.8 | F5: 62812.71 | H5: Property, plant and equipments | I5: 38526 | J5: 37144.68 | K5: 36263.94 | L5: 35733.76 | M5: 33543.18 | O5: Property, plant and equipment | P5: 44662.61 | Q5: 48748.86 | R5: 50502.96 | S5: 54524.96 | T5: 59624.06 | V5: Goodwill | W5: 639.82 | X5: 639.82 | Y5: 639.82 | Z5: 639.82 | AA5: 639.82 | AC5: Property, plant and equipment | AD5: 187176.46 | AE5: 202598.05 | AF5: 224343.75 | AG5: 239882.5 | AH5: 258423.86
A6: Capital work in progress | B6: 2346.77 | C6: 6439.42 | D6: 10269.74 | E6: 12879.54 | F6: 925.12 | H6: Capital work in progress | I6: 3614.79 | J6: 1911.68 | K6: 2019.95 | L6: 2319.59 | M6: 1293.41 | O6: Capital work in progress | P6: 1611.52 | Q6: 3599.8 | R6: 4635.1 | S6: 5376.36 | T6: 11561.31 | V6: Other intangible assets | W6: 855.82 | X6: 830.68 | Y6: 768 | Z6: 1315.66 | AA6: 2218.22 | AC6: Capital work in progress | AD6: 98210.94 | AE6: 97404.16 | AF6: 91025.21 | AG6: 89133.12 | AH6: 87592.8
A7: Investment Property | B7: 0 | C7: 0 | D7: 0 | E7: 704.94 | F7: 0 | H7: Goodwill on consolidation | I7: 14.11 | J7: 14.11 | K7: 14.11 | L7: 14.11 | M7: 14.11 | O7: Goodwill | P7: 1641.57 | Q7: 1794.57 | R7: 1858.31 | S7: 1858.31 | T7: 1757.46 | V7: Intangible assets under development | W7: 0 | X7: 0 | Y7: 0 | Z7: 8.69 | AA7: 2.79 | AC7: Intangible assets | AD7: 626.33 | AE7: 647.13 | AF7: 579.27 | AG7: 541.92 | AH7: 509.77
A8: Goodwill | B8: 190.61 | C8: 190.61 | D8: 190.61 | E8: 190.61 | F8: 190.61 | H8: Other intangible assets | I8: 33.49 | J8: 31.64 | K8: 29.8 | L8: 28.16 | M8: 26.33 | O8: Other intangible assets | P8: 1362.18 | Q8: 1345.85 | R8: =1366.18+3661.99 -> 5028.17 | S8: =3982.05+1381.34 -> 5363.39 | T8: =4368.75+1459.29 -> 5828.04 | V8: Investment in an associate and a joint venture | W8: 10.53 | X8: 27.68 | Y8: 36.22 | Z8: 55.51 | AA8: 72.02 | AC8: Intangible assets under development | AD8: 297.53 | AE8: 101.87 | AF8: 101.05 | AG8: 45.88 | AH8: 71.65
A9: Intangible Assets | B9: 84.1 | C9: 85.45 | D9: 11.98 | E9: 12.03 | F9: 12.53 | H9: Financial Assets | O9: Investments accounted for using equity method | P9: 13202.65 | Q9: 11920.63 | R9: 12580 | S9: 14218.88 | T9: 12983.51 | V9: Financial Assets | AC9: Investments accounted for using the equity method | AD9: 9256.31 | AE9: 9992.18 | AF9: 10522.14 | AG9: 13252.09 | AH9: 15130.96
A10: Financial Assets | H10: Investments | I10: 0.23 | J10: 4.29 | K10: 4.43 | L10: 4.43 | M10: 172.77 | O10: Financial assets | V10: Investments | W10: 1098.96 | X10: 3340.24 | Y10: 5194.6 | Z10: 4906.11 | AA10: 5873.76 | AC10: Financial assets
A11: Investments | B11: 0.01 | C11: 0.01 | D11: 0.01 | E11: 42.51 | F11: 0.01 | H11: Loans | I11: 407.86 | J11: 395.18 | K11: 400.88 | L11: 434.77 | M11: 0 | O11: Other investments | P11: 632.68 | Q11: 728.88 | R11: 1169.81 | S11: 1301.21 | T11: 1854.59 | V11: Trade receivables | W11: 0 | X11: 5.34 | Y11: 99.46 | Z11: 99.46 | AA11: 176.26 | AC11: Investments | AD11: 50.28 | AE11: 97.08 | AF11: 104.1 | AG11: 632.7 | AH11: 703.6
A12: Loans | B12: 0 | C12: 0 | D12: 0 | E12: 0 | F12: 0 | H12: Financial lease receivables | I12: 4240.85 | J12: 3944.79 | K12: 3648.26 | L12: 3381.53 | M12: 3307.93 | O12: Trade receivables | P12: 30.28 | Q12: 604.71 | R12: 685.78 | S12: 359.63 | T12: 273.29 | V12: Loans | W12: 664.96 | X12: 569.09 | Y12: 567.64 | Z12: 567.64 | AA12: 567.64 | AC12: Loans | AD12: 511.08 | AE12: 554.97 | AF12: 559.81 | AG12: 553.77 | AH12: 570.19
A13: Other Financial Assets | B13: 427.91 | C13: 245.44 | D13: 856.04 | E13: 779.71 | F13: 636.2 | H13: Other Financial assets | I13: 97.52 | J13: 81.3 | K13: 71.74 | L13: 46.96 | M13: 42.33 | O13: Loans | P13: 80.88 | Q13: 58.14 | R13: 3.45 | S13: 2.99 | T13: 2.48 | V13: Other Financial assets | W13: 1195.22 | X13: 1262.84 | Y13: 1312.97 | Z13: 2092.07 | AA13: 2139.16 | AC13: Trade receivables | AD13: 0 | AE13: 0 | AF13: 0 | AG13: 2638.68 | AH13: 1287.54
A14: Deferred tax assets (Net) | B14: 0 | C14: 0 | D14: 0 | E14: 0 | F14: 376.34 | H14: Non current tax assets | I14: 59.79 | J14: 51.83 | K14: 67.51 | L14: 78.46 | M14: 92.87 | O14: Financial lease receivables | P14: 588.92 | Q14: 598.61 | R14: 588.69 | S14: 567.22 | T14: 561.66 | V14: Income tax assets (net) | W14: 123.85 | X14: 112.27 | Y14: 130.26 | Z14: 192.55 | AA14: 216.49 | AC14: Other finance assets | AD14: 1206.32 | AE14: 1092.84 | AF14: 1017.98 | AG14: 900.7 | AH14: 710.8
A15: Other Non-current Assets | B15: 1811.32 | C15: 1627.39 | D15: 1352.95 | E15: 1115.13 | F15: 1784.67 | H15: Other non current assets | I15: 1493.85 | J15: 1480.06 | K15: 1481.29 | L15: 1469.8 | M15: 520.06 | O15: Other financial assets | P15: 578.79 | Q15: 1577.04 | R15: 1684.53 | S15: 1726.66 | T15: 2084.5 | V15: Deferred tax assets (net) | W15: 180.54 | X15: 229.76 | Y15: 418.2 | Z15: 324.44 | AA15: 502.25 | AC15: Deferred tax assets (net) | AD15: 1096.6 | AE15: 1075.89 | AF15: 995.7 | AG15: 937.85 | AH15: 1169.9
A16: Total Non-current Assets | B16: =SUM(B5:B9,B11:B15) -> 60431.82 | C16: =SUM(C5:C9,C11:C15) -> 61163.56 | D16: =SUM(D5:D9,D11:D15) -> 65752.95 | E16: =SUM(E5:E9,E11:E15) -> 66268.27 | F16: =SUM(F5:F9,F11:F15) -> 66738.19 | H16: Total non current assets | I16: =SUM(I5:I8,I10:I15) -> 48488.49 | J16: =SUM(J5:J8,J10:J15) -> 45059.56 | K16: =SUM(K5:K8,K10:K15) -> 44001.91 | L16: =SUM(L5:L8,L10:L15) -> 43511.57 | M16: =SUM(M5:M8,M10:M15) -> 39012.99 | O16: Non current tax assets (net) | P16: 342 | Q16: 328.35 | R16: 520.54 | S16: 739.07 | T16: 585.89 | V16: Other non-current assets | W16: 186.08 | X16: 315.5 | Y16: 1051.45 | Z16: 1071.13 | AA16: 825.45 | AC16: Other non-current assets | AD16: 14092.61 | AE16: 17031.51 | AF16: 15877.02 | AG16: 16333.91 | AH16: 16016.17
A17: Current Assets | H17: Current assets | O17: Deferred tax assets (net) | P17: 74.24 | Q17: 184.02 | R17: 334.6 | S17: 252.9 | T17: 499.09 | V17: Total non-current assets | W17: =SUM(W3:W8,W10:W16) -> 20564.21 | X17: =SUM(X3:X8,X10:X16) -> 21972.25 | Y17: =SUM(Y3:Y8,Y10:Y16) -> 25732.04 | Z17: =SUM(Z3:Z8,Z10:Z16) -> 39117.59 | AA17: =SUM(AA3:AA8,AA10:AA16) -> 49604.32 | AC17: Total non current assets | AD17: =SUM(AD5:AD9,AD11:AD16) -> 312524.46 | AE17: =SUM(AE5:AE9,AE11:AE16) -> 330595.68 | AF17: =SUM(AF5:AF9,AF11:AF16) -> 345126.03 | AG17: =SUM(AG5:AG9,AG11:AG16) -> 364853.12 | AH17: =SUM(AH5:AH9,AH11:AH16) -> 382187.24
A18: Inventories | B18: 2522.77 | C18: 2025.11 | D18: 2258.27 | E18: 3075.2 | F18: 4142.1 | H18: Inventories | I18: 1014.18 | J18: 874.12 | K18: 828.04 | L18: 925.32 | M18: 961.17 | O18: Other non current assets | P18: 1185.12 | Q18: 1465.06 | R18: 1849.82 | S18: 2532.46 | T18: 5173.57 | V18: Current Assets | AC18: Current assets
A19: Financial Assets | H19: Financial assets | O19: Total non current assets | P19: =SUM(P5:P9,P11:P18) -> 65993.44 | Q19: =SUM(Q5:Q9,Q11:Q18) -> 72954.52 | R19: =SUM(R5:R9,R11:R18) -> 81441.76 | S19: =SUM(S5:S9,S11:S18) -> 88824.04 | T19: =SUM(T5:T9,T11:T18) -> 102789.45 | V19: Inventories | W19: 639.58 | X19: 395.08 | Y19: 901.02 | Z19: 987.08 | AA19: 830.67 | AC19: Inventories | AD19: 11138.54 | AE19: 9809.6 | AF19: 10139.29 | AG19: 14240.37 | AH19: 18019.12
A20: Investments | B20: 2.79 | C20: 20.09 | D20: 183.24 | E20: 611.54 | F20: 373.5 | H20: Investments | I20: 30.21 | J20: 31.28 | K20: 32.32 | L20: 34.12 | M20: 36.58 | O20: Current Assets | V20: Financial Assets | AC20: Financial assets
A21: Trade Receivables | B21: 8366.47 | C21: 11839.28 | D21: 9560.92 | E21: 11529.36 | F21: 11677.48 | H21: Trade receivables | I21: 2364.52 | J21: 2409.88 | K21: 3213.5 | L21: 2679.9 | M21: 1650.41 | O21: Inventories | P21: 1752.35 | Q21: 1884.8 | R21: 4231.52 | S21: 3942.88 | T21: 4419.63 | V21: Investments | W21: 744.07 | X21: 684.23 | Y21: 1392.35 | Z21: 1071.15 | AA21: 1089.08 | AC21: Investments | AD21: 0 | AE21: 499.99 | AF21: 0 | AG21: 50 | AH21: 50
A22: Cash and Cash equivalents | B22: 941.1 | C22: 113.04 | D22: 782.37 | E22: 349.23 | F22: 1136.25 | H22: Cash and cash equivalents | I22: 124.94 | J22: 144.2 | K22: 164.88 | L22: 238.65 | M22: 486.15 | O22: Financial assets | V22: Trade receivables | W22: 1565.2 | X22: 964.46 | Y22: 670.22 | Z22: 1531.92 | AA22: 844.2 | AC22: Trade receivables | AD22: 20314.59 | AE22: 17718.07 | AF22: 27970.87 | AG22: 28825.22 | AH22: 33349.68
A23: Bank balance other than Cash equivalents | B23: 1038.21 | C23: 1494.28 | D23: 1582.31 | E23: 1524.42 | F23: 6075.51 | H23: Bank balances other than cash and cash equivalents | I23: 159.49 | J23: 171.01 | K23: 480.48 | L23: 412.51 | M23: 431.45 | O23: Investments | P23: 699.51 | Q23: 499.54 | R23: 410.52 | S23: 1149.6 | T23: 1477.89 | V23: Unbilled revenue | W23: 543.81 | X23: 336.78 | Y23: 544.43 | Z23: 776.03 | AA23: 859.34 | AC23: Cash and cash equivalents | AD23: 589.52 | AE23: 950.02 | AF23: 675.77 | AG23: 465.65 | AH23: 863.34
A24: Loans | B24: 3.05 | C24: 8.83 | D24: 7.62 | E24: 3.19 | F24: 3.49 | H24: Loans | I24: 139.1 | J24: 154.89 | K24: 191.59 | L24: 166.28 | M24: 483.26 | O24: Trade receivables | P24: 4425.9 | Q24: 5000.97 | R24: 5979.74 | S24: 6952.15 | T24: 7401.69 | V24: Cash and cash equivalents | W24: 151.69 | X24: 366.84 | Y24: 585.15 | Z24: 3422.29 | AA24: 3091.74 | AC24: Bank Balances other than cash | AD24: 2624.77 | AE24: 3437.78 | AF24: 3782.31 | AG24: 4482.88 | AH24: 5984
A25: Other Financial Assets | B25: 767.65 | C25: 325.12 | D25: 308.28 | E25: 557.5 | F25: 435.82 | H25: Finance lease receivables | I25: 298.76 | J25: 297.66 | K25: 296.53 | L25: 266.72 | M25: 169.16 | O25: Unbilled revenue | P25: 799.42 | Q25: 1573.64 | R25: 2285.57 | S25: 2456.71 | T25: 2552.23 | V25: Bank balances other than cash above | W25: 49.04 | X25: 112.34 | Y25: 548.95 | Z25: 591.59 | AA25: 1114.86 | AC25: Loans | AD25: 252.67 | AE25: 259.13 | AF25: 270.37 | AG25: 268.78 | AH25: 271.12
A26: Other Current assets | B26: 951.14 | C26: 1023.08 | D26: 1545.06 | E26: 1902.56 | F26: 1742.43 | H26: Other financial assets | I26: 665.39 | J26: 565.67 | K26: =419.76+1.02 -> 420.78 | L26: =112.57+1.05 -> 113.62 | M26: =90.06+1.36 -> 91.42 | O26: Cash and cash equivalents | P26: 1861.5 | Q26: 3782.51 | R26: 3077.24 | S26: 4189.76 | T26: 3324.34 | V26: Loans | W26: 250.84 | X26: 1130.84 | Y26: 150.9 | Z26: 180.9 | AA26: 110.9 | AC26: Other finance assets | AD26: =13081.12+8501.08 -> 21582.2 | AE26: =14991.26+9086.7 -> 24077.96 | AF26: =5826.14+9525.32 -> 15351.46 | AG26: =8912.07+11160.27 -> 20072.34 | AH26: =13212.71+11238.78 -> 24451.49
A27: Total Current Assets | B27: =SUM(B18,B20:B26) -> 14593.18 | C27: =SUM(C18,C20:C26) -> 16848.83 | D27: =SUM(D18,D20:D26) -> 16228.07 | E27: =SUM(E18,E20:E26) -> 19553 | F27: =SUM(F18,F20:F26) -> 25586.58 | H27: Other current assets | I27: 57.3 | J27: 218.56 | K27: 109.19 | L27: 114.29 | M27: 229.52 | O27: Bank balance other cash | P27: 232.68 | Q27: 2330.17 | R27: 3563.46 | S27: 7016.77 | T27: 5827.57 | V27: Other Financial assets | W27: =484.36+119.06 -> 603.42 | X27: =254.19+104.99 -> 359.18 | Y27: =252.78+154.61 -> 407.39 | Z27: =675.91+285.6 -> 961.51 | AA27: =194.52+529.47 -> 723.99 | AC27: Current tax assets (net) | AD27: 60.96 | AE27: 64.7 | AF27: 62.64 | AG27: 93.51 | AH27: 46.78
A28: Assets classified as held for sale | B28: 0 | C28: 793.52 | D28: 0 | E28: 0 | H28: Total current assets | I28: =SUM(I18,I20:I27) -> 4853.89 | J28: =SUM(J18,J20:J27) -> 4867.27 | K28: =SUM(K18,K20:K27) -> 5737.31 | L28: =SUM(L18,L20:L27) -> 4951.41 | M28: =SUM(M18,M20:M27) -> 4539.12 | O28: Loans | P28: 33 | Q28: 30.71 | R28: 9.34 | S28: 11.55 | T28: 11.14 | V28: Total Current assets | W28: =SUM(W19,W21:W27) -> 4547.65 | X28: =SUM(X19,X21:X27) -> 4349.75 | Y28: =SUM(Y19,Y21:Y27) -> 5200.41 | Z28: =SUM(Z19,Z21:Z27) -> 9522.47 | AA28: =SUM(AA19,AA21:AA27) -> 8664.78 | AC28: Total current assets | AD28: =SUM(AD19,AD21:AD27) -> 56563.25 | AE28: =SUM(AE19,AE21:AE27) -> 56817.25 | AF28: =SUM(AF19,AF21:AF27) -> 58252.71 | AG28: =SUM(AG19,AG21:AG27) -> 68498.75 | AH28: =SUM(AH19,AH21:AH27) -> 83035.53
A29: Total Assets | B29: =B16+B27 -> 75025 | C29: =C16+C27+C28 -> 78805.91 | D29: =D16+D27 -> 81981.02 | E29: =E16+E27 -> 85821.27 | F29: =F16+F27 -> 92324.77 | H29: Assets classified held for sale | I29: 0.52 | J29: 855 | K29: 72.44 | L29: 72.44 | M29: 208.15 | O29: Financial lease receivables | P29: 33.2 | Q29: 41.45 | R29: 46.91 | S29: 54.5 | T29: 65.92 | V29: Assets classified as held for sale | W29: 0 | X29: 114.33 | Y29: 0 | Z29: 101.64 | AA29: 0 | AC29: Assets held for sale | AD29: 0 | AE29: 0 | AF29: 18.5 | AG29: 120.92 | AH29: 117.77
A30: EQUITY AND LIABILITIES | H30: Total assets | I30: =I16+I28+I29 -> 53342.9 | J30: =J16+J28+J29 -> 50781.83 | K30: =K16+K28+K29 -> 49811.66 | L30: =L16+L28+L29 -> 48535.42 | M30: =M16+M28+M29 -> 43760.26 | O30: Other financial assets | P30: 1412.43 | Q30: 310.15 | R30: 501.45 | S30: 688.3 | T30: 471.48 | V30: Total assets | W30: =W17+W28+W29 -> 25111.86 | X30: =X17+X28+X29 -> 26436.33 | Y30: =Y17+Y28+Y29 -> 30932.45 | Z30: =Z17+Z28+Z29 -> 48741.7 | AA30: =AA17+AA28+AA29 -> 58269.1 | AC30: Regulatory deferral a/c debit balances | AD30: 9397.73 | AE30: 11553.28 | AF30: 13199.17 | AG30: 12548.66 | AH30: 14856.03
A31: EQUITY | H31: EQUITY AND LIABILITIES | O31: Current tax assets (net) | P31: 1.1 | Q31: 0.45 | R31: 0.01 | S31: 0.69 | T31: 8.2 | V31: EQUITY AND LIABILITIES | AC31: Total Assets | AD31: =AD17+AD28+AD29+AD30 -> 378485.44 | AE31: =AE17+AE28+AE29+AE30 -> 398966.21 | AF31: =AF17+AF28+AF29+AF30 -> 416596.41 | AG31: =AG17+AG28+AG29+AG30 -> 446021.45 | AH31: =AH17+AH28+AH29+AH30 -> 480196.57
A32: Equity share capital | B32: 3856.94 | C32: 3856.94 | D32: 3856.94 | E32: 3856.94 | F32: 3856.94 | H32: Equity | O32: Other current assets | P32: 770.39 | Q32: 916.69 | R32: 1479.67 | S32: 1328.72 | T32: 1704.3 | V32: Equity | AC32: EQUITY AND LIABILITIES
A33: Unsecured perpetual securities | B33: 8615 | C33: 12615 | D33: 13215 | E33: 13215 | F33: 7315 | H33: Equity share capital | I33: 2805.13 | J33: 2805.13 | K33: 3400.13 | L33: 3735.21 | M33: 4016.98 | O33: Total current assets | P33: =SUM(P21,P23:P32) -> 12021.48 | Q33: =SUM(Q21,Q23:Q32) -> 16371.08 | R33: =SUM(R21,R23:R32) -> 21585.43 | S33: =SUM(S21,S23:S32) -> 27791.63 | T33: =SUM(T21,T23:T32) -> 27264.39 | V33: Equity share capital | W33: 1641.9 | X33: 1642.33 | Y33: 1639.67 | Z33: 1640.54 | AA33: 1641.22 | AC33: Equity
A34: Other equity | B34: -5991.5 | C34: -3359.35 | D34: 1631.5 | E34: 12803.72 | F34: 31973.09 | H34: Other Equity | I34: 9063.74 | J34: 9440.71 | K34: =182.5+8879.9 -> 9062.4 | L34: =80+7780.17 -> 7860.17 | M34: 7596.88 | O34: Assets classified as held for sale | P34: 6253.06 | Q34: 3047.46 | R34: 3046.83 | S34: 3299.94 | T34: 1200.99 | V34: Other equity | W34: 10003.72 | X34: 12864.67 | Y34: 15775.23 | Z34: 16988.27 | AA34: 19190.52 | AC34: Equity share capital | AD34: 9894.56 | AE34: 9696.67 | AF34: 9696.67 | AG34: 9696.67 | AH34: 9696.67
A35: Equity attributed to equity holders of the parent | B35: =SUM(B32:B34) -> 6480.44 | C35: =SUM(C32:C34) -> 13112.59 | D35: =SUM(D32:D34) -> 18703.44 | E35: =SUM(E32:E34) -> 29875.66 | F35: =SUM(F32:F34) -> 43145.03 | H35: Equity attributable to the owners of the company | I35: =I33+I34 -> 11868.87 | J35: =J33+J34 -> 12245.84 | K35: =K33+K34 -> 12462.53 | L35: =L33+L34 -> 11595.38 | M35: =M33+M34 -> 11613.86 | O35: Total Assets before regulatory deferred a/c | P35: =P19+P33+P34 -> 84267.98 | Q35: =Q19+Q33+Q34 -> 92373.06 | R35: =R19+R33+R34 -> 106074.02 | S35: =S19+S33+S34 -> 119915.61 | T35: =T19+T33+T34 -> 131254.83 | V35: Equity attributable to owners of the parent | W35: =W33+W34 -> 11645.62 | X35: =X33+X34 -> 14507 | Y35: =Y33+Y34 -> 17414.9 | Z35: =Z33+Z34 -> 18628.81 | AA35: =AA33+AA34 -> 20831.74 | AC35: Other equity | AD35: 108944.6 | AE35: 116041.8 | AF35: 125677.07 | AG35: 137326.5 | AH35: 151012.6
A36: Non-Controlling interests | B36: 0.01 | C36: 0.01 | D36: 0 | E36: 0 | F36: 0 | H36: Non controlling interests | I36: 1352.79 | J36: 1568.01 | K36: 1621.57 | L36: 1691.75 | M36: 0 | O36: Regulatory deferred a/c- Assets | P36: 5480.17 | Q36: 6478.17 | R36: 6810.57 | S36: 8433.43 | T36: 8298.66 | V36: Non-controlling interests | W36: -23.84 | X36: -8.72 | Y36: 2.06 | Z36: 105.37 | AA36: 182.5 | AC36: Total equity attributable to owners of the company | AD36: =AD34+AD35 -> 118839.16 | AE36: =AE34+AE35 -> 125738.47 | AF36: =AF34+AF35 -> 135373.74 | AG36: =AG34+AG35 -> 147023.17 | AH36: =AH34+AH35 -> 160709.27
A37: Total Equity | B37: =B35+B36 -> 6480.45 | C37: =C35+C36 -> 13112.6 | D37: =D35+D36 -> 18703.44 | E37: =E35+E36 -> 29875.66 | F37: =F35+F36 -> 43145.03 | H37: Total equity | I37: =I35+I36 -> 13221.66 | J37: =J35+J36 -> 13813.85 | K37: =K35+K36 -> 14084.1 | L37: =L35+L36 -> 13287.13 | M37: =M35+M36 -> 11613.86 | O37: Total Assets | P37: =P35+P36 -> 89748.15 | Q37: =Q35+Q36 -> 98851.23 | R37: =R35+R36 -> 112884.59 | S37: =S35+S36 -> 128349.04 | T37: =T35+T36 -> 139553.49 | V37: Total equity | W37: =W35+W36 -> 11621.78 | X37: =X35+X36 -> 14498.28 | Y37: =Y35+Y36 -> 17416.96 | Z37: =Z35+Z36 -> 18734.18 | AA37: =AA35+AA36 -> 21014.24 | AC37: Non-controlling interests | AD37: 3317.19 | AE37: 3523.71 | AF37: 3760.41 | AG37: 3930.45 | AH37: 4413.01
A38: LIABILITIES | H38: Liabilities | O38: EQUITY AND LIABILITIES | V38: Liabilities | AC38: Total equity | AD38: =AD36+AD37 -> 122156.35 | AE38: =AE36+AE37 -> 129262.18 | AF38: =AF36+AF37 -> 139134.15 | AG38: =AG36+AG37 -> 150953.62 | AH38: =AH36+AH37 -> 165122.28
A39: Non current Liabilities | H39: Non current liabilities | O39: EQUITY | V39: Non Current liabilities | AC39: Liabilities
A40: Financial Liabilities | H40: Financial liabilities | O40: Equity share capital | P40: 270.5 | Q40: 319.56 | R40: 319.56 | S40: 319.56 | T40: 319.56 | V40: Financial liabilities | AC40: Non-current Liabilities
...

Sheet Income Statement
A1: INCOME STATEMENT (ADANI POWER) | F1: #VALUE! | H1: INCOME STATEMENT (Reliance Power) | M1: #VALUE! | O1: INCOME STATEMENT (TATA Power) | T1: #VALUE! | V1: INCOME STATEMENT (JSW Energy) | AA1: #VALUE! | AC1: INCOME STATEMENT (NTPC) | AH1: #VALUE!
A2: Particulars | B2: Mar 20 | C2: Mar 21 | D2: Mar 22 | E2: Mar 23 | F2: Mar 24 | H2: Particulars | I2: Mar 20 | J2: Mar 21 | K2: Mar 22 | L2: Mar 23 | M2: Mar 24 | O2: Particulars | P2: Mar 20 | Q2: Mar 21 | R2: Mar 22 | S2: Mar 23 | T2: Mar 24 | V2: Particulars | W2: Mar 20 | X2: Mar 21 | Y2: Mar 22 | Z2: Mar 23 | AA2: Mar 24 | AC2: Particulars | AD2: Mar 20 | AE2: Mar 21 | AF2: Mar 22 | AG2: Mar 23 | AH2: Mar 24
A3: INCOME | H3: INCOME | O3: Revenue from operations | P3: 29136.37 | Q3: 32468.1 | R3: 42815.67 | S3: 55109.08 | T3: 61448.9 | V3: INCOME | AC3: INCOME
A4: Revenue from operations | B4: 26467.72 | C4: 26221.48 | D4: 27711.18 | E4: 38773.3 | F4: 50351.25 | H4: Revenue from Operations | I4: 7562.27 | J4: 7934.01 | K4: 7503.11 | L4: 7542.69 | M4: 7892.6 | O4: Other income | P4: 562.61 | Q4: 439.24 | R4: 919.96 | S4: 1438.02 | T4: 1823.42 | V4: Revenue from operations | W4: 8272.71 | X4: 6922.2 | Y4: 8167.15 | Z4: 10331.81 | AA4: 11486.91 | AC4: Revenue from operations | AD4: 109464.04 | AE4: 111531.15 | AF4: 132669.28 | AG4: 176206.93 | AH4: 178500.88
A5: Other income | B5: 1374.09 | C5: 1928.2 | D5: 3975.29 | E5: 4267.22 | F5: 9930.23 | H5: Other income | I5: 640.14 | J5: 454.59 | K5: 183.62 | L5: 340.05 | M5: 367.63 | O5: Total income | P5: =P3+P4 -> 29698.98 | Q5: =Q3+Q4 -> 32907.34 | R5: =R3+R4 -> 43735.63 | S5: =S3+S4 -> 56547.1 | T5: =T3+T4 -> 63272.32 | V5: Other income | W5: 286.98 | X5: 237.45 | Y5: 568.69 | Z5: 535.24 | AA5: 455.43 | AC5: Other income | AD5: 2908.54 | AE5: 4015.68 | AF5: 2325.03 | AG5: 1770.24 | AH5: 2664.98
A6: Total Income | B6: =B4+B5 -> 27841.81 | C6: =C4+C5 -> 28149.68 | D6: =D4+D5 -> 31686.47 | E6: =E4+E5 -> 43040.52 | F6: =F4+F5 -> 60281.48 | H6: Total Income | I6: =I4+I5 -> 8202.41 | J6: =J4+J5 -> 8388.6 | K6: =K4+K5 -> 7686.73 | L6: =L4+L5 -> 7882.74 | M6: =M4+M5 -> 8260.23 | O6: EXPENSES | V6: Total Income | W6: =W4+W5 -> 8559.69 | X6: =X4+X5 -> 7159.65 | Y6: =Y4+Y5 -> 8735.84 | Z6: =Z4+Z5 -> 10867.05 | AA6: =AA4+AA5 -> 11942.34 | AC6: Total Income | AD6: =AD4+AD5 -> 112372.58 | AE6: =AE4+AE5 -> 115546.83 | AF6: =AF4+AF5 -> 134994.31 | AG6: =AG4+AG5 -> 177977.17 | AH6: =AH4+AH5 -> 181165.86
A7: EXPENSES | H7: EXPENSES | O7: Cost of power purchased | P7: 6220.46 | Q7: 8334.41 | R7: 14640.62 | S7: 19062.67 | T7: 20014.46 | V7: EXPENSES | AC7: EXPENSES
A8: Fuel cost | B8: 17580.39 | C8: 14781.15 | D8: 14762.21 | E8: 25480.85 | F8: 28452.64 | H8: Cost of fuel consumed (including cost of coal excavation) | I8: 2896.6 | J8: 3116.69 | K8: 3025.8 | L8: 3654.76 | M8: 3831.35 | O8: Cost of fuel | P8: =9922.39+214 -> 10136.39 | Q8: =9074.96+504.6 -> 9579.56 | R8: =8290.92+1018.19 -> 9309.11 | S8: =13763.59+1194.95 -> 14958.54 | T8: =14130.47+1168.69 -> 15299.16 | V8: Fuel costs | W8: 4460.51 | X8: 3283.04 | Y8: 3493.95 | Z8: 5569.7 | AA8: 4581.6 | AC8: Fuel cost | AD8: 57185.69 | AE8: 56099.26 | AF8: 69752.97 | AG8: 100655.78 | AH8: 98311.96
A9: Purchase of stock in trade / Power for resale | B9: 467.1 | C9: 365.3 | D9: 545.56 | E9: 214.14 | F9: 222.26 | H9: Employee benefit expenses | I9: 209.33 | J9: 156.06 | K9: 173.74 | L9: 178.81 | M9: 184.24 | O9: Raw material consumed and construction cost (including project land and sub-contracting cost) | P9: 957.18 | Q9: 2628.19 | R9: 3832.83 | S9: 3882.3 | T9: 5439.86 | V9: Purchase of power | W9: 37.75 | X9: 0 | Y9: 80.21 | Z9: 367.6 | AA9: 124.79 | AC9: Electricity purchased for trading | AD9: 5185.95 | AE9: 5049.42 | AF9: 5584.69 | AG9: 5324.95 | AH9: 5682.79
A10: Transmission charges | B10: 621.82 | C10: 664.31 | D10: 642.77 | E10: 519.61 | F10: 503.99 | H10: Finance cost | I10: 3053.97 | J10: 2538.59 | K10: 2349.08 | L10: 2526.61 | M10: 2451.29 | O10: Purchase of finished goods and spares | P10: 111.74 | Q10: 28.89 | R10: 49.11 | S10: 56.15 | T10: 39.89 | V10: Employee benefit expenses | W10: 242.96 | X10: 236.63 | Y10: 264.15 | Z10: 307.6 | AA10: 364.47 | AC10: Employee benefit expenses | AD10: 5830.48 | AE10: 5953.93 | AF10: 6310.09 | AG10: 6528.34 | AH10: 6592.03
A11: Employee benefit expenses | B11: 426.82 | C11: 431.54 | D11: 470.31 | E11: 569.99 | F11: 643.7 | H11: Depreciation and ammortization | I11: 836.3 | J11: 1083.21 | K11: 1077.28 | L11: 1032.73 | M11: 1061.75 | O11: Decrease/Increase in stock-in-trade and work in progress | P11: -15.64 | Q11: 0.41 | R11: -199.22 | S11: 43.53 | T11: -51.78 | V11: Changes in inventories | W11: 0 | X11: 0 | Y11: 0 | Z11: 0 | AA11: 0.63 | AC11: Finance cost | AD11: 8116.85 | AE11: 9224.14 | AF11: 9315.98 | AG11: 11156.06 | AH11: 12048.21
A12: Finance costs | B12: 5314.82 | C12: 5106.33 | D12: 4094.78 | E12: 3333.5 | F12: 3388.09 | H12: Generation, Administration and other expenses | I12: 1433.71 | J12: 1086.3 | K12: 1582.23 | L12: 1824.14 | M12: 2719.7 | O12: Employee benefit expenses | P12: 1440.64 | Q12: 2156.48 | R12: 3611.63 | S12: 3624.26 | T12: 4036.09 | V12: Finance costs | W12: 1051.07 | X12: 895.65 | Y12: 776.91 | Z12: 844.3 | AA12: 2053.4 | AC12: Depreciation and ammortization expense | AD12: 10356.16 | AE12: 12450.31 | AF12: 13787.83 | AG12: 14792.27 | AH12: 16203.63
A13: Depreciation and ammortization expense | B13: 3006.5 | C13: 3201.65 | D13: 3117.54 | E13: 3303.68 | F13: 3931.33 | H13: Total Expenses | I13: =SUM(I8:I12) -> 8429.91 | J13: =SUM(J8:J12) -> 7980.85 | K13: =SUM(K8:K12) -> 8208.13 | L13: =SUM(L8:L12) -> 9217.05 | M13: =SUM(M8:M12) -> 10248.33 | O13: Finance cost | P13: 4493.73 | Q13: 4010.39 | R13: 3859.02 | S13: 4371.65 | T13: 4633.22 | V13: Depreciation and ammortization expense | W13: 1168.05 | X13: 1166.94 | Y13: 1131.05 | Z13: 1169.23 | AA13: 1633.41 | AC13: Other expenses | AD13: 9725.41 | AE13: 10454.71 | AF13: 10741.97 | AG13: 15968.95 | AH13: 16821.39
A14: Other expense | B14: 1686.29 | C14: 1310.66 | D14: 1476.17 | E14: 1944.05 | F14: 2347.96 | H14: Profit/Loss before exceptional items and tax | I14: =I6-I13 -> -227.5 | J14: =J6-J13 -> 407.75 | K14: =K6-K13 -> -521.4 | L14: =L6-L13 -> -1334.31 | M14: =M6-M13 -> -1988.1 | O14: Depreciation and ammortization | P14: 2633.56 | Q14: 2744.94 | R14: 3122.2 | S14: 3439.2 | T14: 3786.37 | V14: Other expense | W14: 574.63 | X14: 495.95 | Y14: 759.84 | Z14: 805.07 | AA14: 1032.64 | AC14: Total expenses | AD14: =SUM(AD8:AD13) -> 96400.54 | AE14: =SUM(AE8:AE13) -> 99231.77 | AF14: =SUM(AF8:AF13) -> 115493.53 | AG14: =SUM(AG8:AG13) -> 154426.35 | AH14: =SUM(AH8:AH13) -> 155660.01
A15: Total expenses | B15: =SUM(B8:B14) -> 29103.74 | C15: =SUM(C8:C14) -> 25860.94 | D15: =SUM(D8:D14) -> 25109.34 | E15: =SUM(E8:E14) -> 35365.82 | F15: =SUM(F8:F14) -> 39489.97 | H15: Exceptional items | O15: Other expenses | P15: 2342.78 | Q15: 2812.48 | R15: 4060.42 | S15: 5775.31 | T15: 5887.39 | V15: Total expenses | W15: =SUM(W8:W14) -> 7534.97 | X15: =SUM(X8:X14) -> 6078.21 | Y15: =SUM(Y8:Y14) -> 6506.11 | Z15: =SUM(Z8:Z14) -> 9063.5 | AA15: =SUM(AA8:AA14) -> 9790.94 | AC15: Profit before share of profits of joint ventures accounted for using equity method, tax and regulatory deferral a/c balances | AD15: =AD6-AD14 -> 15972.04 | AE15: =AE6-AE14 -> 16315.06 | AF15: =AF6-AF14 -> 19500.78 | AG15: =AG6-AG14 -> 23550.82 | AH15: =AH6-AH14 -> 25505.85
A16: Profit / Loss from operations before exceptional items, tax and deferred tax | B16: =B6-B15 -> -1261.93 | C16: =C6-C15 -> 2288.74 | D16: =D6-D15 -> 6577.13 | E16: =E6-E15 -> 7674.7 | F16: =F6-F15 -> 20791.51 | H16: Impairement of property, plant and equipments and capital work in progress | I16: -4004.21 | J16: 0 | K16: 0 | L16: 0 | M16: -1926.35 | O16: Total expenses | P16: =SUM(P7:P15) -> 28320.84 | Q16: =SUM(Q7:Q15) -> 32295.75 | R16: =SUM(R7:R15) -> 42285.72 | S16: =SUM(S7:S15) -> 55213.61 | T16: =SUM(T7:T15) -> 59084.66 | V16: Share of profit of joint venture and an associate | W16: 28.04 | X16: 17.15 | Y16: 8.54 | Z16: 19.29 | AA16: 16.51 | AC16: Add: Share of profits of joint ventures accounted for using equity method | AD16: 405.4 | AE16: 683.87 | AF16: 1020.13 | AG16: 779.77 | AH16: 1635.6
A17: Less: Exceptional items | B17: 1002.99 | C17: 0 | D17: 0 | E17: 0 | F17: 0 | H17: Liabilities written back | I17: 0 | J17: 4.42 | K17: 0 | L17: 1036.86 | M17: 1886.3 | O17: Profit/Loss before movement in regulatory deferral balances, exceptional items, tax and share of net profit of associates and Joint ventures accounted for using the equity method | P17: =P5-P16 -> 1378.14 | Q17: =Q5-Q16 -> 611.59 | R17: =R5-R16 -> 1449.91 | S17: =S5-S16 -> 1333.49 | T17: =T5-T16 -> 4187.66 | V17: Profit before exceptional items, tax and deferred tax adjustable in future tariff | W17: =W6-W15+W16 -> 1052.76 | X17: =X6-X15+X16 -> 1098.59 | Y17: =Y6-Y15+Y16 -> 2238.27 | Z17: =Z6-Z15+Z16 -> 1822.84 | AA17: =AA6-AA15+AA16 -> 2167.91 | AC17: Profit before exceptional items, tax and regulatory deferral a/c balances | AD17: =AD15+AD16 -> 16377.44 | AE17: =AE15+AE16 -> 16998.93 | AF17: =AF15+AF16 -> 20520.91 | AG17: =AG15+AG16 -> 24330.59 | AH17: =AH15+AH16 -> 27141.45
A18: Profit/Loss before tax and deferred tax recoverable from future tariff | B18: =B16-B17 -> -2264.92 | C18: =C16-C17 -> 2288.74 | D18: =D16-D17 -> 6577.13 | E18: =E16-E17 -> 7674.7 | F18: =F16-F17 -> 20791.51 | H18: Total exceptional items | I18: =SUM(I16:I17) -> -4004.21 | J18: =SUM(J16:J17) -> 4.42 | K18: 0 | L18: =SUM(L16:L17) -> 1036.86 | M18: =SUM(M16:M17) -> -40.05 | O18: Add/Less: Net movement in regulatory deferral balances | P18: -451.68 | Q18: 529.24 | R18: -380.42 | S18: 815.7 | T18: 56.24 | V18: Exceptional items (net) | W18: -61.46 | X18: 0 | Y18: 0 | Z18: 120 | AA18: 0 | AC18: Exceptional items | AD18: 0 | AE18: 1512.19 | AF18: 0 | AG18: 0 | AH18: 0
A19: Tax expense | H19: Profit/Loss before tax | I19: =I14+I18 -> -4231.71 | J19: =J14+J18 -> 412.17 | K19: =K14+K18 -> -521.4 | L19: =L14+L18 -> -297.45 | M19: =M14+M18 -> -2028.15 | O19: Add/Less: Net movement in regulatory deferral balances in respect of earlier years | P19: -21.32 | Q19: 0 | R19: 0 | S19: -8.53 | T19: 7.34 | V19: Profit before tax and deferred tax adjustable in future tariff | W19: =W17-W18 -> 1114.22 | X19: =X17-X18 -> 1098.59 | Y19: =Y17-Y18 -> 2238.27 | Z19: =Z17+Z18 -> 1942.84 | AA19: =AA17-AA18 -> 2167.91 | AC19: Profit before tax and regulatory deferral a/c balances | AD19: =AD17-AD18 -> 16377.44 | AE19: =AE17-AE18 -> 15486.74 | AF19: =AF17-AF18 -> 20520.91 | AG19: =AG17-AG18 -> 24330.59 | AH19: =AH17-AH18 -> 27141.45
A20: Current tax | B20: 24.68 | C20: 25.64 | D20: 768.34 | E20: 0.58 | F20: 0.09 | H20: Income tax expense | O20: Add/Less: Deferred tax recoverable/Payable | P20: 284.31 | Q20: 81.8 | R20: 140.95 | S20: 116.88 | T20: 29.85 | V20: Tax expense | AC20: Tax expenses
A21: Excess provision for earlier years written back | B21: -7.33 | C21: -4.27 | D21: -0.11 | E21: -768.18 | F21: 13.91 | H21: Current tax | I21: 45.18 | J21: 56.46 | K21: 23.13 | L21: 46.21 | M21: 18.13 | O21: Total movement in regulatory deferral balances (Net) | P21: =P18+P19+P20 -> -188.69 | Q21: =Q18+Q19+Q20 -> 611.04 | R21: =R18+R19+R20 -> -239.47 | S21: =S18+S19+S20 -> 924.05 | T21: =T18+T19+T20 -> 93.43 | V21: Current tax | W21: 111.91 | X21: 194.59 | Y21: 421.92 | Z21: 298.3 | AA21: 393.84 | AC21: Current Tax in current year | AD21: 2782.89 | AE21: 2958.8 | AF21: 3760.62 | AG21: 4659.84 | AH21: 4457.24
A22: Deferred tax | B22: 38.19 | C22: 1062.5 | D22: 976.57 | E22: -2499.77 | F22: -51.28 | H22: Deferred tax | I22: -21.28 | J22: -71.4 | K22: 12.06 | L22: 17.17 | M22: 195.9 | O22: Profit/Loss before exceptional items, tax and share of net profit of associates and Joint ventures | P22: =P17+P21 -> 1189.45 | Q22: =Q17+Q21 -> 1222.63 | R22: =R17+R21 -> 1210.44 | S22: =S17+S21 -> 2257.54 | T22: =T17+T21 -> 4281.09 | V22: Deferred tax | W22: -183.05 | X22: 31.67 | Y22: -83.29 | Z22: 178.31 | AA22: -104.24 | AC22: Earlier years | AD22: 2743.64 | AE22: -1867.74 | AF22: -2.69 | AG22: 196.27 | AH22: -161.14
A23: Total Tax expense | B23: =SUM(B20:B22) -> 55.54 | C23: =SUM(C20:C22) -> 1083.87 | D23: =SUM(D20:D22) -> 1744.8 | E23: =SUM(E20:E22) -> -3267.37 | F23: =SUM(F20:F22) -> -37.28 | H23: Income tax for previous years | I23: -0.24 | J23: 0.03 | K23: 8.54 | L23: 0.53 | M23: 0 | O23: Share of net profit of associates and Joint ventures accounted for using the equity method | P23: 952.55 | Q23: 873.39 | R23: 1942.83 | S23: 3199.46 | T23: 1177.57 | V23: Deferred tax adjustable in future tariff | W23: 104.18 | X23: 49.65 | Y23: 156.16 | Z23: -13.89 | AA23: 152.66 | AC23: Deferred tax | AD23: 3821.01 | AE23: 1329.47 | AF23: 1289.17 | AG23: 1940.01 | AH23: 2513.1
A24: Deferred tax recoverable from future tariff (net) | B24: -45.69 | C24: 65.11 | D24: 79.25 | E24: -215.43 | F24: 0 | H24: Total tax expenses | I24: =SUM(I21:I23) -> 23.66 | J24: =SUM(J21:J23) -> -14.91 | K24: =SUM(K21:K23) -> 43.73 | L24: =SUM(L21:L23) -> 63.91 | M24: =SUM(M21:M23) -> 214.03 | O24: Profit/Loss before exceptional items and tax | P24: =P22+P23 -> 2142 | Q24: =Q22+Q23 -> 2096.02 | R24: =R22+R23 -> 3153.27 | S24: =S22+S23 -> 5457 | T24: =T22+T23 -> 5458.66 | V24: Profit for the year | W24: =W19-W21-W22-W23 -> 1081.18 | X24: =X19-X21-X22-X23 -> 822.68 | Y24: =Y19-Y21-Y22-Y23 -> 1743.48 | Z24: =Z19-Z21-Z22-Z23 -> 1480.12 | AA24: =AA19-AA21-AA22-AA23 -> 1725.65 | AC24: Total tax expenses | AD24: =SUM(AD21:AD23) -> 9347.54 | AE24: =SUM(AE21:AE23) -> 2420.53 | AF24: =SUM(AF21:AF23) -> 5047.1 | AG24: =SUM(AG21:AG23) -> 6796.12 | AH24: =SUM(AH21:AH23) -> 6809.2
A25: Loss/Profit for the year | B25: =B18-B23-B24 -> -2274.77 | C25: =C18-C23+C24 -> 1269.98 | D25: =D18-D23+D24 -> 4911.58 | E25: =E18-E23+E24 -> 10726.64 | F25: =F18-F23+F24 -> 20828.79 | H25: Profit/Loss from continuing operations | I25: =I19-I24 -> -4255.37 | J25: =J19-J24 -> 427.08 | K25: =K19-K24 -> -565.13 | L25: =L19-L24 -> -361.36 | M25: =M19-M24 -> -2242.18 | O25: Add/Less: Exceptional Items: | AC25: Profit before regulatory deferral a/c balances | AD25: =AD19-AD24 -> 7029.9 | AE25: =AE19-AE24 -> 13066.21 | AF25: =AF19-AF24 -> 15473.81 | AG25: =AG19-AG24 -> 17534.47 | AH25: =AH19-AH24 -> 20332.25
A26: Other Comprehensive income/loss | H26: Discontinuing operations: | O26: Gain on dilution of interest in an associate | P26: 532.51 | Q26: 0 | R26: 0 | S26: 0 | T26: 234.68 | AC26: Net movement in regulatory deferral a/c balances (net of tax) | AD26: 4879.01 | AE26: 1903.19 | AF26: 1486.48 | AG26: -413.12 | AH26: 1000
A27: Items that will not be reclassified to profit/loss | H27: Profit/Loss before tax from discontinued operations | I27: -16.11 | J27: 26.86 | K27: 8.6 | L27: -41.53 | M27: 173.8 | O27: Impairement of Goodwill on acquisition | P27: -276.35 | Q27: -109.29 | R27: -150.27 | S27: 0 | T27: -100.85 | AC27: Profit for the year | AD27: =AD25+AD26 -> 11908.91 | AE27: =AE25+AE26 -> 14969.4 | AF27: =AF25+AF26 -> 16960.29 | AG27: =AG25+AG26 -> 17121.35 | AH27: =AH25+AH26 -> 21332.25
A28: Remeasurement gain/loss of defined benefit plans | B28: 1.26 | C28: -6.13 | D28: -10.73 | E28: -5.9 | F28: 9.29 | H28: Tax expense of discontinued operations | I28: 0 | J28: 0 | K28: 0 | L28: 0 | M28: 0 | O28: Profit on sale of subsidiaries and Join ventures | P28: =-265+235 -> -30 | Q28: 0 | R28: 0 | S28: 0 | T28: 139.53
A29: Gain on sale of investment | B29: 0 | C29: 0.49 | D29: 0.78 | E29: 0 | F29: -2.33 | H29: Profit/Loss from discontinuing operations | I29: =I27+I28 -> -16.11 | J29: =J27+J28 -> 26.86 | K29: =K27+K28 -> 8.6 | L29: =L27+L28 -> -41.53 | M29: =M27+M28 -> 173.8 | O29: Profit/Loss before tax for the year | P29: =P24+P26+P27+P28 -> 2368.16 | Q29: =Q24+Q26+Q27+Q28 -> 1986.73 | R29: =R24+R26+R27+R28 -> 3003 | S29: =S24+S26+S27+S28 -> 5457 | T29: =T24+T26+T27+T28 -> 5732.02
A30: Income tax impact | B30: -0.14 | C30: 3.76 | D30: 26.94 | E30: 0 | F30: 0 | H30: Profit/Loss for the year before non controlling interest | I30: =I25+I29 -> -4271.48 | J30: =J25+J29 -> 453.94 | K30: =K25+K29 -> -556.53 | L30: =L25+L29 -> -402.89 | M30: =M25+M29 -> -2068.38 | O30: Tax expense
A31: Other comprehensive gain/loss that will not be reclassified to profit or loss | B31: =SUM(B28:B30) -> 1.12 | C31: =SUM(C28:C30) -> -1.88 | D31: =SUM(D28:D30) -> 16.99 | E31: =SUM(E28:E30) -> -5.9 | F31: =SUM(F28:F30) -> 6.96 | H31: Non-Controlling interest | I31: -194.89 | J31: 225.31 | K31: 49.38 | L31: 67.88 | M31: 0 | O31: Current Tax | P31: 494.3 | Q31: 647.57 | R31: 580.3 | S31: 804.33 | T31: 871.47
A32: Items that will be reclassified to profit or loss | H32: Profit/Loss for the year | I32: =I30-I31 -> -4076.59 | J32: =J30-J31 -> 228.63 | K32: =K30-K31 -> -605.91 | L32: =L30-L31 -> -470.77 | M32: =M30-M31 -> -2068.38 | O32: Current tax in respect of earlier years | P32: 330.95 | Q32: 0 | R32: -105.11 | S32: -52.37 | T32: -62.68
A33: Net gain on effective portion of cash flow hedges | B33: 9.2 | C33: -28.52 | D33: 26.64 | E33: 39.64 | F33: -46.04 | H33: Other comprehensive income | O33: Deferred tax | P33: -24.51 | Q33: -145.69 | R33: 133.31 | S33: 1010.3 | T33: 725.85
A34: Income tax impact | B34: 0 | C34: 0 | F34: 11.59 | H34: Items that will be reclassified to profit or loss | O34: Deferred tax relating to earlier years | P34: -159.25 | Q34: 0 | R34: =-588.56+359.62 -> -228.94 | S34: -114.93 | T34: -82.72
A35: Other comprehensive gain/loss that will not be reclassified to profit or loss | B35: =B33+B34 -> 9.2 | C35: =C33+C34 -> -28.52 | D35: =D33+D34 -> 26.64 | E35: =E33+E34 -> 39.64 | F35: =F33+F34 -> -34.45 | H35: Remeasurements of post employment benefit obligation | I35: -2.81 | J35: 4.44 | K35: -0.99 | L35: -16.14 | M35: -1 | O35: Total Tax expense | P35: =P31+P33+P32+P34 -> 641.49 | Q35: =Q31+Q33+Q32+Q34 -> 501.88 | R35: =R31+R33+R32+R34 -> 379.56 | S35: =S31+S33+S32+S34 -> 1647.33 | T35: =T31+T33+T32+T34 -> 1451.92
A36: Other comprehensive gain/loss for the year, net of tax | B36: =B31+B35 -> 10.32 | C36: =C31+C35 -> -30.4 | D36: =D31+D35 -> 43.63 | E36: =E31+E35 -> 33.74 | F36: =F31+F35 -> -27.49 | H36: Currency translation gains/loss | I36: 29.13 | J36: -3.34 | K36: 1.97 | L36: -19.79 | M36: 4.16 | O36: Profit/Loss for the year from continuing operations | P36: =P29-P35 -> 1726.67 | Q36: =Q29-Q35 -> 1484.85 | R36: =R29-R35 -> 2623.44 | S36: =S29-S35 -> 3809.67 | T36: =T29-T35 -> 4280.1
A37: Total Comprehensive Profit/Loss for the year | B37: =B25+B36 -> -2264.45 | C37: =C25+C36 -> 1239.58 | D37: =D25+D36 -> 4955.21 | E37: =E25+E36 -> 10760.38 | F37: =F25+F36 -> 20801.3 | H37: Other comprehensive income/loss for the year | I37: =I35+I36 -> 26.32 | J37: =J35+J36 -> 1.1 | K37: =K35+K36 -> 0.98 | L37: =L35+L36 -> -35.93 | M37: =M35+M36 -> 3.16 | O37: Profit/Loss before tax from discontinued operations | P37: -81.64 | Q37: -59.85 | R37: 0 | S37: 0
H38: Total comprehensive income/loss for the year | I38: =I32+I37 -> -4050.27 | J38: =J32+J37 -> 229.73 | K38: =K32+K37 -> -604.93 | L38: =L32+L37 -> -506.7 | M38: =M32+M37 -> -2065.22 | O38: Impairement loss related to discontinued operations on remeasurement to fair value | P38: -361 | Q38: -160 | R38: -467.83 | S38: 0 | T38: 0
O39: Tax expense/Credit of discontinued operations
O40: Current tax | P40: 0 | Q40: -101.48 | R40: 0 | S40: 0 | T40: 0
...

Sheet Cash Flow Statement
A1: CASH FLOW STATEMENT (ADANI POWER) | F1: #VALUE! | H1: CASH FLOW STATEMENT (Reliance Power) | M1: #VALUE! | O1: CASH FLOW STATEMENT (TATA Power) | T1: #VALUE! | V1: CASH FLOW STATEMENT (JSW Energy) | AA1: #VALUE! | AC1: CASH FLOW STATEMENT (NTPC) | AH1: #VALUE!
A2: Particulars | B2: Mar 20 | C2: Mar 21 | D2: Mar 22 | E2: Mar 23 | F2: Mar 24 | H2: Particulars | I2: Mar 20 | J2: Mar 21 | K2: Mar 22 | L2: Mar 23 | M2: Mar 24 | O2: Particulars | P2: Mar 20 | Q2: Mar 21 | R2: Mar 22 | S2: Mar 23 | T2: Mar 24 | V2: Particulars | W2: Mar 20 | X2: Mar 21 | Y2: Mar 22 | Z2: Mar 23 | AA2: Mar 24 | AC2: Particulars | AD2: Mar 20 | AE2: Mar 21 | AF2: Mar 22 | AG2: Mar 23 | AH2: Mar 24
A3: Cash flow from operating activities | H3: Cash flow from operating activities | O3: Cash flow Operating activities | V3: CASH FLOW FROM OPERATING ACTIVTIES | AC3: CASH FLOW FROM OPERATING ACTIVITIES
A4: Profit/Loss before tax | B4: -2264.92 | C4: 2288.74 | D4: 6577.13 | E4: 7674.7 | F4: 20791.51 | H4: Profit/Loss before tax | I4: -4231.54 | J4: 412.17 | K4: -879.49 | L4: -297.45 | M4: -2028.15 | O4: Profit/Loss before tax for the year | P4: =2368.16-442.64 -> 1925.52 | Q4: =1986.73-219.85 -> 1766.88 | R4: =3003-467.83 -> 2535.17 | S4: 5457 | T4: 5732.02 | V4: Profit before tax and deferred tax adjustable in future tariff | W4: 1114.22 | X4: 1098.59 | Y4: 2238.27 | Z4: 1942.84 | AA4: 2166.91 | AC4: Profit before tax and regulatory deferral ac balances | AD4: 16377.51 | AE4: 16998.93 | AF4: 20520.91 | AG4: 24330.59 | AH4: 27141.45
A5: Adjustments to reconcile profit before tax to net cash flows: | H5: Adjusted for: | O5: Adjustments: | V5: Adjusted for: | AC5: Add: Net movements in regulatory deferral a/c balances | AD5: 4872.01 | AE5: 1903.19 | AF5: 1486.48 | AG5: -413.12 | AH5: 1000.2
A6: Depreciation and ammortization expenses | B6: 3006.5 | C6: 3201.65 | D6: 3117.54 | E6: 3303.68 | F6: 3931.33 | H6: Gain arising on mutual fund investment | I6: -4.94 | J6: -1.08 | K6: -1.03 | L6: -1.79 | M6: -2.46 | O6: Depreciation and ammortization | P6: 2633.56 | Q6: 2744.94 | R6: 3122.2 | S6: 3439.2 | T6: 3786.37 | V6: Depreciation and ammortization | W6: 1168.05 | X6: 1166.94 | Y6: 1131.05 | Z6: 1169.23 | AA6: 1633.41 | AC6: Add: Tax on net movements in regulatory deferral a/c balances | AD6: 1032.07 | AE6: 387.5 | AF6: 303.99 | AG6: -92.68 | AH6: 214.19
A7: Unrealized foreign exchange fluctuation Gain/Loss (net) | B7: 84.1 | C7: -336.75 | D7: 61.55 | E7: 101.61 | F7: -2.49 | H7: Depreciation/Ammortization | I7: 984.06 | J7: 1293.07 | K7: 1275.05 | L7: 1243.79 | M7: 1256.75 | O7: Transfer to contingency reserve | P7: 17 | Q7: 11 | R7: 12.57 | S7: 13.68 | T7: 15.8 | V7: Finance cost | W7: 1051.07 | X7: 895.65 | Y7: 776.91 | Z7: 844.3 | AA7: 2053.4 | AC7: Profit before tax including movement in regulatory deferral a/c balances | AD7: =AD4+AD5+AD6 -> 22281.59 | AE7: =AE4+AE5+AE6 -> 19289.62 | AF7: =AF4+AF5+AF6 -> 22311.38 | AG7: =AG4+AG5+AG6 -> 23824.79 | AH7: =AH4+AH5+AH6 -> 28355.84
A8: Income from mutual funds | B8: -4.09 | C8: -0.02 | D8: -0.83 | E8: -13.1 | F8: -42.92 | H8: Finance cost including gain/loss on derivative | I8: 3053.97 | J8: 2538.59 | K8: 2707.17 | L8: 2526.61 | M8: 2451.29 | O8: Gain on dilution of interest in an associate | P8: -235 | Q8: -67.76 | R8: 467.83 | S8: 0 | T8: -234.68 | V8: Interest income earned on financial assets that are not designated | W8: -184.12 | X8: -105.56 | Y8: -351.22 | Z8: -144.98 | AA8: -223.12 | AC8: Adjustments:
A9: Loss on sale/retirement/provided for/write off of property, plant and equipment | B9: 48.34 | C9: 19.64 | D9: 67.25 | E9: 85.65 | F9: 78.35 | H9: Fair value of investment measured at FVTPL | I9: 3.98 | J9: 0 | K9: 0 | M9: -167.7 | O9: Finance cost | P9: 361 | Q9: 160 | R9: 41.09 | S9: 29.97 | T9: 0 | V9: Dividend income from investments designated as fair value | W9: -1.71 | X9: 0 | Y9: -45.52 | Z9: -121.52 | AA9: -23.81 | AC9: Depreciation, ammortization and impaired expense | AD9: 10356.16 | AE9: 12450.31 | AF9: 13787.83 | AG9: 14792.27 | AH9: 16203.63
A10: Ammortized government grant income | B10: -304.06 | C10: -304.06 | D10: -304.06 | E10: -304.06 | F10: -391.67 | H10: Interest income | I10: -92.29 | J10: -46.46 | K10: -53.36 | L10: -57.65 | M10: -53.81 | O10: Impairement of goodwill on acquisition | P10: 24.99 | Q10: -5.6 | R10: 3859.02 | S10: 4371.65 | T10: 4633.22 | V10: Share of profit of a joint venture | W10: -28.72 | X10: -14.01 | Y10: -8.54 | Z10: -19.29 | AA10: -16.51 | AC10: Provisions | AD10: 421.12 | AE10: 907.54 | AF10: 407.63 | AG10: 753.86 | AH10: 864.55
A11: Liabilitiy no longer required written back | B11: -42.44 | C11: -307.81 | D11: -21.82 | E11: -41.37 | F11: -92.2 | H11: Gain on foreign exchange fluctuations (net) | I11: 0 | J11: -289.54 | K11: 41.24 | L11: -8.81 | M11: -1.03 | O11: Profit on sale of subsidiaries and joint ventures | P11: 4529.88 | Q11: 4035.3 | R11: -292.51 | S11: -513.65 | T11: 100.85 | V11: Net gain arising on financial instruments designated | W11: -28.04 | X11: -17.15 | Y11: -4.99 | Z11: -1.72 | AA11: -0.71 | AC11: Share of net profit of joint ventures accounted for using equity method | AD11: -405.4 | AE11: =-683.87+15.88 -> -667.99 | AF11: -1020.13 | AG11: -779.77 | AH11: -1635.6
A12: Gain on sale of investment in subsidiaries | B12: 0 | C12: 0 | D12: 0 | E12: -694.45 | F12: -232.9 | H12: Liabilities written back | I12: 21.82 | J12: 68.95 | K12: -6.56 | L12: -1049.12 | M12: -1903.95 | O12: Gain/Loss on disposal of PPE (net) | P12: -135.55 | Q12: -175.65 | R12: 0 | S12: -3 | T12: -139.53 | V12: Writeback of liabilities no longer required | W12: -0.6 | X12: 1.27 | Y12: -43.52 | Z12: -41.59 | AA12: -43.1 | AC12: On account of govt grants | AD12: -91.54 | AE12: 477.38 | AF12: -109.5 | AG12: 668.76 | AH12: 214.33
A13: Finance cost | B13: 5314.82 | C13: 5106.33 | D13: 4094.78 | E13: 3333.5 | F13: 3388.09 | H13: Govt grant | I13: -53.07 | J13: -53.07 | K13: -53.07 | L13: -53.07 | M13: -53.07 | O13: Employee stock option expenses | P13: -85.87 | Q13: -6.78 | R13: -6.79 | S13: -524.14 | T13: -5.36 | V13: Share based payments | W13: -0.17 | X13: -31.08 | Y13: 15.38 | Z13: 24.73 | AA13: 24.55 | AC13: Deferred foreign currency fluctuation asset | AD13: -1072.34 | AE13: 527.46 | AF13: 416.75 | AG13: -84.69 | AH13: 78.84
A14: Interest income | B14: -959.63 | C14: -1045.45 | D14: -3558.27 | E14: -3607.19 | F14: -8921.11 | H14: Loss on sale of PPE | I14: -40.45 | J14: -35.89 | K14: 0.15 | L14: 21.22 | M14: 2.58 | O14: Interest income | P14: -53.39 | Q14: 25.82 | R14: -19.31 | S14: -92.22 | T14: 8.27 | V14: Gain/loss on disposal of PPE (net) | W14: 4.12 | X14: 1.92 | Y14: 2.63 | Z14: 0.15 | AA14: -0.05 | AC14: Deferred income from foreign currency fluctuation | AD14: =1340.04+0.03 -> 1340.07 | AE14: -412.13 | AF14: 224.94 | AG14: 948.27 | AH14: 14.72
A15: Stores and spares provided for | B15: 0 | C15: 0 | D15: 79.33 | E15: 12.13 | F15: -0.4 | H15: Provisions made during the year/impairement/amouts written off | I15: 4004.21 | J15: -0.1 | K15: 569.71 | L15: 824.75 | M15: 3620.36 | O15: Discount amortised/accrued on bonds (net) | P15: -532.51 | Q15: 0 | R15: 127.62 | S15: 383.81 | T15: -616.69 | V15: Allowance for slow moving inventory | W15: -2.85 | X15: 5.01 | Y15: 0 | Z15: 0.79 | AA15: 0 | AC15: Regulatory deferral account balances | AD15: -5904.08 | AE15: -2290.69 | AF15: -1790.47 | AG15: 505.8 | AH15: -1214.39
A16: Bad debts and sundry balance written off | B16: 216.84 | C16: 0 | D16: 0.42 | E16: 8.68 | F16: 7.53 | H16: Loss on revaluation of inventories | I16: 325.83 | J16: 16.25 | K16: 0 | L16: 5.63 | M16: 2.48 | O16: Dividend income | P16: 20.71 | Q16: 24.37 | R16: 11.94 | S16: 51.54 | T16: 0.02 | V16: Impairement loss on loans/trade receivables | W16: 0.29 | X16: 0.97 | Y16: 0.83 | Z16: 8.83 | AA16: 36.64 | AC16: Fly ash utilization reserve fund | AD16: -38.39 | AE16: 19.88 | AF16: -19.71 | AG16: 143.38 | AH16: 175.82
A17: Advances to suppliers/unrealized balances provided for | B17: 1002.99 | C17: 43.05 | D17: 39.44 | E17: 0 | F17: 164.53 | H17: Provision for leave encashment and gratuity | I17: 8.01 | J17: 5.91 | K17: 7.27 | L17: 13.67 | M17: 12.65 | O17: Gain on sale of current investment measured at fair value | P17: 0 | Q17: 69.87 | R17: 10.67 | S17: 26.07 | T17: -764.05 | V17: Unrealized foreign exchange loss (net) | W17: 0.41 | X17: =0.84-1.88 -> -1.04 | Y17: 0.22 | Z17: 13.38 | AA17: 3.22 | AC17: Finance cost | AD17: 8060.61 | AE17: 9162.74 | AF17: 9238.86 | AG17: 11092.08 | AH17: 11954.79
A18: Operating profit before working capital changes | B18: =SUM(B4,B6:B17) -> 6098.45 | C18: =SUM(C4,C6:C17) -> 8665.32 | D18: =SUM(D4,D6:D17) -> 10152.46 | E18: =SUM(E4,E6:E17) -> 9859.78 | F18: =SUM(F4,F6:F17) -> 18677.65 | H18: Operating profit before working capital changes | I18: =SUM(I4:I17) -> 3979.59 | J18: =SUM(J4:J17) -> 3908.8 | K18: =SUM(K4:K17) -> 3607.08 | L18: =SUM(L4:L17) -> 3167.78 | M18: =SUM(M4:M17) -> 3135.94 | O18: Allowances for doubtful debts and advances (net) | P18: 10.45 | Q18: 26.5 | R18: 150.27 | S18: 0 | T18: -80 | V18: Allowance for impairement of advances | W18: =-11.29+10.04+2.18 -> 0.93 | X18: =3.85+10.33+0.94 -> 15.12 | Y18: =70.27+10 -> 80.27 | Z18: =10 -> 10 | AA18: 0 | AC18: Unwinding of discount on vendor liabilities | AD18: 56.24 | AE18: 61.4 | AF18: 77.12 | AG18: 63.98 | AH18: 93.42
A19: Changes in working capital: | H19: Change in operating assets and liabilities | O19: Bad debts | P19: 0 | Q19: 109.29 | R19: -68.31 | S19: -94.77 | T19: 489.61 | V19: Exceptional items | W19: =0.53-177.48+116.02 -> -60.93 | X19: 0 | Y19: 36.56 | Z19: -120 | AA19: 0 | AC19: Interest income/late payment surcharge/income on investments | AD19: -1986.27 | AE19: -3390.34 | AF19: -1292.3 | AG19: -918.04 | AH19: -961.91
A20: Increase in inventories | B20: -1233.29 | C20: 385.47 | D20: -262.29 | E20: -829.06 | F20: -1066.5 | H20: Increase in inventories | I20: -2.46 | J20: 137.44 | K20: 46.08 | L20: -102.91 | M20: -38.32 | O20: Provision for warranties | P20: -49.46 | Q20: -66.27 | R20: -317.7 | S20: -356.67 | T20: 7.49 | AC20: Dividend income | AD20: -4.8 | AE20: -9 | AF20: -9 | AG20: -6.96 | AH20: -9.36
A21: Increase in trade receivables | B21: 1252.45 | C21: 188.86 | D21: 980.98 | E21: -2995.25 | F21: -1738.44 | H21: Increase/decrease in trade receivables | I21: -175.61 | J21: -61.67 | K21: -1052.64 | L21: 533.6 | M21: -41.02 | O21: Interest on overdue TR | P21: -3.15 | Q21: 0 | R21: -9.61 | S21: -11.15 | T21: 37.76 | V21: Operating profit before working capital changes | W21: =SUM(W4,W6:W19) -> 3031.95 | X21: =SUM(X4,X6:X20) -> 3016.63 | Y21: =SUM(Y4,Y6:Y20) -> 3828.33 | Z21: =SUM(Z4,Z6:Z20) -> 3565.15 | AA21: =SUM(AA4,AA6:AA20) -> 5610.83 | AC21: Provisions writtenback | AD21: -484.06 | AE21: -64.19 | AF21: -378.01 | AG21: -368.3 | AH21: -560.73
A22: Increase in other financial assets | B22: 0 | C22: -64.99 | D22: -215.37 | E22: -51.2 | F22: -122.33 | H22: Decrease in other financial assets | I22: 382.37 | J22: 479.24 | K22: 73.21 | L22: 346.05 | M22: 186.49 | O22: Ammortization of service line contributions and govt grant | P22: -89.18 | Q22: -152.19 | R22: -1942.83 | S22: -3199.46 | T22: -195.7 | V22: Adjustments for working capital changes | AC22: Profit on de recognition of PPE | AD22: -12.59 | AE22: -3.36 | AF22: -6.27 | AG22: -31.8 | AH22: -30.37
A23: Decrease/increase in other assets | B23: 818.47 | C23: -126.97 | D23: -358.75 | E23: -233.11 | F23: 1.43 | H23: Increase in other current assets | I23: 255.1 | J23: -161.36 | K23: 125.08 | L23: -16.39 | M23: -115.34 | O23: Guarantee commission from joint ventures | P23: -9.4 | Q23: -8.26 | R23: 55.41 | S23: 53.59 | T23: -385.56 | V23: Decrease/increase in trade receivables and unbilled revenue | W23: -676.92 | X23: 803.62 | Y23: -6.65 | Z23: -501.63 | AA23: 639.4 | AC23: Loss on de recognition of PPE | AD23: 64.19 | AE23: 137.27 | AF23: 108.06 | AG23: 168.55 | AH23: 220.67
A24: Increase/decrease in trade payables | B24: -1104.86 | C24: -1488.52 | D24: -368.06 | E24: -423.16 | F24: 615.62 | H24: Increase in other current liabilities | I24: 113.01 | J24: 153.43 | K24: 24.49 | L24: 108.71 | M24: 41.48 | O24: Share of net profit of associates and JV accounted for equity method | P24: -952.55 | Q24: -873.39 | R24: 1.44 | S24: 2.06 | T24: -12.12 | V24: Decrease/increase in inventories | W24: -185.14 | X24: 243.53 | Y24: -505.94 | Z24: -59.94 | AA24: 148.76 | AC24: Special rebate to beneficiaries - exceptional items | AD24: 0 | AE24: -1512.19 | AF24: 0 | AG24: 0
A25: Decrease/increase in Other financial liabilities | B25: 0 | C25: -479.32 | D25: 140.95 | E25: 414.57 | F25: -601.34 | H25: Decrease/increase in trade payables | I25: 15.77 | J25: -27.75 | K25: 74.47 | L25: 28.72 | M25: -57.93 | O25: Ammortization of deferred revenue | P25: 38.69 | Q25: 48.23 | R25: -199.64 | S25: 0 | T25: -1177.57 | V25: Decrease/increase in current and non current assets | W25: -72.77 | X25: 91.27 | Y25: -45.73 | Z25: -163.54 | AA25: 107.39 | AC25: Operating profit before working capital changes | AD25: =SUM(AD9:AD24) -> 10298.92 | AE25: =SUM(AE9:AE24) -> 15394.09 | AF25: =SUM(AF9:AF24) -> 19635.8 | AG25: =SUM(AG9:AG24) -> 26947.39 | AH25: =SUM(AH9:AH23) -> 25408.41
A26: Decrease/increase in other liabilities and provisions | B26: -175.85 | C26: -59.95 | D26: 387.15 | E26: 2766.61 | F26: -1538.52 | H26: Increase in other financial liabilities | I26: 94.07 | J26: -266.75 | K26: 850.73 | L26: 16.13 | M26: 77.82 | O26: Ammortization of deferred rent | P26: 0 | Q26: 1.12 | R26: 0 | S26: 18.52 | T26: 37.98 | V26: Increase/decrease in trade payables and other liabilities | W26: 163.53 | X26: -272.09 | Y26: 120.78 | Z26: -408.47 | AA26: 112.96 | AC26: Adjustments for;
A27: Cash flow from operating activities | B27: =SUM(B20:B26) -> -443.08 | C27: =SUM(C20:C26) -> -1645.42 | D27: =SUM(D20:D26) -> 304.61 | E27: =SUM(E20:E26) -> -1350.6 | F27: =SUM(F20:F26) -> -4450.08 | I27: =SUM(I20:I26) -> 682.25 | J27: =SUM(J20:J26) -> 252.58 | K27: =SUM(K20:K26) -> 141.42 | L27: =SUM(L20:L26) -> 913.91 | M27: =SUM(M20:M26) -> 53.18 | O27: Provision for future forseeable losses | P27: 0 | Q27: 0 | R27: 0 | S27: 0 | T27: 0.37 | AC27: Trade receivables | AD27: -7086.6 | AE27: 1805.87 | AF27: 199.73 | AG27: -3256.07 | AH27: -1296.73
A28: Less: Income tax paid/ tax deducted at sources (net of refund) | B28: -57.82 | C28: -5.55 | D28: -224.34 | E28: -78.65 | F28: -57.42 | H28: Taxes paid/refund (net) | I28: -118.9 | J28: -40.27 | K28: -49.07 | L28: -57.93 | M28: -34.04 | O28: Net foreign exchange differences | P28: -105.59 | Q28: -16.75 | R28: 37.56 | S28: -36.46 | T28: =1.42+18.18 -> 19.6 | V28: Cash flow from operations | W28: =SUM(W21,W23:W27) -> 2260.65 | X28: =SUM(X21,X23:X27) -> 3882.96 | Y28: =SUM(Y21,Y23:Y27) -> 3390.79 | Z28: =SUM(Z21,Z23:Z27) -> 2431.57 | AA28: =SUM(AA21,AA23:AA27) -> 6619.34 | AC28: Inventories | AD28: -2309.68 | AE28: 2032.27 | AF28: 538.68 | AG28: -3004.98 | AH28: -2586.73
A29: Net cash flows from Operating activities | B29: =B18+B27+B28 -> 5597.55 | C29: =C18+C27+C28 -> 7014.35 | D29: =D18+D27+D28 -> 10232.73 | E29: =E18+E27+E28 -> 8430.53 | F29: =F18+F27+F28 -> 14170.15 | H29: Net cash generated from operating activities-continuing operations | I29: =I27+I28+I18 -> 4542.94 | J29: =J27+J28+J18 -> 4121.11 | K29: =K27+K28+K18 -> 3699.43 | L29: =L27+L28+L18 -> 4023.76 | M29: =M27+M28+M18 -> 3155.08 | O29: Adjustments for increase/decrease in operating assets: | V29: Income tax paid | W29: -175.11 | X29: -183.1 | Y29: -438.76 | Z29: -347.3 | AA29: -385.71 | AC29: Trade payables, provisions, other financial liabilties and other liabilities | AD29: 1524.12 | AE29: -24.25 | AF29: 3697.41 | AG29: 3461.28 | AH29: -588.35
A30: Cash flow from investing activities | H30: Net cash generated from operating activities-discontinuing operations | I30: -0.12 | J30: 27.51 | K30: -86.33 | L30: 0.02 | M30: 18.77 | O30: Inventories | P30: -21.32 | Q30: -93.26 | R30: -2308.21 | S30: 309.91 | T30: -444.66 | V30: NET CASH GENERATED/USED IN OPERATING ACTIVITIES | W30: =W28+W29 -> 2085.54 | X30: =X28+X29 -> 3699.86 | Y30: =Y28+Y29 -> 2952.03 | Z30: =Z28+Z29 -> 2084.27 | AA30: =AA28+AA29 -> 6233.63 | AC30: Loans, othe financial assets and other assets | AD30: 2502.01 | AE30: -2985.25 | AF30: -2521.72 | AG30: -3845.21 | AH30: -4864.99
A31: Capital expenditure on payment towards PPE, including capital advances and capital WIP, and intangible assets | B31: -2226.56 | C31: -3617.61 | D31: -3434.55 | E31: -3243.68 | F31: -2602.45 | H31: Net cash generated from operating activities- continuing and discontinuing operations | I31: =I29+I30 -> 4542.82 | J31: =J29+J30 -> 4148.62 | K31: =K29+K30 -> 3613.1 | L31: =L29-L30 -> 4023.74 | M31: =M29+M30 -> 3173.85 | O31: Trade receivables | P31: -96.56 | Q31: -1103.76 | R31: -887.56 | S31: -1070.43 | T31: -859.28 | V31: CASH FLOW FROM INVESTING ACTIVITIES
A32: Proceeds from sale of PPE | B32: 6.72 | C32: 9.96 | D32: 1.24 | E32: 0.83 | F32: 0.56 | H32: Cash flow from investing activities | O32: Unbilled revenue | P32: 54.23 | Q32: -885.35 | R32: -694.43 | S32: -171.14 | T32: -95.52 | V32: Purchase of PPE | W32: -121.5 | X32: -435.44 | Y32: -2294.07 | Z32: -4236.31 | AA32: -8032.77 | AC32: Cash Generated from operations | AD32: =AD7+AD25+SUM(AD27:AD30) -> 27210.36 | AE32: =AE7+AE25+SUM(AE27:AE30) -> 35512.35 | AF32: =AF7+AF25+SUM(AF27:AF30) -> 43861.28 | AG32: =AG7+AG25+SUM(AG27:AG30) -> 44127.2 | AH32: =AH7+AH25+SUM(AH27:AH30) -> 44427.45
