Workbook

Sheet Company Profile
A1: COMPANY PROFILE
A3: Logo | B3: #VALUE! | C3: #VALUE! | D3: #VALUE! | E3: #VALUE! | F3: #VALUE! | G3: #VALUE!
A5: Trading Name | B5: #VALUE! | C5: #VALUE! | D5: #VALUE! | E5: #VALUE! | F5: #VALUE! | G5: #VALUE!
A6: Official Name | B6: {=_FV(B5,"Name")} -> BHARAT PETROLEUM CORPORATION LIMITED | C6: {=_FV(C5,"Name")} -> GAIL (INDIA) LIMITED | D6: {=_FV(D5,"Name")} -> HINDUSTAN PETROLEUM CORPORATION LIMITED | E6: {=_FV(E5,"Name")} -> INDIAN OIL CORPORATION LIMITED | F6: {=_FV(F5,"Name")} -> OIL AND NATURAL GAS CORPORATION LIMITED | G6: {=_FV(G5,"Name")} -> RELIANCE INDUSTRIES LIMITED
A7: Share Price | B7: {=_FV(B5,"Price")} -> 365.15 | C7: {=_FV(C5,"Price")} -> 181.52 | D7: {=_FV(D5,"Price")} -> 481.7 | E7: {=_FV(E5,"Price")} -> 169 | F7: {=_FV(F5,"Price")} -> 251.4 | G7: {=_FV(G5,"Price")} -> 1489.25
A8: Outstanding Shares | B8: {=_FV(B5,"Shares outstanding",TRUE)} -> 4338505000 | C8: {=_FV(C5,"Shares outstanding",TRUE)} -> 6575080000 | D8: {=_FV(D5,"Shares outstanding",TRUE)} -> 2127823000 | E8: {=_FV(E5,"Shares outstanding",TRUE)} -> 14121240000 | F8: {=_FV(F5,"Shares outstanding",TRUE)} -> 12580280000 | G8: {=_FV(G5,"Shares outstanding",TRUE)} -> 13532740000
A9: In crores | B9: =B8/10000000 -> 433.8505 | C9: =C8/10000000 -> 657.508 | D9: =D8/10000000 -> 212.7823 | E9: =E8/10000000 -> 1412.124 | F9: =F8/10000000 -> 1258.028 | G9: =G8/10000000 -> 1353.274
A10: Market Cap | B10: {=_FV(B5,"Market cap",TRUE)} -> 1592882000000 | C10: {=_FV(C5,"Market cap",TRUE)} -> 1186605000000 | D10: {=_FV(D5,"Market cap",TRUE)} -> 1020397000000 | E10: {=_FV(E5,"Market cap",TRUE)} -> 2388749000000 | F10: {=_FV(F5,"Market cap",TRUE)} -> 3172747000000 | G10: {=_FV(G5,"Market cap",TRUE)} -> 20000990000000
A11: Change | B11: {=_FV(B5,"Change (%)",TRUE)} -> -0.005447 | C11: {=_FV(C5,"Change (%)",TRUE)} -> 0.005818 | D11: {=_FV(D5,"Change (%)",TRUE)} -> 0.004483 | E11: {=_FV(E5,"Change (%)",TRUE)} -> -0.0002958 | F11: {=_FV(F5,"Change (%)",TRUE)} -> -0.003172 | G11: {=_FV(G5,"Change (%)",TRUE)} -> 0.007441
A12: Beta | B12: {=_FV(B5,"Beta")} -> 1.2921 | C12: {=_FV(C5,"Beta")} -> 1.5484 | D12: {=_FV(D5,"Beta")} -> 1.5872 | E12: {=_FV(E5,"Beta")} -> 1.3211 | F12: {=_FV(F5,"Beta")} -> 0.9935 | G12: {=_FV(G5,"Beta")} -> 1.1399

Sheet Balance Sheet
A1: BALANCE SHEET
A3: #VALUE! | I3: #VALUE! | Q3: #VALUE! | Y3: #VALUE! | AG3: #VALUE! | AO3: #VALUE!
A4: Particulars | B4: 2020 | C4: 2021 | D4: 2022 | E4: 2023 | F4: 2024 | G4: 2025 | I4: Particulars | J4: 2020 | K4: 2021 | L4: 2022 | M4: 2023 | N4: 2024 | O4: 2025 | Q4: Particulars | R4: 2020 | S4: 2021 | T4: 2022 | U4: 2023 | V4: 2024 | W4: 2025 | Y4: Particulars | Z4: 2020 | AA4: 2021 | AB4: 2022 | AC4: 2023 | AD4: 2024 | AE4: 2025 | AG4: Particulars | AH4: 2020 | AI4: 2021 | AJ4: 2022 | AK4: 2023 | AL4: 2024 | AM4: 2025 | AO4: Particulars | AP4: 2020 | AQ4: 2021 | AR4: 2022 | AS4: 2023 | AT4: 2024 | AU4: 2025
A5: ASSETS | I5: ASSETS | Q5: ASSETS | Y5: ASSETS | AG5: ASSETS | AO5: ASSETS
A6: Non-current assets | I6: Non current assets | Q6: Non Current assets | Y6: Non current assets | AG6: Non current assets | AO6: Non current Assets
A7: Property, plant and equipment | B7: 56687.98 | C7: 63588.84 | D7: 81507.26 | E7: 84464.8 | F7: 84718.04 | G7: 86593.79 | I7: Property, plant and equipment | J7: 35896.6 | K7: 37952.8 | L7: 40410.09 | M7: 44651.29 | N7: 47956.66 | O7: 49352.91 | Q7: Property, plant and equipment | R7: 48391.57 | S7: 49950.58 | T7: 56982.17 | U7: 67305.13 | V7: 78371.79 | W7: 84767.38 | Y7: PPE | Z7: 144076.3 | AA7: 153698.39 | AB7: 157194.98 | AC7: 176532.05 | AD7: 192159.52 | AE7: 197162.03 | AG7: Property, plant and equipment | AO7: PPE | AP7: 297854 | AQ7: 292092 | AR7: 223824 | AS7: 232238 | AT7: 258911 | AU7: 267096
A8: Capital work-in-progress | B8: 9108.09 | C8: 7537.18 | D8: 4979.89 | E8: 5645.05 | F8: 8679.72 | G8: 13240.29 | I8: Capital work in progress | J8: 11666.31 | K8: 13399.66 | L8: 15490.4 | M8: 16646.5 | N8: 23626.78 | O8: 27421.06 | Q8: Capital work in progress | R8: 17047.34 | S8: 25128.63 | T8: 28645.09 | U8: 25310.74 | V8: 20048.26 | W8: 17935.16 | Y8: Capital work in progress | Z8: 29628.86 | AA8: 32953.16 | AB8: 44049.82 | AC8: 47550.08 | AD8: 57316.86 | AE8: 73740.41 | AG8: Oil and gas assets | AH8: 140044.14 | AI8: 139280.85 | AJ8: 143352.36 | AK8: 130983.63 | AL8: =144996.692+362.896 -> 145359.59 | AM8: =157405.428+329.216 -> 157734.64 | AO8: Intangible assets | AP8: 15638 | AQ8: 20765 | AR8: 15802 | AS8: 12926 | AT8: 40719 | AU8: 43951
A9: Investment Property | B9: 0.21 | C9: 0 | D9: 1203.98 | E9: 0.01 | F9: 0.09 | G9: 0.09 | I9: Intangible assets | J9: 1880.36 | K9: 2300.68 | L9: 2536.61 | M9: 2856.29 | N9: 3135.35 | O9: 3324.56 | Q9: Intangible assets | R9: =16.69+543.52 -> 560.21 | S9: =321.62+639.71 -> 961.33 | T9: =321.62+822.31 -> 1143.93 | U9: =304.92+777.41 -> 1082.33 | V9: =304.92+1085.85 -> 1390.77 | W9: =304.92+1106.9 -> 1411.82 | Y9: Goodwill | Z9: 1.04 | AA9: 1.04 | AB9: 1.04 | AC9: 1.04 | AD9: 1.04 | AE9: 1.04 | AG9: Other property plant and equipment | AH9: 74127.397 | AI9: 74125.818 | AJ9: 83026.264 | AK9: 92631.504 | AL9: 126992.77 | AM9: 134067.95 | AO9: Capital work in progress | AP9: 8624 | AQ9: 14741 | AR9: 19267 | AS9: 30958 | AT9: 44294 | AU9: 76322
A10: Goodwill | B10: 0 | C10: 0.05 | D10: 0.03 | E10: 1203.98 | F10: 1203.98 | G10: 1203.98 | I10: Right of use assetss | J10: 452.66 | K10: 906.86 | L10: 1625.36 | M10: 2189.29 | N10: 4096.49 | O10: 6158.04 | Q10: Intangible assets under development | R10: 122.42 | S10: 207.4 | T10: 262.15 | U10: 296.62 | V10: 29.54 | W10: 31.99 | Y10: Intangible assets | Z10: 2944.79 | AA10: 3385.36 | AB10: 3318.33 | AC10: 3514.48 | AD10: 3837.23 | AE10: 3979.1 | AG10: Right of use assets | AH10: 14711.763 | AI10: 15906.384 | AJ10: 15782.603 | AK10: 14189.416 | AL10: 34407.325 | AM10: 34181.47 | AO10: Intangible assets under development | AP10: 12327 | AQ10: 12070 | AR10: 15395 | AS10: 17957 | AT10: 17338 | AU10: 6095
A11: Intangible assets | B11: 262.93 | C11: 509.42 | D11: 1190.19 | E11: 1006.33 | F11: 876.14 | G11: 830.37 | I11: Investments accounted as per equiy method | J11: 7331.43 | K11: 9042.74 | L11: 10978.18 | M11: 12163.97 | N11: 13120.76 | O11: 14638.56 | Q11: Investment in subsidiaries, Joint ventures and Associates | R11: 8820.82 | S11: 9333.88 | T11: 12840.27 | U11: 17809.73 | V11: 22654.1 | W11: 22136.45 | Y11: Intangible assets under development | Z11: 3215.98 | AA11: 3337.38 | AB11: 3419.45 | AC11: 3583.39 | AD11: 3715.56 | AE11: 4180.87 | AG11: Capital work in progress | AO11: Investments | AP11: 421793 | AQ11: 252620 | AR11: 330493 | AS11: 303558 | AT11: 301400 | AU11: 333258
A12: Intangible assets under development | B12: 396.62 | C12: 9500.11 | D12: 10453.06 | E12: 10603.88 | F12: 11524.24 | G12: 13146.5 | I12: Other investments | J12: 2561.52 | K12: 3546.52 | L12: 5429.97 | M12: 5084.35 | N12: 8789.28 | O12: 8126.05 | Q12: Other investments | R12: 229.93 | S12: 341.96 | T12: 655.56 | U12: 710.53 | V12: 1703.5 | W12: 1657.43 | Y12: Equity investment in joint ventures and associates | Z12: 13572.23 | AA12: 15010.12 | AB12: 16335 | AC12: 18038.31 | AD12: 18097 | AE12: 21392.04 | AG12: Oil and gas assets | AO12: Loans | AP12: 44348 | AQ12: 65698 | AR12: 41951 | AS12: 22448 | AT12: 10051 | AU12: 4941
A13: Investments accounted for using the equity method | B13: 10561.62 | C13: 19549.64 | D13: 18415.49 | E13: 21700.65 | F13: 20561.41 | G13: 21090.68 | I13: Trade receivables | J13: 1029.99 | K13: 1093.47 | L13: 1055.54 | M13: 1047.98 | N13: 1049.69 | O13: 1046.88 | Q13: Loans | R13: 1409.48 | S13: 979.21 | T13: 925.89 | U13: 977.81 | V13: 1201.41 | W13: 5148.97 | Y13: Investments | Z13: 13707.46 | AA13: 20424.09 | AB13: 28003.76 | AC13: 23715.61 | AD13: 37065.04 | AE13: 35457.55 | AG13: Development wells in progress | AH13: 5589.94 | AI13: 5900.707 | AJ13: 7612.84 | AK13: 9725.987 | AL13: 9010.132 | AM13: 4047.329 | AO13: Other financial assets | AP13: 0 | AQ13: 0 | AR13: 2247 | AS13: 2215 | AT13: 16902 | AU13: 15256
A14: Other investments | B14: 287.86 | C14: 423.82 | D14: 758.14 | E14: 800.49 | F14: 1778.51 | G14: 1776.77 | I14: Loans & Other receivables | J14: 556.12 | K14: 390.36 | L14: 285.37 | M14: 281.21 | N14: 305.85 | O14: 329.02 | Q14: Other financial assets | R14: =6.29+2702.07 -> 2708.36 | S14: =16.39+3073.25 -> 3089.64 | T14: =3337.66+145.55 -> 3483.21 | U14: =3677.97+192.63 -> 3870.6 | V14: =204.24+4329.47 -> 4533.71 | W14: =461.95+3488.65 -> 3950.6 | Y14: Loans | Z14: 3294.66 | AA14: 2615.24 | AB14: 2292.96 | AC14: 2285.11 | AD14: 2586.98 | AE14: 3223.44 | AG14: Oil and gas facilities in progress | AH14: 19750.109 | AI14: 27472.641 | AJ14: 32260.77 | AK14: 35301.822 | AL14: 37305.961 | AM14: 39269.055 | AO14: Other non current assets | AP14: 4461 | AQ14: 4968 | AR14: 7297 | AS14: 2333 | AT14: 7403 | AU14: 5919
A15: Loans | B15: 5442.94 | C15: 5175.31 | D15: 3956.62 | E15: 4336.01 | F15: 4452.74 | G15: 4939.75 | I15: Other financial assets | J15: 113.97 | K15: 356.12 | L15: 1144.03 | M15: 550.82 | N15: 329.36 | O15: 107.18 | Q15: Total non-current assets | R15: =SUM(R7:R14) -> 79290.13 | S15: =SUM(S7:S14) -> 89992.63 | T15: =SUM(T7:T14) -> 104938.27 | U15: =SUM(U7:U14) -> 117363.49 | V15: =SUM(V7:V14) -> 129933.08 | W15: =SUM(W7:W14) -> 137039.8 | Y15: Other financial assets | Z15: 1430.85 | AA15: 1952.5 | AB15: 2639.28 | AC15: 1748.36 | AD15: 2360.8 | AE15: 2336.86 | AG15: Others | AH15: 20495.577 | AI15: 29548.035 | AJ15: 31610.94 | AK15: 28947.362 | AL15: =21109.73+24229.713 -> 45339.443 | AM15: =21634.896+22085.543 -> 43720.439 | AO15: Total non current assets | AP15: =SUM(AP7:AP14) -> 805045 | AQ15: =SUM(AQ7:AQ14) -> 662954 | AR15: =SUM(AR7:AR14) -> 656276 | AS15: =SUM(AS7:AS14) -> 624633 | AT15: =SUM(AT7:AT14) -> 697018 | AU15: =SUM(AU7:AU14) -> 752838
A16: Other financial assets | B16: 8.3 | C16: 184.6 | D16: 706.98 | E16: 537.57 | F16: 653.89 | G16: 757.48 | I16: Non current tax assets | J16: 676.47 | K16: 413.57 | L16: 432.04 | M16: 744.13 | N16: 888.44 | O16: 3.11 | Q16: Current Assets | Y16: Income tax assets | Z16: 4236.2 | AA16: 2479.91 | AB16: 2819.51 | AC16: 1857.22 | AD16: 1827.98 | AE16: 1589.73 | AG16: Goodwill | AH16: 14236.65 | AI16: 13538.591 | AJ16: 7.869 | AK16: 7.868 | AL16: 7.867 | AM16: 7.866 | AO16: Current assets
A17: Income tax assets | B17: 1381.25 | C17: =1158.07+3.53 -> 1161.6 | D17: 349.8 | E17: 485.95 | F17: 477.44 | G17: 226.43 | I17: Other non current assets | J17: 1091.86 | K17: 1114.95 | L17: 864.66 | M17: 1034.23 | N17: 1146.76 | O17: 1139.66 | Q17: Inventories | R17: 19325.99 | S17: 28763.9 | T17: 35514.71 | U17: 29575 | V17: 34211.46 | W17: 38325.27 | Y17: Other non current assets | Z17: 2893.18 | AA17: 2850.04 | AB17: 3690.03 | AC17: 4070.95 | AD17: 4951.37 | AE17: 6160.83 | AG17: Investment property | AH17: 7.7872 | AI17: 7.871 | AJ17: 11205.649 | AK17: 12033.412 | AL17: 12136.444 | AM17: 12762.488 | AO17: Inventories | AP17: 38802 | AQ17: 37437 | AR17: 45923 | AS17: 48926 | AT17: 85100 | AU17: 89216
A18: Other non current assets | B18: 1267.95 | C18: 1276.13 | D18: 2007.83 | E18: 1311.12 | F18: 1797.44 | G18: 1743.87 | I18: Total Non current assets | J18: =SUM(J7:J17) -> 63257.29 | K18: =SUM(K7:K17) -> 70517.73 | L18: =SUM(L7:L17) -> 80252.25 | M18: =SUM(M7:M17) -> 87250.06 | N18: =SUM(N7:N17) -> 104445.42 | O18: =SUM(O7:O17) -> 111647.03 | Q18: Investments | R18: 5344.86 | S18: 5417.58 | T18: 5371.52 | U18: 5168.89 | V18: 5182.7 | W18: 3252.49 | Y18: Total non current assets | Z18: =SUM(Z7:Z17) -> 219001.55 | AA18: =SUM(AA7:AA17) -> 238707.23 | AB18: =SUM(AB7:AB17) -> 263764.16 | AC18: =SUM(AC7:AC17) -> 282896.6 | AD18: =SUM(AD7:AD17) -> 323919.38 | AE18: =SUM(AE7:AE17) -> 349223.9 | AG18: Other intangible assets | AH18: 764.141 | AI18: 886.849 | AJ18: 1027.428 | AK18: 973.607 | AL18: 1360.78 | AM18: 1420.744 | AO18: Investments | AP18: 70030 | AQ18: 94665 | AR18: 78304 | AS18: 86074 | AT18: 68663 | AU18: 57102
A19: Total non-current assets | B19: =SUM(B7:B18) -> 85405.75 | C19: =SUM(C7:C18) -> 108906.7 | D19: =SUM(D7:D18) -> 125529.27 | E19: =SUM(E7:E18) -> 132095.84 | F19: =SUM(F7:F18) -> 136723.64 | G19: =SUM(G7:G18) -> 145550 | I19: Current Assets | Q19: Trade receivables | R19: 3934.19 | S19: 6869.99 | T19: 6340.31 | U19: 6832.38 | V19: 9324.09 | W19: 11780.71 | Y19: Current Assets | AG19: Intangible assets under development | AO19: Trade receivables | AP19: 7483 | AQ19: 4159 | AR19: 14394 | AS19: 16898 | AT19: 14740 | AU19: 15591
A20: Current Assets | I20: Inventories | J20: 3183.01 | K20: 2989.73 | L20: 3576.61 | M20: 5917.92 | N20: 5970 | O20: 6249.92 | Q20: Cash and cash equivalents | R20: 204.76 | S20: 480.38 | T20: 233.85 | U20: 518.48 | V20: 279.85 | W20: 166.22 | Y20: Inventories | Z20: 67010.76 | AA20: 83427.46 | AB20: 111736.51 | AC20: 121107.58 | AD20: 121375.83 | AE20: 113878.49 | AG20: Exploratory wells in progress | AH20: 19402.48 | AI20: 18790.63 | AJ20: 15860.473 | AK20: 16392.494 | AL20: 18456.391 | AM20: 19585.93 | AO20: Cash and cash equivalents | AP20: 8485 | AQ20: 5573 | AR20: 161 | AS20: 595 | AT20: 69248 | AU20: 82471
A21: Inventories | B21: 20421.06 | C21: 26706.72 | D21: 42178.74 | E21: 38069.19 | F21: 42836.13 | G21: 45265.19 | I21: Investments | J21: 0 | K21: 468.48 | L21: 7446.53 | M21: 10679.61 | N21: 9580.27 | O21: 9436.44 | Q21: Bank Balances other than cash and cash equivalents | R21: 18.36 | S21: 94.54 | T21: 24.12 | U21: 153.92 | V21: 193.58 | W21: 87.58 | Y21: Investments | Z21: 8291.18 | AA21: 9282.61 | AB21: 8013.2 | AC21: 10436.54 | AD21: 10379.86 | AE21: 10368.91 | AG21: Acquisition cost | AH21: 18497.864 | AI21: 18439.733 | AJ21: 19165.642 | AK21: 23283.305 | AL21: 1265 | AM21: 0 | AO21: Other financial assets | AP21: =15028+16115 -> 31143 | AQ21: =993+59560 -> 60553 | AR21: 54901 | AS21: 49408 | AT21: 11747 | AU21: 15218
A22: Investments | B22: 5208.54 | C22: 6794.27 | D22: 4442.27 | E22: 4277.14 | F22: 4290.67 | G22: 3663.07 | I22: Trade receivables | J22: 4818.31 | K22: 3501.5 | L22: 1519.8 | M22: 243.77 | N22: 1146.03 | O22: 1317.18 | Q22: Loans | R22: 409.86 | S22: 126.33 | T22: 155.18 | U22: 171.46 | V22: 107.97 | W22: 118.52 | Y22: Trade receivables | Z22: 13259.48 | AA22: 13800.28 | AB22: 18700.42 | AC22: 16271.21 | AD22: 13831.45 | AE22: 18550.96 | AG22: Others | AH22: 96.758 | AI22: 180.251 | AJ22: 208.562 | AK22: 293.637 | AL22: =4219.238+51.998 -> 4271.236 | AM22: =5695.76+40.758 -> 5736.518 | AO22: Other current assets | AP22: 10711 | AQ22: 8332 | AR22: 7001 | AS22: 7220 | AT22: 13127 | AU22: 9965
A23: Trade receivables | B23: 5164.34 | C23: 7834.77 | D23: 9707.47 | E23: 6723.78 | F23: 8342.03 | G23: 9338.98 | I23: Cash and cash equivalents | J23: 624.13 | K23: 1506.59 | L23: 1284.23 | M23: 859.2 | N23: 566.1 | O23: 1403.34 | Q23: Other financial assets | R23: 7970.43 | S23: 1975.77 | T23: 1508 | U23: 1041.67 | V23: 2556.35 | W23: 2727.13 | Y23: Cash and cash equivalents | Z23: 1434.61 | AA23: 781.24 | AB23: 1176.59 | AC23: 996.35 | AD23: 1246.59 | AE23: 673.17 | AG23: Investments in | AO23: Total current assets | AP23: =SUM(AP17:AP22) -> 166654 | AQ23: =SUM(AQ17:AQ22) -> 210719 | AR23: =SUM(AR17:AR22) -> 200684 | AS23: =SUM(AS17:AS22) -> 209121 | AT23: =SUM(AT17:AT22) -> 262625 | AU23: =SUM(AU17:AU22) -> 269563
A24: Cash and cash equivalents | B24: 98.27 | C24: 7567.57 | D24: 2159.04 | E24: 2312.72 | F24: 2300.74 | G24: 557.93 | I24: Bank balances | J24: 626.04 | K24: 518.05 | L24: 99.54 | M24: 67.99 | N24: 72.62 | O24: 74.47 | Q24: Other current assets | R24: 401.24 | S24: 425.92 | T24: 482.39 | U24: 463.73 | V24: 914.09 | W24: 1237.15 | Y24: Bank balances other than above | Z24: 861.37 | AA24: 1693.49 | AB24: 643.55 | AC24: 1100.29 | AD24: 1910.46 | AE24: 2631.77 | AG24: Joint ventures and associates | AH24: 35352.174 | AI24: 35546.594 | AJ24: 36915.098 | AK24: 53671.154 | AL24: 54036.428 | AM24: 58647.459 | AO24: Total Assets | AP24: =AP15+AP23 -> 971699 | AQ24: =AQ15+AQ23 -> 873673 | AR24: =AR15+AR23 -> 856960 | AS24: =AS15+AS23 -> 833754 | AT24: =AT15+AT23 -> 959643 | AU24: =AU15+AU23 -> 1022401
A25: Bank balances | B25: 17.51 | C25: 542.54 | D25: 77.65 | E25: 261.66 | F25: 3985.62 | G25: 9917.66 | I25: Loans & Other receivables | J25: 720.32 | K25: 685.67 | L25: 1679.42 | M25: 1823.79 | N25: 1540.36 | O25: 1150.99 | Q25: Assets classified as held for sale | R25: 10.07 | S25: 12.67 | T25: 60.51 | U25: 50.49 | V25: 65.2 | W25: 9.77 | Y25: Loans | Z25: 1089.64 | AA25: 988.61 | AB25: 450.92 | AC25: 379.73 | AD25: 492.94 | AE25: 628.76 | AG25: Other investments | AH25: 16058.14 | AI25: 19057.991 | AJ25: 24355.513 | AK25: 20032.559 | AL25: 41444.934 | AM25: 33717.452 | AO25: EQUITY AND LIABILITIES
A26: Loans | B26: 590.58 | C26: 132.5 | D26: 136 | E26: 142.64 | F26: 136.92 | G26: 141.87 | I26: Other financial assets | J26: 766.26 | K26: 487.19 | L26: 0 | M26: 0 | N26: 0 | O26: 23.88 | Q26: Total current assets | R26: =SUM(R17:R25) -> 37619.76 | S26: =SUM(S17:S25) -> 44167.08 | T26: =SUM(T17:T25) -> 49690.59 | U26: =SUM(U17:U25) -> 43976.02 | V26: =SUM(V17:V25) -> 52835.29 | W26: =SUM(W17:W25) -> 57704.84 | Y26: Other financial assets | Z26: 14340.19 | AA26: 2256.04 | AB26: 1537.72 | AC26: 2660.79 | AD26: 2760.99 | AE26: 2259.46 | AG26: Trade receivables | AH26: 2374.097 | AI26: 2562.956 | AJ26: 2476.501 | AK26: 2622.486 | AL26: 2535.478 | AM26: 2379.229 | AO26: Equity
A27: Other financial assets | B27: 6811.24 | C27: 599.95 | D27: 559.66 | E27: 1101.66 | F27: 1257.95 | G27: 1771.88 | I27: Other current assets | J27: 918.82 | K27: 710.02 | L27: 701.02 | M27: 938.41 | N27: 1396.43 | O27: 1845.48 | Q27: Total assets | R27: =R15+R26 -> 116909.89 | S27: =S15+S26 -> 134159.71 | T27: =T15+T26 -> 154628.86 | U27: =U15+U26 -> 161339.51 | V27: =V15+V26 -> 182768.37 | W27: =W15+W26 -> 194744.64 | Y27: Current tax assets | Z27: 55.62 | AA27: 0 | AB27: 0 | AC27: 0 | AD27: 0.82 | AE27: 725.05 | AG27: Loans | AH27: 3214.581 | AI27: 2821.86 | AJ27: 2643.717 | AK27: 2965.559 | AL27: 3442.593 | AM27: 7584.73 | AO27: Equity share capital | AP27: 6339 | AQ27: 6445 | AR27: 6765 | AS27: 6766 | AT27: 6766 | AU27: 13532
A28: Current tax assets] | B28: 0.17 | C28: 535.21 | D28: 894.89 | E28: 969.11 | F28: 827.9 | G28: 164.66 | I28: Total current assets | J28: =SUM(J20:J27) -> 11656.89 | K28: =SUM(K20:K27) -> 10867.23 | L28: =SUM(L20:L27) -> 16307.15 | M28: =SUM(M20:M27) -> 20530.69 | N28: =SUM(N20:N27) -> 20271.81 | O28: =SUM(O20:O27) -> 21501.7 | Q28: EQUITY AND LIABILITIES | Y28: Other current assets | Z28: 4157.2 | AA28: 3786.06 | AB28: 3813.53 | AC28: 4929.57 | AD28: 5212.25 | AE28: 6414.73 | AG28: Deposit under site restoration fund | AH28: 22283.606 | AI28: 23511.47 | AJ28: 24872.18 | AK28: 26751.158 | AL28: 28571.04 | AM28: 30848.792 | AO28: Other equity | AP28: 384876 | AQ28: 468038 | AR28: 464762 | AS28: 472328 | AT28: 508330 | AU28: 529555
A29: Other current assets | B29: 1545.68 | C29: 1339.82 | D29: 1830.98 | E29: 2167.55 | F29: 1673.73 | G29: 1978.67 | I29: Total Assets | J29: =J18+J28 -> 74914.18 | K29: =K18+K28 -> 81384.96 | L29: =L18+L28 -> 96559.4 | M29: =M18+M28 -> 107780.75 | N29: =N18+N28 -> 124717.23 | O29: =O18+O28 -> 133148.73 | Q29: Equity | Y29: Assets held for sale | Z29: 235.23 | AA29: 192.9 | AB29: 788.25 | AC29: 983.43 | AD29: 1231.43 | AE29: 1511.85 | AG29: Finance lease receivables | AH29: 0 | AI29: 0 | AJ29: 0 | AK29: 0 | AL29: 0 | AM29: 0 | AO29: Total equity | AP29: =AP27+AP28 -> 391215 | AQ29: =AQ27+AQ28 -> 474483 | AR29: =AR27+AR28 -> 471527 | AS29: =AS27+AS28 -> 479094 | AT29: =AT27+AT28 -> 515096 | AU29: =AU27+AU28 -> 543087
A30: Assets held for sale | B30: 1205.84 | C30: 21.5 | D30: 12.66 | E30: 16.8 | F30: 42.42 | G30: 32.31 | I30: EQUITY AND LIABILITIES | Q30: Equity share capital | R30: 1524.21 | S30: 1452.41 | T30: 1418.94 | U30: 1418.94 | V30: 1418.94 | W30: 2128.21 | Y30: Total current assets | Z30: =SUM(Z20:Z29) -> 110735.28 | AA30: =SUM(AA20:AA29) -> 116208.69 | AB30: =SUM(AB20:AB29) -> 146860.69 | AC30: =SUM(AC20:AC29) -> 158865.49 | AD30: =SUM(AD20:AD29) -> 158442.62 | AE30: =SUM(AE20:AE29) -> 157643.15 | AG30: Others | AH30: 4136.896 | AI30: 3830.737 | AJ30: 7993.057 | AK30: 9421.588 | AL30: 10519.071 | AM30: 12098.23 | AO30: Liabilities
A31: Total current assets | B31: =SUM(B21:B30) -> 41063.23 | C31: =SUM(C21:C30) -> 52074.85 | D31: =SUM(D21:D30) -> 61999.36 | E31: =SUM(E21:E30) -> 56042.25 | F31: =SUM(F21:F30) -> 65694.11 | G31: =SUM(G21:G30) -> 72832.22 | I31: Equity | Q31: Other equity | R31: 29456.41 | S31: 36628.45 | T31: 39985.27 | U31: 30844.33 | V31: 45502.41 | W31: 49016.08 | Y31: Total assets | Z31: =Z18+Z30 -> 329736.83 | AA31: =AA18+AA30 -> 354915.92 | AB31: =AB18+AB30 -> 410624.85 | AC31: =AC18+AC30 -> 441762.09 | AD31: =AD18+AD30 -> 482362 | AE31: =AE18+AE30 -> 506867.05 | AG31: Deferred tax assets | AH31: 2667.495 | AI31: 2693.644 | AJ31: 3327.935 | AK31: 2414.586 | AL31: 6381.871 | AM31: 7077.557 | AO31: Non-current liabilities
A32: Total Assets | B32: =B19+B31 -> 126468.98 | C32: =C19+C31 -> 160981.55 | D32: =D19+D31 -> 187528.63 | E32: =E19+E31 -> 188138.09 | F32: =F19+F31 -> 202417.75 | G32: =G19+G31 -> 218382.22 | I32: Equity share capital | J32: 4510.14 | K32: 4440.39 | L32: 4440.39 | M32: 6575.1 | N32: 6575.1 | O32: 6575.1 | Q32: Total equity | R32: =R30+R31 -> 30980.62 | S32: =S30+S31 -> 38080.86 | T32: =T30+T31 -> 41404.21 | U32: =U30+U31 -> 32263.27 | V32: =V30+V31 -> 46921.35 | W32: =W30+W31 -> 51144.29 | Y32: EQUITY AND LIABILITIES | AG32: Non current tax assets | AH32: 10759.995 | AI32: 9588.479 | AJ32: 10518.589 | AK32: 14254.502 | AL32: 14873.245 | AM32: 14676.319 | AO32: Borrowings | AP32: 194402 | AQ32: 160598 | AR32: 167231 | AS32: 135561 | AT32: 161059 | AU32: 172025
A33: EQUITY AND LIABILITIES | I33: Other equity | J33: 44758.11 | K33: 48741.95 | L33: 59673.89 | M33: 58352.33 | N33: 70422.08 | O33: 78422.45 | Q33: Non current liabilities | Y33: Equity | AG33: Other non current assets | AH33: 4736.822 | AI33: 6388.355 | AJ33: 5176.63 | AK33: 3480.557 | AL33: 4060.286 | AM33: 4371.359 | AO33: Lease Liabilities | AP33: 0 | AQ33: 0 | AR33: 2790 | AS33: 2786 | AT33: 2692 | AU33: 2627
A34: Equity | I34: Non controlling interests | J34: 87.04 | K34: 97.49 | L34: 191.18 | M34: 179.55 | N34: 198.6 | O34: 242.93 | Q34: Borrowings | R34: 23109.63 | S34: 27764.42 | T34: 32115.28 | U34: 48171.47 | V34: 37943.04 | W34: 34650.77 | Y34: Equity share capital | Z34: 9181.04 | AA34: 9181.04 | AB34: 9181.04 | AC34: 13771.56 | AD34: 13771.56 | AE34: 13771.56 | AG34: Total non current assets | AH34: =SUM(AH8:AH10,AH13:AH18,AH20:AH22,AH24:AH33) -> 429308.41 | AI34: =SUM(AI8:AI10,AI13:AI18,AI20:AI22,AI24:AI33) -> 450080.45 | AJ34: =SUM(AJ8:AJ10,AJ13:AJ18,AJ20:AJ22,AJ24:AJ33) -> 479400.62 | AK34: =SUM(AK8:AK10,AK13:AK18,AK20:AK22,AK24:AK33) -> 500378.19 | AL34: =SUM(AL8:AL10,AL13:AL18,AL20:AL22,AL24:AL33) -> 601777.88 | AM34: =SUM(AM8:AM10,AM13:AM18,AM20:AM22,AM24:AM33) -> 623935.56 | AO34: Other financial liabilities | AP34: 2930 | AQ34: 4014 | AR34: 3210 | AS34: 584 | AT34: 0 | AU34: 4397
A35: Equity share capital | B35: 1966.88 | C35: 2092.91 | D35: 2129.45 | E35: 2129.45 | F35: 2136.29 | G35: 4272.58 | I35: Total equity | J35: =SUM(J32:J34) -> 49355.29 | K35: =SUM(K32:K34) -> 53279.83 | L35: =SUM(L32:L34) -> 64305.46 | M35: =SUM(M32:M34) -> 65106.98 | N35: =SUM(N32:N34) -> 77195.78 | O35: =SUM(O32:O34) -> 85240.48 | Q35: Lease Liabilities | R35: 0 | S35: 0 | T35: 3150.74 | U35: 3279.97 | V35: 3645.15 | W35: 3875.76 | Y35: Other equity | Z35: 86216.87 | AA35: 102657.01 | AB35: 124354.14 | AC35: 125948.68 | AD35: 169644.71 | AE35: 172715.76 | AG35: Current Assets | AO35: Provisions | AP35: 1410 | AQ35: 1499 | AR35: 1598 | AS35: 1296 | AT35: 1701 | AU35: 1767
A36: Other equity | B36: 31247.5 | C36: 51462.17 | D36: 49776.17 | E36: 51392.91 | F36: 73498.82 | G36: 77111.5 | I36: Non-current Liabilities | Q36: Other financial liabilities | R36: 0.7 | S36: 32.63 | T36: 0.73 | U36: 0.3 | V36: 0.32 | W36: 0.35 | Y36: Non controlling interest | Z36: 876.27 | AA36: 975.94 | AB36: 1591.47 | AC36: 3494.1 | AD36: 4746.71 | AE36: 4537.34 | AG36: Inventories | AH36: 33051.203 | AI36: 44573.326 | AJ36: 54163.099 | AK36: 44238.068 | AL36: 53792.779 | AM36: 58956.33 | AO36: Deferred tax liabilities | AP36: 50556 | AQ36: 30788 | AR36: 30832 | AS36: 33968 | AT36: 36259 | AU36: 37390
A37: Total Equity | B37: =B35+B36 -> 33214.38 | C37: =C35+C36 -> 53555.08 | D37: =D35+D36 -> 51905.62 | E37: =E35+E36 -> 53522.36 | F37: =F35+F36 -> 75635.11 | G37: =G35+G36 -> 81384.08 | I37: Borrowings | J37: 3773.4 | K37: 5237.4 | L37: 5468.06 | M37: 8879.69 | N37: 12806.02 | O37: 10781.04 | Q37: Provision | R37: 54.62 | S37: 56.78 | T37: 103.11 | U37: 112.93 | V37: 82.62 | W37: 203.34 | Y37: Total equity | Z37: =SUM(Z34:Z36) -> 96274.18 | AA37: =SUM(AA34:AA36) -> 112813.99 | AB37: =SUM(AB34:AB36) -> 135126.65 | AC37: =SUM(AC34:AC36) -> 143214.34 | AD37: =SUM(AD34:AD36) -> 188162.98 | AE37: =SUM(AE34:AE36) -> 191024.66 | AG37: Investments | AH37: 5344.862 | AI37: 5417.573 | AJ37: 5371.524 | AK37: 5168.897 | AL37: 5380.209 | AM37: 3252.502 | AO37: Other non current liabilities | AP37: 504 | AQ37: 504 | AR37: 504 | AS37: 0 | AT37: 2822 | AU37: 3173
A38: Non-current Liabilities | I38: Lease Liabilities | J38: 92.49 | K38: 453.34 | L38: 1001.9 | M38: 1117.72 | N38: 2331.35 | O38: 4237.97 | Q38: Deferred tax liabilities | R38: 5491.44 | S38: 5462.21 | T38: 5957.71 | U38: 2927.63 | V38: 6932.89 | W38: 7707.65 | Y38: LIABILITIES | AG38: Trade receivables | AH38: 9193.407 | AI38: 16015.834 | AJ38: 19187.283 | AK38: 18751.581 | AL38: 19704.13 | AM38: 21227.799 | AO38: Total non current liabilities | AP38: =SUM(AP32:AP37) -> 249802 | AQ38: =SUM(AQ32:AQ37) -> 197403 | AR38: =SUM(AR32:AR37) -> 206165 | AS38: =SUM(AS32:AS37) -> 174195 | AT38: =SUM(AT32:AT37) -> 204533 | AU38: =SUM(AU32:AU37) -> 221379
A39: Borrowings | B39: 26272.7 | C39: 35740.22 | D39: 36358.93 | E39: 41369.36 | F39: 26877.14 | G39: 26527.88 | I39: Deferred tax Liabilities | J39: 871.12 | K39: 689.72 | L39: 691.55 | M39: 732.8 | N39: 717.61 | O39: 809.44 | Q39: Other non current liabilities | R39: 224.83 | S39: 382.48 | T39: 456.84 | U39: 718.05 | V39: 817.49 | W39: 884.76 | Y39: Non current liabilities | AG39: Cash and cash equivalents | AH39: 4780.562 | AI39: 4019.369 | AJ39: 5034.667 | AK39: 2639.998 | AL39: 4141.571 | AM39: 4554.357 | AO39: Current Liabilities
A40: Lease liabilities | B40: 0 | C40: 7612.07 | D40: 8040.73 | E40: 8265.17 | F40: 8600.15 | G40: 8840.4 | I40: Other non current liabilities | J40: 538.51 | K40: 557.02 | L40: 676.08 | M40: 809.13 | N40: 942.05 | O40: 994.43 | Q40: Total non current liabilities | R40: =SUM(R34:R39) -> 28881.22 | S40: =SUM(S34:S39) -> 33698.52 | T40: =SUM(T34:T39) -> 41784.41 | U40: =SUM(U34:U39) -> 55210.35 | V40: =SUM(V34:V39) -> 49421.51 | W40: =SUM(W34:W39) -> 47322.63 | Y40: Borrowings | Z40: 56070.61 | AA40: 60934.9 | AB40: 55944.54 | AC40: 63312.94 | AD40: 46792.9 | AE40: 51755.75 | AG40: Other bank balances | AH40: 4859.674 | AI40: 3172.902 | AJ40: 1806.272 | AK40: 26500.329 | AL40: 37690.277 | AM40: 22623.402 | AO40: Borrowings | AP40: 59899 | AQ40: 33152 | AR40: 27332 | AS40: 80262 | AT40: 50731 | AU40: 26788
A41: Other financial liabilities | B41: 53.99 | C41: 58.08 | D41: 56.63 | E41: 68.89 | F41: 70.82 | G41: 58.74 | I41: Other financial liabilities | J41: 245.81 | K41: 345.16 | L41: 447.22 | M41: 486.13 | N41: 560.09 | O41: 692.3 | Q41: Current Liabilities | Y41: Other financial liabilities | Z41: 789.58 | AA41: 847.48 | AB41: 6363.62 | AC41: 6476.91 | AD41: 6331.9 | AE41: 6578.65 | AG41: Loans | AH41: 1182.117 | AI41: 752.06 | AJ41: 492.88 | AK41: 457.61 | AL41: 420.073 | AM41: 459.038 | AO41: Lease Liabilities | AP41: 0 | AQ41: 0 | AR41: 86 | AS41: 97 | AT41: 93 | AU41: 65
...

Sheet Income Statement
A1: INCOME STATEMENT
A3: #VALUE! | I3: #VALUE! | Q3: #VALUE! | Y3: #VALUE! | AG3: #VALUE! | AO3: #VALUE!
A4: Particulars | B4: 2020 | C4: 2021 | D4: 2022 | E4: 2023 | F4: 2024 | G4: 2025 | I4: Particulars | J4: 2020 | K4: 2021 | L4: 2022 | M4: 2023 | N4: 2024 | O4: 2025 | Q4: Particulars | R4: 2020 | S4: 2021 | T4: 2022 | U4: 2023 | V4: 2024 | W4: 2025 | Y4: Particulars | Z4: 2020 | AA4: 2021 | AB4: 2022 | AC4: 2023 | AD4: 2024 | AE4: 2025 | AG4: Particulars | AH4: 2020 | AI4: 2021 | AJ4: 2022 | AK4: 2023 | AL4: 2024 | AM4: 2025 | AO4: Particulars | AP4: 2020 | AQ4: 2021 | AR4: 2022 | AS4: 2023 | AT4: 2024 | AU4: 2025
A5: INCOME | I5: INCOME | Q5: INCOME | Y5: INCOME | AG5: INCOME | AO5: INCOME
A6: Revenue from operations | B6: 327580.78 | C6: 301873.16 | D6: 432422.48 | E6: 533467.55 | F6: 506992.6 | G6: 500517.48 | I6: Revenue from operations | J6: 72576.98 | K6: 57428.26 | L6: 92873.82 | M6: 145875.03 | N6: 133499.54 | O6: 142291.42 | Q6: Gross sale of products | R6: 286574.27 | S6: 269493.69 | T6: 372867.94 | U6: 464989.7 | V6: 460147.32 | W6: 464626.25 | Y6: Revenue from operations | Z6: 575989.7 | AA6: 520236.84 | AB6: 736716.3 | AC6: 951409.94 | AD6: 881235.45 | AE6: 859362.73 | AG6: Revenue from operations | AH6: 424961.08 | AI6: 360572.31 | AJ6: 531792.54 | AK6: 684829.22 | AL6: 653170.77 | AM6: 663262.31 | AO6: Value of sales | AP6: 362869 | AQ6: 276181 | AR6: 463067 | AS6: 562234 | AT6: 533566 | AU6: 538564
A7: Other income | B7: 3081.31 | C7: 4336.27 | D7: 2629.36 | E7: 2183.99 | F7: 2234.73 | G7: 2684.72 | I7: Other income | J7: 1537.15 | K7: 1120.2 | L7: 1172.25 | M7: 1328.47 | N7: 1007.81 | O7: 1267.64 | Q7: Other operating income | R7: 1167.78 | S7: 1084.27 | T7: 1259.05 | U7: 1508.91 | V7: 1821.82 | W7: 2097.43 | Y7: Other income | Z7: 2773.62 | AA7: 3499.54 | AB7: 3096.76 | AC7: 4198.92 | AD7: 3838.56 | AE7: 3513.73 | AG7: Other income | AH7: 9077.022 | AI7: 9323.019 | AJ7: 7437.71 | AK7: 8074.08 | AL7: 12030.696 | AM7: 12393.574 | AO7: Income from services | AP7: 3308 | AQ7: 2759 | AR7: 1978 | AS7: 3113 | AT7: 41390 | AU7: 18599
A8: Total income | B8: =B6+B7 -> 330662.09 | C8: =C6+C7 -> 306209.43 | D8: =D6+D7 -> 435051.84 | E8: =E6+E7 -> 535651.54 | F8: =F6+F7 -> 509227.33 | G8: =G6+G7 -> 503202.2 | I8: Total income | J8: =J6+J7 -> 74114.13 | K8: =K6+K7 -> 58548.46 | L8: =L6+L7 -> 94046.07 | M8: =M6+M7 -> 147203.5 | N8: =N6+N7 -> 134507.35 | O8: =O6+O7 -> 143559.06 | Q8: Other income | R8: 1681.62 | S8: 2643.73 | T8: 2438.92 | U8: 1465.91 | V8: 1916.94 | W8: 2087.85 | Y8: Total income | Z8: =Z6+Z7 -> 578763.32 | AA8: =AA6+AA7 -> 523736.38 | AB8: =AB6+AB7 -> 739813.06 | AC8: =AC6+AC7 -> 955608.86 | AD8: =AD6+AD7 -> 885074.01 | AE8: =AE6+AE7 -> 862876.46 | AG8: Total income | AH8: =AH6+AH7 -> 434038.1 | AI8: =AI6+AI7 -> 369895.33 | AJ8: =AJ6+AJ7 -> 539230.25 | AK8: =AK6+AK7 -> 692903.3 | AL8: =AL6+AL7 -> 665201.46 | AM8: =AM6+AM7 -> 675655.88 | AO8: Less: GST | AP8: 14322 | AQ8: 13871 | AR8: 21050 | AS8: 23556 | AT8: 27014 | AU8: 24371
A9: EXPENSES | I9: EXPENSES | Q9: Total income | R9: =SUM(R6:R8) -> 289423.67 | S9: =SUM(S6:S8) -> 273221.69 | T9: =SUM(T6:T8) -> 376565.91 | U9: =SUM(U6:U8) -> 467964.52 | V9: =SUM(V6:V8) -> 463886.08 | W9: =SUM(W6:W8) -> 468811.53 | Y9: EXPENSES | AG9: EXPENSES | AO9: Other income | AP9: 13566 | AQ9: 14818 | AR9: 13843 | AS9: 11229 | AT9: 12128 | AU9: 16094
A10: Cost of materials consumed | B10: 113229.3 | C10: 71153.56 | D10: 163541.19 | E10: 234305.39 | F10: 212853 | G10: 225319.41 | I10: Cost of materials consumed | J10: 4411.97 | K10: 3905.88 | L10: 11103.28 | M10: 6860.15 | N10: 7325.46 | O10: 7273.36 | Q10: EXPENSES | Y10: Cost of material consumed | Z10: 281080.13 | AA10: 174196.22 | AB10: 330672.38 | AC10: 503757.28 | AD10: 446484.44 | AE10: 449812.63 | AG10: Purchase of stock in trade | AH10: 176006.43 | AI10: 144561.83 | AJ10: 225616.93 | AK10: 266120.04 | AL10: 234072.28 | AM10: 221401.89 | AO10: Total income | AP10: =AP6+AP7-AP8+AP9 -> 365421 | AQ10: =AQ6+AQ7-AQ8+AQ9 -> 279887 | AR10: =AR6+AR7-AR8+AR9 -> 457838 | AS10: =AS6+AS7-AS8+AS9 -> 553020 | AT10: =AT6+AT7-AT8+AT9 -> 560070 | AU10: =AU6+AU7-AU8+AU9 -> 548886
A11: Purchase of stock in trade | B11: 143164.25 | C11: 127800.87 | D11: 143901.7 | E11: 199884.14 | F11: 165232.84 | G11: 159646.45 | I11: Purchase of stock in trade | J11: 52878.13 | K11: 39379.13 | L11: 59266.68 | M11: 123964.11 | N11: 100670.08 | O11: 108757.13 | Q11: Cost of material consumed | R11: 59906.49 | S11: 41212.33 | T11: 68790.6 | U11: 123336.11 | V11: 126965.71 | W11: 146337.31 | Y11: Excise duty | Z11: 92226.67 | AA11: 156287.17 | AB11: 147395.1 | AC11: 109654.03 | AD11: 104883.6 | AE11: 101256.92 | AG11: Changes in inventories of finished goods | AH11: 1145.563 | AI11: -9916.659 | AJ11: -2303.069 | AK11: 2566.082 | AL11: -4394.95 | AM11: 689.546 | AO11: EXPENSES
A12: Changes in inventories of finished goods | B12: -456.62 | C12: -3633.57 | D12: -3988.8 | E12: -975.21 | F12: -1989.84 | G12: 331.05 | I12: Changes in inventories of finished goods | J12: -427.99 | K12: 440.2 | L12: -262.78 | M12: -1992.39 | N12: -41.02 | O12: -292.27 | Q12: Purchase of stock in trade | R12: 187234.13 | S12: 167861.2 | T12: 253966.25 | U12: 302443.32 | V12: 263318.4 | W12: 247545.55 | Y12: Purchase of stock in trade | Z12: 139463.72 | AA12: 107444.28 | AB12: 169991.5 | AC12: 250207.42 | AD12: 191018.86 | AE12: 207762.62 | AG12: Production, transportation, selling and distribution | AH12: 183947.98 | AI12: 168147.84 | AJ12: 221903.57 | AK12: 326689.01 | AL12: 311897.84 | AM12: 339329.62 | AO12: Cost of material consumed | AP12: 237342 | AQ12: 168262 | AR12: 320852 | AS12: 391508 | AT12: 376418 | AU12: 384021
A13: Excise duty expense | B13: 43197.83 | C13: 69319.86 | D13: 85778.54 | E13: 60342.88 | F13: 58909.57 | G13: 60245.62 | I13: Employee benefit expenses | J13: 1592.32 | K13: 1645.89 | L13: 1815.55 | M13: 1902.39 | N13: 2273.69 | O13: 2236.46 | Q13: Changes in inventories of finished goods | R13: -354.51 | S13: -8518.53 | T13: -625.88 | U13: 1429.83 | V13: -2732.49 | W13: 1016 | Y13: Changes in inventories of finished goods | Z13: -5414.35 | AA13: -6181.61 | AB13: -13710.98 | AC13: -6329.71 | AD13: 1290.52 | AE13: -789.75 | AG13: Survey costs | AH13: 1901.534 | AI13: 1967.724 | AJ13: 1988.529 | AK13: 3979.431 | AL13: 1942.949 | AM13: 2391.36 | AO13: Purchase of stock in trade | AP13: 7292 | AQ13: 7301 | AR13: 10691 | AS13: 9974 | AT13: 13453 | AU13: 15864
A14: Employee benefit expenses | B14: 3691.45 | C14: 4477.17 | D14: 3397.92 | E14: 2763.97 | F14: 3577.17 | G14: 3509.53 | I14: Finance costs | J14: 308.94 | K14: 179.27 | L14: 202.48 | M14: 366.58 | N14: 719.2 | O14: 747.99 | Q14: Excise duty | R14: 18650.52 | S14: 37329.51 | T14: 24213.81 | U14: 25789.36 | V14: 28112.63 | W14: 32617.51 | Y14: Employee benefit expenses | Z14: 9336.93 | AA14: 11308.78 | AB14: 11582.92 | AC14: 9359.14 | AD14: 11670.94 | AE14: 10879.86 | AG14: Exploration well costs | AH14: 7121.877 | AI14: 5167.817 | AJ14: 3904.613 | AK14: 6201.54 | AL14: 3867.626 | AM14: 7605.434 | AO14: Changes in inventories of finished goods | AP14: 77 | AQ14: 610 | AR14: -7962 | AS14: -6487 | AT14: 2700 | AU14: -10679
A15: Finance costs | B15: 2181.86 | C15: 1328.36 | D15: 2208.81 | E15: 3216.48 | F15: 4148.89 | G15: 3591.44 | I15: Depreciation and amortisation expense | J15: 2080.16 | K15: 2173.82 | L15: 2420.17 | M15: 2701.57 | N15: 3672 | O15: 3799.23 | Q15: Employee benefit expenses | R15: 3224.06 | S15: 3219.42 | T15: 3017.35 | U15: 3000.67 | V15: 3469.74 | W15: 3381.23 | Y15: Finance costs | Z15: 6578.74 | AA15: 3589.12 | AB15: 5423.26 | AC15: 7541.36 | AD15: 7825.65 | AE15: 9261.93 | AG15: Finance costs | AH15: 7489.339 | AI15: 5079.031 | AJ15: 5696.043 | AK15: 7889.356 | AL15: 13025.698 | AM15: 14534.947 | AO15: Excise duty | AP15: 14902 | AQ15: 19402 | AR15: 21672 | AS15: 13476 | AT15: 13408 | AU15: 15443
A16: Depreciation and amortisation expense | B16: 3786.89 | C16: 3978.05 | D16: 5417.9 | E16: 6347.48 | F16: 6771.26 | G16: 7256.69 | I16: Excise duty | J16: 59.28 | K16: 56.35 | L16: 103.99 | M16: 206.73 | N16: 271.08 | O16: 387.93 | Q16: Finance costs | R16: 1138.85 | S16: 963.28 | T16: 997.32 | U16: 2174.11 | V16: 2556 | W16: 3365.48 | Y16: Depreciation, amortisation and impairment | AG16: Depreciation, depletion, amortisation and impairment | AH16: 26634.881 | AI16: 25538.471 | AJ16: 26883.164 | AK16: 24557.055 | AL16: 30440.1 | AM16: 35205.965 | AO16: Employee benefit expenses | AP16: 6067 | AQ16: 5024 | AR16: 5419 | AS16: 5691 | AT16: 7807 | AU16: 8690
A17: Other expenses | B17: 18115.26 | C17: 15616.46 | D17: 20765.91 | E17: 26189.75 | F17: 24327.68 | G17: 26064.04 | I17: Other expenses | J17: 5028.98 | K17: 4757.05 | L17: 5695.52 | M17: 7446.58 | N17: 8703.93 | O17: 8496.99 | Q17: Depreciation and amortisation | R17: 3369.87 | S17: 3625.47 | T17: 4000.36 | U17: 4560.15 | V17: 5596.43 | W17: 6154.1 | Y17: PPE | Z17: 9586.7 | AA17: 10643.34 | AB17: 11986.15 | AC17: 12888.89 | AD17: 15603.44 | AE17: 16448.15 | AG17: Other impairment and write offs | AH17: 2732.717 | AI17: 1177.763 | AJ17: 808.38 | AK17: 3746.146 | AL17: 3401.989 | AM17: 2983.738 | AO17: Finance costs | AP17: 12105 | AQ17: 16211 | AR17: 9123 | AS17: 12626 | AT17: 13430 | AU17: 10054
A18: Total expenses | B18: =SUM(B10:B17) -> 326910.22 | C18: =SUM(C10:C17) -> 290040.76 | D18: =SUM(D10:D17) -> 421023.17 | E18: =SUM(E10:E17) -> 532074.88 | F18: =SUM(F10:F17) -> 473830.57 | G18: =SUM(G10:G17) -> 485964.23 | I18: Total expenses | J18: =SUM(J10:J17) -> 65931.79 | K18: =SUM(K10:K17) -> 52537.59 | L18: =SUM(L10:L17) -> 80344.89 | M18: =SUM(M10:M17) -> 141455.72 | N18: =SUM(N10:N17) -> 123594.42 | O18: =SUM(O10:O17) -> 131406.82 | Q18: Other expenses | R18: 13418.87 | S18: 13470.67 | T18: 14520.53 | U18: 17706.4 | V18: 17907.37 | W18: 19274.88 | Y18: Intangible assets | Z18: 686.69 | AA18: 298.11 | AB18: 361.43 | AC18: 292.16 | AD18: 262.67 | AE18: 329.19 | AG18: Total expenses | AH18: =SUM(AH10:AH17) -> 406980.32 | AI18: =SUM(AI10:AI17) -> 341723.81 | AJ18: =SUM(AJ10:AJ17) -> 484498.16 | AK18: =SUM(AK10:AK17) -> 641748.66 | AL18: =SUM(AL10:AL17) -> 594253.53 | AM18: =SUM(AM10:AM17) -> 624142.51 | AO18: Depreciation, amortisation and depletion | AP18: 9728 | AQ18: 9199 | AR18: 10264 | AS18: 10118 | AT18: 17690 | AU18: 17981
A19: Profit before exceptional items and tax | B19: =B8-B18 -> 3751.87 | C19: =C8-C18 -> 16168.67 | D19: =D8-D18 -> 14028.67 | E19: =E8-E18 -> 3576.66 | F19: =F8-F18 -> 35396.76 | G19: =G8-G18 -> 17237.97 | I19: Profit/loss before share of profit/loss of associate and JV | J19: =J8-J18 -> 8182.34 | K19: =K8-K18 -> 6010.87 | L19: =L8-L18 -> 13701.18 | M19: =M8-M18 -> 5747.78 | N19: =N8-N18 -> 10912.93 | O19: =O8-O18 -> 12152.24 | Q19: Total expenses | R19: =SUM(R11:R18) -> 286588.28 | S19: =SUM(S11:S18) -> 259163.35 | T19: =SUM(T11:T18) -> 368880.34 | U19: =SUM(U11:U18) -> 480439.95 | V19: =SUM(V11:V18) -> 445193.79 | W19: =SUM(W11:W18) -> 459692.06 | Y19: Impairment loss on financial assets | Z19: -613.94 | AA19: 1111.98 | AB19: -444.98 | AC19: 375.49 | AD19: 270.57 | AE19: 173.27 | AG19: Profit before exceptional items and tax | AH19: =AH8-AH18 -> 27057.779 | AI19: =AI8-AI18 -> 28171.517 | AJ19: =AJ8-AJ18 -> 54732.086 | AK19: =AK8-AK18 -> 51154.643 | AL19: =AL8-AL18 -> 70947.928 | AM19: =AM8-AM18 -> 51513.376 | AO19: Other expenses | AP19: 33347 | AQ19: 30970 | AR19: 42383 | AS19: 61981 | AT19: 59891 | AU19: 61384
A20: Exceptional items | B20: 1080.83 | C20: -6448.91 | D20: -1643.07 | E20: 1359.96 | F20: =1065.53-267.7 -> 797.83 | G20: =1322.74-378.41 -> 944.33 | I20: Share of profit/loss | J20: 2246.6 | K20: 1714.58 | L20: 1762.34 | M20: 1508.06 | N20: =1682.08+0 -> 1682.08 | O20: =1503.24+2440.03 -> 3943.27 | Q20: Profit/loss before share in profit of joint ventures | R20: =R9-R19 -> 2835.39 | S20: =S9-S19 -> 14058.34 | T20: =T9-T19 -> 7685.57 | U20: =U9-U19 -> -12475.43 | V20: =V9-V19 -> 18692.29 | W20: =W9-W19 -> 9119.47 | Y20: Net loss on de recognition of financial assets at amortised cost | Z20: 5.73 | AA20: 7.69 | AB20: 172.75 | AC20: 307.84 | AD20: 3.9 | AE20: 46.7 | AG20: Exceptional items | AH20: -9028.479 | AI20: 918.768 | AJ20: -2104.911 | AK20: -8137.942 | AL20: -1636.431 | AM20: -151.086 | AO20: Total expenses | AP20: =SUM(AP12:AP19) -> 320860 | AQ20: =SUM(AQ12:AQ19) -> 256979 | AR20: =SUM(AR12:AR19) -> 412442 | AS20: =SUM(AS12:AS19) -> 498887 | AT20: =SUM(AT12:AT19) -> 504797 | AU20: =SUM(AU12:AU19) -> 502758
A21: Profit before tax | B21: =B19-B20 -> 2671.04 | C21: =C19-C20 -> 22617.58 | D21: =D19-D20 -> 15671.74 | E21: =E19-E20 -> 2216.7 | F21: =F19-F20 -> 34598.93 | G21: =G19-G20 -> 16293.64 | I21: Profit/loss before tax | J21: =J19+J20 -> 10428.94 | K21: =K19+K20 -> 7725.45 | L21: =L19+L20 -> 15463.52 | M21: =M19+M20 -> 7255.84 | N21: =N19+N20 -> 12595.01 | O21: =O19+O20 -> 16095.51 | Q21: Share in profit/loss | R21: -458.17 | S21: 138.66 | T21: 1458.05 | U21: 2491.51 | V21: 1807.98 | W21: -119.59 | Y21: Other expenses | Z21: 43064.76 | AA21: 35477.3 | AB21: 43330.47 | AC21: 53379.46 | AD21: 50017.56 | AE21: 54229.94 | AG21: Share of profit of associates | AH21: 2355.957 | AI21: 1174.834 | AJ21: 809.519 | AK21: -319.234 | AL21: 3003.848 | AM21: 1081.166 | AO21: Profit before exceptional items and tax | AP21: =AP10-AP20 -> 44561 | AQ21: =AQ10-AQ20 -> 22908 | AR21: =AR10-AR20 -> 45396 | AS21: =AS10-AS20 -> 54133 | AT21: =AT10-AT20 -> 55273 | AU21: =AU10-AU20 -> 46128
A22: Tax expense | I22: Tax expense | Q22: Profit/loss before exceptional items and tax | R22: =R20+R21 -> 2377.22 | S22: =S20+S21 -> 14197 | T22: =T20+T21 -> 9143.62 | U22: =U20+U21 -> -9983.92 | V22: =V20+V21 -> 20500.27 | W22: =W20+W21 -> 8999.88 | Y22: Total expenses | Z22: =SUM(Z10:Z15,Z17:Z21) -> 576001.78 | AA22: =SUM(AA10:AA15,AA17:AA21) -> 494182.38 | AB22: =SUM(AB10:AB15,AB17:AB21) -> 706760 | AC22: =SUM(AC10:AC15,AC17:AC21) -> 941433.36 | AD22: =SUM(AD10:AD15,AD17:AD21) -> 829332.15 | AE22: =SUM(AE10:AE15,AE17:AE21) -> 849411.46 | AG22: Share of profit of Joint ventures | AH22: -1422.812 | AI22: -155.472 | AJ22: 654.408 | AK22: 353.285 | AL22: 1313.87 | AM22: -45.575 | AO22: Exceptional items | AP22: -4245 | AQ22: 4304 | AR22: 0 | AS22: 0 | AT22: 0 | AU22: 0
A23: Current tax | B23: 201 | C23: 5134.78 | D23: 2706.34 | E23: 352.18 | F23: 9419.98 | G23: 4470.93 | I23: Current tax | J23: 2116.2 | K23: 1591.88 | L23: 3333.25 | M23: 1355.89 | N23: 2683.02 | O23: 3464.8 | Q23: Exceptional items | R23: -1002.93 | S23: 0 | T23: 0 | U23: 0 | V23: 0 | W23: 0 | Y23: Profit/loss before share of profit | Z23: =Z8-Z22 -> 2761.54 | AA23: =AA8-AA22 -> 29554 | AB23: =AB8-AB22 -> 33053.06 | AC23: =AC8-AC22 -> 14175.5 | AD23: =AD8-AD22 -> 55741.86 | AE23: =AE8-AE22 -> 13465 | AG23: Profit before tax | AH23: =SUM(AH19:AH22) -> 18962.445 | AI23: =SUM(AI19:AI22) -> 30109.647 | AJ23: =SUM(AJ19:AJ22) -> 54091.102 | AK23: =SUM(AK19:AK22) -> 43050.752 | AL23: =SUM(AL19:AL22) -> 73629.215 | AM23: =SUM(AM19:AM22) -> 52397.881 | AO23: Profit before tax | AP23: =AP21+AP22 -> 40316 | AQ23: =AQ21+AQ22 -> 27212 | AR23: =AR21+AR22 -> 45396 | AS23: =AS21+AS22 -> 54133 | AT23: =AT21+AT22 -> 55273 | AU23: =AU21+AU22 -> 46128
A24: Deferred tax | B24: 400.68 | C24: -402.98 | D24: 643.99 | E24: 37.32 | F24: -84.39 | G24: 374.85 | I24: Earlier year | J24: 900.17 | K24: 6.32 | L24: -77.24 | M24: -52.01 | N24: -2.39 | O24: -4.53 | Q24: Profit/loss before tax | R24: =R22-R23 -> 3380.15 | S24: =S22-S23 -> 14197 | T24: =T22-T23 -> 9143.62 | U24: =U22-U23 -> -9983.92 | V24: =V22-V23 -> 20500.27 | W24: =W22-W23 -> 8999.88 | Y24: Share of profit/loss | Z24: 1366.09 | AA24: 1196.73 | AB24: 1235.56 | AC24: 862.19 | AD24: 1545.93 | AE24: 1760.43 | AG24: Tax expense | AO24: Tax expenses
A25: Tax provision for earlier years | B25: -613.83 | C25: -1155.89 | D25: 958.06 | E25: -42.9 | F25: 0.01 | G25: -0.03 | I25: Deferred tax | J25: -2102.07 | K25: -15.57 | L25: -96.12 | M25: 356.61 | N25: 11.57 | O25: 172.37 | Q25: Tax expense | Y25: Profit/loss before exceptional items and tax | Z25: =Z23+Z24 -> 4127.63 | AA25: =AA23+AA24 -> 30750.73 | AB25: =AB23+AB24 -> 34288.62 | AC25: =AC23+AC24 -> 15037.69 | AD25: =AD23+AD24 -> 57287.79 | AE25: =AE23+AE24 -> 15225.43 | AG25: Current tax | AH25: 9647.58 | AI25: 8081.523 | AJ25: 14017.279 | AK25: 14620.93 | AL25: 15230.188 | AM25: 15364.331 | AO25: Current tax | AP25: 7200 | AQ25: 0 | AR25: 544 | AS25: 6186 | AT25: 10922 | AU25: 9399
A26: Total tax expense | B26: =SUM(B23:B25) -> -12.15 | C26: =SUM(C23:C25) -> 3575.91 | D26: =SUM(D23:D25) -> 4308.39 | E26: =SUM(E23:E25) -> 346.6 | F26: =SUM(F23:F25) -> 9335.6 | G26: =SUM(G23:G25) -> 4845.75 | I26: Total tax expenses | J26: =J23+J24+J25 -> 914.3 | K26: =K23+K24+K25 -> 1582.63 | L26: =L23+L24+L25 -> 3159.89 | M26: =M23+M24+M25 -> 1660.49 | N26: =N23+N24+N25 -> 2692.2 | O26: =O23+O24+O25 -> 3632.64 | Q26: Current tax | R26: 166.95 | S26: 3569.56 | T26: 1510 | U26: 0 | V26: 814.36 | W26: 1770.92 | Y26: Exceptional items | Z26: -11304.64 | AA26: 0 | AB26: 0 | AC26: 0 | AD26: 0 | AE26: 1838.02 | AG26: Earlier year | AH26: -1805.422 | AI26: 982.03 | AJ26: -665.255 | AK26: -2891.432 | AL26: -391.723 | AM26: -124.899 | AO26: Deferred tax | AP26: 2213 | AQ26: -4732 | AR26: 6915 | AS26: 4930 | AT26: 2309 | AU26: 1467
A27: Profit for the period | B27: =B21-B26 -> 2683.19 | C27: =C21-C26 -> 19041.67 | D27: =D21-D26 -> 11363.35 | E27: =E21-E26 -> 1870.1 | F27: =F21-F26 -> 25263.33 | G27: =G21-G26 -> 11447.89 | I27: Profit for the year | J27: =J21-J26 -> 9514.64 | K27: =K21-K26 -> 6142.82 | L27: =L21-L26 -> 12303.63 | M27: =M21-M26 -> 5595.35 | N27: =N21-N26 -> 9902.81 | O27: =O21-O26 -> 12462.87 | Q27: Deferred tax | R27: 116.73 | S27: -52.08 | T27: 526.41 | U27: -2957.58 | V27: 3936.66 | W27: 597.42 | Y27: Profit/loss before tax | Z27: =Z25+Z26 -> -7177.01 | AA27: =AA25+AA26 -> 30750.73 | AB27: =AB25+AB26 -> 34288.62 | AC27: =AC25+AC26 -> 15037.69 | AD27: =AD25+AD26 -> 57287.79 | AE27: =AE25+AE26 -> 17063.45 | AG27: Deferred tax | AH27: -335.972 | AI27: -297.352 | AJ27: -8554.979 | AK27: -1456.351 | AL27: 3517.601 | AM27: -1170.161 | AO27: Total tax expense | AP27: =AP25+AP26 -> 9413 | AQ27: =AQ25+AQ26 -> -4732 | AR27: =AR25+AR26 -> 7459 | AS27: =AS25+AS26 -> 11116 | AT27: =AT25+AT26 -> 13231 | AU27: =AU25+AU26 -> 10866
Q28: Provision for earlier years | R28: -1548.12 | S28: 16.63 | T28: -187.02 | U28: -46.11 | V28: -265.36 | W28: -104.16 | Y28: Tax expense | AG28: Total tax expenses | AH28: =AH25+AH26+AH27 -> 7506.186 | AI28: =AI25+AI26+AI27 -> 8766.201 | AJ28: =AJ25+AJ26+AJ27 -> 4797.045 | AK28: =AK25+AK26+AK27 -> 10273.147 | AL28: =AL25+AL26+AL27 -> 18356.066 | AM28: =AM25+AM26+AM27 -> 14069.271 | AO28: Profit for the year | AP28: =AP23-AP27 -> 30903 | AQ28: =AQ23-AQ27 -> 31944 | AR28: =AR23-AR27 -> 37937 | AS28: =AS23-AS27 -> 43017 | AT28: =AT23-AT27 -> 42042 | AU28: =AU23-AU27 -> 35262
Q29: Total tax expenses | R29: =SUM(R26:R28) -> -1264.44 | S29: =SUM(S26:S28) -> 3534.11 | T29: =SUM(T26:T28) -> 1849.39 | U29: =SUM(U26:U28) -> -3003.69 | V29: =SUM(V26:V28) -> 4485.66 | W29: =SUM(W26:W28) -> 2264.18 | Y29: Current tax | Z29: 221.23 | AA29: 6868.47 | AB29: 7234.66 | AC29: 1922.46 | AD29: 12895.91 | AE29: 1700.08 | AG29: Profit for the year | AH29: =AH23-AH28 -> 11456.259 | AI29: =AI23-AI28 -> 21343.446 | AJ29: =AJ23-AJ28 -> 49294.057 | AK29: =AK23-AK28 -> 32777.605 | AL29: =AL23-AL28 -> 55273.149 | AM29: =AM23-AM28 -> 38328.61
Q30: Profit/Loss for the year | R30: =R24+R29 -> 2115.71 | S30: =S24-S29 -> 10662.89 | T30: =T24+T29 -> 10993.01 | U30: =U24-U29 -> -6980.23 | V30: =V24-V29 -> 16014.61 | W30: =W24-W29 -> 6735.7 | Y30: Deferred tax | Z30: -5521.92 | AA30: 2120.04 | AB30: 1327.36 | AC30: 1410.97 | AD30: 1230.73 | AE30: 1574.54
Y31: Total tax expense | Z31: =Z29+Z30 -> -5300.69 | AA31: =AA29+AA30 -> 8988.51 | AB31: =AB29+AB30 -> 8562.02 | AC31: =AC29+AC30 -> 3333.43 | AD31: =AD29+AD30 -> 14126.64 | AE31: =AE29+AE30 -> 3274.62
Y32: Profit/loss for the year | Z32: =Z27-Z31 -> -1876.32 | AA32: =AA27-AA31 -> 21762.22 | AB32: =AB27-AB31 -> 25726.6 | AC32: =AC27-AC31 -> 11704.26 | AD32: =AD27-AD31 -> 43161.15 | AE32: =AE27-AE31 -> 13788.83

Sheet Cash Flow Statement
A1: CASH FLOW STATEMENT
A3: #VALUE! | I3: #VALUE! | Q3: #VALUE! | Y3: #VALUE! | AG3: #VALUE! | AO3: #VALUE!
A4: Particulars | B4: 2020 | C4: 2021 | D4: 2022 | E4: 2023 | F4: 2024 | G4: 2025 | I4: Particulars | J4: 2020 | K4: 2021 | L4: 2022 | M4: 2023 | N4: 2024 | O4: 2025 | Q4: Particulars | R4: 2020 | S4: 2021 | T4: 2022 | U4: 2023 | V4: 2024 | W4: 2025 | Y4: Particulars | Z4: 2020 | AA4: 2021 | AB4: 2022 | AC4: 2023 | AD4: 2024 | AE4: 2025 | AG4: Particulars | AH4: 2020 | AI4: 2021 | AJ4: 2022 | AK4: 2023 | AL4: 2024 | AM4: 2025 | AO4: Particulars | AP4: 2020 | AQ4: 2021 | AR4: 2022 | AS4: 2023 | AT4: 2024 | AU4: 2025
A5: Net cash from/used in Operating Activities | B5: 6357.75 | C5: 20029.76 | D5: 20049.25 | E5: 10664.05 | F5: 35969.63 | G5: 23677.79 | I5: Net cash from/used in Operating Activities | J5: 8345.36 | K5: 8993.4 | L5: 9419.91 | M5: 3204.69 | N5: 12585.72 | O5: 15735.04 | Q5: Net cash from/used in Operating Activities | R5: 5469.24 | S5: 17829.26 | T5: 15810.23 | U5: -3466.31 | V5: 23851.87 | W5: 14227.74 | Y5: Net cash from/used in Operating Activities | Z5: 7146.25 | AA5: 49861.73 | AB5: 25746.67 | AC5: 29643.72 | AD5: 71146.41 | AE5: 34699.28 | AG5: Net cash from/used in Operating Activities | AH5: 70592.978 | AI5: 47201.393 | AJ5: 78248.246 | AK5: 84211.334 | AL5: 98846.605 | AM5: 90868.191 | AO5: Net cash from/used in Operating Activities | AP5: 77533 | AQ5: -512 | AR5: 67491 | AS5: 48050 | AT5: 73998 | AU5: 79392
A6: Capex | B6: -9460.25 | C6: -6063.48 | D6: -5355.16 | E6: -7376.83 | F6: -8838.62 | G6: -13342.56 | I6: Capex | J6: -9262.94 | K6: -5697.21 | L6: -6971.28 | M6: -8830.56 | N6: -12501.17 | O6: -7929.71 | Q6: Capex | R6: -13856.51 | S6: -11666 | T6: -12344.76 | U6: -9446.71 | V6: -10071.24 | W6: -9579.33 | Y6: Capex | Z6: -12337.43 | AA6: -6566.16 | AB6: -4944.71 | AC6: -5609.49 | AD6: -5005.85 | AE6: -5105.48 | AG6: Capex | AH6: -42258.429 | AI6: -32335.248 | AJ6: -33457.291 | AK6: -36792.453 | AL6: -38132.841 | AM6: -41030.802 | AO6: Capex | AP6: -21183 | AQ6: -21755 | AR6: -18154 | AS6: -28573 | AT6: -34258 | AU6: -37304
A7: Net cash from/used in Investing activities | B7: -9263.97 | C7: 2170.08 | D7: -7167.07 | E7: -6397.31 | F7: -10554.31 | G7: -19179.99 | I7: Net cash from/used in Investing activities | J7: -7444.64 | K7: -4693.04 | L7: -5436.04 | M7: -7640.12 | N7: -8273.42 | O7: -6737.79 | Q7: Net cash from/used in Investing activities | R7: -14167.89 | S7: -12278.59 | T7: -13744.84 | U7: -11383.55 | V7: -13019.23 | W7: -10556.61 | Y7: Net cash from/used in Investing activities | Z7: -29100.76 | AA7: -24244.89 | AB7: -21293.57 | AC7: -28029.56 | AD7: -31511.53 | AE7: -31848.19 | AG7: Net cash from/used in Investing activities | AH7: -53498.314 | AI7: -39089.771 | AJ7: -41329.623 | AK7: -73208.997 | AL7: -57485.019 | AM7: -43021.689 | AO7: Net cash from/used in Investing activities | AP7: -143625 | AQ7: 74257 | AR7: -45315 | AS7: -584 | AT7: -38292 | AU7: -28106
A8: Dividends Paid | B8: -4818.86 | C8: -4261.3 | D8: -14482.78 | E8: -1281.57 | F8: -5328.8 | G8: -6560.92 | I8: Dividends Paid | J8: -3960.56 | K8: -2238.06 | L8: -3995.37 | M8: -3069.25 | N8: -3620.53 | O8: -4275.44 | Q8: Dividends Paid | R8: -1725.11 | S8: -1484.41 | T8: -3222.89 | U8: -1985.71 | V8: -2130.51 | W8: -2336.26 | Y8: Dividends Paid | Z8: -5803.18 | AA8: -8383.19 | AB8: -10896.04 | AC8: -3305.68 | AD8: -10972.58 | AE8: -9545.1 | AG8: Dividends Paid | AH8: -8297.242 | AI8: -3096.294 | AJ8: -12923.827 | AK8: -17608.965 | AL8: -12894.901 | AM8: -16984.736 | AO8: Dividends Paid | AP8: -4584 | AQ8: -3921 | AR8: -4297 | AS8: -5083 | AT8: -6089 | AU8: -6766
A9: Net cash from/used in Financing activities | B9: 2940.22 | C9: -15622.27 | D9: -18697.08 | E9: -3665.87 | F9: -25247.3 | G9: -6240.61 | I9: Net cash from/used in Financing activities | J9: 281.22 | K9: -3470.62 | L9: -3916.71 | M9: 2972.06 | N9: -3457.39 | O9: -8940.85 | Q9: Net cash from/used in Financing activities | R9: 8451.96 | S9: -4709.19 | T9: -2066.24 | U9: 16025.17 | V9: -16155.04 | W9: -4138.24 | Y9: Net cash from/used in Financing activities | Z9: 22456.03 | AA9: -26270.21 | AB9: -4057.7 | AC9: -1794.4 | AD9: -39384.64 | AE9: -3424.51 | AG9: Net cash from/used in Financing activities | AH9: -16726.364 | AI9: -8257.811 | AJ9: -35790.015 | AK9: -12916.346 | AL9: -45009.25 | AM9: -47907.547 | AO9: Net cash from/used in Financing activities | AP9: 70767 | AQ9: -76657 | AR9: -6035 | AS9: -7369 | AT9: -27465 | AU9: -38063
A10: Net change in cash and cash equivalents | B10: 34 | C10: 6577.27 | D10: -5814.9 | E10: 600.87 | F10: -11.98 | G10: -1742.81 | I10: Net change in cash and cash equivalents | J10: 1181.94 | K10: 829.74 | L10: 67.16 | M10: -1463.37 | N10: 854.91 | O10: 56.4 | Q10: Net change in cash and cash equivalents | R10: -246.69 | S10: 841.48 | T10: -0.85 | U10: 1175.31 | V10: -5322.4 | W10: -467.11 | Y10: Net change in cash and cash equivalents | Z10: 501.52 | AA10: -653.37 | AB10: 395.4 | AC10: -180.24 | AD10: 250.24 | AE10: -573.42 | AG10: Net change in cash and cash equivalents | AH10: 368.3 | AI10: -146.189 | AJ10: 1128.608 | AK10: -1914.009 | AL10: -3647.664 | AM10: -61.045 | AO10: Net change in cash and cash equivalents | AP10: 4675 | AQ10: -2912 | AR10: 16141 | AS10: 40097 | AT10: 8241 | AU10: 13223

Sheet Financial Ratios
A1: FINANCIAL RATIOS
A3: #VALUE! | J3: #VALUE! | S3: #VALUE! | AB3: #VALUE! | AK3: #VALUE! | AT3: #VALUE!
A4: Category | B4: Ratio | C4: 2020 | D4: 2021 | E4: 2022 | F4: 2023 | G4: 2024 | H4: 2025 | J4: Category | K4: Ratio | L4: 2020 | M4: 2021 | N4: 2022 | O4: 2023 | P4: 2024 | Q4: 2025 | S4: Category | T4: Ratio | U4: 2020 | V4: 2021 | W4: 2022 | X4: 2023 | Y4: 2024 | Z4: 2025 | AB4: Category | AC4: Ratio | AD4: 2020 | AE4: 2021 | AF4: 2022 | AG4: 2023 | AH4: 2024 | AI4: 2025 | AK4: Category | AL4: Ratio | AM4: 2020 | AN4: 2021 | AO4: 2022 | AP4: 2023 | AQ4: 2024 | AR4: 2025 | AT4: Category | AU4: Ratio | AV4: 2020 | AW4: 2021 | AX4: 2022 | AY4: 2023 | AZ4: 2024 | BA4: 2025
A5: Liquidity | B5: Current Ratio | C5: ='Balance Sheet'!B31/'Balance Sheet'!B56 -> 0.70229318 | D5: ='Balance Sheet'!C31/'Balance Sheet'!C56 -> 0.90244502 | E5: ='Balance Sheet'!D31/'Balance Sheet'!D56 -> 0.74636454 | F5: ='Balance Sheet'!E31/'Balance Sheet'!E56 -> 0.74851615 | G5: ='Balance Sheet'!F31/'Balance Sheet'!F56 -> 0.81220777 | H5: ='Balance Sheet'!G31/'Balance Sheet'!G56 -> 0.80324929 | J5: Liquidity | K5: Current Ratio | L5: ='Balance Sheet'!J28/'Balance Sheet'!J56 -> 0.93433391 | M5: ='Balance Sheet'!K28/'Balance Sheet'!K56 -> 0.86575401 | N5: ='Balance Sheet'!L28/'Balance Sheet'!L56 -> 1.080421 | O5: ='Balance Sheet'!M28/'Balance Sheet'!M56 -> 0.94563452 | P5: ='Balance Sheet'!N28/'Balance Sheet'!N56 -> 0.93675158 | Q5: ='Balance Sheet'!O28/'Balance Sheet'!O56 -> 0.98183475 | S5: Liquidity | T5: Current Ratio | U5: ='Balance Sheet'!R26/'Balance Sheet'!R51 -> 0.65943989 | V5: ='Balance Sheet'!S26/'Balance Sheet'!S51 -> 0.70802896 | W5: ='Balance Sheet'!T26/'Balance Sheet'!T51 -> 0.69555463 | X5: ='Balance Sheet'!U26/'Balance Sheet'!U51 -> 0.59534949 | Y5: ='Balance Sheet'!V26/'Balance Sheet'!V51 -> 0.61198478 | Z5: ='Balance Sheet'!W26/'Balance Sheet'!W51 -> 0.59935819 | AB5: Liquidity | AC5: Current Ratio | AD5: ='Balance Sheet'!Z30/'Balance Sheet'!Z56 -> 0.68559163 | AE5: ='Balance Sheet'!AA30/'Balance Sheet'!AA56 -> 0.71656401 | AF5: ='Balance Sheet'!AB30/'Balance Sheet'!AB56 -> 0.76156931 | AG5: ='Balance Sheet'!AC30/'Balance Sheet'!AC56 -> 0.76877614 | AH5: ='Balance Sheet'!AD30/'Balance Sheet'!AD56 -> 0.73222498 | AI5: ='Balance Sheet'!AE30/'Balance Sheet'!AE56 -> 0.68362333 | AK5: Liquidity | AL5: Current Ratio | AM5: ='Balance Sheet'!AH46/'Balance Sheet'!AH73 -> 0.60272676 | AN5: ='Balance Sheet'!AI46/'Balance Sheet'!AI73 -> 0.71201698 | AO5: ='Balance Sheet'!AJ46/'Balance Sheet'!AJ73 -> 0.78999688 | AP5: ='Balance Sheet'!AK46/'Balance Sheet'!AK73 -> 0.82393199 | AQ5: ='Balance Sheet'!AL46/'Balance Sheet'!AL73 -> 0.79623587 | AR5: ='Balance Sheet'!AM46/'Balance Sheet'!AM73 -> 0.78843478 | AT5: Liquidity | AU5: Current Ratio | AV5: ='Balance Sheet'!AP23/'Balance Sheet'!AP48 -> 0.50397058 | AW5: ='Balance Sheet'!AQ23/'Balance Sheet'!AQ48 -> 1.0442645 | AX5: ='Balance Sheet'!AR23/'Balance Sheet'!AR48 -> 0.99851728 | AY5: ='Balance Sheet'!AS23/'Balance Sheet'!AS48 -> 0.88134072 | AZ5: ='Balance Sheet'!AT23/'Balance Sheet'!AT48 -> 1.094207 | BA5: ='Balance Sheet'!AU23/'Balance Sheet'!AU48 -> 1.0450811
A6: Liquidity | B6: Quick Ratio | C6: =('Balance Sheet'!B31-'Balance Sheet'!B21)/'Balance Sheet'!B56 -> 0.35303738 | D6: =('Balance Sheet'!C31-'Balance Sheet'!C21)/'Balance Sheet'!C56 -> 0.43962378 | E6: =('Balance Sheet'!D31-'Balance Sheet'!D21)/'Balance Sheet'!D56 -> 0.23860582 | F6: =('Balance Sheet'!E31-'Balance Sheet'!E21)/'Balance Sheet'!E56 -> 0.24005328 | G6: =('Balance Sheet'!F31-'Balance Sheet'!F21)/'Balance Sheet'!F56 -> 0.28260416 | H6: =('Balance Sheet'!G31-'Balance Sheet'!G21)/'Balance Sheet'!G56 -> 0.30403024 | J6: Liquidity | K6: Quick Ratio | L6: =('Balance Sheet'!J28-'Balance Sheet'!J20)/'Balance Sheet'!J56 -> 0.67920633 | M6: =('Balance Sheet'!K28-'Balance Sheet'!K20)/'Balance Sheet'!K56 -> 0.62757273 | N6: =('Balance Sheet'!L28-'Balance Sheet'!L20)/'Balance Sheet'!L56 -> 0.84345469 | O6: =('Balance Sheet'!M28-'Balance Sheet'!M20)/'Balance Sheet'!M56 -> 0.67305774 | P6: =('Balance Sheet'!N28-'Balance Sheet'!N20)/'Balance Sheet'!N56 -> 0.66088046 | Q6: =('Balance Sheet'!O28-'Balance Sheet'!O20)/'Balance Sheet'!O56 -> 0.69644389 | S6: Liquidity | T6: Quick Ratio | U6: =('Balance Sheet'!R26-'Balance Sheet'!R17)/'Balance Sheet'!R51 -> 0.32067301 | V6: =('Balance Sheet'!S26-'Balance Sheet'!S17)/'Balance Sheet'!S51 -> 0.24692367 | W6: =('Balance Sheet'!T26-'Balance Sheet'!T17)/'Balance Sheet'!T51 -> 0.1984299 | X6: =('Balance Sheet'!U26-'Balance Sheet'!U17)/'Balance Sheet'!U51 -> 0.19496171 | Y6: =('Balance Sheet'!V26-'Balance Sheet'!V17)/'Balance Sheet'!V51 -> 0.21571757 | Z6: =('Balance Sheet'!W26-'Balance Sheet'!W17)/'Balance Sheet'!W51 -> 0.20128821 | AB6: Liquidity | AC6: Quick Ratio | AD6: =('Balance Sheet'!Z30-'Balance Sheet'!Z20)/'Balance Sheet'!Z56 -> 0.27071016 | AE6: =('Balance Sheet'!AA30-'Balance Sheet'!AA20)/'Balance Sheet'!AA56 -> 0.20213505 | AF6: =('Balance Sheet'!AB30-'Balance Sheet'!AB20)/'Balance Sheet'!AB56 -> 0.18214198 | AG6: =('Balance Sheet'!AC30-'Balance Sheet'!AC20)/'Balance Sheet'!AC56 -> 0.18271671 | AH6: =('Balance Sheet'!AD30-'Balance Sheet'!AD20)/'Balance Sheet'!AD56 -> 0.17130006 | AI6: =('Balance Sheet'!AE30-'Balance Sheet'!AE20)/'Balance Sheet'!AE56 -> 0.18978651 | AK6: Liquidity | AL6: Quick Ratio | AM6: =('Balance Sheet'!AH46-'Balance Sheet'!AH36)/'Balance Sheet'!AH73 -> 0.33847057 | AN6: =('Balance Sheet'!AI46-'Balance Sheet'!AI36)/'Balance Sheet'!AI73 -> 0.35041053 | AO6: =('Balance Sheet'!AJ46-'Balance Sheet'!AJ36)/'Balance Sheet'!AJ73 -> 0.36473879 | AP6: =('Balance Sheet'!AK46-'Balance Sheet'!AK36)/'Balance Sheet'!AK73 -> 0.48947968 | AQ6: =('Balance Sheet'!AL46-'Balance Sheet'!AL36)/'Balance Sheet'!AL73 -> 0.47858851 | AR6: =('Balance Sheet'!AM46-'Balance Sheet'!AM36)/'Balance Sheet'!AM73 -> 0.43506855 | AT6: Liquidity | AU6: Quick Ratio | AV6: =('Balance Sheet'!AP23-'Balance Sheet'!AP17)/'Balance Sheet'!AP48 -> 0.38663127 | AW6: =('Balance Sheet'!AQ23-'Balance Sheet'!AQ17)/'Balance Sheet'!AQ48 -> 0.85873718 | AX6: =('Balance Sheet'!AR23-'Balance Sheet'!AR17)/'Balance Sheet'!AR48 -> 0.77002418 | AY6: =('Balance Sheet'!AS23-'Balance Sheet'!AS17)/'Balance Sheet'!AS48 -> 0.67514203 | AZ6: =('Balance Sheet'!AT23-'Balance Sheet'!AT17)/'Balance Sheet'!AT48 -> 0.73964435 | BA6: =('Balance Sheet'!AU23-'Balance Sheet'!AU17)/'Balance Sheet'!AU48 -> 0.69919553
