Workbook

Sheet Company Profile
A1: Particulars | B1: #VALUE! | C1: #VALUE! | D1: #VALUE! | E1: #VALUE! | F1: #VALUE! | G1: #VALUE!
A2: Company | B2: #VALUE! | C2: #VALUE! | D2: #VALUE! | E2: #VALUE! | F2: #VALUE! | G2: #VALUE!
A3: Official Name | B3: {=_FV(B2,"Official name",TRUE)} -> AVENUE SUPERMARTS LIMITED | C3: {=_FV(C2,"Official name",TRUE)} -> ITC LIMITED | D3: {=_FV(D2,"Official name",TRUE)} -> TRENT LIMITED | E3: {=_FV(E2,"Official name",TRUE)} -> VARUN BEVERAGES LIMITED | F3: {=_FV(F2,"Official name",TRUE)} -> TITAN COMPANY LIMITED | G3: {=_FV(G2,"Official name",TRUE)} -> HINDUSTAN UNILEVER LIMITED
A4: Ticker Symbol | B4: {=_FV(B2,"Ticker symbol",TRUE)} -> DMART | C4: {=_FV(C2,"Ticker symbol",TRUE)} -> ITC | D4: {=_FV(D2,"Ticker symbol",TRUE)} -> TRENT | E4: {=_FV(E2,"Ticker symbol",TRUE)} -> VBL | F4: {=_FV(F2,"Ticker symbol",TRUE)} -> TITAN | G4: {=_FV(G2,"Ticker symbol",TRUE)} -> HINDUNILVR
A5: Industry | B5: {=_FV(B2,"Industry")} -> Food & Drug Retailing | C5: {=_FV(C2,"Industry")} -> Food & Tobacco | D5: {=_FV(D2,"Industry")} -> Diversified Retail | E5: {=_FV(E2,"Industry")} -> Beverages | F5: {=_FV(F2,"Industry")} -> Textiles & Apparel | G5: {=_FV(G2,"Industry")} -> Personal & Household Products & Services
A6: Year of Corporation | B6: {=_FV(B2,"Year incorporated",TRUE)} -> 2000 | C6: {=_FV(C2,"Year incorporated",TRUE)} -> 1910 | D6: {=_FV(D2,"Year incorporated",TRUE)} -> 1952 | E6: {=_FV(E2,"Year incorporated",TRUE)} -> 1995 | F6: {=_FV(F2,"Year incorporated",TRUE)} -> 1984 | G6: {=_FV(G2,"Year incorporated",TRUE)} -> 1933
A7: Employees count | B7: {=_FV(B2,"Employees")} -> 16959 | C7: {=_FV(C2,"Employees")} -> 22041 | D7: {=_FV(D2,"Employees")} -> 27887 | E7: {=_FV(E2,"Employees")} -> 11041 | F7: {=_FV(F2,"Employees")} -> 9191 | G7: {=_FV(G2,"Employees")} -> 18802
A8: Shares outstanding | B8: {=_FV(B2,"Shares outstanding",TRUE)} -> 650733100 | C8: {=_FV(C2,"Shares outstanding",TRUE)} -> 12527840000 | D8: {=_FV(D2,"Shares outstanding",TRUE)} -> 355487500 | E8: {=_FV(E2,"Shares outstanding",TRUE)} -> 3381989000 | F8: {=_FV(F2,"Shares outstanding",TRUE)} -> 887045300 | G8: {=_FV(G2,"Shares outstanding",TRUE)} -> 2349591000
B9: =B8/10000000 -> 65.07331 | C9: =C8/10000000 -> 1252.784 | D9: =D8/10000000 -> 35.54875 | E9: =E8/10000000 -> 338.1989 | F9: =F8/10000000 -> 88.70453 | G9: =G8/10000000 -> 234.9591
A10: Share Price | B10: {=_FV(B2,"Price")} -> 4019 | C10: {=_FV(C2,"Price")} -> 405.55 | D10: {=_FV(D2,"Price")} -> 4283.7 | E10: {=_FV(E2,"Price")} -> 463.25 | F10: {=_FV(F2,"Price")} -> 3803 | G10: {=_FV(G2,"Price")} -> 2408.8
A11: Market Cap | B11: {=_FV(B2,"Market cap",TRUE)} -> 2610090000000 | C11: {=_FV(C2,"Market cap",TRUE)} -> 5061873000000 | D11: {=_FV(D2,"Market cap",TRUE)} -> 1644947000000 | E11: {=_FV(E2,"Market cap",TRUE)} -> 1590211000000 | F11: {=_FV(F2,"Market cap",TRUE)} -> 3343540000000 | G11: {=_FV(G2,"Market cap",TRUE)} -> 5671914000000
B12: =B11/10000000 -> 261009 | C12: =C11/10000000 -> 506187.3 | D12: =D11/10000000 -> 164494.7 | E12: =E11/10000000 -> 159021.1 | F12: =F11/10000000 -> 334354 | G12: =G11/10000000 -> 567191.4
A13: Change (%) | B13: {=_FV(B2,"Change (%)",TRUE)} -> 0.001995 | C13: {=_FV(C2,"Change (%)",TRUE)} -> 0.003712 | D13: {=_FV(D2,"Change (%)",TRUE)} -> -0.074255 | E13: {=_FV(E2,"Change (%)",TRUE)} -> -0.014781 | F13: {=_FV(F2,"Change (%)",TRUE)} -> 0.008941 | G13: {=_FV(G2,"Change (%)",TRUE)} -> -0.002154
A14: Beta | B14: {=_FV(B2,"Beta")} -> 1.4373 | C14: {=_FV(C2,"Beta")} -> 0.7767 | D14: {=_FV(D2,"Beta")} -> 1.4651 | E14: {=_FV(E2,"Beta")} -> 0.9261 | F14: {=_FV(F2,"Beta")} -> 1.3028 | G14: {=_FV(G2,"Beta")} -> 0.8014

Sheet Balance Sheet
G1: #VALUE! | N1: #VALUE! | V1: #VALUE! | AD1: #VALUE! | AL1: #VALUE! | AS1: #VALUE!
A2: Particulars | B2: 2020 | C2: 2021 | D2: 2022 | E2: 2023 | F2: 2024 | G2: 2025 | I2: Particulars | J2: 2020 | K2: 2021 | L2: 2022 | M2: 2023 | N2: 2024 | P2: Particulars | Q2: 2020 | R2: 2021 | S2: 2022 | T2: 2023 | U2: 2024 | V2: 2025 | X2: Particulars | Y2: 2020 | Z2: 2021 | AA2: 2022 | AB2: 2023 | AC2: 2024 | AD2: 2025 | AF2: Particulars | AG2: 2020 | AH2: 2021 | AI2: 2022 | AJ2: 2023 | AK2: 2024 | AL2: 2025 | AN2: Particulars | AO2: 2020 | AP2: 2021 | AQ2: 2022 | AR2: 2023 | AS2: 2024
A3: Assets | I3: Assets | P3: Assets | X3: Assets | AF3: Assets | AN3: Assets
A4: Non-current Assets | I4: Non-current assets | P4: Non-current Assets | X4: Non-current Assets | AF4: Non-current Assets | AN4: Non-current Assets
A5: Property, plant and equipment | B5: 5107.36 | C5: 5938.5 | D5: 7770.46 | E5: 9725.61 | F5: 11759.19 | G5: 14349.83 | I5: Property, plant and equipment | J5: 4192 | K5: 4960 | L5: 6116 | M5: 6169 | N5: 8031 | P5: Property, plant and equipment | Q5: 19632.92 | R5: 19153.94 | S5: 20207.43 | T5: 21117.06 | U5: 23082.33 | V5: 17428.89 | X5: Property, plant and equipment | Y5: 1285 | Z5: 1216 | AA5: 1218 | AB5: 1343 | AC5: 1737 | AD5: 1854 | AF5: Property, plant and equipment | AG5: 654.64 | AH5: 640.45 | AI5: 724.94 | AJ5: 871.18 | AK5: 1146.32 | AL5: 2068.24 | AN5: Property, plant and equipment | AO5: 5827.188 | AP5: 5155.172 | AQ5: 5441.578 | AR5: 6803.132 | AS5: 10622.551
A6: Capital work in progress | B6: 364.4 | C6: 1019.59 | D6: 1129.34 | E6: 829.16 | F6: 935.22 | G6: 1099.35 | I6: Capital work in progress | J6: 406 | K6: 597 | L6: 745 | M6: 1313 | N6: 1025 | P6: Capital work in progress | Q6: 3251.61 | R6: 4004.45 | S6: 3198.45 | T6: 2984.71 | U6: 2851.14 | V6: 1087.6 | X6: Capital work in progress | Y6: 11 | Z6: 19 | AA6: 69 | AB6: 133 | AC6: 88 | AD6: 93 | AF6: Capital work in progress | AG6: 23.32 | AH6: 107.98 | AI6: 104.72 | AJ6: 101.72 | AK6: 223.78 | AL6: 179.5 | AN6: Capital work in progress | AO6: 66.815 | AP6: 496.608 | AQ6: 606.632 | AR6: 1922.222 | AS6: 1162.343
A7: Right of use assets | B7: 717.33 | C7: 960.24 | D7: 1388.65 | E7: 1504.88 | F7: 1539.1 | G7: 1741.73 | I7: Goodwill | J7: 36 | K7: 36 | L7: 17316 | M7: 17316 | N7: 17466 | P7: Investment property | Q7: 385.36 | R7: 376.56 | S7: 364.2 | T7: 352.26 | U7: 340.93 | V7: 322.4 | X7: Right of use assets | Y7: 935 | Z7: 917 | AA7: 973 | AB7: 1285 | AC7: 1543 | AD7: 1774 | AF7: Investment property | AG7: 28.76 | AH7: 28.11 | AI7: 27.84 | AJ7: 27.13 | AK7: 26.91 | AL7: 26.86 | AN7: Right of use assets | AO7: 0 | AP7: 572.799 | AQ7: 915.501 | AR7: 1034.707 | AS7: 1363.122
A8: Investment Properties | B8: 16.53 | C8: 9.57 | D8: 9.03 | E8: 8.54 | F8: 8.09 | G8: 7.65 | I8: Other intangible assets | J8: 406 | K8: 402 | L8: 27930 | M8: 27907 | N8: 28247 | P8: Goodwill | Q8: 202.53 | R8: 779.73 | S8: 779.73 | T8: 779.73 | U8: 779.73 | V8: 896.93 | X8: Investment property | Y8: 24 | Z8: 24 | AA8: 1 | AB8: 1 | AC8: 1 | AD8: 1 | AF8: Goodwill on consolidation | AG8: 27.19 | AH8: 27.19 | AI8: 27.19 | AJ8: 27.19 | AK8: 27.19 | AL8: 27.19 | AN8: Goodwill | AO8: 24.23 | AP8: 24.23 | AQ8: 24.23 | AR8: 24.23 | AS8: 300.937
A9: Goodwill | B9: 78.27 | C9: 78.27 | D9: 78.27 | E9: 78.27 | F9: 78.27 | G9: 78.27 | I9: Goodwill on consideration | J9: 81 | K9: 81 | L9: 81 | M9: 81 | N9: 65 | P9: Other tangible assets | Q9: 525.37 | R9: 2011.06 | S9: 2013.1 | T9: 2727.32 | U9: 2678.11 | V9: 2724.74 | X9: Goodwill | Y9: 123 | Z9: 123 | AA9: 123 | AB9: 123 | AC9: 123 | AD9: 123 | AF9: Other intangible assets | AG9: 42.27 | AH9: 39.58 | AI9: 42.53 | AJ9: 51.21 | AK9: 47.37 | AL9: 46.09 | AN9: Other intangible assets | AO9: 557.201 | AP9: 558.574 | AQ9: 550.91 | AR9: 547.1 | AS9: 1115.126
A10: Intangible assets | B10: 28.54 | C10: 22.22 | D10: 13.61 | E10: 23.18 | F10: 30.35 | G10: 28.98 | I10: Financial assets | P10: Intangible assets under development | Q10: 4.85 | R10: 6.84 | S10: 27.09 | T10: 18.59 | U10: 9.64 | V10: 3.31 | X10: Other intangible assets | Y10: 266 | Z10: 243 | AA10: 229 | AB10: 246 | AC10: 305 | AD10: 310 | AF10: Right of use assets | AG10: 1985.57 | AH10: 2318.49 | AI10: 3864.21 | AJ10: 3550.24 | AK10: 1202.13 | AL10: 1726.75 | AN10: Intangible assets under development | AO10: 0 | AP10: 0 | AQ10: 0 | AR10: 0 | AS10: 4.369
A11: Financial Assets | I11: Investments | J11: 2 | K11: 2 | L11: 2 | M11: 2 | N11: 2 | P11: Right of use assets | Q11: 967.16 | R11: 977.19 | S11: 867.13 | T11: 874.88 | U11: 939.12 | V11: 581.89 | X11: Intangible assets under development | Y11: 7 | Z11: 13 | AA11: 16 | AB11: 11 | AC11: 9 | AD11: 12 | AF11: Investments | AG11: 735.91 | AH11: 816.63 | AI11: 757.39 | AJ11: 564.13 | AK11: 696.26 | AL11: 845.56 | AN11: Investment in associate | AO11: 0 | AP11: 0 | AQ11: 0.004 | AR11: 17.932 | AS11: 53.447
A12: Other non-current financial assets | B12: 3122.67 | C12: 1109.28 | D12: 1262.7 | E12: 108.55 | F12: 0.01 | G12: 2.01 | I12: Loans | J12: 215 | K12: 238 | L12: 111 | M12: 115 | N12: 102 | P12: Investment accounted for using the equity method | Q12: 266.16 | R12: 262.55 | S12: 269.24 | T12: 337.59 | U12: 549.73 | V12: 4711.78 | X12: Investments | Y12: 44 | Z12: 19 | AA12: 279 | AB12: 351 | AC12: 679 | AD12: 651 | AF12: Loan considered good-unsecured | AG12: 2.34 | AH12: 2.35 | AI12: 2.13 | AJ12: 1.86 | AK12: 1.66 | AL12: 1.35 | AN12: Investments | AO12: 0.001 | AP12: 0.001 | AQ12: 0.001 | AR12: 3.151 | AS12: 6.055
A13: Investments | D13: 0.01 | E13: 0.01 | F13: 234.76 | G13: 168.12 | I13: Other financial assets | J13: 11 | K13: 3 | L13: 757 | M13: 729 | N13: 760 | P13: Financial Assets | X13: Loans receivables | Y13: 154 | Z13: 158 | AA13: 42 | AB13: 54 | AC13: 72 | AD13: 62 | AF13: Others | AG13: 76.07 | AH13: 72.28 | AI13: 94.75 | AJ13: 136.71 | AK13: 447.7 | AL13: 616.75 | AN13: Loans | AO13: 41.789 | AP13: 0 | AQ13: 0 | AR13: 0 | AS13: 21.887
A14: Income tax assets (net) | B14: 8.25 | C14: 1.63 | D14: 2.28 | E14: 17.5 | F14: 17.56 | G14: 18.19 | I14: Non-current tax assets (net) | J14: 835 | K14: 1083 | L14: 17 | M14: 11 | N14: 10 | P14: Investments | Q14: 10448.46 | R14: 9761.99 | S14: 12307.49 | T14: 11844.57 | U14: 17619.87 | V14: 13720.54 | X14: Other financial assets | Y14: 199 | Z14: 211 | AA14: 382 | AB14: 595 | AC14: 788 | AD14: 868 | AF14: Deferred tax assets (net) | AG14: 110.4 | AH14: 114.52 | AI14: 126.35 | AJ14: 156.05 | AK14: 54.43 | AL14: 43.47 | AN14: Others | AO14: 0.121 | AP14: 42.06 | AQ14: 48.68 | AR14: 62.267 | AS14: 98.726
A15: Deferred tax assets (net) | B15: 0.29 | C15: 0.92 | D15: 1.66 | E15: 1.77 | F15: 4.72 | G15: 7.51 | I15: Deferred tax assets (net) | J15: 373 | K15: 284 | L15: 1246 | M15: 1158 | N15: 1175 | P15: Loans | Q15: 5.27 | R15: 4.07 | S15: 6.61 | T15: 5.48 | U15: 4.05 | V15: 7.6 | X15: Deferred tax assets (net) | Y15: 159 | Z15: 105 | AA15: 187 | AB15: 158 | AC15: 187 | AD15: 170 | AF15: Other non-current assets | AG15: 116.75 | AH15: 152.8 | AI15: 170.51 | AJ15: 216.33 | AK15: 178.15 | AL15: 164.43 | AN15: Deferred tax assets (net) | AO15: 11.018 | AP15: 2.41 | AQ15: 0 | AR15: 0 | AS15: 19.631
A16: Other non-current assets | B16: 285.14 | C16: 454.62 | D16: 373.78 | E16: 360.73 | F16: 367.9 | G16: 426.45 | I16: Other non-current assets | J16: 158 | K16: 146 | L16: 219 | M16: 194 | N16: 292 | P16: Others | Q16: 615.65 | R16: 101.87 | S16: 1589.58 | T16: 3739.75 | U16: 408.99 | V16: 1557.57 | X16: Income tax assets (net) | Y16: 144 | Z16: 121 | AA16: 137 | AB16: 151 | AC16: 213 | AD16: 104 | AF16: Total non-current assets | AG16: =SUM(AG5:AG15) -> 3803.22 | AH16: =SUM(AH5:AH15) -> 4320.38 | AI16: =SUM(AI5:AI15) -> 5942.56 | AJ16: =SUM(AJ5:AJ15) -> 5703.75 | AK16: =SUM(AK5:AK15) -> 4051.9 | AL16: =SUM(AL5:AL15) -> 5746.19 | AN16: Other non current assets | AO16: 130.344 | AP16: 183.923 | AQ16: 626.677 | AR16: 536.812 | AS16: 511.742
A17: Total non-current Assets | B17: =SUM(B5:B10,B12:B16) -> 9728.78 | C17: =SUM(C5:C10,C12:C16) -> 9594.84 | D17: =SUM(D5:D10,D12:D16) -> 12029.79 | E17: =SUM(E5:E10,E12:E16) -> 12658.2 | F17: =SUM(F5:F10,F12:F16) -> 14975.17 | G17: =SUM(G5:G10,G12:G16) -> 17928.09 | I17: Total non-current assets | J17: =SUM(J5:J16) -> 6715 | K17: =SUM(K5:K16) -> 7832 | L17: =SUM(L5:L16) -> 54540 | M17: =SUM(M5:M16) -> 54995 | N17: =SUM(N5:N16) -> 57175 | P17: Deferred tax assets (net) | Q17: 56.29 | R17: 58.54 | S17: 63.53 | T17: 52.02 | U17: 72.19 | V17: 87.98 | X17: Other non-current assets | Y17: 78 | Z17: 86 | AA17: 84 | AB17: 165 | AC17: 197 | AD17: 191 | AF17: Current Assets | AN17: Total non-current assets | AO17: =SUM(AO5:AO16) -> 6658.707 | AP17: =SUM(AP5:AP16) -> 7035.777 | AQ17: =SUM(AQ5:AQ16) -> 8214.213 | AR17: =SUM(AR5:AR16) -> 10951.553 | AS17: =SUM(AS5:AS16) -> 15279.936
A18: Current Assets | I18: Current Assets | P18: Income tax assets (net) | Q18: 38.42 | R18: 33.04 | S18: 42.3 | T18: 66.16 | U18: 44.93 | V18: 50.24 | X18: Total non-current assets | Y18: =SUM(Y5:Y17) -> 3429 | Z18: =SUM(Z5:Z17) -> 3255 | AA18: =SUM(AA5:AA17) -> 3740 | AB18: =SUM(AB5:AB17) -> 4616 | AC18: =SUM(AC5:AC17) -> 5942 | AD18: =SUM(AD5:AD17) -> 6213 | AF18: Inventories | AG18: 607.81 | AH18: 428.39 | AI18: 867.78 | AJ18: 1361.16 | AK18: 1582.73 | AL18: 2045.05 | AN18: Current Assets
A19: Inventories | B19: 1947.4 | C19: 2248.28 | D19: 2742.66 | E19: 3243.48 | F19: 3927.31 | G19: 5044.37 | I19: Inventories | J19: 2574 | K19: 2767 | L19: 3579 | M19: 4096 | N19: 4022 | P19: Other non-current assets | Q19: 1461.24 | R19: 1295.48 | S19: 1291.22 | T19: 1311.95 | U19: 1379.86 | V19: 1015.93 | X19: Current Assets | AF19: Investments | AG19: 778.87 | AH19: 670.66 | AI19: 526.33 | AJ19: 545.74 | AK19: 719.77 | AL19: 634.69 | AN19: Inventories | AO19: 928.804 | AP19: 1448.087 | AQ19: 1993.885 | AR19: 2150.533 | AS19: 2791.234
A20: Financial Assets | I20: Investments | J20: 2714 | K20: 1253 | L20: 2707 | M20: 3519 | N20: 4558 | P20: Total non-current assets | Q20: =SUM(Q5:Q19) -> 37861.29 | R20: =SUM(R5:R19) -> 38827.31 | S20: =SUM(S5:S19) -> 43027.1 | T20: =SUM(T5:T19) -> 46212.07 | U20: =SUM(U5:U19) -> 50760.62 | V20: =SUM(V5:V19) -> 44197.4 | X20: Inventories | Y20: 8103 | Z20: 8408 | AA20: 13609 | AB20: 16584 | AC20: 19051 | AD20: 28184 | AF20: Trade receivables considered good-unsecured | AG20: 17.12 | AH20: 20.77 | AI20: 18.26 | AJ20: 34.39 | AK20: 81.74 | AL20: 62.95 | AN20: Trade receivables | AO20: 241.797 | AP20: 221.249 | AQ20: 299.338 | AR20: 359.385 | AS20: 845.842
A21: Investments | B21: 14.68 | C21: 2.95 | D21: 5.93 | E21: 202.19 | F21: 106.66 | G21: 1.25 | I21: Loans | J21: 4 | K21: 0 | L21: 34 | M21: 35 | N21: 38 | P21: Current Assets | X21: Investments | Y21: 114 | Z21: 2805 | AA21: 15 | AB21: 2164 | AC21: 1666 | AD21: 1337 | AF21: Credit impaired | AG21: 0 | AH21: 0 | AI21: 0 | AJ21: 0 | AK21: 0 | AL21: 0 | AN21: Cash and cash equivalents | AO21: 104.558 | AP21: 150.75 | AQ21: 154.332 | AR21: 242.212 | AS21: 2266.283
A22: Trade receivables | B22: 19.55 | C22: 43.58 | D22: 66.89 | E22: 62.16 | F22: 166.37 | G22: 153.79 | I22: Trade receivables | J22: 1816 | K22: 1149 | L22: 1758 | M22: 2236 | N22: 2997 | P22: Inventories | Q22: 8879.33 | R22: 10397.16 | S22: 10864.15 | T22: 11771.16 | U22: 14152.88 | V22: 15637.56 | X22: Trade receivables | Y22: 312 | Z22: 366 | AA22: 565 | AB22: 674 | AC22: 1018 | AD22: 1068 | AF22: Cash and cash equivalents | AG22: 56 | AH22: 75.63 | AI22: 82.39 | AJ22: 83.23 | AK22: 294.55 | AL22: 338.47 | AN22: Bank balances | AO22: 85.492 | AP22: 185.872 | AQ22: 130.935 | AR22: 217.65 | AS22: 183.771
A23: Cash and cash equivalents | B23: 105.87 | C23: 191.5 | D23: 95.12 | E23: 207.15 | F23: 337.12 | G23: 355.48 | I23: Cash and cash equivalents | J23: 621 | K23: 3216 | L23: 1842 | M23: 1147 | N23: 825 | P23: Biological assets other than bearer plants | Q23: 86.2 | R23: 110.06 | S23: 109.44 | T23: 142.97 | U23: 150 | V23: 198.58 | X23: Cash and cash equivalents | Y23: 75 | Z23: 181 | AA23: 219 | AB23: 232 | AC23: 409 | AD23: 407 | AF23: Bank balances | AG23: 5.41 | AH23: 5.84 | AI23: 3.58 | AJ23: 3.07 | AK23: 3.01 | AL23: 1.37 | AN23: Loans | AO23: 10.016 | AP23: 0 | AQ23: 0 | AR23: 0 | AS23: 0
A24: Bank balances other cash & cash equiv. | B24: 2.01 | C24: 1254.08 | D24: 203.46 | E24: 1201.18 | F24: 301.06 | G24: 2.72 | I24: Bank balances other than cash and cash equivalents | J24: 3136 | K24: 1897 | L24: 2629 | M24: 2699 | N24: 6734 | P24: Financial Assets | X24: Balances other than above | Y24: 306 | Z24: 379 | AA24: 1354 | AB24: 1111 | AC24: 1117 | AD24: 1177 | AF24: Loans receivables considered good- Secured | AG24: 25 | AH24: 25 | AI24: 25 | AJ24: 15 | AK24: 15 | AL24: 15 | AN24: Others | AO24: 167.004 | AP24: 245.555 | AQ24: 397.706 | AR24: 738.823 | AS24: 835.616
A25: Other current financial assets | B25: 109.06 | C25: 167.91 | D25: 127.46 | E25: 316.77 | F25: 1128.49 | G25: 528.36 | I25: Other financial assets | J25: 605 | K25: 1420 | L25: 1154 | M25: 1089 | N25: 1425 | P25: Investments | Q25: 17948.33 | R25: 14846.33 | S25: 12264.28 | T25: 17232.86 | U25: 12944.42 | V25: 16287.5 | X25: Loans receivables | Y25: 56 | Z25: 109 | AA25: 423 | AB25: 135 | AC25: 281 | AD25: 44 | AF25: Unsecured | AG25: 60.98 | AH25: 1.04 | AI25: 1.44 | AJ25: 2.04 | AK25: 2.08 | AL25: 2.97 | AN25: Current tax assets (net) | AO25: 10.219 | AP25: 1.108 | AQ25: 0 | AR25: 0.311 | AS25: 4.872
A26: Other current assets | B26: 149.1 | C26: 152.83 | D26: 201.33 | E26: 215.46 | F26: 235.02 | G26: 306.23 | I26: Other current assets | J26: 440 | K26: 601 | L26: 497 | M26: 688 | N26: 713 | P26: Trade receivables | Q26: 2562.48 | R26: 2501.7 | S26: 2461.9 | T26: 2956.17 | U26: 4025.82 | V26: 4719.67 | X26: Others financial assets | Y26: 459 | Z26: 197 | AA26: 291 | AB26: 201 | AC26: 327 | AD26: 260 | AF26: Credit impaired | AG26: 0 | AH26: 0 | AI26: 0 | AJ26: 0 | AK26: 0 | AL26: 0 | AN26: Other current assets | AO26: 251.786 | AP26: 293.492 | AQ26: 427.834 | AR26: 526.716 | AS26: 936.356
A27: Total current assets | B27: =SUM(B19:B26) -> 2347.67 | C27: =SUM(C19:C26) -> 4061.13 | D27: =SUM(D19:D26) -> 3442.85 | E27: =SUM(E19:E26) -> 5448.39 | F27: =SUM(F19:F26) -> 6202.03 | G27: =SUM(G19:G26) -> 6392.2 | I27: Assets held for sale | J27: 4 | K27: 18 | L27: 17 | M27: 13 | N27: 12 | P27: Cash and cash equivalents | Q27: 650.35 | R27: 290.42 | S27: 271.37 | T27: 463.35 | U27: 625.89 | V27: 620 | X27: Other current assets | Y27: 696 | Z27: 752 | AA27: 978 | AB27: 1288 | AC27: 1721 | AD27: 1957 | AF27: Others | AG27: 39.09 | AH27: 55.5 | AI27: 98.19 | AJ27: 119.24 | AK27: 140.22 | AL27: 158.84 | AN27: Total current assets | AO27: =SUM(AO19:AO26) -> 1799.676 | AP27: =SUM(AP19:AP26) -> 2546.113 | AQ27: =SUM(AQ19:AQ26) -> 3404.03 | AR27: =SUM(AR19:AR26) -> 4235.63 | AS27: =SUM(AS19:AS26) -> 7863.974
A28: Total Assets | B28: =B17+B27 -> 12076.45 | C28: =C17+C27 -> 13655.97 | D28: =D17+D27 -> 15472.64 | E28: =E17+E27 -> 18106.59 | F28: =F17+F27 -> 21177.2 | G28: =G17+G27 -> 24320.29 | I28: Total current assets | J28: =SUM(J19:J27) -> 11914 | K28: =SUM(K19:K27) -> 12321 | L28: =SUM(L19:L27) -> 14217 | M28: =SUM(M19:M27) -> 15522 | N28: =SUM(N19:N27) -> 21324 | P28: Other bank balances | Q28: 6626.99 | R28: 4368.6 | S28: 4383.05 | T28: 4416.84 | U28: 6591.79 | V28: 3392.36 | X28: Assets held for sale | Y28: 0 | Z28: 0 | AA28: 0 | AB28: 18 | AC28: 18 | AD28: 0 | AF28: Current tax assets (net) | AG28: 23.45 | AH28: 4.52 | AI28: 1.89 | AJ28: 17.21 | AK28: 4 | AL28: 2.36 | AN28: Total assets | AO28: =AO17+AO27 -> 8458.383 | AP28: =AP17+AP27 -> 9581.89 | AQ28: =AQ17+AQ27 -> 11618.243 | AR28: =AR17+AR27 -> 15187.183 | AS28: =AS17+AS27 -> 23143.91
A29: Equity and Liabilities | I29: Total assets | J29: =J17+J28 -> 18629 | K29: =K17+K28 -> 20153 | L29: =L17+L28 -> 68757 | M29: =M17+M28 -> 70517 | N29: =N17+N28 -> 78499 | P29: Loans | Q29: 6.33 | R29: 3.47 | S29: 6.77 | T29: 7.12 | U29: 9.81 | V29: 9.51 | X29: Total current assets | Y29: =SUM(Y20:Y28) -> 10121 | Z29: =SUM(Z20:Z28) -> 13197 | AA29: =SUM(AA20:AA28) -> 17454 | AB29: =SUM(AB20:AB28) -> 22407 | AC29: =SUM(AC20:AC28) -> 25608 | AD29: =SUM(AD20:AD28) -> 34434 | AF29: Other current assets | AG29: 83.28 | AH29: 106.03 | AI29: 152.2 | AJ29: 188.01 | AK29: 253.63 | AL29: 402.61 | AN29: Equity and Liabilities
A30: Equity | I30: Equity and Liabilities | P30: Others | Q30: 1818.54 | R30: 1379.02 | S30: 2565.41 | T30: 1118.67 | U30: 1181.74 | V30: 1656.25 | X30: Total assets | Y30: =Y18+Y29 -> 13550 | Z30: =Z18+Z29 -> 16452 | AA30: =AA18+AA29 -> 21194 | AB30: =AB18+AB29 -> 27023 | AC30: =AC18+AC29 -> 31550 | AD30: =AD18+AD29 -> 40647 | AF30: Assets held under sale | AG30: 6.45 | AH30: 9.97 | AI30: 6.4 | AJ30: 8.69 | AK30: 13.12 | AL30: 9.14 | AN30: Equity
A31: Equity Share capital | B31: 647.77 | C31: 647.77 | D31: 647.77 | E31: 648.26 | F31: 650.73 | G31: 650.73 | I31: Equity | P31: Other current assets | Q31: 926.8 | R31: 1095.23 | S31: 1306.08 | T31: 1561.75 | U31: 1383.19 | V31: 1371.85 | X31: Equity and Liabilities | AF31: Total current assets | AG31: =SUM(AG18:AG30) -> 1703.46 | AH31: =SUM(AH18:AH30) -> 1403.35 | AI31: =SUM(AI18:AI30) -> 1783.46 | AJ31: =SUM(AJ18:AJ30) -> 2377.78 | AK31: =SUM(AK18:AK30) -> 3109.85 | AL31: =SUM(AL18:AL30) -> 3673.45 | AN31: Equity share capital | AO31: 288.689 | AP31: 433.033 | AQ31: 649.55 | AR31: 649.607 | AS31: 676.302
A32: Other equity | B32: 10431.97 | C32: 11535.94 | D32: 13029.87 | E32: 15430.44 | F32: 18047.09 | G32: 20777.02 | I32: Equity share capital | J32: 216 | K32: 216 | L32: 235 | M32: 235 | N32: 235 | P32: Total current assets | Q32: =SUM(Q22:Q31) -> 39505.35 | R32: =SUM(R22:R31) -> 34991.99 | S32: =SUM(S22:S31) -> 34232.45 | T32: =SUM(T22:T31) -> 39670.89 | U32: =SUM(U22:U31) -> 41065.54 | V32: =SUM(V22:V31) -> 43893.28 | X32: Equity | AF32: Total assets | AG32: =AG16+AG31 -> 5506.68 | AH32: =AH16+AH31 -> 5723.73 | AI32: =AI16+AI31 -> 7726.02 | AJ32: =AJ16+AJ31 -> 8081.53 | AK32: =AK16+AK31 -> 7161.75 | AL32: =AL16+AL31 -> 9419.64 | AN32: Other equity | AO32: 3235.12 | AP32: 3646.875 | AQ32: 4452.83 | AR32: 6286.891 | AS32: 15933.527
A33: Equity attributable to equity holders of the parent | B33: =SUM(B31:B32) -> 11079.74 | C33: =SUM(C31:C32) -> 12183.71 | D33: =SUM(D31:D32) -> 13677.64 | E33: =SUM(E31:E32) -> 16078.7 | F33: =SUM(F31:F32) -> 18697.82 | G33: =SUM(G31:G32) -> 21427.75 | I33: Other equity | J33: 7651 | K33: 8013 | L33: 47439 | M33: 48826 | N33: 50983 | P33: Total assets | Q33: =Q20+Q32 -> 77366.64 | R33: =R20+R32 -> 73819.3 | S33: =S20+S32 -> 77259.55 | T33: =T20+T32 -> 85882.96 | U33: =U20+U32 -> 91826.16 | V33: =V20+V32 -> 88090.68 | X33: Equity share capital | Y33: 89 | Z33: 89 | AA33: 89 | AB33: 89 | AC33: 89 | AD33: 89 | AF33: Equity and Liabilities | AN33: Attributable to the owners | AO33: =AO31+AO32 -> 3523.809 | AP33: =AP31+AP32 -> 4079.908 | AQ33: =AQ31+AQ32 -> 5102.38 | AR33: =AR31+AR32 -> 6936.498 | AS33: =AS31+AS32 -> 16609.829
A34: Non-controlling interest | B34: 0.46 | C34: 0.4 | D34: 0.25 | E34: 0.08 | F34: -0.48 | G34: -1.05 | I34: Non-controlling interest | J34: 18 | K34: 17 | L34: 20 | M34: 26 | N34: 205 | P34: Equity and Liabilities | X34: Other equity | Y34: 6580 | Z34: 7408 | AA34: 9214 | AB34: 11762 | AC34: 9304 | AD34: 11535 | AF34: Equity | AN34: Non controlling interest | AO34: 64.788 | AP34: 116.789 | AQ34: 113.107 | AR34: 148.155 | AS34: 129.807
A35: Total equity | B35: =SUM(B33,B34) -> 11080.2 | C35: =SUM(C33,C34) -> 12184.11 | D35: =SUM(D33,D34) -> 13677.89 | E35: =SUM(E33,E34) -> 16078.78 | F35: =SUM(F33,F34) -> 18697.34 | G35: =SUM(G33,G34) -> 21426.7 | I35: Total equity | J35: =SUM(J32:J34) -> 7885 | K35: =SUM(K32:K34) -> 8246 | L35: =SUM(L32:L34) -> 47694 | M35: =SUM(M32:M34) -> 49087 | N35: =SUM(N32:N34) -> 51423 | P35: Equity | X35: Attributable to the owners | Y35: =Y33+Y34 -> 6669 | Z35: =Z33+Z34 -> 7497 | AA35: =AA33+AA34 -> 9303 | AB35: =AB33+AB34 -> 11851 | AC35: =AC33+AC34 -> 9393 | AD35: =AD33+AD34 -> 11624 | AF35: Equity share capital | AG35: 35.55 | AH35: 35.55 | AI35: 35.55 | AJ35: 35.55 | AK35: 35.55 | AL35: 35.55 | AN35: Total equity | AO35: =AO33+AO34 -> 3588.597 | AP35: =AP33+AP34 -> 4196.697 | AQ35: =AQ33+AQ34 -> 5215.487 | AR35: =AR33+AR34 -> 7084.653 | AS35: =AS33+AS34 -> 16739.636
A36: Liabilities | I36: Liabilities | P36: Equity Share capital | Q36: 1229.22 | R36: 1230.88 | S36: 1232.33 | T36: 1242.8 | U36: 1248.47 | V36: 1251.41 | X36: Non controlling interest | Y36: 4 | Z36: 5 | AA36: 30 | AB36: 53 | AC36: 0 | AD36: 0 | AF36: Other equity | AG36: 2352.22 | AH36: 2277.48 | AI36: 2328.45 | AJ36: 2559.94 | AK36: 4032.19 | AL36: 5426.19 | AN36: Liabilities
A37: Non-current liabilities | I37: Non-current liabilities | P37: Other equity | Q37: 64044.04 | R37: 59116.46 | S37: 61223.24 | T37: 67912.46 | U37: 73258.53 | V37: 68778.64 | X37: Total equity | Y37: =Y35+Y36 -> 6673 | Z37: =Z35+Z36 -> 7502 | AA37: =AA35+AA36 -> 9333 | AB37: =AB35+AB36 -> 11904 | AC37: =AC35+AC36 -> 9393 | AD37: =AD35+AD36 -> 11624 | AF37: Attributable to the owners | AG37: =AG35+AG36 -> 2387.77 | AH37: =AH35+AH36 -> 2313.03 | AI37: =AI35+AI36 -> 2364 | AJ37: =AJ35+AJ36 -> 2595.49 | AK37: =AK35+AK36 -> 4067.74 | AL37: =AL35+AL36 -> 5461.74 | AN37: Non-current liabilities
A38: Financial Liabilities | I38: Lease liabilities | J38: 0 | K38: 0 | L38: 731 | M38: 741 | N38: 1106 | P38: Attributale to the owners of the parent | Q38: =Q36+Q37 -> 65273.26 | R38: =R36+R37 -> 60347.34 | S38: =S36+S37 -> 62455.57 | T38: =T36+T37 -> 69155.26 | U38: =U36+U37 -> 74507 | V38: =V36+V37 -> 70030.05 | X38: Liabilities | AF38: Non controlling interest | AG38: 79.59 | AH38: 44.49 | AI38: 45.94 | AJ38: 67.48 | AK38: 34.85 | AL38: 121.62 | AN38: Borrowings | AO38: 1979.622 | AP38: 1813.327 | AQ38: 1727.022 | AR38: 3188.938 | AS38: 840.689
A39: Borrowings | B39: 0 | C39: 0 | D39: 0 | E39: 0 | F39: 0 | G39: 0 | I39: Other financial liabilities | J39: 394 | K39: 939 | L39: 296 | M39: 357 | N39: 718 | P39: Non-controlling interest | Q39: 377.47 | R39: 346.81 | S39: 366.3 | T39: 383.53 | U39: 382.97 | V39: 367.89 | X39: Non-current liabilities | AF39: Total equity | AG39: =AG37+AG38 -> 2467.36 | AH39: =AH37+AH38 -> 2357.52 | AI39: =AI37+AI38 -> 2409.94 | AJ39: =AJ37+AJ38 -> 2662.97 | AK39: =AK37+AK38 -> 4102.59 | AL39: =AL37+AL38 -> 5583.36 | AN39: Other financial liabilities | AO39: 24.439 | AP39: 31.263 | AQ39: 165.425 | AR39: 197.885 | AS39: 357.086
A40: Lease Liability | B40: 221.11 | C40: 312.01 | D40: 507.15 | E40: 476.66 | F40: 399.24 | G40: 555.79 | I40: Provisions | J40: 1082 | K40: 1227 | L40: 1578 | M40: 1580 | N40: 1576 | P40: Total equity | Q40: =Q38+Q39 -> 65650.73 | R40: =R38+R39 -> 60694.15 | S40: =S38+S39 -> 62821.87 | T40: =T38+T39 -> 69538.79 | U40: =U38+U39 -> 74889.97 | V40: =V38+V39 -> 70397.94 | X40: Borrowings | Y40: 17 | Z40: 9 | AA40: 2 | AB40: 0 | AC40: 3302 | AD40: 595 | AF40: Liabilities | AN40: Provisions | AO40: 203.906 | AP40: 208.543 | AQ40: 204.113 | AR40: 212.644 | AS40: 189.434
...

Sheet Common Size Balance Sheet
A1: Common Size Balance Sheet | F1: #VALUE! | I1: Common Size Balance Sheet | M1: #VALUE! | P1: Common Size Balance Sheet | U1: #VALUE! | X1: Common Size Balance Sheet | AC1: #VALUE! | AF1: Common Size Balance Sheet | AK1: #VALUE! | AN1: Common Size Balance Sheet | AR1: #VALUE!
A2: Particulars | B2: 2020 | C2: 2021 | D2: 2022 | E2: 2023 | F2: 2024 | G2: 2025 | I2: Particulars | J2: 2020 | K2: 2021 | L2: 2022 | M2: 2023 | N2: 2024 | P2: Particulars | Q2: 2020 | R2: 2021 | S2: 2022 | T2: 2023 | U2: 2024 | V2: 2025 | X2: Particulars | Y2: 2020 | Z2: 2021 | AA2: 2022 | AB2: 2023 | AC2: 2024 | AD2: 2025 | AF2: Particulars | AG2: 2020 | AH2: 2021 | AI2: 2022 | AJ2: 2023 | AK2: 2024 | AL2: 2025 | AN2: Particulars | AO2: 2020 | AP2: 2021 | AQ2: 2022 | AR2: 2023 | AS2: 2024
A3: Assets | I3: Assets | P3: Assets | X3: Assets | AF3: Assets | AN3: Assets
A4: Property, plant and Equipment | B4: ='Balance Sheet'!B5/'Balance Sheet'!B28 -> 0.42291899 | C4: ='Balance Sheet'!C5/'Balance Sheet'!C28 -> 0.43486475 | D4: ='Balance Sheet'!D5/'Balance Sheet'!D28 -> 0.50220648 | E4: ='Balance Sheet'!E5/'Balance Sheet'!E28 -> 0.53713096 | F4: ='Balance Sheet'!F5/'Balance Sheet'!F28 -> 0.55527596 | G4: ='Balance Sheet'!G5/'Balance Sheet'!G28 -> 0.59003532 | I4: Property, plant and Equipment | J4: ='Balance Sheet'!J5/'Balance Sheet'!J29 -> 0.2250255 | K4: ='Balance Sheet'!K5/'Balance Sheet'!K29 -> 0.2461172 | L4: ='Balance Sheet'!L5/'Balance Sheet'!L29 -> 0.088950943 | M4: ='Balance Sheet'!M5/'Balance Sheet'!M29 -> 0.087482451 | N4: ='Balance Sheet'!N5/'Balance Sheet'!N29 -> 0.10230704 | P4: Property, plant and Equipment | Q4: ='Balance Sheet'!Q5/'Balance Sheet'!Q33 -> 0.25376467 | R4: ='Balance Sheet'!R5/'Balance Sheet'!R33 -> 0.25947063 | S4: ='Balance Sheet'!S5/'Balance Sheet'!S33 -> 0.26155252 | T4: ='Balance Sheet'!T5/'Balance Sheet'!T33 -> 0.24588184 | U4: ='Balance Sheet'!U5/'Balance Sheet'!U33 -> 0.25136987 | V4: ='Balance Sheet'!V5/'Balance Sheet'!V33 -> 0.19785169 | X4: Property, plant and Equipment | Y4: ='Balance Sheet'!Y5/'Balance Sheet'!Y30 -> 0.094833948 | Z4: ='Balance Sheet'!Z5/'Balance Sheet'!Z30 -> 0.073911986 | AA4: ='Balance Sheet'!AA5/'Balance Sheet'!AA30 -> 0.057469095 | AB4: ='Balance Sheet'!AB5/'Balance Sheet'!AB30 -> 0.049698405 | AC4: ='Balance Sheet'!AC5/'Balance Sheet'!AC30 -> 0.055055468 | AD4: ='Balance Sheet'!AD5/'Balance Sheet'!AD30 -> 0.045612222 | AF4: Property, plant and Equipment | AG4: ='Balance Sheet'!AG5/'Balance Sheet'!AG32 -> 0.11888107 | AH4: ='Balance Sheet'!AH5/'Balance Sheet'!AH32 -> 0.11189382 | AI4: ='Balance Sheet'!AI5/'Balance Sheet'!AI32 -> 0.093830976 | AJ4: ='Balance Sheet'!AJ5/'Balance Sheet'!AJ32 -> 0.10779889 | AK4: ='Balance Sheet'!AK5/'Balance Sheet'!AK32 -> 0.16006144 | AL4: ='Balance Sheet'!AL5/'Balance Sheet'!AL32 -> 0.21956678 | AN4: Property, plant and Equipment | AO4: ='Balance Sheet'!AO5/'Balance Sheet'!AO28 -> 0.68892459 | AP4: ='Balance Sheet'!AP5/'Balance Sheet'!AP28 -> 0.53801202 | AQ4: ='Balance Sheet'!AQ5/'Balance Sheet'!AQ28 -> 0.46836497 | AR4: ='Balance Sheet'!AR5/'Balance Sheet'!AR28 -> 0.4479522 | AS4: ='Balance Sheet'!AS5/'Balance Sheet'!AS28 -> 0.45897824
A5: Rights of use assets | B5: ='Balance Sheet'!B7/'Balance Sheet'!B28 -> 0.059399078 | C5: ='Balance Sheet'!C7/'Balance Sheet'!C28 -> 0.070316499 | D5: ='Balance Sheet'!D7/'Balance Sheet'!D28 -> 0.089748744 | E5: ='Balance Sheet'!E7/'Balance Sheet'!E28 -> 0.083112281 | F5: ='Balance Sheet'!F7/'Balance Sheet'!F28 -> 0.072677219 | G5: ='Balance Sheet'!G7/'Balance Sheet'!G28 -> 0.071616334 | I5: Rights of use assets | J5: 0 | K5: 1 | L5: 2 | M5: 3 | N5: 4 | P5: Rights of use assets | Q5: ='Balance Sheet'!Q11/'Balance Sheet'!Q33 -> 0.012500995 | R5: ='Balance Sheet'!R11/'Balance Sheet'!R33 -> 0.013237595 | S5: ='Balance Sheet'!S11/'Balance Sheet'!S33 -> 0.011223596 | T5: ='Balance Sheet'!T11/'Balance Sheet'!T33 -> 0.010186887 | U5: ='Balance Sheet'!U11/'Balance Sheet'!U33 -> 0.010227151 | V5: ='Balance Sheet'!V11/'Balance Sheet'!V33 -> 0.0066055796 | X5: Rights of use assets | Y5: ='Balance Sheet'!Y7/'Balance Sheet'!Y30 -> 0.06900369 | Z5: ='Balance Sheet'!Z7/'Balance Sheet'!Z30 -> 0.055737904 | AA5: ='Balance Sheet'!AA7/'Balance Sheet'!AA30 -> 0.04590922 | AB5: ='Balance Sheet'!AB7/'Balance Sheet'!AB30 -> 0.047552085 | AC5: ='Balance Sheet'!AC7/'Balance Sheet'!AC30 -> 0.048906498 | AD5: ='Balance Sheet'!AD7/'Balance Sheet'!AD30 -> 0.043644057 | AF5: Rights of use assets | AG5: ='Balance Sheet'!AG10/'Balance Sheet'!AG32 -> 0.36057479 | AH5: ='Balance Sheet'!AH10/'Balance Sheet'!AH32 -> 0.40506628 | AI5: ='Balance Sheet'!AI10/'Balance Sheet'!AI32 -> 0.50015532 | AJ5: ='Balance Sheet'!AJ10/'Balance Sheet'!AJ32 -> 0.43930295 | AK5: ='Balance Sheet'!AK10/'Balance Sheet'!AK32 -> 0.16785423 | AL5: ='Balance Sheet'!AL10/'Balance Sheet'!AL32 -> 0.1833138 | AN5: Rights of use assets | AO5: ='Balance Sheet'!AO7/'Balance Sheet'!AO28 -> 0 | AP5: ='Balance Sheet'!AP7/'Balance Sheet'!AP28 -> 0.059779334 | AQ5: ='Balance Sheet'!AQ7/'Balance Sheet'!AQ28 -> 0.078798576 | AR5: ='Balance Sheet'!AR7/'Balance Sheet'!AR28 -> 0.068130278 | AS5: ='Balance Sheet'!AS7/'Balance Sheet'!AS28 -> 0.058897654
A6: Intangible assets | B6: ='Balance Sheet'!B10/'Balance Sheet'!B28 -> 0.0023632773 | C6: ='Balance Sheet'!C10/'Balance Sheet'!C28 -> 0.0016271272 | D6: ='Balance Sheet'!D10/'Balance Sheet'!D28 -> 0.00087961718 | E6: ='Balance Sheet'!E10/'Balance Sheet'!E28 -> 0.0012801969 | F6: ='Balance Sheet'!F10/'Balance Sheet'!F28 -> 0.0014331451 | G6: ='Balance Sheet'!G10/'Balance Sheet'!G28 -> 0.0011915976 | I6: Intangible assets | J6: ='Balance Sheet'!J8/'Balance Sheet'!J29 -> 0.021793977 | K6: ='Balance Sheet'!K8/'Balance Sheet'!K29 -> 0.019947402 | L6: ='Balance Sheet'!L8/'Balance Sheet'!L29 -> 0.40621319 | M6: ='Balance Sheet'!M8/'Balance Sheet'!M29 -> 0.39574854 | N6: ='Balance Sheet'!N8/'Balance Sheet'!N29 -> 0.35983898 | P6: Intangible assets | Q6: =('Balance Sheet'!Q9+'Balance Sheet'!Q10)/'Balance Sheet'!Q33 -> 0.0068533414 | R6: =('Balance Sheet'!R9+'Balance Sheet'!R10)/'Balance Sheet'!R33 -> 0.02733567 | S6: =('Balance Sheet'!S9+'Balance Sheet'!S10)/'Balance Sheet'!S33 -> 0.026406962 | T6: =('Balance Sheet'!T9+'Balance Sheet'!T10)/'Balance Sheet'!T33 -> 0.031972699 | U6: =('Balance Sheet'!U9+'Balance Sheet'!U10)/'Balance Sheet'!U33 -> 0.029269981 | V6: =('Balance Sheet'!V9+'Balance Sheet'!V10)/'Balance Sheet'!V33 -> 0.030968656 | X6: Intangible assets | Y6: =('Balance Sheet'!Y10+'Balance Sheet'!Y11)/'Balance Sheet'!Y30 -> 0.020147601 | Z6: =('Balance Sheet'!Z10+'Balance Sheet'!Z11)/'Balance Sheet'!Z30 -> 0.015560418 | AA6: =('Balance Sheet'!AA10+'Balance Sheet'!AA11)/'Balance Sheet'!AA30 -> 0.011559875 | AB6: =('Balance Sheet'!AB10+'Balance Sheet'!AB11)/'Balance Sheet'!AB30 -> 0.0095104171 | AC6: =('Balance Sheet'!AC10+'Balance Sheet'!AC11)/'Balance Sheet'!AC30 -> 0.0099524564 | AD6: =('Balance Sheet'!AD10+'Balance Sheet'!AD11)/'Balance Sheet'!AD30 -> 0.0079218639 | AF6: Intangible assets | AG6: =('Balance Sheet'!AG9)/'Balance Sheet'!AG32 -> 0.0076761315 | AH6: =('Balance Sheet'!AH9)/'Balance Sheet'!AH32 -> 0.0069150711 | AI6: =('Balance Sheet'!AI9)/'Balance Sheet'!AI32 -> 0.0055047748 | AJ6: =('Balance Sheet'!AJ9)/'Balance Sheet'!AJ32 -> 0.0063366714 | AK6: =('Balance Sheet'!AK9)/'Balance Sheet'!AK32 -> 0.0066143052 | AL6: =('Balance Sheet'!AL9)/'Balance Sheet'!AL32 -> 0.0048929683 | AN6: Intangible assets | AO6: ='Balance Sheet'!AO9/'Balance Sheet'!AO28 -> 0.065875593 | AP6: ='Balance Sheet'!AP9/'Balance Sheet'!AP28 -> 0.058294762 | AQ6: ='Balance Sheet'!AQ9/'Balance Sheet'!AQ28 -> 0.047417669 | AR6: ='Balance Sheet'!AR9/'Balance Sheet'!AR28 -> 0.036023797 | AS6: ='Balance Sheet'!AS9/'Balance Sheet'!AS28 -> 0.048182265
A7: Non-current investments | B7: ='Balance Sheet'!B13/'Balance Sheet'!B28 -> 0 | C7: ='Balance Sheet'!C13/'Balance Sheet'!C28 -> 0 | D7: ='Balance Sheet'!D13/'Balance Sheet'!D28 -> 6.4630212e-07 | E7: ='Balance Sheet'!E13/'Balance Sheet'!E28 -> 5.5228511e-07 | F7: ='Balance Sheet'!F13/'Balance Sheet'!F28 -> 0.011085507 | G7: ='Balance Sheet'!G13/'Balance Sheet'!G28 -> 0.0069127465 | I7: Non-current investments | J7: ='Balance Sheet'!J11/'Balance Sheet'!J29 -> 0.00010735949 | K7: ='Balance Sheet'!K11/'Balance Sheet'!K29 -> 9.9240808e-05 | L7: ='Balance Sheet'!L11/'Balance Sheet'!L29 -> 2.9087947e-05 | M7: ='Balance Sheet'!M11/'Balance Sheet'!M29 -> 2.8361955e-05 | N7: ='Balance Sheet'!N11/'Balance Sheet'!N29 -> 2.5478032e-05 | P7: Non-current investments | Q7: ='Balance Sheet'!Q14/'Balance Sheet'!Q33 -> 0.13505123 | R7: ='Balance Sheet'!R14/'Balance Sheet'!R33 -> 0.1322417 | S7: ='Balance Sheet'!S14/'Balance Sheet'!S33 -> 0.15930057 | T7: ='Balance Sheet'!T14/'Balance Sheet'!T33 -> 0.13791525 | U7: ='Balance Sheet'!U14/'Balance Sheet'!U33 -> 0.1918829 | V7: ='Balance Sheet'!V14/'Balance Sheet'!V33 -> 0.15575473 | X7: Non-current investments | Y7: ='Balance Sheet'!Y12/'Balance Sheet'!Y30 -> 0.0032472325 | Z7: ='Balance Sheet'!Z12/'Balance Sheet'!Z30 -> 0.0011548748 | AA7: ='Balance Sheet'!AA12/'Balance Sheet'!AA30 -> 0.013164103 | AB7: ='Balance Sheet'!AB12/'Balance Sheet'!AB30 -> 0.012988935 | AC7: ='Balance Sheet'!AC12/'Balance Sheet'!AC30 -> 0.021521395 | AD7: ='Balance Sheet'!AD12/'Balance Sheet'!AD30 -> 0.016015942 | AF7: Non-current investments | AG7: ='Balance Sheet'!AG11/'Balance Sheet'!AG32 -> 0.13363951 | AH7: ='Balance Sheet'!AH11/'Balance Sheet'!AH32 -> 0.14267444 | AI7: ='Balance Sheet'!AI11/'Balance Sheet'!AI32 -> 0.098031069 | AJ7: ='Balance Sheet'!AJ11/'Balance Sheet'!AJ32 -> 0.069804851 | AK7: ='Balance Sheet'!AK11/'Balance Sheet'!AK32 -> 0.097219255 | AL7: ='Balance Sheet'!AL11/'Balance Sheet'!AL32 -> 0.089765639 | AN7: Non-current investments | AO7: ='Balance Sheet'!AO12/'Balance Sheet'!AO28 -> 1.1822591e-07 | AP7: ='Balance Sheet'!AP12/'Balance Sheet'!AP28 -> 1.0436354e-07 | AQ7: ='Balance Sheet'!AQ12/'Balance Sheet'!AQ28 -> 8.6071534e-08 | AR7: ='Balance Sheet'!AR12/'Balance Sheet'!AR28 -> 0.00020747758 | AS7: ='Balance Sheet'!AS12/'Balance Sheet'!AS28 -> 0.0002616239
A8: Total non-current investments | B8: ='Balance Sheet'!B17/'Balance Sheet'!B28 -> 0.80559933 | C8: ='Balance Sheet'!C17/'Balance Sheet'!C28 -> 0.70261139 | D8: ='Balance Sheet'!D17/'Balance Sheet'!D28 -> 0.77748788 | E8: ='Balance Sheet'!E17/'Balance Sheet'!E28 -> 0.69909353 | F8: ='Balance Sheet'!F17/'Balance Sheet'!F28 -> 0.70713645 | G8: ='Balance Sheet'!G17/'Balance Sheet'!G28 -> 0.73716596 | I8: Total non-current assets | J8: ='Balance Sheet'!J17/'Balance Sheet'!J29 -> 0.3604595 | K8: ='Balance Sheet'!K17/'Balance Sheet'!K29 -> 0.388627 | L8: ='Balance Sheet'!L17/'Balance Sheet'!L29 -> 0.79322833 | M8: ='Balance Sheet'!M17/'Balance Sheet'!M29 -> 0.77988287 | N8: ='Balance Sheet'!N17/'Balance Sheet'!N29 -> 0.72835323 | P8: Total non-current assets | Q8: ='Balance Sheet'!Q20/'Balance Sheet'!Q33 -> 0.48937488 | R8: ='Balance Sheet'!R20/'Balance Sheet'!R33 -> 0.52597776 | S8: ='Balance Sheet'!S20/'Balance Sheet'!S33 -> 0.55691626 | T8: ='Balance Sheet'!T20/'Balance Sheet'!T33 -> 0.53808194 | U8: ='Balance Sheet'!U20/'Balance Sheet'!U33 -> 0.5527904 | V8: ='Balance Sheet'!V20/'Balance Sheet'!V33 -> 0.50172618 | X8: Total non-current assets | Y8: ='Balance Sheet'!Y18/'Balance Sheet'!Y30 -> 0.25306273 | Z8: ='Balance Sheet'!Z18/'Balance Sheet'!Z30 -> 0.19784829 | AA8: ='Balance Sheet'!AA18/'Balance Sheet'!AA30 -> 0.17646504 | AB8: ='Balance Sheet'!AB18/'Balance Sheet'!AB30 -> 0.17081745 | AC8: ='Balance Sheet'!AC18/'Balance Sheet'!AC30 -> 0.18833597 | AD8: ='Balance Sheet'!AD18/'Balance Sheet'!AD30 -> 0.15285261 | AF8: Total non-current assets | AG8: ='Balance Sheet'!AG16/'Balance Sheet'!AG32 -> 0.69065571 | AH8: ='Balance Sheet'!AH16/'Balance Sheet'!AH32 -> 0.75481897 | AI8: ='Balance Sheet'!AI16/'Balance Sheet'!AI32 -> 0.76916187 | AJ8: ='Balance Sheet'!AJ16/'Balance Sheet'!AJ32 -> 0.70577601 | AK8: ='Balance Sheet'!AK16/'Balance Sheet'!AK32 -> 0.56576954 | AL8: ='Balance Sheet'!AL16/'Balance Sheet'!AL32 -> 0.61002225 | AN8: Total non-current assets | AO8: ='Balance Sheet'!AO17/'Balance Sheet'!AO28 -> 0.78723167 | AP8: ='Balance Sheet'!AP17/'Balance Sheet'!AP28 -> 0.73427862 | AQ8: ='Balance Sheet'!AQ17/'Balance Sheet'!AQ28 -> 0.70700992 | AR8: ='Balance Sheet'!AR17/'Balance Sheet'!AR28 -> 0.72110496 | AS8: ='Balance Sheet'!AS17/'Balance Sheet'!AS28 -> 0.66021411
A9: Inventories | B9: ='Balance Sheet'!B19/'Balance Sheet'!B28 -> 0.161256 | C9: ='Balance Sheet'!C19/'Balance Sheet'!C28 -> 0.16463715 | D9: ='Balance Sheet'!D19/'Balance Sheet'!D28 -> 0.1772587 | E9: ='Balance Sheet'!E19/'Balance Sheet'!E28 -> 0.17913257 | F9: ='Balance Sheet'!F19/'Balance Sheet'!F28 -> 0.18544992 | G9: ='Balance Sheet'!G19/'Balance Sheet'!G28 -> 0.20741406 | I9: Inventories | J9: ='Balance Sheet'!J19/'Balance Sheet'!J29 -> 0.13817167 | K9: ='Balance Sheet'!K19/'Balance Sheet'!K29 -> 0.13729966 | L9: ='Balance Sheet'!L19/'Balance Sheet'!L29 -> 0.052052882 | M9: ='Balance Sheet'!M19/'Balance Sheet'!M29 -> 0.058085284 | N9: ='Balance Sheet'!N19/'Balance Sheet'!N29 -> 0.051236321 | P9: Inventories | Q9: ='Balance Sheet'!Q22/'Balance Sheet'!Q33 -> 0.11476949 | R9: ='Balance Sheet'!R22/'Balance Sheet'!R33 -> 0.14084609 | S9: ='Balance Sheet'!S22/'Balance Sheet'!S33 -> 0.14061886 | T9: ='Balance Sheet'!T22/'Balance Sheet'!T33 -> 0.13706048 | U9: ='Balance Sheet'!U22/'Balance Sheet'!U33 -> 0.15412688 | V9: ='Balance Sheet'!V22/'Balance Sheet'!V33 -> 0.17751662 | X9: Inventories | Y9: ='Balance Sheet'!Y20/'Balance Sheet'!Y30 -> 0.59800738 | Z9: ='Balance Sheet'!Z20/'Balance Sheet'!Z30 -> 0.51106248 | AA9: ='Balance Sheet'!AA20/'Balance Sheet'!AA30 -> 0.64211569 | AB9: ='Balance Sheet'!AB20/'Balance Sheet'!AB30 -> 0.61369944 | AC9: ='Balance Sheet'!AC20/'Balance Sheet'!AC30 -> 0.60383518 | AD9: ='Balance Sheet'!AD20/'Balance Sheet'!AD30 -> 0.69338451 | AF9: Inventories | AG9: ='Balance Sheet'!AG18/'Balance Sheet'!AG32 -> 0.11037685 | AH9: ='Balance Sheet'!AH18/'Balance Sheet'!AH32 -> 0.074844551 | AI9: ='Balance Sheet'!AI18/'Balance Sheet'!AI32 -> 0.11231915 | AJ9: ='Balance Sheet'!AJ18/'Balance Sheet'!AJ32 -> 0.1684285 | AK9: ='Balance Sheet'!AK18/'Balance Sheet'!AK32 -> 0.22099766 | AL9: ='Balance Sheet'!AL18/'Balance Sheet'!AL32 -> 0.2171049 | AN9: Inventories | AO9: ='Balance Sheet'!AO19/'Balance Sheet'!AO28 -> 0.1098087 | AP9: ='Balance Sheet'!AP19/'Balance Sheet'!AP28 -> 0.15112749 | AQ9: ='Balance Sheet'!AQ19/'Balance Sheet'!AQ28 -> 0.17161674 | AR9: ='Balance Sheet'!AR19/'Balance Sheet'!AR28 -> 0.14160184 | AS9: ='Balance Sheet'!AS19/'Balance Sheet'!AS28 -> 0.12060339
A10: Trade receivables | B10: ='Balance Sheet'!B22/'Balance Sheet'!B28 -> 0.0016188532 | C10: ='Balance Sheet'!C22/'Balance Sheet'!C28 -> 0.0031912782 | D10: ='Balance Sheet'!D22/'Balance Sheet'!D28 -> 0.0043231149 | E10: ='Balance Sheet'!E22/'Balance Sheet'!E28 -> 0.0034330042 | F10: ='Balance Sheet'!F22/'Balance Sheet'!F28 -> 0.0078560905 | G10: ='Balance Sheet'!G22/'Balance Sheet'!G28 -> 0.0063235266 | I10: Trade receivables | J10: ='Balance Sheet'!J22/'Balance Sheet'!J29 -> 0.09748242 | K10: ='Balance Sheet'!K22/'Balance Sheet'!K29 -> 0.057013844 | L10: ='Balance Sheet'!L22/'Balance Sheet'!L29 -> 0.025568306 | M10: ='Balance Sheet'!M22/'Balance Sheet'!M29 -> 0.031708666 | N10: ='Balance Sheet'!N22/'Balance Sheet'!N29 -> 0.03817883 | P10: Trade receivables | Q10: =('Balance Sheet'!Q26)/'Balance Sheet'!Q33 -> 0.033121252 | R10: =('Balance Sheet'!R26)/'Balance Sheet'!R33 -> 0.033889511 | S10: =('Balance Sheet'!S26)/'Balance Sheet'!S33 -> 0.031865316 | T10: =('Balance Sheet'!T26)/'Balance Sheet'!T33 -> 0.034420914 | U10: =('Balance Sheet'!U26)/'Balance Sheet'!U33 -> 0.043841755 | V10: =('Balance Sheet'!V26)/'Balance Sheet'!V33 -> 0.053577405 | X10: Trade receivables | Y10: ='Balance Sheet'!Y22/'Balance Sheet'!Y30 -> 0.02302583 | Z10: ='Balance Sheet'!Z22/'Balance Sheet'!Z30 -> 0.022246535 | AA10: ='Balance Sheet'!AA22/'Balance Sheet'!AA30 -> 0.026658488 | AB10: ='Balance Sheet'!AB22/'Balance Sheet'!AB30 -> 0.024941716 | AC10: ='Balance Sheet'!AC22/'Balance Sheet'!AC30 -> 0.032266244 | AD10: ='Balance Sheet'!AD22/'Balance Sheet'!AD30 -> 0.026275002 | AF10: Trade receivables | AG10: ='Balance Sheet'!AG20/'Balance Sheet'!AG32 -> 0.0031089513 | AH10: ='Balance Sheet'!AH20/'Balance Sheet'!AH32 -> 0.0036287526 | AI10: ='Balance Sheet'!AI20/'Balance Sheet'!AI32 -> 0.002363442 | AJ10: ='Balance Sheet'!AJ20/'Balance Sheet'!AJ32 -> 0.0042553823 | AK10: ='Balance Sheet'!AK20/'Balance Sheet'!AK32 -> 0.011413412 | AL10: ='Balance Sheet'!AL20/'Balance Sheet'!AL32 -> 0.0066828456 | AN10: Trade receivables | AO10: ='Balance Sheet'!AO20/'Balance Sheet'!AO28 -> 0.02858667 | AP10: ='Balance Sheet'!AP20/'Balance Sheet'!AP28 -> 0.02309033 | AQ10: ='Balance Sheet'!AQ20/'Balance Sheet'!AQ28 -> 0.025764481 | AR10: ='Balance Sheet'!AR20/'Balance Sheet'!AR28 -> 0.023663704 | AS10: ='Balance Sheet'!AS20/'Balance Sheet'!AS28 -> 0.036547066
A11: Cash and bank balances | B11: =('Balance Sheet'!B23+'Balance Sheet'!B24)/'Balance Sheet'!B28 -> 0.0089330888 | C11: =('Balance Sheet'!C23+'Balance Sheet'!C24)/'Balance Sheet'!C28 -> 0.105857 | D11: =('Balance Sheet'!D23+'Balance Sheet'!D24)/'Balance Sheet'!D28 -> 0.019297289 | E11: =('Balance Sheet'!E23+'Balance Sheet'!E24)/'Balance Sheet'!E28 -> 0.077779969 | F11: =('Balance Sheet'!F23+'Balance Sheet'!F24)/'Balance Sheet'!F28 -> 0.03013524 | G11: =('Balance Sheet'!G23+'Balance Sheet'!G24)/'Balance Sheet'!G28 -> 0.014728443 | I11: Cash and bank balances | J11: =('Balance Sheet'!J23+'Balance Sheet'!J24)/'Balance Sheet'!J29 -> 0.20167481 | K11: =('Balance Sheet'!K23+'Balance Sheet'!K24)/'Balance Sheet'!K29 -> 0.25370913 | L11: =('Balance Sheet'!L23+'Balance Sheet'!L24)/'Balance Sheet'!L29 -> 0.065026106 | M11: =('Balance Sheet'!M23+'Balance Sheet'!M24)/'Balance Sheet'!M29 -> 0.05454004 | N11: =('Balance Sheet'!N23+'Balance Sheet'!N24)/'Balance Sheet'!N29 -> 0.09629422 | P11: Cash and bank balances | Q11: =('Balance Sheet'!Q27+'Balance Sheet'!Q28)/'Balance Sheet'!Q33 -> 0.094063023 | R11: =('Balance Sheet'!R27+'Balance Sheet'!R28)/'Balance Sheet'!R33 -> 0.063113847 | S11: =('Balance Sheet'!S27+'Balance Sheet'!S28)/'Balance Sheet'!S33 -> 0.060243944 | T11: =('Balance Sheet'!T27+'Balance Sheet'!T28)/'Balance Sheet'!T33 -> 0.056823728 | U11: =('Balance Sheet'!U27+'Balance Sheet'!U28)/'Balance Sheet'!U33 -> 0.078601566 | V11: =('Balance Sheet'!V27+'Balance Sheet'!V28)/'Balance Sheet'!V33 -> 0.045548065 | X11: Cash and bank balances | Y11: =('Balance Sheet'!Y23+'Balance Sheet'!Y24)/'Balance Sheet'!Y30 -> 0.028118081 | Z11: =('Balance Sheet'!Z23+'Balance Sheet'!Z24)/'Balance Sheet'!Z30 -> 0.034038415 | AA11: =('Balance Sheet'!AA23+'Balance Sheet'!AA24)/'Balance Sheet'!AA30 -> 0.074219119 | AB11: =('Balance Sheet'!AB23+'Balance Sheet'!AB24)/'Balance Sheet'!AB30 -> 0.049698405 | AC11: =('Balance Sheet'!AC23+'Balance Sheet'!AC24)/'Balance Sheet'!AC30 -> 0.04836767 | AD11: =('Balance Sheet'!AD23+'Balance Sheet'!AD24)/'Balance Sheet'!AD30 -> 0.038969666 | AF11: Cash and bank balances | AG11: =('Balance Sheet'!AG22+'Balance Sheet'!AG23)/'Balance Sheet'!AG32 -> 0.01115191 | AH11: =('Balance Sheet'!AH22+'Balance Sheet'!AH23)/'Balance Sheet'!AH32 -> 0.014233725 | AI11: =('Balance Sheet'!AI22+'Balance Sheet'!AI23)/'Balance Sheet'!AI32 -> 0.011127333 | AJ11: =('Balance Sheet'!AJ22+'Balance Sheet'!AJ23)/'Balance Sheet'!AJ32 -> 0.010678671 | AK11: =('Balance Sheet'!AK22+'Balance Sheet'!AK23)/'Balance Sheet'!AK32 -> 0.041548504 | AL11: =('Balance Sheet'!AL22+'Balance Sheet'!AL23)/'Balance Sheet'!AL32 -> 0.036077812 | AN11: Cash and bank balances | AO11: =('Balance Sheet'!AO21+'Balance Sheet'!AO22)/'Balance Sheet'!AO28 -> 0.022468834 | AP11: =('Balance Sheet'!AP21+'Balance Sheet'!AP22)/'Balance Sheet'!AP28 -> 0.035131065 | AQ11: =('Balance Sheet'!AQ21+'Balance Sheet'!AQ22)/'Balance Sheet'!AQ28 -> 0.024553368 | AR11: =('Balance Sheet'!AR21+'Balance Sheet'!AR22)/'Balance Sheet'!AR28 -> 0.030279611 | AS11: =('Balance Sheet'!AS21+'Balance Sheet'!AS22)/'Balance Sheet'!AS28 -> 0.10586171
A12: Other current assets | B12: ='Balance Sheet'!B26/'Balance Sheet'!B28 -> 0.012346344 | C12: ='Balance Sheet'!C26/'Balance Sheet'!C28 -> 0.011191442 | D12: ='Balance Sheet'!D26/'Balance Sheet'!D28 -> 0.013012001 | E12: ='Balance Sheet'!E26/'Balance Sheet'!E28 -> 0.011899535 | F12: ='Balance Sheet'!F26/'Balance Sheet'!F28 -> 0.011097784 | G12: ='Balance Sheet'!G26/'Balance Sheet'!G28 -> 0.012591544 | I12: Other current assets | J12: ='Balance Sheet'!J26/'Balance Sheet'!J29 -> 0.023619089 | K12: ='Balance Sheet'!K26/'Balance Sheet'!K29 -> 0.029821863 | L12: ='Balance Sheet'!L26/'Balance Sheet'!L29 -> 0.0072283549 | M12: ='Balance Sheet'!M26/'Balance Sheet'!M29 -> 0.0097565126 | N12: ='Balance Sheet'!N26/'Balance Sheet'!N29 -> 0.0090829183 | P12: Other current assets | Q12: ='Balance Sheet'!Q31/'Balance Sheet'!Q33 -> 0.011979323 | R12: ='Balance Sheet'!R31/'Balance Sheet'!R33 -> 0.014836635 | S12: ='Balance Sheet'!S31/'Balance Sheet'!S33 -> 0.016905095 | T12: ='Balance Sheet'!T31/'Balance Sheet'!T33 -> 0.018184632 | U12: ='Balance Sheet'!U31/'Balance Sheet'!U33 -> 0.015063137 | V12: ='Balance Sheet'!V31/'Balance Sheet'!V33 -> 0.015573157 | X12: Other current assets | Y12: ='Balance Sheet'!Y27/'Balance Sheet'!Y30 -> 0.051365314 | Z12: ='Balance Sheet'!Z27/'Balance Sheet'!Z30 -> 0.045708728 | AA12: ='Balance Sheet'!AA27/'Balance Sheet'!AA30 -> 0.046145135 | AB12: ='Balance Sheet'!AB27/'Balance Sheet'!AB30 -> 0.047663102 | AC12: ='Balance Sheet'!AC27/'Balance Sheet'!AC30 -> 0.054548336 | AD12: ='Balance Sheet'!AD27/'Balance Sheet'!AD30 -> 0.048146235 | AF12: Other current assets | AG12: ='Balance Sheet'!AG29/'Balance Sheet'!AG32 -> 0.01512345 | AH12: ='Balance Sheet'!AH29/'Balance Sheet'!AH32 -> 0.018524633 | AI12: ='Balance Sheet'!AI29/'Balance Sheet'!AI32 -> 0.019699664 | AJ12: ='Balance Sheet'!AJ29/'Balance Sheet'!AJ32 -> 0.023264159 | AK12: ='Balance Sheet'!AK29/'Balance Sheet'!AK32 -> 0.035414529 | AL12: ='Balance Sheet'!AL29/'Balance Sheet'!AL32 -> 0.042741549 | AN12: Other current assets | AO12: ='Balance Sheet'!AO26/'Balance Sheet'!AO28 -> 0.029767628 | AP12: ='Balance Sheet'!AP26/'Balance Sheet'!AP28 -> 0.030629865 | AQ12: ='Balance Sheet'!AQ26/'Balance Sheet'!AQ28 -> 0.036824329 | AR12: ='Balance Sheet'!AR26/'Balance Sheet'!AR28 -> 0.034681613 | AS12: ='Balance Sheet'!AS26/'Balance Sheet'!AS28 -> 0.040457987
A13: Total current assets | B13: ='Balance Sheet'!B27/'Balance Sheet'!B28 -> 0.19440067 | C13: ='Balance Sheet'!C27/'Balance Sheet'!C28 -> 0.29738861 | D13: ='Balance Sheet'!D27/'Balance Sheet'!D28 -> 0.22251212 | E13: ='Balance Sheet'!E27/'Balance Sheet'!E28 -> 0.30090647 | F13: ='Balance Sheet'!F27/'Balance Sheet'!F28 -> 0.29286355 | G13: ='Balance Sheet'!G27/'Balance Sheet'!G28 -> 0.26283404 | I13: Total current assets | J13: ='Balance Sheet'!J28/'Balance Sheet'!J29 -> 0.6395405 | K13: ='Balance Sheet'!K28/'Balance Sheet'!K29 -> 0.611373 | L13: ='Balance Sheet'!L28/'Balance Sheet'!L29 -> 0.20677167 | M13: ='Balance Sheet'!M28/'Balance Sheet'!M29 -> 0.22011713 | N13: ='Balance Sheet'!N28/'Balance Sheet'!N29 -> 0.27164677 | P13: Total current assets | Q13: ='Balance Sheet'!Q32/'Balance Sheet'!Q33 -> 0.51062512 | R13: ='Balance Sheet'!R32/'Balance Sheet'!R33 -> 0.47402224 | S13: ='Balance Sheet'!S32/'Balance Sheet'!S33 -> 0.44308374 | T13: ='Balance Sheet'!T32/'Balance Sheet'!T33 -> 0.46191806 | U13: ='Balance Sheet'!U32/'Balance Sheet'!U33 -> 0.4472096 | V13: ='Balance Sheet'!V32/'Balance Sheet'!V33 -> 0.49827382 | X13: Total current assets | Y13: ='Balance Sheet'!Y29/'Balance Sheet'!Y30 -> 0.74693727 | Z13: ='Balance Sheet'!Z29/'Balance Sheet'!Z30 -> 0.80215171 | AA13: ='Balance Sheet'!AA29/'Balance Sheet'!AA30 -> 0.82353496 | AB13: ='Balance Sheet'!AB29/'Balance Sheet'!AB30 -> 0.82918255 | AC13: ='Balance Sheet'!AC29/'Balance Sheet'!AC30 -> 0.81166403 | AD13: ='Balance Sheet'!AD29/'Balance Sheet'!AD30 -> 0.84714739 | AF13: Total current assets | AG13: ='Balance Sheet'!AG31/'Balance Sheet'!AG32 -> 0.30934429 | AH13: ='Balance Sheet'!AH31/'Balance Sheet'!AH32 -> 0.24518103 | AI13: ='Balance Sheet'!AI31/'Balance Sheet'!AI32 -> 0.23083813 | AJ13: ='Balance Sheet'!AJ31/'Balance Sheet'!AJ32 -> 0.29422399 | AK13: ='Balance Sheet'!AK31/'Balance Sheet'!AK32 -> 0.43423046 | AL13: ='Balance Sheet'!AL31/'Balance Sheet'!AL32 -> 0.38997775 | AN13: Total current assets | AO13: ='Balance Sheet'!AO27/'Balance Sheet'!AO28 -> 0.21276833 | AP13: ='Balance Sheet'!AP27/'Balance Sheet'!AP28 -> 0.26572138 | AQ13: ='Balance Sheet'!AQ27/'Balance Sheet'!AQ28 -> 0.29299008 | AR13: ='Balance Sheet'!AR27/'Balance Sheet'!AR28 -> 0.27889504 | AS13: ='Balance Sheet'!AS27/'Balance Sheet'!AS28 -> 0.33978589
A14: Total assets | B14: =B8+B13 -> 1 | C14: =C8+C13 -> 1 | D14: =D8+D13 -> 1 | E14: =E8+E13 -> 1 | F14: =F8+F13 -> 1 | G14: =G8+G13 -> 1 | I14: Total assets | J14: =J8+J13 -> 1 | K14: =K8+K13 -> 1 | L14: =L8+L13 -> 1 | M14: =M8+M13 -> 1 | N14: =N8+N13 -> 1 | P14: Total assets | Q14: =Q8+Q13 -> 1 | R14: =R8+R13 -> 1 | S14: =S8+S13 -> 1 | T14: =T8+T13 -> 1 | U14: =U8+U13 -> 1 | V14: =V8+V13 -> 1 | X14: Total assets | Y14: =Y8+Y13 -> 1 | Z14: =Z8+Z13 -> 1 | AA14: =AA8+AA13 -> 1 | AB14: =AB8+AB13 -> 1 | AC14: =AC8+AC13 -> 1 | AD14: =AD8+AD13 -> 1 | AF14: Total assets | AG14: =AG8+AG13 -> 1 | AH14: =AH8+AH13 -> 1 | AI14: =AI8+AI13 -> 1 | AJ14: =AJ8+AJ13 -> 1 | AK14: =AK8+AK13 -> 1 | AL14: =AL8+AL13 -> 1 | AN14: Total assets | AO14: =AO8+AO13 -> 1 | AP14: =AP8+AP13 -> 1 | AQ14: =AQ8+AQ13 -> 1 | AR14: =AR8+AR13 -> 1 | AS14: =AS8+AS13 -> 1
A15: Equity & Liabilities | I15: Equity & Liabilities | P15: Equity & Liabilities | X15: Equity & Liabilities | AF15: Equity & Liabilities | AN15: Equity & Liabilities
A16: Equity share capital | B16: ='Balance Sheet'!B31/'Balance Sheet'!B56 -> 0.053639108 | C16: ='Balance Sheet'!C31/'Balance Sheet'!C56 -> 0.047434931 | D16: ='Balance Sheet'!D31/'Balance Sheet'!D56 -> 0.041865512 | E16: ='Balance Sheet'!E31/'Balance Sheet'!E56 -> 0.035803028 | F16: ='Balance Sheet'!F31/'Balance Sheet'!F56 -> 0.030727858 | G16: ='Balance Sheet'!G31/'Balance Sheet'!G56 -> 0.026756671 | I16: Equity share capital | J16: ='Balance Sheet'!J32/'Balance Sheet'!J53 -> 0.011594825 | K16: ='Balance Sheet'!K32/'Balance Sheet'!K53 -> 0.010718007 | L16: ='Balance Sheet'!L32/'Balance Sheet'!L53 -> 0.0034178338 | M16: ='Balance Sheet'!M32/'Balance Sheet'!M53 -> 0.0033325297 | N16: ='Balance Sheet'!N32/'Balance Sheet'!N53 -> 0.0029936687 | P16: Equity share capital | Q16: ='Balance Sheet'!Q36/'Balance Sheet'!Q61 -> 0.015888161 | R16: ='Balance Sheet'!R36/'Balance Sheet'!R61 -> 0.01667423 | S16: ='Balance Sheet'!S36/'Balance Sheet'!S61 -> 0.01595052 | T16: ='Balance Sheet'!T36/'Balance Sheet'!T61 -> 0.014470853 | U16: ='Balance Sheet'!U36/'Balance Sheet'!U61 -> 0.013596017 | V16: ='Balance Sheet'!V36/'Balance Sheet'!V61 -> 0.01420593 | X16: Equity share capital | Y16: ='Balance Sheet'!Y33/'Balance Sheet'!Y59 -> 0.0065682657 | Z16: ='Balance Sheet'!Z33/'Balance Sheet'!Z59 -> 0.0054096766 | AA16: ='Balance Sheet'!AA33/'Balance Sheet'!AA59 -> 0.0041993017 | AB16: ='Balance Sheet'!AB33/'Balance Sheet'!AB59 -> 0.0032934907 | AC16: ='Balance Sheet'!AC33/'Balance Sheet'!AC59 -> 0.0028209192 | AD16: ='Balance Sheet'!AD33/'Balance Sheet'!AD59 -> 0.0021895835 | AF16: Equity share capital | AG16: ='Balance Sheet'!AG35/'Balance Sheet'!AG60 -> 0.0064557955 | AH16: ='Balance Sheet'!AH35/'Balance Sheet'!AH60 -> 0.0062109848 | AI16: ='Balance Sheet'!AI35/'Balance Sheet'!AI60 -> 0.0046013342 | AJ16: ='Balance Sheet'!AJ35/'Balance Sheet'!AJ60 -> 0.0043989195 | AK16: ='Balance Sheet'!AK35/'Balance Sheet'!AK60 -> 0.0049638706 | AL16: ='Balance Sheet'!AL35/'Balance Sheet'!AL60 -> 0.0037740296 | AN16: Equity share capital | AO16: ='Balance Sheet'!AO31/'Balance Sheet'!AO55 -> 0.034131294 | AP16: ='Balance Sheet'!AP31/'Balance Sheet'!AP55 -> 0.045257103 | AQ16: ='Balance Sheet'!AQ31/'Balance Sheet'!AQ55 -> 0.05602145 | AR16: ='Balance Sheet'!AR31/'Balance Sheet'!AR55 -> 0.04277337 | AS16: ='Balance Sheet'!AS31/'Balance Sheet'!AS55 -> 0.029221597
A17: Other equity | B17: ='Balance Sheet'!B32/'Balance Sheet'!B56 -> 0.86382753 | C17: ='Balance Sheet'!C32/'Balance Sheet'!C56 -> 0.84475435 | D17: ='Balance Sheet'!D32/'Balance Sheet'!D56 -> 0.84212326 | E17: ='Balance Sheet'!E32/'Balance Sheet'!E56 -> 0.85221434 | F17: ='Balance Sheet'!F32/'Balance Sheet'!F56 -> 0.85219434 | G17: ='Balance Sheet'!G32/'Balance Sheet'!G56 -> 0.85430807 | I17: Other equity | J17: =('Balance Sheet'!J33+'Balance Sheet'!J34)/'Balance Sheet'!J53 -> 0.41166998 | K17: =('Balance Sheet'!K33+'Balance Sheet'!K34)/'Balance Sheet'!K53 -> 0.39845184 | L17: =('Balance Sheet'!L33+'Balance Sheet'!L34)/'Balance Sheet'!L53 -> 0.69024245 | M17: =('Balance Sheet'!M33+'Balance Sheet'!M34)/'Balance Sheet'!M53 -> 0.69276912 | N17: =('Balance Sheet'!N33+'Balance Sheet'!N34)/'Balance Sheet'!N53 -> 0.65208474 | P17: Other equity | Q17: ='Balance Sheet'!Q37/'Balance Sheet'!Q61 -> 0.82779489 | R17: ='Balance Sheet'!R37/'Balance Sheet'!R61 -> 0.80082661 | S17: ='Balance Sheet'!S37/'Balance Sheet'!S61 -> 0.79243589 | T17: ='Balance Sheet'!T37/'Balance Sheet'!T61 -> 0.79075575 | U17: ='Balance Sheet'!U37/'Balance Sheet'!U61 -> 0.79779586 | V17: ='Balance Sheet'!V37/'Balance Sheet'!V61 -> 0.78077091 | X17: Other equity | Y17: ='Balance Sheet'!Y34/'Balance Sheet'!Y59 -> 0.48560886 | Z17: ='Balance Sheet'!Z34/'Balance Sheet'!Z59 -> 0.4502796 | AA17: ='Balance Sheet'!AA34/'Balance Sheet'!AA59 -> 0.43474568 | AB17: ='Balance Sheet'!AB34/'Balance Sheet'!AB59 -> 0.43525885 | AC17: ='Balance Sheet'!AC34/'Balance Sheet'!AC59 -> 0.29489699 | AD17: ='Balance Sheet'!AD34/'Balance Sheet'!AD59 -> 0.28378478 | AF17: Other equity | AG17: ='Balance Sheet'!AG36/'Balance Sheet'!AG60 -> 0.42715756 | AH17: ='Balance Sheet'!AH36/'Balance Sheet'!AH60 -> 0.39790137 | AI17: ='Balance Sheet'!AI36/'Balance Sheet'!AI60 -> 0.30137768 | AJ17: ='Balance Sheet'!AJ36/'Balance Sheet'!AJ60 -> 0.31676428 | AK17: ='Balance Sheet'!AK36/'Balance Sheet'!AK60 -> 0.56301742 | AL17: ='Balance Sheet'!AL36/'Balance Sheet'!AL60 -> 0.57605068 | AN17: Other equity | AO17: ='Balance Sheet'!AO32/'Balance Sheet'!AO55 -> 0.38248368 | AP17: ='Balance Sheet'!AP32/'Balance Sheet'!AP55 -> 0.38114185 | AQ17: ='Balance Sheet'!AQ32/'Balance Sheet'!AQ55 -> 0.38404125 | AR17: ='Balance Sheet'!AR32/'Balance Sheet'!AR55 -> 0.41396031 | AS17: ='Balance Sheet'!AS32/'Balance Sheet'!AS55 -> 0.68845441
A18: Total equity | B18: ='Balance Sheet'!B35/'Balance Sheet'!B56 -> 0.91750473 | C18: ='Balance Sheet'!C35/'Balance Sheet'!C56 -> 0.89221857 | D18: ='Balance Sheet'!D35/'Balance Sheet'!D56 -> 0.88400493 | E18: ='Balance Sheet'!E35/'Balance Sheet'!E56 -> 0.88802179 | F18: ='Balance Sheet'!F35/'Balance Sheet'!F56 -> 0.88289953 | G18: ='Balance Sheet'!G35/'Balance Sheet'!G56 -> 0.88102157 | I18: Total equity | J18: ='Balance Sheet'!J35/'Balance Sheet'!J53 -> 0.4232648 | K18: ='Balance Sheet'!K35/'Balance Sheet'!K53 -> 0.40916985 | L18: ='Balance Sheet'!L35/'Balance Sheet'!L53 -> 0.69366028 | M18: ='Balance Sheet'!M35/'Balance Sheet'!M53 -> 0.69610165 | N18: ='Balance Sheet'!N35/'Balance Sheet'!N53 -> 0.65507841 | P18: Total equity | Q18: ='Balance Sheet'!Q40/'Balance Sheet'!Q61 -> 0.848562 | R18: ='Balance Sheet'!R40/'Balance Sheet'!R61 -> 0.82219894 | S18: ='Balance Sheet'!S40/'Balance Sheet'!S61 -> 0.81312757 | T18: ='Balance Sheet'!T40/'Balance Sheet'!T61 -> 0.80969233 | U18: ='Balance Sheet'!U40/'Balance Sheet'!U61 -> 0.81556247 | V18: ='Balance Sheet'!V40/'Balance Sheet'!V61 -> 0.7991531 | X18: Total equity | Y18: ='Balance Sheet'!Y37/'Balance Sheet'!Y59 -> 0.49247232 | Z18: ='Balance Sheet'!Z37/'Balance Sheet'!Z59 -> 0.45599319 | AA18: ='Balance Sheet'!AA37/'Balance Sheet'!AA59 -> 0.44036048 | AB18: ='Balance Sheet'!AB37/'Balance Sheet'!AB59 -> 0.44051364 | AC18: ='Balance Sheet'!AC37/'Balance Sheet'!AC59 -> 0.29771791 | AD18: ='Balance Sheet'!AD37/'Balance Sheet'!AD59 -> 0.28597436 | AF18: Total equity | AG18: ='Balance Sheet'!AG39/'Balance Sheet'!AG60 -> 0.44806671 | AH18: ='Balance Sheet'!AH39/'Balance Sheet'!AH60 -> 0.41188526 | AI18: ='Balance Sheet'!AI39/'Balance Sheet'!AI60 -> 0.31192516 | AJ18: ='Balance Sheet'!AJ39/'Balance Sheet'!AJ60 -> 0.3295131 | AK18: ='Balance Sheet'!AK39/'Balance Sheet'!AK60 -> 0.57284742 | AL18: ='Balance Sheet'!AL39/'Balance Sheet'!AL60 -> 0.59273603 | AN18: Total equity | AO18: ='Balance Sheet'!AO35/'Balance Sheet'!AO55 -> 0.42427477 | AP18: ='Balance Sheet'!AP35/'Balance Sheet'!AP55 -> 0.4386048 | AQ18: ='Balance Sheet'!AQ35/'Balance Sheet'!AQ55 -> 0.44981779 | AR18: ='Balance Sheet'!AR35/'Balance Sheet'!AR55 -> 0.46648895 | AS18: ='Balance Sheet'!AS35/'Balance Sheet'!AS55 -> 0.7232847
