Workbook

Sheet Company Profile
A1: Company Profile
A2: Logo | B2: #VALUE! | C2: #VALUE! | D2: #VALUE! | E2: #VALUE! | F2: #VALUE! | G2: #VALUE!
A3: Company Name | B3: #VALUE! | C3: #VALUE! | D3: #VALUE! | E3: #VALUE! | F3: #VALUE! | G3: Reliance Jio Infocomm Limited
A4: Ticker Symbol | B4: {=_FV(B3,"Ticker symbol",TRUE)} -> BHARTIARTL | C4: {=_FV(C3,"Ticker symbol",TRUE)} -> INDUSTOWER | D4: {=_FV(D3,"Ticker symbol",TRUE)} -> RAILTEL | E4: {=_FV(E3,"Ticker symbol",TRUE)} -> 500483 | F4: {=_FV(F3,"Ticker symbol",TRUE)} -> 532822 | G4: ~
A5: Employees | B5: {=_FV(B3,"Employees")} -> 28701 | C5: {=_FV(C3,"Employees")} -> 3732 | D5: {=_FV(D3,"Employees")} -> 530 | E5: {=_FV(E3,"Employees")} -> 13047 | F5: {=_FV(F3,"Employees")} -> 9985 | G5: 90067
A6: Total Subscribers/Tenants | B6: 399560000 | C6: 411200 | D6: 460000 | E6: 7000 | F6: 197700000 | G6: 463780000
A7: Share Price | B7: {=_FV(B3,"Price")} -> 2019.8 | C7: {=_FV(C3,"Price")} -> 398.75 | D7: {=_FV(D3,"Price")} -> 349.25 | E7: {=_FV(E3,"Price")} -> 1849.85 | F7: {=_FV(F3,"Price")} -> 9.51 | G7: ~
A8: Outstanding Shares | B8: {=_FV(B3,"Shares outstanding",TRUE)} -> 6091080000 | C8: {=_FV(C3,"Shares outstanding",TRUE)} -> 2637135000 | D8: {=_FV(D3,"Shares outstanding",TRUE)} -> 320938400 | E8: {=_FV(E3,"Shares outstanding",TRUE)} -> 285000000 | F8: {=_FV(F3,"Shares outstanding",TRUE)} -> 108343000000 | G8: ~
A9: Market Cap | B9: {=_FV(B3,"Market cap",TRUE)} -> 11993430000000 | C9: {=_FV(C3,"Market cap",TRUE)} -> 1056964000000 | D9: {=_FV(D3,"Market cap",TRUE)} -> 112858000000 | E9: {=_FV(E3,"Market cap",TRUE)} -> 527079000000 | F9: {=_FV(F3,"Market cap",TRUE)} -> 1041177000000
A10: Change (%) | B10: {=_FV(B3,"Change (%)",TRUE)} -> 0.009294 | C10: {=_FV(C3,"Change (%)",TRUE)} -> -0.005115 | D10: {=_FV(D3,"Change (%)",TRUE)} -> -0.006825 | E10: {=_FV(E3,"Change (%)",TRUE)} -> 2.703e-05 | F10: {=_FV(F3,"Change (%)",TRUE)} -> -0.010406
A11: Beta | B11: {=_FV(B3,"Beta")} -> 0.7464 | C11: {=_FV(C3,"Beta")} -> 1.0382 | D11: {=_FV(D3,"Beta")} -> 1.3204 | E11: {=_FV(E3,"Beta")} -> 1.4164 | F11: {=_FV(F3,"Beta")} -> 0.9757
A12: Industry | B12: {=_FV(B3,"Industry")} -> Telecommunications Services | C12: {=_FV(C3,"Industry")} -> Telecommunications Services | D12: {=_FV(D3,"Industry")} -> Telecommunications Services | E12: {=_FV(E3,"Industry")} -> Telecommunications Services | F12: {=_FV(F3,"Industry")} -> Telecommunications Services | G12: Telecom & Digital Services
A13: P/E | B13: {=_FV(B3,"P/E",TRUE)} -> 30.35 | C13: {=_FV(C3,"P/E",TRUE)} -> 11.24 | D13: {=_FV(D3,"P/E",TRUE)} -> 34.96 | E13: {=_FV(E3,"P/E",TRUE)} -> 36.91 | F13: 0 | G13: 0
A14: Year Corporated | B14: {=_FV(B3,"Year incorporated",TRUE)} -> 1995 | C14: {=_FV(C3,"Year incorporated",TRUE)} -> 2006 | D14: {=_FV(D3,"Year incorporated",TRUE)} -> 2000 | E14: {=_FV(E3,"Year incorporated",TRUE)} -> 1986 | F14: {=_FV(F3,"Year incorporated",TRUE)} -> 1995 | G14: 2007

Sheet Balance Sheet
A1: Balance Sheet | F1: #VALUE! | N1: #VALUE! | V1: #VALUE! | AD1: #VALUE! | AL1: #VALUE! | AT1: #VALUE!
A2: Particulars | B2: 2020 | C2: 2021 | D2: 2022 | E2: 2023 | F2: 2024 | G2: 2025 | I2: Particulars | J2: 2020 | K2: 2021 | L2: 2022 | M2: 2023 | N2: 2024 | O2: 2025 | Q2: Particulars | R2: 2020 | S2: 2021 | T2: 2022 | U2: 2023 | V2: 2024 | W2: 2025 | Y2: Particulars | Z2: 2020 | AA2: 2021 | AB2: 2022 | AC2: 2023 | AD2: 2024 | AE2: 2025 | AG2: Particulars | AH2: 2020 | AI2: 2021 | AJ2: 2022 | AK2: 2023 | AL2: 2024 | AM2: 2025 | AO2: Particulars | AP2: 2020 | AQ2: 2021 | AR2: 2022 | AS2: 2023 | AT2: 2024 | AU2: 2025
A3: Non-Current assets | I3: Non-Current assets | Q3: Non-Current assets | Y3: Non-Current assets | AG3: Non-Current assets | AO3: Non-Current Assets
A4: Property, plant and equipment | B4: 54828.6 | C4: 55567.6 | D4: 63795 | E4: 65083.7 | F4: 106612.1 | G4: 143272.4 | I4: Property, plant and equipment | J4: 5070.2 | K4: 21581.9 | L4: 20869.9 | M4: 21172.3 | N4: 26649.3 | O4: 29408.2 | Q4: Property, plant and equipment | R4: 608.54 | S4: 576.58 | T4: 601.49 | U4: 646.83 | V4: 740.33 | W4: 898.56 | Y4: Property, plant and equipment | Z4: 9021.91 | AA4: 8209.78 | AB4: 7768.61 | AC4: 7459.8 | AD4: 7429.73 | AE4: 7637.93 | AG4: Property, plant and equipment | AH4: 66311.3 | AI4: 57570.4 | AJ4: 53632.7 | AK4: 59821.1 | AL4: 52176 | AM4: 56195.6 | AO4: Property, plant and equipment | AP4: 102864 | AQ4: 115146 | AR4: 132910 | AS4: 146010 | AT4: 146635 | AU4: 184757
A5: Capital work-in-progress | B5: 1233.2 | C5: 1283.1 | D5: 1714.9 | E5: 6959.8 | F5: 8907.7 | G5: 10596.2 | I5: Right-of-use assets | J5: 1631.9 | K5: 10211 | L5: 10921 | M5: 11188.2 | N5: 12637.7 | O5: 14933.7 | Q5: Capital work-in-progress | R5: 252.54 | S5: 214.84 | T5: 163.26 | U5: 156.93 | V5: 129.59 | W5: 123.71 | Y5: Capital work-in-progress | Z5: 285.95 | AA5: 394.46 | AB5: 778.68 | AC5: 1003.37 | AD5: 1176.53 | AE5: 1005.13 | AG5: Capital work-in-progress | AH5: 1041.5 | AI5: 599.6 | AJ5: 323.9 | AK5: 300.3 | AL5: 638.8 | AM5: 2471.6 | AO5: Capital work-in-progress | AP5: 21176 | AQ5: 16888 | AR5: 20161 | AS5: 44758 | AT5: 77862 | AU5: 56866
A6: Right-of-use assets | B6: 34502.8 | C6: 34836.9 | D6: 21968.2 | E6: 39702.6 | F6: 55936.7 | G6: 60241.5 | I6: Capital work-in-progress | J6: 54.5 | K6: 273.6 | L6: 178.7 | M6: 354.6 | N6: 421.9 | O6: 567.2 | Q6: Right-of-use assets | R6: 172.96 | S6: 170.26 | T6: 165.02 | U6: 169 | V6: 167.02 | W6: 169 | Y6: Right-of-use assets | Z6: 1595.62 | AA6: 1333.67 | AB6: 1148.76 | AC6: 996.8 | AD6: 1103.49 | AE6: 1430.42 | AG6: Right-of-use assets | AH6: 0 | AI6: 0 | AJ6: 0 | AK6: 0 | AL6: 0 | AM6: 0 | AO6: Intangible assets | AP6: 60563 | AQ6: 56008 | AR6: =79692+4787 -> 84479 | AS6: =75339+4704 -> 80043 | AT6: =69852+3787 -> 73639 | AU6: =147122+4376 -> 151498
A7: Goodwill | B7: 73.9 | C7: 73.9 | D7: 108.3 | E7: 108.3 | F7: 26501.7 | G7: 51697.4 | I7: Intangible assets | J7: 12 | K7: 7.3 | L7: 35.2 | M7: 23.1 | N7: 13.2 | O7: 38 | Q7: Intangible assets | R7: 7.85 | S7: 13.07 | T7: 8.41 | U7: 5.48 | V7: 5.98 | W7: 13.3 | Y7: Investment property | Z7: 280.26 | AA7: 276.94 | AB7: 376.47 | AC7: 397.01 | AD7: 385.71 | AE7: 194.98 | AG7: Investment property | AH7: 66 | AI7: 0 | AJ7: 0 | AK7: 0 | AL7: 0 | AM7: 0 | AO7: Intangible assets under development | AP7: 82 | AQ7: 93 | AR7: =28626+63 -> 28689 | AS7: =122357+256 -> 122613 | AT7: =129602+449 -> 130051 | AU7: =54176 -> 54176
A8: Other intangible assets | B8: 72274 | C8: 66910 | D8: 77864.2 | E8: 82514.5 | F8: 114252.6 | G8: 133256.9 | I8: Investment in joint venture | J8: 5731.8 | K8: 0 | L8: 0 | M8: 0 | N8: 0 | O8: 0 | Q8: Investments | R8: 0 | S8: 0 | T8: 0 | U8: 0 | V8: 0 | W8: 0 | Y8: Investment property under development | Z8: 97.74 | AA8: 116.21 | AB8: 19.8 | AC8: 0 | AD8: 0 | AE8: 0 | AG8: Intangible assets | AH8: 119459.2 | AI8: 109920 | AJ8: 103185.9 | AK8: 96434.1 | AL8: 87948.8 | AM8: 85124 | AO8: Investments | AP8: 1108 | AQ8: 1108 | AR8: 59 | AS8: 37 | AT8: 1108 | AU8: 1108
A9: Intangible assets under development | B9: 25.5 | C9: 23.2 | D9: 1670.8 | E9: 33595.9 | F9: 7996.4 | G9: 402.7 | I9: Investment | J9: 1700.2 | K9: 0 | L9: 0 | M9: 0 | N9: 2.8 | O9: 0 | Q9: Loans and Security deposits | R9: 3.32 | S9: 4.82 | T9: 0 | U9: 0 | V9: 0 | W9: 0 | Y9: Goodwill | Z9: 91.84 | AA9: 110.33 | AB9: 108.28 | AC9: 115.05 | AD9: 1783.73 | AE9: 1932.52 | AG9: Intangible assets under development | AH9: 96.6 | AI9: 6.3 | AJ9: 40.4 | AK9: 17576.1 | AL9: 17550.3 | AM9: 15740.6 | AO9: Other Financial assets | AP9: 3 | AQ9: 10 | AR9: 32 | AS9: 8 | AT9: 10 | AU9: 5
A10: Investments in subsidiaries, associates and Joint Ventures | B10: 30046.6 | C10: 33513.3 | D10: 45897.4 | E10: 43115 | F10: 31240.4 | G10: 3641.6 | I10: Other financial assets | J10: 145 | K10: 1053.3 | L10: 1101.2 | M10: 1175.2 | N10: 1323.3 | O10: 1465.3 | Q10: Other Non-current financial assets | R10: 219.3 | S10: 58.78 | T10: 339.83 | U10: 233.57 | V10: 434.16 | W10: 96.68 | Y10: Other intangible assets | Z10: 1680.81 | AA10: 1472.68 | AB10: 1514.23 | AC10: 1530.92 | AD10: 2764.75 | AE10: 2723.1 | AG10: Investments accounted for using the equity method | AH10: 1524.4 | AI10: 4.1 | AJ10: 5.3 | AK10: 5.8 | AL10: 0.3 | AM10: 0 | AO10: Deferred tax assets (net) | AP10: 1546 | AQ10: 0 | AR10: 0 | AS10: 0 | AT10: 0 | AU10: 0
A11: Investments | B11: 5.2 | C11: 15015.4 | D11: 31.2 | E11: 56.5 | F11: 92.4 | G11: 543.5 | I11: Income tax assets (net) | J11: 75.7 | K11: 728.2 | L11: 684.4 | M11: 725.1 | N11: 771.5 | O11: 856.1 | Q11: Deferred tax assets (net) | R11: 0 | S11: 24.23 | T11: 24.94 | U11: 31.2 | V11: 45.3 | W11: 66.15 | Y11: Intangible assets under development | Z11: 62.91 | AA11: 98.46 | AB11: 73.78 | AC11: 144.69 | AD11: 150.5 | AE11: 94.79 | AG11: Other non-current financial assets | AH11: 8245.9 | AI11: 7732.3 | AJ11: 8849.2 | AK11: 8850.1 | AL11: 7100.2 | AM11: 728 | AO11: Other non-current assets | AP11: 25920 | AQ11: 38401 | AR11: 24058 | AS11: 23895 | AT11: 25009 | AU11: 25729
A12: Derivative instruments | B12: 3.9 | C12: 0 | D12: 0 | E12: 8.1 | F12: 6.5 | G12: 0 | I12: Deferred tax assets (net) | J12: 133.1 | K12: 0 | L12: 0 | M12: 1221.8 | N12: 1075.6 | O12: 2.3 | Q12: Other non-current assets | R12: 18.06 | S12: 0.25 | T12: 0.68 | U12: 0.32 | V12: 3.04 | W12: 7.37 | Y12: Investments | AG12: Deferred tax assets (net) | AH12: 2 | AI12: 2.3 | AJ12: 6 | AK12: 13.5 | AL12: 13.8 | AM12: 11.6 | AO12: Total non-current assets | AP12: =SUM(AP4:AP11) -> 213262 | AQ12: =SUM(AQ4:AQ11) -> 227654 | AR12: =SUM(AR4:AR11) -> 290388 | AS12: =SUM(AS4:AS11) -> 417364 | AT12: =SUM(AT4:AT11) -> 454314 | AU12: =SUM(AU4:AU11) -> 474139
A13: Trade receivables | B13: 0 | C13: 0 | D13: 0 | E13: 0 | F13: 180.5 | G13: 213.1 | I13: Other non-current assets | J13: 248.2 | K13: 1458.6 | L13: 1865.9 | M13: 2004.5 | N13: 2482.3 | O13: 2969.6 | Q13: Total non-current assets | R13: =SUM(R4:R12) -> 1282.57 | S13: =SUM(S4:S12) -> 1062.83 | T13: =SUM(T4:T12) -> 1303.63 | U13: =SUM(U4:U12) -> 1243.33 | V13: =SUM(V4:V12) -> 1525.42 | W13: =SUM(W4:W12) -> 1374.77 | Y13: Investments in associates | Z13: 686.5 | AA13: 718.69 | AB13: 895.1 | AC13: 1019.69 | AD13: 1306.83 | AE13: 1630.75 | AG13: Other non-current assets | AH13: 13486.6 | AI13: 13546.1 | AJ13: 11150.2 | AK13: 10338.8 | AL13: 6659.7 | AM13: 6555.7 | AO13: Current assets
A14: Loans and security deposits | B14: 18725.2 | C14: 576.4 | D14: 1684 | E14: 1722.8 | F14: 0 | G14: 86.5 | I14: Total Non-current assets | J14: =SUM(J4:J13) -> 14802.6 | K14: =SUM(K4:K13) -> 35313.9 | L14: =SUM(L4:L13) -> 35656.3 | M14: =SUM(M4:M13) -> 37864.8 | N14: =SUM(N4:N13) -> 45377.6 | O14: =SUM(O4:O13) -> 50240.4 | Q14: Current Assets | Y14: Other investments | Z14: 214.82 | AA14: 232.24 | AB14: 237.33 | AC14: 171.3 | AD14: 152.11 | AE14: 167.48 | AG14: Total non-current assets | AH14: =SUM(AH4:AH13) -> 210233.5 | AI14: =SUM(AI4:AI13) -> 189381.1 | AJ14: =SUM(AJ4:AJ13) -> 177193.6 | AK14: =SUM(AK4:AK13) -> 193339.8 | AL14: =SUM(AL4:AL13) -> 172087.9 | AM14: =SUM(AM4:AM13) -> 166827.1 | AO14: Investments | AP14: 1381 | AQ14: 420 | AR14: 555 | AS14: 590 | AT14: 2523 | AU14: 19257
A15: Others | B15: 1272.1 | C15: 1114.1 | D15: 0 | E15: 0 | F15: 2655.7 | G15: 3747.1 | I15: Current Assets | Q15: Inventories | R15: 0.49 | S15: 1.21 | T15: 0.94 | U15: 0.92 | V15: 3.01 | W15: 0.01 | Y15: Other financial assets | Z15: 119.85 | AA15: 126.78 | AB15: 126.02 | AC15: 146.8 | AD15: 144.02 | AE15: 154.35 | AG15: Current assets | AO15: Trade receivables | AP15: 1609 | AQ15: 1410 | AR15: 4403 | AS15: 2609 | AT15: 1549 | AU15: 955
A16: Income tax assets (net) | B16: 1341 | C16: 1420.6 | D16: 1165.8 | E16: 1354 | F16: 1413.5 | G16: 2497.8 | I16: Inventories | J16: 0 | K16: 0 | L16: 0 | M16: 0 | N16: 0 | O16: 7.6 | Q16: Investments | R16: 0 | S16: 0 | T16: 30.05 | U16: 40.07 | V16: 90.29 | W16: 39.23 | Y16: Deferred tax assets (net) | Z16: 279.86 | AA16: 310.23 | AB16: 217.27 | AC16: 355.17 | AD16: 717.01 | AE16: 806.58 | AG16: Inventories | AH16: 2.5 | AI16: 0.6 | AJ16: 2.3 | AK16: 16.3 | AL16: 1.2 | AM16: 1.1 | AO16: Cash and cash equivalents | AP16: 7066 | AQ16: 178 | AR16: 429 | AS16: 891 | AT16: 967 | AU16: 5929
A17: Deferred tax assets (net) | B17: 22701.4 | C17: 15838.6 | D17: 16017.5 | E17: 14643.9 | F17: 19242.8 | G17: 24911.1 | I17: Investments | J17: 3738.1 | K17: 2271.4 | L17: 1652.1 | M17: 275.6 | N17: 0 | O17: 1486.1 | Q17: Trade receivables | R17: 507.07 | S17: 772.16 | T17: 684.76 | U17: 1048.34 | V17: 1267.79 | W17: 1581.36 | Y17: Non current tax assets | Z17: 1594 | AA17: 1888.71 | AB17: 1369.52 | AC17: 1268.51 | AD17: 1216.99 | AE17: 1187.09 | AG17: Other investments | AH17: 454.8 | AI17: 0 | AJ17: 0 | AK17: 0 | AL17: 0.2 | AM17: 0 | AO17: Other bank balances | AP17: 414 | AQ17: 411 | AR17: 386 | AS17: 408 | AT17: 397 | AU17: 412
A18: Other non-current assets | B18: 4558.1 | C18: 11502.1 | D18: 6032.3 | E18: 6135.1 | F18: 11215.9 | G18: 11663.8 | I18: Trade receivables | J18: 367.2 | K18: 3828.5 | L18: 7058.6 | M18: 4868.7 | N18: 6450.7 | O18: 4767.5 | Q18: Cash and cash equivalents | R18: 134.52 | S18: 250.97 | T18: 187.11 | U18: 187.97 | V18: 247.65 | W18: 308.04 | Y18: Other non-current assets | Z18: 207.29 | AA18: 207.09 | AB18: 164.29 | AC18: 132.52 | AD18: 231.01 | AE18: 380.68 | AG18: Trade receivables | AH18: 3094.3 | AI18: 2507 | AJ18: 2443.9 | AK18: 2164 | AL18: 2194.8 | AM18: 2000.3 | AO18: Other Financial assets | AP18: 1067 | AQ18: 614 | AR18: 3645 | AS18: 3978 | AT18: 1567 | AU18: 2463
A19: Total Non-current assets | B19: =SUM(B4:B18) -> 241591.5 | C19: =SUM(C4:C18) -> 237675.2 | D19: =SUM(D4:D18) -> 237949.6 | E19: =SUM(E4:E18) -> 295000.2 | F19: =SUM(F4:F18) -> 386254.9 | G19: =SUM(G4:G18) -> 446771.6 | I19: Cash and cash equivalents | J19: 145.2 | K19: 14.5 | L19: 980.2 | M19: 22.4 | N19: 63.1 | O19: 149.7 | Q19: Other bank balances | R19: 133.91 | S19: 337.44 | T19: 140.98 | U19: 84.68 | V19: 237.5 | W19: 218.34 | Y19: Total non-current assets | Z19: =SUM(Z4:Z18) -> 16219.36 | AA19: =SUM(AA4:AA18) -> 15496.27 | AB19: =SUM(AB4:AB18) -> 14798.14 | AC19: =SUM(AC4:AC18) -> 14741.63 | AD19: =SUM(AD4:AD18) -> 18562.41 | AE19: =SUM(AE4:AE18) -> 19345.8 | AG19: Cash and cash equivalents | AH19: 370.8 | AI19: 350.3 | AJ19: 1453.2 | AK19: 228.8 | AL19: 167.8 | AM19: 256.8 | AO19: Other current assets | AP19: 16906 | AQ19: 19402 | AR19: 19917 | AS19: 22041 | AT19: 26088 | AU19: 20927
A20: Current Assets | I20: Other bank balances | J20: 1.8 | K20: 0 | L20: 0 | M20: 0 | N20: 0 | O20: 1706.4 | Q20: Loans and advances | R20: 4.87 | S20: 5.3 | T20: 0.37 | U20: 0.21 | V20: 0.15 | W20: 0.34 | Y20: Current assets | AG20: Bank balances other than above | AH20: 2292.2 | AI20: 1866.2 | AJ20: 2043.4 | AK20: 626.6 | AL20: 368.4 | AM20: 10311.7 | AO20: Total current assets | AP20: =SUM(AP14:AP19) -> 28443 | AQ20: =SUM(AQ14:AQ19) -> 22435 | AR20: =SUM(AR14:AR19) -> 29335 | AS20: =SUM(AS14:AS19) -> 30517 | AT20: =SUM(AT14:AT19) -> 33091 | AU20: =SUM(AU14:AU19) -> 49943
A21: Inventories | B21: 3.1 | C21: 0.8 | D21: 0.4 | E21: 0 | F21: 363.9 | G21: 451.7 | I21: Other financial assets | J21: 446.6 | K21: 2955.9 | L21: 2375.5 | M21: 3251.8 | N21: 3576.8 | O21: 3883.9 | Q21: Other current financial assets | R21: 213.52 | S21: 136.07 | T21: 346.37 | U21: 471.55 | V21: 401.76 | W21: 1175.64 | Y21: Inventories | Z21: 72.97 | AA21: 34.44 | AB21: 37.88 | AC21: 160 | AD21: 83.54 | AE21: 157.84 | AG21: Loans to joint ventures and others | AH21: 0.9 | AI21: 0.9 | AJ21: 0 | AK21: 0 | AL21: 0 | AM21: 0 | AO21: Total Assets | AP21: =AP12+AP20 -> 241705 | AQ21: =AQ12+AQ20 -> 250089 | AR21: =AR12+AR20 -> 319723 | AS21: =AS12+AS20 -> 447881 | AT21: =AT12+AT20 -> 487405 | AU21: =AU12+AU20 -> 524082
A22: Investments | B22: 8675 | C22: 3744.3 | D22: 797.4 | E22: 3519.9 | F22: 269.5 | G22: 1653.2 | I22: Other current assets | J22: 252.4 | K22: 559.5 | L22: 244.9 | M22: 289.1 | N22: 399.4 | O22: 928.6 | Q22: Current tax assets (net) | R22: 27.48 | S22: 16.29 | T22: 15.45 | U22: 15.44 | V22: 22.5 | W22: 8.58 | Y22: Other investments | Z22: 661.78 | AA22: 1282.43 | AB22: 432.8 | AC22: 759.56 | AD22: 149.28 | AE22: 915.7 | AG22: Other current financial assets | AH22: 2303.3 | AI22: 211.7 | AJ22: 7.56 | AK22: 3.94 | AL22: 53.4 | AM22: 6926.2 | AO22: Equity and Liabilities
A23: Derivative instruments | B23: 189.7 | C23: 2.8 | D23: 31.6 | E23: 96.3 | F23: 116.8 | G23: 81.3 | I23: Total current assets | J23: =SUM(J16:J22) -> 4951.3 | K23: =SUM(K16:K22) -> 9629.8 | L23: =SUM(L16:L22) -> 12311.3 | M23: =SUM(M16:M22) -> 8707.6 | N23: =SUM(N16:N22) -> 10490 | O23: =SUM(O16:O22) -> 12929.8 | Q23: Other current assets | R23: 93.66 | S23: 127.66 | T23: 148.51 | U23: 246.63 | V23: 253.51 | W23: 454.9 | Y23: Trade receivables | Z23: 3228.87 | AA23: 2607.68 | AB23: 2582.13 | AC23: 2734.99 | AD23: 3758.36 | AE23: 4006.1 | AG23: Other current assets | AH23: 8167.3 | AI23: 9097.5 | AJ23: 10214 | AK23: 10778.5 | AL23: 10068.8 | AM23: 11543.4 | AO23: Equity
A24: Trade receivables | B24: 3810 | C24: 3178.2 | D24: 2771.7 | E24: 2116.5 | F24: 4727.7 | G24: 7455.7 | I24: Total assets | J24: =J14+J23 -> 19753.9 | K24: =K14+K23 -> 44943.7 | L24: =L14+L23 -> 47967.6 | M24: =M14+M23 -> 46572.4 | N24: =N14+N23 -> 55867.6 | O24: =O14+O23 -> 63170.2 | Q24: Total current assets | R24: =SUM(R15:R23) -> 1115.52 | S24: =SUM(S15:S23) -> 1647.1 | T24: =SUM(T15:T23) -> 1554.54 | U24: =SUM(U15:U23) -> 2095.81 | V24: =SUM(V15:V23) -> 2524.16 | W24: =SUM(W15:W23) -> 3786.44 | Y24: Cash and cash equivalents | Z24: 850 | AA24: 817.85 | AB24: 696.86 | AC24: 1004.48 | AD24: 732.05 | AE24: 533.9 | AG24: Current tax assets (net) | AH24: 0 | AI24: 0 | AJ24: 603.1 | AK24: 0 | AL24: 5.9 | AM24: 0 | AO24: Equity share capital | AP24: 45000 | AQ24: 45000 | AR24: 45000 | AS24: 45000 | AT24: 45000 | AU24: 45000
A25: Cash and cash equivalents | B25: 3366.8 | C25: 992.8 | D25: 310.2 | E25: 1392.5 | F25: 6915.5 | G25: 6105.6 | I25: Equity and Liabilities | Q25: Total Assets | R25: =R13+R24 -> 2398.09 | S25: =S13+S24 -> 2709.93 | T25: =T13+T24 -> 2858.17 | U25: =U13+U24 -> 3339.14 | V25: =V13+V24 -> 4049.58 | W25: =W13+W24 -> 5161.21 | Y25: Bank balances other than above | Z25: 59.13 | AA25: 109.25 | AB25: 46.53 | AC25: 58.09 | AD25: 110.4 | AE25: 53.51 | AG25: Assets classified as held for sale | AH25: 0 | AI25: 65.3 | AJ25: 0 | AK25: 49.3 | AL25: 49.3 | AM25: 0 | AO25: Other equity | AP25: 125956 | AQ25: 137973 | AR25: 153089 | AS25: 171519 | AT25: 191369 | AU25: 216377
A26: Other bank balances | B26: 30.8 | C26: 43.7 | D26: 31.2 | E26: 50.5 | F26: 9424.4 | G26: 10614.3 | I26: Equity | Q26: Equity and Liabilities | Y26: Other financial assets | Z26: 139.76 | AA26: 109.03 | AB26: 105.98 | AC26: 146.4 | AD26: 155.75 | AE26: 255.54 | AG26: Total current assets | AH26: =SUM(AH16:AH25) -> 16686.1 | AI26: =SUM(AI16:AI25) -> 14099.5 | AJ26: =SUM(AJ16:AJ25) -> 16767.46 | AK26: =SUM(AK16:AK25) -> 13867.44 | AL26: =SUM(AL16:AL25) -> 12909.8 | AM26: =SUM(AM16:AM25) -> 31039.5 | AO26: Total equity | AP26: =SUM(AP24:AP25) -> 170956 | AQ26: =SUM(AQ24:AQ25) -> 182973 | AR26: =SUM(AR24:AR25) -> 198089 | AS26: =SUM(AS24:AS25) -> 216519 | AT26: =SUM(AT24:AT25) -> 236369 | AU26: =SUM(AU24:AU25) -> 261377
A27: Loans | B27: 758 | C27: 1566.9 | D27: 1128.8 | E27: 4176.3 | F27: 0 | G27: 0 | I27: Equity share capital | J27: 1849.6 | K27: 2694.9 | L27: 2694.9 | M27: 2694.9 | N27: 2694.9 | O27: 2638.1 | Q27: Equity | Y27: Other current assets | Z27: 805.82 | AA27: 746.22 | AB27: 815.32 | AC27: 691.12 | AD27: 899.01 | AE27: 1261.1 | AG27: Total assets | AH27: =AH14+AH26 -> 226919.6 | AI27: =AI14+AI26 -> 203480.6 | AJ27: =AJ14+AJ26 -> 193961.06 | AK27: =AK14+AK26 -> 207207.24 | AL27: =AL14+AL26 -> 184997.7 | AM27: =AM14+AM26 -> 197866.6 | AO27: Non-Current Liabilities
A28: Others | B28: 24377.2 | C28: 19670 | D28: 19495 | E28: 20083.6 | F28: 24954.4 | G28: 26766.2 | I28: Other Equity | J28: 11692.7 | K28: 13182.1 | L28: 19455.6 | M28: 18414.6 | N28: 24343.9 | O28: 29860.2 | Q28: Equity share capital | R28: 320.94 | S28: 320.94 | T28: 320.94 | U28: 320.94 | V28: 320.94 | W28: 320.94 | Y28: Assets classified for sale | Z28: 123.78 | AA28: 130.24 | AB28: 152.28 | AC28: 256.35 | AD28: 110.54 | AE28: 54.99 | AG28: Equity and Liabilities | AO28: Borrowings | AP28: 0 | AQ28: 364 | AR28: 16162 | AS28: 22732 | AT28: 42373 | AU28: 44244
A29: Other current assets | B29: 17570.7 | C29: 10872.4 | D29: 8724.9 | E29: 9141.4 | F29: 11503.9 | G29: 14460.8 | I29: Total Equity | J29: =SUM(J27:J28) -> 13542.3 | K29: =SUM(K27:K28) -> 15877 | L29: =SUM(L27:L28) -> 22150.5 | M29: =SUM(M27:M28) -> 21109.5 | N29: =SUM(N27:N28) -> 27038.8 | O29: =SUM(O27:O28) -> 32498.3 | Q29: Other Equity | R29: 1048.39 | S29: 1091.88 | T29: 1205.77 | U29: 1327.94 | V29: 1506.3 | W29: 1678.68 | Y29: Total current assets | Z29: =SUM(Z21:Z28) -> 5942.11 | AA29: =SUM(AA21:AA28) -> 5837.14 | AB29: =SUM(AB21:AB28) -> 4869.78 | AC29: =SUM(AC21:AC28) -> 5810.99 | AD29: =SUM(AD21:AD28) -> 5998.93 | AE29: =SUM(AE21:AE28) -> 7238.68 | AG29: Equity | AO29: Lease Liabilities | AP29: 0 | AQ29: 0 | AR29: 7952 | AS29: 10302 | AT29: 9413 | AU29: 8707
A30: Total Current assets | B30: =SUM(B21:B29) -> 58781.3 | C30: =SUM(C21:C29) -> 40071.9 | D30: =SUM(D21:D29) -> 33291.2 | E30: =SUM(E21:E29) -> 40577 | F30: =SUM(F21:F29) -> 58276.1 | G30: =SUM(G21:G29) -> 67588.8 | I30: Non-Current Liabilities | Q30: Total Equity | R30: =SUM(R28:R29) -> 1369.33 | S30: =SUM(S28:S29) -> 1412.82 | T30: =SUM(T28:T29) -> 1526.71 | U30: =SUM(U28:U29) -> 1648.88 | V30: =SUM(V28:V29) -> 1827.24 | W30: =SUM(W28:W29) -> 1999.62 | Y30: Total Assets | Z30: =Z19+Z29 -> 22161.47 | AA30: =AA19+AA29 -> 21333.41 | AB30: =AB19+AB29 -> 19667.92 | AC30: =AC19+AC29 -> 20552.62 | AD30: =AD19+AD29 -> 24561.34 | AE30: =AE19+AE29 -> 26584.48 | AG30: Equity share capital | AH30: 28735.4 | AI30: 28735.4 | AJ30: 32118.8 | AK30: 48679.7 | AL30: 50119.8 | AM30: 71393 | AO30: Other Financial Liabilities | AP30: 13490 | AQ30: 15145 | AR30: 6225 | AS30: 5091 | AT30: 4461 | AU30: 5156
A31: Total Assets | B31: =B19+B30 -> 300372.8 | C31: =C19+C30 -> 277747.1 | D31: =D19+D30 -> 271240.8 | E31: =E19+E30 -> 335577.2 | F31: =F19+F30 -> 444531 | G31: =G19+G30 -> 514360.4 | I31: Borrowings | J31: 0 | K31: 1505.1 | L31: 2373.9 | M31: 2434 | N31: 1504.4 | O31: 153.2 | Q31: Non-Current Liabilities | Y31: Equity and Liabilities | AG31: Other equity | AH31: -22755.5 | AI31: -66963.4 | AJ31: -94083.6 | AK31: -123038.8 | AL31: -154286.6 | AM31: -141713.2 | AO31: Deferred payment liabilities | AP31: 18839 | AQ31: 18837 | AR31: 37184 | AS31: 112844 | AT31: 108270 | AU31: 104410
A32: Equity and Liabilities | I32: Lease Liabilities | J32: 1967.4 | K32: 11232.7 | L32: 12087.7 | M32: 12420.6 | N32: 13820.2 | O32: 16325.7 | Q32: Borrowings | R32: 0 | S32: 0 | T32: 0 | U32: 0 | V32: 0 | W32: 0 | Y32: Equity | AG32: Non-controlling interests | AH32: 0 | AI32: 0 | AJ32: 0 | AK32: 0 | AL32: 0 | AM32: 0 | AO32: Deferred tax liabilities (net) | AP32: 0 | AQ32: 2526 | AR32: 7606 | AS32: 13861 | AT32: 20784 | AU32: 29357
A33: Equity | I33: Other financial liabilities | J33: 63.5 | K33: 523.6 | L33: 570.8 | M33: 382.4 | N33: 392.3 | O33: 397.8 | Q33: Lease Liabilities | R33: 34.8 | S33: 22.17 | T33: 23.49 | U33: 36.27 | V33: 35.36 | W33: 35.25 | Y33: Equity share capital | Z33: 285 | AA33: 285 | AB33: 285 | AC33: 285 | AD33: 285 | AE33: 285 | AG33: Total equity | AH33: =SUM(AH30:AH32) -> 5979.9 | AI33: =SUM(AI30:AI32) -> -38228 | AJ33: =SUM(AJ30:AJ32) -> -61964.8 | AK33: =SUM(AK30:AK32) -> -74359.1 | AL33: =SUM(AL30:AL32) -> -104166.8 | AM33: =SUM(AM30:AM32) -> -70320.2 | AO33: Provisions | AP33: 0 | AQ33: 0 | AR33: 99 | AS33: 124 | AT33: 127 | AU33: 132
A34: Equity share capital | B34: 2727.8 | C34: 2746 | D34: 2795 | E34: 2836.6 | F34: 2876.6 | G34: 2900.1 | I34: Provisions | J34: 302.3 | K34: 1566.6 | L34: 1719.8 | M34: 1873.8 | N34: 2159.2 | O34: 2465.6 | Q34: Other non current financial liabilities | R34: 7.4 | S34: 30.14 | T34: 38.59 | U34: 52.32 | V34: 27.91 | W34: 79.68 | Y34: Other equity | Z34: -1563.36 | AA34: -169.54 | AB34: 642.59 | AC34: 1233.26 | AD34: 1501.42 | AE34: 2736.17 | AG34: Non-current liabilities | AO34: Other non-current liabilities | AP34: 0 | AQ34: 0 | AR34: 448 | AS34: 788 | AT34: 612 | AU34: 1037
A35: Other Equity | B35: 98701.4 | C35: 74614.1 | D35: 72075.5 | E35: 76156.8 | F35: 79142.2 | G35: 110771.8 | I35: Deferred tax liabilities (net) | J35: 0 | K35: 70.3 | L35: 91.8 | M35: 0 | N35: 0 | O35: 407.2 | Q35: Provisions | R35: 9.9 | S35: 9.83 | T35: 9.51 | U35: 8.69 | V35: 0 | W35: 0 | Y35: Non-controlling interests | Z35: 4.75 | AA35: 28.17 | AB35: 28.49 | AC35: 30.34 | AD35: 3.88 | AE35: 3.11 | AG35: Loans from banks and others | AH35: 8627.9 | AI35: 6484.6 | AJ35: 2836.3 | AK35: 935.1 | AL35: 0 | AM35: 0 | AO35: Total Non-current liabilities | AP35: =SUM(AP28:AP34) -> 32329 | AQ35: =SUM(AQ28:AQ34) -> 36872 | AR35: =SUM(AR28:AR34) -> 75676 | AS35: =SUM(AS28:AS34) -> 165742 | AT35: =SUM(AT28:AT34) -> 186040 | AU35: =SUM(AU28:AU34) -> 193043
A36: Non-controlling interests | B36: 0 | C36: 0 | D36: 0 | E36: 0 | F36: 23545.1 | G36: 39795.8 | I36: Other non-current liabilities | J36: 52.1 | K36: 217.8 | L36: 146.2 | M36: 189.3 | N36: 796.2 | O36: 1135.6 | Q36: Other non current liabilities | R36: 88.69 | S36: 115.12 | T36: 73.41 | U36: 80.54 | V36: 65.22 | W36: 107.16 | Y36: Total equity | Z36: =SUM(Z33:Z35) -> -1273.61 | AA36: =SUM(AA33:AA35) -> 143.63 | AB36: =SUM(AB33:AB35) -> 956.08 | AC36: =SUM(AC33:AC35) -> 1548.6 | AD36: =SUM(AD33:AD35) -> 1790.3 | AE36: =SUM(AE33:AE35) -> 3024.28 | AG36: Deferred payment obligations | AH36: 87652.5 | AI36: 150930.9 | AJ36: 173114.5 | AK36: 188355 | AL36: 202896.2 | AM36: 182768 | AO36: Current Liabilities
A37: Total Equity | B37: =SUM(B34:B36) -> 101429.2 | C37: =SUM(C34:C36) -> 77360.1 | D37: =SUM(D34:D36) -> 74870.5 | E37: =SUM(E34:E36) -> 78993.4 | F37: =SUM(F34:F36) -> 105563.9 | G37: =SUM(G34:G36) -> 153467.7 | I37: Total Non-current liabilities | J37: =SUM(J31:J36) -> 2385.3 | K37: =SUM(K31:K36) -> 15116.1 | L37: =SUM(L31:L36) -> 16990.2 | M37: =SUM(M31:M36) -> 17300.1 | N37: =SUM(N31:N36) -> 18672.3 | O37: =SUM(O31:O36) -> 20885.1 | Q37: Total non current liabilities | R37: =SUM(R33:R36) -> 140.79 | S37: =SUM(S33:S36) -> 177.26 | T37: =SUM(T33:T36) -> 145 | U37: =SUM(U33:U36) -> 177.82 | V37: =SUM(V33:V36) -> 128.49 | W37: =SUM(W33:W36) -> 222.09 | Y37: Non-current liabilities | AG37: Total Long term borrowings | AH37: =AH35+AH36 -> 96280.4 | AI37: =AI35+AI36 -> 157415.5 | AJ37: =AJ35+AJ36 -> 175950.8 | AK37: =AK35+AK36 -> 189290.1 | AL37: =AL35+AL36 -> 202896.2 | AM37: =AM35+AM36 -> 182768 | AO37: Borrowings | AP37: 23242 | AQ37: 10775 | AR37: 26324 | AS37: 12946 | AT37: 10367 | AU37: 26285
A38: Non-Current Liabilities | I38: Current Liabilities | Q38: Current Liabilities | Y38: Borrowings | Z38: 6797.78 | AA38: 8886.39 | AB38: 5990.92 | AC38: 5008.58 | AD38: 4745.73 | AE38: 6996.71 | AG38: Trade payables | AH38: 666 | AI38: 126.8 | AJ38: 85.2 | AK38: 105.8 | AL38: 38.6 | AM38: 0.4 | AO38: Lease Liabilities | AP38: 0 | AQ38: 0 | AR38: 2040 | AS38: 3407 | AT38: 3200 | AU38: 3794
A39: Borrowings | B39: 70471.2 | C39: 89908.8 | D39: 97322.8 | E39: 136230 | F39: 130962.6 | G39: 104863.8 | I39: Borrowings | J39: 2418.4 | K39: 5465.2 | L39: 3112.9 | M39: 2278.6 | N39: 2807.4 | O39: 2109.2 | Q39: Borrowings | R39: 0 | S39: 0 | T39: 0 | U39: 0 | V39: 0 | W39: 0 | Y39: Other financial liabilities | Z39: 33.43 | AA39: 8.79 | AB39: 49.18 | AC39: 132.59 | AD39: 159.74 | AE39: 37.25 | AG39: Lease Liabilities | AH39: 0 | AI39: 0 | AJ39: 11432.5 | AK39: 25061.2 | AL39: 24325 | AM39: 29216.6 | AO39: Total outstanding dues of micro and small enterprises | AP39: 38 | AQ39: 6 | AR39: 27 | AS39: 21 | AT39: 15 | AU39: 45
A40: Lease Liabilities | B40: 30703.9 | C40: 29998.6 | D40: 17435 | E40: 35136.9 | F40: 53927.1 | G40: 55670.1 | I40: Total outstanding dues of micro and small enterprises | J40: 18.9 | K40: 37.4 | L40: 52.2 | M40: 49.4 | N40: 70.2 | O40: 45.3 | Q40: Lease Liabilities | R40: 7.74 | S40: 8.01 | T40: 8.02 | U40: 5.52 | V40: 10.26 | W40: 9.29 | Y40: Lease liabilities | Z40: 1394.02 | AA40: 1153.06 | AB40: 955.72 | AC40: 771.58 | AD40: 822.38 | AE40: 1162.6 | AG40: Other non current financial liabilities | AH40: 27407.3 | AI40: 17281.9 | AJ40: 6846.1 | AK40: 6662.3 | AL40: 7330.1 | AM40: 135.8 | AO40: Total outstanding dues other than above | AP40: 4662 | AQ40: 2233 | AR40: 1944 | AS40: 3396 | AT40: 4321 | AU40: 4428
...

Sheet Income Statement
A1: Income Statement | F1: #VALUE! | N1: #VALUE! | V1: #VALUE! | AD1: #VALUE! | AL1: #VALUE! | AT1: #VALUE!
A2: Particulars | B2: 2020 | C2: 2021 | D2: 2022 | E2: 2023 | F2: 2024 | G2: 2025 | I2: Particulars | J2: 2020 | K2: 2021 | L2: 2022 | M2: 2023 | N2: 2024 | O2: 2025 | Q2: Particulars | R2: 2020 | S2: 2021 | T2: 2022 | U2: 2023 | V2: 2024 | W2: 2025 | Y2: Particulars | Z2: 2020 | AA2: 2021 | AB2: 2022 | AC2: 2023 | AD2: 2024 | AE2: 2025 | AG2: Particulars | AH2: 2020 | AI2: 2021 | AJ2: 2022 | AK2: 2023 | AL2: 2024 | AM2: 2025 | AO2: Particulars | AP2: 2020 | AQ2: 2021 | AR2: 2022 | AS2: 2023 | AT2: 2024 | AU2: 2025
A3: Income | I3: Income | Q3: Income | Y3: Income | AG3: Income | AO3: Income
A4: Revenue from Operations | B4: 54317.1 | C4: 64325.9 | D4: 70795 | E4: 84720.1 | F4: 149982.4 | G4: 172985.2 | I4: Revenue from Operations | J4: 6743 | K4: 13954.3 | L4: 27717.2 | M4: 28381.8 | N4: 28600.6 | O4: 30122.8 | Q4: Revenue from operations | R4: 1128.05 | S4: 1377.82 | T4: 1548.45 | U4: 1963.51 | V4: 2567.82 | W4: 3477.5 | Y4: Revenue from Operations | Z4: 17067.99 | AA4: 17100.1 | AB4: 16724.73 | AC4: 17838.26 | AD4: 20784.68 | AE4: 23108.59 | AG4: Service revenue | AH4: 44912.3 | AI4: 41933.1 | AJ4: 38489.5 | AK4: 42133.9 | AL4: 42554.9 | AM4: 43453.7 | AO4: Revenue from operations | AP4: 54316 | AQ4: 69888 | AR4: 77356 | AS4: 91373 | AT4: 100119 | AU4: 114141
A5: Other income | B5: 2242.5 | C5: 2387.9 | D5: 604 | E5: 2633.8 | F5: 1435.4 | G5: 1573.7 | I5: Other income | J5: 128.7 | K5: 196.9 | L5: 352.5 | M5: 361.3 | N5: 361.1 | O5: 345.8 | Q5: Other income | R5: 37.99 | S5: 32.12 | T5: 26.83 | U5: 37.01 | V5: 56.3 | W5: 66.01 | Y5: Other income | Z5: 69.68 | AA5: 156.76 | AB5: 332.09 | AC5: 363.15 | AD5: 264.12 | AE5: 130.3 | AG5: Sale of trading goods | AH5: 4.4 | AI5: 5.1 | AJ5: 8.9 | AK5: 8.7 | AL5: 17.8 | AM5: 2 | AO5: Other income | AP5: 87 | AQ5: 548 | AR5: 229 | AS5: 368 | AT5: 458 | AU5: 947
A6: Total Income | B6: =SUM(B4:B5) -> 56559.6 | C6: =SUM(C4:C5) -> 66713.8 | D6: =SUM(D4:D5) -> 71399 | E6: =SUM(E4:E5) -> 87353.9 | F6: =SUM(F4:F5) -> 151417.8 | G6: =SUM(G4:G5) -> 174558.9 | I6: Total Income | J6: =SUM(J4:J5) -> 6871.7 | K6: =SUM(K4:K5) -> 14151.2 | L6: =SUM(L4:L5) -> 28069.7 | M6: =SUM(M4:M5) -> 28743.1 | N6: =SUM(N4:N5) -> 28961.7 | O6: =SUM(O4:O5) -> 30468.6 | Q6: Finance income | R6: -0.25 | S6: 1.35 | T6: 2.45 | U6: 1.68 | V6: -1.95 | W6: 7.53 | Y6: Total Income | Z6: =SUM(Z4:Z5) -> 17137.67 | AA6: =SUM(AA4:AA5) -> 17256.86 | AB6: =SUM(AB4:AB5) -> 17056.82 | AC6: =SUM(AC4:AC5) -> 18201.41 | AD6: =SUM(AD4:AD5) -> 21048.8 | AE6: =SUM(AE4:AE5) -> 23238.89 | AG6: Other operating income | AH6: 40.8 | AI6: 14 | AJ6: 17.1 | AK6: 34.6 | AL6: 79 | AM6: 115.6 | AO6: Total Income | AP6: =AP4+AP5 -> 54403 | AQ6: =AQ4+AQ5 -> 70436 | AR6: =AR4+AR5 -> 77585 | AS6: =AS4+AS5 -> 91741 | AT6: =AT4+AT5 -> 100577 | AU6: =AU4+AU5 -> 115088
A7: Expenses | I7: Expenses | Q7: Total income | R7: =SUM(R4:R6) -> 1165.79 | S7: =SUM(S4:S6) -> 1411.29 | T7: =SUM(T4:T6) -> 1577.73 | U7: =SUM(U4:U6) -> 2002.2 | V7: =SUM(V4:V6) -> 2622.17 | W7: =SUM(W4:W6) -> 3551.04 | Y7: Expenses | AG7: Other income | AH7: 1039.3 | AI7: 174.2 | AJ7: 129.4 | AK7: 311.3 | AL7: 113.2 | AM7: 1020.6 | AO7: Expenses
A8: Network operating expenses | B8: 13641.9 | C8: 15120.5 | D8: 17187.7 | E8: 18385.7 | F8: 30018.8 | G8: 33504.3 | I8: Cost of material consumed | J8: 0 | K8: 0 | L8: 0 | M8: 0 | N8: 0 | O8: 3.8 | Q8: Expenses | Y8: Network transmission expense | Z8: 6777.56 | AA8: 6333.27 | AB8: 6199.49 | AC8: 6375.49 | AD8: 8078.73 | AE8: 10047.77 | AG8: Total income | AH8: =SUM(AH4:AH7) -> 45996.8 | AI8: =SUM(AI4:AI7) -> 42126.4 | AJ8: =SUM(AJ4:AJ7) -> 38644.9 | AK8: =SUM(AK4:AK7) -> 42488.5 | AL8: =SUM(AL4:AL7) -> 42764.9 | AM8: =SUM(AM4:AM7) -> 44591.9 | AO8: Network Operating expenses | AP8: 16930 | AQ8: 22058 | AR8: 25080 | AS8: 28702 | AT8: 30558 | AU8: 32932
A9: Access charges | B9: 9076.7 | C9: 8564.7 | D9: 3230.9 | E9: 4131.8 | F9: 7518.5 | G9: 7171.3 | I9: Power and fuel | J9: 2367.2 | K9: 5153.6 | L9: 10265.8 | M9: 10590.8 | N9: 11149.9 | O9: 11445 | Q9: Access and other charges | R9: 249.03 | S9: 338.17 | T9: 432.6 | U9: 514.96 | V9: 544.14 | W9: 569.94 | Y9: Employee benefit expense | Z9: 3039.14 | AA9: 3049.09 | AB9: 3040.34 | AC9: 3597.46 | AD9: 4342.82 | AE9: 4557.28 | AG9: Expenses | AO9: Access charges | AP9: 5795 | AQ9: 4631 | AR9: 719 | AS9: 881 | AT9: 1135 | AU9: 1685
A10: License fee/Spectrum charges | B10: 5365.3 | C10: 6789.9 | D10: 8462.3 | E10: 8792.5 | F10: 12035.8 | G10: 13829 | I10: Employee benefit expenses | J10: 293.5 | K10: 512.6 | L10: 772.2 | M10: 774.1 | N10: 782.3 | O10: 841.4 | Q10: License fee and spectrum charges | R10: 47.93 | S10: 56.56 | T10: 66.79 | U10: 77.26 | V10: 82.13 | W10: 99.52 | Y10: Finance costs | Z10: 470.74 | AA10: 420.2 | AB10: 360.25 | AC10: 432.46 | AD10: 630.09 | AE10: 729.06 | AG10: Cost of trading goods | AH10: 3.9 | AI10: 3 | AJ10: 7 | AK10: 7.8 | AL10: 15.6 | AM10: 1.7 | AO10: License fees/Spectrum charges | AP10: 5720 | AQ10: 7755 | AR10: 9074 | AS10: 9132 | AT10: 9213 | AU10: 10494
A11: Employee benefit expenses | B11: 1520.2 | C11: 1664.5 | D11: 1795.4 | E11: 1966.4 | F11: 5323.1 | G11: 6308.9 | I11: Repairs and maintenance | J11: 250.3 | K11: 724.6 | L11: 1346.7 | M11: 1350.6 | N11: 1399.1 | O11: 1441 | Q11: Expenses on project | R11: 340.08 | S11: 414.5 | T11: 459.47 | U11: 754.83 | V11: 1232.33 | W11: 2020.94 | Y11: Depreciation and amortisation expense | Z11: 2357.72 | AA11: 2313.87 | AB11: 2204.54 | AC11: 2261.81 | AD11: 2397.35 | AE11: 2592.1 | AG11: Employee benefit expenses | AH11: 2164.3 | AI11: 2030 | AJ11: 1735.1 | AK11: 1866.3 | AL11: 2122.4 | AM11: 2230.9 | AO11: Employee benefit expenses | AP11: 1463 | AQ11: 1337 | AR11: 1539 | AS11: 1756 | AT11: 1896 | AU11: 1987
A12: Sales and marketing expenses | B12: 1818 | C12: 2064.9 | D12: 3149.7 | E12: 4638.3 | F12: 10788.2 | G12: 11460.1 | I12: Other expenses | J12: 214.4 | K12: 303.6 | L12: 389.6 | M12: 5899.3 | N12: 575.4 | O12: -4453.1 | Q12: Employee benefit expenses | R12: 120.53 | S12: 126.7 | T12: 185.79 | U12: 195.27 | V12: 204.53 | W12: 209.72 | Y12: Operating and other expenses | Z12: 3962.34 | AA12: 3457.16 | AB12: 3258.18 | AC12: 3547.08 | AD12: 4045.93 | AE12: 3934.51 | AG12: Network expenses and IT outsourcing cost | AH12: 10991.6 | AI12: 9593.8 | AJ12: 9818.2 | AK12: 10078.3 | AL12: 9810.4 | AM12: 9439.1 | AO12: Finance costs | AP12: 6617 | AQ12: 3840 | AR12: 4377 | AS12: 4059 | AT12: 3999 | AU12: 4837
A13: Other expenses | B13: 2761.4 | C13: 2137.3 | D13: 2268.5 | E13: 3006.7 | F13: 6006.2 | G13: 7552.4 | I13: Total expenses | J13: =SUM(J8:J12) -> 3125.4 | K13: =SUM(K8:K12) -> 6694.4 | L13: =SUM(L8:L12) -> 12774.3 | M13: =SUM(M8:M12) -> 18614.8 | N13: =SUM(N8:N12) -> 13906.7 | O13: =SUM(O8:O12) -> 9278.1 | Q13: Administrative & other expenses | R13: 31.49 | S13: 109.9 | T13: 34.11 | U13: 35.7 | V13: 35.98 | W13: 38.18 | Y13: Total expenses | Z13: =SUM(Z8:Z12) -> 16607.5 | AA13: =SUM(AA8:AA12) -> 15573.59 | AB13: =SUM(AB8:AB12) -> 15062.8 | AC13: =SUM(AC8:AC12) -> 16214.3 | AD13: =SUM(AD8:AD12) -> 19494.92 | AE13: =SUM(AE8:AE12) -> 21860.72 | AG13: License fees and spectrum usage charges | AH13: 4848.2 | AI13: 4129.5 | AJ13: 4198.8 | AK13: 4002.1 | AL13: 3672.6 | AM13: 3696.2 | AO13: Depreciation and amortisation expense | AP13: 7396 | AQ13: 11534 | AR13: 13702 | AS13: 18641 | AT13: 21394 | AU13: 23098
A14: Total expenses | B14: =SUM(B8:B13) -> 34183.5 | C14: =SUM(C8:C13) -> 36341.8 | D14: =SUM(D8:D13) -> 36094.5 | E14: =SUM(E8:E13) -> 40921.4 | F14: =SUM(F8:F13) -> 71690.6 | G14: =SUM(G8:G13) -> 79826 | I14: EBITDA | J14: =J6-J13 -> 3746.3 | K14: =K6-K13 -> 7456.8 | L14: =L6-L13 -> 15295.4 | M14: =M6-M13 -> 10128.3 | N14: =N6-N13 -> 15055 | O14: =O6-O13 -> 21190.5 | Q14: CSR | R14: 5.19 | S14: 4.9 | T14: 2.78 | U14: 7.01 | V14: 4.84 | W14: 5.73 | Y14: Profit before exceptional items and tax | Z14: =Z6-Z13 -> 530.17 | AA14: =AA6-AA13 -> 1683.27 | AB14: =AB6-AB13 -> 1994.02 | AC14: =AC6-AC13 -> 1987.11 | AD14: =AD6-AD13 -> 1553.88 | AE14: =AE6-AE13 -> 1378.17 | AG14: Roaming and access charges | AH14: 5997.6 | AI14: 5290.6 | AJ14: 2915.5 | AK14: 3899.1 | AL14: 4117.7 | AM14: 4597.4 | AO14: Selling and Distribution expenses | AP14: 1277 | AQ14: 1172 | AR14: 1100 | AS14: 1822 | AT14: 2493 | AU14: 3641
A15: EBITDA | B15: =B6-B14 -> 22376.1 | C15: =C6-C14 -> 30372 | D15: =D6-D14 -> 35304.5 | E15: =E6-E14 -> 46432.5 | F15: =F6-F14 -> 79727.2 | G15: =G6-G14 -> 94732.9 | I15: Depreciation and ammortisation expense | J15: 1321.7 | K15: 2991.3 | L15: 5422.2 | M15: 5441 | N15: 6160 | O15: 6489.9 | Q15: Depreciation, amortisation and impairment | R15: 130.89 | S15: 159.32 | T15: 160.18 | U15: 154.31 | V15: 157.7 | W15: 180.4 | Y15: Exceptional items | Z15: -390.51 | AA15: -74.72 | AB15: 5.96 | AC15: 76.35 | AD15: -235.66 | AE15: 691.47 | AG15: Subscriber acquisition and servicing expenditure | AH15: 2929.9 | AI15: 1767.7 | AJ15: 1971.1 | AK15: 3678 | AL15: 4280.6 | AM15: 4092.3 | AO15: Other expenses | AP15: 1564 | AQ15: 2022 | AR15: 2013 | AS15: 2183 | AT15: 2404 | AU15: 3116
A16: Depreciation and ammortisation expense | B16: 20392.1 | C16: 21997.5 | D16: 24329.8 | E16: 26355 | F16: 39537.6 | G16: 45570.3 | I16: Less: adjusted with general reserve | J16: -40.2 | K16: -142.9 | L16: -97 | M16: -117.1 | N16: -100.1 | O16: -87.8 | Q16: Finance expenses | R16: 6.59 | S16: 4.06 | T16: 5.49 | U16: 6.02 | V16: 5.71 | W16: 3.11 | Y16: Profit before tax and share of profit/loss of associates | Z16: =Z14+Z15 -> 139.66 | AA16: =AA14+AA15 -> 1608.55 | AB16: =AB14+AB15 -> 1999.98 | AC16: =AC14+AC15 -> 2063.46 | AD16: =AD14+AD15 -> 1318.22 | AE16: =AE14+AE15 -> 2069.64 | AG16: Advertisement, business promotion expense and cotent cost | AH16: 1177.4 | AI16: 787.5 | AJ16: 979.1 | AK16: 941.2 | AL16: 564.7 | AM16: 500 | AO16: Total expenses | AP16: =SUM(AP8:AP15) -> 46762 | AQ16: =SUM(AQ8:AQ15) -> 54349 | AR16: =SUM(AR8:AR15) -> 57604 | AS16: =SUM(AS8:AS15) -> 67176 | AT16: =SUM(AT8:AT15) -> 73092 | AU16: =SUM(AU8:AU15) -> 81790
A17: Finance costs | B17: 11463.1 | C17: 11816.7 | D17: 13220.8 | E17: 14531.8 | F17: 22647.7 | G17: 21753.9 | I17: Finance costs | J17: 335 | K17: 836.4 | L17: 1603.3 | M17: 1670.4 | N17: 1863.8 | O17: 1857.9 | Q17: Total expenses | R17: =SUM(R9:R16) -> 931.73 | S17: =SUM(S9:S16) -> 1214.11 | T17: =SUM(T9:T16) -> 1347.21 | U17: =SUM(U9:U16) -> 1745.36 | V17: =SUM(V9:V16) -> 2267.36 | W17: =SUM(W9:W16) -> 3127.54 | Y17: Current tax | Z17: 334.18 | AA17: 406.49 | AB17: 431.31 | AC17: 432.77 | AD17: 601.63 | AE17: 610.53 | AG17: Other expense | AH17: 1932.1 | AI17: 1404.4 | AJ17: 854.6 | AK17: 887.4 | AL17: 941.7 | AM17: 887.1 | AO17: Profit before exceptional items and tax | AP17: =AP6-AP16 -> 7641 | AQ17: =AQ6-AQ16 -> 16087 | AR17: =AR6-AR16 -> 19981 | AS17: =AS6-AS16 -> 24565 | AT17: =AT6-AT16 -> 27485 | AU17: =AU6-AU16 -> 33298
A18: Share of profit of associates and joint ventures (net) | B18: 0 | C18: 0 | D18: 0 | E18: 0 | F18: -2709.4 | G18: -3703 | I18: Finance income | J18: -337 | K18: -199.2 | L18: -106 | M18: -216.5 | N18: -1128.4 | O18: -417.9 | Q18: Profit/Loss before exceptional items and tax | R18: =R7-R17 -> 234.06 | S18: =S7-S17 -> 197.18 | T18: =T7-T17 -> 230.52 | U18: =U7-U17 -> 256.84 | V18: =V7-V17 -> 354.81 | W18: =W7-W17 -> 423.5 | Y18: Deferred tax | Z18: -107.51 | AA18: -51.6 | AB18: 90.82 | AC18: -136.15 | AD18: -388.13 | AE18: -124.04 | AG18: Total Expenses | AH18: =SUM(AH10:AH17) -> 30045 | AI18: =SUM(AI10:AI17) -> 25006.5 | AJ18: =SUM(AJ10:AJ17) -> 22479.4 | AK18: =SUM(AK10:AK17) -> 25360.2 | AL18: =SUM(AL10:AL17) -> 25525.7 | AM18: =SUM(AM10:AM17) -> 25444.7 | AO18: Exceptional items | AP18: 146 | AQ18: 0 | AR18: 0 | AS18: 0 | AT18: 0 | AU18: 0
A19: Profit/Loss before exceptional items and tax | B19: =B15-(B16+B17+B18) -> -9479.1 | C19: =C15-(C16+C17+C18) -> -3442.2 | D19: =D15-(D16+D17+D18) -> -2246.1 | E19: =E15-(E16+E17+E18) -> 5545.7 | F19: =F15-(F16+F17+F18) -> 20251.3 | G19: =G15-(G16+G17+G18) -> 31111.7 | I19: Charity and donation | J19: 59.8 | K19: 80.6 | L19: 42.2 | M19: 98.4 | N19: 137.3 | O19: 194.7 | Q19: Exceptional items | R19: 49.3 | S19: 0 | T19: 50.1 | U19: 2.06 | V19: 26.72 | W19: 21.72 | AG19: EBITDA | AH19: =AH8-AH18 -> 15951.8 | AI19: =AI8-AI18 -> 17119.9 | AJ19: =AJ8-AJ18 -> 16165.5 | AK19: =AK8-AK18 -> 17128.3 | AL19: =AL8-AL18 -> 17239.2 | AM19: =AM8-AM18 -> 19147.2 | AO19: Profit before tax | AP19: =AP17-AP18 -> 7495 | AQ19: =AQ17-AQ18 -> 16087 | AR19: =AR17-AR18 -> 19981 | AS19: =AS17-AS18 -> 24565 | AT19: =AT17-AT18 -> 27485 | AU19: =AU17-AU18 -> 33298
A20: Exceptional items | B20: 41541.8 | C20: 15023 | D20: 2009.6 | E20: 4276.4 | F20: 7572.3 | G20: -7286.8 | I20: Profit before share of profit of joint venture and tax | J20: =J14-(SUM(J15:J19)) -> 2407 | K20: =K14-(SUM(K15:K19)) -> 3890.6 | L20: =L14-(SUM(L15:L19)) -> 8430.7 | M20: =M14-(SUM(M15:M19)) -> 3252.1 | N20: =N14-(SUM(N15:N19)) -> 8122.4 | O20: =O14-(SUM(O15:O19)) -> 13153.7 | Q20: Profit/Loss before tax | R20: =R18-R19 -> 184.76 | S20: =S18-S19 -> 197.18 | T20: =T18-T19 -> 180.42 | U20: =U18-U19 -> 254.78 | V20: =V18-V19 -> 328.09 | W20: =W18-W19 -> 401.78 | Y20: Total tax expense | Z20: =SUM(Z17:Z19) -> 226.67 | AA20: =SUM(AA17:AA19) -> 354.89 | AB20: =SUM(AB17:AB19) -> 522.13 | AC20: =SUM(AC17:AC19) -> 296.62 | AD20: =SUM(AD17:AD19) -> 213.5 | AE20: =SUM(AE17:AE19) -> 486.49 | AG20: Finance costs | AH20: 15392 | AI20: 17998.1 | AJ20: 20980.8 | AK20: 23354.3 | AL20: 25765.5 | AM20: 24543.4 | AO20: Current tax | AP20: 0 | AQ20: 0 | AR20: 58 | AS20: 16 | AT20: 0 | AU20: 0
A21: Profit/Loss before tax | B21: =B19-B20 -> -51020.9 | C21: =C19-C20 -> -18465.2 | D21: =D19-D20 -> -4255.7 | E21: =E19-E20 -> 1269.3 | F21: =F19-F20 -> 12679 | G21: =G19-G20 -> 38398.5 | I21: Share of profit of joint venture | J21: 1380.5 | K21: 866.3 | L21: 0 | M21: -492.8 | N21: 0 | O21: 0 | Q21: Current tax | R21: 55.98 | S21: 83.06 | T21: 72.5 | U21: 71.51 | V21: 96.71 | W21: 121.45 | Y21: Profit/Loss before share in profit/loss of associates | Z21: =Z16-Z20 -> -87.01 | AA21: =AA16-AA20 -> 1253.66 | AB21: =AB16-AB20 -> 1477.85 | AC21: =AC16-AC20 -> 1766.84 | AD21: =AD16-AD20 -> 1104.72 | AE21: =AE16-AE20 -> 1583.15 | AG21: Depreciation | AH21: 15208 | AI21: 14501.3 | AJ21: 14656.9 | AK21: 14258.4 | AL21: 13871.5 | AM21: 13393.7 | AO21: Deferred tax | AP21: 1933 | AQ21: 4072 | AR21: 5069 | AS21: 6250 | AT21: 7019 | AU21: 8503
A22: Current tax | B22: 0 | C22: -131.2 | D22: 0 | E22: -17.8 | F22: 4149.8 | G22: 4112.1 | I22: Profit before tax | J22: =J20+J21 -> 3787.5 | K22: =K20+K21 -> 4756.9 | L22: =L20+L21 -> 8430.7 | M22: =M20+M21 -> 2759.3 | N22: =N20+N21 -> 8122.4 | O22: =O20+O21 -> 13153.7 | Q22: Deferred tax | R22: -13.41 | S22: -27.77 | T22: -0.71 | U22: -6.25 | V22: -0.74 | W22: 1.38 | Y22: Share in profit/loss of associates | Z22: 2.18 | AA22: -2.14 | AB22: 6.82 | AC22: 34.03 | AD22: 19.99 | AE22: 42.54 | AG22: Amortisation | AH22: 9148.4 | AI22: 9137.2 | AJ22: 8927.4 | AK22: 8791.3 | AL22: 8762 | AM22: 8579.5 | AO22: Total tax expenses | AP22: =SUM(AP20:AP21) -> 1933 | AQ22: =SUM(AQ20:AQ21) -> 4072 | AR22: =SUM(AR20:AR21) -> 5127 | AS22: =SUM(AS20:AS21) -> 6266 | AT22: =SUM(AT20:AT21) -> 7019 | AU22: =SUM(AU20:AU21) -> 8503
A23: Deferred tax | B23: -14932.7 | C23: 6863.6 | D23: -392 | E23: 1376.7 | F23: -28.8 | G23: -3194.9 | I23: Current tax | J23: 580.6 | K23: 985.2 | L23: 2037.3 | M23: 2032.7 | N23: 1938.8 | O23: 1740.5 | Q23: Tax impact of earlier years | R23: 1.12 | S23: -0.56 | T23: -0.11 | U23: 0.45 | V23: -14.09 | W23: -20.86 | Y23: Profit/Loss for the period | Z23: =Z21+Z22 -> -84.83 | AA23: =AA21+AA22 -> 1251.52 | AB23: =AB21+AB22 -> 1484.67 | AC23: =AC21+AC22 -> 1800.87 | AD23: =AD21+AD22 -> 1124.71 | AE23: =AE21+AE22 -> 1625.69 | AG23: Profit before share of profit/loss of joint ventures and associate, exceptional items and tax | AH23: =AH19-(SUM(AH20:AH22)) -> -23796.6 | AI23: =AI19-(SUM(AI20:AI22)) -> -24516.7 | AJ23: =AJ19-(SUM(AJ20:AJ22)) -> -28399.6 | AK23: =AK19-(SUM(AK20:AK22)) -> -29275.7 | AL23: =AL19-(SUM(AL20:AL22)) -> -31159.8 | AM23: =AM19-(SUM(AM20:AM22)) -> -27369.4 | AO23: Profit for the year | AP23: =AP19-AP22 -> 5562 | AQ23: =AQ19-AQ22 -> 12015 | AR23: =AR19-AR22 -> 14854 | AS23: =AS19-AS22 -> 18299 | AT23: =AT19-AT22 -> 20466 | AU23: =AU19-AU22 -> 24795
A24: Total tax expense | B24: =B22+B23 -> -14932.7 | C24: =C22+C23 -> 6732.4 | D24: =D22+D23 -> -392 | E24: =E22+E23 -> 1358.9 | F24: =F22+F23 -> 4121 | G24: =G22+G23 -> 917.2 | I24: Deferred tax | J24: -91.8 | K24: -7.3 | L24: 20.3 | M24: -1313.4 | N24: 147.4 | O24: 1481.5 | Q24: Total tax expense | R24: =SUM(R21:R23) -> 43.69 | S24: =SUM(S21:S23) -> 54.73 | T24: =SUM(T21:T23) -> 71.68 | U24: =SUM(U21:U23) -> 65.71 | V24: =SUM(V21:V23) -> 81.88 | W24: =SUM(W21:W23) -> 101.97 | AG24: Add: Share in profits/loss of joint ventures (net) | AH24: 367.7 | AI24: 231.4 | AJ24: 1.2 | AK24: 0.5 | AL24: -5.5 | AM24: 1.8
A25: Profit/Loss for the year | B25: =B21-B24 -> -36088.2 | C25: =C21-C24 -> -25197.6 | D25: =D21-D24 -> -3863.7 | E25: =E21-E24 -> -89.6 | F25: =F21-F24 -> 8558 | G25: =G21-G24 -> 37481.3 | I25: Total tax expense | J25: =SUM(J23:J24) -> 488.8 | K25: =SUM(K23:K24) -> 977.9 | L25: =SUM(L23:L24) -> 2057.6 | M25: =SUM(M23:M24) -> 719.3 | N25: =SUM(N23:N24) -> 2086.2 | O25: =SUM(O23:O24) -> 3222 | Q25: Profit/Loss for the year | R25: =R20-R24 -> 141.07 | S25: =S20-S24 -> 142.45 | T25: =T20-T24 -> 108.74 | U25: =U20-U24 -> 189.07 | V25: =V20-V24 -> 246.21 | W25: =W20-W24 -> 299.81 | AG25: Add: Share in profit/loss of associate | AH25: -12.4 | AI25: 0 | AJ25: 0 | AK25: 0 | AL25: 0 | AM25: 0 | AO25: Earnings per Share | AP25: 2020 | AQ25: 2021 | AR25: 2022 | AS25: 2023 | AT25: 2024 | AU25: 2025
I26: Profit for the year | J26: =J22-J25 -> 3298.7 | K26: =K22-K25 -> 3779 | L26: =L22-L25 -> 6373.1 | M26: =M22-M25 -> 2040 | N26: =N22-N25 -> 6036.2 | O26: =O22-O25 -> 9931.7 | AG26: Profit/Loss before exceptional items and tax | AH26: =AH23+(SUM(AH24:AH25)) -> -23441.3 | AI26: =AI23+(SUM(AI24:AI25)) -> -24285.3 | AJ26: =AJ23+(SUM(AJ24:AJ25)) -> -28398.4 | AK26: =AK23+(SUM(AK24:AK25)) -> -29275.2 | AL26: =AL23+(SUM(AL24:AL25)) -> -31165.3 | AM26: =AM23+(SUM(AM24:AM25)) -> -27367.6 | AO26: Basic | AP26: 1.24 | AQ26: 2.67 | AR26: 3.3 | AS26: 4.07 | AT26: 4.55 | AU26: 5.51
A27: Earnings/Loss per share | B27: 2020 | C27: 2021 | D27: 2022 | E27: 2023 | F27: 2024 | G27: 2025 | Q27: Earnings per share | R27: 2020 | S27: 2021 | T27: 2022 | U27: 2023 | V27: 2024 | W27: 2025 | Y27: Earnings per share | Z27: 2020 | AA27: 2021 | AB27: 2022 | AC27: 2023 | AD27: 2024 | AE27: 2025 | AG27: Exceptional items (net) | AH27: -38355.7 | AI27: -19968.1 | AJ27: 164.3 | AK27: -22.4 | AL27: 755.5 | AM27: 0
A28: Basic | B28: -71.08 | C28: -46.18 | D28: -6.96 | E28: -0.16 | F28: 13.09 | G28: 58 | I28: Earnings per share | J28: 2020 | K28: 2021 | L28: 2022 | M28: 2023 | N28: 2024 | O28: 2025 | Q28: Basic | R28: 4.4 | S28: 4.44 | T28: 6.51 | U28: 5.89 | V28: 7.67 | W28: 9.34 | Y28: Basic | Z28: -3.02 | AA28: 43.88 | AB28: 51.99 | AC28: 63.02 | AD28: 39.42 | AE28: 57.03 | AG28: Profit/Loss before tax | AH28: =AH26+AH27 -> -61797 | AI28: =AI26+AI27 -> -44253.4 | AJ28: =AJ26+AJ27 -> -28234.1 | AK28: =AK26+AK27 -> -29297.6 | AL28: =AL26+AL27 -> -30409.8 | AM28: =AM26+AM27 -> -27367.6 | AO28: Subscribers base | AP28: 387500000 | AQ28: 422900000 | AR28: 409280000 | AS28: 438560000 | AT28: 481800000 | AU28: 476580000
I29: Basic | J29: 17.84 | K29: 17.516 | L29: 23.65 | M29: 7.57 | N29: 22.4 | O29: 37.31 | AG29: Current tax | AH29: 0.4 | AI29: -18 | AJ29: 17.3 | AK29: 11.5 | AL29: 828.5 | AM29: -2.7 | AO29: In 000s | AP29: =AP28/10000000 -> 38.75 | AQ29: =AQ28/10000000 -> 42.29 | AR29: =AR28/10000000 -> 40.928 | AS29: =AS28/10000000 -> 43.856 | AT29: =AT28/10000000 -> 48.18 | AU29: =AU28/10000000 -> 47.658
AG30: Deferred tax | AH30: 12080.7 | AI30: -2.3 | AJ30: -6 | AK30: -8 | AL30: 0.1 | AM30: 18.5
A31: Customer Base | B31: 423287000 | C31: 471362000 | D31: 489729000 | E31: 518446000 | F31: 561970000 | G31: 590514000 | I31: Towers base | J31: 95372 | K31: 179225 | L31: 188447 | M31: 192874 | N31: 219736 | O31: 260000 | Q31: Subscriber Base | R31: 300000 | S31: 400000 | T31: 472000 | U31: 516000 | V31: 568000 | W31: 575000 | AG31: Total tax expense | AH31: =SUM(AH29:AH30) -> 12081.1 | AI31: =SUM(AI29:AI30) -> -20.3 | AJ31: =SUM(AJ29:AJ30) -> 11.3 | AK31: =SUM(AK29:AK30) -> 3.5 | AL31: =SUM(AL29:AL30) -> 828.6 | AM31: =SUM(AM29:AM30) -> 15.8 | AO31: 2019 | AP31: 30.67
A32: in crores | B32: =B31/10000000 -> 42.3287 | C32: =C31/10000000 -> 47.1362 | D32: =D31/10000000 -> 48.9729 | E32: =E31/10000000 -> 51.8446 | F32: =F31/10000000 -> 56.197 | G32: =G31/10000000 -> 59.0514 | I32: In 000s | J32: =J31/10000000 -> 0.0095372 | K32: =K31/10000000 -> 0.0179225 | L32: =L31/10000000 -> 0.0188447 | M32: =M31/10000000 -> 0.0192874 | N32: =N31/10000000 -> 0.0219736 | O32: =O31/10000000 -> 0.026 | Q32: In 000s | R32: =R31/10000000 -> 0.03 | S32: =S31/10000000 -> 0.04 | T32: =T31/10000000 -> 0.0472 | U32: =U31/10000000 -> 0.0516 | V32: =V31/10000000 -> 0.0568 | W32: =W31/10000000 -> 0.0575 | AG32: Profit/Loss after tax | AH32: =AH28-AH31 -> -73878.1 | AI32: =AI28-AI31 -> -44233.1 | AJ32: =AJ28-AJ31 -> -28245.4 | AK32: =AK28-AK31 -> -29301.1 | AL32: =AL28-AL31 -> -31238.4 | AM32: =AM28-AM31 -> -27383.4
A34: 2019 Customer | B34: 32.73 | I34: 2019 | J34: 123546 | Q34: 2019 | R34: 142000 | AG34: Earnings/Loss per share | AH34: 2020 | AI34: 2021 | AJ34: 2022 | AK34: 2023 | AL34: 2024 | AM34: 2025
J35: =J34/10000000 -> 0.0123546 | R35: =R34/10000000 -> 0.0142 | AG35: Basic | AH35: -27.26 | AI35: -15.4 | AJ35: -9.83 | AK35: -8.43 | AL35: -6.41 | AM35: -4.01
AG37: Subscriber Base | AH37: 293700000 | AI37: 247200000 | AJ37: 243800000 | AK37: 223000000 | AL37: 212600000 | AM37: 198200000
AG38: In 000s | AH38: =AH37/10000000 -> 29.37 | AI38: =AI37/10000000 -> 24.72 | AJ38: =AJ37/10000000 -> 24.38 | AK38: =AK37/10000000 -> 22.3 | AL38: =AL37/10000000 -> 21.26 | AM38: =AM37/10000000 -> 19.82
AG40: 2019 | AH40: 39.48

Sheet Cash Flow Statement
A1: Cash Flow Statement | F1: #VALUE! | N1: #VALUE! | V1: #VALUE! | AD1: #VALUE! | AL1: #VALUE! | AT1: #VALUE!
A2: Particulars | B2: 2020 | C2: 2021 | D2: 2022 | E2: 2023 | F2: 2024 | G2: 2025 | I2: Particulars | J2: 2020 | K2: 2021 | L2: 2022 | M2: 2023 | N2: 2024 | O2: 2025 | Q2: Particulars | R2: 2020 | S2: 2021 | T2: 2022 | U2: 2023 | V2: 2024 | W2: 2025 | Y2: Particulars | Z2: 2020 | AA2: 2021 | AB2: 2022 | AC2: 2023 | AD2: 2024 | AE2: 2025 | AG2: Particulars | AH2: 2020 | AI2: 2021 | AJ2: 2022 | AK2: 2023 | AL2: 2024 | AM2: 2025 | AO2: Particulars | AP2: 2020 | AQ2: 2021 | AR2: 2022 | AS2: 2023 | AT2: 2024 | AU2: 2025
A3: Profit/Loss before tax | B3: -51020.9 | C3: -18465.2 | D3: -4255.7 | E3: 1269.3 | F3: 12679 | G3: 38398.5 | I3: Profit before tax | J3: 3787.5 | K3: 4756.9 | L3: 8430.7 | M3: 2759.3 | N3: 8122.4 | O3: 13153.7 | Q3: Profit before tax | R3: 141.07 | S3: 142.45 | T3: 208.94 | U3: 189.07 | V3: 246.21 | W3: 299.81 | Y3: Operating Activities | AG3: Operating activities | AO3: Operating activities
A4: Adjustments for | I4: Adjustments for | Q4: Adjustments for | Y4: Profit/Loss for the year | Z4: -84.83 | AA4: 1251.52 | AB4: 1999.98 | AC4: 2063.46 | AD4: 1163.09 | AE4: 2280.73 | AG4: Loss before tax | AH4: -61797 | AI4: -44253.4 | AJ4: -28234.1 | AK4: -29297.6 | AL4: -30409.8 | AM4: -27367.6 | AO4: Profit/Loss before exceptional items and tax | AP4: 7641 | AQ4: 16087 | AR4: 19981 | AS4: 24565 | AT4: 27485 | AU4: 33298
A5: Depreciation and amortisation expense | B5: 20392.1 | C5: 21997.5 | D5: 24329.8 | E5: 26355 | F5: 39537.6 | G5: 45570.3 | I5: Depreciation and amortization expense | J5: 1281.5 | K5: 2848.4 | L5: 5325.2 | M5: 5323.9 | N5: 6059.9 | O5: 6402.1 | Q5: Other comprehensive income | R5: -5.01 | S5: 1.19 | T5: -0.38 | U5: 2.1 | V5: -2.06 | W5: -3.87 | Y5: Adjustments for | AG5: Adjustments for | AO5: Exceptional items | AP5: -195 | AQ5: 0
A6: Finance costs | B6: 11248.5 | C6: 11754.3 | D6: 13155.7 | E6: 14397.3 | F6: 21933.7 | G6: 21625.8 | I6: Finance income | J6: -337 | K6: -199.2 | L6: -106 | M6: -83 | N6: -647.9 | O6: -417.9 | Q6: Depreciation, amortisation and Impairment | R6: 180.19 | S6: 159.32 | T6: 160.18 | U6: 154.31 | V6: 157.7 | W6: 180.4 | Y6: Income tax expense recognised in consolidated statement of P&L | Z6: 226.67 | AA6: 354.89 | AB6: 2204.54 | AC6: 2261.81 | AD6: 2469.67 | AE6: 2628.32 | AG6: Share in profit of joint ventures and associate | AH6: -355.3 | AI6: -231.4 | AJ6: -1.2 | AK6: -0.5 | AL6: 5.5 | AM6: -1.8 | AO6: Profit/Loss before tax | AP6: =AP4+AP5 -> 7446 | AQ6: =AQ4+AQ5 -> 16087 | AR6: =AR4+AR5 -> 19981 | AS6: =AS4+AS5 -> 24565 | AT6: =AT4+AT5 -> 27485 | AU6: =AU4+AU5 -> 33298
A7: Interest income | B7: -239 | C7: -332.2 | D7: -142.8 | E7: -249.9 | F7: -264.5 | G7: -204.8 | I7: Finance costs | J7: 335 | K7: 836.4 | L7: 1603.3 | M7: 1670.4 | N7: 1863.8 | O7: 1857.9 | Q7: Amortisation of deferred government grant | R7: -2.13 | S7: -3.02 | T7: -2.66 | U7: -3.59 | V7: -3.19 | W7: -6.3 | Y7: Share in profit/loss of associate | Z7: -2.18 | AA7: 2.14 | AB7: -4.33 | AC7: -6 | AD7: -8.9 | AE7: -5.2 | AG7: Depreciation of PPE and investment property | AH7: 15208 | AI7: 14501.3 | AJ7: 14656.9 | AK7: 14258.4 | AL7: 13871.5 | AM7: 13393.7 | AO7: Adjustments for
A8: Dividend income | B8: -863.1 | C8: -1716.3 | D8: -45 | E8: -1518.1 | F8: -649.3 | G8: -530.6 | I8: Share of profit of joint venture | J8: -1380.5 | K8: -866.3 | L8: -255.1 | M8: -261.4 | N8: -279.3 | O8: -268.7 | Q8: Non cash income | R8: 0.25 | S8: -1.35 | T8: -2.45 | U8: -1.68 | V8: 1.95 | W8: -7.53 | Y8: Depreciation and amortisation expenses | Z8: 2357.72 | AA8: 2313.87 | AB8: 0 | AC8: -46.74 | AD8: -1.97 | AE8: -733.02 | AG8: Amortisation of intangible assets | AH8: 9148.4 | AI8: 9137.2 | AJ8: 8927.4 | AK8: 8791.3 | AL8: 8762 | AM8: 8579.5 | AO8: Depreciation and amortisation expense | AP8: 7396 | AQ8: 11534 | AR8: 13702 | AS8: 18641 | AT8: 21394 | AU8: 23098
A9: Net loss/gain on derivative financial instruments | B9: -381 | C9: 271.3 | D9: -8.7 | E9: -350.2 | F9: 631.9 | G9: 42 | I9: Gain disposal of PPE | J9: -38.4 | K9: -82.3 | L9: -117 | M9: 5307.7 | N9: 0 | O9: 0 | Q9: Non cash expense | R9: 0.04 | S9: -0.66 | T9: 0.55 | U9: 0.59 | V9: 3.02 | W9: 0.1 | Y9: Gain on disposal of PPE | Z9: -8.51 | AA9: -42.27 | AB9: -3.59 | AC9: -6.53 | AD9: 0 | AE9: -311.2 | AG9: Share-based payment expense | AH9: -10.2 | AI9: 3.5 | AJ9: -1.6 | AK9: 0.2 | AL9: -48.6 | AM9: -77.9 | AO9: Effect of exchange rate change | AP9: 58 | AQ9: -160 | AR9: 60 | AS9: 73 | AT9: -72 | AU9: 13
A10: Net gain on FVTPL investments | B10: -446.2 | C10: -255.4 | D10: -97.5 | E10: -198.7 | F10: -2709.4 | G10: -3703 | I10: Provision for doubtful debts and advances | J10: 68.1 | K10: -46.1 | L10: 0 | M10: 492.8 | N10: -80.9 | O10: -5077.1 | Q10: Non cash expense (Interest credited) | R10: 3.14 | S10: 2.23 | T10: 2.27 | U10: 2.17 | V10: 2.69 | W10: 3.01 | Y10: Gain on disposal of assets held for sale | Z10: 0 | AA10: -67.38 | AB10: -6.45 | AC10: -18 | AD10: -7.65 | AE10: -1.71 | AG10: Loss on disposal of PPE and intangible assets | AH10: 2.6 | AI10: 0.5 | AJ10: -67.9 | AK10: -64.2 | AL10: -755.5 | AM10: 0 | AO10: Interest income | AP10: 0 | AQ10: -9 | AR10: -6 | AS10: -12 | AT10: -8 | AU10: -717
A11: Exceptional items | B11: 41525.2 | C11: 15023 | D11: 970.2 | E11: 4276.4 | F11: 7572.3 | G11: -7286.8 | I11: Revenue equalisation | J11: -129.7 | K11: -207.4 | L11: -343.6 | M11: -616.5 | N11: -490.7 | O11: -533 | Q11: Interest expense for Lease liabilities | R11: 3.41 | S11: 2.49 | T11: 2.67 | U11: 2.35 | V11: 0.07 | W11: 0.09 | Y11: Gain on modificatio/termination lease | Z11: -3.01 | AA11: -31.94 | AB11: 360.25 | AC11: 432.46 | AD11: -15.01 | AE11: -15.66 | AG11: Gain on sale of stake in Indus | AH11: 0 | AI11: -2118.9 | AJ11: -126.6 | AK11: 22.4 | AL11: 0 | AM11: 0 | AO11: Gain on investments (net) | AP11: -83 | AQ11: -473 | AR11: -55 | AS11: -155 | AT11: -362 | AU11: -201
A12: Loss on sale of PPE | B12: 0.1 | C12: 7.3 | D12: -24.3 | E12: -6.1 | F12: 119.4 | G12: 166.9 | I12: Others | J12: -187.9 | K12: -123.7 | L12: -113.8 | M12: -64.4 | N12: -50.7 | O12: -37.1 | Q12: Non cash expense (Loss on sale of fixed assets) | R12: 0.02 | S12: 0.03 | T12: 0.09 | U12: 0.14 | V12: 0.03 | W12: 0.01 | Y12: Interest income on financial assets carried at amortised cost | Z12: -4.75 | AA12: -11.53 | AB12: 0 | AC12: -29.61 | AD12: 634.73 | AE12: 747.53 | AG12: Impact due to cancellation of lease contract | AH12: -217.2 | AI12: -169.6 | AJ12: 13.7 | AK12: 0 | AL12: 0 | AM12: 0 | AO12: Loss on sale/discard of PPE | AP12: 1 | AQ12: 0 | AR12: -13 | AS12: -14 | AT12: 13 | AU12: 28
A13: Employee share-based payment expenses | B13: 30.2 | C13: 64.8 | D13: 61.7 | E13: 96.1 | F13: 4.4 | G13: -103.1 | I13: Operating profit before working capital changes | J13: =SUM(J3,J5:J12) -> 3398.6 | K13: =SUM(K3,K5:K12) -> 6916.7 | L13: =SUM(L3,L5:L12) -> 14423.7 | M13: =SUM(M3,M5:M12) -> 14528.8 | N13: =SUM(N3,N5:N12) -> 14496.6 | O13: =SUM(O3,O5:O12) -> 15079.9 | Q13: Non cash expense (Forex loss) | R13: 0.12 | S13: 0.02 | T13: 0 | U13: 0.07 | V13: 0 | W13: 0 | Y13: Finance cost | Z13: 470.74 | AA13: 420.2 | AB13: 23.12 | AC13: 46.32 | AD13: 0 | AE13: 12.85 | AG13: Accelerated depreciation on account of network | AH13: 5974.3 | AI13: 574.5 | AJ13: 20980.8 | AK13: 23354.3 | AL13: 25765.5 | AM13: 24543.4 | AO13: Finance cost | AP13: 6617 | AQ13: 3840 | AR13: 4377 | AS13: 4059 | AT13: 3999 | AU13: 4837
A14: Provision for doubtful debts/bad debts written off | B14: 0 | C14: 0 | D14: 173.7 | E14: 274.1 | F14: 427.8 | G14: 374.1 | I14: Changes in other financial assets | J14: 33.6 | K14: -312.9 | L14: 538 | M14: -950 | N14: -450 | O14: -385.2 | Q14: Non cash income | R14: -0.26 | S14: -0.12 | T14: -0.6 | U14: -0.73 | V14: -3.9 | W14: -2.69 | Y14: Loss on sale of investment | Z14: 6.48 | AA14: 0 | AB14: -10.56 | AC14: -41.82 | AD14: 194.94 | AE14: -194.94 | AG14: License fees and SUC on AGR | AH14: 27514.3 | AI14: 19440.5 | AJ14: 175.6 | AK14: 117 | AL14: 211.9 | AM14: 152.8 | AO14: Operating profit before working capital changes | AP14: =SUM(AP6,AP8:AP13) -> 21435 | AQ14: =SUM(AQ6,AQ8:AQ13) -> 30819 | AR14: =SUM(AR6,AR8:AR13) -> 38046 | AS14: =SUM(AS6,AS8:AS13) -> 47157 | AT14: =SUM(AT6,AT8:AT13) -> 52449 | AU14: =SUM(AU6,AU8:AU13) -> 60356
A15: Other non-cash itmes | B15: 493.5 | C15: 260.7 | D15: 114.5 | E15: 79.7 | F15: 82.3 | G15: 39.6 | I15: Changes in other non current and current assets | J15: 61 | K15: -106.9 | L15: 253.1 | M15: -49.4 | N15: -91.1 | O15: -481.7 | Q15: Provision for expected credit loss | R15: 12.51 | S15: 83.16 | T15: -50.1 | U15: 2.06 | V15: 0 | W15: 0 | Y15: Bad debts written off | Z15: 18.01 | AA15: 47.33 | AB15: 2.71 | AC15: 46.46 | AD15: 54.3 | AE15: 132.55 | AG15: One time spectrum charges | AH15: 3887.1 | AI15: 502.7 | AJ15: 47.9 | AK15: 8.6 | AL15: -47.8 | AM15: -49.9 | AO15: Adjustments for
